Workbook

Sheet 합계
B2: ■ 케이코믹스 22년 12월 판매 정산서 | K2: 선MG | L2: 516950000
K3: 프로젝트수익 | L3: =636950000-516950000 -> 120000000
B4: 사이트명 | C4: 소비자매출액 | D4: 유통사수수료 | E4: 스토리위즈매출액 | F4: 스토리위즈수익 | G4: 케이코믹스수익 | H4: 비고 | K4: 정산월 | L4: MG 회수금 | M4: 잔여 MG | N4: 수익회수금
B5: 브랜드이모티콘 | C5: =브랜드이모티콘!C5 -> 830480000 | D5: =브랜드이모티콘!D5 -> 685800000 | E5: =브랜드이모티콘!E5 -> 144680000 | F5: =브랜드이모티콘!F5 -> 21702000 | G5: =브랜드이모티콘!G5 -> 122978000 | H5: 정산요율:스토리위즈15%/케이코믹스 85% | J5: 1 | K5: 2020년 7월 | L5: =4411886/1.1 -> 4010805.5 | M5: =L2-L5 -> 5.1293919e+08 | O5: =(F5+G5)-E5 -> 0
B6: 브랜드웹툰 | C6: =브랜드웹툰!C5 -> 29418183 | D6: =브랜드웹툰!D5 -> 9400000 | E6: =브랜드웹툰!E5 -> 20018183 | F6: =브랜드웹툰!F5 -> 3002727 | G6: =브랜드웹툰!G5 -> 17015456 | H6: 정산요율:스토리위즈15%/케이코믹스 85% | J6: 2 | K6: 2020년 8월 | L6: =5440596/1.1 -> 4945996.4 | M6: 507993197 | O6: =(F6+G6)-E6 -> 0
B7: 카카오톡(케이코믹스IP) | C7: ='카카오톡 판매용이모티콘(자사IP)'!C6 -> 1040960 | D7: ='카카오톡 판매용이모티콘(자사IP)'!D6+'카카오톡 판매용이모티콘(자사IP)'!G6 -> 2233712 | E7: ='카카오톡 판매용이모티콘(자사IP)'!H6 -> 1921424 | F7: ='카카오톡 판매용이모티콘(자사IP)'!I6 -> 288214 | G7: ='카카오톡 판매용이모티콘(자사IP)'!J6 -> 1633210 | H7: 정산요율:스토리위즈15%/케이코믹스 85% | J7: 3 | K7: 2020년 9월 | L7: 7741975 | M7: =M6-L7 -> 500251222 | O7: =(F7+G7)-E7 -> 0
B8: 카카오톡(작가IP) | C8: ='카카오톡 판매용이모티콘(작가IP)'!C6 -> 2615229 | D8: ='카카오톡 판매용이모티콘(작가IP)'!D6+'카카오톡 판매용이모티콘(작가IP)'!G6 -> 3854267 | E8: ='카카오톡 판매용이모티콘(작가IP)'!H6 -> 3071198 | F8: ='카카오톡 판매용이모티콘(작가IP)'!I6 -> 460680 | G8: ='카카오톡 판매용이모티콘(작가IP)'!J6 -> 2610518 | H8: 정산요율:스토리위즈15%/케이코믹스 85% | J8: 4 | K8: 2020년 10월 | L8: 5800332 | M8: =M7-L8 -> 494450890 | O8: =(F8+G8)-E8 -> 0
B9: 밴드스티커(케이코믹스IP) | C9: ='밴드스티커(자사IP)'!C6 -> 7323 | D9: ='밴드스티커(자사IP)'!D6+'밴드스티커(자사IP)'!F6 -> 5785 | E9: ='밴드스티커(자사IP)'!H6 -> 1538 | F9: ='밴드스티커(자사IP)'!I6 -> 231 | G9: ='밴드스티커(자사IP)'!J6 -> 1307 | H9: 정산요율:스토리위즈15%/케이코믹스 85% | J9: 5 | K9: 2020년 11월 | L9: 8297406 | M9: =M8-L9 -> 486153484 | O9: =(F9+G9)-E9 -> 0
B10: 밴드스티커(작가IP) | C10: ='밴드스티커(작가IP)'!C6 -> 10500 | D10: ='밴드스티커(작가IP)'!D6+'밴드스티커(작가IP)'!G6 -> 5355 | E10: ='밴드스티커(작가IP)'!H6 -> 2205 | F10: ='밴드스티커(작가IP)'!I6 -> 331 | G10: ='밴드스티커(작가IP)'!J6 -> 1874 | H10: 정산요율:스토리위즈15%/케이코믹스 85% | J10: 6 | K10: 2020년 12월 | L10: 32035958 | M10: =M9-L10 -> 454117526 | O10: =(F10+G10)-E10 -> 0
J11: 7 | K11: 2021년 1월 | L11: 1722168 | M11: =M10-L11 -> 452395358 | O11: =(F11+G11)-E11 -> 0
J12: 8 | K12: 2021년 2월 | L12: 1613941 | M12: =M11-L12 -> 450781417 | O12: =(F12+G12)-E12 -> 0
J13: 9 | K13: 2021년 3월 | L13: 6715963 | M13: =M12-L13 -> 444065454 | O13: =(F13+G13)-E13 -> 0
B14: 합계 | C14: =SUM(C5:C13) -> 863572195 | D14: =SUM(D5:D13) -> 701299119 | E14: =SUM(E5:E13) -> 169694548 | F14: =SUM(F5:F13) -> 25454183 | G14: =SUM(G5:G13) -> 144240365 | J14: 10 | K14: 2021년 4월 | L14: 4947594 | M14: =M13-L14 -> 439117860
J15: 11 | K15: 2021년 5월 | L15: 6579706 | M15: =M14-L15 -> 432538154
B16: * 플랫폼이 추가될 경우: (1) 본 합계표 내 행 추가 (2) 계정정보 추가 (3) 플랫폼 시트 추가 | J16: 12 | K16: 2021년 6월 | L16: 7693335 | M16: =M15-L16 -> 424844819
J17: 13 | K17: 2021년 7월 | L17: 10452516 | M17: =M16-L17 -> 414392303
E18: 공급가액 | F18: 합계금액 | J18: 14 | K18: 2021년 8월 | L18: 10374097 | M18: =M17-L18 -> 404018206
C19: 스토리위즈->케이코믹스 계산서발행 | E19: =E14 -> 169694548 | F19: =E19 -> 169694548 | J19: 15 | K19: 2021년 9월 | L19: 2587622 | M19: 401430584
C20: 케이코믹스->스토리위즈 계산서발행 | E20: =G14 -> 144240365 | F20: =E20 -> 144240365 | J20: 16 | K20: 2021년 10월 | L20: 10768091 | M20: =M19-L20 -> 390662493
C21: 상계 후 입금액 | E21: =F14 -> 25454183 | F21: =E21 -> 25454183 | J21: 17 | K21: 2021년 11월 | L21: 10162222 | M21: =M20-L21 -> 380500271
C22: 오입금액
F23: =F21+E23+F22 -> 25454183 | J23: 18 | K23: 2021년 12월 | L23: 15953145 | M23: 364547126
J24: 19 | K24: 2022년 01월 | L24: 4170625 | M24: =M23-L24 -> 360376501
J25: 20 | K25: 2022년 02월 | L25: 4968474 | M25: =M24-L25 -> 355408027
J26: 21 | K26: 2022년 03월 | L26: 6137824 | M26: =M25-L26 -> 349270203
J27: 22 | K27: 2022년 04월 | L27: 3606106 | M27: =M26-L27 -> 345664097
J28: 23 | K28: 2022년 05월 | L28: 11504011 | M28: =M27-L28 -> 334160086
J29: 24 | K29: 2022년 06월 | L29: 4545796 | M29: =M28-L29 -> 329614290
J30: 25 | K30: 2022년 07월 | L30: 9074989 | M30: =M29-L30 -> 320539301
J31: 26 | K31: 2022년 08월 | L31: 9161122 | M31: =M30-L31 -> 311378179
J32: 27 | K32: 2022년 09월 | L32: 7480310 | M32: =M31-L32 -> 303897869
J33: 28 | K33: 2022년 10월 | L33: 5629884 | M33: =M32-L33 -> 298267985
J34: 29 | K34: 2022년 11월 | L34: 6854629 | M34: =M33-L34 -> 291413356
J35: 30 | K35: 2022년 12월 | L35: =F23 -> 25454183 | M35: =M34-L35 -> 265959173
K36: 합계 | L36: =SUM(L5:L29) -> 1.8733571e+08

Sheet 계정정보
B2: ■ 케이코믹스 유통계정정보
B4: 서비스명 | C4: 아이디 | D4: 패스워드 | E4: URL
B5: 카카오톡 이모티콘 | C5: emoticon_team@k-comics.com | D5: 7503cyk!! | E5: https://emoticonstudio.kakao.com/

Sheet 브랜드이모티콘
B2: 브랜드이모티콘
F3: 0.15 | G3: 0.85
B4: 작품명 | C4: 소비자매출액 | D4: 유통사수수료 | E4: 스토리위즈 매출액 | F4: 스토리위즈 수익 | G4: 케이코믹스 수익 | H4: 비고
B5: 합계 | C5: =ROUND(SUM(C6:C1981),0) -> 830480000 | D5: =ROUND(SUM(D6:D1981),0) -> 685800000 | E5: =ROUND(SUM(E6:E1981),0) -> 144680000 | F5: =ROUND(SUM(F6:F1981),0) -> 21702000 | G5: =ROUND(SUM(G6:G1981),0) -> 122978000
B6: 큐티즈주식회사 | C6: 18480000 | D6: 16800000 | E6: =C6-D6 -> 1680000 | F6: =E6*15% -> 252000 | G6: =E6*85% -> 1428000
B7: 주식회사 디그리드인터렉티브 | C7: 19800000 | D7: 18000000 | E7: =C7-D7 -> 1800000 | F7: =E7*15% -> 270000 | G7: =E7*85% -> 1530000
B8: 주식회사 워니프레임 | C8: 21000000 | D8: 20000000 | E8: =C8-D8 -> 1000000 | F8: =E8*15% -> 150000 | G8: =E8*85% -> 850000
B9: 롯데쇼핑(주) | C9: 18700000 | D9: 17000000 | E9: =C9-D9 -> 1700000 | F9: =E9*15% -> 255000 | G9: =E9*85% -> 1445000
B10: 주식회사 데이그린 | C10: 19000000 | D10: 10000000 | E10: =C10-D10 -> 9000000 | F10: =E10*15% -> 1350000 | G10: =E10*85% -> 7650000
B11: 디원씽 | C11: 180000000 | D11: 175000000 | E11: =C11-D11 -> 5000000 | F11: =E11*15% -> 750000 | G11: =E11*85% -> 4250000
B12: 현대지비에프엠에스(주) | C12: 19000000 | D12: 10000000 | E12: =C12-D12 -> 9000000 | F12: =E12*15% -> 1350000 | G12: =E12*85% -> 7650000
B13: 순천시청 | C13: 8000000 | D13: 0 | E13: =C13-D13 -> 8000000 | F13: =E13*15% -> 1200000 | G13: =E13*85% -> 6800000
B14: 에프앤에프 | C14: 11000000 | D14: 10000000 | E14: =C14-D14 -> 1000000 | F14: =E14*15% -> 150000 | G14: =E14*85% -> 850000
B15: 광주관광재단 | C15: 29000000 | D15: 20000000 | E15: =C15-D15 -> 9000000 | F15: =E15*15% -> 1350000 | G15: =E15*85% -> 7650000
B16: 볼보자동자코리아 | C16: 42000000 | D16: 30000000 | E16: =C16-D16 -> 12000000 | F16: =E16*15% -> 1800000 | G16: =E16*85% -> 10200000
B17: 짐싸 | C17: 11000000 | D17: 10000000 | E17: =C17-D17 -> 1000000 | F17: =E17*15% -> 150000 | G17: =E17*85% -> 850000
... B31: 현대그린푸드 | C31: 11000000 | D31: 10000000 | E31: =C31-D31 -> 1000000 | F31: =E31*15% -> 150000 | G31: =E31*85% -> 850000
E32: =C32-D32 -> 0 | F32: =E32*15% -> 0 | G32: =E32*85% -> 0
E33: =C33-D33 -> 0 | F33: =E33*15% -> 0 | G33: =E33*85% -> 0
E34: =C34-D34 -> 0 | F34: =E34*15% -> 0 | G34: =E34*85% -> 0
E35: =C35-D35 -> 0 | F35: =E35*15% -> 0 | G35: =E35*85% -> 0
D542: =C542-E542 -> 0 | F542: =E542*10% -> 0 | G542: =E542*90% -> 0
D543: =C543-E543 -> 0 | F543: =E543*10% -> 0 | G543: =E543*90% -> 0
D544: =C544-E544 -> 0 | F544: =E544*10% -> 0 | G544: =E544*90% -> 0
D545: =C545-E545 -> 0 | F545: =E545*10% -> 0 | G545: =E545*90% -> 0
D546: =C546-E546 -> 0 | F546: =E546*10% -> 0 | G546: =E546*90% -> 0
D547: =C547-E547 -> 0 | F547: =E547*10% -> 0 | G547: =E547*90% -> 0
D548: =C548-E548 -> 0 | F548: =E548*10% -> 0 | G548: =E548*90% -> 0
D549: =C549-E549 -> 0 | F549: =E549*10% -> 0 | G549: =E549*90% -> 0
D550: =C550-E550 -> 0 | F550: =E550*10% -> 0 | G550: =E550*90% -> 0
D551: =C551-E551 -> 0 | F551: =E551*10% -> 0 | G551: =E551*90% -> 0
D552: =C552-E552 -> 0 | F552: =E552*10% -> 0 | G552: =E552*90% -> 0
D553: =C553-E553 -> 0 | F553: =E553*10% -> 0 | G553: =E553*90% -> 0
... D960: =C960-E960 -> 0 | F960: =E960*10% -> 0 | G960: =E960*90% -> 0
F961: =E961*10% -> 0 | G961: =E961*90% -> 0

Sheet 브랜드웹툰
B2: 브랜드웹툰
F3: 0.15 | G3: 0.85
B4: 작품명 | C4: 소비자매출액 | D4: 유통사수수료 | E4: 스토리위즈 매출액 | F4: 스토리위즈 수익 | G4: 케이코믹스 수익 | H4: 비고
B5: 합계 | C5: =ROUND(SUM(C6:C1979),0) -> 29418183 | D5: =ROUND(SUM(D6:D1979),0) -> 9400000 | E5: =ROUND(SUM(E6:E1979),0) -> 20018183 | F5: =ROUND(SUM(F6:F1979),0) -> 3002727 | G5: =ROUND(SUM(G6:G1979),0) -> 17015456
B6: 레디엔터테인먼트 | C6: 1600000 | D6: 0 | E6: =C6-D6 -> 1600000 | F6: =E6*15% -> 240000 | G6: =E6*85% -> 1360000
B7: 사회복지법인 사회복지공동모금회 | C7: 909092 | D7: 900000 | E7: =C7-D7 -> 9092 | F7: =E7*15% -> 1363.8 | G7: =E7*85% -> 7728.2
B8: 산림청 국립수목원 | C8: 16000000 | D8: 0 | E8: =C8-D8 -> 16000000 | F8: =E8*15% -> 2400000 | G8: =E8*85% -> 13600000
B9: 영천시청 | C9: 10909091 | D9: 8500000 | E9: =C9-D9 -> 2409091 | F9: =E9*15% -> 361363.65 | G9: =E9*85% -> 2047727.3
E10: =C10-D10 -> 0 | F10: =E10*15% -> 0 | G10: =E10*85% -> 0
E11: =C11-D11 -> 0 | F11: =E11*15% -> 0 | G11: =E11*85% -> 0
D12: 0 | E12: =C12-D12 -> 0 | F12: =E12*15% -> 0 | G12: =E12*85% -> 0
D13: 0 | E13: =C13-D13 -> 0 | F13: =E13*15% -> 0 | G13: =E13*85% -> 0
D14: 0 | E14: =C14-D14 -> 0 | F14: =E14*15% -> 0 | G14: =E14*85% -> 0
D15: 0 | E15: =C15-D15 -> 0 | F15: =E15*15% -> 0 | G15: =E15*85% -> 0
D16: 0 | E16: =C16-D16 -> 0 | F16: =E16*15% -> 0 | G16: =E16*85% -> 0
D17: 0 | E17: =C17-D17 -> 0 | F17: =E17*15% -> 0 | G17: =E17*85% -> 0
D18: 0 | E18: =C18-D18 -> 0 | F18: =E18*15% -> 0 | G18: =E18*85% -> 0
D19: 0 | E19: =C19-D19 -> 0 | F19: =E19*15% -> 0 | G19: =E19*85% -> 0
D540: =C540-E540 -> 0 | F540: =E540*10% -> 0 | G540: =E540*90% -> 0
D541: =C541-E541 -> 0 | F541: =E541*10% -> 0 | G541: =E541*90% -> 0
D542: =C542-E542 -> 0 | F542: =E542*10% -> 0 | G542: =E542*90% -> 0
D543: =C543-E543 -> 0 | F543: =E543*10% -> 0 | G543: =E543*90% -> 0
D544: =C544-E544 -> 0 | F544: =E544*10% -> 0 | G544: =E544*90% -> 0
D545: =C545-E545 -> 0 | F545: =E545*10% -> 0 | G545: =E545*90% -> 0
D546: =C546-E546 -> 0 | F546: =E546*10% -> 0 | G546: =E546*90% -> 0
D547: =C547-E547 -> 0 | F547: =E547*10% -> 0 | G547: =E547*90% -> 0
D548: =C548-E548 -> 0 | F548: =E548*10% -> 0 | G548: =E548*90% -> 0
D549: =C549-E549 -> 0 | F549: =E549*10% -> 0 | G549: =E549*90% -> 0
D550: =C550-E550 -> 0 | F550: =E550*10% -> 0 | G550: =E550*90% -> 0
D551: =C551-E551 -> 0 | F551: =E551*10% -> 0 | G551: =E551*90% -> 0
... D958: =C958-E958 -> 0 | F958: =E958*10% -> 0 | G958: =E958*90% -> 0
F959: =E959*10% -> 0 | G959: =E959*90% -> 0

Sheet 카카오톡 판매용이모티콘(자사IP)
B2: 카카오톡
I3: 0.15 | J3: 0.85
B4: 카카오톡 11월 매출 (판매용이모티콘_케이코믹스IP) | C4: 결재금액 | D4: 유통사수수료 | H4: 스토리위즈 매출액 | I4: 스토리위즈 수익 | J4: 케이코믹스 수익 | K4: 비고
C5: (VAT포함) | D5: 앱스토어 (30%) | E5: 정산대상금액 (VAT포함) | F5: 정산대상금액 (VAT별도) | G5: 카카오톡 (50%)
B6: 합계 | C6: =ROUND(SUM(C7:C1982),0) -> 1040960 | D6: =ROUND(SUM(D7:D1982),0) -> 312288 | E6: =ROUND(SUM(E7:E1982),0) -> 4227133 | F6: =ROUND(SUM(F7:F1982),0) -> 3842848 | G6: =ROUND(SUM(G7:G1982),0) -> 1921424 | H6: =ROUND(SUM(H7:H1982),0) -> 1921424 | I6: =ROUND(SUM(I7:I1982),0) -> 288214 | J6: =ROUND(SUM(J7:J1982),0) -> 1633210
B7: 곰니찌와 곰방와(2종) | C7: 11000 | D7: =C7*0.3 -> 3300 | E7: 50632 | F7: =E7/1.1 -> 46029.091 | G7: =F7*0.5 -> 23014.545 | H7: =G7 -> 23014.545 | I7: =H7*15% -> 3452.1818 | J7: =H7*85% -> 19562.364
B8: 나대지마심장아 | C8: 38001 | D8: =C8*0.3 -> 11400.3 | E8: 82856 | F8: =E8/1.1 -> 75323.636 | G8: =F8*0.5 -> 37661.818 | H8: =G8 -> 37661.818 | I8: =H8*15% -> 5649.2727 | J8: =H8*85% -> 32012.545
B9: 니니의 꽃스런 일상 | C9: 23000 | D9: =C9*0.3 -> 6900 | E9: 29798 | F9: =E9/1.1 -> 27089.091 | G9: =F9*0.5 -> 13544.545 | H9: =G9 -> 13544.545 | I9: =H9*15% -> 2031.6818 | J9: =H9*85% -> 11512.864
B10: 다미(2종) | C10: 43000 | D10: =C10*0.3 -> 12900 | E10: 81664 | F10: =E10/1.1 -> 74240 | G10: =F10*0.5 -> 37120 | H10: =G10 -> 37120 | I10: =H10*15% -> 5568 | J10: =H10*85% -> 31552
B11: 달콤톡! 꼬미 | C11: 15500 | D11: =C11*0.3 -> 4650 | E11: 17278 | F11: =E11/1.1 -> 15707.273 | G11: =F11*0.5 -> 7853.6364 | H11: =G11 -> 7853.6364 | I11: =H11*15% -> 1178.0455 | J11: =H11*85% -> 6675.5909
B12: 달콤톡! 또미 | C12: 15715 | D12: =C12*0.3 -> 4714.5 | E12: 154556 | F12: =E12/1.1 -> 140505.45 | G12: =F12*0.5 -> 70252.727 | H12: =G12 -> 70252.727 | I12: =H12*15% -> 10537.909 | J12: =H12*85% -> 59714.818
B13: 인절미 토끼 머디 | C13: 0 | D13: =C13*0.3 -> 0 | E13: 32061 | F13: =E13/1.1 -> 29146.364 | G13: =F13*0.5 -> 14573.182 | H13: =G13 -> 14573.182 | I13: =H13*15% -> 2185.9773 | J13: =H13*85% -> 12387.205
B14: 얌얌이의 먹방티콘 | C14: 12715 | D14: =C14*0.3 -> 3814.5 | E14: 117996 | F14: =E14/1.1 -> 107269.09 | G14: =F14*0.5 -> 53634.545 | H14: =G14 -> 53634.545 | I14: =H14*15% -> 8045.1818 | J14: =H14*85% -> 45589.364
B15: 몽글몽글 몽구리 | C15: 3000 | D15: =C15*0.3 -> 900 | E15: 31779 | F15: =E15/1.1 -> 28890 | G15: =F15*0.5 -> 14445 | H15: =G15 -> 14445 | I15: =H15*15% -> 2166.75 | J15: =H15*85% -> 12278.25
B16: 썸톡(7종) | C16: 327485 | D16: =C16*0.3 -> 98245.5 | E16: 375708 | F16: =E16/1.1 -> 341552.73 | G16: =F16*0.5 -> 170776.36 | H16: =G16 -> 170776.36 | I16: =H16*15% -> 25616.455 | J16: =H16*85% -> 145159.91
B17: 무조껀 나와!! 약속티콘 | C17: 25398 | D17: =C17*0.3 -> 7619.4 | E17: 247914 | F17: =E17/1.1 -> 225376.36 | G17: =F17*0.5 -> 112688.18 | H17: =G17 -> 112688.18 | I17: =H17*15% -> 16903.227 | J17: =H17*85% -> 95784.955
B18: 탱탱볼 예동이(2종) | C18: 12500 | D18: =C18*0.3 -> 3750 | E18: 186647 | F18: =E18/1.1 -> 169679.09 | G18: =F18*0.5 -> 84839.545 | H18: =G18 -> 84839.545 | I18: =H18*15% -> 12725.932 | J18: =H18*85% -> 72113.614
... B24: 오셨슴까!! 햄님!! | C24: 356501 | D24: =C24*0.3 -> 106950.3 | E24: 1330530 | F24: =E24/1.1 -> 1209572.7 | G24: =F24*0.5 -> 604786.36 | H24: =G24 -> 604786.36 | I24: =H24*15% -> 90717.955 | J24: =H24*85% -> 514068.41
D28: =C28*0.3 -> 0 | F28: =E28/1.1 -> 0 | G28: =F28*0.5 -> 0 | H28: =G28 -> 0 | I28: =H28*15% -> 0 | J28: =H28*85% -> 0
D29: =C29*0.3 -> 0 | F29: =E29/1.1 -> 0 | G29: =F29*0.5 -> 0 | H29: =G29 -> 0 | I29: =H29*15% -> 0 | J29: =H29*85% -> 0
D543: =C543-H543 -> 0 | I543: =H543*10% -> 0 | J543: =H543*90% -> 0
D544: =C544-H544 -> 0 | I544: =H544*10% -> 0 | J544: =H544*90% -> 0
D545: =C545-H545 -> 0 | I545: =H545*10% -> 0 | J545: =H545*90% -> 0
D546: =C546-H546 -> 0 | I546: =H546*10% -> 0 | J546: =H546*90% -> 0
D547: =C547-H547 -> 0 | I547: =H547*10% -> 0 | J547: =H547*90% -> 0
D548: =C548-H548 -> 0 | I548: =H548*10% -> 0 | J548: =H548*90% -> 0
D549: =C549-H549 -> 0 | I549: =H549*10% -> 0 | J549: =H549*90% -> 0
D550: =C550-H550 -> 0 | I550: =H550*10% -> 0 | J550: =H550*90% -> 0
D551: =C551-H551 -> 0 | I551: =H551*10% -> 0 | J551: =H551*90% -> 0
D552: =C552-H552 -> 0 | I552: =H552*10% -> 0 | J552: =H552*90% -> 0
D553: =C553-H553 -> 0 | I553: =H553*10% -> 0 | J553: =H553*90% -> 0
D554: =C554-H554 -> 0 | I554: =H554*10% -> 0 | J554: =H554*90% -> 0
... D961: =C961-H961 -> 0 | I961: =H961*10% -> 0 | J961: =H961*90% -> 0
I962: =H962*10% -> 0 | J962: =H962*90% -> 0

Sheet 카카오톡 판매용이모티콘(작가IP)
B2: 카카오톡
I3: 0.15 | J3: 0.85
B4: 카카오톡 11월 매출 (판매용이모티콘_작가IP) | C4: 결재금액 | D4: 유통사수수료 | H4: 스토리위즈 매출액 | I4: 스토리위즈 수익 | J4: 케이코믹스 수익 | K4: 비고
C5: (VAT포함) | D5: 앱스토어 (30%) | E5: 정산대상금액 (VAT포함) | F5: 정산대상금액 (VAT별도) | G5: 카카오톡 (50%)
B6: 합계 | C6: =ROUND(SUM(C7:C1980),0) -> 2615229 | D6: =ROUND(SUM(D7:D1980),0) -> 783069 | E6: =ROUND(SUM(E7:E1980),0) -> 6756635 | F6: =ROUND(SUM(F7:F1980),0) -> 6142395 | G6: =ROUND(SUM(G7:G1980),0) -> 3071198 | H6: =ROUND(SUM(H7:H1980),0) -> 3071198 | I6: =ROUND(SUM(I7:I1980),0) -> 460680 | J6: =ROUND(SUM(J7:J1980),0) -> 2610518
B7: EBS 3종(두다다쿵, 번개맨, 뿡뿡이) | C7: =54500+10500+43500 -> 108500 | D7: =C7*0.3 -> 32550 | E7: =74288+30527+67350 -> 172165 | F7: =E7/1.1 -> 156513.64 | G7: =(F7/2) -> 78256.818 | H7: =G7 -> 78256.818 | I7: =H7*15% -> 11738.523 | J7: =H7*85% -> 66518.295
B8: 강성수(위대한캣츠비) | C8: 0 | D8: =C8*0.3 -> 0 | E8: 12234 | F8: =E8/1.1 -> 11121.818 | G8: =(F8/2) -> 5560.9091 | H8: =G8 -> 5560.9091 | I8: =H8*15% -> 834.13636 | J8: =H8*85% -> 4726.7727
B9: 고필헌(메가쇼킹 5종) | C9: 22000 | D9: =C9*0.3 -> 6600 | E9: 73108 | F9: =E9/1.1 -> 66461.818 | G9: =(F9/2) -> 33230.909 | H9: =G9 -> 33230.909 | I9: =H9*15% -> 4984.6364 | J9: =H9*85% -> 28246.273
B10: 곽백수(가우스전자) | C10: 2500 | D10: =C10*0.3 -> 750 | E10: 11726 | F10: =E10/1.1 -> 10660 | G10: =(F10/2) -> 5330 | H10: =G10 -> 5330 | I10: =H10*15% -> 799.5 | J10: =H10*85% -> 4530.5
B11: 권순호(호조 15종) | C11: 326417 | D11: =C11*0.3 -> 97925.1 | E11: 1119194 | F11: =E11/1.1 -> 1017449.1 | G11: =(F11/2) -> 508724.55 | H11: =G11 -> 508724.55 | I11: =H11*15% -> 76308.682 | J11: =H11*85% -> 432415.86
B12: 김미숙(배추걸의 배추티콘) | C12: 5000 | D12: =C12*0.3 -> 1500 | E12: 23104 | F12: =E12/1.1 -> 21003.636 | G12: =(F12/2) -> 10501.818 | H12: =G12 -> 10501.818 | I12: =H12*15% -> 1575.2727 | J12: =H12*85% -> 8926.5455
B13: 김보통(쉬고싶은 고양이) | C13: 24500 | D13: =C13*0.3 -> 7350 | E13: 71248 | F13: =E13/1.1 -> 64770.909 | G13: =(F13/2) -> 32385.455 | H13: =G13 -> 32385.455 | I13: =H13*15% -> 4857.8182 | J13: =H13*85% -> 27527.636
B14: 김성모(김성모 3종) | C14: 153000 | D14: =C14*0.3 -> 45900 | E14: 262963 | F14: =E14/1.1 -> 239057.27 | G14: =(F14/2) -> 119528.64 | H14: =G14 -> 119528.64 | I14: =H14*15% -> 17929.295 | J14: =H14*85% -> 101599.34
B15: 김양수(3종) | C15: 5500 | D15: =C15*0.3 -> 1650 | E15: 36632 | F15: =E15/1.1 -> 33301.818 | G15: =(F15/2) -> 16650.909 | H15: =G15 -> 16650.909 | I15: =H15*15% -> 2497.6364 | J15: =H15*85% -> 14153.273
B16: 감자도리(16종) | C16: 550502 | D16: =C16*0.3 -> 165150.6 | E16: 1150528 | F16: =E16/1.1 -> 1045934.5 | G16: =(F16/2) -> 522967.27 | H16: =G16 -> 522967.27 | I16: =H16*15% -> 78445.091 | J16: =H16*85% -> 444522.18
B17: 와탕카/김석주, 정필용, 김은구 | C17: 74500 | D17: =C17*0.3 -> 22350 | E17: 109448 | F17: =E17/1.1 -> 99498.182 | G17: =(F17/2) -> 49749.091 | H17: =G17 -> 49749.091 | I17: =H17*15% -> 7462.3636 | J17: =H17*85% -> 42286.727
B18: 조선경(올리브의하루)/ 조선경, 김은구 | C18: 0 | D18: =C18*0.3 -> 0 | E18: 10868 | F18: =E18/1.1 -> 9880 | G18: =(F18/2) -> 4940 | H18: =G18 -> 4940 | I18: =H18*15% -> 741 | J18: =H18*85% -> 4199
B19: 기량(천년구미호) | C19: 43145 | D19: =C19*0.3 -> 12943.5 | E19: 60273 | F19: =E19/1.1 -> 54793.636 | G19: =(F19/2) -> 27396.818 | H19: =G19 -> 27396.818 | I19: =H19*15% -> 4109.5227 | J19: =H19*85% -> 23287.295
... B23: 강민구(3종) | C23: 71000 | D23: =C23*0.3 -> 21300 | E23: 253678 | F23: =E23/1.1 -> 230616.36 | G23: =(F23/2) -> 115308.18 | H23: =G23 -> 115308.18 | I23: =H23*15% -> 17296.227 | J23: =H23*85% -> 98011.955
B24: 야구하는 고릴라 미스터고 | C24: 5000 | D24: 0 | E24: 7321 | F24: =E24/1.1 -> 6655.4545 | G24: =(F24/2) -> 3327.7273 | H24: =G24 -> 3327.7273 | I24: =H24*15% -> 499.15909 | J24: =H24*85% -> 2828.5682
B25: 박종원 | C25: 5000 | D25: =C25*0.3 -> 1500 | E25: 58093 | F25: =E25/1.1 -> 52811.818 | G25: =(F25/2) -> 26405.909 | H25: =G25 -> 26405.909 | I25: =H25*15% -> 3960.8864 | J25: =H25*85% -> 22445.023
B26: 박종원+심윤수 | C26: 0 | D26: =C26*0.3 -> 0 | E26: 5261 | F26: =E26/1.1 -> 4782.7273 | G26: =(F26/2) -> 2391.3636 | H26: =G26 -> 2391.3636 | I26: =H26*15% -> 358.70455 | J26: =H26*85% -> 2032.6591
B27: 배진수(2종) | C27: 12500 | D27: =C27*0.3 -> 3750 | E27: 33640 | F27: =E27/1.1 -> 30581.818 | G27: =(F27/2) -> 15290.909 | H27: =G27 -> 15290.909 | I27: =H27*15% -> 2293.6364 | J27: =H27*85% -> 12997.273
B28: 백승원(쭈그리 라이프) | C28: 5000 | D28: =C28*0.3 -> 1500 | E28: 32509 | F28: =E28/1.1 -> 29553.636 | G28: =(F28/2) -> 14776.818 | H28: =G28 -> 14776.818 | I28: =H28*15% -> 2216.5227 | J28: =H28*85% -> 12560.295
B29: 성은호(2종) | C29: 61000 | D29: =C29*0.3 -> 18300 | E29: 387253 | F29: =E29/1.1 -> 352048.18 | G29: =(F29/2) -> 176024.09 | H29: =G29 -> 176024.09 | I29: =H29*15% -> 26403.614 | J29: =H29*85% -> 149620.48
B30: 송지선(8종) | C30: 653099 | D30: =C30*0.3 -> 195929.7 | E30: 1235167 | F30: =E30/1.1 -> 1122879.1 | G30: =(F30/2) -> 561439.55 | H30: =G30 -> 561439.55 | I30: =H30*15% -> 84215.932 | J30: =H30*85% -> 477223.61
B31: 오현동(캐러멜의 칭찬스티커) | C31: 5500 | D31: =C31*0.3 -> 1650 | E31: 40327 | F31: =E31/1.1 -> 36660.909 | G31: =(F31/2) -> 18330.455 | H31: =G31 -> 18330.455 | I31: =H31*15% -> 2749.5682 | J31: =H31*85% -> 15580.886
B32: 원수연(4종) | C32: 17985 | D32: =C32*0.3 -> 5395.5 | E32: 40458 | F32: =E32/1.1 -> 36780 | G32: =(F32/2) -> 18390 | H32: =G32 -> 18390 | I32: =H32*15% -> 2758.5 | J32: =H32*85% -> 15631.5
B33: 이상신,국중록(2종) | C33: 7500 | D33: =C33*0.3 -> 2250 | E33: 87662 | F33: =E33/1.1 -> 79692.727 | G33: =(F33/2) -> 39846.364 | H33: =G33 -> 39846.364 | I33: =H33*15% -> 5976.9545 | J33: =H33*85% -> 33869.409
B34: 이주희(2종) | C34: 5500 | D34: =C34*0.3 -> 1650 | E34: 46482 | F34: =E34/1.1 -> 42256.364 | G34: =(F34/2) -> 21128.182 | H34: =G34 -> 21128.182 | I34: =H34*15% -> 3169.2273 | J34: =H34*85% -> 17958.955
B35: 정희수(아이들의권선생님) | C35: 2500 | D35: =C35*0.3 -> 750 | E35: 11131 | F35: =E35/1.1 -> 10119.091 | G35: =(F35/2) -> 5059.5455 | H35: =G35 -> 5059.5455 | I35: =H35*15% -> 758.93182 | J35: =H35*85% -> 4300.6136
B36: 케이원미디어/혈관고(9종) | C36: 101500 | D36: =C36*0.3 -> 30450 | E36: 190123 | F36: =E36/1.1 -> 172839.09 | G36: =(F36/2) -> 86419.545 | H36: =G36 -> 86419.545 | I36: =H36*15% -> 12962.932 | J36: =H36*85% -> 73456.614
... B40: 홍지선(날바다줘) | C40: 8000 | D40: =C40*0.3 -> 2400 | E40: 35205 | F40: =E40/1.1 -> 32004.545 | G40: =(F40/2) -> 16002.273 | H40: =G40 -> 16002.273 | I40: =H40*15% -> 2400.3409 | J40: =H40*85% -> 13601.932
D41: =C41*0.3 -> 0 | F41: =E41/1.1 -> 0 | G41: =(F41/2) -> 0 | H41: =G41 -> 0 | I41: =H41*15% -> 0 | J41: =H41*85% -> 0
G42: =(F42/2) -> 0 | H42: =G42 -> 0
G43: =(F43/2) -> 0 | H43: =G43 -> 0
G44: =(F44/2) -> 0 | H44: =G44 -> 0
G45: =(F45/2) -> 0 | H45: =G45 -> 0
G46: =(F46*0.5) -> 0 | H46: =G46 -> 0
G47: =(F47*0.5) -> 0 | H47: =G47 -> 0
...

Sheet 밴드스티커(자사IP)
B2: 밴드스티커
I3: 0.15 | J3: 0.85
B4: 밴드스티커 11월 매출 (판매용밴드스티커_자사IP) | C4: 결재금액 | D4: 유통사수수료 | H4: 스토리위즈 매출액 | I4: 스토리위즈 수익 | J4: 케이코믹스 수익 | K4: 비고
C5: (VAT포함) | D5: 앱스토어 (30%) | E5: 순매출 | F5: 네이버밴드 (70%) | G5: 정산대상금액 (약30%)
B6: 합계 | C6: =ROUND(SUM(C7:C1981),0) -> 7323 | D6: =ROUND(SUM(D7:D1981),0) -> 2197 | E6: =ROUND(SUM(E7:E1981),0) -> 5126 | F6: =ROUND(SUM(F7:F1981),0) -> 3588 | G6: =ROUND(SUM(G7:G1981),0) -> 1538 | H6: =ROUND(SUM(H7:H1981),0) -> 1538 | I6: =ROUND(SUM(I7:I1981),0) -> 231 | J6: =ROUND(SUM(J7:J1981),0) -> 1307
B7: 행운이의 따뜻한 마음이야 | C7: 0 | D7: =C7*0.3 -> 0 | E7: =C7-D7 -> 0 | F7: =E7*0.7 -> 0 | G7: =E7-F7 -> 0 | H7: =G7 -> 0 | I7: =H7*15% -> 0 | J7: =H7*85% -> 0
B8: MC냥은 춤출거야 | C8: 2500 | D8: =C8*0.3 -> 750 | E8: =C8-D8 -> 1750 | F8: =E8*0.7 -> 1225 | G8: =E8-F8 -> 525 | H8: =G8 -> 525 | I8: =H8*15% -> 78.75 | J8: =H8*85% -> 446.25
B9: 반전매력 쫄랑이 | C9: 0 | D9: =C9*0.3 -> 0 | E9: =C9-D9 -> 0 | F9: =E9*0.7 -> 0 | G9: =E9-F9 -> 0 | H9: =G9 -> 0 | I9: =H9*15% -> 0 | J9: =H9*85% -> 0
B10: 크리미프렌즈 | C10: 4823 | D10: =C10*0.3 -> 1446.9 | E10: =C10-D10 -> 3376.1 | F10: =E10*0.7 -> 2363.27 | G10: =E10-F10 -> 1012.83 | H10: =G10 -> 1012.83 | I10: =H10*15% -> 151.9245 | J10: =H10*85% -> 860.9055
D542: =C542-H542 -> 0 | I542: =H542*10% -> 0 | J542: =H542*90% -> 0
D543: =C543-H543 -> 0 | I543: =H543*10% -> 0 | J543: =H543*90% -> 0
D544: =C544-H544 -> 0 | I544: =H544*10% -> 0 | J544: =H544*90% -> 0
D545: =C545-H545 -> 0 | I545: =H545*10% -> 0 | J545: =H545*90% -> 0
D546: =C546-H546 -> 0 | I546: =H546*10% -> 0 | J546: =H546*90% -> 0
D547: =C547-H547 -> 0 | I547: =H547*10% -> 0 | J547: =H547*90% -> 0
D548: =C548-H548 -> 0 | I548: =H548*10% -> 0 | J548: =H548*90% -> 0
D549: =C549-H549 -> 0 | I549: =H549*10% -> 0 | J549: =H549*90% -> 0
D550: =C550-H550 -> 0 | I550: =H550*10% -> 0 | J550: =H550*90% -> 0
D551: =C551-H551 -> 0 | I551: =H551*10% -> 0 | J551: =H551*90% -> 0
D552: =C552-H552 -> 0 | I552: =H552*10% -> 0 | J552: =H552*90% -> 0
D553: =C553-H553 -> 0 | I553: =H553*10% -> 0 | J553: =H553*90% -> 0
... D960: =C960-H960 -> 0 | I960: =H960*10% -> 0 | J960: =H960*90% -> 0
I961: =H961*10% -> 0 | J961: =H961*90% -> 0

Sheet 밴드스티커(작가IP)
B2: 밴드스티커
I3: 0.15 | J3: 0.85
B4: 밴드스티커 11월 매출 (판매용밴드스티커_작가IP) | C4: 결재금액 | D4: 유통사수수료 | H4: 스토리위즈 매출액 | I4: 스토리위즈 수익 | J4: 케이코믹스 수익 | K4: 비고
C5: (VAT포함) | D5: 앱스토어 (30%) | E5: 순매출 | F5: 네이버밴드 (70%) | G5: 정산대상금액 (약30%)
B6: 합계 | C6: =ROUND(SUM(C7:C1981),0) -> 10500 | D6: =ROUND(SUM(D7:D1981),0) -> 3150 | E6: =ROUND(SUM(E7:E1981),0) -> 7350 | F6: =ROUND(SUM(F7:F1981),0) -> 5145 | G6: =ROUND(SUM(G7:G1981),0) -> 2205 | H6: =ROUND(SUM(H7:H1981),0) -> 2205 | I6: =ROUND(SUM(I7:I1981),0) -> 331 | J6: =ROUND(SUM(J7:J1981),0) -> 1874
B7: 감자도리(1종) | C7: =8000 -> 8000 | D7: =C7*0.3 -> 2400 | E7: =C7-D7 -> 5600 | F7: =E7*0.7 -> 3920 | G7: =E7-F7 -> 1680 | H7: =G7 -> 1680 | I7: =H7*15% -> 252 | J7: =H7*85% -> 1428
B8: 송지선(3종) | C8: 2500 | D8: =C8*0.3 -> 750 | E8: =C8-D8 -> 1750 | F8: =E8*0.7 -> 1225 | G8: =E8-F8 -> 525 | H8: =G8 -> 525 | I8: =H8*15% -> 78.75 | J8: =H8*85% -> 446.25
G9: =C9-D9-E9-F9 -> 0
G10: =C10-D10-E10-F10 -> 0
G11: =C11-D11-E11-F11 -> 0
G12: =C12-D12-E12-F12 -> 0
G13: =C13-D13-E13-F13 -> 0
G14: =C14-D14-E14-F14 -> 0
G15: =C15-D15-E15-F15 -> 0
G16: =C16-D16-E16-F16 -> 0
D542: =C542-H542 -> 0 | I542: =H542*10% -> 0 | J542: =H542*90% -> 0
D543: =C543-H543 -> 0 | I543: =H543*10% -> 0 | J543: =H543*90% -> 0
D544: =C544-H544 -> 0 | I544: =H544*10% -> 0 | J544: =H544*90% -> 0
D545: =C545-H545 -> 0 | I545: =H545*10% -> 0 | J545: =H545*90% -> 0
D546: =C546-H546 -> 0 | I546: =H546*10% -> 0 | J546: =H546*90% -> 0
D547: =C547-H547 -> 0 | I547: =H547*10% -> 0 | J547: =H547*90% -> 0
D548: =C548-H548 -> 0 | I548: =H548*10% -> 0 | J548: =H548*90% -> 0
D549: =C549-H549 -> 0 | I549: =H549*10% -> 0 | J549: =H549*90% -> 0
D550: =C550-H550 -> 0 | I550: =H550*10% -> 0 | J550: =H550*90% -> 0
D551: =C551-H551 -> 0 | I551: =H551*10% -> 0 | J551: =H551*90% -> 0
D552: =C552-H552 -> 0 | I552: =H552*10% -> 0 | J552: =H552*90% -> 0
D553: =C553-H553 -> 0 | I553: =H553*10% -> 0 | J553: =H553*90% -> 0
... D960: =C960-H960 -> 0 | I960: =H960*10% -> 0 | J960: =H960*90% -> 0
I961: =H961*10% -> 0 | J961: =H961*90% -> 0
