Workbook
Name raw_a: 전체리스트!$A$2:$F$2827
Name raw_d: 전체리스트!$C$2:$F$2827

Sheet 전체리스트
A1: 사이트명 | B1: 월별 | C1: 작품명 | D1: 총매출 | E1: 순매출 | F1: 환율
A2: 카카오페이지 | B2: 12월분 | C2: 거짓말, 뱀파이어가 어디 있어? [BL] | D2: 634996.8 | E2: 444498
A3: 카카오페이지 | B3: 12월분 | C3: 광속으로 레벨업 | D3: 4835187 | E3: 3384633
A4: 카카오페이지 | B4: 12월분 | C4: 귀신 보는 급식은 퇴마 중입니다 | D4: 429033.8 | E4: 300323
A5: 카카오페이지 | B5: 12월분 | C5: 극한 공녀 | D5: 73972.2 | E5: 51781
A6: 카카오페이지 | B6: 12월분 | C6: 꿈꾸는 먹잇감 | D6: 324635.4 | E6: 227243
A7: 카카오페이지 | B7: 12월분 | C7: 꿰인 사이 | D7: 165445 | E7: 115811
A8: 카카오페이지 | B8: 12월분 | C8: 내 자기님이 로그인 하셨습니다 | D8: 531387.9 | E8: 371971
A9: 카카오페이지 | B9: 12월분 | C9: 너에게만 음성인식 | D9: 701039.3 | E9: 490729
A10: 카카오페이지 | B10: 12월분 | C10: 네게 취한 날들 | D10: 668745.9 | E10: 468124
A11: 카카오페이지 | B11: 12월분 | C11: 대표님, 사모님이 도망가요 | D11: 214639.2 | E11: 150248
A12: 카카오페이지 | B12: 12월분 | C12: 대표님, 오늘은 아니에요 | D12: 416774.2 | E12: 291742
A13: 카카오페이지 | B13: 12월분 | C13: 도군 | D13: 291315.7 | E13: 203921
... A68: 카카오 타파스 | B68: 11월분 | C68: 내 자기님이 로그인하셨습니다 | D68: 806182 | E68: 806182
N69: .
A71: 레진코믹스 | B71: 12월분 | C71: 슬기로운 생활 | D71: 2100 | E71: 2100
A72: 레진코믹스 | B72: 12월분 | C72: 쌀툰 | D72: 3150 | E72: 3150
A73: 레진코믹스 | B73: 12월분 | C73: 멍멍이와 주인님 | D73: 140 | E73: 140
A74: 레진코믹스 | B74: 12월분 | C74: 옆집 최애 | D74: 12040 | E74: 12040
A75: 레진코믹스 | B75: 12월분 | C75: 한집 두 살림 | D75: 12040 | E75: 12040
A76: 레진코믹스 | B76: 12월분 | C76: 사랑과 우정 사이에서 | D76: 17360 | E76: 17360
A77: 레진코믹스 | B77: 12월분 | C77: 내 자기님이 로그인 하셨습니다 | D77: 14000 | E77: 14000
A78: 레진코믹스 | B78: 12월분 | C78: 호랑이 장가 드는 날 | D78: 64200 | E78: 64200
A79: 레진코믹스 | B79: 12월분 | C79: 호랑이 장가 드는 날 [개정판] | D79: 17200 | E79: 17200
A80: 레진코믹스 | B80: 12월분 | C80: 파쿠리인 내가 어시를 | D80: 9150 | E80: 9150
A81: 레진코믹스 | B81: 12월분 | C81: 츤데레 흥신소 | D81: 9750 | E81: 9750
A82: 레진코믹스 | B82: 12월분 | C82: 사랑할 수 없는 그녀 | D82: 426636 | E82: 426636
... A134: 봄툰_유통1 | B134: 10월분 | C134: 페티쉬 BL 단편선 | D134: 420 | E134: 420
A135: 봄툰 | B135: 11월분 | C135: 망나니 도련님 조교일지 | D135: 131339 | E135: 131339 | G135: * 같은이름 같은 유통사 주의
A136: 봄툰 | B136: 11월분 | C136: 사랑할 수 없는 그녀 | D136: 62629 | E136: 62629 | G136: - 유통사 이름 변경 (예. 봄툰_유통1.2.3)
A137: 봄툰 | B137: 11월분 | C137: 슬기로운 생활(완결) | D137: 1890 | E137: 1890
A138: 봄툰 | B138: 11월분 | C138: 아랫집 웬수 | D138: 23101 | E138: 23101
A139: 봄툰 | B139: 11월분 | C139: 악마와 나 사이에는 | D139: 227 | E139: 227
A140: 봄툰 | B140: 11월분 | C140: 옆집 최애 | D140: 8748 | E140: 8748
A141: 봄툰 | B141: 11월분 | C141: 파쿠리인 내가 어시를?! | D141: 11081 | E141: 11081
A142: 봄툰 | B142: 11월분 | C142: 페티쉬 BL 단편선 | D142: 15579 | E142: 15579
A143: 봄툰 | B143: 11월분 | C143: 한집 두 살림 | D143: 8672 | E143: 8672
A144: 봄툰 | B144: 11월분 | C144: 호랑이 장가드는 날 | D144: 18436 | E144: 18436
A145: 봄툰 | B145: 11월분 | C145: 이혼신청 | D145: 990090 | E145: 990090
A146: 봄툰 | B146: 11월분 | C146: 집착공의 인형놀이 | D146: 654210 | E146: 654210
...

Sheet 합계
C2: ■ 스토리숲 22년 12월 (주)스토리위즈 정산서
C3: **판매월 12월1일~12월31일 기준
C5: RS 정산 기준, MG 미포함 | L5: 0.12
C6: 사이트명 | D6: 소비자매출액 | E6: 유통사수수료 | F6: 스토리위즈매출액 | G6: 스토리위즈수익 | H6: 스토리숲 수익 | I6: 비고 | K6: 선지급금 | L6: 500000000
B7: =COUNTA(INDIRECT(C7&"!B:B")) -> 67 | C7: 카카오페이지 | D7: =INDIRECT(C7 & "!E" & B7+3) -> 62185102 | E7: =INDIRECT(C7 & "!F" & B7+3) -> 19540170 | F7: =INDIRECT(C7 & "!G" & B7+3) -> 42644932 | G7: =INDIRECT(C7 & "!H" & B7+3) -> 2132246.6 | H7: =INDIRECT(C7 & "!I" & B7+3) -> 40512685 | K7: KT프로젝트수익 | L7: 60000000 | N7: =L7/L6 -> 0.12
B8: =COUNTA(INDIRECT(C8&"!B:B")) -> 5 | C8: 카카오타파스 | D8: =INDIRECT(C8 & "!E" & B8+3) -> 868220 | E8: =INDIRECT(C8 & "!F" & B8+3) -> 0 | F8: =INDIRECT(C8 & "!G" & B8+3) -> 868220 | G8: =INDIRECT(C8 & "!H" & B8+3) -> 43411 | H8: =INDIRECT(C8 & "!I" & B8+3) -> 824809 | I8: 분기정산
B9: =COUNTA(INDIRECT(C9&"!B:B")) -> 80 | C9: 네이버웹툰 | D9: =INDIRECT(C9 & "!E" & B9+3) -> 1.2243156e+08 | E9: =INDIRECT(C9 & "!F" & B9+3) -> 28445742 | F9: =INDIRECT(C9 & "!G" & B9+3) -> 93985814 | G9: =INDIRECT(C9 & "!H" & B9+3) -> 4699290.7 | H9: =INDIRECT(C9 & "!I" & B9+3) -> 89286523
B10: =COUNTA(INDIRECT(C10&"!B:B")) -> 10 | C10: 콰이칸_중국 | D10: =F10 -> 566686.48 | E10: =INDIRECT(C10 & "!F" & B10+3) -> 0 | F10: =INDIRECT(C10 & "!G" & B10+3) -> 566686.48 | G10: =INDIRECT(C10 & "!H" & B10+3) -> 28334.324 | H10: =INDIRECT(C10 & "!I" & B10+3) -> 538352.16 | I10: V | K10: 월별 회수금 (케이티 수익)
B11: =COUNTA(INDIRECT(C11&"!B:B")) -> 1 | C11: kt_alpha | I11: 계약 만료 | K11: 2021.05 | L11: 38491275 | N11: 8/10송금
B12: =COUNTA(INDIRECT(C12&"!B:B")) -> 52 | C12: 레진코믹스 | D12: =INDIRECT(C12 & "!E" & B12+3) -> 10858028 | E12: =INDIRECT(C12 & "!F" & B12+3) -> 0 | F12: =INDIRECT(C12 & "!G" & B12+3) -> 10858028 | G12: =INDIRECT(C12 & "!H" & B12+3) -> 542901.4 | H12: =INDIRECT(C12 & "!I" & B12+3) -> 10315127 | K12: 2021.06 | L12: 40614671 | N12: 9/10송금
B13: =COUNTA(INDIRECT(C13&"!B:B")) -> 14 | C13: 북큐브 | D13: =INDIRECT(C13 & "!E" & B13+3) -> 591900 | E13: =INDIRECT(C13 & "!F" & B13+3) -> 177570 | F13: =INDIRECT(C13 & "!G" & B13+3) -> 414330 | G13: =INDIRECT(C13 & "!H" & B13+3) -> 20716.5 | H13: =INDIRECT(C13 & "!I" & B13+3) -> 393613.5 | K13: 2021.07 | L13: 38906565 | N13: 10/8송금
B14: =COUNTA(INDIRECT(C14&"!B:B")) -> 21 | C14: 탑툰 | D14: =INDIRECT(C14 & "!E" & B14+3) -> 3906249 | E14: =INDIRECT(C14 & "!F" & B14+3) -> 0 | F14: =INDIRECT(C14 & "!G" & B14+3) -> 3906249 | G14: =INDIRECT(C14 & "!H" & B14+3) -> 195312.45 | H14: =INDIRECT(C14 & "!I" & B14+3) -> 3710936.6 | K14: 2021.08 | L14: 40116328 | N14: 11/10송금
B15: =COUNTA(INDIRECT(C15&"!B:B")) -> 45 | C15: 봄툰 | D15: =INDIRECT(C15 & "!E" & B15+3) -> 3324770 | E15: =INDIRECT(C15 & "!F" & B15+3) -> 0 | F15: =INDIRECT(C15 & "!G" & B15+3) -> 3324770 | G15: =INDIRECT(C15 & "!H" & B15+3) -> 166238.5 | H15: =INDIRECT(C15 & "!I" & B15+3) -> 3158531.5 | K15: 2021.09 | L15: 34882157 | N15: 12/10송금
B16: =COUNTA(INDIRECT(C16&"!B:B")) -> 89 | C16: 애니툰 | D16: =INDIRECT(C16 & "!E" & B16+3) -> 4468128.6 | E16: =INDIRECT(C16 & "!F" & B16+3) -> 0 | F16: =INDIRECT(C16 & "!G" & B16+3) -> 4468128.6 | G16: =INDIRECT(C16 & "!H" & B16+3) -> 223406.43 | H16: =INDIRECT(C16 & "!I" & B16+3) -> 4244722.2 | K16: 2021.1 | L16: 33253241 | N16: 1/10송금
B17: =COUNTA(INDIRECT(C17&"!B:B")) -> 40 | C17: 코미코_한국 | D17: =INDIRECT(C17 & "!E" & B17+3) -> 3928418 | E17: =INDIRECT(C17 & "!F" & B17+3) -> 1809202 | F17: =INDIRECT(C17 & "!G" & B17+3) -> 2119216 | G17: =INDIRECT(C17 & "!H" & B17+3) -> 105960.8 | H17: =INDIRECT(C17 & "!I" & B17+3) -> 2013255.2 | K17: 2021.11 | L17: 30199565 | N17: 2/10송금
B18: =COUNTA(INDIRECT(C18&"!B:B")) -> 9 | C18: 포켓코믹스 | D18: =INDIRECT(C18 & "!E" & B18+3) -> 820056 | E18: =INDIRECT(C18 & "!F" & B18+3) -> 0 | F18: =INDIRECT(C18 & "!G" & B18+3) -> 820056 | G18: =INDIRECT(C18 & "!H" & B18+3) -> 41002.8 | H18: =INDIRECT(C18 & "!I" & B18+3) -> 779053.2 | K18: 2021.12 | L18: 31091642 | N18: 3/10송금
B19: =COUNTA(INDIRECT(C19&"!B:B")) -> 54 | C19: 리디북스 | D19: =INDIRECT(C19 & "!E" & B19+3) -> 6568466 | E19: =INDIRECT(C19 & "!F" & B19+3) -> 0 | F19: =INDIRECT(C19 & "!G" & B19+3) -> 6568466 | G19: =INDIRECT(C19 & "!H" & B19+3) -> 328423.3 | H19: =INDIRECT(C19 & "!I" & B19+3) -> 6240042.7 | K19: 2021년 합계 | L19: =SUM(L11:L18) -> 2.8755544e+08
B20: =COUNTA(INDIRECT(C20&"!B:B")) -> 14 | C20: 조아라 | D20: =INDIRECT(C20 & "!E" & B20+3) -> 530300 | E20: =INDIRECT(C20 & "!F" & B20+3) -> 180302 | F20: =INDIRECT(C20 & "!G" & B20+3) -> 349998 | G20: =INDIRECT(C20 & "!H" & B20+3) -> 17499.9 | H20: =INDIRECT(C20 & "!I" & B20+3) -> 332498.1 | K20: 2022.01 | L20: 13657156 | N20: 4/8송금
B21: =COUNTA(INDIRECT(C21&"!B:B")) -> 12 | C21: 위코믹스_태국 | D21: =INDIRECT(C21 & "!E" & B21+3) -> 41.79 | E21: =INDIRECT(C21 & "!F" & B21+3) -> 0 | F21: =INDIRECT(C21 & "!G" & B21+3) -> 57181.257 | G21: =INDIRECT(C21 & "!H" & B21+3) -> 2859.0628 | H21: =INDIRECT(C21 & "!I" & B21+3) -> 54322.194 | I21: V | K21: 2022.02 | L21: 14815344 | N21: 5/10송금
B22: =COUNTA(INDIRECT(C22&"!B:B")) -> 20 | C22: 태피툰_영어 | D22: =INDIRECT(C22 & "!E" & B22+3) -> 10846800 | E22: =INDIRECT(C22 & "!F" & B22+3) -> 0 | F22: =INDIRECT(C22 & "!G" & B22+3) -> 10846800 | G22: =INDIRECT(C22 & "!H" & B22+3) -> 542340 | H22: =INDIRECT(C22 & "!I" & B22+3) -> 10304460 | K22: 2022.03 | L22: 13280075 | N22: 6/10송금
B23: =COUNTA(INDIRECT(C23&"!B:B")) -> 22 | C23: 델리툰 | D23: =INDIRECT(C23 & "!E" & B23+3) -> 1951265 | E23: =INDIRECT(C23 & "!F" & B23+3) -> 0 | F23: =INDIRECT(C23 & "!G" & B23+3) -> 1951265 | G23: =INDIRECT(C23 & "!H" & B23+3) -> 97563.25 | H23: =INDIRECT(C23 & "!I" & B23+3) -> 1853701.8 | K23: 2022.04 | L23: 14485385 | N23: 7/10송금
B24: =COUNTA(INDIRECT(C24&"!B:B")) -> 21 | C24: 픽코마_일본 | D24: =INDIRECT(C24 & "!E" & B24+3) -> 12060379 | E24: =INDIRECT(C24 & "!F" & B24+3) -> 0 | F24: =INDIRECT(C24 & "!G" & B24+3) -> 12060379 | G24: =INDIRECT(C24 & "!H" & B24+3) -> 603018.95 | H24: =INDIRECT(C24 & "!I" & B24+3) -> 11457360 | K24: 2022.05 | L24: 12780778 | N24: 8/10송금
B25: =COUNTA(INDIRECT(C25&"!B:B")) -> 13 | C25: 픽코마_동영상 | D25: =INDIRECT(C25 & "!E" & B25+3) -> 135279 | E25: =INDIRECT(C25 & "!F" & B25+3) -> 0 | F25: =INDIRECT(C25 & "!G" & B25+3) -> 135279 | G25: =INDIRECT(C25 & "!H" & B25+3) -> 6763.95 | H25: =INDIRECT(C25 & "!I" & B25+3) -> 128515.05 | K25: 2022.06 | L25: 13025700 | N25: 9/10송금
B26: =COUNTA(INDIRECT(C26&"!B:B")) -> 13 | C26: 코미코_태국 | D26: =INDIRECT(C26 & "!E" & B26+3) -> 14094.086 | E26: =INDIRECT(C26 & "!F" & B26+3) -> 0 | F26: =INDIRECT(C26 & "!G" & B26+3) -> 530360.46 | G26: =INDIRECT(C26 & "!H" & B26+3) -> 26518.023 | H26: =INDIRECT(C26 & "!I" & B26+3) -> 503842.43 | I26: V | K26: 2022.07 | L26: 12633543 | N26: 10/7송금
B27: =COUNTA(INDIRECT(C27&"!B:B")) -> 4 | C27: 코미코_일본_대만 | D27: =INDIRECT(C27 & "!E" & B27+3) -> 2051.1 | E27: =INDIRECT(C27 & "!F" & B27+3) -> 0 | F27: =INDIRECT(C27 & "!G" & B27+3) -> 19608.516 | G27: =INDIRECT(C27 & "!H" & B27+3) -> 980.4258 | H27: =INDIRECT(C27 & "!I" & B27+3) -> 18628.09 | I27: v | K27: 2022.08 | L27: 13997325 | N27: 11/10송금
B28: =COUNTA(INDIRECT(C28&"!B:B")) -> 55 | C28: 미스터블루 | D28: =INDIRECT(C28 & "!E" & B28+3) -> 15320968 | E28: =INDIRECT(C28 & "!F" & B28+3) -> 6114605 | F28: =INDIRECT(C28 & "!G" & B28+3) -> 9206363 | G28: =INDIRECT(C28 & "!H" & B28+3) -> 460318.15 | H28: =INDIRECT(C28 & "!I" & B28+3) -> 8746044.9 | K28: 2022.09 | L28: 14147654 | N28: 12/9 송금
B29: =COUNTA(INDIRECT(C29&"!B:B")) -> 40 | C29: 피너툰 | D29: =INDIRECT(C29 & "!E" & B29+3) -> 43467060 | E29: =INDIRECT(C29 & "!F" & B29+3) -> 17386824 | F29: =INDIRECT(C29 & "!G" & B29+3) -> 26080236 | G29: =INDIRECT(C29 & "!H" & B29+3) -> 1304011.8 | H29: =INDIRECT(C29 & "!I" & B29+3) -> 24776224 | K29: 2022.1 | L29: 13936551 | N29: 1/10 송금
B30: =COUNTA(INDIRECT(C30&"!B:B")) -> 46 | C30: 원스토어 | D30: =INDIRECT(C30 & "!E" & B30+3) -> 2636663.4 | E30: =INDIRECT(C30 & "!F" & B30+3) -> 0 | F30: =INDIRECT(C30 & "!G" & B30+3) -> 2636663.4 | G30: =INDIRECT(C30 & "!H" & B30+3) -> 131833.17 | H30: =INDIRECT(C30 & "!I" & B30+3) -> 2504830.2 | K30: 2022.11 | L30: 15531683 | N30: 2/10송금
B31: =COUNTA(INDIRECT(C31&"!B:B")) -> 51 | C31: 투믹스 | D31: =INDIRECT(C31 & "!E" & B31+3) -> 3137517 | E31: =INDIRECT(C31 & "!F" & B31+3) -> 0 | F31: =INDIRECT(C31 & "!G" & B31+3) -> 3137517 | G31: =INDIRECT(C31 & "!H" & B31+3) -> 156875.85 | H31: =INDIRECT(C31 & "!I" & B31+3) -> 2980641.2 | K31: 2022.12 | L31: =G50 -> 12460719
B32: =COUNTA(INDIRECT(C32&"!B:B")) -> 11 | C32: 빌리빌리 | D32: =INDIRECT(C32 & "!E" & B32+3) -> 1102.5244 | E32: =INDIRECT(C32 & "!F" & B32+3) -> 0 | F32: =INDIRECT(C32 & "!G" & B32+3) -> 201982.47 | G32: =INDIRECT(C32 & "!H" & B32+3) -> 10099.123 | H32: =INDIRECT(C32 & "!I" & B32+3) -> 191883.34 | I32: V
B33: =COUNTA(INDIRECT(C33&"!B:B")) -> 21 | C33: INKR | D33: =INDIRECT(C33 & "!E" & B33+3) -> 242.56521 | E33: =INDIRECT(C33 & "!F" & B33+3) -> 0 | F33: =INDIRECT(C33 & "!G" & B33+3) -> 311017.11 | G33: =INDIRECT(C33 & "!H" & B33+3) -> 15550.856 | H33: =INDIRECT(C33 & "!I" & B33+3) -> 295466.26 | I33: V
B34: =COUNTA(INDIRECT(C34&"!B:B")) -> 6 | C34: 타파스 | D34: =INDIRECT(C34 & "!E" & B34+3) -> 0 | E34: =INDIRECT(C34 & "!F" & B34+3) -> 0 | F34: =INDIRECT(C34 & "!G" & B34+3) -> 0 | G34: =INDIRECT(C34 & "!H" & B34+3) -> 0 | H34: =INDIRECT(C34 & "!I" & B34+3) -> 0 | I34: v 분기정산,이월
B35: =COUNTA(INDIRECT(C35&"!B:B")) -> 14 | C35: 코믹툰 | D35: =INDIRECT(C35 & "!E" & B35+3) -> 15616.089 | E35: =INDIRECT(C35 & "!F" & B35+3) -> 0 | F35: =INDIRECT(C35 & "!G" & B35+3) -> 15616.089 | G35: =INDIRECT(C35 & "!H" & B35+3) -> 780.80444 | H35: =INDIRECT(C35 & "!I" & B35+3) -> 14835.284
B36: =COUNTA(INDIRECT(C36&"!B:B")) -> 15 | C36: 코핀코믹스 | D36: =INDIRECT(C36 & "!E" & B36+3) -> 1626715 | E36: =INDIRECT(C36 & "!F" & B36+3) -> 810404 | F36: =INDIRECT(C36 & "!G" & B36+3) -> 816311 | G36: =INDIRECT(C36 & "!H" & B36+3) -> 40815.55 | H36: =INDIRECT(C36 & "!I" & B36+3) -> 775495.45
B37: =COUNTA(INDIRECT(C37&"!B:B")) -> 15 | C37: 예스24 | D37: =INDIRECT(C37 & "!E" & B37+3) -> 65300 | E37: =INDIRECT(C37 & "!F" & B37+3) -> 19590 | F37: =INDIRECT(C37 & "!G" & B37+3) -> 45710 | G37: =INDIRECT(C37 & "!H" & B37+3) -> 2285.5 | H37: =INDIRECT(C37 & "!I" & B37+3) -> 43424.5
B38: =COUNTA(INDIRECT(C38&"!B:B")) -> 36 | C38: 핑거스토리_큐툰 | D38: =INDIRECT(C38 & "!E" & B38+3) -> 1188990 | E38: =INDIRECT(C38 & "!F" & B38+3) -> 475596 | F38: =INDIRECT(C38 & "!G" & B38+3) -> 713394 | G38: =INDIRECT(C38 & "!H" & B38+3) -> 35669.7 | H38: =INDIRECT(C38 & "!I" & B38+3) -> 677724.3
B39: =COUNTA(INDIRECT(C39&"!B:B")) -> 39 | C39: 핑거스토리_무툰 | D39: =INDIRECT(C39 & "!E" & B39+3) -> 3740940 | E39: =INDIRECT(C39 & "!F" & B39+3) -> 1496376 | F39: =INDIRECT(C39 & "!G" & B39+3) -> 2244564 | G39: =INDIRECT(C39 & "!H" & B39+3) -> 112228.2 | H39: =INDIRECT(C39 & "!I" & B39+3) -> 2132335.8
B40: =COUNTA(INDIRECT(C40&"!B:B")) -> 16 | C40: 북팔 | D40: =INDIRECT(C40 & "!E" & B40+3) -> 312100 | E40: =INDIRECT(C40 & "!F" & B40+3) -> 93630 | F40: =INDIRECT(C40 & "!G" & B40+3) -> 218470 | G40: =INDIRECT(C40 & "!H" & B40+3) -> 10923.5 | H40: =INDIRECT(C40 & "!I" & B40+3) -> 207546.5
B41: =COUNTA(INDIRECT(C41&"!B:B")) -> 25 | C41: 엠유네트웍스 | D41: =INDIRECT(C41 & "!E" & B41+3) -> 769770 | E41: =INDIRECT(C41 & "!F" & B41+3) -> 284814.9 | F41: =INDIRECT(C41 & "!G" & B41+3) -> 484955.1 | G41: =INDIRECT(C41 & "!H" & B41+3) -> 24247.755 | H41: =INDIRECT(C41 & "!I" & B41+3) -> 460707.34
B42: =COUNTA(INDIRECT(C42&"!B:B")) -> 9 | C42: 엠스토리링크 | D42: =INDIRECT(C42 & "!E" & B42+3) -> 653.5392 | E42: =INDIRECT(C42 & "!F" & B42+3) -> 0 | F42: =INDIRECT(C42 & "!G" & B42+3) -> 653.5392 | G42: =INDIRECT(C42 & "!H" & B42+3) -> 32.67696 | H42: =INDIRECT(C42 & "!I" & B42+3) -> 620.86224
...

Sheet 카카오페이지
B4: [RS 정산 기준]
B5: 사이트명 | C5: 매출월 | D5: 작품명 | E5: 소비자매출액 | F5: 유통사수수료 | G5: 스토리위즈매출액 | H5: 스토리위즈수익 | I5: 스토리숲 수익 | J5: 비고
B6: 카카오페이지 | C6: =VLOOKUP(B6,raw_a,2,0) -> 12월분 | D6: 거짓말, 뱀파이어가 어디 있어? [BL] | E6: =SUMIFS(전체리스트!D:D,전체리스트!A:A,B6,전체리스트!C:C,D6) -> 634996.8 | F6: =E6-G6 -> 190498.8 | G6: =SUMIFS(전체리스트!E:E,전체리스트!A:A,B6,전체리스트!C:C,D6) -> 444498 | H6: =G6*0.05 -> 22224.9 | I6: =G6-H6 -> 422273.1
B7: 카카오페이지 | C7: =VLOOKUP(B7,raw_a,2,0) -> 12월분 | D7: 광속으로 레벨업 | E7: =SUMIFS(전체리스트!D:D,전체리스트!A:A,B7,전체리스트!C:C,D7) -> 4835187 | F7: =E7-G7 -> 1450554 | G7: =SUMIFS(전체리스트!E:E,전체리스트!A:A,B7,전체리스트!C:C,D7) -> 3384633 | H7: =G7*0.05 -> 169231.65 | I7: =G7-H7 -> 3215401.4
B8: 카카오페이지 | C8: =VLOOKUP(B8,raw_a,2,0) -> 12월분 | D8: 귀신 보는 급식은 퇴마 중입니다 | E8: =SUMIFS(전체리스트!D:D,전체리스트!A:A,B8,전체리스트!C:C,D8) -> 429033.8 | F8: =E8-G8 -> 128710.8 | G8: =SUMIFS(전체리스트!E:E,전체리스트!A:A,B8,전체리스트!C:C,D8) -> 300323 | H8: =G8*0.05 -> 15016.15 | I8: =G8-H8 -> 285306.85
B9: 카카오페이지 | C9: =VLOOKUP(B9,raw_a,2,0) -> 12월분 | D9: 꿈꾸는 먹잇감 | E9: =SUMIFS(전체리스트!D:D,전체리스트!A:A,B9,전체리스트!C:C,D9) -> 324635.4 | F9: =E9-G9 -> 97392.4 | G9: =SUMIFS(전체리스트!E:E,전체리스트!A:A,B9,전체리스트!C:C,D9) -> 227243 | H9: =G9*0.05 -> 11362.15 | I9: =G9-H9 -> 215880.85
B10: 카카오페이지 | C10: =VLOOKUP(B10,raw_a,2,0) -> 12월분 | D10: 꿰인 사이 | E10: =SUMIFS(전체리스트!D:D,전체리스트!A:A,B10,전체리스트!C:C,D10) -> 165445 | F10: =E10-G10 -> 49634 | G10: =SUMIFS(전체리스트!E:E,전체리스트!A:A,B10,전체리스트!C:C,D10) -> 115811 | H10: =G10*0.05 -> 5790.55 | I10: =G10-H10 -> 110020.45
B11: 카카오페이지 | C11: =VLOOKUP(B11,raw_a,2,0) -> 12월분 | D11: 내 자기님이 로그인 하셨습니다 | E11: =SUMIFS(전체리스트!D:D,전체리스트!A:A,B11,전체리스트!C:C,D11) -> 531387.9 | F11: =E11-G11 -> 159416.9 | G11: =SUMIFS(전체리스트!E:E,전체리스트!A:A,B11,전체리스트!C:C,D11) -> 371971 | H11: =G11*0.05 -> 18598.55 | I11: =G11-H11 -> 353372.45
B12: 카카오페이지 | C12: =VLOOKUP(B12,raw_a,2,0) -> 12월분 | D12: 너에게만 음성인식 | E12: =SUMIFS(전체리스트!D:D,전체리스트!A:A,B12,전체리스트!C:C,D12) -> 701039.3 | F12: =E12-G12 -> 210310.3 | G12: =SUMIFS(전체리스트!E:E,전체리스트!A:A,B12,전체리스트!C:C,D12) -> 490729 | H12: =G12*0.05 -> 24536.45 | I12: =G12-H12 -> 466192.55
B13: 카카오페이지 | C13: =VLOOKUP(B13,raw_a,2,0) -> 12월분 | D13: 네게 취한 날들 | E13: =SUMIFS(전체리스트!D:D,전체리스트!A:A,B13,전체리스트!C:C,D13) -> 668745.9 | F13: =E13-G13 -> 200621.9 | G13: =SUMIFS(전체리스트!E:E,전체리스트!A:A,B13,전체리스트!C:C,D13) -> 468124 | H13: =G13*0.05 -> 23406.2 | I13: =G13-H13 -> 444717.8
B14: 카카오페이지 | C14: =VLOOKUP(B14,raw_a,2,0) -> 12월분 | D14: 대표님, 사모님이 도망가요 | E14: =SUMIFS(전체리스트!D:D,전체리스트!A:A,B14,전체리스트!C:C,D14) -> 214639.2 | F14: =E14-G14 -> 64391.2 | G14: =SUMIFS(전체리스트!E:E,전체리스트!A:A,B14,전체리스트!C:C,D14) -> 150248 | H14: =G14*0.05 -> 7512.4 | I14: =G14-H14 -> 142735.6
B15: 카카오페이지 | C15: =VLOOKUP(B15,raw_a,2,0) -> 12월분 | D15: 대표님, 오늘은 아니에요 | E15: =SUMIFS(전체리스트!D:D,전체리스트!A:A,B15,전체리스트!C:C,D15) -> 416774.2 | F15: =E15-G15 -> 125032.2 | G15: =SUMIFS(전체리스트!E:E,전체리스트!A:A,B15,전체리스트!C:C,D15) -> 291742 | H15: =G15*0.05 -> 14587.1 | I15: =G15-H15 -> 277154.9
B16: 카카오페이지 | C16: =VLOOKUP(B16,raw_a,2,0) -> 12월분 | D16: 도군 | E16: =SUMIFS(전체리스트!D:D,전체리스트!A:A,B16,전체리스트!C:C,D16) -> 291315.7 | F16: =E16-G16 -> 87394.7 | G16: =SUMIFS(전체리스트!E:E,전체리스트!A:A,B16,전체리스트!C:C,D16) -> 203921 | H16: =G16*0.05 -> 10196.05 | I16: =G16-H16 -> 193724.95
B17: 카카오페이지 | C17: =VLOOKUP(B17,raw_a,2,0) -> 12월분 | D17: 레벨업에 미친 의사 | E17: =SUMIFS(전체리스트!D:D,전체리스트!A:A,B17,전체리스트!C:C,D17) -> 12824655 | F17: =E17-G17 -> 3847397.7 | G17: =SUMIFS(전체리스트!E:E,전체리스트!A:A,B17,전체리스트!C:C,D17) -> 8977257 | H17: =G17*0.05 -> 448862.85 | I17: =G17-H17 -> 8528394.2
... B68: 카카오웹툰-글로벌 | C68: =VLOOKUP(B68,raw_a,2,0) -> 11월분 | D68: 외나무 다리에 꽃을 뿌려주세요 | E68: =SUMIFS(전체리스트!D:D,전체리스트!A:A,B68,전체리스트!C:C,D68) -> 21927 | F68: =E68-G68 -> 0 | G68: =SUMIFS(전체리스트!E:E,전체리스트!A:A,B68,전체리스트!C:C,D68) -> 21927 | H68: =G68*0.05 -> 1096.35 | I68: =G68-H68 -> 20830.65
B69: 카카오_JV_PODO | C69: =VLOOKUP(B69,raw_a,2,0) -> 10월분 | D69: 외나무 다리에 꽃을 뿌려주세요 | E69: =SUMIFS(전체리스트!D:D,전체리스트!A:A,B69,전체리스트!C:C,D69) -> 109726 | G69: =SUMIFS(전체리스트!E:E,전체리스트!A:A,B69,전체리스트!C:C,D69) -> 109726 | H69: =G69*0.05 -> 5486.3 | I69: =G69-H69 -> 104239.7
B70: 합계 | E70: =SUM(E6:E69) -> 62185102 | F70: =SUM(F6:F69) -> 19540170 | G70: =SUM(G6:G69) -> 42644932 | H70: =SUM(H6:H69) -> 2132246.6 | I70: =SUM(I6:I69) -> 40512685 | J70: =SUM(J6:J68) -> 0

Sheet 카카오타파스
B4: [RS 정산 기준]
B5: 사이트명 | C5: 매출월 | D5: 작품명 | E5: 소비자매출액 | F5: 유통사수수료 | G5: 스토리위즈매출액 | H5: 스토리위즈수익 | I5: 스토리숲 수익 | J5: 비고
B6: 카카오 타파스 | C6: =VLOOKUP(B6,raw_a,2,0) -> 11월분 | D6: 아랫집 웬수 | E6: =SUMIFS(전체리스트!D:D,전체리스트!A:A,B6,전체리스트!C:C,D6) -> 62038 | F6: =E6-G6 -> 0 | G6: =SUMIFS(전체리스트!E:E,전체리스트!A:A,B6,전체리스트!C:C,D6) -> 62038 | H6: =G6*0.05 -> 3101.9 | I6: =G6-H6 -> 58936.1
B7: 카카오 타파스 | C7: =VLOOKUP(B7,raw_a,2,0) -> 11월분 | D7: 내 자기님이 로그인하셨습니다 | E7: =SUMIFS(전체리스트!D:D,전체리스트!A:A,B7,전체리스트!C:C,D7) -> 806182 | F7: =E7-G7 -> 0 | G7: =SUMIFS(전체리스트!E:E,전체리스트!A:A,B7,전체리스트!C:C,D7) -> 806182 | H7: =G7*0.05 -> 40309.1 | I7: =G7-H7 -> 765872.9
B8: 합계 | E8: =SUM(E6:E7) -> 868220 | F8: =SUM(F6:F7) -> 0 | G8: =SUM(G6:G7) -> 868220 | H8: =SUM(H6:H7) -> 43411 | I8: =SUM(I6:I7) -> 824809 | J8: =SUM(J6:J7) -> 0

Sheet 네이버웹툰
B4: [RS 정산 기준]
B5: 사이트명 | C5: 매출월 | D5: 작품명 | E5: 소비자매출액 | F5: 유통사수수료 | G5: 스토리위즈매출액 | H5: 스토리위즈수익 | I5: 스토리숲 수익 | J5: 비고
B6: 네이버웹툰 | C6: =VLOOKUP(B6,raw_a,2,0) -> 12월분 | D6: 레벨업에 미친 의사 | E6: =SUMIFS(전체리스트!D:D,전체리스트!A:A,B6,전체리스트!C:C,D6) -> 1896353.6 | F6: =E6-G6 -> 568906.08 | G6: =SUMIFS(전체리스트!E:E,전체리스트!A:A,B6,전체리스트!C:C,D6) -> 1327447.5 | H6: =G6*0.05 -> 66372.376 | I6: =G6-H6 -> 1261075.1
B7: 네이버웹툰 | C7: =VLOOKUP(B7,raw_a,2,0) -> 12월분 | D7: 이혼신청 [BL] | E7: =SUMIFS(전체리스트!D:D,전체리스트!A:A,B7,전체리스트!C:C,D7) -> 1863997.7 | F7: =E7-G7 -> 559199.31 | G7: =SUMIFS(전체리스트!E:E,전체리스트!A:A,B7,전체리스트!C:C,D7) -> 1304798.4 | H7: =G7*0.05 -> 65239.919 | I7: =G7-H7 -> 1239558.5
B8: 네이버웹툰 | C8: =VLOOKUP(B8,raw_a,2,0) -> 12월분 | D8: 집착공의 인형놀이 [BL] | E8: =SUMIFS(전체리스트!D:D,전체리스트!A:A,B8,전체리스트!C:C,D8) -> 1762382.8 | F8: =E8-G8 -> 528714.84 | G8: =SUMIFS(전체리스트!E:E,전체리스트!A:A,B8,전체리스트!C:C,D8) -> 1233668 | H8: =G8*0.05 -> 61683.398 | I8: =G8-H8 -> 1171984.6
B9: 네이버웹툰 | C9: =VLOOKUP(B9,raw_a,2,0) -> 12월분 | D9: 대표님의 삐뚤어진 사랑 | E9: =SUMIFS(전체리스트!D:D,전체리스트!A:A,B9,전체리스트!C:C,D9) -> 1505312.6 | F9: =E9-G9 -> 451593.78 | G9: =SUMIFS(전체리스트!E:E,전체리스트!A:A,B9,전체리스트!C:C,D9) -> 1053718.8 | H9: =G9*0.05 -> 52685.941 | I9: =G9-H9 -> 1001032.9
B10: 네이버웹툰 | C10: =VLOOKUP(B10,raw_a,2,0) -> 12월분 | D10: 네게 취한 날들 [BL] | E10: =SUMIFS(전체리스트!D:D,전체리스트!A:A,B10,전체리스트!C:C,D10) -> 1187740.6 | F10: =E10-G10 -> 356322.18 | G10: =SUMIFS(전체리스트!E:E,전체리스트!A:A,B10,전체리스트!C:C,D10) -> 831418.42 | H10: =G10*0.05 -> 41570.921 | I10: =G10-H10 -> 789847.5
B11: 네이버웹툰 | C11: =VLOOKUP(B11,raw_a,2,0) -> 12월분 | D11: 학사신공 | E11: =SUMIFS(전체리스트!D:D,전체리스트!A:A,B11,전체리스트!C:C,D11) -> 1138096 | F11: =E11-G11 -> 341428.8 | G11: =SUMIFS(전체리스트!E:E,전체리스트!A:A,B11,전체리스트!C:C,D11) -> 796667.2 | H11: =G11*0.05 -> 39833.36 | I11: =G11-H11 -> 756833.84
B12: 네이버웹툰 | C12: =VLOOKUP(B12,raw_a,2,0) -> 12월분 | D12: 꿈꾸는 먹잇감 [BL] | E12: =SUMIFS(전체리스트!D:D,전체리스트!A:A,B12,전체리스트!C:C,D12) -> 1059344 | F12: =E12-G12 -> 317803.2 | G12: =SUMIFS(전체리스트!E:E,전체리스트!A:A,B12,전체리스트!C:C,D12) -> 741540.8 | H12: =G12*0.05 -> 37077.04 | I12: =G12-H12 -> 704463.76
B13: 네이버웹툰 | C13: =VLOOKUP(B13,raw_a,2,0) -> 12월분 | D13: 극한 공녀 | E13: =SUMIFS(전체리스트!D:D,전체리스트!A:A,B13,전체리스트!C:C,D13) -> 846255.6 | F13: =E13-G13 -> 253876.68 | G13: =SUMIFS(전체리스트!E:E,전체리스트!A:A,B13,전체리스트!C:C,D13) -> 592378.92 | H13: =G13*0.05 -> 29618.946 | I13: =G13-H13 -> 562759.97
B14: 네이버웹툰 | C14: =VLOOKUP(B14,raw_a,2,0) -> 12월분 | D14: 광속으로 레벨업 | E14: =SUMIFS(전체리스트!D:D,전체리스트!A:A,B14,전체리스트!C:C,D14) -> 687850.2 | F14: =E14-G14 -> 206355.06 | G14: =SUMIFS(전체리스트!E:E,전체리스트!A:A,B14,전체리스트!C:C,D14) -> 481495.14 | H14: =G14*0.05 -> 24074.757 | I14: =G14-H14 -> 457420.38
B15: 네이버웹툰 | C15: =VLOOKUP(B15,raw_a,2,0) -> 12월분 | D15: 사랑할 수 없는 그녀 | E15: =SUMIFS(전체리스트!D:D,전체리스트!A:A,B15,전체리스트!C:C,D15) -> 626292.4 | F15: =E15-G15 -> 187887.72 | G15: =SUMIFS(전체리스트!E:E,전체리스트!A:A,B15,전체리스트!C:C,D15) -> 438404.68 | H15: =G15*0.05 -> 21920.234 | I15: =G15-H15 -> 416484.45
B16: 네이버웹툰 | C16: =VLOOKUP(B16,raw_a,2,0) -> 12월분 | D16: 전직고수 | E16: =SUMIFS(전체리스트!D:D,전체리스트!A:A,B16,전체리스트!C:C,D16) -> 544349.2 | F16: =E16-G16 -> 163304.76 | G16: =SUMIFS(전체리스트!E:E,전체리스트!A:A,B16,전체리스트!C:C,D16) -> 381044.44 | H16: =G16*0.05 -> 19052.222 | I16: =G16-H16 -> 361992.22
B17: 네이버웹툰 | C17: =VLOOKUP(B17,raw_a,2,0) -> 12월분 | D17: 대표님, 오늘은 아니에요 | E17: =SUMIFS(전체리스트!D:D,전체리스트!A:A,B17,전체리스트!C:C,D17) -> 525328 | F17: =E17-G17 -> 157598.4 | G17: =SUMIFS(전체리스트!E:E,전체리스트!A:A,B17,전체리스트!C:C,D17) -> 367729.6 | H17: =G17*0.05 -> 18386.48 | I17: =G17-H17 -> 349343.12
... B78: 네이버웹툰-창작지원금 | C78: =VLOOKUP(B78,raw_a,2,0) -> 11월분 | D78: 마녀와 용의 신혼일기 | E78: =SUMIFS(전체리스트!D:D,전체리스트!A:A,B78,전체리스트!C:C,D78) -> 67175 | F78: =E78-G78 -> 0 | G78: =SUMIFS(전체리스트!E:E,전체리스트!A:A,B78,전체리스트!C:C,D78) -> 67175 | H78: =G78*0.05 -> 3358.75 | I78: =G78-H78 -> 63816.25
B79: 네이버웹툰-창작지원금 | C79: 11월분 | D79: 아찔한전남편 | E79: =SUMIFS(전체리스트!D:D,전체리스트!A:A,B79,전체리스트!C:C,D79) -> 25599 | F79: =E79-G79 -> 0 | G79: =SUMIFS(전체리스트!E:E,전체리스트!A:A,B79,전체리스트!C:C,D79) -> 25599 | H79: =G79*0.05 -> 1279.95 | I79: =G79-H79 -> 24319.05
B80: 네이버웹툰-창작지원금 | C80: =VLOOKUP(B80,raw_a,2,0) -> 11월분 | D80: 백설을 위하여 | E80: =SUMIFS(전체리스트!D:D,전체리스트!A:A,B80,전체리스트!C:C,D80) -> 32077 | F80: =E80-G80 -> 0 | G80: =SUMIFS(전체리스트!E:E,전체리스트!A:A,B80,전체리스트!C:C,D80) -> 32077 | H80: =G80*0.05 -> 1603.85 | I80: =G80-H80 -> 30473.15
B81: 네이버웹툰-창작지원금 | C81: =VLOOKUP(B81,raw_a,2,0) -> 11월분 | D81: 영애의경호관 | E81: =SUMIFS(전체리스트!D:D,전체리스트!A:A,B81,전체리스트!C:C,D81) -> 963 | F81: =E81-G81 -> 0 | G81: =SUMIFS(전체리스트!E:E,전체리스트!A:A,B81,전체리스트!C:C,D81) -> 963 | H81: =G81*0.05 -> 48.15 | I81: =G81-H81 -> 914.85
B82: 네이버웹툰-창작지원금 | C82: =VLOOKUP(B82,raw_a,2,0) -> 11월분 | D82: 완벽한 부부는 없다 | E82: =SUMIFS(전체리스트!D:D,전체리스트!A:A,B82,전체리스트!C:C,D82) -> 38040 | F82: =E82-G82 -> 0 | G82: =SUMIFS(전체리스트!E:E,전체리스트!A:A,B82,전체리스트!C:C,D82) -> 38040 | H82: =G82*0.05 -> 1902 | I82: =G82-H82 -> 36138
B83: 합계 | E83: =SUM(E6:E82) -> 1.2243156e+08 | F83: =SUM(F6:F82) -> 28445742 | G83: =SUM(G6:G82) -> 93985814 | H83: =SUM(H6:H82) -> 4699290.7 | I83: =SUM(I6:I82) -> 89286523 | J83: =SUM(J6:J82) -> 0

Sheet 콰이칸_중국
G3: 3개월 평균
B4: [RS 정산 기준] | F4: 환율(CNY) | G4: =VLOOKUP(B6,raw_a,6,0) -> 187.57
B5: 사이트명 | C5: 매출월 | D5: 작품명 | E5: 소비자매출액 | F5: 유통사수수료 | G5: 스토리위즈매출액 | H5: 스토리위즈수익 | I5: 스토리숲 수익 | J5: 비고
B6: 콰이칸 | C6: =VLOOKUP(B6,raw_a,2,0) -> 11월분 | D6: 내 자기님 로그인하셨다 2 | E6: =SUMIFS(전체리스트!D:D,전체리스트!A:A,B6,전체리스트!C:C,D6) -> 1278.99 | G6: =SUMIFS(전체리스트!E:E,전체리스트!A:A,B6,전체리스트!C:C,D6) -> 239900.15 | H6: =G6*0.05 -> 11995.008 | I6: =G6-H6 -> 227905.15
B7: 콰이칸 | C7: =VLOOKUP(B7,raw_a,2,0) -> 11월분 | D7: 사랑과 우정 사이에는 爱情与友谊之间 | E7: =SUMIFS(전체리스트!D:D,전체리스트!A:A,B7,전체리스트!C:C,D7) -> 101.05 | G7: =SUMIFS(전체리스트!E:E,전체리스트!A:A,B7,전체리스트!C:C,D7) -> 18953.948 | H7: =G7*0.05 -> 947.69742 | I7: =G7-H7 -> 18006.251
B8: 콰이칸 | C8: =VLOOKUP(B8,raw_a,2,0) -> 11월분 | D8: 거짓말! 뱀페이어가 어디있어? | E8: =SUMIFS(전체리스트!D:D,전체리스트!A:A,B8,전체리스트!C:C,D8) -> 923.97 | G8: =SUMIFS(전체리스트!E:E,전체리스트!A:A,B8,전체리스트!C:C,D8) -> 173309.05 | H8: =G8*0.05 -> 8665.4526 | I8: =G8-H8 -> 164643.6
B9: 콰이칸 | C9: =VLOOKUP(B9,raw_a,2,0) -> 11월분 | D9: 옆집최애 | E9: =SUMIFS(전체리스트!D:D,전체리스트!A:A,B9,전체리스트!C:C,D9) -> 543.38 | G9: =SUMIFS(전체리스트!E:E,전체리스트!A:A,B9,전체리스트!C:C,D9) -> 101921.79 | H9: =G9*0.05 -> 5096.0893 | I9: =G9-H9 -> 96825.697
B10: 콰이칸 | C10: =VLOOKUP(B10,raw_a,2,0) -> 11월분 | D10: 거짓말 뱀파이어가 어디있어_영상툰 | E10: =SUMIFS(전체리스트!D:D,전체리스트!A:A,B10,전체리스트!C:C,D10) -> 130.84 | G10: =SUMIFS(전체리스트!E:E,전체리스트!A:A,B10,전체리스트!C:C,D10) -> 24541.659 | H10: =G10*0.05 -> 1227.0829 | I10: =G10-H10 -> 23314.576
B11: 콰이칸 | C11: =VLOOKUP(B11,raw_a,2,0) -> 11월분 | D11: 내 자기님이 로그인하셨습니다_영상툰 | E11: =SUMIFS(전체리스트!D:D,전체리스트!A:A,B11,전체리스트!C:C,D11) -> 0.9 | G11: =SUMIFS(전체리스트!E:E,전체리스트!A:A,B11,전체리스트!C:C,D11) -> 168.813 | H11: =G11*0.05 -> 8.44065 | I11: =G11-H11 -> 160.37235
B12: 콰이칸 | C12: =VLOOKUP(B12,raw_a,2,0) -> 11월분 | D12: 아랫집 웬수_영상툰 | E12: =SUMIFS(전체리스트!D:D,전체리스트!A:A,B12,전체리스트!C:C,D12) -> 42.07 | G12: =SUMIFS(전체리스트!E:E,전체리스트!A:A,B12,전체리스트!C:C,D12) -> 7891.0699 | H12: =G12*0.05 -> 394.55349 | I12: =G12-H12 -> 7496.5164
B13: 합계 | E13: =SUM(E6:E12) -> 3021.2 | F13: =SUM(F6:F12) -> 0 | G13: =SUM(G6:G12) -> 566686.48 | H13: =SUM(H6:H12) -> 28334.324 | I13: =SUM(I6:I12) -> 538352.16 | J13: =SUM(J6:J9) -> 0

Sheet 엠스토리링크
B4: [RS 정산 기준]
B5: 사이트명 | C5: 매출월 | D5: 작품명 | E5: 소비자매출액 | F5: 유통사수수료 | G5: 스토리위즈매출액 | H5: 스토리위즈수익 | I5: 스토리숲 수익 | J5: 비고
B6: 엠스토리링크 | C6: 11월분 | D6: 인 유어 드림 | E6: =SUMIFS(전체리스트!D:D,전체리스트!A:A,B6,전체리스트!C:C,D6) -> 85.7696 | F6: =E6-G6 -> 0 | G6: =SUMIFS(전체리스트!E:E,전체리스트!A:A,B6,전체리스트!C:C,D6) -> 85.7696 | H6: =G6*0.05 -> 4.28848 | I6: =G6-H6 -> 81.48112
B7: 엠스토리링크 | C7: 11월분 | D7: 황비님? 황비님! | E7: =SUMIFS(전체리스트!D:D,전체리스트!A:A,B7,전체리스트!C:C,D7) -> 85.7696 | F7: =E7-G7 -> 0 | G7: =SUMIFS(전체리스트!E:E,전체리스트!A:A,B7,전체리스트!C:C,D7) -> 85.7696 | H7: =G7*0.05 -> 4.28848 | I7: =G7-H7 -> 81.48112
B8: 엠스토리링크 | C8: 11월분 | D8: 귀신 보는 공작부인 | E8: =SUMIFS(전체리스트!D:D,전체리스트!A:A,B8,전체리스트!C:C,D8) -> 85 | F8: =E8-G8 -> 0 | G8: =SUMIFS(전체리스트!E:E,전체리스트!A:A,B8,전체리스트!C:C,D8) -> 85 | H8: =G8*0.05 -> 4.25 | I8: =G8-H8 -> 80.75
B9: 엠스토리링크 | C9: 12월분 | D9: 귀신 보는 공작부인-12월 | E9: =SUMIFS(전체리스트!D:D,전체리스트!A:A,B9,전체리스트!C:C,D9) -> 66 | F9: =E9-G9 -> 0 | G9: =SUMIFS(전체리스트!E:E,전체리스트!A:A,B9,전체리스트!C:C,D9) -> 66 | H9: =G9*0.05 -> 3.3 | I9: =G9-H9 -> 62.7
B10: 엠스토리링크 | C10: 12월분 | D10: 인 유어 드림-12월 | E10: =SUMIFS(전체리스트!D:D,전체리스트!A:A,B10,전체리스트!C:C,D10) -> 199 | F10: =E10-G10 -> 0 | G10: =SUMIFS(전체리스트!E:E,전체리스트!A:A,B10,전체리스트!C:C,D10) -> 199 | H10: =G10*0.05 -> 9.95 | I10: =G10-H10 -> 189.05
B11: 엠스토리링크 | C11: 12월분 | D11: 황비님? 황비님!-12월 | E11: =SUMIFS(전체리스트!D:D,전체리스트!A:A,B11,전체리스트!C:C,D11) -> 132 | F11: =E11-G11 -> 0 | G11: =SUMIFS(전체리스트!E:E,전체리스트!A:A,B11,전체리스트!C:C,D11) -> 132 | H11: =G11*0.05 -> 6.6 | I11: =G11-H11 -> 125.4
B12: 합계 | E12: =SUM(E6:E11) -> 653.5392 | F12: =SUM(F6:F11) -> 0 | G12: =SUM(G6:G11) -> 653.5392 | H12: =SUM(H6:H11) -> 32.67696 | I12: =SUM(I6:I11) -> 620.86224 | J12: =SUM(J6:J8) -> 0

Sheet 레진코믹스
B4: [RS 정산 기준]
B5: 사이트명 | C5: 매출월 | D5: 작품명 | E5: 소비자매출액 | F5: 유통사수수료 | G5: 스토리위즈매출액 | H5: 스토리위즈수익 | I5: 스토리숲 수익 | J5: 비고
B6: 레진코믹스 | C6: =VLOOKUP(B6,raw_a,2,0) -> 12월분 | D6: 슬기로운 생활 | E6: =SUMIFS(전체리스트!D:D,전체리스트!A:A,B6,전체리스트!C:C,D6) -> 2100 | F6: =E6-G6 -> 0 | G6: =SUMIFS(전체리스트!E:E,전체리스트!A:A,B6,전체리스트!C:C,D6) -> 2100 | H6: =G6*0.05 -> 105 | I6: =G6-H6 -> 1995
B7: 레진코믹스 | C7: =VLOOKUP(B7,raw_a,2,0) -> 12월분 | D7: 쌀툰 | E7: =SUMIFS(전체리스트!D:D,전체리스트!A:A,B7,전체리스트!C:C,D7) -> 3150 | F7: =E7-G7 -> 0 | G7: =SUMIFS(전체리스트!E:E,전체리스트!A:A,B7,전체리스트!C:C,D7) -> 3150 | H7: =G7*0.05 -> 157.5 | I7: =G7-H7 -> 2992.5
B8: 레진코믹스 | C8: =VLOOKUP(B8,raw_a,2,0) -> 12월분 | D8: 멍멍이와 주인님 | E8: =SUMIFS(전체리스트!D:D,전체리스트!A:A,B8,전체리스트!C:C,D8) -> 140 | F8: =E8-G8 -> 0 | G8: =SUMIFS(전체리스트!E:E,전체리스트!A:A,B8,전체리스트!C:C,D8) -> 140 | H8: =G8*0.05 -> 7 | I8: =G8-H8 -> 133
B9: 레진코믹스 | C9: =VLOOKUP(B9,raw_a,2,0) -> 12월분 | D9: 옆집 최애 | E9: =SUMIFS(전체리스트!D:D,전체리스트!A:A,B9,전체리스트!C:C,D9) -> 12040 | F9: =E9-G9 -> 0 | G9: =SUMIFS(전체리스트!E:E,전체리스트!A:A,B9,전체리스트!C:C,D9) -> 12040 | H9: =G9*0.05 -> 602 | I9: =G9-H9 -> 11438
B10: 레진코믹스 | C10: =VLOOKUP(B10,raw_a,2,0) -> 12월분 | D10: 한집 두 살림 | E10: =SUMIFS(전체리스트!D:D,전체리스트!A:A,B10,전체리스트!C:C,D10) -> 12040 | F10: =E10-G10 -> 0 | G10: =SUMIFS(전체리스트!E:E,전체리스트!A:A,B10,전체리스트!C:C,D10) -> 12040 | H10: =G10*0.05 -> 602 | I10: =G10-H10 -> 11438
B11: 레진코믹스 | C11: =VLOOKUP(B11,raw_a,2,0) -> 12월분 | D11: 사랑과 우정 사이에서 | E11: =SUMIFS(전체리스트!D:D,전체리스트!A:A,B11,전체리스트!C:C,D11) -> 17360 | F11: =E11-G11 -> 0 | G11: =SUMIFS(전체리스트!E:E,전체리스트!A:A,B11,전체리스트!C:C,D11) -> 17360 | H11: =G11*0.05 -> 868 | I11: =G11-H11 -> 16492
B12: 레진코믹스 | C12: =VLOOKUP(B12,raw_a,2,0) -> 12월분 | D12: 내 자기님이 로그인 하셨습니다 | E12: =SUMIFS(전체리스트!D:D,전체리스트!A:A,B12,전체리스트!C:C,D12) -> 14000 | F12: =E12-G12 -> 0 | G12: =SUMIFS(전체리스트!E:E,전체리스트!A:A,B12,전체리스트!C:C,D12) -> 14000 | H12: =G12*0.05 -> 700 | I12: =G12-H12 -> 13300
B13: 레진코믹스 | C13: =VLOOKUP(B13,raw_a,2,0) -> 12월분 | D13: 호랑이 장가 드는 날 | E13: =SUMIFS(전체리스트!D:D,전체리스트!A:A,B13,전체리스트!C:C,D13) -> 64200 | F13: =E13-G13 -> 0 | G13: =SUMIFS(전체리스트!E:E,전체리스트!A:A,B13,전체리스트!C:C,D13) -> 64200 | H13: =G13*0.05 -> 3210 | I13: =G13-H13 -> 60990
B14: 레진코믹스 | C14: =VLOOKUP(B14,raw_a,2,0) -> 12월분 | D14: 호랑이 장가 드는 날 [개정판] | E14: =SUMIFS(전체리스트!D:D,전체리스트!A:A,B14,전체리스트!C:C,D14) -> 17200 | F14: =E14-G14 -> 0 | G14: =SUMIFS(전체리스트!E:E,전체리스트!A:A,B14,전체리스트!C:C,D14) -> 17200 | H14: =G14*0.05 -> 860 | I14: =G14-H14 -> 16340
B15: 레진코믹스 | C15: =VLOOKUP(B15,raw_a,2,0) -> 12월분 | D15: 파쿠리인 내가 어시를 | E15: =SUMIFS(전체리스트!D:D,전체리스트!A:A,B15,전체리스트!C:C,D15) -> 9150 | F15: =E15-G15 -> 0 | G15: =SUMIFS(전체리스트!E:E,전체리스트!A:A,B15,전체리스트!C:C,D15) -> 9150 | H15: =G15*0.05 -> 457.5 | I15: =G15-H15 -> 8692.5
B16: 레진코믹스 | C16: =VLOOKUP(B16,raw_a,2,0) -> 12월분 | D16: 츤데레 흥신소 | E16: =SUMIFS(전체리스트!D:D,전체리스트!A:A,B16,전체리스트!C:C,D16) -> 9750 | F16: =E16-G16 -> 0 | G16: =SUMIFS(전체리스트!E:E,전체리스트!A:A,B16,전체리스트!C:C,D16) -> 9750 | H16: =G16*0.05 -> 487.5 | I16: =G16-H16 -> 9262.5
B17: 레진코믹스 | C17: =VLOOKUP(B17,raw_a,2,0) -> 12월분 | D17: 사랑할 수 없는 그녀 | E17: =SUMIFS(전체리스트!D:D,전체리스트!A:A,B17,전체리스트!C:C,D17) -> 426636 | F17: =E17-G17 -> 0 | G17: =SUMIFS(전체리스트!E:E,전체리스트!A:A,B17,전체리스트!C:C,D17) -> 426636 | H17: =G17*0.05 -> 21331.8 | I17: =G17-H17 -> 405304.2
... B54: 레진코믹스 | C54: =VLOOKUP(B54,raw_a,2,0) -> 12월분 | D54: 도군 [연재] | E54: =SUMIFS(전체리스트!D:D,전체리스트!A:A,B54,전체리스트!C:C,D54) -> 16296 | F54: =E54-G54 -> 0 | G54: =SUMIFS(전체리스트!E:E,전체리스트!A:A,B54,전체리스트!C:C,D54) -> 16296 | H54: =G54*0.05 -> 814.8 | I54: =G54-H54 -> 15481.2
B55: 합계 | E55: =SUM(E6:E54) -> 10858028 | F55: =SUM(F6:F54) -> 0 | G55: =SUM(G6:G54) -> 10858028 | H55: =SUM(H6:H54) -> 542901.4 | I55: =SUM(I6:I54) -> 10315127 | J55: =SUM(J6:J54) -> 0

Sheet 북큐브
B4: [RS 정산 기준]
B5: 사이트명 | C5: 매출월 | D5: 작품명 | E5: 소비자매출액 | F5: 유통사수수료 | G5: 스토리위즈매출액 | H5: 스토리위즈수익 | I5: 스토리숲 수익 | J5: 비고
B6: 북큐브 | C6: =VLOOKUP(B6,raw_a,2,0) -> 12월분 | D6: 거짓말, 뱀파이어가 어디 있어? | E6: =SUMIFS(전체리스트!D:D,전체리스트!A:A,B6,전체리스트!C:C,D6) -> 14800 | F6: =E6-G6 -> 4440 | G6: =SUMIFS(전체리스트!E:E,전체리스트!A:A,B6,전체리스트!C:C,D6) -> 10360 | H6: =G6*0.05 -> 518 | I6: =G6-H6 -> 9842
B7: 북큐브 | C7: =VLOOKUP(B7,raw_a,2,0) -> 12월분 | D7: 꿈꾸는 먹잇감 | E7: =SUMIFS(전체리스트!D:D,전체리스트!A:A,B7,전체리스트!C:C,D7) -> 7600 | F7: =E7-G7 -> 2280 | G7: =SUMIFS(전체리스트!E:E,전체리스트!A:A,B7,전체리스트!C:C,D7) -> 5320 | H7: =G7*0.05 -> 266 | I7: =G7-H7 -> 5054
B8: 북큐브 | C8: =VLOOKUP(B8,raw_a,2,0) -> 12월분 | D8: 꿰인 사이 | E8: =SUMIFS(전체리스트!D:D,전체리스트!A:A,B8,전체리스트!C:C,D8) -> 2200 | F8: =E8-G8 -> 660 | G8: =SUMIFS(전체리스트!E:E,전체리스트!A:A,B8,전체리스트!C:C,D8) -> 1540 | H8: =G8*0.05 -> 77 | I8: =G8-H8 -> 1463
B9: 북큐브 | C9: =VLOOKUP(B9,raw_a,2,0) -> 12월분 | D9: 네게 취한 날들 | E9: =SUMIFS(전체리스트!D:D,전체리스트!A:A,B9,전체리스트!C:C,D9) -> 49200 | F9: =E9-G9 -> 14760 | G9: =SUMIFS(전체리스트!E:E,전체리스트!A:A,B9,전체리스트!C:C,D9) -> 34440 | H9: =G9*0.05 -> 1722 | I9: =G9-H9 -> 32718
B10: 북큐브 | C10: =VLOOKUP(B10,raw_a,2,0) -> 12월분 | D10: 망나니 도련님 조교일지 | E10: =SUMIFS(전체리스트!D:D,전체리스트!A:A,B10,전체리스트!C:C,D10) -> 39300 | F10: =E10-G10 -> 11790 | G10: =SUMIFS(전체리스트!E:E,전체리스트!A:A,B10,전체리스트!C:C,D10) -> 27510 | H10: =G10*0.05 -> 1375.5 | I10: =G10-H10 -> 26134.5
B11: 북큐브 | C11: =VLOOKUP(B11,raw_a,2,0) -> 12월분 | D11: 사랑과 우정 사이에서[성인] | E11: =SUMIFS(전체리스트!D:D,전체리스트!A:A,B11,전체리스트!C:C,D11) -> 17100 | F11: =E11-G11 -> 5130 | G11: =SUMIFS(전체리스트!E:E,전체리스트!A:A,B11,전체리스트!C:C,D11) -> 11970 | H11: =G11*0.05 -> 598.5 | I11: =G11-H11 -> 11371.5
B12: 북큐브 | C12: =VLOOKUP(B12,raw_a,2,0) -> 12월분 | D12: 슬기로운 생활 | E12: =SUMIFS(전체리스트!D:D,전체리스트!A:A,B12,전체리스트!C:C,D12) -> 5800 | F12: =E12-G12 -> 1740 | G12: =SUMIFS(전체리스트!E:E,전체리스트!A:A,B12,전체리스트!C:C,D12) -> 4060 | H12: =G12*0.05 -> 203 | I12: =G12-H12 -> 3857
B13: 북큐브 | C13: =VLOOKUP(B13,raw_a,2,0) -> 12월분 | D13: 아랫집 웬수 | E13: =SUMIFS(전체리스트!D:D,전체리스트!A:A,B13,전체리스트!C:C,D13) -> 19200 | F13: =E13-G13 -> 5760 | G13: =SUMIFS(전체리스트!E:E,전체리스트!A:A,B13,전체리스트!C:C,D13) -> 13440 | H13: =G13*0.05 -> 672 | I13: =G13-H13 -> 12768
B14: 북큐브 | C14: =VLOOKUP(B14,raw_a,2,0) -> 12월분 | D14: 이혼신청 | E14: =SUMIFS(전체리스트!D:D,전체리스트!A:A,B14,전체리스트!C:C,D14) -> 272800 | F14: =E14-G14 -> 81840 | G14: =SUMIFS(전체리스트!E:E,전체리스트!A:A,B14,전체리스트!C:C,D14) -> 190960 | H14: =G14*0.05 -> 9548 | I14: =G14-H14 -> 181412
B15: 북큐브 | C15: =VLOOKUP(B15,raw_a,2,0) -> 12월분 | D15: 집착공의 인형놀이 | E15: =SUMIFS(전체리스트!D:D,전체리스트!A:A,B15,전체리스트!C:C,D15) -> 152500 | F15: =E15-G15 -> 45750 | G15: =SUMIFS(전체리스트!E:E,전체리스트!A:A,B15,전체리스트!C:C,D15) -> 106750 | H15: =G15*0.05 -> 5337.5 | I15: =G15-H15 -> 101412.5
B16: 북큐브 | C16: =VLOOKUP(B16,raw_a,2,0) -> 12월분 | D16: 한번 해볼래? | E16: =SUMIFS(전체리스트!D:D,전체리스트!A:A,B16,전체리스트!C:C,D16) -> 11400 | F16: =E16-G16 -> 3420 | G16: =SUMIFS(전체리스트!E:E,전체리스트!A:A,B16,전체리스트!C:C,D16) -> 7980 | H16: =G16*0.05 -> 399 | I16: =G16-H16 -> 7581
B17: 합계 | E17: =SUM(E6:E16) -> 591900 | F17: =SUM(F6:F16) -> 177570 | G17: =SUM(G6:G16) -> 414330 | H17: =SUM(H6:H16) -> 20716.5 | I17: =SUM(I6:I16) -> 393613.5 | J17: =SUM(J6:J16) -> 0

Sheet 탑툰
B4: [RS 정산 기준]
B5: 사이트명 | C5: 매출월 | D5: 작품명 | E5: 소비자매출액 | F5: 유통사수수료 | G5: 스토리위즈매출액 | H5: 스토리위즈수익 | I5: 스토리숲 수익 | J5: 비고
B6: 탑툰 | C6: =VLOOKUP(B6,raw_a,2,0) -> 11월분 | D6: 속도위반 대표님과 계약 아내 | E6: =SUMIFS(전체리스트!D:D,전체리스트!A:A,B6,전체리스트!C:C,D6) -> 395514 | F6: =E6-G6 -> 0 | G6: =SUMIFS(전체리스트!E:E,전체리스트!A:A,B6,전체리스트!C:C,D6) -> 395514 | H6: =G6*0.05 -> 19775.7 | I6: =G6-H6 -> 375738.3
B7: 탑툰 | C7: =VLOOKUP(B7,raw_a,2,0) -> 11월분 | D7: 사랑할 수 없는 그녀 | E7: =SUMIFS(전체리스트!D:D,전체리스트!A:A,B7,전체리스트!C:C,D7) -> 729 | F7: =E7-G7 -> 0 | G7: =SUMIFS(전체리스트!E:E,전체리스트!A:A,B7,전체리스트!C:C,D7) -> 729 | H7: =G7*0.05 -> 36.45 | I7: =G7-H7 -> 692.55
B8: 탑툰 | C8: =VLOOKUP(B8,raw_a,2,0) -> 11월분 | D8: 대표님의 삐뚤어진 사랑 | E8: =SUMIFS(전체리스트!D:D,전체리스트!A:A,B8,전체리스트!C:C,D8) -> 474759 | F8: =E8-G8 -> 0 | G8: =SUMIFS(전체리스트!E:E,전체리스트!A:A,B8,전체리스트!C:C,D8) -> 474759 | H8: =G8*0.05 -> 23737.95 | I8: =G8-H8 -> 451021.05
B9: 탑툰 | C9: =VLOOKUP(B9,raw_a,2,0) -> 11월분 | D9: 대표님, 사모님이 도망가요 | E9: =SUMIFS(전체리스트!D:D,전체리스트!A:A,B9,전체리스트!C:C,D9) -> 45846 | F9: =E9-G9 -> 0 | G9: =SUMIFS(전체리스트!E:E,전체리스트!A:A,B9,전체리스트!C:C,D9) -> 45846 | H9: =G9*0.05 -> 2292.3 | I9: =G9-H9 -> 43553.7
B10: 탑툰 | C10: =VLOOKUP(B10,raw_a,2,0) -> 11월분 | D10: 너에게만 음성인식 | E10: =SUMIFS(전체리스트!D:D,전체리스트!A:A,B10,전체리스트!C:C,D10) -> 14229 | F10: =E10-G10 -> 0 | G10: =SUMIFS(전체리스트!E:E,전체리스트!A:A,B10,전체리스트!C:C,D10) -> 14229 | H10: =G10*0.05 -> 711.45 | I10: =G10-H10 -> 13517.55
B11: 탑툰 | C11: =VLOOKUP(B11,raw_a,2,0) -> 11월분 | D11: 만지고 싶어 | E11: =SUMIFS(전체리스트!D:D,전체리스트!A:A,B11,전체리스트!C:C,D11) -> 23166 | F11: =E11-G11 -> 0 | G11: =SUMIFS(전체리스트!E:E,전체리스트!A:A,B11,전체리스트!C:C,D11) -> 23166 | H11: =G11*0.05 -> 1158.3 | I11: =G11-H11 -> 22007.7
B12: 탑툰 | C12: =VLOOKUP(B12,raw_a,2,0) -> 11월분 | D12: 레벨업에 미친 의사 | E12: =SUMIFS(전체리스트!D:D,전체리스트!A:A,B12,전체리스트!C:C,D12) -> 1753587 | F12: =E12-G12 -> 0 | G12: =SUMIFS(전체리스트!E:E,전체리스트!A:A,B12,전체리스트!C:C,D12) -> 1753587 | H12: =G12*0.05 -> 87679.35 | I12: =G12-H12 -> 1665907.6
B13: 탑툰 | C13: =VLOOKUP(B13,raw_a,2,0) -> 11월분 | D13: 전설 헌터로 키워지는 중입니다 | E13: =SUMIFS(전체리스트!D:D,전체리스트!A:A,B13,전체리스트!C:C,D13) -> 257976 | F13: =E13-G13 -> 0 | G13: =SUMIFS(전체리스트!E:E,전체리스트!A:A,B13,전체리스트!C:C,D13) -> 257976 | H13: =G13*0.05 -> 12898.8 | I13: =G13-H13 -> 245077.2
B14: 탑툰 | C14: =VLOOKUP(B14,raw_a,2,0) -> 11월분 | D14: 대표님, 오늘은 아니에요 | E14: =SUMIFS(전체리스트!D:D,전체리스트!A:A,B14,전체리스트!C:C,D14) -> 45572 | F14: =E14-G14 -> 0 | G14: =SUMIFS(전체리스트!E:E,전체리스트!A:A,B14,전체리스트!C:C,D14) -> 45572 | H14: =G14*0.05 -> 2278.6 | I14: =G14-H14 -> 43293.4
B15: 탑툰 | C15: =VLOOKUP(B15,raw_a,2,0) -> 11월분 | D15: 용의주도 대표님의 연애 게임 | E15: =SUMIFS(전체리스트!D:D,전체리스트!A:A,B15,전체리스트!C:C,D15) -> 20606 | F15: =E15-G15 -> 0 | G15: =SUMIFS(전체리스트!E:E,전체리스트!A:A,B15,전체리스트!C:C,D15) -> 20606 | H15: =G15*0.05 -> 1030.3 | I15: =G15-H15 -> 19575.7
B16: 탑툰 | C16: =VLOOKUP(B16,raw_a,2,0) -> 11월분 | D16: 호감도가 오르면 | E16: =SUMIFS(전체리스트!D:D,전체리스트!A:A,B16,전체리스트!C:C,D16) -> 56073 | F16: =E16-G16 -> 0 | G16: =SUMIFS(전체리스트!E:E,전체리스트!A:A,B16,전체리스트!C:C,D16) -> 56073 | H16: =G16*0.05 -> 2803.65 | I16: =G16-H16 -> 53269.35
B17: 탑툰 | C17: =VLOOKUP(B17,raw_a,2,0) -> 11월분 | D17: 용서해줘, 제자님 | E17: =SUMIFS(전체리스트!D:D,전체리스트!A:A,B17,전체리스트!C:C,D17) -> 143272 | F17: =E17-G17 -> 0 | G17: =SUMIFS(전체리스트!E:E,전체리스트!A:A,B17,전체리스트!C:C,D17) -> 143272 | H17: =G17*0.05 -> 7163.6 | I17: =G17-H17 -> 136108.4
... B23: 탑툰 | C23: =VLOOKUP(B23,raw_a,2,0) -> 11월분 | D23: 서녀공략 | E23: =SUMIFS(전체리스트!D:D,전체리스트!A:A,B23,전체리스트!C:C,D23) -> 5763 | F23: =E23-G23 -> 0 | G23: =SUMIFS(전체리스트!E:E,전체리스트!A:A,B23,전체리스트!C:C,D23) -> 5763 | H23: =G23*0.05 -> 288.15 | I23: =G23-H23 -> 5474.85
B24: 합계 | E24: =SUM(E6:E23) -> 3906249 | F24: =SUM(F6:F23) -> 0 | G24: =SUM(G6:G23) -> 3906249 | H24: =SUM(H6:H23) -> 195312.45 | I24: =SUM(I6:I23) -> 3710936.6 | J24: =SUM(J6:J23) -> 0

Sheet 봄툰
B4: [RS 정산 기준]
B5: 사이트명 | C5: 매출월 | D5: 작품명 | E5: 소비자매출액 | F5: 유통사수수료 | G5: 스토리위즈매출액 | H5: 스토리위즈수익 | I5: 스토리숲 수익 | J5: 비고
B6: 봄툰_유통1 | C6: =VLOOKUP(B6,raw_a,2,0) -> 10월분 | D6: 페티쉬 BL 단편선 | E6: =SUMIFS(전체리스트!D:D,전체리스트!A:A,B6,전체리스트!C:C,D6) -> 420 | F6: =E6-G6 -> 0 | G6: =SUMIFS(전체리스트!E:E,전체리스트!A:A,B6,전체리스트!C:C,D6) -> 420 | H6: =G6*0.05 -> 21 | I6: =G6-H6 -> 399
B7: 봄툰 | C7: =VLOOKUP(B7,raw_a,2,0) -> 11월분 | D7: 망나니 도련님 조교일지 | E7: =SUMIFS(전체리스트!D:D,전체리스트!A:A,B7,전체리스트!C:C,D7) -> 131339 | F7: =E7-G7 -> 0 | G7: =SUMIFS(전체리스트!E:E,전체리스트!A:A,B7,전체리스트!C:C,D7) -> 131339 | H7: =G7*0.05 -> 6566.95 | I7: =G7-H7 -> 124772.05
B8: 봄툰 | C8: =VLOOKUP(B8,raw_a,2,0) -> 11월분 | D8: 사랑할 수 없는 그녀 | E8: =SUMIFS(전체리스트!D:D,전체리스트!A:A,B8,전체리스트!C:C,D8) -> 62629 | F8: =E8-G8 -> 0 | G8: =SUMIFS(전체리스트!E:E,전체리스트!A:A,B8,전체리스트!C:C,D8) -> 62629 | H8: =G8*0.05 -> 3131.45 | I8: =G8-H8 -> 59497.55
B9: 봄툰 | C9: =VLOOKUP(B9,raw_a,2,0) -> 11월분 | D9: 슬기로운 생활(완결) | E9: =SUMIFS(전체리스트!D:D,전체리스트!A:A,B9,전체리스트!C:C,D9) -> 1890 | F9: =E9-G9 -> 0 | G9: =SUMIFS(전체리스트!E:E,전체리스트!A:A,B9,전체리스트!C:C,D9) -> 1890 | H9: =G9*0.05 -> 94.5 | I9: =G9-H9 -> 1795.5
B10: 봄툰 | C10: =VLOOKUP(B10,raw_a,2,0) -> 11월분 | D10: 아랫집 웬수 | E10: =SUMIFS(전체리스트!D:D,전체리스트!A:A,B10,전체리스트!C:C,D10) -> 23101 | F10: =E10-G10 -> 0 | G10: =SUMIFS(전체리스트!E:E,전체리스트!A:A,B10,전체리스트!C:C,D10) -> 23101 | H10: =G10*0.05 -> 1155.05 | I10: =G10-H10 -> 21945.95
B11: 봄툰 | C11: =VLOOKUP(B11,raw_a,2,0) -> 11월분 | D11: 악마와 나 사이에는 | E11: =SUMIFS(전체리스트!D:D,전체리스트!A:A,B11,전체리스트!C:C,D11) -> 227 | F11: =E11-G11 -> 0 | G11: =SUMIFS(전체리스트!E:E,전체리스트!A:A,B11,전체리스트!C:C,D11) -> 227 | H11: =G11*0.05 -> 11.35 | I11: =G11-H11 -> 215.65
B12: 봄툰 | C12: =VLOOKUP(B12,raw_a,2,0) -> 11월분 | D12: 옆집 최애 | E12: =SUMIFS(전체리스트!D:D,전체리스트!A:A,B12,전체리스트!C:C,D12) -> 8748 | F12: =E12-G12 -> 0 | G12: =SUMIFS(전체리스트!E:E,전체리스트!A:A,B12,전체리스트!C:C,D12) -> 8748 | H12: =G12*0.05 -> 437.4 | I12: =G12-H12 -> 8310.6
B13: 봄툰 | C13: =VLOOKUP(B13,raw_a,2,0) -> 11월분 | D13: 파쿠리인 내가 어시를?! | E13: =SUMIFS(전체리스트!D:D,전체리스트!A:A,B13,전체리스트!C:C,D13) -> 11081 | F13: =E13-G13 -> 0 | G13: =SUMIFS(전체리스트!E:E,전체리스트!A:A,B13,전체리스트!C:C,D13) -> 11081 | H13: =G13*0.05 -> 554.05 | I13: =G13-H13 -> 10526.95
B14: 봄툰 | C14: =VLOOKUP(B14,raw_a,2,0) -> 11월분 | D14: 페티쉬 BL 단편선 | E14: =SUMIFS(전체리스트!D:D,전체리스트!A:A,B14,전체리스트!C:C,D14) -> 15579 | F14: =E14-G14 -> 0 | G14: =SUMIFS(전체리스트!E:E,전체리스트!A:A,B14,전체리스트!C:C,D14) -> 15579 | H14: =G14*0.05 -> 778.95 | I14: =G14-H14 -> 14800.05
B15: 봄툰 | C15: =VLOOKUP(B15,raw_a,2,0) -> 11월분 | D15: 한집 두 살림 | E15: =SUMIFS(전체리스트!D:D,전체리스트!A:A,B15,전체리스트!C:C,D15) -> 8672 | F15: =E15-G15 -> 0 | G15: =SUMIFS(전체리스트!E:E,전체리스트!A:A,B15,전체리스트!C:C,D15) -> 8672 | H15: =G15*0.05 -> 433.6 | I15: =G15-H15 -> 8238.4
B16: 봄툰 | C16: =VLOOKUP(B16,raw_a,2,0) -> 11월분 | D16: 호랑이 장가드는 날 | E16: =SUMIFS(전체리스트!D:D,전체리스트!A:A,B16,전체리스트!C:C,D16) -> 18436 | F16: =E16-G16 -> 0 | G16: =SUMIFS(전체리스트!E:E,전체리스트!A:A,B16,전체리스트!C:C,D16) -> 18436 | H16: =G16*0.05 -> 921.8 | I16: =G16-H16 -> 17514.2
B17: 봄툰 | C17: =VLOOKUP(B17,raw_a,2,0) -> 11월분 | D17: 이혼신청 | E17: =SUMIFS(전체리스트!D:D,전체리스트!A:A,B17,전체리스트!C:C,D17) -> 990090 | F17: =E17-G17 -> 0 | G17: =SUMIFS(전체리스트!E:E,전체리스트!A:A,B17,전체리스트!C:C,D17) -> 990090 | H17: =G17*0.05 -> 49504.5 | I17: =G17-H17 -> 940585.5
... B47: 봄툰 | C47: =VLOOKUP(B47,raw_a,2,0) -> 11월분 | D47: 광속으로 레벨업 | E47: =SUMIFS(전체리스트!D:D,전체리스트!A:A,B47,전체리스트!C:C,D47) -> 324 | F47: =E47-G47 -> 0 | G47: =SUMIFS(전체리스트!E:E,전체리스트!A:A,B47,전체리스트!C:C,D47) -> 324 | H47: =G47*0.05 -> 16.2 | I47: =G47-H47 -> 307.8
B48: 합계 | E48: =SUM(E6:E47) -> 3324770 | F48: =SUM(F6:F47) -> 0 | G48: =SUM(G6:G47) -> 3324770 | H48: =SUM(H6:H47) -> 166238.5 | I48: =SUM(I6:I47) -> 3158531.5 | J48: =SUM(J6:J47) -> 0

Sheet 애니툰
B4: [RS 정산 기준]
B5: 사이트명 | C5: 매출월 | D5: 작품명 | E5: 소비자매출액 | F5: 유통사수수료 | G5: 스토리위즈매출액 | H5: 스토리위즈수익 | I5: 스토리숲 수익 | J5: 비고
B6: 애니툰 | C6: =VLOOKUP(B6,raw_a,2,0) -> 11월분 | D6: (GL) 한집 두 살림 [성인판] | E6: =SUMIFS(전체리스트!D:D,전체리스트!A:A,B6,전체리스트!C:C,D6) -> 7843.5 | F6: =E6-G6 -> 0 | G6: =SUMIFS(전체리스트!E:E,전체리스트!A:A,B6,전체리스트!C:C,D6) -> 7843.5 | H6: =G6*0.05 -> 392.175 | I6: =G6-H6 -> 7451.325
B7: 애니툰 | C7: =VLOOKUP(B7,raw_a,2,0) -> 11월분 | D7: (GL) 한집 두 살림 [일반판] | E7: =SUMIFS(전체리스트!D:D,전체리스트!A:A,B7,전체리스트!C:C,D7) -> 283.5 | F7: =E7-G7 -> 0 | G7: =SUMIFS(전체리스트!E:E,전체리스트!A:A,B7,전체리스트!C:C,D7) -> 283.5 | H7: =G7*0.05 -> 14.175 | I7: =G7-H7 -> 269.325
B8: 애니툰 | C8: =VLOOKUP(B8,raw_a,2,0) -> 11월분 | D8: 거짓말, 뱀파이어가 어디 있어? | E8: =SUMIFS(전체리스트!D:D,전체리스트!A:A,B8,전체리스트!C:C,D8) -> 5512.5 | F8: =E8-G8 -> 0 | G8: =SUMIFS(전체리스트!E:E,전체리스트!A:A,B8,전체리스트!C:C,D8) -> 5512.5 | H8: =G8*0.05 -> 275.625 | I8: =G8-H8 -> 5236.875
B9: 애니툰 | C9: =VLOOKUP(B9,raw_a,2,0) -> 11월분 | D9: 광속으로 레벨업 | E9: =SUMIFS(전체리스트!D:D,전체리스트!A:A,B9,전체리스트!C:C,D9) -> 7092.75 | F9: =E9-G9 -> 0 | G9: =SUMIFS(전체리스트!E:E,전체리스트!A:A,B9,전체리스트!C:C,D9) -> 7092.75 | H9: =G9*0.05 -> 354.6375 | I9: =G9-H9 -> 6738.1125
B10: 애니툰 | C10: =VLOOKUP(B10,raw_a,2,0) -> 11월분 | D10: 귀신 보는 급식은 퇴마 중입니다 | E10: =SUMIFS(전체리스트!D:D,전체리스트!A:A,B10,전체리스트!C:C,D10) -> 4509.75 | F10: =E10-G10 -> 0 | G10: =SUMIFS(전체리스트!E:E,전체리스트!A:A,B10,전체리스트!C:C,D10) -> 4509.75 | H10: =G10*0.05 -> 225.4875 | I10: =G10-H10 -> 4284.2625
B11: 애니툰 | C11: =VLOOKUP(B11,raw_a,2,0) -> 11월분 | D11: 꿈꾸는 먹잇감 | E11: =SUMIFS(전체리스트!D:D,전체리스트!A:A,B11,전체리스트!C:C,D11) -> 20469.75 | F11: =E11-G11 -> 0 | G11: =SUMIFS(전체리스트!E:E,전체리스트!A:A,B11,전체리스트!C:C,D11) -> 20469.75 | H11: =G11*0.05 -> 1023.4875 | I11: =G11-H11 -> 19446.263
B12: 애니툰 | C12: =VLOOKUP(B12,raw_a,2,0) -> 11월분 | D12: 꿰인 사이 | E12: =SUMIFS(전체리스트!D:D,전체리스트!A:A,B12,전체리스트!C:C,D12) -> 61094.25 | F12: =E12-G12 -> 0 | G12: =SUMIFS(전체리스트!E:E,전체리스트!A:A,B12,전체리스트!C:C,D12) -> 61094.25 | H12: =G12*0.05 -> 3054.7125 | I12: =G12-H12 -> 58039.537
B13: 애니툰 | C13: =VLOOKUP(B13,raw_a,2,0) -> 11월분 | D13: 내 자기님이 로그인 하셨습니다 | E13: =SUMIFS(전체리스트!D:D,전체리스트!A:A,B13,전체리스트!C:C,D13) -> 11560.5 | F13: =E13-G13 -> 0 | G13: =SUMIFS(전체리스트!E:E,전체리스트!A:A,B13,전체리스트!C:C,D13) -> 11560.5 | H13: =G13*0.05 -> 578.025 | I13: =G13-H13 -> 10982.475
B14: 애니툰 | C14: =VLOOKUP(B14,raw_a,2,0) -> 11월분 | D14: 너에게만 음성인식 | E14: =SUMIFS(전체리스트!D:D,전체리스트!A:A,B14,전체리스트!C:C,D14) -> 16185.75 | F14: =E14-G14 -> 0 | G14: =SUMIFS(전체리스트!E:E,전체리스트!A:A,B14,전체리스트!C:C,D14) -> 16185.75 | H14: =G14*0.05 -> 809.2875 | I14: =G14-H14 -> 15376.462
B15: 애니툰 | C15: =VLOOKUP(B15,raw_a,2,0) -> 11월분 | D15: 네게 취한 날들 | E15: =SUMIFS(전체리스트!D:D,전체리스트!A:A,B15,전체리스트!C:C,D15) -> 85548.75 | F15: =E15-G15 -> 0 | G15: =SUMIFS(전체리스트!E:E,전체리스트!A:A,B15,전체리스트!C:C,D15) -> 85548.75 | H15: =G15*0.05 -> 4277.4375 | I15: =G15-H15 -> 81271.312
B16: 애니툰 | C16: =VLOOKUP(B16,raw_a,2,0) -> 11월분 | D16: 대표님, 사모님이 도망가요 | E16: =SUMIFS(전체리스트!D:D,전체리스트!A:A,B16,전체리스트!C:C,D16) -> 334768.88 | F16: =E16-G16 -> 0 | G16: =SUMIFS(전체리스트!E:E,전체리스트!A:A,B16,전체리스트!C:C,D16) -> 334768.88 | H16: =G16*0.05 -> 16738.444 | I16: =G16-H16 -> 318030.43
B17: 애니툰 | C17: =VLOOKUP(B17,raw_a,2,0) -> 11월분 | D17: 대표님, 오늘은 아니에요 | E17: =SUMIFS(전체리스트!D:D,전체리스트!A:A,B17,전체리스트!C:C,D17) -> 81459 | F17: =E17-G17 -> 0 | G17: =SUMIFS(전체리스트!E:E,전체리스트!A:A,B17,전체리스트!C:C,D17) -> 81459 | H17: =G17*0.05 -> 4072.95 | I17: =G17-H17 -> 77386.05
... B91: 애니툰 | C91: =VLOOKUP(B91,raw_a,2,0) -> 11월분 | D91: ASP한번 해볼래? | E91: =SUMIFS(전체리스트!D:D,전체리스트!A:A,B91,전체리스트!C:C,D91) -> 1058 | F91: =E91-G91 -> 0 | G91: =SUMIFS(전체리스트!E:E,전체리스트!A:A,B91,전체리스트!C:C,D91) -> 1058 | H91: =G91*0.05 -> 52.9 | I91: =G91-H91 -> 1005.1
B92: 합계 | E92: =SUM(E6:E91) -> 4468128.6 | F92: =SUM(F6:F91) -> 0 | G92: =SUM(G6:G91) -> 4468128.6 | H92: =SUM(H6:H91) -> 223406.43 | I92: =SUM(I6:I91) -> 4244722.2 | J92: =SUM(J6:J91) -> 0

Sheet 코미코_한국
B4: [RS 정산 기준]
B5: 사이트명 | C5: 매출월 | D5: 작품명 | E5: 소비자매출액 | F5: 유통사수수료 | G5: 스토리위즈매출액 | H5: 스토리위즈수익 | I5: 스토리숲 수익 | J5: 비고
B6: 코미코_위즈덤 | C6: =VLOOKUP(B6,raw_a,2,0) -> 11월분 | D6: 내 자기님이 로그인 하셨습니다 | E6: =SUMIFS(전체리스트!D:D,전체리스트!A:A,B6,전체리스트!C:C,D6) -> 258318 | F6: =E6-G6 -> 0 | G6: =SUMIFS(전체리스트!E:E,전체리스트!A:A,B6,전체리스트!C:C,D6) -> 258318 | H6: =G6*0.05 -> 12915.9 | I6: =G6-H6 -> 245402.1
B7: 코미코코리아 | C7: =VLOOKUP(B7,raw_a,2,0) -> 12월분 | D7: 거짓말, 뱀파이어가 어디 있어? [완] | E7: =SUMIFS(전체리스트!D:D,전체리스트!A:A,B7,전체리스트!C:C,D7) -> 105100 | F7: =E7-G7 -> 51223 | G7: =SUMIFS(전체리스트!E:E,전체리스트!A:A,B7,전체리스트!C:C,D7) -> 53877 | H7: =G7*0.05 -> 2693.85 | I7: =G7-H7 -> 51183.15
B8: 코미코코리아 | C8: =VLOOKUP(B8,raw_a,2,0) -> 12월분 | D8: 광속으로 레벨업 | E8: =SUMIFS(전체리스트!D:D,전체리스트!A:A,B8,전체리스트!C:C,D8) -> 41800 | F8: =E8-G8 -> 17370 | G8: =SUMIFS(전체리스트!E:E,전체리스트!A:A,B8,전체리스트!C:C,D8) -> 24430 | H8: =G8*0.05 -> 1221.5 | I8: =G8-H8 -> 23208.5
B9: 코미코코리아 | C9: =VLOOKUP(B9,raw_a,2,0) -> 12월분 | D9: 귀신 보는 급식은 퇴마 중입니다 | E9: =SUMIFS(전체리스트!D:D,전체리스트!A:A,B9,전체리스트!C:C,D9) -> 600 | F9: =E9-G9 -> 306 | G9: =SUMIFS(전체리스트!E:E,전체리스트!A:A,B9,전체리스트!C:C,D9) -> 294 | H9: =G9*0.05 -> 14.7 | I9: =G9-H9 -> 279.3
B10: 코미코코리아 | C10: =VLOOKUP(B10,raw_a,2,0) -> 12월분 | D10: 꿈꾸는 먹잇감 | E10: =SUMIFS(전체리스트!D:D,전체리스트!A:A,B10,전체리스트!C:C,D10) -> 102400 | F10: =E10-G10 -> 46344 | G10: =SUMIFS(전체리스트!E:E,전체리스트!A:A,B10,전체리스트!C:C,D10) -> 56056 | H10: =G10*0.05 -> 2802.8 | I10: =G10-H10 -> 53253.2
B11: 코미코코리아 | C11: =VLOOKUP(B11,raw_a,2,0) -> 12월분 | D11: 꿰인 사이 | E11: =SUMIFS(전체리스트!D:D,전체리스트!A:A,B11,전체리스트!C:C,D11) -> 65100 | F11: =E11-G11 -> 37515 | G11: =SUMIFS(전체리스트!E:E,전체리스트!A:A,B11,전체리스트!C:C,D11) -> 27585 | H11: =G11*0.05 -> 1379.25 | I11: =G11-H11 -> 26205.75
B12: 코미코코리아 | C12: =VLOOKUP(B12,raw_a,2,0) -> 12월분 | D12: 너에게만 음성인식 | E12: =SUMIFS(전체리스트!D:D,전체리스트!A:A,B12,전체리스트!C:C,D12) -> 24200 | F12: =E12-G12 -> 13784 | G12: =SUMIFS(전체리스트!E:E,전체리스트!A:A,B12,전체리스트!C:C,D12) -> 10416 | H12: =G12*0.05 -> 520.8 | I12: =G12-H12 -> 9895.2
B13: 코미코코리아 | C13: =VLOOKUP(B13,raw_a,2,0) -> 12월분 | D13: 네게 취한 날들 | E13: =SUMIFS(전체리스트!D:D,전체리스트!A:A,B13,전체리스트!C:C,D13) -> 49400 | F13: =E13-G13 -> 17130 | G13: =SUMIFS(전체리스트!E:E,전체리스트!A:A,B13,전체리스트!C:C,D13) -> 32270 | H13: =G13*0.05 -> 1613.5 | I13: =G13-H13 -> 30656.5
B14: 코미코코리아 | C14: =VLOOKUP(B14,raw_a,2,0) -> 12월분 | D14: 대표님, 사모님이 도망가요 | E14: =SUMIFS(전체리스트!D:D,전체리스트!A:A,B14,전체리스트!C:C,D14) -> 88400 | F14: =E14-G14 -> 51185 | G14: =SUMIFS(전체리스트!E:E,전체리스트!A:A,B14,전체리스트!C:C,D14) -> 37215 | H14: =G14*0.05 -> 1860.75 | I14: =G14-H14 -> 35354.25
B15: 코미코코리아 | C15: =VLOOKUP(B15,raw_a,2,0) -> 12월분 | D15: 대표님, 오늘은 아니에요 | E15: =SUMIFS(전체리스트!D:D,전체리스트!A:A,B15,전체리스트!C:C,D15) -> 485200 | F15: =E15-G15 -> 209148 | G15: =SUMIFS(전체리스트!E:E,전체리스트!A:A,B15,전체리스트!C:C,D15) -> 276052 | H15: =G15*0.05 -> 13802.6 | I15: =G15-H15 -> 262249.4
B16: 코미코코리아 | C16: =VLOOKUP(B16,raw_a,2,0) -> 12월분 | D16: 대표님의 삐뚤어진 사랑 | E16: =SUMIFS(전체리스트!D:D,전체리스트!A:A,B16,전체리스트!C:C,D16) -> 367300 | F16: =E16-G16 -> 198526 | G16: =SUMIFS(전체리스트!E:E,전체리스트!A:A,B16,전체리스트!C:C,D16) -> 168774 | H16: =G16*0.05 -> 8438.7 | I16: =G16-H16 -> 160335.3
B17: 코미코코리아 | C17: =VLOOKUP(B17,raw_a,2,0) -> 12월분 | D17: 레벨업에 미친 의사 | E17: =SUMIFS(전체리스트!D:D,전체리스트!A:A,B17,전체리스트!C:C,D17) -> 10800 | F17: =E17-G17 -> 4962 | G17: =SUMIFS(전체리스트!E:E,전체리스트!A:A,B17,전체리스트!C:C,D17) -> 5838 | H17: =G17*0.05 -> 291.9 | I17: =G17-H17 -> 5546.1
... B42: 코미코코리아 | C42: =VLOOKUP(B42,raw_a,2,0) -> 12월분 | D42: 호랑이 장가드는 날 [개정판] | E42: =SUMIFS(전체리스트!D:D,전체리스트!A:A,B42,전체리스트!C:C,D42) -> 1200 | F42: =E42-G42 -> 660 | G42: =SUMIFS(전체리스트!E:E,전체리스트!A:A,B42,전체리스트!C:C,D42) -> 540 | H42: =G42*0.05 -> 27 | I42: =G42-H42 -> 513
B43: 합계 | E43: =SUM(E6:E42) -> 3928418 | F43: =SUM(F6:F42) -> 1809202 | G43: =SUM(G6:G42) -> 2119216 | H43: =SUM(H6:H42) -> 105960.8 | I43: =SUM(I6:I42) -> 2013255.2 | J43: =SUM(J6:J42) -> 0

Sheet 조아라
B4: [RS 정산 기준]
B5: 사이트명 | C5: 매출월 | D5: 작품명 | E5: 소비자매출액 | F5: 유통사수수료 | G5: 스토리위즈매출액 | H5: 스토리위즈수익 | I5: 스토리숲 수익 | J5: 비고
B6: 조아라 | C6: =VLOOKUP(B6,raw_a,2,0) -> 12월분 | D6: 꿈꾸는 먹잇감 | E6: =SUMIFS(전체리스트!D:D,전체리스트!A:A,B6,전체리스트!C:C,D6) -> 800 | F6: =E6-G6 -> 272 | G6: =SUMIFS(전체리스트!E:E,전체리스트!A:A,B6,전체리스트!C:C,D6) -> 528 | H6: =G6*0.05 -> 26.4 | I6: =G6-H6 -> 501.6
B7: 조아라 | C7: =VLOOKUP(B7,raw_a,2,0) -> 12월분 | D7: 꿰인 사이 | E7: =SUMIFS(전체리스트!D:D,전체리스트!A:A,B7,전체리스트!C:C,D7) -> 9300 | F7: =E7-G7 -> 3162 | G7: =SUMIFS(전체리스트!E:E,전체리스트!A:A,B7,전체리스트!C:C,D7) -> 6138 | H7: =G7*0.05 -> 306.9 | I7: =G7-H7 -> 5831.1
B8: 조아라 | C8: =VLOOKUP(B8,raw_a,2,0) -> 12월분 | D8: 네게 취한 날들 | E8: =SUMIFS(전체리스트!D:D,전체리스트!A:A,B8,전체리스트!C:C,D8) -> 32000 | F8: =E8-G8 -> 10880 | G8: =SUMIFS(전체리스트!E:E,전체리스트!A:A,B8,전체리스트!C:C,D8) -> 21120 | H8: =G8*0.05 -> 1056 | I8: =G8-H8 -> 20064
B9: 조아라 | C9: =VLOOKUP(B9,raw_a,2,0) -> 12월분 | D9: 대표님, 오늘은 아니에요 | E9: =SUMIFS(전체리스트!D:D,전체리스트!A:A,B9,전체리스트!C:C,D9) -> 5200 | F9: =E9-G9 -> 1768 | G9: =SUMIFS(전체리스트!E:E,전체리스트!A:A,B9,전체리스트!C:C,D9) -> 3432 | H9: =G9*0.05 -> 171.6 | I9: =G9-H9 -> 3260.4
B10: 조아라 | C10: =VLOOKUP(B10,raw_a,2,0) -> 12월분 | D10: 레벨업에 미친 의사 | E10: =SUMIFS(전체리스트!D:D,전체리스트!A:A,B10,전체리스트!C:C,D10) -> 209200 | F10: =E10-G10 -> 71128 | G10: =SUMIFS(전체리스트!E:E,전체리스트!A:A,B10,전체리스트!C:C,D10) -> 138072 | H10: =G10*0.05 -> 6903.6 | I10: =G10-H10 -> 131168.4
B11: 조아라 | C11: =VLOOKUP(B11,raw_a,2,0) -> 12월분 | D11: 마녀 따위 안 할래요 | E11: =SUMIFS(전체리스트!D:D,전체리스트!A:A,B11,전체리스트!C:C,D11) -> 600 | F11: =E11-G11 -> 204 | G11: =SUMIFS(전체리스트!E:E,전체리스트!A:A,B11,전체리스트!C:C,D11) -> 396 | H11: =G11*0.05 -> 19.8 | I11: =G11-H11 -> 376.2
B12: 조아라 | C12: =VLOOKUP(B12,raw_a,2,0) -> 12월분 | D12: 속도위반 대표님과 계약 아내 | E12: =SUMIFS(전체리스트!D:D,전체리스트!A:A,B12,전체리스트!C:C,D12) -> 3200 | F12: =E12-G12 -> 1088 | G12: =SUMIFS(전체리스트!E:E,전체리스트!A:A,B12,전체리스트!C:C,D12) -> 2112 | H12: =G12*0.05 -> 105.6 | I12: =G12-H12 -> 2006.4
B13: 조아라 | C13: =VLOOKUP(B13,raw_a,2,0) -> 12월분 | D13: 아랫집 웬수 | E13: =SUMIFS(전체리스트!D:D,전체리스트!A:A,B13,전체리스트!C:C,D13) -> 600 | F13: =E13-G13 -> 204 | G13: =SUMIFS(전체리스트!E:E,전체리스트!A:A,B13,전체리스트!C:C,D13) -> 396 | H13: =G13*0.05 -> 19.8 | I13: =G13-H13 -> 376.2
B14: 조아라 | C14: =VLOOKUP(B14,raw_a,2,0) -> 12월분 | D14: 이혼신청 | E14: =SUMIFS(전체리스트!D:D,전체리스트!A:A,B14,전체리스트!C:C,D14) -> 264400 | F14: =E14-G14 -> 89896 | G14: =SUMIFS(전체리스트!E:E,전체리스트!A:A,B14,전체리스트!C:C,D14) -> 174504 | H14: =G14*0.05 -> 8725.2 | I14: =G14-H14 -> 165778.8
B15: 조아라 | C15: =VLOOKUP(B15,raw_a,2,0) -> 12월분 | D15: 전설 헌터로 키워지는 중입니다 | E15: =SUMIFS(전체리스트!D:D,전체리스트!A:A,B15,전체리스트!C:C,D15) -> 4400 | F15: =E15-G15 -> 1496 | G15: =SUMIFS(전체리스트!E:E,전체리스트!A:A,B15,전체리스트!C:C,D15) -> 2904 | H15: =G15*0.05 -> 145.2 | I15: =G15-H15 -> 2758.8
B16: 조아라 | C16: =VLOOKUP(B16,raw_a,2,0) -> 12월분 | D16: 한집 두 살림 | E16: =SUMIFS(전체리스트!D:D,전체리스트!A:A,B16,전체리스트!C:C,D16) -> 600 | F16: =E16-G16 -> 204 | G16: =SUMIFS(전체리스트!E:E,전체리스트!A:A,B16,전체리스트!C:C,D16) -> 396 | H16: =G16*0.05 -> 19.8 | I16: =G16-H16 -> 376.2
B17: 합계 | E17: =SUM(E6:E16) -> 530300 | F17: =SUM(F6:F16) -> 180302 | G17: =SUM(G6:G16) -> 349998 | H17: =SUM(H6:H16) -> 17499.9 | I17: =SUM(I6:I16) -> 332498.1 | J17: =SUM(J6:J16) -> 0

Sheet 포켓코믹스
B4: [RS 정산 기준]
B5: 사이트명 | C5: 매출월 | D5: 작품명 | E5: 소비자매출액 | F5: 유통사수수료 | G5: 스토리위즈매출액 | H5: 스토리위즈수익 | I5: 스토리숲 수익 | J5: 비고
B6: 포켓코믹스 | C6: =VLOOKUP(B6,raw_a,2,0) -> 11월분 | D6: 내 자기님이 로그인 하셨습니다 | E6: =SUMIFS(전체리스트!D:D,전체리스트!A:A,B6,전체리스트!C:C,D6) -> 398304 | F6: =E6-G6 -> 0 | G6: =SUMIFS(전체리스트!E:E,전체리스트!A:A,B6,전체리스트!C:C,D6) -> 398304 | H6: =G6*0.05 -> 19915.2 | I6: =G6-H6 -> 378388.8
B7: 포켓코믹스 | C7: =VLOOKUP(B7,raw_a,2,0) -> 11월분 | D7: 사랑과 우정 사이에서 | E7: =SUMIFS(전체리스트!D:D,전체리스트!A:A,B7,전체리스트!C:C,D7) -> 37717 | F7: =E7-G7 -> 0 | G7: =SUMIFS(전체리스트!E:E,전체리스트!A:A,B7,전체리스트!C:C,D7) -> 37717 | H7: =G7*0.05 -> 1885.85 | I7: =G7-H7 -> 35831.15
B8: 포켓코믹스 | C8: =VLOOKUP(B8,raw_a,2,0) -> 11월분 | D8: 사랑과 우정사이에서 | E8: =SUMIFS(전체리스트!D:D,전체리스트!A:A,B8,전체리스트!C:C,D8) -> 132020 | F8: =E8-G8 -> 0 | G8: =SUMIFS(전체리스트!E:E,전체리스트!A:A,B8,전체리스트!C:C,D8) -> 132020 | H8: =G8*0.05 -> 6601 | I8: =G8-H8 -> 125419
B9: 포켓코믹스 | C9: =VLOOKUP(B9,raw_a,2,0) -> 11월분 | D9: 아랫집 웬수 | E9: =SUMIFS(전체리스트!D:D,전체리스트!A:A,B9,전체리스트!C:C,D9) -> 41555 | F9: =E9-G9 -> 0 | G9: =SUMIFS(전체리스트!E:E,전체리스트!A:A,B9,전체리스트!C:C,D9) -> 41555 | H9: =G9*0.05 -> 2077.75 | I9: =G9-H9 -> 39477.25
B10: 포켓코믹스 | C10: =VLOOKUP(B10,raw_a,2,0) -> 11월분 | D10: 옆집 최애 | E10: =SUMIFS(전체리스트!D:D,전체리스트!A:A,B10,전체리스트!C:C,D10) -> 134591 | F10: =E10-G10 -> 0 | G10: =SUMIFS(전체리스트!E:E,전체리스트!A:A,B10,전체리스트!C:C,D10) -> 134591 | H10: =G10*0.05 -> 6729.55 | I10: =G10-H10 -> 127861.45
B11: 포켓코믹스 | C11: =VLOOKUP(B11,raw_a,2,0) -> 11월분 | D11: 한 번만 부탁해 | E11: =SUMIFS(전체리스트!D:D,전체리스트!A:A,B11,전체리스트!C:C,D11) -> 75869 | F11: =E11-G11 -> 0 | G11: =SUMIFS(전체리스트!E:E,전체리스트!A:A,B11,전체리스트!C:C,D11) -> 75869 | H11: =G11*0.05 -> 3793.45 | I11: =G11-H11 -> 72075.55
B12: 합계 | E12: =SUM(E6:E11) -> 820056 | F12: =SUM(F6:F11) -> 0 | G12: =SUM(G6:G11) -> 820056 | H12: =SUM(H6:H11) -> 41002.8 | I12: =SUM(I6:I11) -> 779053.2 | J12: =SUM(J6:J9) -> 0

Sheet 리디북스
B4: [RS 정산 기준]
B5: 사이트명 | C5: 매출월 | D5: 작품명 | E5: 소비자매출액 | F5: 유통사수수료 | G5: 스토리위즈매출액 | H5: 스토리위즈수익 | I5: 스토리숲 수익 | J5: 비고
B6: 리디북스 | C6: =VLOOKUP(B6,raw_a,2,0) -> 11월분 | D6: [e북]사랑과 우정 사이에서 | E6: =SUMIFS(전체리스트!D:D,전체리스트!A:A,B6,전체리스트!C:C,D6) -> 36902.46 | F6: =E6-G6 -> 0 | G6: =SUMIFS(전체리스트!E:E,전체리스트!A:A,B6,전체리스트!C:C,D6) -> 36902.46 | H6: =G6*0.05 -> 1845.123 | I6: =G6-H6 -> 35057.337
B7: 리디북스 | C7: =VLOOKUP(B7,raw_a,2,0) -> 11월분 | D7: 거짓말, 뱀파이어가 어디 있어? | E7: =SUMIFS(전체리스트!D:D,전체리스트!A:A,B7,전체리스트!C:C,D7) -> 10134.88 | F7: =E7-G7 -> 0 | G7: =SUMIFS(전체리스트!E:E,전체리스트!A:A,B7,전체리스트!C:C,D7) -> 10134.88 | H7: =G7*0.05 -> 506.744 | I7: =G7-H7 -> 9628.136
B8: 리디북스 | C8: =VLOOKUP(B8,raw_a,2,0) -> 11월분 | D8: 광속으로 레벨업 | E8: =SUMIFS(전체리스트!D:D,전체리스트!A:A,B8,전체리스트!C:C,D8) -> 5432 | F8: =E8-G8 -> 0 | G8: =SUMIFS(전체리스트!E:E,전체리스트!A:A,B8,전체리스트!C:C,D8) -> 5432 | H8: =G8*0.05 -> 271.6 | I8: =G8-H8 -> 5160.4
B9: 리디북스 | C9: =VLOOKUP(B9,raw_a,2,0) -> 11월분 | D9: 귀신 보는 급식은 퇴마중입니다 | E9: =SUMIFS(전체리스트!D:D,전체리스트!A:A,B9,전체리스트!C:C,D9) -> 2380 | F9: =E9-G9 -> 0 | G9: =SUMIFS(전체리스트!E:E,전체리스트!A:A,B9,전체리스트!C:C,D9) -> 2380 | H9: =G9*0.05 -> 119 | I9: =G9-H9 -> 2261
B10: 리디북스 | C10: =VLOOKUP(B10,raw_a,2,0) -> 11월분 | D10: 꿈꾸는 먹잇감 | E10: =SUMIFS(전체리스트!D:D,전체리스트!A:A,B10,전체리스트!C:C,D10) -> 249729.77 | F10: =E10-G10 -> 0 | G10: =SUMIFS(전체리스트!E:E,전체리스트!A:A,B10,전체리스트!C:C,D10) -> 249729.77 | H10: =G10*0.05 -> 12486.488 | I10: =G10-H10 -> 237243.28
B11: 리디북스 | C11: =VLOOKUP(B11,raw_a,2,0) -> 11월분 | D11: 꿰인 사이 | E11: =SUMIFS(전체리스트!D:D,전체리스트!A:A,B11,전체리스트!C:C,D11) -> 39793.6 | F11: =E11-G11 -> 0 | G11: =SUMIFS(전체리스트!E:E,전체리스트!A:A,B11,전체리스트!C:C,D11) -> 39793.6 | H11: =G11*0.05 -> 1989.68 | I11: =G11-H11 -> 37803.92
B12: 리디북스 | C12: =VLOOKUP(B12,raw_a,2,0) -> 11월분 | D12: 너에게만 음성인식 | E12: =SUMIFS(전체리스트!D:D,전체리스트!A:A,B12,전체리스트!C:C,D12) -> 15820 | F12: =E12-G12 -> 0 | G12: =SUMIFS(전체리스트!E:E,전체리스트!A:A,B12,전체리스트!C:C,D12) -> 15820 | H12: =G12*0.05 -> 791 | I12: =G12-H12 -> 15029
B13: 리디북스 | C13: =VLOOKUP(B13,raw_a,2,0) -> 11월분 | D13: 네게 취한 날들 | E13: =SUMIFS(전체리스트!D:D,전체리스트!A:A,B13,전체리스트!C:C,D13) -> 338640.68 | F13: =E13-G13 -> 0 | G13: =SUMIFS(전체리스트!E:E,전체리스트!A:A,B13,전체리스트!C:C,D13) -> 338640.68 | H13: =G13*0.05 -> 16932.034 | I13: =G13-H13 -> 321708.65
B14: 리디북스 | C14: =VLOOKUP(B14,raw_a,2,0) -> 11월분 | D14: 대표님, 사모님이 도망가요 | E14: =SUMIFS(전체리스트!D:D,전체리스트!A:A,B14,전체리스트!C:C,D14) -> 108210.48 | F14: =E14-G14 -> 0 | G14: =SUMIFS(전체리스트!E:E,전체리스트!A:A,B14,전체리스트!C:C,D14) -> 108210.48 | H14: =G14*0.05 -> 5410.524 | I14: =G14-H14 -> 102799.96
B15: 리디북스 | C15: =VLOOKUP(B15,raw_a,2,0) -> 11월분 | D15: 대표님, 오늘은 아니에요 | E15: =SUMIFS(전체리스트!D:D,전체리스트!A:A,B15,전체리스트!C:C,D15) -> 168669.2 | F15: =E15-G15 -> 0 | G15: =SUMIFS(전체리스트!E:E,전체리스트!A:A,B15,전체리스트!C:C,D15) -> 168669.2 | H15: =G15*0.05 -> 8433.46 | I15: =G15-H15 -> 160235.74
B16: 리디북스 | C16: =VLOOKUP(B16,raw_a,2,0) -> 11월분 | D16: 대표님의 삐뚤어진 사랑 | E16: =SUMIFS(전체리스트!D:D,전체리스트!A:A,B16,전체리스트!C:C,D16) -> 1928081.4 | F16: =E16-G16 -> 0 | G16: =SUMIFS(전체리스트!E:E,전체리스트!A:A,B16,전체리스트!C:C,D16) -> 1928081.4 | H16: =G16*0.05 -> 96404.068 | I16: =G16-H16 -> 1831677.3
B17: 리디북스 | C17: =VLOOKUP(B17,raw_a,2,0) -> 11월분 | D17: 레벨업에 미친 의사 | E17: =SUMIFS(전체리스트!D:D,전체리스트!A:A,B17,전체리스트!C:C,D17) -> 12180 | F17: =E17-G17 -> 0 | G17: =SUMIFS(전체리스트!E:E,전체리스트!A:A,B17,전체리스트!C:C,D17) -> 12180 | H17: =G17*0.05 -> 609 | I17: =G17-H17 -> 11571
... B45: 리디북스 | C45: =VLOOKUP(B45,raw_a,2,0) -> 11월분 | D45: 집착공의 인형놀이 | E45: =SUMIFS(전체리스트!D:D,전체리스트!A:A,B45,전체리스트!C:C,D45) -> 1182681.3 | F45: =E45-G45 -> 0 | G45: =SUMIFS(전체리스트!E:E,전체리스트!A:A,B45,전체리스트!C:C,D45) -> 1182681.3 | H45: =G45*0.05 -> 59134.066 | I45: =G45-H45 -> 1123547.2
B46: 리디북스 | C46: =VLOOKUP(B46,raw_a,2,0) -> 11월분 | D46: 초월진화 | E46: =SUMIFS(전체리스트!D:D,전체리스트!A:A,B46,전체리스트!C:C,D46) -> 140 | F46: =E46-G46 -> 0 | G46: =SUMIFS(전체리스트!E:E,전체리스트!A:A,B46,전체리스트!C:C,D46) -> 140 | H46: =G46*0.05 -> 7 | I46: =G46-H46 -> 133 | P46: ㅅ
B47: 리디북스 | C47: =VLOOKUP(B47,raw_a,2,0) -> 11월분 | D47: 츤데레 흥신소 | E47: =SUMIFS(전체리스트!D:D,전체리스트!A:A,B47,전체리스트!C:C,D47) -> 560 | F47: =E47-G47 -> 0 | G47: =SUMIFS(전체리스트!E:E,전체리스트!A:A,B47,전체리스트!C:C,D47) -> 560 | H47: =G47*0.05 -> 28 | I47: =G47-H47 -> 532
B48: 리디북스 | C48: =VLOOKUP(B48,raw_a,2,0) -> 11월분 | D48: 탑배우의 이중생활 | E48: =SUMIFS(전체리스트!D:D,전체리스트!A:A,B48,전체리스트!C:C,D48) -> 4670.4 | F48: =E48-G48 -> 0 | G48: =SUMIFS(전체리스트!E:E,전체리스트!A:A,B48,전체리스트!C:C,D48) -> 4670.4 | H48: =G48*0.05 -> 233.52 | I48: =G48-H48 -> 4436.88
B49: 리디북스 | C49: =VLOOKUP(B49,raw_a,2,0) -> 11월분 | D49: 학사신공 | E49: =SUMIFS(전체리스트!D:D,전체리스트!A:A,B49,전체리스트!C:C,D49) -> 140 | F49: =E49-G49 -> 0 | G49: =SUMIFS(전체리스트!E:E,전체리스트!A:A,B49,전체리스트!C:C,D49) -> 140 | H49: =G49*0.05 -> 7 | I49: =G49-H49 -> 133
