Workbook

Sheet 종합
A1: 태피툰(콘텐츠퍼스트)
A2: 기본정보
A3: 매출월: M 정산서 전달: M+1월 10일 내 실제 정산(세금계산서 발행): M+2월 1~15일 입금일: M+2월 말일 기타: 세금계산서 발행 (면세사업자X) RS: 태피툰 순매출의 50% ※순매출액 : 앱 마켓 수수료 30% 제외한 태피툰 매출액
A5: 매출내역
A6: 작품명 | B6: The Adventures of a Demon King's Daughter (마왕의 딸로 태어났습니다)
A7: 런칭일 | B7: 2020.09.28
A8: MG | B8: 10000000
A9: 구분(매출월) | B9: 계산서발행 | C9: 총매출 | D9: 태피툰 순매출 | E9: SW매출 | F9: SW정산액
A10: 2020.09 | B10: X | C10: =(D10/7)*100 -> 102222000 | D10: =E10*2 -> 7155540 | E10: ='월별 매출_SW'!C4 -> 3577770 | F10: =-(B8-E10) -> -6422230
A11: 2020.10 | B11: 2020.12 | C11: =(D11/7)*100 -> 2.6879657e+08 | D11: =E11*2 -> 18815760 | E11: ='월별 매출_SW'!C13 -> 9407880 | F11: =F10+E11 -> 2985650
A12: 2020.11 | B12: 2021.01 | C12: =(D12/7)*100 -> 2.3115086e+08 | D12: =E12*2 -> 16180560 | E12: ='월별 매출_SW'!C22 -> 8090280 | F12: =E12 -> 8090280
A13: 2020.12 | B13: 2021.02 | C13: =(D13/7)*100 -> 2.5707471e+08 | D13: =E13*2 -> 17995230 | E13: ='월별 매출_SW'!C31 -> 8997615 | F13: =E13 -> 8997615
A14: 2021.01 | B14: 2021.03 | C14: =(D14/7)*100 -> 3.9661457e+08 | D14: =E14*2 -> 27763020 | E14: ='월별 매출_SW'!C40 -> 13881510 | F14: =E14 -> 13881510
A15: 2021.02 | B15: 2021.04 | C15: =(D15/7)*100 -> 4.0706743e+08 | D15: =E15*2 -> 28494720 | E15: ='월별 매출_SW'!F48 -> 14247360 | F15: =E15 -> 14247360
A16: 2021.03 | B16: 2021.05 | C16: =(D16/7)*100 -> 6.6255943e+08 | D16: =E16*2 -> 46379160 | E16: ='월별 매출_SW'!F57 -> 23189580 | F16: =E16 -> 23189580
A17: 2021.04 | B17: 2021.06 | C17: =(D17/7)*100 -> 6.1361357e+08 | D17: =E17*2 -> 42952950 | E17: ='월별 매출_SW'!F66 -> 21476475 | F17: =E17 -> 21476475
A18: 2021.05 | B18: 2021.07 | C18: =(D18/7)*100 -> 6.4752171e+08 | D18: =E18*2 -> 45326520 | E18: ='월별 매출_SW'!F75 -> 22663260 | F18: =E18 -> 22663260
A19: 2021.06 | B19: 2021.08 | C19: =(D19/7)*100 -> 5.6317371e+08 | D19: =E19*2 -> 39422160 | E19: ='월별 매출_SW'!A87 -> 19711080 | F19: =E19 -> 19711080
A20: 2021.07 | B20: 2021.09 | C20: =(D20/7)*100 -> 4.9897543e+08 | D20: =E20*2 -> 34928280 | E20: 17464140 | F20: =E20 -> 17464140
A21: 2021.08 | B21: 2021.10 | C21: =(D21/7)*100 -> 514116000 | D21: =E21*2 -> 35988120 | E21: ='월별 매출_SW'!A104 -> 17994060 | F21: =E21 -> 17994060
A22: 2021.09 | B22: 2021.11 | C22: =(D22/7)*100 -> 3.9813943e+08 | D22: =E22*2 -> 27869760 | E22: ='월별 매출_SW'!C108 -> 13934880 | F22: =E22 -> 13934880
A23: 2021.10 | B23: 2021.12 | C23: =(D23/7)*100 -> 2.9564743e+08 | D23: =E23*2 -> 20695320 | E23: ='월별 매출_SW'!A120 -> 10347660 | F23: =E23 -> 10347660
A24: 2021.11 | B24: 2022.01 | C24: =(D24/7)*100 -> 2.9802343e+08 | D24: =E24*2 -> 20861640 | E24: ='월별 매출_SW'!A128 -> 10430820 | F24: =E24 -> 10430820
A25: 2021.12 | B25: 2022.02 | C25: =(D25/7)*100 -> 4.3068857e+08 | D25: =E25*2 -> 30148200 | E25: ='월별 매출_SW'!F132 -> 15074100 | F25: =E25 -> 15074100
A26: 2022.01 | B26: 2022.03 | C26: =(D26/7)*100 -> 2.1920914e+08 | D26: =E26*2 -> 15344640 | E26: ='월별 매출_SW'!F140 -> 7672320 | F26: =E26 -> 7672320
A27: 2022.02 | B27: 2022.04 | C27: =(D27/7)*100 -> 1.4851029e+08 | D27: =E27*2 -> 10395720 | E27: ='월별 매출_SW'!F147 -> 5197860 | F27: =E27 -> 5197860
A28: 2022.03 | B28: 2022.05 | C28: =(D28/7)*100 -> 1.8498343e+08 | D28: =E28*2 -> 12948840 | E28: ='월별 매출_SW'!F154 -> 6474420 | F28: =E28 -> 6474420
A29: 2022.04 | B29: 2022.06 | C29: =(D29/7)*100 -> 2.4976114e+08 | D29: =E29*2 -> 17483280 | E29: ='월별 매출_SW'!F162 -> 8741640 | F29: =E29 -> 8741640
A31: 작품명 | B31: You At First Sight (소녀예찬)
A32: 구분(매출월) | B32: 계산서발행 | C32: 총매출 | D32: 태피툰 순매출 | E32: SW매출 | F32: SW정산액
A33: 2021.08 | B33: 2021.10 | C33: =(D33/7)*100 -> 10913143 | D33: =E33*2 -> 763920 | E33: ='월별 매출_KTOON'!F5 -> 381960 | F33: =E33 -> 381960
A34: 2021.09 | B34: 2021.11 | C34: =(D34/7)*100 -> 12281143 | D34: =E34*2 -> 859680 | E34: ='월별 매출_KTOON'!F14 -> 429840 | F34: =E34 -> 429840
A35: 2021.10 | B35: 2021.12 | C35: =(D35/7)*100 -> 7452000 | D35: =E35*2 -> 521640 | E35: ='월별 매출_KTOON'!A28 -> 260820 | F35: =E35 -> 260820
A36: 2021.11 | B36: 2022.01 | C36: =(D36/7)*100 -> 6464571.4 | D36: =E36*2 -> 452520 | E36: ='월별 매출_KTOON'!A37 -> 226260 | F36: =E36 -> 226260
A37: 2021.12 | B37: 2022.02 | C37: =(D37/7)*100 -> 4690285.7 | D37: =E37*2 -> 328320 | E37: ='월별 매출_KTOON'!C42 -> 164160 | F37: =E37 -> 164160
A38: 2022.01 | B38: 2022.03 | C38: =(D38/7)*100 -> 3142285.7 | D38: =E38*2 -> 219960 | E38: ='월별 매출_KTOON'!F51 -> 109980 | F38: =E38 -> 109980
A39: 2022.02 | B39: 2022.04 | C39: =(D39/7)*100 -> 4227428.6 | D39: =E39*2 -> 295920 | E39: ='월별 매출_KTOON'!F60 -> 147960 | F39: =E39 -> 147960
A40: 2022.03 | B40: 2022.05 | C40: =(D40/7)*100 -> 3543428.6 | D40: =E40*2 -> 248040 | E40: ='월별 매출_KTOON'!F69 -> 124020 | F40: =E40 -> 124020
A41: 2022.04 | B41: 2022.06 | C41: =(D41/7)*100 -> 2324571.4 | D41: =E41*2 -> 162720 | E41: ='월별 매출_KTOON'!F78 -> 81360 | F41: =E41 -> 81360

Sheet 월별 매출_SW
A1: 월별 매출 정산내역
A2: 2020년 09월
A3: 작품명 | B3: 토큰 합계 | C3: 배분 수익 | D3: 이월 선급금 | E3: 잔여 선급금 | F3: 정산 금액
A4: The Adventures of a Demon King's Daughter (221) | B4: 79506 | C4: 3577770 | D4: 10000000 | E4: 6422230 | F4: 0
A7: 전체 수익 | B7: 총 지급액 (부가세 미포함) | C7: 지급일
A8: 0 | B8: 0 | C8: 2020-11-30
A11: 2020년 10월
A12: 작품명 | B12: 토큰 합계 | C12: 배분 수익 | D12: 이월 선급금 | E12: 잔여 선급금 | F12: 정산 금액
A13: The Adventures of a Demon King's Daughter (221) | B13: 209064 | C13: 9407880 | D13: 6422230 | E13: 0 | F13: 2985650
A16: 전체 수익 | B16: 총 지급액 (부가세 포함) | C16: 지급일
A17: 2985650 | B17: 3284215 | C17: 2020-12-31
A20: 2020년 11월
A21: 작품명 | B21: 토큰 합계 | C21: 배분 수익 | D21: 이월 선급금 | E21: 잔여 선급금 | F21: 정산 금액
A22: The Adventures of a Demon King's Daughter (221) | B22: 179784 | C22: 8090280 | D22: 0 | E22: 0 | F22: 8090280
A25: 전체 수익 | B25: 총 지급액 (부가세 포함) | C25: 지급일
A26: 8090280 | B26: 8899308 | C26: 2021-01-31
A29: 2020년 12월
A30: 작품명 | B30: 토큰 합계 | C30: 배분 수익 | D30: 이월 선급금 | E30: 잔여 선급금 | F30: 정산 금액
A31: The Adventures of a Demon King's Daughter (221) | B31: 199947 | C31: 8997615 | D31: 0 | E31: 0 | F31: 8997615
A34: 전체 수익 | B34: 총 지급액 (부가세 포함) | C34: 지급일
A35: 8997615 | B35: 9897376 | C35: 2021-02-28
A38: 2021년 01월
A39: 작품명 | B39: 토큰 합계 | C39: 배분 수익 | D39: 이월 선급금 | E39: 잔여 선급금 | F39: 정산 금액
A40: The Adventures of a Demon King's Daughter (221) | B40: 308478 | C40: 13881510 | D40: 0 | E40: 0 | F40: 13881510
A43: 전체 수익 | B43: 총 지급액 (부가세 포함) | C43: 지급일
A44: 13881510 | B44: 15269661 | C44: 2021-03-31
A46: 2021년 02월
A47: 작품명 | B47: 토큰 합계 | C47: 배분 수익 | D47: 이월 선급금 | E47: 잔여 선급금 | F47: 정산 금액
A48: The Adventures of a Demon King's Daughter (221) | B48: 316608 | C48: 14247360 | D48: 0 | E48: 0 | F48: 14247360
A51: 전체 수익 | B51: 총 지급액 (부가세 포함) | C51: 지급일
A52: 14247360 | B52: 15672096 | C52: 2021-04-30
A55: 2021년 03월
A56: 작품명 | B56: 토큰 합계 | C56: 배분 수익 | D56: 이월 선급금 | E56: 잔여 선급금 | F56: 정산 금액
A57: The Adventures of a Demon King's Daughter (221) | B57: 515324 | C57: 23189580 | D57: 0 | E57: 0 | F57: 23189580
A60: 전체 수익 | B60: 총 지급액 (부가세 포함) | C60: 지급일
A61: =F57 -> 23189580 | B61: =A61*1.1 -> 25508538 | C61: 44347
A64: 2021년 04월
A65: 작품명 | B65: 토큰 합계 | C65: 배분 수익 | D65: 이월 선급금 | E65: 잔여 선급금 | F65: 정산 금액
A66: The Adventures of a Demon King's Daughter (221) | B66: 477255 | C66: 21476475 | D66: 0 | E66: 0 | F66: 21476475
A69: 전체 수익 | B69: 총 지급액 (부가세 포함) | C69: 지급일
...

Sheet 월별 매출_KTOON
A1: 월별 매출 정산내역
A2: 2021년 08월
A3: 작품명 | B3: 포인트 합계 | C3: 배분 수익 | D3: 이월 선급금 | E3: 잔여 선급금 | F3: 정산 금액
A4: He's My Softy (38) | B4: 0 | C4: 0 | D4: 0 | E4: 0 | F4: 0
A5: You At First Sight (41) | B5: 636600 | C5: 381960 | D5: 0 | E5: 0 | F5: 381960
A8: 전체 수익 | B8: 총 지급액 (부가세 포함) | C8: 지급일
A9: 381960 | B9: 420156 | C9: 2021-10-31
A11: 2021년 09월
A12: 작품명 | B12: 포인트 합계 | C12: 배분 수익 | D12: 이월 선급금 | E12: 잔여 선급금 | F12: 정산 금액
A13: He's My Softy (38) | B13: 0 | C13: 0 | D13: 0 | E13: 0 | F13: 0
A14: You At First Sight (41) | B14: 716400 | C14: 429840 | D14: 0 | E14: 0 | F14: 429840
A17: 전체 수익 | B17: 총 지급액 (부가세 포함) | C17: 지급일
A18: 429840 | B18: 472824 | C18: 2021-11-30
A21: 2021년 10월
A22: 작품명 | B22: 포인트 합계 | C22: 배분 수익 | D22: 이월 선급금 | E22: 잔여 선급금 | F22: 정산 금액
A23: He's My Softy (38) | B23: 0 | C23: 0 | D23: 0 | E23: 0 | F23: 0
A24: You At First Sight (41) | B24: 434700 | C24: 260820 | D24: 0 | E24: 0 | F24: 260820
A27: 전체 수익 | B27: 총 지급액 (부가세 포함) | C27: 지급일
A28: 260820 | B28: 286902 | C28: 2021-12-31
A30: 2021년 11월
A31: 작품명 | B31: 포인트 합계 | C31: 배분 수익 | D31: 이월 선급금 | E31: 잔여 선급금 | F31: 정산 금액
A32: He's My Softy (38) | B32: 0 | C32: 0 | D32: 0 | E32: 0 | F32: 0
A33: You At First Sight (41) | B33: 377100 | C33: 226260 | D33: 0 | E33: 0 | F33: 226260
A36: 전체 수익 | B36: 총 지급액 (부가세 포함) | C36: 지급일
A37: 226260 | B37: 248886 | C37: 2022-01-31
A39: 2021년 12월
A40: 작품명 | B40: 포인트 합계 | C40: 배분 수익 | D40: 이월 선급금 | E40: 잔여 선급금 | F40: 정산 금액
A41: He's My Softy (38) | B41: 0 | C41: 0 | D41: 0 | E41: 0 | F41: 0
A42: You At First Sight (41) | B42: 273600 | C42: 164160 | D42: 0 | E42: 0 | F42: 164160
A45: 전체 수익 | B45: 총 지급액 (부가세 포함) | C45: 지급일
A46: 164160 | B46: 180576 | C46: 2022-02-28
A48: 2022년 1월
A49: 작품명 | B49: 포인트 합계 | C49: 배분 수익 | D49: 이월 선급금 | E49: 잔여 선급금 | F49: 정산 금액
A50: He's My Softy (38) | B50: 0 | C50: 0 | D50: 0 | E50: 0 | F50: 0
A51: You At First Sight (41) | B51: 183300 | C51: 109980 | D51: 0 | E51: 0 | F51: 109980
A54: 전체 수익 | B54: 총 지급액 (부가세 포함) | C54: 지급일
A55: 109980 | B55: 120978 | C55: 2022-03-31
A57: 2022년 2월
A58: 작품명 | B58: 포인트 합계 | C58: 배분 수익 | D58: 이월 선급금 | E58: 잔여 선급금 | F58: 정산 금액
A59: He's My Softy (38) | B59: 0 | C59: 0 | D59: 0 | E59: 0 | F59: 0
...
