Workbook

Sheet 합계
B2: ■ 만화가족 2022.02월 KT 정산서 | J2: *익익월 입금
J3: 선지급금 | K3: 1027970000
B4: 사이트명 | C4: 소비자매출액 | D4: 유통사수수료 | E4: 케이티매출액 | F4: 케이티수익 | G4: 만화가족 수익 | H4: 비고 | J4: KT프로젝트수익 | K4: 250000000
B5: 카카오페이지1 | C5: =카카오페이지1!D7 -> 18550000 | D5: =카카오페이지1!E7 -> 0 | E5: =카카오페이지1!F7 -> 18550000 | F5: =카카오페이지1!G7 -> 3710000 | G5: =카카오페이지1!H7 -> 14840000 | H5: 연재고료 | J5: 월별 회수금 (케이티 수익)
B6: 카카오페이지2 | C6: =카카오페이지2!D6 -> 10737935 | D6: =카카오페이지2!E6 -> 4648831.3 | E6: =카카오페이지2!F6 -> 6089104 | F6: =카카오페이지2!G6 -> 1217820.8 | G6: =카카오페이지2!H6 -> 4871283.2 | H6: 유료판매 | J6: 2018. 08 | K6: 14506621 | L6: 입금
B7: 네이버웹툰1 | C7: =네이버웹툰1!D5 -> 4700000 | D7: =네이버웹툰1!E5 -> 0 | E7: =네이버웹툰1!F5 -> 4700000 | F7: =네이버웹툰1!G5 -> 940000 | G7: =네이버웹툰1!H5 -> 3760000 | H7: 연재고료 | J7: 2018. 09 | K7: 8562269 | L7: 입금
B8: 네이버웹툰2 | C8: =네이버웹툰2!D20 -> 115630393 | D8: =네이버웹툰2!E20 -> 52232688 | E8: =네이버웹툰2!F20 -> 63397705 | F8: =네이버웹툰2!G20 -> 12679541 | G8: =네이버웹툰2!H20 -> 50718164 | H8: 유료판매 | J8: 2018. 10 | K8: 17036883 | L8: 입금
B9: 테크앤조이 | C9: =테크앤조이!D4 -> 762859 | D9: =테크앤조이!E4 -> 457715 | E9: =테크앤조이!F4 -> 305144 | F9: =테크앤조이!G4 -> 61028.8 | G9: =테크앤조이!H4 -> 244115.2 | H9: 유료판매 | J9: 2018. 11 | K9: 30825944 | L9: 입금
B10: 키다리스튜디오 | C10: =키다리스튜디오!D4 -> 12389440 | D10: =키다리스튜디오!E4 -> 9703554 | E10: =키다리스튜디오!F4 -> 2685886 | F10: =키다리스튜디오!G4 -> 537177.2 | G10: =키다리스튜디오!H4 -> 2148708.8 | H10: 유료판매 | J10: 2018. 12 | K10: 17198136 | L10: 입금
B11: 탑툰 | C11: =탑툰!D4 -> 3335368 | D11: =네이버웹툰1!E9 -> 0 | E11: =탑툰!F4 -> 3335368 | F11: =탑툰!G4 -> 667073.6 | G11: =탑툰!H4 -> 2668294.4 | H11: 유료판매 | J11: 2018년 합계 | K11: =SUM(K6:K10) -> 88129853
B12: 합계 | C12: =SUM(C5:C11) -> 1.66106e+08 | D12: =SUM(D5:D11) -> 67042788 | E12: =SUM(E5:E11) -> 99063207 | F12: =SUM(F5:F11) -> 19812641 | G12: =SUM(G5:G11) -> 79250566 | J12: 2019.01 | K12: 17,908,333 | L12: 입금
F13: =E12*0.2 -> 19812641 | G13: =E12*0.8 -> 79250566 | J13: 2019.02 | K13: 40642286 | L13: 입금
B14: ＊각 플랫폼 데이터는 시트 추가하여 작성, 합계 표로 가져와 총 정산금액 정리 | J14: 2019.03 | K14: 28776392 | L14: 입금
J15: 2019.04 | K15: 17432662 | L15: 입금
J16: 2019.05 | K16: 35056871 | L16: 입금
B17: 구분 | D17: 금액 | J17: 2019.06 | K17: 33089659 | L17: 입금
B18: 케이티> 만화가족 계산서 발행 금액 | D18: =F12 -> 19812641 | J18: 2019.07 | K18: 17278906 | L18: 입금
B19: 만화가족> 입금 대상 금액 | D19: =D18 -> 19812641 | J19: 2019.08 | K19: 24626732 | L19: 입금
J20: 2019.09 | K20: 27140688 | L20: 입금
J21: 2019.10 | K21: 29171298 | L21: 입금
J22: 2019.11 | K22: 15744187 | L22: 입금
J23: 2019.12 | K23: 18683634 | L23: 입금
J24: 2019년 합계 | K24: =SUM(K12:K23) -> 287643315
J25: 2020.01 | K25: 25963688 | L25: 입금
J26: 2020.02 | K26: 24673815 | L26: 입금 | M26: 입금 : 스토리위즈
J27: 2020.03 | K27: 24315434 | L27: 입금
J28: 2020.04 | K28: 31918486 | L28: 입금
J29: 2020.05 | K29: 27302553 | L29: 입금
J30: 2020.06 | K30: 25712668 | L30: 입금
J31: 2020.07 | K31: 29131889 | L31: 입금
J32: 2020.08 | K32: 27059690 | L32: 입금
J33: 2020.09 | K33: 34344144 | L33: 입금
J34: 2020.10 | K34: 27618375 | L34: 입금
J35: 2020.11 | K35: 18666794 | L35: 입금 | M35: 11/10초과분 18,000원 차감 후 지급
J36: 2020.12 | K36: 22399933 | L36: 입금
J37: 2020년 합계 | K37: =SUM(K25:K36) -> 319107469
J38: 2021.01 | K38: 25525201 | L38: 입금
J39: 2021.02 | K39: 23838777 | L39: 입금
J40: 2021.03 | K40: 19328258 | L40: 입금
J41: 2021.04 | K41: 20722060 | L41: 입금
...

Sheet 계정정보
B2: ■ 만화가족 유통계정정보
B4: 서비스명 | C4: 아이디 | D4: 패스워드 | E4: URL
B5: 카카오페이지 | C5: toonsfamily11 | D5: aocnf60djr! | E5: https://biz.kakaopage.com/partner/login
B6: 네이버 | C6: FRA01967 | D6: Good2seeu! | E6: https://friend.navercorp.com/login/loginForm.sec?url=%2Fview%2Fsvc%2Fmain%3FsvcId%3DCOM%26lz%3Dko_KR%26tz%3DAsia%252FSeoul%253A%252B09%253A00&c=d# | F6: 구작
C7: FRA09683 | D7: aocnf60djr! | E7: https://friend.navercorp.com/login/loginForm.sec?url=%2Fview%2Fsvc%2Fmain%3FsvcId%3DCOM%26lz%3Dko_KR%26tz%3DAsia%252FSeoul%253A%252B09%253A00&c=d# | F7: 악마와계약연애
C8: FRA07849 | D8: aocnf60djr! | E8: https://friend.navercorp.com/login/loginForm.sec?url=%2Fview%2Fsvc%2Fmain%3FsvcId%3DCOM%26lz%3Dko_KR%26tz%3DAsia%252FSeoul%253A%252B09%253A00&c=d# | F8: 반투명인간
C9: FRA08900 | D9: Epemfkdlvm8! | E9: https://friend.navercorp.com/login/loginForm.sec?url=%2Fview%2Fsvc%2Fmain%3FsvcId%3DCOM%26lz%3Dko_KR%26tz%3DAsia%252FSeoul%253A%252B09%253A00&c=d# | F9: 데드라이프
C10: FRA07850 | D10: aocnf60djr! | E10: https://friend.navercorp.com/login/loginForm.sec?url=%2Fview%2Fsvc%2Fmain%3FsvcId%3DCOM%26lz%3Dko_KR%26tz%3DAsia%252FSeoul%253A%252B09%253A00&c=d# | F10: 황금의핸드메이커
C11: FRA09684 | D11: aocnf60djr! | E11: https://friend.navercorp.com/login/loginForm.sec?url=%2Fview%2Fsvc%2Fmain%3FsvcId%3DCOM%26lz%3Dko_KR%26tz%3DAsia%252FSeoul%253A%252B09%253A00&c=d# | F11: 나를바꿔줘
C12: FRA09669 | D12: aocnf60djr! | E12: https://friend.navercorp.com/login/loginForm.sec?url=%2Fview%2Fsvc%2Fmain%3FsvcId%3DCOM%26lz%3Dko_KR%26tz%3DAsia%252FSeoul%253A%252B09%253A00&c=d# | F12: 그녀의 버킷리스트

Sheet 카카오페이지1
B2: 사이트명 | C2: 작품명 | D2: 소비자매출액 | E2: 유통사수수료 | F2: 케이티매출액 | G2: 케이티수익 | H2: 만화가족 수익 | I2: 비고
B3: 카카오페이지 | C3: 부기영화 | D3: 4000000 | E3: 0 | F3: =D3 -> 4000000 | G3: =F3*20% -> 800000 | H3: =F3*80% -> 3200000 | I3: 1월 MG (요율 : 약 60%, 카카오페이지 약관에 따름)
B4: 카카오페이지 | C4: 더익스트림 | D4: 5400000 | E4: 0 | F4: =D4 -> 5400000 | G4: =F4*20% -> 1080000 | H4: =F4*80% -> 4320000 | I4: 1월 MG (요율 : 약 60%, 카카오페이지 약관에 따름)
B5: 카카오페이지 | C5: 시히트왕국정복기 | D5: 2400000 | E5: 0 | F5: =D5 -> 2400000 | G5: =F5*20% -> 480000 | H5: =F5*80% -> 1920000 | I5: 1월 MG (요율 : 약 60%, 카카오페이지 약관에 따름)
B6: 카카오페이지 | C6: 웽 | D6: 6750000 | E6: 0 | F6: =D6 -> 6750000 | G6: =F6*20% -> 1350000 | H6: =F6*80% -> 5400000 | I6: 1월 MG (요율 : 약 60%, 카카오페이지 약관에 따름)
B7: 합계 | D7: =SUM(D3:D6) -> 18550000 | E7: =SUM(E3:E6) -> 0 | F7: =SUM(F3:F6) -> 18550000 | G7: =SUM(G3:G6) -> 3710000 | H7: =SUM(H3:H6) -> 14840000
G8: =F7*0.2 -> 3710000 | H8: =F7*0.8 -> 14840000

Sheet 카카오페이지2
B2: 사이트명 | C2: 작품명 | D2: 소비자매출액 | E2: 유통사수수료 | F2: 케이티매출액 | G2: 케이티수익 | H2: 만화가족 수익 | I2: 비고
B3: 카카오페이지 | C3: 우리집아이돌 | D3: =AD30 -> 772120 | E3: =D3-F3 -> 289927 | F3: 482193 | G3: =F3*20% -> 96438.6 | H3: =F3*80% -> 385754.4 | I3: 1월 초과수익
B4: 카카오페이지 | C4: 재밌니짝사랑 | D4: =AD20 -> 5208906.3 | E4: =D4-F4 -> 1982955.3 | F4: 3225951 | G4: =F4*20% -> 645190.2 | H4: =F4*80% -> 2580760.8 | I4: 1월 초과수익
B5: 카카오페이지 | C5: 날라리 外 | D5: 4756909 | E5: =D5-F5 -> 2375949 | F5: 2380960 | G5: =F5*20% -> 476192 | H5: =F5*80% -> 1904768 | I5: 픽코마 12월 RS
B6: 합계 | D6: =SUM(D3:D5) -> 10737935 | E6: =SUM(E3:E5) -> 4648831.3 | F6: =SUM(F3:F5) -> 6089104 | G6: =SUM(G3:G5) -> 1217820.8 | H6: =SUM(H3:H5) -> 4871283.2
G7: =F6*0.2 -> 1217820.8 | H7: =F6*0.8 -> 4871283.2 | L7: `
A10: 기초정보 | T10: 거래현황(캐시) | AD10: 거래금액(원화) | AN10: CP
A11: 특별/일반 | B11: 사업자명 | C11: 사업자번호 | D11: 발행자명 | E11: 계약UID | F11: 계약유형 | G11: 계약(과/면세) | H11: 당월신규계약여부 | I11: 카테고리 | J11: 시리즈ID | K11: 시리즈명 | L11: 제품코드(발행자가 부여하는 코드) | M11: 레이블 | N11: 작가명 | O11: ISBN(유/무) | P11: CP정산율_안드로이드/이벤트캐시 | Q11: CP정산율_iOS | R11: 이용권 종류 | S11: 이용권 금액 | T11: 캐시합계 | U11: CPP | V11: CPI | W11: CP1 | X11: CP2 | Y11: CP3 | Z11: CP7 | AA11: CP8 | AB11: CP9 | AC11: 이벤트캐시 | AD11: 원화합계 | AE11: CPP | AF11: CPI | AG11: CP1 | AH11: CP2 | AI11: CP3 | AJ11: CP7 | AK11: CP8 | AL11: CP9 | AM11: 이벤트캐시 | AN11: 공급가액 | AO11: 세액 | AP11: 합계금액
A12: 특별계약 | B12: 주식회사 만화가족 | C12: 2618118972 | D12: 만화가족 | E12: 1222.0 | F12: 웹툰 선투자 직계약 | G12: 과세 | H12: N | I12: 만화 | J12: 50744771 | K12: 재밌니, 짝사랑 | N12: 손길 | O12: Y | P12: 0.7 | Q12: 0.6 | R12: 단일 이용권 | S12: 400 | T12: 161600 | U12: 38650 | V12: 0 | W12: 0 | X12: 0 | Y12: 1000 | Z12: 10200 | AA12: 0 | AB12: 0 | AC12: 111750 | AD12: 162820 | AE12: 38650 | AF12: 0 | AG12: 0 | AH12: 0 | AI12: 1200 | AJ12: 11220 | AK12: 0 | AL12: 0 | AM12: 111750 | AN12: 102484 | AO12: 10248 | AP12: 112732
A13: 특별계약 | B13: 주식회사 만화가족 | C13: 2618118972 | D13: 만화가족 | E13: 1222.0 | F13: 웹툰 선투자 직계약 | G13: 과세 | H13: N | I13: 만화 | J13: 50744771 | K13: 재밌니, 짝사랑 | N13: 손길 | O13: Y | P13: 0.7 | Q13: 0.6 | R13: 시리즈 이용권 패키지 | S13: 3600 | T13: 74800 | U13: 56200 | V13: 0 | W13: 0 | X13: 0 | Y13: 0 | Z13: 3600 | AA13: 0 | AB13: 0 | AC13: 15000 | AD13: 75160 | AE13: 56200 | AF13: 0 | AG13: 0 | AH13: 0 | AI13: 0 | AJ13: 3960 | AK13: 0 | AL13: 0 | AM13: 15000 | AN13: 47469 | AO13: 4747 | AP13: 52216
A14: 특별계약 | B14: 주식회사 만화가족 | C14: 2618118972 | D14: 만화가족 | E14: 1222.0 | F14: 웹툰 선투자 직계약 | G14: 과세 | H14: N | I14: 만화 | J14: 50744771 | K14: 재밌니, 짝사랑 | N14: 손길 | O14: Y | P14: 0.7 | Q14: 0.6 | R14: 시리즈 이용권 패키지 | S14: 7200 | T14: 100000 | U14: 57400 | V14: 0 | W14: 0 | X14: 0 | Y14: 0 | Z14: 31000 | AA14: 0 | AB14: 0 | AC14: 11600 | AD14: 103100 | AE14: 57400 | AF14: 0 | AG14: 0 | AH14: 0 | AI14: 0 | AJ14: 34100 | AK14: 0 | AL14: 0 | AM14: 11600 | AN14: 62509 | AO14: 6251 | AP14: 68760
A15: 특별계약 | B15: 주식회사 만화가족 | C15: 2618118972 | D15: 만화가족 | E15: 1222.0 | F15: 웹툰 선투자 직계약 | G15: 과세 | H15: N | I15: 만화 | J15: 50744771 | K15: 재밌니, 짝사랑 | N15: 손길 | O15: Y | P15: 0.7 | Q15: 0.6 | R15: 시리즈 이용권 패키지 | S15: 10800 | T15: 583200 | U15: 338900 | V15: 0 | W15: 0 | X15: 0 | Y15: 700 | Z15: 172100 | AA15: 0 | AB15: 0 | AC15: 71500 | AD15: 600550 | AE15: 338900 | AF15: 0 | AG15: 0 | AH15: 0 | AI15: 840 | AJ15: 189310 | AK15: 0 | AL15: 0 | AM15: 71500 | AN15: 364882 | AO15: 36488 | AP15: 401370
A16: 특별계약 | B16: 주식회사 만화가족 | C16: 2618118972 | D16: 만화가족 | E16: 1222.0 | F16: 웹툰 선투자 직계약 | G16: 과세 | H16: N | I16: 만화 | J16: 50744771 | K16: 재밌니, 짝사랑 | N16: 손길 | O16: Y | P16: 0.7 | Q16: 0.6 | R16: 단일 대여 이용권 | S16: 200 | T16: 1269600 | U16: 293670 | V16: 0 | W16: 0 | X16: 400 | Y16: 57390 | Z16: 58390 | AA16: 0 | AB16: 0 | AC16: 859750 | AD16: 1287037.6 | AE16: 293670 | AF16: 0 | AG16: 0 | AH16: 520.5884 | AI16: 68868 | AJ16: 64229 | AK16: 0 | AL16: 0 | AM16: 859750 | AN16: 806877 | AO16: 80688 | AP16: 887565
A17: 특별계약 | B17: 주식회사 만화가족 | C17: 2618118972 | D17: 만화가족 | E17: 1222.0 | F17: 웹툰 선투자 직계약 | G17: 과세 | H17: N | I17: 만화 | J17: 50744771 | K17: 재밌니, 짝사랑 | N17: 손길 | O17: Y | P17: 0.7 | Q17: 0.6 | R17: 시리즈 대여 이용권 패키지 | S17: 1800 | T17: 784000 | U17: 463010 | V17: 0 | W17: 0 | X17: 0 | Y17: 22740 | Z17: 59600 | AA17: 0 | AB17: 0 | AC17: 238650 | AD17: 794508 | AE17: 463010 | AF17: 0 | AG17: 0 | AH17: 0 | AI17: 27288 | AJ17: 65560 | AK17: 0 | AL17: 0 | AM17: 238650 | AN17: 497155 | AO17: 49716 | AP17: 546871
A18: 특별계약 | B18: 주식회사 만화가족 | C18: 2618118972 | D18: 만화가족 | E18: 1222.0 | F18: 웹툰 선투자 직계약 | G18: 과세 | H18: N | I18: 만화 | J18: 50744771 | K18: 재밌니, 짝사랑 | N18: 손길 | O18: Y | P18: 0.7 | Q18: 0.6 | R18: 시리즈 대여 이용권 패키지 | S18: 3600 | T18: 490600 | U18: 296200 | V18: 0 | W18: 0 | X18: 0 | Y18: 7600 | Z18: 101000 | AA18: 0 | AB18: 0 | AC18: 85800 | AD18: 502220 | AE18: 296200 | AF18: 0 | AG18: 0 | AH18: 0 | AI18: 9120 | AJ18: 111100 | AK18: 0 | AL18: 0 | AM18: 85800 | AN18: 308665 | AO18: 30867 | AP18: 339532
A19: 특별계약 | B19: 주식회사 만화가족 | C19: 2618118972 | D19: 만화가족 | E19: 1222.0 | F19: 웹툰 선투자 직계약 | G19: 과세 | H19: N | I19: 만화 | J19: 50744771 | K19: 재밌니, 짝사랑 | N19: 손길 | O19: Y | P19: 0.7 | Q19: 0.6 | R19: 시리즈 대여 이용권 패키지 | S19: 5400 | T19: 1647400 | U19: 1158550 | V19: 0 | W19: 0 | X19: 500 | Y19: 6650 | Z19: 346300 | AA19: 0 | AB19: 0 | AC19: 135400 | AD19: 1683510.7 | AE19: 1158550 | AF19: 0 | AG19: 0 | AH19: 650.7355 | AI19: 7980 | AJ19: 380930 | AK19: 0 | AL19: 0 | AM19: 135400 | AN19: 1035910 | AO19: 103591 | AP19: 1139501
AD20: =SUM(AD12:AD19) -> 5208906.3
A22: 기초정보 | T22: 거래현황(캐시) | AD22: 거래금액(원화) | AN22: CP
A23: 특별/일반 | B23: 사업자명 | C23: 사업자번호 | D23: 발행자명 | E23: 계약UID | F23: 계약유형 | G23: 계약(과/면세) | H23: 당월신규계약여부 | I23: 카테고리 | J23: 시리즈ID | K23: 시리즈명 | L23: 제품코드(발행자가 부여하는 코드) | M23: 레이블 | N23: 작가명 | O23: ISBN(유/무) | P23: CP정산율_안드로이드/이벤트캐시 | Q23: CP정산율_iOS | R23: 이용권 종류 | S23: 이용권 금액 | T23: 캐시합계 | U23: CPP | V23: CPI | W23: CP1 | X23: CP2 | Y23: CP3 | Z23: CP7 | AA23: CP8 | AB23: CP9 | AC23: 이벤트캐시 | AD23: 원화합계 | AE23: CPP | AF23: CPI | AG23: CP1 | AH23: CP2 | AI23: CP3 | AJ23: CP7 | AK23: CP8 | AL23: CP9 | AM23: 이벤트캐시 | AN23: 공급가액 | AO23: 세액 | AP23: 합계금액
A24: 특별계약 | B24: 주식회사 만화가족 | C24: 2618118972 | D24: 만화가족 | E24: 1246.0 | F24: 웹툰 선투자 직계약 | G24: 과세 | H24: N | I24: 만화 | J24: 53067806 | K24: 우리집 아이돌 | N24: 한둘,자라개 | O24: Y | P24: 0.7 | Q24: 0.6 | R24: 단일 이용권 | S24: 400 | T24: 6400 | U24: 4400 | V24: 0 | W24: 0 | X24: 0 | Y24: 0 | Z24: 0 | AA24: 0 | AB24: 0 | AC24: 2000 | AD24: 6400 | AE24: 4400 | AF24: 0 | AG24: 0 | AH24: 0 | AI24: 0 | AJ24: 0 | AK24: 0 | AL24: 0 | AM24: 2000 | AN24: 4073 | AO24: 407 | AP24: 4480
A25: 특별계약 | B25: 주식회사 만화가족 | C25: 2618118972 | D25: 만화가족 | E25: 1246.0 | F25: 웹툰 선투자 직계약 | G25: 과세 | H25: N | I25: 만화 | J25: 53067806 | K25: 우리집 아이돌 | N25: 한둘,자라개 | O25: Y | P25: 0.7 | Q25: 0.6 | R25: 시리즈 이용권 패키지 | S25: 3600 | T25: -1200 | U25: 1200 | V25: 0 | W25: 0 | X25: 0 | Y25: -2400 | Z25: 0 | AA25: 0 | AB25: 0 | AC25: 0 | AD25: -1680 | AE25: 1200 | AF25: 0 | AG25: 0 | AH25: 0 | AI25: -2880 | AJ25: 0 | AK25: 0 | AL25: 0 | AM25: 0 | AN25: -807 | AO25: -81 | AP25: -888
A26: 특별계약 | B26: 주식회사 만화가족 | C26: 2618118972 | D26: 만화가족 | E26: 1246.0 | F26: 웹툰 선투자 직계약 | G26: 과세 | H26: N | I26: 만화 | J26: 53067806 | K26: 우리집 아이돌 | N26: 한둘,자라개 | O26: Y | P26: 0.7 | Q26: 0.6 | R26: 시리즈 이용권 패키지 | S26: 7200 | T26: 50400 | U26: 50400 | V26: 0 | W26: 0 | X26: 0 | Y26: 0 | Z26: 0 | AA26: 0 | AB26: 0 | AC26: 0 | AD26: 50400 | AE26: 50400 | AF26: 0 | AG26: 0 | AH26: 0 | AI26: 0 | AJ26: 0 | AK26: 0 | AL26: 0 | AM26: 0 | AN26: 32073 | AO26: 3207 | AP26: 35280
A27: 특별계약 | B27: 주식회사 만화가족 | C27: 2618118972 | D27: 만화가족 | E27: 1246.0 | F27: 웹툰 선투자 직계약 | G27: 과세 | H27: N | I27: 만화 | J27: 53067806 | K27: 우리집 아이돌 | N27: 한둘,자라개 | O27: Y | P27: 0.7 | Q27: 0.6 | R27: 단일 대여 이용권 | S27: 200 | T27: 194800 | U27: 64100 | V27: 0 | W27: 0 | X27: 0 | Y27: 4400 | Z27: 7000 | AA27: 0 | AB27: 0 | AC27: 119300 | AD27: 196380 | AE27: 64100 | AF27: 0 | AG27: 0 | AH27: 0 | AI27: 5280 | AJ27: 7700 | AK27: 0 | AL27: 0 | AM27: 119300 | AN27: 123789 | AO27: 12379 | AP27: 136168
A28: 특별계약 | B28: 주식회사 만화가족 | C28: 2618118972 | D28: 만화가족 | E28: 1246.0 | F28: 웹툰 선투자 직계약 | G28: 과세 | H28: N | I28: 만화 | J28: 53067806 | K28: 우리집 아이돌 | N28: 한둘,자라개 | O28: Y | P28: 0.7 | Q28: 0.6 | R28: 시리즈 대여 이용권 패키지 | S28: 1800 | T28: 199200 | U28: 171100 | V28: 0 | W28: 0 | X28: 0 | Y28: 3600 | Z28: 10800 | AA28: 0 | AB28: 0 | AC28: 13700 | AD28: 201000 | AE28: 171100 | AF28: 0 | AG28: 0 | AH28: 0 | AI28: 4320 | AJ28: 11880 | AK28: 0 | AL28: 0 | AM28: 13700 | AN28: 126436 | AO28: 12644 | AP28: 139080
A29: 특별계약 | B29: 주식회사 만화가족 | C29: 2618118972 | D29: 만화가족 | E29: 1246.0 | F29: 웹툰 선투자 직계약 | G29: 과세 | H29: N | I29: 만화 | J29: 53067806 | K29: 우리집 아이돌 | N29: 한둘,자라개 | O29: Y | P29: 0.7 | Q29: 0.6 | R29: 시리즈 대여 이용권 패키지 | S29: 3600 | T29: 312200 | U29: 230100 | V29: 0 | W29: 0 | X29: 0 | Y29: 7200 | Z29: 59800 | AA29: 0 | AB29: 0 | AC29: 15100 | AD29: 319620 | AE29: 230100 | AF29: 0 | AG29: 0 | AH29: 0 | AI29: 8640 | AJ29: 65780 | AK29: 0 | AL29: 0 | AM29: 15100 | AN29: 196629 | AO29: 19663 | AP29: 216292
AD30: =SUM(AD24:AD29) -> 772120

Sheet 네이버웹툰1
B2: 사이트명 | C2: 작품명 | D2: 소비자매출액 | E2: 유통사수수료 | F2: 케이티매출액 | G2: 케이티수익 | H2: 만화가족 수익 | I2: 비고
B3: 네이버웹툰 | C3: 견우와선녀 | D3: 2200000 | E3: 0 | F3: =D3 -> 2200000 | G3: =F3*20% -> 440000 | H3: =F3*80% -> 1760000 | I3: 12월 고료
B4: 네이버웹툰 | C4: 나를바꿔줘 | D4: 2500000 | E4: 0 | F4: =D4 -> 2500000 | G4: =F4*20% -> 500000 | H4: =F4*80% -> 2000000 | I4: 12월 고료
B5: 합계 | D5: =SUM(D3:D4) -> 4700000 | E5: =SUM(E3:E4) -> 0 | F5: =SUM(F3:F4) -> 4700000 | G5: =SUM(G3:G4) -> 940000 | H5: =SUM(H3:H4) -> 3760000
G6: =F5*0.2 -> 940000 | H6: =F5*0.8 -> 3760000

Sheet 네이버웹툰2
B2: 사이트명 | C2: 작품명 | D2: 소비자매출액 | E2: 유통사수수료 | F2: 케이티매출액 | G2: 케이티수익 | H2: 만화가족 수익 | I2: 비고
B3: 네이버웹툰 | C3: 글로벌 | D3: 7757187 | E3: - | F3: =D3 -> 7757187 | G3: =F3*20% -> 1551437.4 | H3: =F3*80% -> 6205749.6 | I3: 12월 글로벌
B4: 네이버웹툰 | C4: 창작지원금_견우와선녀 | D4: 91249 | E4: - | F4: =D4 -> 91249 | G4: =F4*20% -> 18249.8 | H4: =F4*80% -> 72999.2 | I4: 12월 창작
B5: 네이버웹툰 | C5: 창작지원금_나를바꿔줘 | D5: 111961 | E5: - | F5: =D5 -> 111961 | G5: =F5*20% -> 22392.2 | H5: =F5*80% -> 89568.8 | I5: 12월 창작
B6: 네이버웹툰 | C6: 데드라이프_앱 | D6: 39512363 | E6: =D6-F6 -> 17935477 | F6: 21576886 | G6: =F6*20% -> 4315377.2 | H6: =F6*80% -> 17261509 | I6: 1월
B7: 네이버웹툰 | C7: 데드라이프_웹 | D7: 314020 | E7: =D7-F7 -> 137089 | F7: 176931 | G7: =F7*20% -> 35386.2 | H7: =F7*80% -> 141544.8 | I7: 1월
B8: 네이버웹툰 | C8: 그녀의 버킷리스트_앱 | D8: 624934 | E8: =D8-F8 -> 303850 | F8: 321084 | G8: =F8*20% -> 64216.8 | H8: =F8*80% -> 256867.2 | I8: 1월
B9: 네이버웹툰 | C9: 그녀의 버킷리스트_웹 | D9: 10200 | E9: =D9-F9 -> 4636 | F9: 5564 | G9: =F9*20% -> 1112.8 | H9: =F9*80% -> 4451.2 | I9: 1월
B10: 네이버웹툰 | C10: 나를바꿔줘_앱 | D10: 61897004 | E10: =D10-F10 -> 31259516 | F10: 30637488 | G10: =F10*20% -> 6127497.6 | H10: =F10*80% -> 24509990 | I10: 1월
B11: 네이버웹툰 | C11: 나를바꿔줘_웹 | D11: 309080 | E11: =D11-F11 -> 152410 | F11: 156670 | G11: =F11*20% -> 31334 | H11: =F11*80% -> 125336 | I11: 1월
B12: 네이버웹툰 | C12: 악마와계약연애_앱 | D12: 4066495 | E12: =D12-F12 -> 2048753 | F12: 2017742 | G12: =F12*20% -> 403548.4 | H12: =F12*80% -> 1614193.6 | I12: 1월
B13: 네이버웹툰 | C13: 악마와계약연애_웹 | D13: 117380 | E13: =D13-F13 -> 58532 | F13: 58848 | G13: =F13*20% -> 11769.6 | H13: =F13*80% -> 47078.4 | I13: 1월
B14: 네이버웹툰 | C14: 반투명인간_앱 | D14: 31640 | E14: =D14-F14 -> 16349 | F14: 15291 | G14: =F14*20% -> 3058.2 | H14: =F14*80% -> 12232.8 | I14: 1월
B15: 네이버웹툰 | C15: 반투명인간_웹 | D15: 3200 | E15: =D15-F15 -> 1571 | F15: 1629 | G15: =F15*20% -> 325.8 | H15: =F15*80% -> 1303.2 | I15: 1월
B16: 네이버웹툰 | C16: 황금의핸드메이커_앱 | D16: 63200 | E16: =D16-F16 -> 31407 | F16: 31793 | G16: =F16*20% -> 6358.6 | H16: =F16*80% -> 25434.4 | I16: 1월
B17: 네이버웹툰 | C17: 황금의핸드메이커_웹 | D17: 400 | E17: =D17-F17 -> 196 | F17: 204 | G17: =F17*20% -> 40.8 | H17: =F17*80% -> 163.2 | I17: 1월
... B19: 네이버웹툰 | C19: 만화가족구작_웹 | D19: 13020 | E19: =D19-F19 -> 4758 | F19: 8262 | G19: =F19*20% -> 1652.4 | H19: =F19*80% -> 6609.6 | I19: 1월
B20: 합계 | D20: =SUM(D3:D19) -> 115630393 | E20: =SUM(E3:E19) -> 52232688 | F20: =SUM(F3:F19) -> 63397705 | G20: =SUM(G3:G19) -> 12679541 | H20: =SUM(H3:H19) -> 50718164
G21: =F20*0.2 -> 12679541 | H21: =F20*0.8 -> 50718164

Sheet 테크앤조이
B2: 사이트명 | C2: 작품명 | D2: 소비자매출액 | E2: 유통사수수료 | F2: 케이티매출액 | G2: 케이티수익 | H2: 만화가족 수익 | I2: 비고
B3: 테크앤조이 | C3: 투믹스/나인픽셀즈 | D3: =테크앤조이정산서!C6 -> 762859 | E3: =D3-F3 -> 457715 | F3: 305144 | G3: =F3*20% -> 61028.8 | H3: =F3*80% -> 244115.2 | I3: 11월 RS
B4: 합계 | D4: =SUM(D3:D3) -> 762859 | E4: =SUM(E3:E3) -> 457715 | F4: =SUM(F3:F3) -> 305144 | G4: =SUM(G3:G3) -> 61028.8 | H4: =SUM(H3:H3) -> 244115.2
G5: =F4*0.2 -> 61028.8 | H5: =F4*0.8 -> 244115.2

Sheet 테크앤조이정산서
B2: 양방향서비스 21년 11월 서비스분 매출정산
G4: 21년 1월 서비스분(VAT별도)
B5: 구분 | C5: 총 청구금액 | D5: 현금 결제 | E5: 포인트결제 | F5: 공동 마케팅/할인/무료 포인트 공동 부담율 | G5: 포인트 정산대상금액
B6: 금액 | C6: 762859 | D6: 707000 | E6: 55859 | F6: 0.5 | G6: =E6*F6 -> 27929.5
B8: 업체 | C8: 수수료 (KT/KTH/TECH) | D8: 만화가족
B9: 정산매출 | C9: =C6*C10 -> 457715.4 | D9: =C6*D10 -> 305143.6
B10: 요율 | C10: 0.6 | D10: 0.4

Sheet 키다리스튜디오
B2: 사이트명 | C2: 작품명 | D2: 소비자매출액 | E2: 유통사수수료 | F2: 케이티매출액 | G2: 케이티수익 | H2: 만화가족 수익 | I2: 비고
B3: 봄툰 | C3: 봄툰 구작연재 | D3: =키다리스튜디오정산서!Z1+키다리스튜디오정산서!H22 -> 12389440 | E3: =D3-F3 -> 9703554 | F3: 2685886 | G3: =F3*20% -> 537177.2 | H3: =F3*80% -> 2148708.8 | I3: 12월 RS
B4: 합계 | D4: =SUM(D3:D3) -> 12389440 | E4: =SUM(E3:E3) -> 9703554 | F4: =SUM(F3:F3) -> 2685886 | G4: =SUM(G3:G3) -> 537177.2 | H4: =SUM(H3:H3) -> 2148708.8
G5: =F4*0.2 -> 537177.2 | H5: =F4*0.8 -> 2148708.8

Sheet 키다리스튜디오정산서
B1: 2021.12 | N1: -9469482 | O1: 0 | P1: 0 | S1: 6945660 | T1: 3436927.2 | W1: 5088600 | X1: 1959980.4 | Y1: 5396907.6 | Z1: 12034260 | AB1: 5396907.6 | AC1: 5396907.6 | AD1: 2508296 | AE1: -6580870.8 | AF1: 0
B2: No | C2: 구분 | D2: 만화idx | E2: 상태 | F2: 요일 | G2: 만화명 | H2: CP회사명 | I2: MCP | J2: 작가명 | K2: CP(정산처) | L2: 구분 | M2: 비고 | N2: 이월 차감잔액 | O2: 콘텐츠 MG | P2: 실지급 MG | Q2: 웹코인합계 | R2: 웹정산율 | S2: 웹매출액 | T2: 웹정산액 | U2: 앱코인합계 | V2: 앱정산율 | W2: 앱매출액 | X2: 앱정산액 | Y2: 정산액(웹+앱) | Z2: 총매출액 | AA2: 글/그림 | AB2: RS정산액 | AC2: RS-MG | AD2: RS지급액(MG-RS) | AE2: 차감잔액 | AF2: MG(당월 소멸)
B3: 2348 | C3: 연재 | D3: 6335 | E3: 업체MG | G3: 겨우내 | H3: 만화가족(웹툰) | J3: 사해&벌래 | K3: 만화가족 | L3: 1.과세 | N3: 0 | Q3: 138 | R3: 45.0% | S3: 24840 | T3: 11178 | U3: 15 | V3: 35.0% | W3: 2700 | X3: 945 | Y3: 12123 | Z3: 27540 | AB3: 12123 | AC3: 12123 | AD3: 12123 | AE3: 0 | AF3: 0
B4: 113 | C4: 연재 | D4: 20105 | E4: 선독점 | F4: 화 | G4: 공유하는 집 | H4: 만화가족(웹툰) | J4: 징망츄&사앙 | K4: 만화가족 | L4: 1.과세 | N4: -9469482 | Q4: 18736 | R4: 54.0% | S4: 3372480 | T4: 1821139.2 | U4: 14120 | V4: 42.0% | W4: 2541600 | X4: 1067472 | Y4: 2888611.2 | Z4: 5914080 | AB4: 2888611.2 | AC4: 2888611.2 | AD4: 0 | AE4: -6580870.8 | AF4: 0
B5: 8464 | C5: 연재 | D5: 6932 | E5: 요일연재 | G5: 날라리(완결) | H5: 만화가족(웹툰) | J5: 손 길 | K5: 만화가족 | L5: 1.과세 | N5: 0 | Q5: 12 | R5: 45.0% | S5: 2160 | T5: 972 | U5: 0 | V5: 35.0% | W5: 0 | X5: 0 | Y5: 972 | Z5: 2160 | AB5: 972 | AC5: 972 | AD5: 972 | AE5: 0 | AF5: 0
B6: 10741 | C6: 연재 | D6: 6555 | E6: 요일연재 | G6: 드리밍(완결) | H6: 만화가족(웹툰) | J6: 달짱 | K6: 만화가족 | L6: 1.과세 | Q6: 2 | R6: 45.0% | S6: 360 | T6: 162 | U6: 0 | V6: 35.0% | W6: 0 | X6: 0 | Y6: 162 | Z6: 360 | AB6: 162 | AC6: 162 | AD6: 162 | AE6: 0 | AF6: 0
B7: 12120 | C7: 연재 | D7: 6456 | E7: 요일연재 | G7: 먼지소녀 시즌1,2 | H7: 만화가족(웹툰) | J7: 독트윈 | K7: 만화가족 | L7: 1.과세 | N7: 0 | Q7: 0 | R7: 45.0% | S7: 0 | T7: 0 | U7: 0 | V7: 35.0% | W7: 0 | X7: 0 | Y7: 0 | Z7: 0 | AB7: 0 | AC7: 0 | AD7: 0 | AE7: 0 | AF7: 0
B8: 4976 | C8: 연재 | D8: 12145 | E8: 요일연재 | G8: 사랑이 커다래 | H8: 만화가족(웹툰) | J8: 깜귤 | K8: 만화가족 | L8: 1.과세 | N8: 0 | Q8: 31 | R8: 54.0% | S8: 5580 | T8: 3013.2 | U8: 0 | V8: 42.0% | W8: 0 | X8: 0 | Y8: 3013.2 | Z8: 5580 | AB8: 3013.2 | AC8: 3013.2 | AD8: 3013 | AE8: 0 | AF8: 0
B9: 11214 | C9: 연재 | D9: 8960 | E9: 업체MG | G9: 세렌디피티 | H9: 만화가족(웹툰) | J9: 잇뚜&주요 | K9: 만화가족 | L9: 1.과세 | Q9: 0 | R9: 45.0% | S9: 0 | T9: 0 | U9: 0 | V9: 35.0% | W9: 0 | X9: 0 | Y9: 0 | Z9: 0 | AB9: 0 | AC9: 0 | AD9: 0 | AE9: 0 | AF9: 0
B10: 6037 | C10: 연재 | D10: 5822 | E10: 요일연재 | G10: 소음(완결) | H10: 만화가족(웹툰) | J10: 어고 | K10: 만화가족 | L10: 1.과세 | N10: 0 | Q10: 12 | R10: 45.0% | S10: 2160 | T10: 972 | U10: 24 | V10: 35.0% | W10: 4320 | X10: 1512 | Y10: 2484 | Z10: 6480 | AB10: 2484 | AC10: 2484 | AD10: 2484 | AE10: 0 | AF10: 0
B11: 4630 | C11: 연재 | D11: 5455 | E11: 요일연재 | G11: 시어머니는 츤데레(완결) | H11: 만화가족(웹툰) | J11: 온조 | K11: 만화가족 | L11: 1.과세 | N11: 0 | Q11: 28 | R11: 45.0% | S11: 5040 | T11: 2268 | U11: 10 | V11: 35.0% | W11: 1800 | X11: 630 | Y11: 2898 | Z11: 6840 | AB11: 2898 | AC11: 2898 | AD11: 2898 | AE11: 0 | AF11: 0
B12: 331 | C12: 연재 | D12: 12853 | E12: 업체MG | G12: 아는 사람 이야기 | H12: 만화가족(웹툰) | J12: 온우주&서랭 | K12: 만화가족 | L12: 1.과세 | N12: 0 | Q12: 3969 | R12: 45.0% | S12: 714420 | T12: 321489 | U12: 3507 | V12: 35.0% | W12: 631260 | X12: 220941 | Y12: 542430 | Z12: 1345680 | AB12: 542430 | AC12: 542430 | AD12: 542430 | AE12: 0 | AF12: 0
B13: 6162 | C13: 연재 | D13: 6732 | E13: 요일연재 | G13: 아임펫! 시즌 1,2,3 | H13: 만화가족(웹툰) | J13: 탐이부 | K13: 만화가족 | L13: 1.과세 | N13: 0 | Q13: 39 | R13: 45.0% | S13: 7020 | T13: 3159 | U13: 0 | V13: 35.0% | W13: 0 | X13: 0 | Y13: 3159 | Z13: 7020 | AB13: 3159 | AC13: 3159 | AD13: 3159 | AE13: 0 | AF13: 0
B14: 148 | C14: 연재 | D14: 17898 | E14: 업체MG | F14: 수 | G14: 애증과 애정 사이 | H14: 만화가족(웹툰) | J14: 부찌 | K14: 만화가족 | L14: 1.과세 | N14: 0 | Q14: 13245 | R14: 45.0% | S14: 2384100 | T14: 1072845 | U14: 8289 | V14: 35.0% | W14: 1492020 | X14: 522207 | Y14: 1595052 | Z14: 3876120 | AB14: 1595052 | AC14: 1595052 | AD14: 1595052 | AE14: 0 | AF14: 0
B15: 476 | C15: 연재 | D15: 12179 | E15: 업체MG | G15: 에버그린 | H15: 만화가족(웹툰) | J15: 부찌 | K15: 만화가족 | L15: 1.과세 | N15: 0 | Q15: 1881 | R15: 45.0% | S15: 338580 | T15: 152361 | U15: 2211 | V15: 35.0% | W15: 397980 | X15: 139293 | Y15: 291654 | Z15: 736560 | AB15: 291654 | AC15: 291654 | AD15: 291654 | AE15: 0 | AF15: 0
B16: 7737 | C16: 연재 | D16: 5392 | E16: 요일연재 | G16: 여고를 아느냐(완결) | H16: 만화가족(웹툰) | J16: 젠틀독 | K16: 만화가족 | L16: 1.과세 | N16: 0 | Q16: 8 | R16: 45.0% | S16: 1440 | T16: 648 | U16: 10 | V16: 35.0% | W16: 1800 | X16: 630 | Y16: 1278 | Z16: 3240 | AB16: 1278 | AC16: 1278 | AD16: 1278 | AE16: 0 | AF16: 0
B17: 7958 | C17: 연재 | D17: 6457 | E17: 요일연재 | G17: 연애에 서툰 뱀파이어(완결) | H17: 만화가족(웹툰) | J17: 유승승 | K17: 만화가족 | L17: 1.과세 | N17: 0 | Q17: 16 | R17: 45.0% | S17: 2880 | T17: 1296 | U17: 0 | V17: 35.0% | W17: 0 | X17: 0 | Y17: 1296 | Z17: 2880 | AB17: 1296 | AC17: 1296 | AD17: 1296 | AE17: 0 | AF17: 0
B18: 1748 | C18: 연재 | D18: 21065 | E18: 요일연재 | F18: 화 | G18: 이상적인관계 | H18: 만화가족(웹툰) | J18: 얏꽁 | K18: 만화가족 | L18: 1.과세 | Q18: 454 | R18: 54.0% | S18: 81720 | T18: 44128.8 | U18: 84 | V18: 42.0% | W18: 15120 | X18: 6350.4 | Y18: 50479.2 | Z18: 96840 | AB18: 50479.2 | AC18: 50479.2 | AD18: 50479 | AE18: 0 | AF18: 0
B19: 6566 | C19: 연재 | D19: 5401 | E19: 요일연재 | G19: 죽은자를 상대하는 방법(완결) | H19: 만화가족(웹툰) | J19: 곽병진 | K19: 만화가족 | L19: 1.과세 | N19: 0 | Q19: 16 | R19: 45.0% | S19: 2880 | T19: 1296 | U19: 0 | V19: 35.0% | W19: 0 | X19: 0 | Y19: 1296 | Z19: 2880 | AB19: 1296 | AC19: 1296 | AD19: 1296 | AE19: 0 | AF19: 0
H22: 355180 | I22: 177590
B23: 서비스사 | C23: 세금계산년월 | D23: 만화IDX | E23: 컨텐츠 | F23: CP1(정산처) | G23: 구분 | H23: 순매출 | I23: 봄툰-CP정산액
B24: 카카오페이지 | C24: 2021-11 | D24: 8960 | E24: 세렌디피티 | F24: 만화가족 | G24: 1.과세 | H24: 3360 | I24: 1680
B25: 레진 | C25: 2021-11 | D25: 12179 | E25: 에버그린 | F25: 만화가족 | G25: 1.과세 | H25: 351820 | I25: 175910

Sheet 탑툰
B2: 사이트명 | C2: 작품명 | D2: 소비자매출액 | E2: 유통사수수료 | F2: 케이티매출액 | G2: 케이티수익 | H2: 만화가족 수익 | I2: 비고
B3: 탑툰 | C3: 해금 外 | D3: 3335368 | E3: 0 | F3: =D3 -> 3335368 | G3: =F3*20% -> 667073.6 | H3: =F3*80% -> 2668294.4 | I3: 12월 국내/해외 RS
B4: 합계 | D4: =SUM(D3:D3) -> 3335368 | E4: =SUM(E3:E3) -> 0 | F4: =SUM(F3:F3) -> 3335368 | G4: =SUM(G3:G3) -> 667073.6 | H4: =SUM(H3:H3) -> 2668294.4
G5: =F4*0.2 -> 667073.6 | H5: =F4*0.8 -> 2668294.4

Sheet 탑툰정산서
A1: # | B1: 구분 | C1: 작품명 | D1: 범위 | E1: 세금 | F1: WEB 정산 | G1: APP 정산 | H1: 해외세액 | I1: 12월 연재 | J1: 12월 휴재 | K1: 연재/MG정산액 | L1: RS 선지급차감액 | M1: RS 조정액 | N1: RS 정산액 | O1: 총 정산액 | P1: 기타
A2: 402 | B2: (대만) | C2: Love & Wish 러브 앤 위시 | D2: 전체회차 | E2: 적용 | F2: 63 | G2: 0 | H2: 12 | I2: (연재없음) | J2: (연재없음) | K2: 0 | L2: 0 | M2: 2592 | N2: 2643 | O2: 2643
A3: 530 | B3: (대만) | C3: 人妻的秘密 당신의 아내를 접수합니다 | D3: 전체회차 | E3: 적용 | F3: 0 | G3: 0 | I3: (연재없음) | J3: (연재없음) | K3: 0 | L3: 0 | M3: 0 | N3: 0 | O3: 0
A4: 570 | B4: (대만) | C4: LUNA 루나 | D4: 전체회차 | E4: 적용 | F4: 0 | G4: 0 | I4: (연재없음) | J4: (연재없음) | K4: 0 | L4: 0 | M4: 0 | N4: 0 | O4: 0
A5: 571 | B5: (대만) | C5: 戀愛ing 그래도 사랑해 | D5: 전체회차 | E5: 적용 | F5: 0 | G5: 0 | I5: (연재없음) | J5: (연재없음) | K5: 0 | L5: 0 | M5: 0 | N5: 0 | O5: 0
A6: 616 | B6: (대만) | C6: 解禁:初始的快感 해금 : 시작되는 쾌락 | D6: 전체회차 | E6: 적용 | F6: 87415 | G6: 0 | H6: 17483 | I6: (연재없음) | J6: (연재없음) | K6: 0 | L6: 0 | M6: 218855 | N6: 288787 | O6: 288787
A7: 807 | B7: (대만) | C7: Lust Awakening 해금 : 시작되는 쾌락 - 영어 | D7: 전체회차 | E7: 적용 | F7: 0 | G7: 0 | I7: (연재없음) | J7: (연재없음) | K7: 0 | L7: 0 | M7: 0 | N7: 0 | O7: 0
A8: 833 | B8: (대만) | C8: 窺視 엿보기 | D8: 전체회차 | E8: 적용 | F8: 6517 | G8: 0 | H8: 1303 | I8: (연재없음) | J8: (연재없음) | K8: 0 | L8: 0 | M8: 34399 | N8: 39613 | O8: 39613
A9: 870 | B9: (대만) | C9: 青春:逆齡小鮮肉 청춘 : 그 몸을 삼키다 | D9: 전체회차 | E9: 적용 | F9: 1086 | G9: 0 | H9: 217 | I9: (연재없음) | J9: (연재없음) | K9: 0 | L9: 0 | M9: 2966 | N9: 3835 | O9: 3835
A10: 1017 | B10: (대만) | C10: 前女友 전여친 | D10: 전체회차 | E10: 적용 | F10: 52142 | G10: 0 | H10: 10428 | I10: (연재없음) | J10: (연재없음) | K10: 0 | L10: 0 | M10: 154714 | N10: 196428 | O10: 196428
A11: 1157 | B11: (대만) | C11: 與前妻同居 전처와의 동거 | D11: 전체회차 | E11: 적용 | F11: 16614 | G11: 0 | H11: 3322 | I11: (연재없음) | J11: (연재없음) | K11: 0 | L11: 0 | M11: 76042 | N11: 89334 | O11: 89334
A12: 1844 | B12: (ASP) | C12: 나싸(완결) | D12: 전체회차 | E12: 적용 | F12: 0 | G12: 0 | I12: (연재없음) | J12: (연재없음) | K12: 0 | L12: 0 | M12: 0 | N12: 0 | O12: 0
A13: 1845 | B13: (ASP) | C13: 당신의 아내를 접수합니다(완결) | D13: 전체회차 | E13: 적용 | F13: 0 | G13: 0 | I13: (연재없음) | J13: (연재없음) | K13: 0 | L13: 0 | M13: 0 | N13: 0 | O13: 0
A14: 1899 | B14: (ASP) | C14: 아임 펫!(완결) | D14: 전체회차 | E14: 적용 | F14: 0 | G14: 0 | I14: (연재없음) | J14: (연재없음) | K14: 0 | L14: 0 | M14: 0 | N14: 0 | O14: 0
A15: 1903 | B15: (ASP) | C15: 그래도 사랑해(완결) | D15: 전체회차 | E15: 적용 | F15: 907 | G15: 0 | I15: (연재없음) | J15: (연재없음) | K15: 0 | L15: 0 | M15: 0 | N15: 907 | O15: 907
A16: 1909 | B16: (ASP) | C16: 해금 : 시작되는 쾌락(완결) | D16: 전체회차 | E16: 적용 | F16: 93279 | G16: 0 | I16: (연재없음) | J16: (연재없음) | K16: 0 | L16: 0 | M16: 0 | N16: 93279 | O16: 93279
A17: 1910 | B17: (ASP) | C17: 루나(완결) | D17: 전체회차 | E17: 적용 | F17: 0 | G17: 0 | I17: (연재없음) | J17: (연재없음) | K17: 0 | L17: 0 | M17: 0 | N17: 0 | O17: 0
A18: 1913 | B18: (ASP) | C18: 우당탕탕 따식이(완결) | D18: 전체회차 | E18: 적용 | F18: 0 | G18: 0 | I18: (연재없음) | J18: (연재없음) | K18: 0 | L18: 0 | M18: 0 | N18: 0 | O18: 0
A19: 2011 | B19: (ASP) | C19: 청춘 : 그 몸을 삼키다(완결) | D19: 전체회차 | E19: 적용 | F19: 1749 | G19: 0 | I19: (연재없음) | J19: (연재없음) | K19: 0 | L19: 0 | M19: 0 | N19: 1749 | O19: 1749
A20: 2013 | B20: (ASP) | C20: 엿보기(완결) | D20: 전체회차 | E20: 적용 | F20: 1944 | G20: 0 | I20: (연재없음) | J20: (연재없음) | K20: 0 | L20: 0 | M20: 0 | N20: 1944 | O20: 1944
A21: 2106 | B21: (ASP) | C21: 전 여친(완결) | D21: 전체회차 | E21: 적용 | F21: 6739 | G21: 0 | I21: (연재없음) | J21: (연재없음) | K21: 0 | L21: 0 | M21: 0 | N21: 6739 | O21: 6739
A22: 2165 | B22: (ASP) | C22: 전처와의 동거(완결) | D22: 전체회차 | E22: 적용 | F22: 52666 | G22: 0 | I22: (연재없음) | J22: (연재없음) | K22: 0 | L22: 0 | M22: 0 | N22: 52666 | O22: 52666
A23: 8013 | B23: (한국) | C23: 나싸 | D23: 전체회차 | E23: 적용 | F23: 0 | G23: 0 | I23: (연재없음) | J23: (연재없음) | K23: 0 | L23: 0 | M23: 0 | N23: 0 | O23: 0
... A40: 10401 | B40: (한국) | C40: 전처와의 동거 | D40: 전체회차 | E40: 적용 | F40: 855214 | G40: 109771 | I40: (연재없음) | J40: (연재없음) | K40: 0 | L40: 0 | M40: 0 | N40: 964985 | O40: 964985
A41: 100104 | B41: (글로벌) | C41: LUNA 루나 | D41: 전체회차 | E41: 적용 | F41: 16655 | G41: 0 | H41: 3331 | I41: (연재없음) | J41: (연재없음) | K41: 0 | L41: 0 | M41: 0 | N41: 13324 | O41: 13324
A42: 100106 | B42: (글로벌) | C42: Nevertheless, I love you. 그래도 사랑해 | D42: 전체회차 | E42: 적용 | F42: 0 | G42: 0 | I42: (연재없음) | J42: (연재없음) | K42: 0 | L42: 0 | M42: 0 | N42: 0 | O42: 0
A43: 100136 | B43: (글로벌) | C43: Lust Awakening 해금:시작되는 쾌락 | D43: 전체회차 | E43: 적용 | F43: 758078 | G43: 0 | H43: 151615 | I43: (연재없음) | J43: (연재없음) | K43: 0 | L43: 0 | M43: 0 | N43: 606463 | O43: 606463
A44: 100217 | B44: (글로벌) | C44: How to Deal With the Dead 죽은자를 상대하는 방법 | D44: 전체회차 | E44: 적용 | F44: 0 | G44: 0 | I44: (연재없음) | J44: (연재없음) | K44: 0 | L44: 0 | M44: 0 | N44: 0 | O44: 0
A45: 100254 | B45: (글로벌) | C45: LOVE & WISH 러브 앤 위시 | D45: 전체회차 | E45: 적용 | F45: 0 | G45: 0 | I45: (연재없음) | J45: (연재없음) | K45: 0 | L45: 0 | M45: 0 | N45: 0 | O45: 0
A46: 100290 | B46: (글로벌) | C46: Ah! I'm your pet! 아임펫 | D46: 전체회차 | E46: 적용 | F46: 0 | G46: 0 | I46: (연재없음) | J46: (연재없음) | K46: 0 | L46: 0 | M46: 1193 | N46: 1193 | O46: 1193
A47: 100307 | B47: (글로벌) | C47: Path of Justice 우당탕탕 따식이 | D47: 전체회차 | E47: 적용 | F47: 351 | G47: 0 | H47: 70 | I47: (연재없음) | J47: (연재없음) | K47: 0 | L47: 0 | M47: 0 | N47: 281 | O47: 281
A48: 100308 | B48: (글로벌) | C48: The Perfect Roommate 위험한 동거 | D48: 전체회차 | E48: 적용 | F48: 821 | G48: 0 | H48: 164 | I48: (연재없음) | J48: (연재없음) | K48: 0 | L48: 0 | M48: 0 | N48: 657 | O48: 657
A49: 100553 | B49: (글로벌) | C49: Living With My Ex-Wife 전처와의 동거 | D49: 전체회차 | E49: 적용 | F49: 73145 | G49: 0 | H49: 14629 | I49: (연재없음) | J49: (연재없음) | K49: 0 | L49: 0 | M49: 0 | N49: 58516 | O49: 58516
A50: 100594 | B50: (글로벌) | C50: Ex-girlfriend 전여친 | D50: 전체회차 | E50: 적용 | F50: 38590 | G50: 0 | H50: 7718 | I50: (연재없음) | J50: (연재없음) | K50: 0 | L50: 0 | M50: 0 | N50: 30872 | O50: 30872
A51: 0 | B51: (한국) | C51: 봄툰 | D51: 일부회차 | E51: 적용 | F51: 0 | G51: 0 | I51: (연재없음) | J51: (연재없음) | K51: 0 | L51: 0 | M51: 0 | N51: 0 | O51: 0
A52: 0 | B52: (한국) | C52: 원스토어 | D52: 일부회차 | E52: 적용 | F52: 20237 | G52: 0 | I52: (연재없음) | J52: (연재없음) | K52: 0 | L52: 0 | M52: 0 | N52: 20237 | O52: 20237
A53: 0 | B53: (한국) | C53: 일본유통 | D53: 일부회차 | E53: 적용 | F53: 0 | G53: 0 | I53: (연재없음) | J53: (연재없음) | K53: 0 | L53: 0 | M53: 0 | N53: 0 | O53: 0
A54: 0 | B54: (한국) | C54: 해외유통 | D54: 일부회차 | E54: 적용 | F54: 139 | G54: 0 | I54: (연재없음) | J54: (연재없음) | K54: 0 | L54: 0 | M54: 0 | N54: 139 | O54: 139
N57: =SUM(N2:N54) -> 3335368
