Workbook
Name raw_a: 전체리스트!$A$2:$F$2571
Name raw_d: 전체리스트!$C$2:$F$2571

Sheet 전체리스트
A1: 사이트명 | B1: 월별 | C1: 작품명 | D1: 총매출 | E1: 순매출 | F1: 환율
A2: 카카오페이지 | B2: 1월분 | C2: 거짓말, 뱀파이어가 어디 있어? [BL] | D2: 1178900 | E2: 810040
A3: 카카오페이지 | B3: 1월분 | C3: 꿈꾸는 먹잇감 | D3: 2183065 | E3: 1516809
A4: 카카오페이지 | B4: 1월분 | C4: 꿰인 사이 | D4: 498435 | E4: 346386
A5: 카카오페이지 | B5: 1월분 | C5: 너에게만 음성인식 | D5: 723460 | E5: 502846
A6: 카카오페이지 | B6: 1월분 | C6: 대표님, 사모님이 도망가요 | D6: 1503980 | E6: 1046968
A7: 카카오페이지 | B7: 1월분 | C7: 레벨업에 미친 의사 | D7: 35898931 | E7: 24832005
A8: 카카오페이지 | B8: 1월분 | C8: 마녀 따위 안 할래요 | D8: 771820 | E8: 533712
A9: 카카오페이지 | B9: 1월분 | C9: 만지고 싶어! | D9: 826960 | E9: 576256
A10: 카카오페이지 | B10: 1월분 | C10: 말도 안되는 관계 (개정판) [BL] | D10: 391890 | E10: 270594
A11: 카카오페이지 | B11: 1월분 | C11: 명판관 장평 | D11: 11000 | E11: 7700
A12: 카카오페이지 | B12: 1월분 | C12: 사랑과 우정 사이에서 (개정판) [BL] | D12: 219840 | E12: 153294
A13: 카카오페이지 | B13: 1월분 | C13: 사랑의 형태 : 마음이 향하는 곳 | D13: 156100 | E13: 107770
... A90: 북큐브 | B90: 1월분 | C90: 호랑이 장가드는 날 | D90: 209700 | E90: 146790
A93: 봄툰_유통1 | B93: 11월분 | C93: 아랫집 웬수 | D93: 625100 | E93: 312550 | G93: * 같은이름 같은 유통사 주의
A94: 봄툰_유통2 | B94: 11월분 | C94: 아랫집 웬수 | D94: 3150 | E94: 1575 | G94: - 유통사 이름 변경 (예. 봄툰_유통1.2.3)
A95: 봄툰_유통3 | B95: 11월분 | C95: 아랫집 웬수 | D95: 8400 | E95: 4200
A96: 봄툰_유통4 | B96: 11월분 | C96: 아랫집 웬수 | D96: 2940 | E96: 1470
A97: 봄툰_유통5 | B97: 11월분 | C97: 페티쉬 BL 단편선 | D97: 11760 | E97: 5880
A98: 봄툰 | B98: 12월분 | C98: 명판관 장평 | D98: 900 | E98: 486
A99: 봄툰 | B99: 12월분 | C99: 사랑할 수 없는 그녀 | D99: 61020 | E99: 30510
A100: 봄툰 | B100: 12월분 | C100: 슬기로운 생활(완결) | D100: 7560 | E100: 3384
A101: 봄툰 | B101: 12월분 | C101: 아랫집 웬수 | D101: 458460 | E101: 175203
A102: 봄툰 | B102: 12월분 | C102: 악마와 나 사이에는 | D102: 25200 | E102: 11664
A103: 봄툰 | B103: 12월분 | C103: 옆집 최애 | D103: 262440 | E103: 124870
A104: 봄툰 | B104: 12월분 | C104: 주작의 귀환 | D104: 2880 | E104: 1555
A105: 봄툰 | B105: 12월분 | C105: 탑배우의 이중생활 | D105: 83160 | E105: 41472
A106: 봄툰 | B106: 12월분 | C106: 파쿠리인 내가 어시를?! | D106: 59220 | E106: 29128
... A131: 봄툰 | B131: 12월분 | C131: 어이상실의 시대 | D131: 7200 | E131: 4680
A135: C&C_콰이칸 | B135: 7월분 | C135: 옆집 최애+아랫집 웬수 | F135: 콰이칸 이관
A137: 애니툰 | B137: 12월분 | C137: 꿈꾸는 먹잇감 | D137: 3510 | E137: 2457
A138: 애니툰 | B138: 12월분 | C138: 꿰인 사이 | D138: 35370 | E138: 46897
A139: 애니툰 | B139: 12월분 | C139: 너에게만 음성인식 | D139: 68175 | E139: 53455.5
A140: 애니툰 | B140: 12월분 | C140: 대표님, 사모님이 도망가요 | D140: 709290 | E140: 641327
A141: 애니툰 | B141: 12월분 | C141: 대표님의 삐뚤어진 사랑 | D141: 2176740 | E141: 1789994
A142: 애니툰 | B142: 12월분 | C142: 마녀 따위 안할래요 | D142: 30780 | E142: 21546
A143: 애니툰 | B143: 12월분 | C143: 만지고 싶어! | D143: 113602.5 | E143: 91428.75
A144: 애니툰 | B144: 12월분 | C144: 말도 안되는 관계 [성인판] | D144: 140400 | E144: 98280
A145: 애니툰 | B145: 12월분 | C145: 말도 안되는 관계 [일반판] | D145: 3240 | E145: 2268
A146: 애니툰 | B146: 12월분 | C146: 멍멍이와 주인님 | D146: 135 | E146: 94.5
...

Sheet 합계
C2: ■ 스토리숲 22년 1월 (주)스토리위즈 정산서
C3: **판매월 1월1일~1월31일 기준
C5: RS 정산 기준, MG 미포함 | L5: 0.12
C6: 사이트명 | D6: 소비자매출액 | E6: 유통사수수료 | F6: 스토리위즈매출액 | G6: 스토리위즈수익 | H6: 스토리숲 수익 | I6: 비고 | K6: 선지급금 | L6: 500000000
B7: =COUNTA(INDIRECT(C7&"!B:B")) -> 40 | C7: 카카오페이지 | D7: =INDIRECT(C7 & "!E" & B7+3) -> 86715946 | E7: =INDIRECT(C7 & "!F" & B7+3) -> 27781486 | F7: =INDIRECT(C7 & "!G" & B7+3) -> 58934460 | G7: =INDIRECT(C7 & "!H" & B7+3) -> 2946723 | H7: =INDIRECT(C7 & "!I" & B7+3) -> 55987737 | K7: KT프로젝트수익 | L7: 60000000 | N7: =L7/L6 -> 0.12
B8: =COUNTA(INDIRECT(C8&"!B:B")) -> 5 | C8: 카카오타파스 | D8: =INDIRECT(C8 & "!E" & B8+3) -> 9101214 | E8: =INDIRECT(C8 & "!F" & B8+3) -> 0 | F8: =INDIRECT(C8 & "!G" & B8+3) -> 9101214 | G8: =INDIRECT(C8 & "!H" & B8+3) -> 455060.7 | H8: =INDIRECT(C8 & "!I" & B8+3) -> 8646153.3
B9: =COUNTA(INDIRECT(C9&"!B:B")) -> 52 | C9: 네이버웹툰 | D9: =INDIRECT(C9 & "!E" & B9+3) -> 78520951 | E9: =INDIRECT(C9 & "!F" & B9+3) -> 9010568.2 | F9: =INDIRECT(C9 & "!G" & B9+3) -> 69510383 | G9: =INDIRECT(C9 & "!H" & B9+3) -> 3475519.2 | H9: =INDIRECT(C9 & "!I" & B9+3) -> 66034864
B10: =COUNTA(INDIRECT(C10&"!B:B")) -> 9 | C10: 콰이칸_중국 | D10: =F10 -> 3193865.7 | E10: =INDIRECT(C10 & "!F" & B10+3) -> 0 | F10: =INDIRECT(C10 & "!G" & B10+3) -> 3193865.7 | G10: =INDIRECT(C10 & "!H" & B10+3) -> 159693.29 | H10: =INDIRECT(C10 & "!I" & B10+3) -> 3034172.4 | I10: V | K10: 월별 회수금 (케이티 수익)
B11: =COUNTA(INDIRECT(C11&"!B:B")) -> 9 | C11: kt_alpha | D11: =INDIRECT(C11 & "!E" & B11+3) -> 667367.3 | E11: =INDIRECT(C11 & "!F" & B11+3) -> 283147.27 | F11: =INDIRECT(C11 & "!G" & B11+3) -> 384220.03 | G11: =INDIRECT(C11 & "!H" & B11+3) -> 19211.002 | H11: =INDIRECT(C11 & "!I" & B11+3) -> 365009.03 | K11: 2021.05 | L11: 38491275 | N11: 8/10송금
B12: =COUNTA(INDIRECT(C12&"!B:B")) -> 30 | C12: 레진코믹스 | D12: =INDIRECT(C12 & "!E" & B12+3) -> 8526312 | E12: =INDIRECT(C12 & "!F" & B12+3) -> 0 | F12: =INDIRECT(C12 & "!G" & B12+3) -> 8526312 | G12: =INDIRECT(C12 & "!H" & B12+3) -> 426315.6 | H12: =INDIRECT(C12 & "!I" & B12+3) -> 8099996.4 | K12: 2021.06 | L12: 40614671 | N12: 9/10송금
B13: =COUNTA(INDIRECT(C13&"!B:B")) -> 14 | C13: 북큐브 | D13: =INDIRECT(C13 & "!E" & B13+3) -> 899900 | E13: =INDIRECT(C13 & "!F" & B13+3) -> 269970 | F13: =INDIRECT(C13 & "!G" & B13+3) -> 629930 | G13: =INDIRECT(C13 & "!H" & B13+3) -> 31496.5 | H13: =INDIRECT(C13 & "!I" & B13+3) -> 598433.5 | K13: 2021.07 | L13: 38906565 | N13: 10/8송금
B14: =COUNTA(INDIRECT(C14&"!B:B")) -> 10 | C14: 탑툰 | D14: =INDIRECT(C14 & "!E" & B14+3) -> 1734282 | E14: =INDIRECT(C14 & "!F" & B14+3) -> 0 | F14: =INDIRECT(C14 & "!G" & B14+3) -> 1734282 | G14: =INDIRECT(C14 & "!H" & B14+3) -> 86714.1 | H14: =INDIRECT(C14 & "!I" & B14+3) -> 1647567.9 | K14: 2021.08 | L14: 40116328 | N14: 11/10송금
B15: =COUNTA(INDIRECT(C15&"!B:B")) -> 42 | C15: 봄툰 | D15: =INDIRECT(C15 & "!E" & B15+3) -> 7149530 | E15: =INDIRECT(C15 & "!F" & B15+3) -> 3131403 | F15: =INDIRECT(C15 & "!G" & B15+3) -> 4018127 | G15: =INDIRECT(C15 & "!H" & B15+3) -> 200906.35 | H15: =INDIRECT(C15 & "!I" & B15+3) -> 3817220.6 | K15: 2021.09 | L15: 34882157 | N15: 12/10송금
B16: =COUNTA(INDIRECT(C16&"!B:B")) -> 39 | C16: 애니툰 | D16: =INDIRECT(C16 & "!E" & B16+3) -> 6190222.5 | E16: =INDIRECT(C16 & "!F" & B16+3) -> 1078566.8 | F16: =INDIRECT(C16 & "!G" & B16+3) -> 5111655.8 | G16: =INDIRECT(C16 & "!H" & B16+3) -> 255582.79 | H16: =INDIRECT(C16 & "!I" & B16+3) -> 4856073 | K16: 2021.1 | L16: 33253241 | N16: 1/10송금
B17: =COUNTA(INDIRECT(C17&"!B:B")) -> 33 | C17: 코미코_한국 | D17: =INDIRECT(C17 & "!E" & B17+3) -> 18820970 | E17: =INDIRECT(C17 & "!F" & B17+3) -> 8344072 | F17: =INDIRECT(C17 & "!G" & B17+3) -> 10476898 | G17: =INDIRECT(C17 & "!H" & B17+3) -> 523844.9 | H17: =INDIRECT(C17 & "!I" & B17+3) -> 9953053.1 | K17: 2021.11 | L17: 30199565 | N17: 2/10송금
B18: =COUNTA(INDIRECT(C18&"!B:B")) -> 9 | C18: 포켓코믹스 | D18: =INDIRECT(C18 & "!E" & B18+3) -> 3395376 | E18: =INDIRECT(C18 & "!F" & B18+3) -> 0 | F18: =INDIRECT(C18 & "!G" & B18+3) -> 3395376 | G18: =INDIRECT(C18 & "!H" & B18+3) -> 169768.8 | H18: =INDIRECT(C18 & "!I" & B18+3) -> 3225607.2 | K18: 2021.12 | L18: 31091642
B19: =COUNTA(INDIRECT(C19&"!B:B")) -> 40 | C19: 리디북스 | D19: =INDIRECT(C19 & "!E" & B19+3) -> 11631900 | E19: =INDIRECT(C19 & "!F" & B19+3) -> 3549561.1 | F19: =INDIRECT(C19 & "!G" & B19+3) -> 8082338.9 | G19: =INDIRECT(C19 & "!H" & B19+3) -> 404116.95 | H19: =INDIRECT(C19 & "!I" & B19+3) -> 7678222 | K19: 2021년 합계 | L19: =SUM(L11:L18) -> 2.8755544e+08
B20: =COUNTA(INDIRECT(C20&"!B:B")) -> 19 | C20: 조아라 | D20: =INDIRECT(C20 & "!E" & B20+3) -> 649800 | E20: =INDIRECT(C20 & "!F" & B20+3) -> 220932 | F20: =INDIRECT(C20 & "!G" & B20+3) -> 428868 | G20: =INDIRECT(C20 & "!H" & B20+3) -> 21443.4 | H20: =INDIRECT(C20 & "!I" & B20+3) -> 407424.6 | K20: 2022.01 | L20: 13657156
B21: =COUNTA(INDIRECT(C21&"!B:B")) -> 12 | C21: 위코믹스_태국 | D21: =F21 -> 0 | E21: =INDIRECT(C21 & "!F" & B21+3) -> 0 | F21: =INDIRECT(C21 & "!G" & B21+3) -> 0 | G21: =INDIRECT(C21 & "!H" & B21+3) -> 0 | H21: =INDIRECT(C21 & "!I" & B21+3) -> 0 | I21: 300미만 V
B22: =COUNTA(INDIRECT(C22&"!B:B")) -> 19 | C22: 태피툰_영어 | D22: =INDIRECT(C22 & "!E" & B22+3) -> 27483480 | E22: =INDIRECT(C22 & "!F" & B22+3) -> 0 | F22: =INDIRECT(C22 & "!G" & B22+3) -> 27483480 | G22: =INDIRECT(C22 & "!H" & B22+3) -> 1374174 | H22: =INDIRECT(C22 & "!I" & B22+3) -> 26109306
B23: =COUNTA(INDIRECT(C23&"!B:B")) -> 20 | C23: 델리툰 | D23: =INDIRECT(C23 & "!E" & B23+3) -> 5334968 | E23: =INDIRECT(C23 & "!F" & B23+3) -> 0 | F23: =INDIRECT(C23 & "!G" & B23+3) -> 5334968 | G23: =INDIRECT(C23 & "!H" & B23+3) -> 266748.4 | H23: =INDIRECT(C23 & "!I" & B23+3) -> 5068219.6
B24: =COUNTA(INDIRECT(C24&"!B:B")) -> 16 | C24: 픽코마_일본 | D24: =INDIRECT(C24 & "!E" & B24+3) -> 8351803 | E24: =INDIRECT(C24 & "!F" & B24+3) -> 0 | F24: =INDIRECT(C24 & "!G" & B24+3) -> 8351803 | G24: =INDIRECT(C24 & "!H" & B24+3) -> 417590.15 | H24: =INDIRECT(C24 & "!I" & B24+3) -> 7934212.9
B25: =COUNTA(INDIRECT(C25&"!B:B")) -> 12 | C25: 픽코마_동영상 | D25: =INDIRECT(C25 & "!E" & B25+3) -> 285338 | E25: =INDIRECT(C25 & "!F" & B25+3) -> 0 | F25: =INDIRECT(C25 & "!G" & B25+3) -> 285338 | G25: =INDIRECT(C25 & "!H" & B25+3) -> 14266.9 | H25: =INDIRECT(C25 & "!I" & B25+3) -> 271071.1
B26: =COUNTA(INDIRECT(C26&"!B:B")) -> 6 | C26: 네오바자르_인도네시아 | D26: =INDIRECT(C26 & "!E" & B26+3) -> 105640.9 | E26: =INDIRECT(C26 & "!F" & B26+3) -> 0 | F26: =INDIRECT(C26 & "!G" & B26+3) -> 105640.9 | G26: =INDIRECT(C26 & "!H" & B26+3) -> 5282.045 | H26: =INDIRECT(C26 & "!I" & B26+3) -> 100358.85
B27: =COUNTA(INDIRECT(C27&"!B:B")) -> 12 | C27: 코미코_태국 | D27: =F27 -> 1383128.5 | E27: =INDIRECT(C27 & "!F" & B27+3) -> 0 | F27: =INDIRECT(C27 & "!G" & B27+3) -> 1383128.5 | G27: =INDIRECT(C27 & "!H" & B27+3) -> 69156.425 | H27: =INDIRECT(C27 & "!I" & B27+3) -> 1313972.1 | I27: V
B28: =COUNTA(INDIRECT(C28&"!B:B")) -> 6 | C28: 코미코_일본_대만 | D28: =F28 -> 72979.92 | E28: =INDIRECT(C28 & "!F" & B28+3) -> 0 | F28: =INDIRECT(C28 & "!G" & B28+3) -> 72979.92 | G28: =INDIRECT(C28 & "!H" & B28+3) -> 3648.996 | H28: =INDIRECT(C28 & "!I" & B28+3) -> 69330.924 | I28: v
B29: =COUNTA(INDIRECT(C29&"!B:B")) -> 39 | C29: 미스터블루 | D29: =INDIRECT(C29 & "!E" & B29+3) -> 26505138 | E29: =INDIRECT(C29 & "!F" & B29+3) -> 10602055 | F29: =INDIRECT(C29 & "!G" & B29+3) -> 15903083 | G29: =INDIRECT(C29 & "!H" & B29+3) -> 795154.14 | H29: =INDIRECT(C29 & "!I" & B29+3) -> 15107929
B30: =COUNTA(INDIRECT(C30&"!B:B")) -> 28 | C30: 피너툰 | D30: =INDIRECT(C30 & "!E" & B30+3) -> 18259360 | E30: =INDIRECT(C30 & "!F" & B30+3) -> 7303744 | F30: =INDIRECT(C30 & "!G" & B30+3) -> 10955616 | G30: =INDIRECT(C30 & "!H" & B30+3) -> 547780.8 | H30: =INDIRECT(C30 & "!I" & B30+3) -> 10407835
B31: =COUNTA(INDIRECT(C31&"!B:B")) -> 30 | C31: 원스토어 | D31: =INDIRECT(C31 & "!E" & B31+3) -> 4620560 | E31: =INDIRECT(C31 & "!F" & B31+3) -> 1386167.9 | F31: =INDIRECT(C31 & "!G" & B31+3) -> 3234392.1 | G31: =INDIRECT(C31 & "!H" & B31+3) -> 161719.61 | H31: =INDIRECT(C31 & "!I" & B31+3) -> 3072672.5
B32: =COUNTA(INDIRECT(C32&"!B:B")) -> 36 | C32: 투믹스 | D32: =INDIRECT(C32 & "!E" & B32+3) -> 1679510 | E32: =INDIRECT(C32 & "!F" & B32+3) -> 0 | F32: =INDIRECT(C32 & "!G" & B32+3) -> 1679510 | G32: =INDIRECT(C32 & "!H" & B32+3) -> 83975.5 | H32: =INDIRECT(C32 & "!I" & B32+3) -> 1595534.5
B33: =COUNTA(INDIRECT(C33&"!B:B")) -> 10 | C33: 빌리빌리 | D33: =F33 -> 1355558 | E33: =INDIRECT(C33 & "!F" & B33+3) -> 0 | F33: =INDIRECT(C33 & "!G" & B33+3) -> 1355558 | G33: =INDIRECT(C33 & "!H" & B33+3) -> 67777.902 | H33: =INDIRECT(C33 & "!I" & B33+3) -> 1287780.1 | I33: V
B34: =COUNTA(INDIRECT(C34&"!B:B")) -> 12 | C34: INKR | D34: =F34 -> 0 | E34: =INDIRECT(C34 & "!F" & B34+3) -> 0 | F34: =INDIRECT(C34 & "!G" & B34+3) -> 0 | G34: =INDIRECT(C34 & "!H" & B34+3) -> 0 | H34: =INDIRECT(C34 & "!I" & B34+3) -> 0 | I34: 100미만X V
B35: =COUNTA(INDIRECT(C35&"!B:B")) -> 6 | C35: 타파스 | D35: =F35 -> 1273714.8 | E35: =INDIRECT(C35 & "!F" & B35+3) -> 0 | F35: =INDIRECT(C35 & "!G" & B35+3) -> 1273714.8 | G35: =INDIRECT(C35 & "!H" & B35+3) -> 63685.738 | H35: =INDIRECT(C35 & "!I" & B35+3) -> 1210029 | I35: v 분기정산
B36: =COUNTA(INDIRECT(C36&"!B:B")) -> 21 | C36: 코믹툰 | D36: =INDIRECT(C36 & "!E" & B36+3) -> 4609874 | E36: =INDIRECT(C36 & "!F" & B36+3) -> 0 | F36: =INDIRECT(C36 & "!G" & B36+3) -> 4609874 | G36: =INDIRECT(C36 & "!H" & B36+3) -> 230493.7 | H36: =INDIRECT(C36 & "!I" & B36+3) -> 4379380.3
B37: =COUNTA(INDIRECT(C37&"!B:B")) -> 18 | C37: 코핀코믹스 | D37: =INDIRECT(C37 & "!E" & B37+3) -> 1661941.1 | E37: =INDIRECT(C37 & "!F" & B37+3) -> 0 | F37: =INDIRECT(C37 & "!G" & B37+3) -> 1661941.1 | G37: =INDIRECT(C37 & "!H" & B37+3) -> 83097.055 | H37: =INDIRECT(C37 & "!I" & B37+3) -> 1578844
B38: =COUNTA(INDIRECT(C38&"!B:B")) -> 20 | C38: 예스24 | D38: =INDIRECT(C38 & "!E" & B38+3) -> 290400 | E38: =INDIRECT(C38 & "!F" & B38+3) -> 87120 | F38: =INDIRECT(C38 & "!G" & B38+3) -> 203280 | G38: =INDIRECT(C38 & "!H" & B38+3) -> 10164 | H38: =INDIRECT(C38 & "!I" & B38+3) -> 193116
B39: =COUNTA(INDIRECT(C39&"!B:B")) -> 32 | C39: 핑거스토리_큐툰 | D39: =INDIRECT(C39 & "!E" & B39+3) -> 1867410 | E39: =INDIRECT(C39 & "!F" & B39+3) -> 746964 | F39: =INDIRECT(C39 & "!G" & B39+3) -> 1120446 | G39: =INDIRECT(C39 & "!H" & B39+3) -> 56022.3 | H39: =INDIRECT(C39 & "!I" & B39+3) -> 1064423.7
B40: =COUNTA(INDIRECT(C40&"!B:B")) -> 26 | C40: 핑거스토리_무툰 | D40: =INDIRECT(C40 & "!E" & B40+3) -> 876060 | E40: =INDIRECT(C40 & "!F" & B40+3) -> 350424 | F40: =INDIRECT(C40 & "!G" & B40+3) -> 525636 | G40: =INDIRECT(C40 & "!H" & B40+3) -> 26281.8 | H40: =INDIRECT(C40 & "!I" & B40+3) -> 499354.2
B41: =COUNTA(INDIRECT(C41&"!B:B")) -> 21 | C41: 북팔 | D41: =INDIRECT(C41 & "!E" & B41+3) -> 1019600 | E41: =INDIRECT(C41 & "!F" & B41+3) -> 305880 | F41: =INDIRECT(C41 & "!G" & B41+3) -> 713720 | G41: =INDIRECT(C41 & "!H" & B41+3) -> 35686 | H41: =INDIRECT(C41 & "!I" & B41+3) -> 678034
B42: =COUNTA(INDIRECT(C42&"!B:B")) -> 11 | C42: 엠유네트웍스 | D42: =INDIRECT(C42 & "!E" & B42+3) -> 3019700 | E42: =INDIRECT(C42 & "!F" & B42+3) -> 1117289 | F42: =INDIRECT(C42 & "!G" & B42+3) -> 1902411 | G42: =INDIRECT(C42 & "!H" & B42+3) -> 95120.55 | H42: =INDIRECT(C42 & "!I" & B42+3) -> 1807290.5
...

Sheet 카카오페이지
B4: [RS 정산 기준]
B5: 사이트명 | C5: 매출월 | D5: 작품명 | E5: 소비자매출액 | F5: 유통사수수료 | G5: 스토리위즈매출액 | H5: 스토리위즈수익 | I5: 스토리숲 수익 | J5: 비고
B6: 카카오페이지 | C6: =VLOOKUP(B6,raw_a,2,0) -> 1월분 | D6: 거짓말, 뱀파이어가 어디 있어? [BL] | E6: =SUMIFS(전체리스트!D:D,전체리스트!A:A,B6,전체리스트!C:C,D6) -> 1178900 | F6: =E6-G6 -> 368860 | G6: =SUMIFS(전체리스트!E:E,전체리스트!A:A,B6,전체리스트!C:C,D6) -> 810040 | H6: =G6*0.05 -> 40502 | I6: =G6-H6 -> 769538
B7: 카카오페이지 | C7: =VLOOKUP(B7,raw_a,2,0) -> 1월분 | D7: 꿈꾸는 먹잇감 | E7: =SUMIFS(전체리스트!D:D,전체리스트!A:A,B7,전체리스트!C:C,D7) -> 2183065 | F7: =E7-G7 -> 666256 | G7: =SUMIFS(전체리스트!E:E,전체리스트!A:A,B7,전체리스트!C:C,D7) -> 1516809 | H7: =G7*0.05 -> 75840.45 | I7: =G7-H7 -> 1440968.6
B8: 카카오페이지 | C8: =VLOOKUP(B8,raw_a,2,0) -> 1월분 | D8: 꿰인 사이 | E8: =SUMIFS(전체리스트!D:D,전체리스트!A:A,B8,전체리스트!C:C,D8) -> 498435 | F8: =E8-G8 -> 152049 | G8: =SUMIFS(전체리스트!E:E,전체리스트!A:A,B8,전체리스트!C:C,D8) -> 346386 | H8: =G8*0.05 -> 17319.3 | I8: =G8-H8 -> 329066.7
B9: 카카오페이지 | C9: =VLOOKUP(B9,raw_a,2,0) -> 1월분 | D9: 너에게만 음성인식 | E9: =SUMIFS(전체리스트!D:D,전체리스트!A:A,B9,전체리스트!C:C,D9) -> 723460 | F9: =E9-G9 -> 220614 | G9: =SUMIFS(전체리스트!E:E,전체리스트!A:A,B9,전체리스트!C:C,D9) -> 502846 | H9: =G9*0.05 -> 25142.3 | I9: =G9-H9 -> 477703.7
B10: 카카오페이지 | C10: =VLOOKUP(B10,raw_a,2,0) -> 1월분 | D10: 대표님, 사모님이 도망가요 | E10: =SUMIFS(전체리스트!D:D,전체리스트!A:A,B10,전체리스트!C:C,D10) -> 1503980 | F10: =E10-G10 -> 457012 | G10: =SUMIFS(전체리스트!E:E,전체리스트!A:A,B10,전체리스트!C:C,D10) -> 1046968 | H10: =G10*0.05 -> 52348.4 | I10: =G10-H10 -> 994619.6
B11: 카카오페이지 | C11: =VLOOKUP(B11,raw_a,2,0) -> 1월분 | D11: 레벨업에 미친 의사 | E11: =SUMIFS(전체리스트!D:D,전체리스트!A:A,B11,전체리스트!C:C,D11) -> 35898931 | F11: =E11-G11 -> 11066926 | G11: =SUMIFS(전체리스트!E:E,전체리스트!A:A,B11,전체리스트!C:C,D11) -> 24832005 | H11: =G11*0.05 -> 1241600.2 | I11: =G11-H11 -> 23590405
B12: 카카오페이지 | C12: =VLOOKUP(B12,raw_a,2,0) -> 1월분 | D12: 마녀 따위 안 할래요 | E12: =SUMIFS(전체리스트!D:D,전체리스트!A:A,B12,전체리스트!C:C,D12) -> 771820 | F12: =E12-G12 -> 238108 | G12: =SUMIFS(전체리스트!E:E,전체리스트!A:A,B12,전체리스트!C:C,D12) -> 533712 | H12: =G12*0.05 -> 26685.6 | I12: =G12-H12 -> 507026.4
B13: 카카오페이지 | C13: =VLOOKUP(B13,raw_a,2,0) -> 1월분 | D13: 만지고 싶어! | E13: =SUMIFS(전체리스트!D:D,전체리스트!A:A,B13,전체리스트!C:C,D13) -> 826960 | F13: =E13-G13 -> 250704 | G13: =SUMIFS(전체리스트!E:E,전체리스트!A:A,B13,전체리스트!C:C,D13) -> 576256 | H13: =G13*0.05 -> 28812.8 | I13: =G13-H13 -> 547443.2
B14: 카카오페이지 | C14: =VLOOKUP(B14,raw_a,2,0) -> 1월분 | D14: 말도 안되는 관계 (개정판) [BL] | E14: =SUMIFS(전체리스트!D:D,전체리스트!A:A,B14,전체리스트!C:C,D14) -> 391890 | F14: =E14-G14 -> 121296 | G14: =SUMIFS(전체리스트!E:E,전체리스트!A:A,B14,전체리스트!C:C,D14) -> 270594 | H14: =G14*0.05 -> 13529.7 | I14: =G14-H14 -> 257064.3
B15: 카카오페이지 | C15: =VLOOKUP(B15,raw_a,2,0) -> 1월분 | D15: 명판관 장평 | E15: =SUMIFS(전체리스트!D:D,전체리스트!A:A,B15,전체리스트!C:C,D15) -> 11000 | F15: =E15-G15 -> 3300 | G15: =SUMIFS(전체리스트!E:E,전체리스트!A:A,B15,전체리스트!C:C,D15) -> 7700 | H15: =G15*0.05 -> 385 | I15: =G15-H15 -> 7315
B16: 카카오페이지 | C16: =VLOOKUP(B16,raw_a,2,0) -> 1월분 | D16: 사랑과 우정 사이에서 (개정판) [BL] | E16: =SUMIFS(전체리스트!D:D,전체리스트!A:A,B16,전체리스트!C:C,D16) -> 219840 | F16: =E16-G16 -> 66546 | G16: =SUMIFS(전체리스트!E:E,전체리스트!A:A,B16,전체리스트!C:C,D16) -> 153294 | H16: =G16*0.05 -> 7664.7 | I16: =G16-H16 -> 145629.3
B17: 카카오페이지 | C17: =VLOOKUP(B17,raw_a,2,0) -> 1월분 | D17: 사랑의 형태 : 마음이 향하는 곳 | E17: =SUMIFS(전체리스트!D:D,전체리스트!A:A,B17,전체리스트!C:C,D17) -> 156100 | F17: =E17-G17 -> 48330 | G17: =SUMIFS(전체리스트!E:E,전체리스트!A:A,B17,전체리스트!C:C,D17) -> 107770 | H17: =G17*0.05 -> 5388.5 | I17: =G17-H17 -> 102381.5
... B42: 카카오웹툰 | C42: =VLOOKUP(B42,raw_a,2,0) -> 12월분 | D42: 신들의 연애사정 | E42: =SUMIFS(전체리스트!D:D,전체리스트!A:A,B42,전체리스트!C:C,D42) -> 3037066 | F42: =E42-G42 -> 586958 | G42: =SUMIFS(전체리스트!E:E,전체리스트!A:A,B42,전체리스트!C:C,D42) -> 2450108 | H42: =G42*0.05 -> 122505.4 | I42: =G42-H42 -> 2327602.6
B43: 합계 | E43: =SUM(E6:E42) -> 86715946 | F43: =SUM(F6:F42) -> 27781486 | G43: =SUM(G6:G42) -> 58934460 | H43: =SUM(H6:H42) -> 2946723 | I43: =SUM(I6:I42) -> 55987737 | J43: =SUM(J6:J42) -> 0

Sheet 카카오타파스
B4: [RS 정산 기준]
B5: 사이트명 | C5: 매출월 | D5: 작품명 | E5: 소비자매출액 | F5: 유통사수수료 | G5: 스토리위즈매출액 | H5: 스토리위즈수익 | I5: 스토리숲 수익 | J5: 비고
B6: 카카오 타파스 | C6: =VLOOKUP(B6,raw_a,2,0) -> 10-12월분 | D6: 아랫집 웬수 | E6: =SUMIFS(전체리스트!D:D,전체리스트!A:A,B6,전체리스트!C:C,D6) -> 3927560 | F6: =E6-G6 -> 0 | G6: =SUMIFS(전체리스트!E:E,전체리스트!A:A,B6,전체리스트!C:C,D6) -> 3927560 | H6: =G6*0.05 -> 196378 | I6: =G6-H6 -> 3731182
B7: 카카오 타파스 | C7: =VLOOKUP(B7,raw_a,2,0) -> 10-12월분 | D7: 내 자기님이 로그인하셨습니다 | E7: =SUMIFS(전체리스트!D:D,전체리스트!A:A,B7,전체리스트!C:C,D7) -> 5173654 | F7: =E7-G7 -> 0 | G7: =SUMIFS(전체리스트!E:E,전체리스트!A:A,B7,전체리스트!C:C,D7) -> 5173654 | H7: =G7*0.05 -> 258682.7 | I7: =G7-H7 -> 4914971.3
B8: 합계 | E8: =SUM(E6:E7) -> 9101214 | F8: =SUM(F6:F7) -> 0 | G8: =SUM(G6:G7) -> 9101214 | H8: =SUM(H6:H7) -> 455060.7 | I8: =SUM(I6:I7) -> 8646153.3 | J8: =SUM(J6:J7) -> 0

Sheet 네이버웹툰
B4: [RS 정산 기준]
B5: 사이트명 | C5: 매출월 | D5: 작품명 | E5: 소비자매출액 | F5: 유통사수수료 | G5: 스토리위즈매출액 | H5: 스토리위즈수익 | I5: 스토리숲 수익 | J5: 비고
B6: 네이버웹툰 | C6: =VLOOKUP(B6,raw_a,2,0) -> 1월분 | D6: 대표님의 삐뚤어진 사랑 | E6: =SUMIFS(전체리스트!D:D,전체리스트!A:A,B6,전체리스트!C:C,D6) -> 5285884.3 | F6: =E6-G6 -> 1585765.3 | G6: =SUMIFS(전체리스트!E:E,전체리스트!A:A,B6,전체리스트!C:C,D6) -> 3700119 | H6: =G6*0.05 -> 185005.95 | I6: =G6-H6 -> 3515113.1
B7: 네이버웹툰 | C7: =VLOOKUP(B7,raw_a,2,0) -> 1월분 | D7: 레벨업에 미친 의사 | E7: =SUMIFS(전체리스트!D:D,전체리스트!A:A,B7,전체리스트!C:C,D7) -> 3034097.4 | F7: =E7-G7 -> 910229.22 | G7: =SUMIFS(전체리스트!E:E,전체리스트!A:A,B7,전체리스트!C:C,D7) -> 2123868.2 | H7: =G7*0.05 -> 106193.41 | I7: =G7-H7 -> 2017674.8
B8: 네이버웹툰 | C8: =VLOOKUP(B8,raw_a,2,0) -> 1월분 | D8: 프렌시아의 꽃 | E8: =SUMIFS(전체리스트!D:D,전체리스트!A:A,B8,전체리스트!C:C,D8) -> 2243126.9 | F8: =E8-G8 -> 672938.07 | G8: =SUMIFS(전체리스트!E:E,전체리스트!A:A,B8,전체리스트!C:C,D8) -> 1570188.8 | H8: =G8*0.05 -> 78509.442 | I8: =G8-H8 -> 1491679.4
B9: 네이버웹툰 | C9: =VLOOKUP(B9,raw_a,2,0) -> 1월분 | D9: 꿈꾸는 먹잇감 [BL] | E9: =SUMIFS(전체리스트!D:D,전체리스트!A:A,B9,전체리스트!C:C,D9) -> 2219680 | F9: =E9-G9 -> 665904 | G9: =SUMIFS(전체리스트!E:E,전체리스트!A:A,B9,전체리스트!C:C,D9) -> 1553776 | H9: =G9*0.05 -> 77688.8 | I9: =G9-H9 -> 1476087.2
B10: 네이버웹툰 | C10: =VLOOKUP(B10,raw_a,2,0) -> 1월분 | D10: 거짓말, 뱀파이어가 어디 있어? [BL] | E10: =SUMIFS(전체리스트!D:D,전체리스트!A:A,B10,전체리스트!C:C,D10) -> 1807989.3 | F10: =E10-G10 -> 542396.79 | G10: =SUMIFS(전체리스트!E:E,전체리스트!A:A,B10,전체리스트!C:C,D10) -> 1265592.5 | H10: =G10*0.05 -> 63279.626 | I10: =G10-H10 -> 1202312.9
B11: 네이버웹툰 | C11: =VLOOKUP(B11,raw_a,2,0) -> 1월분 | D11: 대표님, 사모님이 도망가요 | E11: =SUMIFS(전체리스트!D:D,전체리스트!A:A,B11,전체리스트!C:C,D11) -> 1776986.2 | F11: =E11-G11 -> 533095.86 | G11: =SUMIFS(전체리스트!E:E,전체리스트!A:A,B11,전체리스트!C:C,D11) -> 1243890.3 | H11: =G11*0.05 -> 62194.517 | I11: =G11-H11 -> 1181695.8
B12: 네이버웹툰 | C12: =VLOOKUP(B12,raw_a,2,0) -> 1월분 | D12: 사랑할 수 없는 그녀 | E12: =SUMIFS(전체리스트!D:D,전체리스트!A:A,B12,전체리스트!C:C,D12) -> 1601822.4 | F12: =E12-G12 -> 480546.72 | G12: =SUMIFS(전체리스트!E:E,전체리스트!A:A,B12,전체리스트!C:C,D12) -> 1121275.7 | H12: =G12*0.05 -> 56063.784 | I12: =G12-H12 -> 1065211.9
B13: 네이버웹툰 | C13: =VLOOKUP(B13,raw_a,2,0) -> 1월분 | D13: 용의주도 대표님의 연애 게임 | E13: =SUMIFS(전체리스트!D:D,전체리스트!A:A,B13,전체리스트!C:C,D13) -> 1377208 | F13: =E13-G13 -> 413162.4 | G13: =SUMIFS(전체리스트!E:E,전체리스트!A:A,B13,전체리스트!C:C,D13) -> 964045.6 | H13: =G13*0.05 -> 48202.28 | I13: =G13-H13 -> 915843.32
B14: 네이버웹툰 | C14: =VLOOKUP(B14,raw_a,2,0) -> 1월분 | D14: 이혼신청 [BL] | E14: =SUMIFS(전체리스트!D:D,전체리스트!A:A,B14,전체리스트!C:C,D14) -> 1212326.6 | F14: =E14-G14 -> 363697.98 | G14: =SUMIFS(전체리스트!E:E,전체리스트!A:A,B14,전체리스트!C:C,D14) -> 848628.62 | H14: =G14*0.05 -> 42431.431 | I14: =G14-H14 -> 806197.19
B15: 네이버웹툰 | C15: =VLOOKUP(B15,raw_a,2,0) -> 1월분 | D15: 한번 해볼래? [BL] | E15: =SUMIFS(전체리스트!D:D,전체리스트!A:A,B15,전체리스트!C:C,D15) -> 1104753.2 | F15: =E15-G15 -> 331425.96 | G15: =SUMIFS(전체리스트!E:E,전체리스트!A:A,B15,전체리스트!C:C,D15) -> 773327.24 | H15: =G15*0.05 -> 38666.362 | I15: =G15-H15 -> 734660.88
B16: 네이버웹툰 | C16: =VLOOKUP(B16,raw_a,2,0) -> 1월분 | D16: 만지고 싶어! | E16: =SUMIFS(전체리스트!D:D,전체리스트!A:A,B16,전체리스트!C:C,D16) -> 979223 | F16: =E16-G16 -> 293766.9 | G16: =SUMIFS(전체리스트!E:E,전체리스트!A:A,B16,전체리스트!C:C,D16) -> 685456.1 | H16: =G16*0.05 -> 34272.805 | I16: =G16-H16 -> 651183.29
B17: 네이버웹툰 | C17: =VLOOKUP(B17,raw_a,2,0) -> 1월분 | D17: 한 번만 부탁해! [BL] | E17: =SUMIFS(전체리스트!D:D,전체리스트!A:A,B17,전체리스트!C:C,D17) -> 876490.4 | F17: =E17-G17 -> 262947.12 | G17: =SUMIFS(전체리스트!E:E,전체리스트!A:A,B17,전체리스트!C:C,D17) -> 613543.28 | H17: =G17*0.05 -> 30677.164 | I17: =G17-H17 -> 582866.12
... B54: 네이버웹툰-창작지원금 | C54: =VLOOKUP(B54,raw_a,2,0) -> 12월분 | D54: 아찔한 전남편 | E54: =SUMIFS(전체리스트!D:D,전체리스트!A:A,B54,전체리스트!C:C,D54) -> 28021 | F54: =E54-G54 -> 0 | G54: =SUMIFS(전체리스트!E:E,전체리스트!A:A,B54,전체리스트!C:C,D54) -> 28021 | H54: =G54*0.05 -> 1401.05 | I54: =G54-H54 -> 26619.95
B55: 합계 | E55: =SUM(E6:E54) -> 78520951 | F55: =SUM(F6:F54) -> 9010568.2 | G55: =SUM(G6:G54) -> 69510383 | H55: =SUM(H6:H54) -> 3475519.2 | I55: =SUM(I6:I54) -> 66034864 | J55: =SUM(J6:J54) -> 0

Sheet 콰이칸_중국
G3: 3개월 평균
B4: [RS 정산 기준] | F4: 환율(CNY) | G4: =VLOOKUP(B6,raw_a,6,0) -> 187.29
B5: 사이트명 | C5: 매출월 | D5: 작품명 | E5: 소비자매출액 | F5: 유통사수수료 | G5: 스토리위즈매출액 | H5: 스토리위즈수익 | I5: 스토리숲 수익 | J5: 비고
B6: 콰이칸 | C6: =VLOOKUP(B6,raw_a,2,0) -> 12월분 | D6: 황비님?황비님! MG | E6: =SUMIFS(전체리스트!D:D,전체리스트!A:A,B6,전체리스트!C:C,D6) -> 10613.21 | G6: =SUMIFS(전체리스트!E:E,전체리스트!A:A,B6,전체리스트!C:C,D6) -> 1987748.1 | H6: =G6*0.05 -> 99387.405 | I6: =G6-H6 -> 1888360.7
B7: 콰이칸 | C7: =VLOOKUP(B7,raw_a,2,0) -> 12월분 | D7: 옆집최애 | E7: =SUMIFS(전체리스트!D:D,전체리스트!A:A,B7,전체리스트!C:C,D7) -> 276 | G7: =SUMIFS(전체리스트!E:E,전체리스트!A:A,B7,전체리스트!C:C,D7) -> 51692.04 | H7: =G7*0.05 -> 2584.602 | I7: =G7-H7 -> 49107.438
B8: 콰이칸 | C8: =VLOOKUP(B8,raw_a,2,0) -> 12월분 | D8: 내 자기님 로그인하셨다 2 | E8: =SUMIFS(전체리스트!D:D,전체리스트!A:A,B8,전체리스트!C:C,D8) -> 2935.55 | G8: =SUMIFS(전체리스트!E:E,전체리스트!A:A,B8,전체리스트!C:C,D8) -> 549799.16 | H8: =G8*0.05 -> 27489.958 | I8: =G8-H8 -> 522309.2
B9: 콰이칸 | C9: =VLOOKUP(B9,raw_a,2,0) -> 12월분 | D9: 사랑과 우정 사이에는 爱情与友谊之间 | E9: =SUMIFS(전체리스트!D:D,전체리스트!A:A,B9,전체리스트!C:C,D9) -> 226.89 | G9: =SUMIFS(전체리스트!E:E,전체리스트!A:A,B9,전체리스트!C:C,D9) -> 42494.228 | H9: =G9*0.05 -> 2124.7114 | I9: =G9-H9 -> 40369.517
B10: 콰이칸 | C10: =VLOOKUP(B10,raw_a,2,0) -> 12월분 | D10: 거짓말! 뱀페이어가 어디있어? | E10: =SUMIFS(전체리스트!D:D,전체리스트!A:A,B10,전체리스트!C:C,D10) -> 3001.31 | G10: =SUMIFS(전체리스트!E:E,전체리스트!A:A,B10,전체리스트!C:C,D10) -> 562115.35 | H10: =G10*0.05 -> 28105.767 | I10: =G10-H10 -> 534009.58
B11: 콰이칸 | C11: =VLOOKUP(B11,raw_a,2,0) -> 12월분 | D11: 황비님?황비님! | E11: =SUMIFS(전체리스트!D:D,전체리스트!A:A,B11,전체리스트!C:C,D11) -> 0.09 | G11: =SUMIFS(전체리스트!E:E,전체리스트!A:A,B11,전체리스트!C:C,D11) -> 16.8561 | H11: =G11*0.05 -> 0.842805 | I11: =G11-H11 -> 16.013295
B12: 합계 | E12: =SUM(E6:E11) -> 17053.05 | F12: =SUM(F6:F11) -> 0 | G12: =SUM(G6:G11) -> 3193865.7 | H12: =SUM(H6:H11) -> 159693.29 | I12: =SUM(I6:I11) -> 3034172.4 | J12: =SUM(J6:J11) -> 0

Sheet kt_alpha
B4: [RS 정산 기준]
B5: 사이트명 | C5: 매출월 | D5: 작품명 | E5: 소비자매출액 | F5: 유통사수수료 | G5: 스토리위즈매출액 | H5: 스토리위즈수익 | I5: 스토리숲 수익 | J5: 비고
B6: kt_alpha | C6: =VLOOKUP(B6,raw_a,2,0) -> 1월분 | D6: 원고를 주세요! | E6: =SUMIFS(전체리스트!D:D,전체리스트!A:A,B6,전체리스트!C:C,D6) -> 596.4 | F6: =E6-G6 -> 268.38 | G6: =SUMIFS(전체리스트!E:E,전체리스트!A:A,B6,전체리스트!C:C,D6) -> 328.02 | H6: =G6*0.05 -> 16.401 | I6: =G6-H6 -> 311.619
B7: kt_alpha | C7: =VLOOKUP(B7,raw_a,2,0) -> 1월분 | D7: 어디에서든 널 원해 | E7: =SUMIFS(전체리스트!D:D,전체리스트!A:A,B7,전체리스트!C:C,D7) -> 138199.25 | F7: =E7-G7 -> 62189.663 | G7: =SUMIFS(전체리스트!E:E,전체리스트!A:A,B7,전체리스트!C:C,D7) -> 76009.587 | H7: =G7*0.05 -> 3800.4794 | I7: =G7-H7 -> 72209.108
B8: kt_alpha | C8: =VLOOKUP(B8,raw_a,2,0) -> 1월분 | D8: 어디에서든 널 원해(개정판) | E8: =SUMIFS(전체리스트!D:D,전체리스트!A:A,B8,전체리스트!C:C,D8) -> 93243.25 | F8: =E8-G8 -> 41959.463 | G8: =SUMIFS(전체리스트!E:E,전체리스트!A:A,B8,전체리스트!C:C,D8) -> 51283.787 | H8: =G8*0.05 -> 2564.1894 | I8: =G8-H8 -> 48719.598
B9: kt_alpha | C9: =VLOOKUP(B9,raw_a,2,0) -> 1월분 | D9: 말도 안되는 관계 | E9: =SUMIFS(전체리스트!D:D,전체리스트!A:A,B9,전체리스트!C:C,D9) -> 189304.4 | F9: =E9-G9 -> 75721.76 | G9: =SUMIFS(전체리스트!E:E,전체리스트!A:A,B9,전체리스트!C:C,D9) -> 113582.64 | H9: =G9*0.05 -> 5679.132 | I9: =G9-H9 -> 107903.51
B10: kt_alpha | C10: =VLOOKUP(B10,raw_a,2,0) -> 1월분 | D10: 말도 안되는 관계(개정판) | E10: =SUMIFS(전체리스트!D:D,전체리스트!A:A,B10,전체리스트!C:C,D10) -> 223032 | F10: =E10-G10 -> 89212.8 | G10: =SUMIFS(전체리스트!E:E,전체리스트!A:A,B10,전체리스트!C:C,D10) -> 133819.2 | H10: =G10*0.05 -> 6690.96 | I10: =G10-H10 -> 127128.24
B11: kt_alpha | C11: =VLOOKUP(B11,raw_a,2,0) -> 1월분 | D11: 어디에서든 널 원해_해외 | E11: =SUMIFS(전체리스트!D:D,전체리스트!A:A,B11,전체리스트!C:C,D11) -> 22992 | F11: =E11-G11 -> 13795.2 | G11: =SUMIFS(전체리스트!E:E,전체리스트!A:A,B11,전체리스트!C:C,D11) -> 9196.8 | H11: =G11*0.05 -> 459.84 | I11: =G11-H11 -> 8736.96
B12: 합계 | E12: =SUM(E6:E11) -> 667367.3 | F12: =SUM(F6:F11) -> 283147.27 | G12: =SUM(G6:G11) -> 384220.03 | H12: =SUM(H6:H11) -> 19211.002 | I12: =SUM(I6:I11) -> 365009.03 | J12: =SUM(J6:J11) -> 0

Sheet 레진코믹스
B4: [RS 정산 기준]
B5: 사이트명 | C5: 매출월 | D5: 작품명 | E5: 소비자매출액 | F5: 유통사수수료 | G5: 스토리위즈매출액 | H5: 스토리위즈수익 | I5: 스토리숲 수익 | J5: 비고
B6: 레진코믹스 | C6: =VLOOKUP(B6,raw_a,2,0) -> 1월분 | D6: 슬기로운 생활 | E6: =SUMIFS(전체리스트!D:D,전체리스트!A:A,B6,전체리스트!C:C,D6) -> 8190 | F6: =E6-G6 -> 0 | G6: =SUMIFS(전체리스트!E:E,전체리스트!A:A,B6,전체리스트!C:C,D6) -> 8190 | H6: =G6*0.05 -> 409.5 | I6: =G6-H6 -> 7780.5
B7: 레진코믹스 | C7: =VLOOKUP(B7,raw_a,2,0) -> 1월분 | D7: 쌀툰 | E7: =SUMIFS(전체리스트!D:D,전체리스트!A:A,B7,전체리스트!C:C,D7) -> 21000 | F7: =E7-G7 -> 0 | G7: =SUMIFS(전체리스트!E:E,전체리스트!A:A,B7,전체리스트!C:C,D7) -> 21000 | H7: =G7*0.05 -> 1050 | I7: =G7-H7 -> 19950
B8: 레진코믹스 | C8: =VLOOKUP(B8,raw_a,2,0) -> 1월분 | D8: 옆집 최애 | E8: =SUMIFS(전체리스트!D:D,전체리스트!A:A,B8,전체리스트!C:C,D8) -> 62720 | F8: =E8-G8 -> 0 | G8: =SUMIFS(전체리스트!E:E,전체리스트!A:A,B8,전체리스트!C:C,D8) -> 62720 | H8: =G8*0.05 -> 3136 | I8: =G8-H8 -> 59584
B9: 레진코믹스 | C9: =VLOOKUP(B9,raw_a,2,0) -> 1월분 | D9: 한집 두 살림 | E9: =SUMIFS(전체리스트!D:D,전체리스트!A:A,B9,전체리스트!C:C,D9) -> 45080 | F9: =E9-G9 -> 0 | G9: =SUMIFS(전체리스트!E:E,전체리스트!A:A,B9,전체리스트!C:C,D9) -> 45080 | H9: =G9*0.05 -> 2254 | I9: =G9-H9 -> 42826
B10: 레진코믹스 | C10: =VLOOKUP(B10,raw_a,2,0) -> 1월분 | D10: 탑배우의 이중생활 | E10: =SUMIFS(전체리스트!D:D,전체리스트!A:A,B10,전체리스트!C:C,D10) -> 280 | F10: =E10-G10 -> 0 | G10: =SUMIFS(전체리스트!E:E,전체리스트!A:A,B10,전체리스트!C:C,D10) -> 280 | H10: =G10*0.05 -> 14 | I10: =G10-H10 -> 266
B11: 레진코믹스 | C11: =VLOOKUP(B11,raw_a,2,0) -> 1월분 | D11: 사랑과 우정 사이에서 | E11: =SUMIFS(전체리스트!D:D,전체리스트!A:A,B11,전체리스트!C:C,D11) -> 46200 | F11: =E11-G11 -> 0 | G11: =SUMIFS(전체리스트!E:E,전체리스트!A:A,B11,전체리스트!C:C,D11) -> 46200 | H11: =G11*0.05 -> 2310 | I11: =G11-H11 -> 43890
B12: 레진코믹스 | C12: =VLOOKUP(B12,raw_a,2,0) -> 1월분 | D12: 호랑이 장가 드는 날 | E12: =SUMIFS(전체리스트!D:D,전체리스트!A:A,B12,전체리스트!C:C,D12) -> 48000 | F12: =E12-G12 -> 0 | G12: =SUMIFS(전체리스트!E:E,전체리스트!A:A,B12,전체리스트!C:C,D12) -> 48000 | H12: =G12*0.05 -> 2400 | I12: =G12-H12 -> 45600
B13: 레진코믹스 | C13: =VLOOKUP(B13,raw_a,2,0) -> 1월분 | D13: 호랑이 장가 드는 날 [개정판] | E13: =SUMIFS(전체리스트!D:D,전체리스트!A:A,B13,전체리스트!C:C,D13) -> 14800 | F13: =E13-G13 -> 0 | G13: =SUMIFS(전체리스트!E:E,전체리스트!A:A,B13,전체리스트!C:C,D13) -> 14800 | H13: =G13*0.05 -> 740 | I13: =G13-H13 -> 14060
B14: 레진코믹스 | C14: =VLOOKUP(B14,raw_a,2,0) -> 1월분 | D14: 츤데레 흥신소 | E14: =SUMIFS(전체리스트!D:D,전체리스트!A:A,B14,전체리스트!C:C,D14) -> 600 | F14: =E14-G14 -> 0 | G14: =SUMIFS(전체리스트!E:E,전체리스트!A:A,B14,전체리스트!C:C,D14) -> 600 | H14: =G14*0.05 -> 30 | I14: =G14-H14 -> 570
B15: 레진코믹스 | C15: =VLOOKUP(B15,raw_a,2,0) -> 1월분 | D15: 사랑할 수 없는 그녀 | E15: =SUMIFS(전체리스트!D:D,전체리스트!A:A,B15,전체리스트!C:C,D15) -> 717444 | F15: =E15-G15 -> 0 | G15: =SUMIFS(전체리스트!E:E,전체리스트!A:A,B15,전체리스트!C:C,D15) -> 717444 | H15: =G15*0.05 -> 35872.2 | I15: =G15-H15 -> 681571.8
B16: 레진코믹스 | C16: =VLOOKUP(B16,raw_a,2,0) -> 1월분 | D16: 속도위반 대표님과 계약 아내 [연재] | E16: =SUMIFS(전체리스트!D:D,전체리스트!A:A,B16,전체리스트!C:C,D16) -> 1202544 | F16: =E16-G16 -> 0 | G16: =SUMIFS(전체리스트!E:E,전체리스트!A:A,B16,전체리스트!C:C,D16) -> 1202544 | H16: =G16*0.05 -> 60127.2 | I16: =G16-H16 -> 1142416.8
B17: 레진코믹스 | C17: =VLOOKUP(B17,raw_a,2,0) -> 1월분 | D17: 연애포차 | E17: =SUMIFS(전체리스트!D:D,전체리스트!A:A,B17,전체리스트!C:C,D17) -> 1350 | F17: =E17-G17 -> 0 | G17: =SUMIFS(전체리스트!E:E,전체리스트!A:A,B17,전체리스트!C:C,D17) -> 1350 | H17: =G17*0.05 -> 67.5 | I17: =G17-H17 -> 1282.5
... B32: 레진코믹스 | C32: =VLOOKUP(B32,raw_a,2,0) -> 1월분 | D32: 한 번만 부탁해! | E32: =SUMIFS(전체리스트!D:D,전체리스트!A:A,B32,전체리스트!C:C,D32) -> 249000 | F32: =E32-G32 -> 0 | G32: =SUMIFS(전체리스트!E:E,전체리스트!A:A,B32,전체리스트!C:C,D32) -> 249000 | H32: =G32*0.05 -> 12450 | I32: =G32-H32 -> 236550
B33: 합계 | E33: =SUM(E6:E32) -> 8526312 | F33: =SUM(F6:F32) -> 0 | G33: =SUM(G6:G32) -> 8526312 | H33: =SUM(H6:H32) -> 426315.6 | I33: =SUM(I6:I32) -> 8099996.4 | J33: =SUM(J6:J32) -> 0

Sheet 북큐브
B4: [RS 정산 기준]
B5: 사이트명 | C5: 매출월 | D5: 작품명 | E5: 소비자매출액 | F5: 유통사수수료 | G5: 스토리위즈매출액 | H5: 스토리위즈수익 | I5: 스토리숲 수익 | J5: 비고
B6: 북큐브 | C6: =VLOOKUP(B6,raw_a,2,0) -> 1월분 | D6: 거짓말, 뱀파이어가 어디 있어? | E6: =SUMIFS(전체리스트!D:D,전체리스트!A:A,B6,전체리스트!C:C,D6) -> 34400 | F6: =E6-G6 -> 10320 | G6: =SUMIFS(전체리스트!E:E,전체리스트!A:A,B6,전체리스트!C:C,D6) -> 24080 | H6: =G6*0.05 -> 1204 | I6: =G6-H6 -> 22876
B7: 북큐브 | C7: =VLOOKUP(B7,raw_a,2,0) -> 1월분 | D7: 꿈꾸는 먹잇감 | E7: =SUMIFS(전체리스트!D:D,전체리스트!A:A,B7,전체리스트!C:C,D7) -> 460000 | F7: =E7-G7 -> 138000 | G7: =SUMIFS(전체리스트!E:E,전체리스트!A:A,B7,전체리스트!C:C,D7) -> 322000 | H7: =G7*0.05 -> 16100 | I7: =G7-H7 -> 305900
B8: 북큐브 | C8: =VLOOKUP(B8,raw_a,2,0) -> 1월분 | D8: 꿰인 사이 | E8: =SUMIFS(전체리스트!D:D,전체리스트!A:A,B8,전체리스트!C:C,D8) -> 108500 | F8: =E8-G8 -> 32550 | G8: =SUMIFS(전체리스트!E:E,전체리스트!A:A,B8,전체리스트!C:C,D8) -> 75950 | H8: =G8*0.05 -> 3797.5 | I8: =G8-H8 -> 72152.5
B9: 북큐브 | C9: =VLOOKUP(B9,raw_a,2,0) -> 1월분 | D9: 사랑과 우정 사이에서[성인] | E9: =SUMIFS(전체리스트!D:D,전체리스트!A:A,B9,전체리스트!C:C,D9) -> 10500 | F9: =E9-G9 -> 3150 | G9: =SUMIFS(전체리스트!E:E,전체리스트!A:A,B9,전체리스트!C:C,D9) -> 7350 | H9: =G9*0.05 -> 367.5 | I9: =G9-H9 -> 6982.5
B10: 북큐브 | C10: =VLOOKUP(B10,raw_a,2,0) -> 1월분 | D10: 쌀툰 | E10: =SUMIFS(전체리스트!D:D,전체리스트!A:A,B10,전체리스트!C:C,D10) -> 400 | F10: =E10-G10 -> 120 | G10: =SUMIFS(전체리스트!E:E,전체리스트!A:A,B10,전체리스트!C:C,D10) -> 280 | H10: =G10*0.05 -> 14 | I10: =G10-H10 -> 266
B11: 북큐브 | C11: =VLOOKUP(B11,raw_a,2,0) -> 1월분 | D11: 옆집 최애[성인] | E11: =SUMIFS(전체리스트!D:D,전체리스트!A:A,B11,전체리스트!C:C,D11) -> 13500 | F11: =E11-G11 -> 4050 | G11: =SUMIFS(전체리스트!E:E,전체리스트!A:A,B11,전체리스트!C:C,D11) -> 9450 | H11: =G11*0.05 -> 472.5 | I11: =G11-H11 -> 8977.5
B12: 북큐브 | C12: =VLOOKUP(B12,raw_a,2,0) -> 1월분 | D12: 이혼신청 | E12: =SUMIFS(전체리스트!D:D,전체리스트!A:A,B12,전체리스트!C:C,D12) -> 33600 | F12: =E12-G12 -> 10080 | G12: =SUMIFS(전체리스트!E:E,전체리스트!A:A,B12,전체리스트!C:C,D12) -> 23520 | H12: =G12*0.05 -> 1176 | I12: =G12-H12 -> 22344
B13: 북큐브 | C13: =VLOOKUP(B13,raw_a,2,0) -> 1월분 | D13: 탑배우의 이중생활 | E13: =SUMIFS(전체리스트!D:D,전체리스트!A:A,B13,전체리스트!C:C,D13) -> 300 | F13: =E13-G13 -> 90 | G13: =SUMIFS(전체리스트!E:E,전체리스트!A:A,B13,전체리스트!C:C,D13) -> 210 | H13: =G13*0.05 -> 10.5 | I13: =G13-H13 -> 199.5
B14: 북큐브 | C14: =VLOOKUP(B14,raw_a,2,0) -> 1월분 | D14: 한 번만 부탁해! | E14: =SUMIFS(전체리스트!D:D,전체리스트!A:A,B14,전체리스트!C:C,D14) -> 10000 | F14: =E14-G14 -> 3000 | G14: =SUMIFS(전체리스트!E:E,전체리스트!A:A,B14,전체리스트!C:C,D14) -> 7000 | H14: =G14*0.05 -> 350 | I14: =G14-H14 -> 6650
B15: 북큐브 | C15: =VLOOKUP(B15,raw_a,2,0) -> 1월분 | D15: 한번 해볼래? | E15: =SUMIFS(전체리스트!D:D,전체리스트!A:A,B15,전체리스트!C:C,D15) -> 19000 | F15: =E15-G15 -> 5700 | G15: =SUMIFS(전체리스트!E:E,전체리스트!A:A,B15,전체리스트!C:C,D15) -> 13300 | H15: =G15*0.05 -> 665 | I15: =G15-H15 -> 12635
B16: 북큐브 | C16: =VLOOKUP(B16,raw_a,2,0) -> 1월분 | D16: 호랑이 장가드는 날 | E16: =SUMIFS(전체리스트!D:D,전체리스트!A:A,B16,전체리스트!C:C,D16) -> 209700 | F16: =E16-G16 -> 62910 | G16: =SUMIFS(전체리스트!E:E,전체리스트!A:A,B16,전체리스트!C:C,D16) -> 146790 | H16: =G16*0.05 -> 7339.5 | I16: =G16-H16 -> 139450.5
B17: 합계 | E17: =SUM(E6:E16) -> 899900 | F17: =SUM(F6:F16) -> 269970 | G17: =SUM(G6:G16) -> 629930 | H17: =SUM(H6:H16) -> 31496.5 | I17: =SUM(I6:I16) -> 598433.5 | J17: =SUM(J6:J16) -> 0

Sheet 탑툰
B4: [RS 정산 기준]
B5: 사이트명 | C5: 매출월 | D5: 작품명 | E5: 소비자매출액 | F5: 유통사수수료 | G5: 스토리위즈매출액 | H5: 스토리위즈수익 | I5: 스토리숲 수익 | J5: 비고
B6: 탑툰 | C6: =VLOOKUP(B6,raw_a,2,0) -> 12월분 | D6: 속도위반 대표님과 계약 아내 | E6: =SUMIFS(전체리스트!D:D,전체리스트!A:A,B6,전체리스트!C:C,D6) -> 669024 | F6: =E6-G6 -> 0 | G6: =SUMIFS(전체리스트!E:E,전체리스트!A:A,B6,전체리스트!C:C,D6) -> 669024 | H6: =G6*0.05 -> 33451.2 | I6: =G6-H6 -> 635572.8
B7: 탑툰 | C7: =VLOOKUP(B7,raw_a,2,0) -> 12월분 | D7: 사랑할 수 없는 그녀 | E7: =SUMIFS(전체리스트!D:D,전체리스트!A:A,B7,전체리스트!C:C,D7) -> 38961 | F7: =E7-G7 -> 0 | G7: =SUMIFS(전체리스트!E:E,전체리스트!A:A,B7,전체리스트!C:C,D7) -> 38961 | H7: =G7*0.05 -> 1948.05 | I7: =G7-H7 -> 37012.95
B8: 탑툰 | C8: =VLOOKUP(B8,raw_a,2,0) -> 12월분 | D8: 대표님의 삐뚤어진 사랑 | E8: =SUMIFS(전체리스트!D:D,전체리스트!A:A,B8,전체리스트!C:C,D8) -> 603891 | F8: =E8-G8 -> 0 | G8: =SUMIFS(전체리스트!E:E,전체리스트!A:A,B8,전체리스트!C:C,D8) -> 603891 | H8: =G8*0.05 -> 30194.55 | I8: =G8-H8 -> 573696.45
B9: 탑툰 | C9: =VLOOKUP(B9,raw_a,2,0) -> 12월분 | D9: 대표님, 사모님이 도망가요 | E9: =SUMIFS(전체리스트!D:D,전체리스트!A:A,B9,전체리스트!C:C,D9) -> 332127 | F9: =E9-G9 -> 0 | G9: =SUMIFS(전체리스트!E:E,전체리스트!A:A,B9,전체리스트!C:C,D9) -> 332127 | H9: =G9*0.05 -> 16606.35 | I9: =G9-H9 -> 315520.65
B10: 탑툰 | C10: =VLOOKUP(B10,raw_a,2,0) -> 12월분 | D10: 사랑의 형태: 마음이 향하는 곳 | E10: =SUMIFS(전체리스트!D:D,전체리스트!A:A,B10,전체리스트!C:C,D10) -> 7533 | F10: =E10-G10 -> 0 | G10: =SUMIFS(전체리스트!E:E,전체리스트!A:A,B10,전체리스트!C:C,D10) -> 7533 | H10: =G10*0.05 -> 376.65 | I10: =G10-H10 -> 7156.35
B11: 탑툰 | C11: =VLOOKUP(B11,raw_a,2,0) -> 12월분 | D11: 만지고 싶어 | E11: =SUMIFS(전체리스트!D:D,전체리스트!A:A,B11,전체리스트!C:C,D11) -> 57312 | F11: =E11-G11 -> 0 | G11: =SUMIFS(전체리스트!E:E,전체리스트!A:A,B11,전체리스트!C:C,D11) -> 57312 | H11: =G11*0.05 -> 2865.6 | I11: =G11-H11 -> 54446.4
B12: 탑툰 | C12: =VLOOKUP(B12,raw_a,2,0) -> 12월분 | D12: 너에게만 음성인식 | E12: =SUMIFS(전체리스트!D:D,전체리스트!A:A,B12,전체리스트!C:C,D12) -> 25434 | F12: =E12-G12 -> 0 | G12: =SUMIFS(전체리스트!E:E,전체리스트!A:A,B12,전체리스트!C:C,D12) -> 25434 | H12: =G12*0.05 -> 1271.7 | I12: =G12-H12 -> 24162.3
B13: 합계 | E13: =SUM(E6:E12) -> 1734282 | F13: =SUM(F6:F12) -> 0 | G13: =SUM(G6:G12) -> 1734282 | H13: =SUM(H6:H12) -> 86714.1 | I13: =SUM(I6:I12) -> 1647567.9 | J13: =SUM(J6:J12) -> 0

Sheet 봄툰
B4: [RS 정산 기준]
B5: 사이트명 | C5: 매출월 | D5: 작품명 | E5: 소비자매출액 | F5: 유통사수수료 | G5: 스토리위즈매출액 | H5: 스토리위즈수익 | I5: 스토리숲 수익 | J5: 비고
B6: 봄툰_유통1 | C6: =VLOOKUP(B6,raw_a,2,0) -> 11월분 | D6: 아랫집 웬수 | E6: =SUMIFS(전체리스트!D:D,전체리스트!A:A,B6,전체리스트!C:C,D6) -> 625100 | F6: =E6-G6 -> 312550 | G6: =SUMIFS(전체리스트!E:E,전체리스트!A:A,B6,전체리스트!C:C,D6) -> 312550 | H6: =G6*0.05 -> 15627.5 | I6: =G6-H6 -> 296922.5
B7: 봄툰_유통2 | C7: =VLOOKUP(B7,raw_a,2,0) -> 11월분 | D7: 아랫집 웬수 | E7: =SUMIFS(전체리스트!D:D,전체리스트!A:A,B7,전체리스트!C:C,D7) -> 3150 | F7: =E7-G7 -> 1575 | G7: =SUMIFS(전체리스트!E:E,전체리스트!A:A,B7,전체리스트!C:C,D7) -> 1575 | H7: =G7*0.05 -> 78.75 | I7: =G7-H7 -> 1496.25
B8: 봄툰_유통3 | C8: =VLOOKUP(B8,raw_a,2,0) -> 11월분 | D8: 아랫집 웬수 | E8: =SUMIFS(전체리스트!D:D,전체리스트!A:A,B8,전체리스트!C:C,D8) -> 8400 | F8: =E8-G8 -> 4200 | G8: =SUMIFS(전체리스트!E:E,전체리스트!A:A,B8,전체리스트!C:C,D8) -> 4200 | H8: =G8*0.05 -> 210 | I8: =G8-H8 -> 3990
B9: 봄툰_유통4 | C9: =VLOOKUP(B9,raw_a,2,0) -> 11월분 | D9: 아랫집 웬수 | E9: =SUMIFS(전체리스트!D:D,전체리스트!A:A,B9,전체리스트!C:C,D9) -> 2940 | F9: =E9-G9 -> 1470 | G9: =SUMIFS(전체리스트!E:E,전체리스트!A:A,B9,전체리스트!C:C,D9) -> 1470 | H9: =G9*0.05 -> 73.5 | I9: =G9-H9 -> 1396.5
B10: 봄툰_유통5 | C10: =VLOOKUP(B10,raw_a,2,0) -> 11월분 | D10: 페티쉬 BL 단편선 | E10: =SUMIFS(전체리스트!D:D,전체리스트!A:A,B10,전체리스트!C:C,D10) -> 11760 | F10: =E10-G10 -> 5880 | G10: =SUMIFS(전체리스트!E:E,전체리스트!A:A,B10,전체리스트!C:C,D10) -> 5880 | H10: =G10*0.05 -> 294 | I10: =G10-H10 -> 5586
B11: 봄툰 | C11: =VLOOKUP(B11,raw_a,2,0) -> 12월분 | D11: 명판관 장평 | E11: =SUMIFS(전체리스트!D:D,전체리스트!A:A,B11,전체리스트!C:C,D11) -> 900 | F11: =E11-G11 -> 414 | G11: =SUMIFS(전체리스트!E:E,전체리스트!A:A,B11,전체리스트!C:C,D11) -> 486 | H11: =G11*0.05 -> 24.3 | I11: =G11-H11 -> 461.7
B12: 봄툰 | C12: =VLOOKUP(B12,raw_a,2,0) -> 12월분 | D12: 사랑할 수 없는 그녀 | E12: =SUMIFS(전체리스트!D:D,전체리스트!A:A,B12,전체리스트!C:C,D12) -> 61020 | F12: =E12-G12 -> 30510 | G12: =SUMIFS(전체리스트!E:E,전체리스트!A:A,B12,전체리스트!C:C,D12) -> 30510 | H12: =G12*0.05 -> 1525.5 | I12: =G12-H12 -> 28984.5
B13: 봄툰 | C13: =VLOOKUP(B13,raw_a,2,0) -> 12월분 | D13: 슬기로운 생활(완결) | E13: =SUMIFS(전체리스트!D:D,전체리스트!A:A,B13,전체리스트!C:C,D13) -> 7560 | F13: =E13-G13 -> 4176 | G13: =SUMIFS(전체리스트!E:E,전체리스트!A:A,B13,전체리스트!C:C,D13) -> 3384 | H13: =G13*0.05 -> 169.2 | I13: =G13-H13 -> 3214.8
B14: 봄툰 | C14: =VLOOKUP(B14,raw_a,2,0) -> 12월분 | D14: 아랫집 웬수 | E14: =SUMIFS(전체리스트!D:D,전체리스트!A:A,B14,전체리스트!C:C,D14) -> 458460 | F14: =E14-G14 -> 283257 | G14: =SUMIFS(전체리스트!E:E,전체리스트!A:A,B14,전체리스트!C:C,D14) -> 175203 | H14: =G14*0.05 -> 8760.15 | I14: =G14-H14 -> 166442.85
B15: 봄툰 | C15: =VLOOKUP(B15,raw_a,2,0) -> 12월분 | D15: 악마와 나 사이에는 | E15: =SUMIFS(전체리스트!D:D,전체리스트!A:A,B15,전체리스트!C:C,D15) -> 25200 | F15: =E15-G15 -> 13536 | G15: =SUMIFS(전체리스트!E:E,전체리스트!A:A,B15,전체리스트!C:C,D15) -> 11664 | H15: =G15*0.05 -> 583.2 | I15: =G15-H15 -> 11080.8
B16: 봄툰 | C16: =VLOOKUP(B16,raw_a,2,0) -> 12월분 | D16: 옆집 최애 | E16: =SUMIFS(전체리스트!D:D,전체리스트!A:A,B16,전체리스트!C:C,D16) -> 262440 | F16: =E16-G16 -> 137570 | G16: =SUMIFS(전체리스트!E:E,전체리스트!A:A,B16,전체리스트!C:C,D16) -> 124870 | H16: =G16*0.05 -> 6243.5 | I16: =G16-H16 -> 118626.5
B17: 봄툰 | C17: =VLOOKUP(B17,raw_a,2,0) -> 12월분 | D17: 주작의 귀환 | E17: =SUMIFS(전체리스트!D:D,전체리스트!A:A,B17,전체리스트!C:C,D17) -> 2880 | F17: =E17-G17 -> 1325 | G17: =SUMIFS(전체리스트!E:E,전체리스트!A:A,B17,전체리스트!C:C,D17) -> 1555 | H17: =G17*0.05 -> 77.75 | I17: =G17-H17 -> 1477.25
... B44: 봄툰 | C44: =VLOOKUP(B44,raw_a,2,0) -> 12월분 | D44: 어이상실의 시대 | E44: =SUMIFS(전체리스트!D:D,전체리스트!A:A,B44,전체리스트!C:C,D44) -> 7200 | F44: =E44-G44 -> 2520 | G44: =SUMIFS(전체리스트!E:E,전체리스트!A:A,B44,전체리스트!C:C,D44) -> 4680 | H44: =G44*0.05 -> 234 | I44: =G44-H44 -> 4446
B45: 합계 | E45: =SUM(E6:E44) -> 7149530 | F45: =SUM(F6:F44) -> 3131403 | G45: =SUM(G6:G44) -> 4018127 | H45: =SUM(H6:H44) -> 200906.35 | I45: =SUM(I6:I44) -> 3817220.6 | J45: =SUM(J6:J44) -> 0

Sheet 애니툰
B4: [RS 정산 기준]
B5: 사이트명 | C5: 매출월 | D5: 작품명 | E5: 소비자매출액 | F5: 유통사수수료 | G5: 스토리위즈매출액 | H5: 스토리위즈수익 | I5: 스토리숲 수익 | J5: 비고
B6: 애니툰 | C6: =VLOOKUP(B6,raw_a,2,0) -> 12월분 | D6: 꿈꾸는 먹잇감 | E6: =SUMIFS(전체리스트!D:D,전체리스트!A:A,B6,전체리스트!C:C,D6) -> 3510 | F6: =E6-G6 -> 1053 | G6: =SUMIFS(전체리스트!E:E,전체리스트!A:A,B6,전체리스트!C:C,D6) -> 2457 | H6: =G6*0.05 -> 122.85 | I6: =G6-H6 -> 2334.15
B7: 애니툰 | C7: =VLOOKUP(B7,raw_a,2,0) -> 12월분 | D7: 꿰인 사이 | E7: =SUMIFS(전체리스트!D:D,전체리스트!A:A,B7,전체리스트!C:C,D7) -> 35370 | F7: =E7-G7 -> -11527 | G7: =SUMIFS(전체리스트!E:E,전체리스트!A:A,B7,전체리스트!C:C,D7) -> 46897 | H7: =G7*0.05 -> 2344.85 | I7: =G7-H7 -> 44552.15
B8: 애니툰 | C8: =VLOOKUP(B8,raw_a,2,0) -> 12월분 | D8: 너에게만 음성인식 | E8: =SUMIFS(전체리스트!D:D,전체리스트!A:A,B8,전체리스트!C:C,D8) -> 68175 | F8: =E8-G8 -> 14719.5 | G8: =SUMIFS(전체리스트!E:E,전체리스트!A:A,B8,전체리스트!C:C,D8) -> 53455.5 | H8: =G8*0.05 -> 2672.775 | I8: =G8-H8 -> 50782.725
B9: 애니툰 | C9: =VLOOKUP(B9,raw_a,2,0) -> 12월분 | D9: 대표님, 사모님이 도망가요 | E9: =SUMIFS(전체리스트!D:D,전체리스트!A:A,B9,전체리스트!C:C,D9) -> 709290 | F9: =E9-G9 -> 67963 | G9: =SUMIFS(전체리스트!E:E,전체리스트!A:A,B9,전체리스트!C:C,D9) -> 641327 | H9: =G9*0.05 -> 32066.35 | I9: =G9-H9 -> 609260.65
B10: 애니툰 | C10: =VLOOKUP(B10,raw_a,2,0) -> 12월분 | D10: 대표님의 삐뚤어진 사랑 | E10: =SUMIFS(전체리스트!D:D,전체리스트!A:A,B10,전체리스트!C:C,D10) -> 2176740 | F10: =E10-G10 -> 386746 | G10: =SUMIFS(전체리스트!E:E,전체리스트!A:A,B10,전체리스트!C:C,D10) -> 1789994 | H10: =G10*0.05 -> 89499.7 | I10: =G10-H10 -> 1700494.3
B11: 애니툰 | C11: =VLOOKUP(B11,raw_a,2,0) -> 12월분 | D11: 마녀 따위 안할래요 | E11: =SUMIFS(전체리스트!D:D,전체리스트!A:A,B11,전체리스트!C:C,D11) -> 30780 | F11: =E11-G11 -> 9234 | G11: =SUMIFS(전체리스트!E:E,전체리스트!A:A,B11,전체리스트!C:C,D11) -> 21546 | H11: =G11*0.05 -> 1077.3 | I11: =G11-H11 -> 20468.7
B12: 애니툰 | C12: =VLOOKUP(B12,raw_a,2,0) -> 12월분 | D12: 만지고 싶어! | E12: =SUMIFS(전체리스트!D:D,전체리스트!A:A,B12,전체리스트!C:C,D12) -> 113602.5 | F12: =E12-G12 -> 22173.75 | G12: =SUMIFS(전체리스트!E:E,전체리스트!A:A,B12,전체리스트!C:C,D12) -> 91428.75 | H12: =G12*0.05 -> 4571.4375 | I12: =G12-H12 -> 86857.312
B13: 애니툰 | C13: =VLOOKUP(B13,raw_a,2,0) -> 12월분 | D13: 말도 안되는 관계 [성인판] | E13: =SUMIFS(전체리스트!D:D,전체리스트!A:A,B13,전체리스트!C:C,D13) -> 140400 | F13: =E13-G13 -> 42120 | G13: =SUMIFS(전체리스트!E:E,전체리스트!A:A,B13,전체리스트!C:C,D13) -> 98280 | H13: =G13*0.05 -> 4914 | I13: =G13-H13 -> 93366
B14: 애니툰 | C14: =VLOOKUP(B14,raw_a,2,0) -> 12월분 | D14: 말도 안되는 관계 [일반판] | E14: =SUMIFS(전체리스트!D:D,전체리스트!A:A,B14,전체리스트!C:C,D14) -> 3240 | F14: =E14-G14 -> 972 | G14: =SUMIFS(전체리스트!E:E,전체리스트!A:A,B14,전체리스트!C:C,D14) -> 2268 | H14: =G14*0.05 -> 113.4 | I14: =G14-H14 -> 2154.6
B15: 애니툰 | C15: =VLOOKUP(B15,raw_a,2,0) -> 12월분 | D15: 멍멍이와 주인님 | E15: =SUMIFS(전체리스트!D:D,전체리스트!A:A,B15,전체리스트!C:C,D15) -> 135 | F15: =E15-G15 -> 40.5 | G15: =SUMIFS(전체리스트!E:E,전체리스트!A:A,B15,전체리스트!C:C,D15) -> 94.5 | H15: =G15*0.05 -> 4.725 | I15: =G15-H15 -> 89.775
B16: 애니툰 | C16: =VLOOKUP(B16,raw_a,2,0) -> 12월분 | D16: 명판관 장평 | E16: =SUMIFS(전체리스트!D:D,전체리스트!A:A,B16,전체리스트!C:C,D16) -> 540 | F16: =E16-G16 -> 162 | G16: =SUMIFS(전체리스트!E:E,전체리스트!A:A,B16,전체리스트!C:C,D16) -> 378 | H16: =G16*0.05 -> 18.9 | I16: =G16-H16 -> 359.1
B17: 애니툰 | C17: =VLOOKUP(B17,raw_a,2,0) -> 12월분 | D17: 미니멈 | E17: =SUMIFS(전체리스트!D:D,전체리스트!A:A,B17,전체리스트!C:C,D17) -> 0 | F17: =E17-G17 -> -265 | G17: =SUMIFS(전체리스트!E:E,전체리스트!A:A,B17,전체리스트!C:C,D17) -> 265 | H17: =G17*0.05 -> 13.25 | I17: =G17-H17 -> 251.75
... B41: 애니툰 | C41: =VLOOKUP(B41,raw_a,2,0) -> 12월분 | D41: 호랑이 장가 드는 날(개정판) | E41: =SUMIFS(전체리스트!D:D,전체리스트!A:A,B41,전체리스트!C:C,D41) -> 675 | F41: =E41-G41 -> 202.5 | G41: =SUMIFS(전체리스트!E:E,전체리스트!A:A,B41,전체리스트!C:C,D41) -> 472.5 | H41: =G41*0.05 -> 23.625 | I41: =G41-H41 -> 448.875
B42: 합계 | E42: =SUM(E6:E41) -> 6190222.5 | F42: =SUM(F6:F41) -> 1078566.8 | G42: =SUM(G6:G41) -> 5111655.8 | H42: =SUM(H6:H41) -> 255582.79 | I42: =SUM(I6:I41) -> 4856073 | J42: =SUM(J6:J41) -> 0

Sheet 코미코_한국
B4: [RS 정산 기준]
B5: 사이트명 | C5: 매출월 | D5: 작품명 | E5: 소비자매출액 | F5: 유통사수수료 | G5: 스토리위즈매출액 | H5: 스토리위즈수익 | I5: 스토리숲 수익 | J5: 비고
B6: 코미코_위즈덤 | C6: =VLOOKUP(B6,raw_a,2,0) -> 12월분 | D6: 내 자기님이 로그인 하셨습니다 | E6: =SUMIFS(전체리스트!D:D,전체리스트!A:A,B6,전체리스트!C:C,D6) -> 916470 | F6: =E6-G6 -> 0 | G6: =SUMIFS(전체리스트!E:E,전체리스트!A:A,B6,전체리스트!C:C,D6) -> 916470 | H6: =G6*0.05 -> 45823.5 | I6: =G6-H6 -> 870646.5
B7: 코미코_NHN | C7: =VLOOKUP(B7,raw_a,2,0) -> 1월분 | D7: 거짓말, 뱀파이어가 어디 있어? [완] | E7: =SUMIFS(전체리스트!D:D,전체리스트!A:A,B7,전체리스트!C:C,D7) -> 57700 | F7: =E7-G7 -> 29974 | G7: =SUMIFS(전체리스트!E:E,전체리스트!A:A,B7,전체리스트!C:C,D7) -> 27726 | H7: =G7*0.05 -> 1386.3 | I7: =G7-H7 -> 26339.7
B8: 코미코_NHN | C8: =VLOOKUP(B8,raw_a,2,0) -> 1월분 | D8: 꿈꾸는 먹잇감 | E8: =SUMIFS(전체리스트!D:D,전체리스트!A:A,B8,전체리스트!C:C,D8) -> 107800 | F8: =E8-G8 -> 39606 | G8: =SUMIFS(전체리스트!E:E,전체리스트!A:A,B8,전체리스트!C:C,D8) -> 68194 | H8: =G8*0.05 -> 3409.7 | I8: =G8-H8 -> 64784.3
B9: 코미코_NHN | C9: =VLOOKUP(B9,raw_a,2,0) -> 1월분 | D9: 꿰인 사이 | E9: =SUMIFS(전체리스트!D:D,전체리스트!A:A,B9,전체리스트!C:C,D9) -> 181100 | F9: =E9-G9 -> 91880 | G9: =SUMIFS(전체리스트!E:E,전체리스트!A:A,B9,전체리스트!C:C,D9) -> 89220 | H9: =G9*0.05 -> 4461 | I9: =G9-H9 -> 84759
B10: 코미코_NHN | C10: =VLOOKUP(B10,raw_a,2,0) -> 1월분 | D10: 너에게만 음성인식 | E10: =SUMIFS(전체리스트!D:D,전체리스트!A:A,B10,전체리스트!C:C,D10) -> 110800 | F10: =E10-G10 -> 54097 | G10: =SUMIFS(전체리스트!E:E,전체리스트!A:A,B10,전체리스트!C:C,D10) -> 56703 | H10: =G10*0.05 -> 2835.15 | I10: =G10-H10 -> 53867.85
B11: 코미코_NHN | C11: =VLOOKUP(B11,raw_a,2,0) -> 1월분 | D11: 대표님, 사모님이 도망가요 | E11: =SUMIFS(전체리스트!D:D,전체리스트!A:A,B11,전체리스트!C:C,D11) -> 1622700 | F11: =E11-G11 -> 774441 | G11: =SUMIFS(전체리스트!E:E,전체리스트!A:A,B11,전체리스트!C:C,D11) -> 848259 | H11: =G11*0.05 -> 42412.95 | I11: =G11-H11 -> 805846.05
B12: 코미코_NHN | C12: =VLOOKUP(B12,raw_a,2,0) -> 1월분 | D12: 대표님의 삐뚤어진 사랑 | E12: =SUMIFS(전체리스트!D:D,전체리스트!A:A,B12,전체리스트!C:C,D12) -> 2207500 | F12: =E12-G12 -> 1098481 | G12: =SUMIFS(전체리스트!E:E,전체리스트!A:A,B12,전체리스트!C:C,D12) -> 1109019 | H12: =G12*0.05 -> 55450.95 | I12: =G12-H12 -> 1053568.1
B13: 코미코_NHN | C13: =VLOOKUP(B13,raw_a,2,0) -> 1월분 | D13: 레벨업에 미친 의사 | E13: =SUMIFS(전체리스트!D:D,전체리스트!A:A,B13,전체리스트!C:C,D13) -> 76000 | F13: =E13-G13 -> 32544 | G13: =SUMIFS(전체리스트!E:E,전체리스트!A:A,B13,전체리스트!C:C,D13) -> 43456 | H13: =G13*0.05 -> 2172.8 | I13: =G13-H13 -> 41283.2
B14: 코미코_NHN | C14: =VLOOKUP(B14,raw_a,2,0) -> 1월분 | D14: 마녀 따위 안 할래요 | E14: =SUMIFS(전체리스트!D:D,전체리스트!A:A,B14,전체리스트!C:C,D14) -> 338400 | F14: =E14-G14 -> 123549 | G14: =SUMIFS(전체리스트!E:E,전체리스트!A:A,B14,전체리스트!C:C,D14) -> 214851 | H14: =G14*0.05 -> 10742.55 | I14: =G14-H14 -> 204108.45
B15: 코미코_NHN | C15: =VLOOKUP(B15,raw_a,2,0) -> 1월분 | D15: 만지고 싶어! | E15: =SUMIFS(전체리스트!D:D,전체리스트!A:A,B15,전체리스트!C:C,D15) -> 685000 | F15: =E15-G15 -> 320863 | G15: =SUMIFS(전체리스트!E:E,전체리스트!A:A,B15,전체리스트!C:C,D15) -> 364137 | H15: =G15*0.05 -> 18206.85 | I15: =G15-H15 -> 345930.15
B16: 코미코_NHN | C16: =VLOOKUP(B16,raw_a,2,0) -> 1월분 | D16: 멍멍이와 주인님 [완] | E16: =SUMIFS(전체리스트!D:D,전체리스트!A:A,B16,전체리스트!C:C,D16) -> 300 | F16: =E16-G16 -> 90 | G16: =SUMIFS(전체리스트!E:E,전체리스트!A:A,B16,전체리스트!C:C,D16) -> 210 | H16: =G16*0.05 -> 10.5 | I16: =G16-H16 -> 199.5
B17: 코미코_NHN | C17: =VLOOKUP(B17,raw_a,2,0) -> 1월분 | D17: 사랑과 우정 사이에서 (개정판) | E17: =SUMIFS(전체리스트!D:D,전체리스트!A:A,B17,전체리스트!C:C,D17) -> 92700 | F17: =E17-G17 -> 47286 | G17: =SUMIFS(전체리스트!E:E,전체리스트!A:A,B17,전체리스트!C:C,D17) -> 45414 | H17: =G17*0.05 -> 2270.7 | I17: =G17-H17 -> 43143.3
... B35: 코미코_NHN | C35: =VLOOKUP(B35,raw_a,2,0) -> 1월분 | D35: 호랑이 장가드는 날 [개정판] | E35: =SUMIFS(전체리스트!D:D,전체리스트!A:A,B35,전체리스트!C:C,D35) -> 156600 | F35: =E35-G35 -> 73080 | G35: =SUMIFS(전체리스트!E:E,전체리스트!A:A,B35,전체리스트!C:C,D35) -> 83520 | H35: =G35*0.05 -> 4176 | I35: =G35-H35 -> 79344
B36: 합계 | E36: =SUM(E6:E35) -> 18820970 | F36: =SUM(F6:F35) -> 8344072 | G36: =SUM(G6:G35) -> 10476898 | H36: =SUM(H6:H35) -> 523844.9 | I36: =SUM(I6:I35) -> 9953053.1 | J36: =SUM(J6:J35) -> 0

Sheet 포켓코믹스
B4: [RS 정산 기준]
B5: 사이트명 | C5: 매출월 | D5: 작품명 | E5: 소비자매출액 | F5: 유통사수수료 | G5: 스토리위즈매출액 | H5: 스토리위즈수익 | I5: 스토리숲 수익 | J5: 비고
B6: 포켓코믹스 | C6: =VLOOKUP(B6,raw_a,2,0) -> 12월분 | D6: 내 자기님이 로그인 하셨습니다 | E6: =SUMIFS(전체리스트!D:D,전체리스트!A:A,B6,전체리스트!C:C,D6) -> 1934436 | F6: =E6-G6 -> 0 | G6: =SUMIFS(전체리스트!E:E,전체리스트!A:A,B6,전체리스트!C:C,D6) -> 1934436 | H6: =G6*0.05 -> 96721.8 | I6: =G6-H6 -> 1837714.2
B7: 포켓코믹스 | C7: =VLOOKUP(B7,raw_a,2,0) -> 12월분 | D7: 사랑과 우정사이에서 | E7: =SUMIFS(전체리스트!D:D,전체리스트!A:A,B7,전체리스트!C:C,D7) -> 241642 | F7: =E7-G7 -> 0 | G7: =SUMIFS(전체리스트!E:E,전체리스트!A:A,B7,전체리스트!C:C,D7) -> 241642 | H7: =G7*0.05 -> 12082.1 | I7: =G7-H7 -> 229559.9
B8: 포켓코믹스 | C8: =VLOOKUP(B8,raw_a,2,0) -> 12월분 | D8: 옆집 최애 | E8: =SUMIFS(전체리스트!D:D,전체리스트!A:A,B8,전체리스트!C:C,D8) -> 93340 | F8: =E8-G8 -> 0 | G8: =SUMIFS(전체리스트!E:E,전체리스트!A:A,B8,전체리스트!C:C,D8) -> 93340 | H8: =G8*0.05 -> 4667 | I8: =G8-H8 -> 88673
B9: 포켓코믹스 | C9: =VLOOKUP(B9,raw_a,2,0) -> 12월분 | D9: 한번만 부탁해 | E9: =SUMIFS(전체리스트!D:D,전체리스트!A:A,B9,전체리스트!C:C,D9) -> 972534 | F9: =E9-G9 -> 0 | G9: =SUMIFS(전체리스트!E:E,전체리스트!A:A,B9,전체리스트!C:C,D9) -> 972534 | H9: =G9*0.05 -> 48626.7 | I9: =G9-H9 -> 923907.3
B10: 포켓코믹스 | C10: =VLOOKUP(B10,raw_a,2,0) -> 12월분 | D10: 아랫집 웬수 | E10: =SUMIFS(전체리스트!D:D,전체리스트!A:A,B10,전체리스트!C:C,D10) -> 151738 | F10: =E10-G10 -> 0 | G10: =SUMIFS(전체리스트!E:E,전체리스트!A:A,B10,전체리스트!C:C,D10) -> 151738 | H10: =G10*0.05 -> 7586.9 | I10: =G10-H10 -> 144151.1
B11: 포켓코믹스 | C11: =VLOOKUP(B11,raw_a,2,0) -> 12월분 | D11: 인 유어드림 | E11: =SUMIFS(전체리스트!D:D,전체리스트!A:A,B11,전체리스트!C:C,D11) -> 1686 | F11: =E11-G11 -> 0 | G11: =SUMIFS(전체리스트!E:E,전체리스트!A:A,B11,전체리스트!C:C,D11) -> 1686 | H11: =G11*0.05 -> 84.3 | I11: =G11-H11 -> 1601.7
B12: 합계 | E12: =SUM(E6:E11) -> 3395376 | F12: =SUM(F6:F11) -> 0 | G12: =SUM(G6:G11) -> 3395376 | H12: =SUM(H6:H11) -> 169768.8 | I12: =SUM(I6:I11) -> 3225607.2 | J12: =SUM(J6:J11) -> 0

Sheet 리디북스
B4: [RS 정산 기준]
B5: 사이트명 | C5: 매출월 | D5: 작품명 | E5: 소비자매출액 | F5: 유통사수수료 | G5: 스토리위즈매출액 | H5: 스토리위즈수익 | I5: 스토리숲 수익 | J5: 비고
B6: 리디북스 | C6: =VLOOKUP(B6,raw_a,2,0) -> 11~12월분 | D6: [e북]사랑과 우정 사이에서 | E6: =SUMIFS(전체리스트!D:D,전체리스트!A:A,B6,전체리스트!C:C,D6) -> 129000 | F6: =E6-G6 -> 38700 | G6: =SUMIFS(전체리스트!E:E,전체리스트!A:A,B6,전체리스트!C:C,D6) -> 90300 | H6: =G6*0.05 -> 4515 | I6: =G6-H6 -> 85785
B7: 리디북스 | C7: =VLOOKUP(B7,raw_a,2,0) -> 11~12월분 | D7: [e북]옆집 최애 | E7: =SUMIFS(전체리스트!D:D,전체리스트!A:A,B7,전체리스트!C:C,D7) -> 58800 | F7: =E7-G7 -> 17640 | G7: =SUMIFS(전체리스트!E:E,전체리스트!A:A,B7,전체리스트!C:C,D7) -> 41160 | H7: =G7*0.05 -> 2058 | I7: =G7-H7 -> 39102
B8: 리디북스 | C8: =VLOOKUP(B8,raw_a,2,0) -> 11~12월분 | D8: [e북]탑 배우의 이중생활 | E8: =SUMIFS(전체리스트!D:D,전체리스트!A:A,B8,전체리스트!C:C,D8) -> 30000 | F8: =E8-G8 -> 9000 | G8: =SUMIFS(전체리스트!E:E,전체리스트!A:A,B8,전체리스트!C:C,D8) -> 21000 | H8: =G8*0.05 -> 1050 | I8: =G8-H8 -> 19950
B9: 리디북스 | C9: =VLOOKUP(B9,raw_a,2,0) -> 11~12월분 | D9: 거짓말, 뱀파이어가 어디 있어? | E9: =SUMIFS(전체리스트!D:D,전체리스트!A:A,B9,전체리스트!C:C,D9) -> 48000 | F9: =E9-G9 -> 14400 | G9: =SUMIFS(전체리스트!E:E,전체리스트!A:A,B9,전체리스트!C:C,D9) -> 33600 | H9: =G9*0.05 -> 1680 | I9: =G9-H9 -> 31920
B10: 리디북스 | C10: =VLOOKUP(B10,raw_a,2,0) -> 11~12월분 | D10: 꿰인 사이 | E10: =SUMIFS(전체리스트!D:D,전체리스트!A:A,B10,전체리스트!C:C,D10) -> 837800 | F10: =E10-G10 -> 259224.95 | G10: =SUMIFS(전체리스트!E:E,전체리스트!A:A,B10,전체리스트!C:C,D10) -> 578575.05 | H10: =G10*0.05 -> 28928.752 | I10: =G10-H10 -> 549646.3
B11: 리디북스 | C11: =VLOOKUP(B11,raw_a,2,0) -> 11~12월분 | D11: 너에게만 음성인식 | E11: =SUMIFS(전체리스트!D:D,전체리스트!A:A,B11,전체리스트!C:C,D11) -> 84400 | F11: =E11-G11 -> 26070.4 | G11: =SUMIFS(전체리스트!E:E,전체리스트!A:A,B11,전체리스트!C:C,D11) -> 58329.6 | H11: =G11*0.05 -> 2916.48 | I11: =G11-H11 -> 55413.12
B12: 리디북스 | C12: =VLOOKUP(B12,raw_a,2,0) -> 11~12월분 | D12: 대표님, 사모님이 도망가요 | E12: =SUMIFS(전체리스트!D:D,전체리스트!A:A,B12,전체리스트!C:C,D12) -> 1141000 | F12: =E12-G12 -> 345325.42 | G12: =SUMIFS(전체리스트!E:E,전체리스트!A:A,B12,전체리스트!C:C,D12) -> 795674.58 | H12: =G12*0.05 -> 39783.729 | I12: =G12-H12 -> 755890.85
B13: 리디북스 | C13: =VLOOKUP(B13,raw_a,2,0) -> 11~12월분 | D13: 대표님의 삐뚤어진 사랑 | E13: =SUMIFS(전체리스트!D:D,전체리스트!A:A,B13,전체리스트!C:C,D13) -> 4829400 | F13: =E13-G13 -> 1482141.7 | G13: =SUMIFS(전체리스트!E:E,전체리스트!A:A,B13,전체리스트!C:C,D13) -> 3347258.3 | H13: =G13*0.05 -> 167362.92 | I13: =G13-H13 -> 3179895.4
B14: 리디북스 | C14: =VLOOKUP(B14,raw_a,2,0) -> 11~12월분 | D14: 마녀 따위 안 할래요 | E14: =SUMIFS(전체리스트!D:D,전체리스트!A:A,B14,전체리스트!C:C,D14) -> 28700 | F14: =E14-G14 -> 8610 | G14: =SUMIFS(전체리스트!E:E,전체리스트!A:A,B14,전체리스트!C:C,D14) -> 20090 | H14: =G14*0.05 -> 1004.5 | I14: =G14-H14 -> 19085.5
B15: 리디북스 | C15: =VLOOKUP(B15,raw_a,2,0) -> 11~12월분 | D15: 만지고 싶어! | E15: =SUMIFS(전체리스트!D:D,전체리스트!A:A,B15,전체리스트!C:C,D15) -> 136000 | F15: =E15-G15 -> 41427.2 | G15: =SUMIFS(전체리스트!E:E,전체리스트!A:A,B15,전체리스트!C:C,D15) -> 94572.8 | H15: =G15*0.05 -> 4728.64 | I15: =G15-H15 -> 89844.16
B16: 리디북스 | C16: =VLOOKUP(B16,raw_a,2,0) -> 11~12월분 | D16: 멍멍이와 주인님 | E16: =SUMIFS(전체리스트!D:D,전체리스트!A:A,B16,전체리스트!C:C,D16) -> 100 | F16: =E16-G16 -> 30 | G16: =SUMIFS(전체리스트!E:E,전체리스트!A:A,B16,전체리스트!C:C,D16) -> 70 | H16: =G16*0.05 -> 3.5 | I16: =G16-H16 -> 66.5
B17: 리디북스 | C17: =VLOOKUP(B17,raw_a,2,0) -> 11~12월분 | D17: 명판관 장평 | E17: =SUMIFS(전체리스트!D:D,전체리스트!A:A,B17,전체리스트!C:C,D17) -> 18800 | F17: =E17-G17 -> 5640 | G17: =SUMIFS(전체리스트!E:E,전체리스트!A:A,B17,전체리스트!C:C,D17) -> 13160 | H17: =G17*0.05 -> 658 | I17: =G17-H17 -> 12502
... B42: 리디북스 | C42: =VLOOKUP(B42,raw_a,2,0) -> 11~12월분 | D42: 호랑이 장가드는 날 [개정판] | E42: =SUMIFS(전체리스트!D:D,전체리스트!A:A,B42,전체리스트!C:C,D42) -> 85800 | F42: =E42-G42 -> 28260 | G42: =SUMIFS(전체리스트!E:E,전체리스트!A:A,B42,전체리스트!C:C,D42) -> 57540 | H42: =G42*0.05 -> 2877 | I42: =G42-H42 -> 54663
B43: 합계 | E43: =SUM(E6:E42) -> 11631900 | F43: =SUM(F6:F42) -> 3549561.1 | G43: =SUM(G6:G42) -> 8082338.9 | H43: =SUM(H6:H42) -> 404116.95 | I43: =SUM(I6:I42) -> 7678222 | J43: =SUM(J6:J42) -> 0

Sheet 조아라
B4: [RS 정산 기준]
B5: 사이트명 | C5: 매출월 | D5: 작품명 | E5: 소비자매출액 | F5: 유통사수수료 | G5: 스토리위즈매출액 | H5: 스토리위즈수익 | I5: 스토리숲 수익 | J5: 비고
B6: 조아라 | C6: =VLOOKUP(B6,raw_a,2,0) -> 1월분 | D6: 속도위반 대표님과 계약 아내 | E6: =SUMIFS(전체리스트!D:D,전체리스트!A:A,B6,전체리스트!C:C,D6) -> 120800 | F6: =E6-G6 -> 41072 | G6: =SUMIFS(전체리스트!E:E,전체리스트!A:A,B6,전체리스트!C:C,D6) -> 79728 | H6: =G6*0.05 -> 3986.4 | I6: =G6-H6 -> 75741.6
B7: 조아라 | C7: =VLOOKUP(B7,raw_a,2,0) -> 1월분 | D7: 꿰인 사이 | E7: =SUMIFS(전체리스트!D:D,전체리스트!A:A,B7,전체리스트!C:C,D7) -> 118500 | F7: =E7-G7 -> 40290 | G7: =SUMIFS(전체리스트!E:E,전체리스트!A:A,B7,전체리스트!C:C,D7) -> 78210 | H7: =G7*0.05 -> 3910.5 | I7: =G7-H7 -> 74299.5
B8: 조아라 | C8: =VLOOKUP(B8,raw_a,2,0) -> 1월분 | D8: 마녀 따위 안 할래요 | E8: =SUMIFS(전체리스트!D:D,전체리스트!A:A,B8,전체리스트!C:C,D8) -> 109800 | F8: =E8-G8 -> 37332 | G8: =SUMIFS(전체리스트!E:E,전체리스트!A:A,B8,전체리스트!C:C,D8) -> 72468 | H8: =G8*0.05 -> 3623.4 | I8: =G8-H8 -> 68844.6
B9: 조아라 | C9: =VLOOKUP(B9,raw_a,2,0) -> 1월분 | D9: 대표님의 삐뚤어진 사랑 | E9: =SUMIFS(전체리스트!D:D,전체리스트!A:A,B9,전체리스트!C:C,D9) -> 95400 | F9: =E9-G9 -> 32436 | G9: =SUMIFS(전체리스트!E:E,전체리스트!A:A,B9,전체리스트!C:C,D9) -> 62964 | H9: =G9*0.05 -> 3148.2 | I9: =G9-H9 -> 59815.8
B10: 조아라 | C10: =VLOOKUP(B10,raw_a,2,0) -> 1월분 | D10: 수렁 | E10: =SUMIFS(전체리스트!D:D,전체리스트!A:A,B10,전체리스트!C:C,D10) -> 86300 | F10: =E10-G10 -> 29342 | G10: =SUMIFS(전체리스트!E:E,전체리스트!A:A,B10,전체리스트!C:C,D10) -> 56958 | H10: =G10*0.05 -> 2847.9 | I10: =G10-H10 -> 54110.1
B11: 조아라 | C11: =VLOOKUP(B11,raw_a,2,0) -> 1월분 | D11: 만지고 싶어! | E11: =SUMIFS(전체리스트!D:D,전체리스트!A:A,B11,전체리스트!C:C,D11) -> 52000 | F11: =E11-G11 -> 17680 | G11: =SUMIFS(전체리스트!E:E,전체리스트!A:A,B11,전체리스트!C:C,D11) -> 34320 | H11: =G11*0.05 -> 1716 | I11: =G11-H11 -> 32604
B12: 조아라 | C12: =VLOOKUP(B12,raw_a,2,0) -> 1월분 | D12: 한번 해볼래? | E12: =SUMIFS(전체리스트!D:D,전체리스트!A:A,B12,전체리스트!C:C,D12) -> 24400 | F12: =E12-G12 -> 8296 | G12: =SUMIFS(전체리스트!E:E,전체리스트!A:A,B12,전체리스트!C:C,D12) -> 16104 | H12: =G12*0.05 -> 805.2 | I12: =G12-H12 -> 15298.8
B13: 조아라 | C13: =VLOOKUP(B13,raw_a,2,0) -> 1월분 | D13: 키스했으니 책임져 | E13: =SUMIFS(전체리스트!D:D,전체리스트!A:A,B13,전체리스트!C:C,D13) -> 12000 | F13: =E13-G13 -> 4080 | G13: =SUMIFS(전체리스트!E:E,전체리스트!A:A,B13,전체리스트!C:C,D13) -> 7920 | H13: =G13*0.05 -> 396 | I13: =G13-H13 -> 7524
B14: 조아라 | C14: =VLOOKUP(B14,raw_a,2,0) -> 1월분 | D14: 호랑이 장가드는 날 | E14: =SUMIFS(전체리스트!D:D,전체리스트!A:A,B14,전체리스트!C:C,D14) -> 9000 | F14: =E14-G14 -> 3060 | G14: =SUMIFS(전체리스트!E:E,전체리스트!A:A,B14,전체리스트!C:C,D14) -> 5940 | H14: =G14*0.05 -> 297 | I14: =G14-H14 -> 5643
B15: 조아라 | C15: =VLOOKUP(B15,raw_a,2,0) -> 1월분 | D15: 거짓말, 뱀파이어가 어디 있어? | E15: =SUMIFS(전체리스트!D:D,전체리스트!A:A,B15,전체리스트!C:C,D15) -> 7000 | F15: =E15-G15 -> 2380 | G15: =SUMIFS(전체리스트!E:E,전체리스트!A:A,B15,전체리스트!C:C,D15) -> 4620 | H15: =G15*0.05 -> 231 | I15: =G15-H15 -> 4389
B16: 조아라 | C16: =VLOOKUP(B16,raw_a,2,0) -> 1월분 | D16: 주작의 귀환 | E16: =SUMIFS(전체리스트!D:D,전체리스트!A:A,B16,전체리스트!C:C,D16) -> 6300 | F16: =E16-G16 -> 2142 | G16: =SUMIFS(전체리스트!E:E,전체리스트!A:A,B16,전체리스트!C:C,D16) -> 4158 | H16: =G16*0.05 -> 207.9 | I16: =G16-H16 -> 3950.1
B17: 조아라 | C17: =VLOOKUP(B17,raw_a,2,0) -> 1월분 | D17: 대표님, 사모님이 도망가요 | E17: =SUMIFS(전체리스트!D:D,전체리스트!A:A,B17,전체리스트!C:C,D17) -> 5100 | F17: =E17-G17 -> 1734 | G17: =SUMIFS(전체리스트!E:E,전체리스트!A:A,B17,전체리스트!C:C,D17) -> 3366 | H17: =G17*0.05 -> 168.3 | I17: =G17-H17 -> 3197.7
... B21: 조아라 | C21: =VLOOKUP(B21,raw_a,2,0) -> 1월분 | D21: 두근두근 호기심 컴퍼니 | E21: =SUMIFS(전체리스트!D:D,전체리스트!A:A,B21,전체리스트!C:C,D21) -> 400 | F21: =E21-G21 -> 136 | G21: =SUMIFS(전체리스트!E:E,전체리스트!A:A,B21,전체리스트!C:C,D21) -> 264 | H21: =G21*0.05 -> 13.2 | I21: =G21-H21 -> 250.8
B22: 합계 | E22: =SUM(E6:E21) -> 649800 | F22: =SUM(F6:F21) -> 220932 | G22: =SUM(G6:G21) -> 428868 | H22: =SUM(H6:H21) -> 21443.4 | I22: =SUM(I6:I21) -> 407424.6 | J22: =SUM(J6:J21) -> 0

Sheet 위코믹스_태국
G3: 3개월 평균
B4: [RS 정산 기준] | F4: 환율(THB) | G4: =VLOOKUP(B6,raw_a,6,0) -> 35.81
B5: 사이트명 | C5: 매출월 | D5: 작품명 | E5: 소비자매출액 | F5: 유통사수수료 | G5: 스토리위즈매출액 | H5: 스토리위즈수익 | I5: 스토리숲 수익 | J5: 비고
B6: 위코믹스 | C6: =VLOOKUP(B6,raw_a,2,0) -> 10월분 | D6: 츤데레 흥신소 | E6: =SUMIFS(전체리스트!D:D,전체리스트!A:A,B6,전체리스트!C:C,D6) -> 0 | G6: =SUMIFS(전체리스트!E:E,전체리스트!A:A,B6,전체리스트!C:C,D6) -> 0 | H6: =G6*0.05 -> 0 | I6: =G6-H6 -> 0
B7: 위코믹스 | C7: =VLOOKUP(B7,raw_a,2,0) -> 10월분 | D7: 탑배우의 이중생활 | E7: =SUMIFS(전체리스트!D:D,전체리스트!A:A,B7,전체리스트!C:C,D7) -> 0 | G7: =SUMIFS(전체리스트!E:E,전체리스트!A:A,B7,전체리스트!C:C,D7) -> 0 | H7: =G7*0.05 -> 0 | I7: =G7-H7 -> 0
B8: 위코믹스 | C8: =VLOOKUP(B8,raw_a,2,0) -> 10월분 | D8: 한 집 두 살림 | E8: =SUMIFS(전체리스트!D:D,전체리스트!A:A,B8,전체리스트!C:C,D8) -> 0 | G8: =SUMIFS(전체리스트!E:E,전체리스트!A:A,B8,전체리스트!C:C,D8) -> 0 | H8: =G8*0.05 -> 0 | I8: =G8-H8 -> 0
B9: 위코믹스 | C9: =VLOOKUP(B9,raw_a,2,0) -> 10월분 | D9: 슬기로운 생활 | E9: =SUMIFS(전체리스트!D:D,전체리스트!A:A,B9,전체리스트!C:C,D9) -> 0 | G9: =SUMIFS(전체리스트!E:E,전체리스트!A:A,B9,전체리스트!C:C,D9) -> 0 | H9: =G9*0.05 -> 0 | I9: =G9-H9 -> 0
B10: 위코믹스 | C10: =VLOOKUP(B10,raw_a,2,0) -> 10월분 | D10: 원고를 주세요! | E10: =SUMIFS(전체리스트!D:D,전체리스트!A:A,B10,전체리스트!C:C,D10) -> 0 | G10: =SUMIFS(전체리스트!E:E,전체리스트!A:A,B10,전체리스트!C:C,D10) -> 0 | H10: =G10*0.05 -> 0 | I10: =G10-H10 -> 0
B11: 위코믹스 | C11: =VLOOKUP(B11,raw_a,2,0) -> 10월분 | D11: 아랫집 웬수 | E11: =SUMIFS(전체리스트!D:D,전체리스트!A:A,B11,전체리스트!C:C,D11) -> 0 | G11: =SUMIFS(전체리스트!E:E,전체리스트!A:A,B11,전체리스트!C:C,D11) -> 0 | H11: =G11*0.05 -> 0 | I11: =G11-H11 -> 0
B12: 위코믹스 | C12: =VLOOKUP(B12,raw_a,2,0) -> 10월분 | D12: 말도 안되는 관계 | E12: =SUMIFS(전체리스트!D:D,전체리스트!A:A,B12,전체리스트!C:C,D12) -> 0 | G12: =SUMIFS(전체리스트!E:E,전체리스트!A:A,B12,전체리스트!C:C,D12) -> 0 | H12: =G12*0.05 -> 0 | I12: =G12-H12 -> 0
B13: 위코믹스 | C13: =VLOOKUP(B13,raw_a,2,0) -> 10월분 | D13: BL 패티쉬 단편선 모음 | E13: =SUMIFS(전체리스트!D:D,전체리스트!A:A,B13,전체리스트!C:C,D13) -> 0 | G13: =SUMIFS(전체리스트!E:E,전체리스트!A:A,B13,전체리스트!C:C,D13) -> 0 | H13: =G13*0.05 -> 0 | I13: =G13-H13 -> 0
B14: 위코믹스 | C14: =VLOOKUP(B14,raw_a,2,0) -> 10월분 | D14: 파쿠리인 내가 어시를! | E14: =SUMIFS(전체리스트!D:D,전체리스트!A:A,B14,전체리스트!C:C,D14) -> 0 | G14: =SUMIFS(전체리스트!E:E,전체리스트!A:A,B14,전체리스트!C:C,D14) -> 0 | H14: =G14*0.05 -> 0 | I14: =G14-H14 -> 0
B15: 합계 | E15: =SUM(E6:E14) -> 0 | F15: =SUM(F6:F14) -> 0 | G15: =SUM(G6:G14) -> 0 | H15: =SUM(H6:H14) -> 0 | I15: =SUM(I6:I14) -> 0 | J15: =SUM(J6:J14) -> 0

Sheet 태피툰_영어
B4: [RS 정산 기준]
B5: 사이트명 | C5: 매출월 | D5: 작품명 | E5: 소비자매출액 | F5: 유통사수수료 | G5: 스토리위즈매출액 | H5: 스토리위즈수익 | I5: 스토리숲 수익 | J5: 비고
B6: 태피툰 | C6: =VLOOKUP(B6,raw_a,2,0) -> 11월분 | D6: 인유어드림 | E6: =SUMIFS(전체리스트!D:D,전체리스트!A:A,B6,전체리스트!C:C,D6) -> 1440 | F6: =E6-G6 -> 0 | G6: =SUMIFS(전체리스트!E:E,전체리스트!A:A,B6,전체리스트!C:C,D6) -> 1440 | H6: =G6*0.05 -> 72 | I6: =G6-H6 -> 1368
B7: 태피툰 | C7: =VLOOKUP(B7,raw_a,2,0) -> 11월분 | D7: 옆집최애 | E7: =SUMIFS(전체리스트!D:D,전체리스트!A:A,B7,전체리스트!C:C,D7) -> 240780 | F7: =E7-G7 -> 0 | G7: =SUMIFS(전체리스트!E:E,전체리스트!A:A,B7,전체리스트!C:C,D7) -> 240780 | H7: =G7*0.05 -> 12039 | I7: =G7-H7 -> 228741
B8: 태피툰 | C8: =VLOOKUP(B8,raw_a,2,0) -> 11월분 | D8: 사랑과우정사이에서 | E8: =SUMIFS(전체리스트!D:D,전체리스트!A:A,B8,전체리스트!C:C,D8) -> 171540 | F8: =E8-G8 -> 0 | G8: =SUMIFS(전체리스트!E:E,전체리스트!A:A,B8,전체리스트!C:C,D8) -> 171540 | H8: =G8*0.05 -> 8577 | I8: =G8-H8 -> 162963
B9: 태피툰 | C9: =VLOOKUP(B9,raw_a,2,0) -> 11월분 | D9: 내자기님이로그인하셨습니다 | E9: =SUMIFS(전체리스트!D:D,전체리스트!A:A,B9,전체리스트!C:C,D9) -> 9186300 | F9: =E9-G9 -> 0 | G9: =SUMIFS(전체리스트!E:E,전체리스트!A:A,B9,전체리스트!C:C,D9) -> 9186300 | H9: =G9*0.05 -> 459315 | I9: =G9-H9 -> 8726985
