Workbook

Sheet 합계
B2: ■ 컨텐츠헤라 (만화판권) 스토리위즈 정산서
B4: 사이트명 | C4: 소비자매출액 | D4: 유통사수수료 | E4: 스토리위즈매출액 | F4: 스토리위즈수익 | G4: 컨텐츠헤라 수익 | H4: 비고 | J4: 선지급금 | K4: =250000000+7945000+513560000 -> 771505000
B5: 네이버(11월) | C5: =SUM('네이버 11월'!AT8) -> 5000 | D5: =SUM(C5*0.3) -> 1500 | E5: =SUM(C5-D5) -> 3500 | F5: =E5*20% -> 700 | G5: =E5*80% -> 2800 | J5: 목표 프로젝트 수익 | K5: =330000000+7945000+513560000+144110000 -> 995615000
B6: 엠유(11월) | C6: 0 | D6: =SUM(C6*0.4) -> 0 | E6: =SUM(C6-D6) -> 0 | F6: =E6*20% -> 0 | G6: =E6*80% -> 0 | J6: 월별 회수금 (스토리위즈수익)
B7: 미스터블루(11월) | C7: =SUM(미스터블루_11월!AJ9) -> 400 | D7: =SUM(C7*0.4) -> 160 | E7: =SUM(C7-D7) -> 240 | F7: =E7*20% -> 48 | G7: =E7*80% -> 192 | J7: 2018. 11 | K7: 3039189
B8: 원스토어(11월) | C8: =SUM(원스토어_11월!W4) -> 1000 | D8: =SUM(C8*0.3) -> 300 | E8: =SUM(C8-D8) -> 700 | F8: =E8*20% -> 140 | G8: =E8*80% -> 560 | J8: 2018. 12 | K8: 4024753
B9: 봄툰(11월) | C9: 0 | D9: 0 | E9: 0 | F9: =E9*20% -> 0 | G9: =E9*80% -> 0 | J9: 2018년 합계 | K9: =SUM(K7:K8) -> 7063942
B10: 리디(11월) | C10: =SUM(리디_11월!O14,리디_11월!L14) -> 1000 | D10: =SUM(C10*0.3) -> 300 | E10: =SUM(C10-D10) -> 700 | F10: =E10*20% -> 140 | G10: =E10*80% -> 560 | J10: 2019. 01 | K10: 3785763
B11: 카카오(11월) | C11: 0 | D11: =SUM(C11-E11) -> 0 | E11: =SUM(C11*0.55) -> 0 | F11: =E11*20% -> 0 | G11: =E11*80% -> 0 | J11: 2019. 02 | K11: 2479364
B12: 레진(11월) | C12: 0 | D12: =SUM(C12-E12) -> 0 | E12: 0 | F12: =E12*20% -> 0 | G12: =E12*80% -> 0 | J12: 2019. 03 | K12: 1382094
B13: 알라딘(11월) | C13: =SUM(알라딘_11월!F5) -> 4000 | D13: =SUM(C13*0.3) -> 1200 | E13: =SUM(C13-D13) -> 2800 | F13: =E13*20% -> 560 | G13: =E13*80% -> 2240 | J13: 2019. 04 | K13: 836219
B14: 카카오_스토리위즈 | E14: ='카카오페이지 SW 1월'!AP10+'카카오페이지 SW 1월'!AP18 -> 3517155 | F14: =E14*20% -> 703431 | G14: =E14*80% -> 2813724 | H14: 스토리위즈 계정으로 유통 | J14: 2019. 05 | K14: 292844
B15: 카카오_스토리위즈(회귀) | E15: ='카카오페이지(회귀) SW 1월'!C16 -> 12948515 | F15: =E15*20% -> 2589703 | G15: =E15*80% -> 10358812 | H15: 스토리위즈 계정으로 유통 | J15: 2019. 06 | K15: 317230
B16: 카카오웹툰_동시연재 | E16: ='카카오웹툰(동시연재)SW 1월'!Z4 -> 1862306 | F16: =E16*20% -> 372461.2 | G16: =E16*80% -> 1489844.8 | H16: 스토리위즈 계정으로 유통 | J16: 2019. 07 | K16: 237412
B17: 네이버_스토리위즈 | E17: ='네이버시리즈 SW 1월'!AW16 -> 742300.6 | F17: =E17*20% -> 148460.12 | G17: =E17*80% -> 593840.48 | H17: 스토리위즈 계정으로 유통 | J17: 2019. 08 | K17: 179948
B18: 네이버_글로벌 | E18: ='네이버(북미)SW 01월'!C7 -> 481595.45 | F18: =E18*20% -> 96319.091 | G18: =E18*80% -> 385276.36 | H18: 스토리위즈 계정으로 유통 | J18: 2019. 09 | K18: 125662
B19: 콰이콴(마딸)_스토리위즈 | D19: =SUM(C19*0.3) -> 0 | E19: ='콰이칸(마딸)SW 01월'!D17 -> 6604665.7 | F19: =E19*20% -> 1320933.1 | G19: =E19*80% -> 5283732.5 | H19: 스토리위즈 계정으로 유통 | J19: 2019. 10 | K19: 522544
B20: 콰이콴(옹주)_스토리위즈 | E20: ='콰이칸(옹주)SW 01월'!D15 -> 28600.981 | F20: =E20*20% -> 5720.1962 | G20: =E20*80% -> 22880.785 | H20: 스토리위즈 계정으로 유통 | J20: 2019. 11 | K20: 622018
B21: 태국코미코_스토리위즈 | E21: ='태국코미코SW 01월'!D14 -> 1609908.6 | F21: =E21*20% -> 321981.72 | G21: =E21*80% -> 1287926.9 | H21: 스토리위즈 계정으로 유통 | J21: 2019.12 | K21: 102649273
B22: 태피툰_스토리위즈 | D22: =SUM(C22*0.3) -> 0 | E22: ='태피툰SW 01월'!C5 -> 10430820 | F22: =E22*20% -> 2086164 | G22: =E22*80% -> 8344656 | H22: 스토리위즈 계정으로 유통_과세 | J22: 2019년 합계 | K22: =SUM(K10:K21) -> 113430371
B23: 델리툰(프)_스토리위즈 | E23: ='델리툰(프)SW 01월'!C8 -> 0 | F23: =E23*20% -> 0 | G23: =E23*80% -> 0 | H23: 스토리위즈 계정으로 유통_과세 | J23: 2020. 01 | K23: 27480766
B24: 델리툰(독)_스토리위즈 | D24: =SUM(C24*0.3) -> 0 | E24: ='델리툰(독)SW 01월'!C7 -> 472861 | F24: =E24*20% -> 94572.2 | G24: =E24*80% -> 378288.8 | H24: 스토리위즈 계정으로 유통_과세 | J24: 2020. 02 | K24: 16627659
B25: 코믹툰(베)_스토리위즈 | E25: ='코믹툰(베트남)SW 01월'!C6 -> 0 | F25: =E25*20% -> 0 | G25: =E25*80% -> 0 | H25: 스토리위즈 계정으로 유통_과세 | J25: 2020. 03 | K25: 14851424
B26: 카카페(회귀/타파스)_스토리위즈 | E26: ='카카페_회귀(타파스)SW 01월'!C6 -> 8500000 | F26: =E26*20% -> 1700000 | G26: =E26*80% -> 6800000 | H26: 스토리위즈 계정으로 유통_과세 | J26: 2020. 04 | K26: 62781192
B27: 카카페(인니)_스토리위즈 | D27: 0 | E27: ='카카페(인니)SW 01월'!C6 -> 244488 | F27: =E27*20% -> 48897.6 | G27: =E27*80% -> 195590.4 | H27: 스토리위즈 계정으로 유통_과세 | J27: 2020. 05 | K27: 17087690
B28: 합계 | C28: =SUM(C5:C27) -> 11400 | D28: =SUM(D5:D27) -> 3460 | E28: =SUM(E5:E13) -> 7940 | F28: =ROUND(SUM(F5:F27),0) -> 9490231 | G28: =ROUND(SUM(G5:G27),0) -> 37960925 | J28: 2020. 06 | K28: 31215077
J29: 2020. 07 | K29: 8348200
B30: 구분 | D30: 공급가액 | E30: 부가세 | F30: 합계 | J30: 2020. 08 | K30: 37449637
B31: 스토리위즈-컨헤라 매출 계산서 발행 | D31: =E28 -> 7940 | E31: 0 | F31: =D31 -> 7940 | J31: 2020. 09 | K31: 20076116
B32: 컨헤라-스토리위즈 계산서 발행 | D32: =G28-G22-G23-G27-G24-G25-G26 -> 22242390 | E32: 0 | F32: =D32 -> 22242390 | J32: 2020. 10 | K32: 12892628
B33: 컨헤라-스토리위즈 세금계산서 발행(과세) | D33: =G22+G23+G27+G24+G25+G26 -> 15718535 | E33: =ROUND(D33*10%,0) -> 1571854 | F33: =D33+E33 -> 17290389 | J33: 2020. 11 | K33: 29886560
B34: 스토리위즈-컨헤라 지급 금액 | D34: =D32+D33-D31 -> 37952985 | E34: =SUM(E31:E33) -> 1571854 | F34: =D34+E34 -> 39524839 | J34: 2020. 12 | K34: 10414396
J35: 2020년 합계 | K35: =SUM(K23:K34) -> 289111345
J36: 2021.01 | K36: 15631969
J37: 2021.02 | K37: 32703460
J38: 2021.03 | K38: 21027429
J39: 2021.04 | K39: 16592104
J40: 2021.05 | K40: 32166481
J41: 2021.06 | K41: 26127277
J42: 2021.07 | K42: 23416928
...

Sheet 카카오페이지 SW 1월
A1: 특별/일반 | B1: 사업자명 | C1: 사업자번호 | D1: 발행자명 | E1: 계약UID | F1: 계약유형 | G1: 계약(과/면세) | H1: 당월신규계약여부 | I1: 카테고리 | J1: 시리즈ID | K1: 시리즈명 | L1: 발행자가 부여하는 코드 | M1: 레이블 | N1: 작가명 | O1: ISBN(유/무) | P1: CP정산율_안드로이드/이벤트캐시 | Q1: CP정산율_iOS | R1: 이용권 종류 | S1: 이용권 금액 | T1: 캐시_합계 | U1: 캐시_CPP | V1: 캐시_CPI | W1: 캐시_CP1 | X1: 캐시_CP2 | Y1: 캐시_CP3 | Z1: 캐시_CP7 | AA1: 캐시_CP8 | AB1: 캐시_CP9 | AC1: 캐시_이벤트캐시 | AD1: 원화_합계 | AE1: 원화_CPP | AF1: 원화_CPI | AG1: 원화_CP1 | AH1: 원화_CP2 | AI1: 원화_CP3 | AJ1: 원화_CP7 | AK1: 원화_CP8 | AL1: 원화_CP9 | AM1: 원화_이벤트캐시 | AN1: 공급가액 | AO1: 부가세 | AP1: 공급대가
A2: 특별계약 | B2: 주식회사 스토리위즈 | C2: 3828601768 | D2: storywiz | E2: 1944.0 | F2: 선투자 | G2: 면세 | H2: N | I2: 만화 | J2: 53361105 | K2: 마왕의 딸로 태어났습니다 | N2: 은민,여울 | O2: Y | P2: 0.55 | Q2: 0.55 | R2: 단일 이용권 | S2: 400 | T2: 126400 | U2: 93100 | V2: 0 | W2: 0 | X2: 0 | Y2: 0 | Z2: 4800 | AA2: 0 | AB2: 0 | AC2: 28500 | AD2: 126880 | AE2: 93100 | AF2: 0 | AG2: 0 | AH2: 0 | AI2: 0 | AJ2: 5280 | AK2: 0 | AL2: 0 | AM2: 28500 | AN2: 69784 | AO2: 0 | AP2: 69784
A3: 특별계약 | B3: 주식회사 스토리위즈 | C3: 3828601768 | D3: storywiz | E3: 1944.0 | F3: 선투자 | G3: 면세 | H3: N | I3: 만화 | J3: 53361105 | K3: 마왕의 딸로 태어났습니다 | N3: 은민,여울 | O3: Y | P3: 0.55 | Q3: 0.55 | R3: 시리즈 이용권 패키지 | S3: 3600 | T3: 97200 | U3: 73600 | V3: 0 | W3: 0 | X3: 0 | Y3: 0 | Z3: 10800 | AA3: 0 | AB3: 0 | AC3: 12800 | AD3: 98280 | AE3: 73600 | AF3: 0 | AG3: 0 | AH3: 0 | AI3: 0 | AJ3: 11880 | AK3: 0 | AL3: 0 | AM3: 12800 | AN3: 54054 | AO3: 0 | AP3: 54054
A4: 특별계약 | B4: 주식회사 스토리위즈 | C4: 3828601768 | D4: storywiz | E4: 1944.0 | F4: 선투자 | G4: 면세 | H4: N | I4: 만화 | J4: 53361105 | K4: 마왕의 딸로 태어났습니다 | N4: 은민,여울 | O4: Y | P4: 0.55 | Q4: 0.55 | R4: 시리즈 이용권 패키지 | S4: 10800 | T4: 54000 | U4: 21100 | V4: 0 | W4: 0 | X4: 0 | Y4: 0 | Z4: 32400 | AA4: 0 | AB4: 0 | AC4: 500 | AD4: 57240 | AE4: 21100 | AF4: 0 | AG4: 0 | AH4: 0 | AI4: 0 | AJ4: 35640 | AK4: 0 | AL4: 0 | AM4: 500 | AN4: 31482 | AO4: 0 | AP4: 31482
A5: 특별계약 | B5: 주식회사 스토리위즈 | C5: 3828601768 | D5: storywiz | E5: 1944.0 | F5: 선투자 | G5: 면세 | H5: N | I5: 만화 | J5: 53361105 | K5: 마왕의 딸로 태어났습니다 | N5: 은민,여울 | O5: Y | P5: 0.55 | Q5: 0.55 | R5: 시리즈 이용권 패키지 | S5: 18000 | T5: 75200 | U5: 62200 | V5: 0 | W5: 0 | X5: 0 | Y5: 0 | Z5: 0 | AA5: 0 | AB5: 0 | AC5: 13000 | AD5: 75200 | AE5: 62200 | AF5: 0 | AG5: 0 | AH5: 0 | AI5: 0 | AJ5: 0 | AK5: 0 | AL5: 0 | AM5: 13000 | AN5: 41360 | AO5: 0 | AP5: 41360
A6: 특별계약 | B6: 주식회사 스토리위즈 | C6: 3828601768 | D6: storywiz | E6: 1944.0 | F6: 선투자 | G6: 면세 | H6: N | I6: 만화 | J6: 53361105 | K6: 마왕의 딸로 태어났습니다 | N6: 은민,여울 | O6: Y | P6: 0.55 | Q6: 0.55 | R6: 단일 대여 이용권 | S6: 200 | T6: 2843400 | U6: 1296300 | V6: 0 | W6: 0 | X6: 0 | Y6: 70370 | Z6: 96130 | AA6: 0 | AB6: 0 | AC6: 1380600 | AD6: 2867087 | AE6: 1296300 | AF6: 0 | AG6: 0 | AH6: 0 | AI6: 84444 | AJ6: 105743 | AK6: 0 | AL6: 0 | AM6: 1380600 | AN6: 1576898 | AO6: 0 | AP6: 1576898
A7: 특별계약 | B7: 주식회사 스토리위즈 | C7: 3828601768 | D7: storywiz | E7: 1944.0 | F7: 선투자 | G7: 면세 | H7: N | I7: 만화 | J7: 53361105 | K7: 마왕의 딸로 태어났습니다 | N7: 은민,여울 | O7: Y | P7: 0.55 | Q7: 0.55 | R7: 시리즈 대여 이용권 패키지 | S7: 1800 | T7: 1451000 | U7: 1088400 | V7: 0 | W7: 0 | X7: 0 | Y7: 16100 | Z7: 160400 | AA7: 0 | AB7: 0 | AC7: 186100 | AD7: 1470260 | AE7: 1088400 | AF7: 0 | AG7: 0 | AH7: 0 | AI7: 19320 | AJ7: 176440 | AK7: 0 | AL7: 0 | AM7: 186100 | AN7: 808643 | AO7: 0 | AP7: 808643
A8: 특별계약 | B8: 주식회사 스토리위즈 | C8: 3828601768 | D8: storywiz | E8: 1944.0 | F8: 선투자 | G8: 면세 | H8: N | I8: 만화 | J8: 53361105 | K8: 마왕의 딸로 태어났습니다 | N8: 은민,여울 | O8: Y | P8: 0.55 | Q8: 0.55 | R8: 시리즈 대여 이용권 패키지 | S8: 5400 | T8: 562800 | U8: 488300 | V8: 0 | W8: 0 | X8: 0 | Y8: -4200 | Z8: 24800 | AA8: 0 | AB8: 0 | AC8: 53900 | AD8: 564440 | AE8: 488300 | AF8: 0 | AG8: 0 | AH8: 0 | AI8: -5040 | AJ8: 27280 | AK8: 0 | AL8: 0 | AM8: 53900 | AN8: 310442 | AO8: 0 | AP8: 310442
A9: 특별계약 | B9: 주식회사 스토리위즈 | C9: 3828601768 | D9: storywiz | E9: 1944.0 | F9: 선투자 | G9: 면세 | H9: N | I9: 만화 | J9: 53361105 | K9: 마왕의 딸로 태어났습니다 | N9: 은민,여울 | O9: Y | P9: 0.55 | Q9: 0.55 | R9: 시리즈 대여 이용권 패키지 | S9: 9000 | T9: 678600 | U9: 484300 | V9: 0 | W9: 0 | X9: 0 | Y9: 600 | Z9: 172200 | AA9: 0 | AB9: 0 | AC9: 21500 | AD9: 695940 | AE9: 484300 | AF9: 0 | AG9: 0 | AH9: 0 | AI9: 720 | AJ9: 189420 | AK9: 0 | AL9: 0 | AM9: 21500 | AN9: 382767 | AO9: 0 | AP9: 382767
AD10: =SUM(AD2:AD9) -> 5955327 | AP10: =SUM(AP2:AP9) -> 3275430
A12: 특별/일반 | B12: 사업자명 | C12: 사업자번호 | D12: 발행자명 | E12: 계약UID | F12: 계약유형 | G12: 계약(과/면세) | H12: 당월신규계약여부 | I12: 카테고리 | J12: 시리즈ID | K12: 시리즈명 | L12: 발행자가 부여하는 코드 | M12: 레이블 | N12: 작가명 | O12: ISBN(유/무) | P12: CP정산율_안드로이드/이벤트캐시 | Q12: CP정산율_iOS | R12: 이용권 종류 | S12: 이용권 금액 | T12: 캐시_합계 | U12: 캐시_CPP | V12: 캐시_CPI | W12: 캐시_CP1 | X12: 캐시_CP2 | Y12: 캐시_CP3 | Z12: 캐시_CP7 | AA12: 캐시_CP8 | AB12: 캐시_CP9 | AC12: 캐시_이벤트캐시 | AD12: 원화_합계 | AE12: 원화_CPP | AF12: 원화_CPI | AG12: 원화_CP1 | AH12: 원화_CP2 | AI12: 원화_CP3 | AJ12: 원화_CP7 | AK12: 원화_CP8 | AL12: 원화_CP9 | AM12: 원화_이벤트캐시 | AN12: 공급가액 | AO12: 부가세 | AP12: 공급대가
A13: 특별계약 | B13: 주식회사 스토리위즈 | C13: 3828601768 | D13: storywiz | E13: 1944.0 | F13: 선투자 | G13: 면세 | H13: N | I13: 만화 | J13: 53361778 | K13: 옹주의 호위무사 | N13: 정훈,수국 | O13: Y | P13: 0.55 | Q13: 0.55 | R13: 단일 이용권 | S13: 400 | T13: 800 | U13: 300 | V13: 0 | W13: 0 | X13: 0 | Y13: 0 | Z13: 0 | AA13: 0 | AB13: 0 | AC13: 500 | AD13: 800 | AE13: 300 | AF13: 0 | AG13: 0 | AH13: 0 | AI13: 0 | AJ13: 0 | AK13: 0 | AL13: 0 | AM13: 500 | AN13: 440 | AO13: 0 | AP13: 440
A14: 특별계약 | B14: 주식회사 스토리위즈 | C14: 3828601768 | D14: storywiz | E14: 1944.0 | F14: 선투자 | G14: 면세 | H14: N | I14: 만화 | J14: 53361778 | K14: 옹주의 호위무사 | N14: 정훈,수국 | O14: Y | P14: 0.55 | Q14: 0.55 | R14: 단일 대여 이용권 | S14: 200 | T14: 193400 | U14: 74650 | V14: 0 | W14: 0 | X14: 0 | Y14: 0 | Z14: 2200 | AA14: 0 | AB14: 0 | AC14: 116550 | AD14: 193620 | AE14: 74650 | AF14: 0 | AG14: 0 | AH14: 0 | AI14: 0 | AJ14: 2420 | AK14: 0 | AL14: 0 | AM14: 116550 | AN14: 106491 | AO14: 0 | AP14: 106491
A15: 특별계약 | B15: 주식회사 스토리위즈 | C15: 3828601768 | D15: storywiz | E15: 1944.0 | F15: 선투자 | G15: 면세 | H15: N | I15: 만화 | J15: 53361778 | K15: 옹주의 호위무사 | N15: 정훈,수국 | O15: Y | P15: 0.55 | Q15: 0.55 | R15: 시리즈 대여 이용권 패키지 | S15: 1800 | T15: 177600 | U15: 150300 | V15: 0 | W15: 0 | X15: 0 | Y15: 0 | Z15: 10800 | AA15: 0 | AB15: 0 | AC15: 16500 | AD15: 178680 | AE15: 150300 | AF15: 0 | AG15: 0 | AH15: 0 | AI15: 0 | AJ15: 11880 | AK15: 0 | AL15: 0 | AM15: 16500 | AN15: 98274 | AO15: 0 | AP15: 98274
A16: 특별계약 | B16: 주식회사 스토리위즈 | C16: 3828601768 | D16: storywiz | E16: 1944.0 | F16: 선투자 | G16: 면세 | H16: N | I16: 만화 | J16: 53361778 | K16: 옹주의 호위무사 | N16: 정훈,수국 | O16: Y | P16: 0.55 | Q16: 0.55 | R16: 시리즈 대여 이용권 패키지 | S16: 5400 | T16: 48400 | U16: 48100 | V16: 0 | W16: 0 | X16: 0 | Y16: 0 | Z16: 0 | AA16: 0 | AB16: 0 | AC16: 300 | AD16: 48400 | AE16: 48100 | AF16: 0 | AG16: 0 | AH16: 0 | AI16: 0 | AJ16: 0 | AK16: 0 | AL16: 0 | AM16: 300 | AN16: 26620 | AO16: 0 | AP16: 26620
A17: 특별계약 | B17: 주식회사 스토리위즈 | C17: 3828601768 | D17: storywiz | E17: 1944.0 | F17: 선투자 | G17: 면세 | H17: N | I17: 만화 | J17: 53361778 | K17: 옹주의 호위무사 | N17: 정훈,수국 | O17: Y | P17: 0.55 | Q17: 0.55 | R17: 시리즈 대여 이용권 패키지 | S17: 9000 | T17: 18000 | U17: 17300 | V17: 0 | W17: 0 | X17: 0 | Y17: 0 | Z17: 0 | AA17: 0 | AB17: 0 | AC17: 700 | AD17: 18000 | AE17: 17300 | AF17: 0 | AG17: 0 | AH17: 0 | AI17: 0 | AJ17: 0 | AK17: 0 | AL17: 0 | AM17: 700 | AN17: 9900 | AO17: 0 | AP17: 9900
AP18: =SUM(AP13:AP17) -> 241725

Sheet 카카오페이지(회귀) SW 1월
A1: 특별/일반 | B1: 사업자명 | C1: 사업자번호 | D1: 발행자명 | E1: 계약UID | F1: 계약유형 | G1: 계약(과/면세) | H1: 당월신규계약여부 | I1: 카테고리 | J1: 시리즈ID | K1: 시리즈명 | L1: 발행자가 부여하는 코드 | M1: 레이블 | N1: 작가명 | O1: ISBN(유/무) | P1: CP정산율_안드로이드/이벤트캐시 | Q1: CP정산율_iOS | R1: 이용권 종류 | S1: 이용권 금액 | T1: 캐시_합계 | U1: 캐시_CPP | V1: 캐시_CPI | W1: 캐시_CP1 | X1: 캐시_CP2 | Y1: 캐시_CP3 | Z1: 캐시_CP7 | AA1: 캐시_CP8 | AB1: 캐시_CP9 | AC1: 캐시_이벤트캐시 | AD1: 원화_합계 | AE1: 원화_CPP | AF1: 원화_CPI | AG1: 원화_CP1 | AH1: 원화_CP2 | AI1: 원화_CP3 | AJ1: 원화_CP7 | AK1: 원화_CP8 | AL1: 원화_CP9 | AM1: 원화_이벤트캐시 | AN1: 공급가액 | AO1: 부가세 | AP1: 공급대가
A2: 특별계약 | B2: 주식회사 스토리위즈 | C2: 3828601768 | D2: storywiz | E2: 2531.0 | F2: 선투자 | G2: 면세 | H2: N | I2: 만화 | J2: 57928448 | K2: 회귀의 전설 | N2: 송진우,김광수 | O2: Y | P2: 0.55 | Q2: 0.55 | R2: 단일 이용권 | S2: 400 | T2: 382800 | U2: 273700 | V2: 0 | W2: 0 | X2: 0 | Y2: 400 | Z2: 14400 | AA2: 0 | AB2: 0 | AC2: 94300 | AD2: 384320 | AE2: 273700 | AF2: 0 | AG2: 0 | AH2: 0 | AI2: 480 | AJ2: 15840 | AK2: 0 | AL2: 0 | AM2: 94300 | AN2: 211376 | AO2: 0 | AP2: 211376
A3: 특별계약 | B3: 주식회사 스토리위즈 | C3: 3828601768 | D3: storywiz | E3: 2531.0 | F3: 선투자 | G3: 면세 | H3: N | I3: 만화 | J3: 57928448 | K3: 회귀의 전설 | N3: 송진우,김광수 | O3: Y | P3: 0.55 | Q3: 0.55 | R3: 시리즈 이용권 패키지 | S3: 3600 | T3: 414800 | U3: 342600 | V3: 0 | W3: 0 | X3: 0 | Y3: 0 | Z3: 14400 | AA3: 0 | AB3: 0 | AC3: 57800 | AD3: 416240 | AE3: 342600 | AF3: 0 | AG3: 0 | AH3: 0 | AI3: 0 | AJ3: 15840 | AK3: 0 | AL3: 0 | AM3: 57800 | AN3: 228932 | AO3: 0 | AP3: 228932
A4: 특별계약 | B4: 주식회사 스토리위즈 | C4: 3828601768 | D4: storywiz | E4: 2531.0 | F4: 선투자 | G4: 면세 | H4: N | I4: 만화 | J4: 57928448 | K4: 회귀의 전설 | N4: 송진우,김광수 | O4: Y | P4: 0.55 | Q4: 0.55 | R4: 시리즈 이용권 패키지 | S4: 10800 | T4: 248400 | U4: 234500 | V4: 0 | W4: 0 | X4: 0 | Y4: 0 | Z4: 10800 | AA4: 0 | AB4: 0 | AC4: 3100 | AD4: 249480 | AE4: 234500 | AF4: 0 | AG4: 0 | AH4: 0 | AI4: 0 | AJ4: 11880 | AK4: 0 | AL4: 0 | AM4: 3100 | AN4: 137214 | AO4: 0 | AP4: 137214
A5: 특별계약 | B5: 주식회사 스토리위즈 | C5: 3828601768 | D5: storywiz | E5: 2531.0 | F5: 선투자 | G5: 면세 | H5: N | I5: 만화 | J5: 57928448 | K5: 회귀의 전설 | N5: 송진우,김광수 | O5: Y | P5: 0.55 | Q5: 0.55 | R5: 시리즈 이용권 패키지 | S5: 18000 | T5: 316400 | U5: 284900 | V5: 0 | W5: 0 | X5: 0 | Y5: 600 | Z5: 17400 | AA5: 0 | AB5: 0 | AC5: 13500 | AD5: 318260 | AE5: 284900 | AF5: 0 | AG5: 0 | AH5: 0 | AI5: 720 | AJ5: 19140 | AK5: 0 | AL5: 0 | AM5: 13500 | AN5: 175043 | AO5: 0 | AP5: 175043
A6: 특별계약 | B6: 주식회사 스토리위즈 | C6: 3828601768 | D6: storywiz | E6: 2531.0 | F6: 선투자 | G6: 면세 | H6: N | I6: 만화 | J6: 57928448 | K6: 회귀의 전설 | N6: 송진우,김광수 | O6: Y | P6: 0.55 | Q6: 0.55 | R6: 단일 대여 이용권 | S6: 200 | T6: 13236800 | U6: 7197060 | V6: 0 | W6: 0 | X6: 1200 | Y6: 140950 | Z6: 486790 | AA6: 0 | AB6: 0 | AC6: 5410800 | AD6: 13314031 | AE6: 7197060 | AF6: 0 | AG6: 0 | AH6: 1561.7651 | AI6: 169140 | AJ6: 535469 | AK6: 0 | AL6: 0 | AM6: 5410800 | AN6: 7322717 | AO6: 0 | AP6: 7322717
A7: 특별계약 | B7: 주식회사 스토리위즈 | C7: 3828601768 | D7: storywiz | E7: 2531.0 | F7: 선투자 | G7: 면세 | H7: N | I7: 만화 | J7: 57928448 | K7: 회귀의 전설 | N7: 송진우,김광수 | O7: Y | P7: 0.55 | Q7: 0.55 | R7: 시리즈 대여 이용권 패키지 | S7: 1800 | T7: 9405800 | U7: 7393700 | V7: 0 | W7: 0 | X7: 0 | Y7: 34370 | Z7: 571180 | AA7: 0 | AB7: 0 | AC7: 1406550 | AD7: 9469792 | AE7: 7393700 | AF7: 0 | AG7: 0 | AH7: 0 | AI7: 41244 | AJ7: 628298 | AK7: 0 | AL7: 0 | AM7: 1406550 | AN7: 5208386 | AO7: 0 | AP7: 5208386
A8: 특별계약 | B8: 주식회사 스토리위즈 | C8: 3828601768 | D8: storywiz | E8: 2531.0 | F8: 선투자 | G8: 면세 | H8: N | I8: 만화 | J8: 57928448 | K8: 회귀의 전설 | N8: 송진우,김광수 | O8: Y | P8: 0.55 | Q8: 0.55 | R8: 시리즈 대여 이용권 패키지 | S8: 5400 | T8: 2573200 | U8: 2163350 | V8: 0 | W8: 0 | X8: 0 | Y8: 24400 | Z8: 227350 | AA8: 0 | AB8: 0 | AC8: 158100 | AD8: 2600815 | AE8: 2163350 | AF8: 0 | AG8: 0 | AH8: 0 | AI8: 29280 | AJ8: 250085 | AK8: 0 | AL8: 0 | AM8: 158100 | AN8: 1430448 | AO8: 0 | AP8: 1430448
A9: 특별계약 | B9: 주식회사 스토리위즈 | C9: 3828601768 | D9: storywiz | E9: 2531.0 | F9: 선투자 | G9: 면세 | H9: N | I9: 만화 | J9: 57928448 | K9: 회귀의 전설 | N9: 송진우,김광수 | O9: Y | P9: 0.55 | Q9: 0.55 | R9: 시리즈 대여 이용권 패키지 | S9: 9000 | T9: 934400 | U9: 806400 | V9: 0 | W9: 0 | X9: 0 | Y9: 9000 | Z9: 82200 | AA9: 0 | AB9: 0 | AC9: 36800 | AD9: 944420 | AE9: 806400 | AF9: 0 | AG9: 0 | AH9: 0 | AI9: 10800 | AJ9: 90420 | AK9: 0 | AL9: 0 | AM9: 36800 | AN9: 519431 | AO9: 0 | AP9: 519431
AP10: =SUM(AP2:AP9) -> 15233547
A11: 유통년월 | B11: 총 매출 | C11: 정산 매출(85%)
A12: 202109 | B12: 83595 | C12: =B12*85% -> 71055.75
A13: 202110 | B13: 46964380 | C13: =B13*85% -> 39919723
A14: 202111 | B14: 12173136 | C14: =B14*85% -> 10347166
A15: 202112 | B15: 16953709 | C15: =B15*85% -> 14410653
A16: 202201 | B16: =AP10 -> 15233547 | C16: =B16*85% -> 12948515
A23: 합계 | B23: =SUM(B12:B22) -> 91408367 | C23: =SUM(C12:C22) -> 77697112
A25: ※ 컨헤라 정산 : SW매출 85%
A26: 총 매출의 85%를 판권제휴 SW 매출로 인식/ 해당 매출의 30% 컨헤라 정산(70% 투자회수)

Sheet 카카오웹툰(동시연재)SW 1월
A1: 기초정보 | J1: 유통 플랫폼 거래액_KW | S1: 발행처 동시치감 특별계약타입_KP | W1: 발행처 정산금
P2: A | Q2: B | R2: C | X2: D | Y2: D | Z2: E
A3: 순번 | B3: 카테 고리 | C3: 레이블 구분 | D3: 플랫폼_작품_UID_KW | E3: 플랫폼_작품_UID_KP | F3: 작품명 | G3: 작가명 | H3: 원작정산 (사후) | I3: 판매월 | J3: 오픈일자_KW | K3: 통화 | L3: ANDROID (원화) | M3: WEB (원화) | N3: IOS (원화) | O3: EVENT CASH (원화) | P3: 플랫폼거래액 합계 | Q3: 운영/결제수수료ANDROID (6%) WEB (6%) IOS (30%) EVENT CASH (30%) | R3: KW_순매출 합계 C = A - B | S3: KP_특별계약타입 | T3: KP_특별계약_UID | U3: KP_특별계약_이름 | V3: KP_특별계약_과세유형 | W3: 정산기준 | X3: RS% android% | Y3: RS% _IOS% | Z3: KW_정산금 합계 E = C * D
A4: 1 | B4: 만화 | C4: CP | D4: 2527 | E4: 53361105 | F4: 마왕의 딸로 태어났습니다 | G4: 은민,여울 | H4: 해당없음 | I4: 2021.12월 | J4: 44449 | K4: KRW | L4: 1417500 | M4: 279700 | N4: 523084 | O4: 1165728 | P4: 3386012 | Q4: 608475 | R4: 2777537 | S4: 선투자 | T4: 1944 | U4: 스토리위즈_마왕의 딸 등 2종 | V4: 면세 | W4: 플랫폼거래액 | X4: 0.55 | Y4: 0.55 | Z4: 1862306

Sheet 네이버시리즈 SW 1월
A1: 구분 | B1: 컨텐츠 | C1: 컨텐츠No | D1: 공급자코드 | E1: CP명 | F1: 작가명 | G1: 출판사 | H1: 나이제한 | I1: 서비스일 | J1: 건수 | K1: 비정산 | L1: 무료이용권 | M1: 유상쿠키 | N1: 무상쿠키 | O1: 유상i쿠키 | P1: 무상i쿠키 | Q1: 유상자동충전쿠키 | R1: 무상자동충전쿠키 | S1: 건수 | T1: 비정산 | U1: 무료이용권 | V1: 유상쿠키 | W1: 무상쿠키 | X1: 유상i쿠키 | Y1: 무상i쿠키 | Z1: 유상자동충전쿠키 | AA1: 무상자동충전쿠키 | AB1: 건수 | AC1: 유상 | AD1: 무상 | AE1: 건수 | AF1: 유상 | AG1: 무상 | AH1: 건수 | AI1: 유상 | AJ1: 무상 | AK1: 건수 | AL1: 유상 | AM1: 무상 | AN1: i쿠키 수수료 | AO1: 건수 | AP1: 유상 | AQ1: 무상 | AR1: 건수 | AS1: 유상 | AT1: 무상 | AU1: 합계 | AV1: 순매출(합계-수수료) | AW1: sw 매출
A2: 시리즈APP | B2: 사랑은 비를 타고 [독점] | C2: 423644 | E2: 스토리위즈_사랑은비를타고_MG | F2: 예리 | G2: 스토리위즈 | H2: 전체이용가 | I2: 2022.02.02 | J2: 0 | K2: 613 | L2: 0 | M2: 0 | N2: 0 | O2: 0 | P2: 0 | Q2: 0 | R2: 0 | S2: 0 | T2: 0 | U2: 0 | V2: 0 | W2: 0 | X2: 0 | Y2: 0 | Z2: 0 | AA2: 0 | AB2: 1015 | AC2: 151000 | AD2: 51600 | AE2: 19 | AF2: 2500 | AG2: 5100 | AH2: 1 | AI2: 0 | AJ2: 200 | AK2: 0 | AL2: 0 | AM2: 0 | AN2: 0 | AO2: 152 | AP2: 29600 | AQ2: 400 | AR2: 1 | AS2: 400 | AT2: 0 | AU2: 240800 | AV2: =AU2-AN2 -> 240800 | AW2: =AV2*60% -> 144480
A3: 완전판APP | B3: 사랑은 비를 타고 [독점] | C3: 423644 | E3: 스토리위즈_사랑은비를타고_MG | F3: 예리 | G3: 스토리위즈 | H3: 전체이용가 | I3: 2022.02.02 | J3: 0 | K3: 389 | L3: 0 | M3: 0 | N3: 0 | O3: 0 | P3: 0 | Q3: 0 | R3: 0 | S3: 0 | T3: 0 | U3: 0 | V3: 0 | W3: 0 | X3: 0 | Y3: 0 | Z3: 0 | AA3: 0 | AB3: 532 | AC3: 76200 | AD3: 30000 | AE3: 28 | AF3: 10800 | AG3: 400 | AH3: 0 | AI3: 0 | AJ3: 0 | AK3: 0 | AL3: 0 | AM3: 0 | AN3: 0 | AO3: 54 | AP3: 10600 | AQ3: 0 | AR3: 0 | AS3: 0 | AT3: 0 | AU3: 128000 | AV3: =AU3-AN3 -> 128000 | AW3: =AV3*60% -> 76800
A4: 시리즈IOS | B4: 사랑은 비를 타고 [독점] | C4: 423644 | E4: 스토리위즈_사랑은비를타고_MG | F4: 예리 | G4: 스토리위즈 | H4: 전체이용가 | I4: 2022.02.02 | J4: 0 | K4: 165 | L4: 0 | M4: 0 | N4: 0 | O4: 0 | P4: 0 | Q4: 0 | R4: 0 | S4: 0 | T4: 0 | U4: 0 | V4: 0 | W4: 0 | X4: 0 | Y4: 0 | Z4: 0 | AA4: 0 | AB4: 141 | AC4: 24800 | AD4: 2700 | AE4: 1 | AF4: 400 | AG4: 0 | AH4: 164 | AI4: 17760 | AJ4: 17200 | AK4: 0 | AL4: 0 | AM4: 0 | AN4: 5328 | AO4: 36 | AP4: 7100 | AQ4: 0 | AR4: 0 | AS4: 0 | AT4: 0 | AU4: 69960 | AV4: =AU4-AN4 -> 64632 | AW4: =AV4*60% -> 38779.2
A5: N스토어PC | B5: 사랑은 비를 타고 [독점] | C5: 423644 | E5: 스토리위즈_사랑은비를타고_MG | F5: 예리 | G5: 스토리위즈 | H5: 전체이용가 | I5: 2022.02.02 | J5: 0 | K5: 0 | L5: 0 | M5: 0 | N5: 0 | O5: 0 | P5: 0 | Q5: 0 | R5: 0 | S5: 0 | T5: 0 | U5: 0 | V5: 0 | W5: 0 | X5: 0 | Y5: 0 | Z5: 0 | AA5: 0 | AB5: 1 | AC5: 0 | AD5: 200 | AE5: 0 | AF5: 0 | AG5: 0 | AH5: 0 | AI5: 0 | AJ5: 0 | AK5: 0 | AL5: 0 | AM5: 0 | AN5: 0 | AO5: 0 | AP5: 0 | AQ5: 0 | AR5: 0 | AS5: 0 | AT5: 0 | AU5: 200 | AV5: =AU5-AN5 -> 200 | AW5: =AV5*60% -> 120
A6: PC뷰어PC | B6: 사랑은 비를 타고 [독점] | C6: 423644 | E6: 스토리위즈_사랑은비를타고_MG | F6: 예리 | G6: 스토리위즈 | H6: 전체이용가 | I6: 2022.02.02 | J6: 0 | K6: 0 | L6: 0 | M6: 0 | N6: 0 | O6: 0 | P6: 0 | Q6: 0 | R6: 0 | S6: 0 | T6: 0 | U6: 0 | V6: 0 | W6: 0 | X6: 0 | Y6: 0 | Z6: 0 | AA6: 0 | AB6: 0 | AC6: 0 | AD6: 0 | AE6: 1 | AF6: 400 | AG6: 0 | AH6: 0 | AI6: 0 | AJ6: 0 | AK6: 0 | AL6: 0 | AM6: 0 | AN6: 0 | AO6: 0 | AP6: 0 | AQ6: 0 | AR6: 0 | AS6: 0 | AT6: 0 | AU6: 400 | AV6: =AU6-AN6 -> 400 | AW6: =AV6*60% -> 240
A7: 시리즈APP | B7: 마스코마스코 [독점] | C7: 448747 | E7: 스토리위즈_만화 | F7: 남정훈 | G7: 스토리위즈 | H7: 전체이용가 | I7: 2021.10.25 | J7: 0 | K7: 845 | L7: 0 | M7: 0 | N7: 0 | O7: 0 | P7: 0 | Q7: 0 | R7: 0 | S7: 0 | T7: 0 | U7: 0 | V7: 0 | W7: 0 | X7: 0 | Y7: 0 | Z7: 0 | AA7: 0 | AB7: 194 | AC7: 27300 | AD7: 11500 | AE7: 0 | AF7: 0 | AG7: 0 | AH7: 1 | AI7: 0 | AJ7: 200 | AK7: 0 | AL7: 0 | AM7: 0 | AN7: 0 | AO7: 0 | AP7: 0 | AQ7: 0 | AR7: 0 | AS7: 0 | AT7: 0 | AU7: 39000 | AV7: 39000 | AW7: 27300
A8: 완전판APP | B8: 마스코마스코 [독점] | C8: 448747 | E8: 스토리위즈_만화 | F8: 남정훈 | G8: 스토리위즈 | H8: 전체이용가 | I8: 2021.10.25 | J8: 0 | K8: 623 | L8: 0 | M8: 0 | N8: 0 | O8: 0 | P8: 0 | Q8: 0 | R8: 0 | S8: 0 | T8: 2 | U8: 0 | V8: 0 | W8: 0 | X8: 0 | Y8: 0 | Z8: 0 | AA8: 0 | AB8: 50 | AC8: 2000 | AD8: 8000 | AE8: 20 | AF8: 3100 | AG8: 4900 | AH8: 0 | AI8: 0 | AJ8: 0 | AK8: 0 | AL8: 0 | AM8: 0 | AN8: 0 | AO8: 0 | AP8: 0 | AQ8: 0 | AR8: 0 | AS8: 0 | AT8: 0 | AU8: 18000 | AV8: 18000 | AW8: 12600
A9: 시리즈IOS | B9: 마스코마스코 [독점] | C9: 448747 | E9: 스토리위즈_만화 | F9: 남정훈 | G9: 스토리위즈 | H9: 전체이용가 | I9: 2021.10.25 | J9: 0 | K9: 164 | L9: 0 | M9: 0 | N9: 0 | O9: 0 | P9: 0 | Q9: 0 | R9: 0 | S9: 0 | T9: 6 | U9: 0 | V9: 0 | W9: 0 | X9: 0 | Y9: 0 | Z9: 0 | AA9: 0 | AB9: 1 | AC9: 0 | AD9: 100 | AE9: 51 | AF9: 20400 | AG9: 0 | AH9: 86 | AI9: 19560 | AJ9: 800 | AK9: 3 | AL9: 0 | AM9: 1200 | AN9: 5868 | AO9: 0 | AP9: 0 | AQ9: 0 | AR9: 0 | AS9: 0 | AT9: 0 | AU9: 42060 | AV9: 36192 | AW9: 25334.4
A10: 웹툰스토어MW | B10: 마스코마스코 [독점] | C10: 448747 | E10: 스토리위즈_만화 | F10: 남정훈 | G10: 스토리위즈 | H10: 전체이용가 | I10: 2021.10.25 | J10: 0 | K10: 0 | L10: 0 | M10: 0 | N10: 0 | O10: 0 | P10: 0 | Q10: 0 | R10: 0 | S10: 0 | T10: 0 | U10: 0 | V10: 0 | W10: 0 | X10: 0 | Y10: 0 | Z10: 0 | AA10: 0 | AB10: 32 | AC10: 1500 | AD10: 4900 | AE10: 0 | AF10: 0 | AG10: 0 | AH10: 0 | AI10: 0 | AJ10: 0 | AK10: 0 | AL10: 0 | AM10: 0 | AN10: 0 | AO10: 0 | AP10: 0 | AQ10: 0 | AR10: 0 | AS10: 0 | AT10: 0 | AU10: 6400 | AV10: 6400 | AW10: 4480
A11: 웹툰스토어APP | B11: 마스코마스코 [독점] | C11: 448747 | E11: 스토리위즈_만화 | F11: 남정훈 | G11: 스토리위즈 | H11: 전체이용가 | I11: 2021.10.25 | J11: 0 | K11: 0 | L11: 0 | M11: 0 | N11: 0 | O11: 0 | P11: 0 | Q11: 0 | R11: 0 | S11: 0 | T11: 0 | U11: 0 | V11: 0 | W11: 0 | X11: 0 | Y11: 0 | Z11: 0 | AA11: 0 | AB11: 2 | AC11: 400 | AD11: 0 | AE11: 13 | AF11: 0 | AG11: 4900 | AH11: 0 | AI11: 0 | AJ11: 0 | AK11: 0 | AL11: 0 | AM11: 0 | AN11: 0 | AO11: 0 | AP11: 0 | AQ11: 0 | AR11: 77 | AS11: 30700 | AT11: 0 | AU11: 36000 | AV11: 36000 | AW11: 25200
A12: 웹툰앱엔드APP | B12: 마스코마스코 [독점] | C12: 448747 | E12: 스토리위즈_만화 | F12: 남정훈 | G12: 스토리위즈 | H12: 전체이용가 | I12: 2021.10.25 | J12: 0 | K12: 14463 | L12: 0 | M12: 0 | N12: 0 | O12: 0 | P12: 0 | Q12: 0 | R12: 0 | S12: 0 | T12: 0 | U12: 0 | V12: 0 | W12: 0 | X12: 0 | Y12: 0 | Z12: 0 | AA12: 0 | AB12: 1495 | AC12: 219700 | AD12: 79200 | AE12: 0 | AF12: 0 | AG12: 0 | AH12: 10 | AI12: 120 | AJ12: 1800 | AK12: 0 | AL12: 0 | AM12: 0 | AN12: 36 | AO12: 120 | AP12: 23400 | AQ12: 600 | AR12: 0 | AS12: 0 | AT12: 0 | AU12: 324820 | AV12: 324784 | AW12: 227348.8
A13: 웹툰IOS앤드 | B13: 마스코마스코 [독점] | C13: 448747 | E13: 스토리위즈_만화 | F13: 남정훈 | G13: 스토리위즈 | H13: 전체이용가 | I13: 2021.10.25 | J13: 0 | K13: 6597 | L13: 0 | M13: 0 | N13: 0 | O13: 0 | P13: 0 | Q13: 0 | R13: 0 | S13: 0 | T13: 0 | U13: 0 | V13: 0 | W13: 0 | X13: 0 | Y13: 0 | Z13: 0 | AA13: 0 | AB13: 743 | AC13: 124700 | AD13: 23300 | AE13: 0 | AF13: 0 | AG13: 0 | AH13: 409 | AI13: 70180 | AJ13: 22700 | AK13: 0 | AL13: 0 | AM13: 0 | AN13: 21054 | AO13: 17 | AP13: 3400 | AQ13: 0 | AR13: 0 | AS13: 0 | AT13: 0 | AU13: 244280 | AV13: 223226 | AW13: 156258.2
A14: N스토어(PC) | B14: 마스코마스코 [독점] | C14: 448747 | E14: 스토리위즈_만화 | F14: 남정훈 | G14: 스토리위즈 | H14: 전체이용가 | I14: 2021.10.25 | J14: 0 | K14: 171 | L14: 0 | M14: 0 | N14: 0 | O14: 0 | P14: 0 | Q14: 0 | R14: 0 | S14: 0 | T14: 0 | U14: 0 | V14: 0 | W14: 0 | X14: 0 | Y14: 0 | Z14: 0 | AA14: 0 | AB14: 1 | AC14: 200 | AD14: 0 | AE14: 1 | AF14: 400 | AG14: 0 | AH14: 0 | AI14: 0 | AJ14: 0 | AK14: 0 | AL14: 0 | AM14: 0 | AN14: 0 | AO14: 0 | AP14: 0 | AQ14: 0 | AR14: 0 | AS14: 0 | AT14: 0 | AU14: 600 | AV14: 600 | AW14: 420
A15: PC뷰어(PC) | B15: 마스코마스코 [독점] | C15: 448747 | E15: 스토리위즈_만화 | F15: 남정훈 | G15: 스토리위즈 | H15: 전체이용가 | I15: 2021.10.25 | J15: 0 | K15: 8 | L15: 0 | M15: 0 | N15: 0 | O15: 0 | P15: 0 | Q15: 0 | R15: 0 | S15: 0 | T15: 0 | U15: 0 | V15: 0 | W15: 0 | X15: 0 | Y15: 0 | Z15: 0 | AA15: 0 | AB15: 21 | AC15: 4000 | AD15: 200 | AE15: 0 | AF15: 0 | AG15: 0 | AH15: 0 | AI15: 0 | AJ15: 0 | AK15: 0 | AL15: 0 | AM15: 0 | AN15: 0 | AO15: 0 | AP15: 0 | AQ15: 0 | AR15: 0 | AS15: 0 | AT15: 0 | AU15: 4200 | AV15: 4200 | AW15: 2940
AW16: =SUM(AW2:AW15) -> 742300.6

Sheet 네이버(북미)SW 01월
B2: 당월 정산 대상
B3: 네이버웹툰(글로벌) 2022년 | C3: 1 | D3: 월 정산 금액 (단위 : 원)
B4: 대상 | C4: 금액 (공급가) | D4: 비고
B5: R/S | C5: =C20 -> 481595.45
B7: 합계 | C7: =SUM(C5:C6) -> 481595.45
B10: 상세 *매출월 발생월 기준
B11: 작품명 | C11: Love Falls Like Rain
B12: MG | C12: *국내 독점 서비스/글로벌 계약 포괄 MG (MG 미정산/월별 매출로 정산)
B13: 런칭일 | C13: 2021.07
B15: 항목 | C15: 금액 | D15: 비고
B16: 사랑은 비를 타고_2021 11 LINE MANGA_JP | C16: 52193
B17: 사랑은 비를 타고_2021 11 LINE MANGA_LAP_JP | C17: 4385.4545
B18: 사랑은 비를 타고_2021 12 LINE WEBTOON_US | C18: 366427
B19: 사랑은 비를 타고_2021 12 LINE WEBTOON_FR | C19: 58590
B20: 소계 | C20: =SUM(C16:C19) -> 481595.45

Sheet 콰이칸(마딸)SW 01월
B1: 당월 정산 대상 | C1: (면세)
B2: 콰이칸 2022년 | C2: 1 | D2: 월 정산금액 | F2: (단위 : CNY)
B3: 구분 | C3: 매출청구액 | D3: 세금공제액 | E3: 실입금액 | F3: 비고
B4: MG(2021.12) | C4: =D702 -> 12500 | D4: =D703 -> 1886.79 | E4: =D704 -> 10613.21 | F4: 5화분
B5: RS(2021.10) | C5: =D665 -> 9354.46 | D5: =D666 -> 1412 | E5: =D667 -> 7942.46
B6: RS(2021.11) | C6: =D692 -> 7481.62 | D6: =D693 -> 1129.3 | E6: =D694 -> 6352.32
B7: RS(2021.12) | C7: =D719 -> 12258.83 | D7: =D720 -> 1850.39 | E7: =D721 -> 10408.44
B8: 합계 | C8: =SUM(C4:C7) -> 41594.91 | D8: =SUM(D4:D7) -> 6278.48 | E8: =SUM(E4:E7) -> 35316.43
D10: (단위 : CNY)
B11: 구분 | D11: 금액
B12: 계약액 | C12: MG(고료) | D12: =C4 -> 12500
C13: RS(유료수익) | D13: =SUM(C5:C7) -> 29094.91
B14: 세금 | D14: =D8 -> 6278.48
B15: 실제입금액 | D15: =E8 -> 35316.43
B16: 정산대상액 | D16: =D15 -> 35316.43
B17: 정산대상액(KRW) | D17: =(D16/$E$20*100)*F20 -> 6604665.7
B18: *2021년 1월부터 기업소득세 정산 대상 제외 (미환급)
E19: RMB-USD환율 | F19: USD-KRW환율
B20: 환산일 : 2022년 1월 21일 (스토리위즈 매출 전표 결의일) | E20: 636.53 | F20: 1190.4
B21: 환산기준율 : http://www.smbs.biz/ExRate/TodayExRate.jsp
B23: 상세 *매출월 발생월 기준 / MG 월별정산 (M+1), RS 분기별 정산 (Q+1M)
B24: 작품명 | C24: 重生为魔王的女儿(마왕의 딸로 태어났습니다)
B25: MG | C25: 화당 2,500 RMB | D25: 매월 정산
B26: 런칭일 | C26: 2019.11.21
B27: 중국 Kuaikan 2019.11 정산표
B28: 타이틀 | D28: 마왕의 딸로 태어났습니다
D29: RMB | E29: KRW | F29: 비고
B30: MG | C30: 정산화수 | D30: 17 | F30: 01-17화
C31: 화별MG | D31: 2500 | E31: =D31*180 -> 450000
C32: 상금 | D32: 100 | E32: =D32*180 -> 18000
C33: 당월 고료 | D33: =(D31*D30)+D32 -> 42600 | E33: =D33*180 -> 7668000
C34: 세금공제액 | D34: =ROUND(D33/(1+0.06)*16.72%,2) -> 6719.55 | E34: =D34*180 -> 1209519
C35: 당월 세후 고료 | D35: =D33-D34 -> 35880.45 | E35: =D35*180 -> 6458481
C36: 합 계
B37: 타이틀 | D37: 마왕의 딸로 태어났습니다
D38: RMB | E38: KRW | F38: 비고
B39: RS | C39: 코인 총매출 | D39: 94951.85 | E39: =D39*180 -> 17091333
C40: ㄴ채널수수료 | D40: -24721.63 | E40: =D40*180 -> -4449893.4
C41: 코인 순수익 | D41: =D39+D40 -> 70230.22 | E41: =D41*180 -> 12641440
C42: 증정코익 수익 | D42: 41324.56 | E42: =D42*180 -> 7438420.8
...

Sheet 콰이칸(옹주)SW 01월
B1: 당월 정산 대상 | C1: (면세)
B2: 콰이칸 2022년 | C2: 1 | D2: 월 정산금액 | H2: (단위 : CNY)
B3: 구분 | C3: 매출청구액 | D3: 공제세액합계 | E3: 실입금액 | F3: 비고
B4: RS(2021.10) | C4: =D295 -> 70.315 | D4: =D296 -> 10.61 | E4: =D297 -> 59.705
B5: RS(2021.11) | C5: =D313 -> 62.595 | D5: =D314 -> 9.45 | E5: =D315 -> 53.145
B6: RS(2021.12) | C6: =D331 -> 47.215 | D6: =D332 -> 7.13 | E6: =D333 -> 40.085
B7: 합계 | C7: =SUM(C4:C6) -> 180.125 | D7: =SUM(D4:D6) -> 27.19 | E7: =SUM(E4:E6) -> 152.935
D9: (단위 : CNY)
B10: 구분 | D10: 금액
B11: 계약액 | C11: RS(유료수익) | D11: =C7 -> 180.125
B12: 세금 | D12: =D7 -> 27.19
B13: 실제입금액 | D13: =E7 -> 152.935
B14: 정산대상액 | D14: =D13 -> 152.935
B15: 정산대상액(KRW) | D15: =D14/$E$18*100*$F$18 -> 28600.981
B16: *2021년 1월부터 기업소득세 정산 대상 제외 (미환급)
E17: RMB-USD환율 | F17: USD-KRW환율
B18: 환산일 : 2022년 1월 21일 (스토리위즈 매출 전표 결의일) | E18: 636.53 | F18: 1190.4
B19: 환산기준율 : http://www.smbs.biz/ExRate/TodayExRate.jsp
B21: 상세 *매출월 발생월 기준 / MG 월별정산 (M+1), RS 분기별 정산 (Q+1M)
B22: 작품명 | C22: 逃婚郡主和她的影卫们
B23: MG | C23: NO MG
B24: 런칭일 | C24: 2020.08.07
B25: 중국 Kuaikan 2020.08 정산표
B26: 타이틀 | C26: 옹주의 호위무사
D27: RMB | E27: KRW | F27: 비고
B28: RS | C28: 코인 총매출 | D28: 2287.74 | E28: =D28*180 -> 411793.2
C29: ㄴ채널수수료 | D29: -622.11 | E29: =D29*180 -> -111979.8
C30: 코인 순수익 | D30: =D28+D29 -> 1665.63 | E30: =D30*180 -> 299813.4
C31: 증정코익 수익 | D31: 1311.15 | E31: =D31*180 -> 236007
C32: 카드수익 | D32: 0 | E32: =D32*180 -> 0
C33: 외부수익 | D33: 12.07 | E33: =D33*180 -> 2172.6
C34: 순이익 | D34: =SUM(D30:D33) -> 2988.85 | E34: =D34*180 -> 537993
C35: 당월세전RS수익 | D35: =(D34*50%)-(D19*D20) -> 1494.425 | E35: =D35*180 -> 268996.5
C36: 전월누적RS수익 | D36: 0 | E36: =D36*180 -> 0
C37: 당월 발생 RS수익 | D37: =SUM(D35:D36) -> 1494.425 | E37: =D37*180 -> 268996.5
C38: 세금공제액 | D38: 235.73 | E38: =D38*180 -> 42431.4
C39: RS 정산금액 | D39: =D37-D38 -> 1258.695 | E39: =D39*180 -> 226565.1
B42: 중국 Kuaikan 2020.09 정산표
B43: 타이틀 | C43: 옹주의 호위무사
D44: RMB | E44: KRW | F44: 비고
...

Sheet 콰이칸(아파트)SW 01월
B1: 당월 정산 대상 | C1: (면세)
B2: 콰이칸 2022년 | C2: 1 | D2: 월 정산금액 | H2: (단위 : CNY)
B3: 구분 | C3: 매출청구액 | D3: 공제세액합계 | E3: 실입금액 | F3: 비고
B4: RS(2021.04)
B5: RS(2021.05)
B6: RS(2021.06)
B7: 합계 | C7: =D55 -> 0 | D7: =D56 -> 0 | E7: =D57 -> 0
D9: (단위 : CNY)
B10: 구분 | D10: 금액
B11: 계약액 | C11: RS(유료수익) | D11: =C7 -> 0
B12: 세금 | D12: =D7 -> 0
B13: 실제입금액 | D13: =E7 -> 0
B14: 정산대상액 | D14: =D13 -> 0
B15: 정산대상액(KRW) | D15: =D14*E18 -> 0
B16: *2021년 1월부터 기업소득세 정산 대상 제외 (미환급)
B18: 환산일 : 년 월 일 (스토리위즈 매출 전표 결의일) | E18: 182.5
B19: 환산기준율 : http://www.smbs.biz/ExRate/TodayExRate.jsp
B21: 상세 *매출월 발생월 기준 / MG 월별정산 (M+1), RS 분기별 정산 (Q+1M)
B22: 작품명 | C22: 逃婚郡主和她的影卫们
B23: MG | C23: 10000000
B24: 런칭일
B25: 중국 Kuaikan 2021.08 정산표
B26: 타이틀 | D26: 아파트 용사
D27: RMB | E27: KRW | F27: 비고
B28: MG | C28: 정산화수 | D28: - | E28: - | F28: MG 일괄 지급
C29: 화별MG | D29: - | E29: -
C30: 상금 | D30: - | E30: -
C31: 당월 고료 | D31: 60000 | E31: =D31*180 -> 10800000
C32: 세금공제액 | D32: =ROUND(D31/(1+0.06)*16.72%,2) -> 9464.15 | E32: =D32*180 -> 1703547
C33: 당월 세후 고료 | D33: =D31-D32 -> 50535.85 | E33: =D33*180 -> 9096453
B34: RS | C34: 코인 총매출
C35: ㄴ채널수수료
C36: 코인 순수익
C37: 증정코인 수익
C38: 카드수익
C39: 외부수익
C40: 순이익
C41: 당월세전RS수익
C42: 전월누적RS수익
C43: 광고수익
...

Sheet 태국코미코SW 01월
B2: 당월 정산 대상 | C2: (면세)
B3: 태국 코미코 2022년 | C3: 1 | D3: 월 정산 금액 (단위 :THB)
B4: 대상 | C4: 금액(THB) | D4: 비고
B5: RS | C5: =J37 -> 47362.79
B7: 합계 | C7: =SUM(C5:C6) -> 47362.79
D9: (단위 :THB)
B10: 구분 | D10: 금액
B11: 계약액 | C11: RS | D11: =C7 -> 47362.79
B12: 세금(5%) | D12: =D11*5% -> 2368.1395
B13: 정산대상액 | D13: =D11-D12 -> 44994.65
B14: 정산대상액(KRW) | D14: =D13*D16 -> 1609908.6
B16: 환산일 : 2022년 01월 17일(인보이스 발행일) | D16: 35.78
B17: 환산기준율 : http://www.smbs.biz/ExRate/TodayExRate.jsp
B18: *원천세 5% 포함 / 2021년 1월부터 원천세 정산 대상 제외 (미환급)
B20: 상세 *매출월 발생월 기준 / 타이틀 MG, RS 분기별 정산 (Q+2M)
B21: 작품명 | C21: เกิดมาอีกทีกลายเป็นเบบี๋ของจอมมาร (마왕의 딸로 태어났습니다)
B22: MG | C22: 1500 | D22: USD | E22: 2020.09 SW정산
B23: 런칭일 | C23: 2020.10.16
B24: 매출월 | C24: 잔여 MG (THB) | D24: Gross (THB) | E24: Fee (THB) | F24: Deducted (THB) | G24: Net Rev (THB) | H24: Rev-MG (THB) | I24: 정산액 (THB) | J24: 분기정산(THB) | K24: 정산현황
B25: 2020.10 | C25: 47040 | D25: 205468.5 | E25: 61372.15 | F25: 144096.35 | G25: 57638.54 | H25: =G25-C25 -> 10598.54 | I25: =H25 -> 10598.54 | J25: =SUM(I25:I27) -> 94463.355 | K25: 정산완료(2021.01)
B26: 2020.11 | C26: 0 | D26: 170942.38 | E26: 50980.888 | F26: 119961.49 | G26: 47984.595 | H26: =G26-C26 -> 47984.595 | I26: =H26 -> 47984.595
B27: 2020.12 | C27: 0 | D27: 127926.75 | E27: 38226.19 | F27: 89700.56 | G27: 35880.22 | H27: =G27-C27 -> 35880.22 | I27: =H27 -> 35880.22
B28: 2021.01 | C28: 0 | D28: 126933.88 | E28: 37958.088 | F28: 88975.788 | G28: 35590.315 | H28: =G28-C28 -> 35590.315 | I28: =ROUND(H28,2) -> 35590.32 | J28: =SUM(I28:I30) -> 83637.2 | K28: 정산완료(2021.04)
B29: 2021.02 | C29: 0 | D29: 72882.625 | E29: 21745.05 | F29: 51137.575 | G29: 20455.03 | H29: =G29-C29 -> 20455.03 | I29: =ROUND(H29,2) -> 20455.03
B30: 2021.03 | C30: 0 | D30: 98390 | E30: 29410.375 | F30: 68979.625 | G30: 27591.85 | H30: =G30-C30 -> 27591.85 | I30: =ROUND(H30,2) -> 27591.85
B31: 2021.04 | C31: 0 | D31: 111033.38 | E31: 33225.775 | F31: 77807.6 | G31: 31123.04 | H31: 31123.04 | I31: 31123.04 | J31: 73105.85 | K31: 정산완료(2021.07)
B32: 2021.05 | C32: 0 | D32: 85254.625 | E32: 25521.175 | F32: 59733.45 | G32: 23893.38 | H32: =G32-C32 -> 23893.38 | I32: =ROUND(H32,2) -> 23893.38
B33: 2021.06 | C33: 0 | D33: 64526 | E33: 19302.44 | F33: 45223.56 | G33: 18089.43 | H33: 18089.43 | I33: 18089.43
B34: 2021.07 | C34: 0 | D34: 53346.25 | E34: 15937.412 | F34: 37408.838 | G34: 14963.535 | H34: 14963.535 | I34: 14963.54 | J34: 47448.29 | K34: 정산완료(2021.10)
B35: 2021.08 | D35: 55174 | E35: 16449.625 | F35: 38724.375 | G35: 15489.75 | H35: 15489.75 | I35: 15489.75
B36: 2021.09 | D36: 60624 | E36: 18136.512 | F36: 42487.488 | G36: 16994.995 | H36: 16994.995 | I36: 16995
B37: 2021.10 | D37: 68804.125 | E37: 20552.188 | F37: 48251.938 | G37: 19300.775 | H37: =G37-C37 -> 19300.775 | I37: =ROUND(H37,2) -> 19300.78 | J37: 47362.79 | K37: 정산완료(2022.01)
B38: 2021.11 | D38: 42695.25 | E38: 12712.625 | F38: 29982.625 | G38: 11993.05 | H38: =G38-C38 -> 11993.05 | I38: =ROUND(H38,2) -> 11993.05
B39: 2021.12 | D39: 57278.75 | E39: 17106.363 | F39: 40172.387 | G39: 16068.955 | H39: 16068.955 | I39: 16068.96
B40: Total | C40: =SUM(C25:C37) -> 47040 | D40: =SUM(D25:D37) -> 1301306.5 | E40: =SUM(E25:E37) -> 388817.87 | F40: =SUM(F25:F37) -> 912488.63 | G40: =SUM(G25:G37) -> 364995.46 | H40: =SUM(H25:H37) -> 317955.46 | I40: =SUM(I25:I37) -> 317955.47
B41: *업체 송금일 기준 USD 환산 송금 / 내부 매출인식 문제로 업체 송금 완료 후 국내 제휴사 정산 예정 (Q+3M)

Sheet 태피툰SW 01월
B2: 당월 정산 대상 | C2: (과세)
B3: 태피툰 2022년 | C3: 1 | D3: 월 정산 금액 (단위: KRW)
B4: 구분 | C4: 정산대상액 | D4: 비고
B5: RS(2021.11) | C5: =G29 -> 10430820 | D5: VAT 별도
B6: 합계 | C6: =SUM(C5) -> 10430820
B8: *최초 MG 정산 제외 모두 과세
B10: 상세 *매출월 발생월 기준 / 타이틀 MG, RS 월별 정산 (M+2)
B11: 작품명 | C11: The Adventures of a Demon King's Daughter (마왕의 딸로 태어났습니다)
B12: MG | C12: 10000000 | D12: KRW | E12: 2020.08 SW정산
B13: 런칭일 | C13: 2020.09.28
B14: 매출월 | C14: 토큰 합계 | D14: 배분 수익 | E14: 이월 선급금 | F14: 잔여 선급금 | G14: 정산 금액 | H14: 정산현황
B15: 2020.09 | C15: 79506 | D15: 3577770 | E15: 10000000 | F15: 6422230 | G15: 0 | H15: -
B16: 2020.10 | C16: 209064 | D16: 9407880 | E16: 6422230 | F16: 0 | G16: 2985650 | H16: 2020.12 정산
B17: 2020.11 | C17: 179784 | D17: 8090280 | E17: =F16 -> 0 | F17: 0 | G17: =D17 -> 8090280 | H17: 2021.01 정산
B18: 2020.12 | C18: 199947 | D18: 8997615 | E18: =F17 -> 0 | F18: 0 | G18: =D18 -> 8997615 | H18: 2021.02 정산
B19: 2021.01 | C19: 308478 | D19: 13881510 | E19: =F18 -> 0 | F19: 0 | G19: =D19 -> 13881510 | H19: 2021.03 정산
B20: 2021.02 | C20: 316608 | D20: 14247360 | E20: - | F20: - | G20: =D20 -> 14247360 | H20: 2021.04 정산
B21: 2021.03 | C21: 515324 | D21: 23189580 | E21: 0 | F21: 0 | G21: 23189580 | H21: 2021.05 정산
B22: 2021.04 | C22: 477255 | D22: 21476475 | E22: 0 | F22: 0 | G22: 21476475 | H22: 2021.06 정산
B23: 2021.05 | C23: 377721 | D23: 22663260 | E23: 0 | F23: 0 | G23: 22663260 | H23: 2021.07 정산
B24: 2021.06 | C24: 328518 | D24: 19711080 | E24: 0 | F24: 0 | G24: 19711080 | H24: 2021.09 정산
B25: 2021.07 | C25: 291069 | D25: 17464140 | E25: 0 | F25: 0 | G25: 17464140 | H25: 2021.08 정산
B26: 2021.08 | C26: 299901 | D26: 17994060 | E26: 0 | F26: 0 | G26: 17994060 | H26: 2021.10 정산
B27: 2021.09 | C27: 232248 | D27: 13934880 | E27: 0 | F27: 0 | G27: 13934880 | H27: 2021.11 정산
B28: 2021.10 | C28: 172461 | D28: 10347660 | G28: 10347660 | H28: 2021.12 정산
B29: 2021.11 | C29: 173847 | D29: 10430820 | G29: 10430820 | H29: 2022.01 정산

Sheet 델리툰(프)SW 01월
B2: 당월 정산 대상 | C2: (면세)
B3: 델리툰(프) 2022년 | C3: 1 | D3: 월 정산 금액 (단위: KRW)
B4: 구분 | C4: 정산대상액 | D4: 비고
B5: RS | C5: 0 | D5: vat 별도
B8: 합계 | C8: =SUM(C5:C7) -> 0
B9: *2021년 3월 매출분(스토리위즈 4월 매출적용분)부터 과세
B11: 상세 *매출월 발생월 기준 / 타이틀 MG, RS 월별 정산 (M+2)
B12: 작품명 | C12: Les aventures de la fille du Roi Démon (마왕의 딸로 태어났습니다)
B13: MG | C13: 3000000 | D13: KRW | E13: 2020.07 SW정산
B14: MG 2차 | C14: 4000000 | D14: KRW | E14: 2021.11 SW 정산
B15: 런칭일 | C15: 2020.12.15
B16: 매출월 | C16: CP RS (€) | D16: CP RS (￦) | E16: 전체 MG (￦) | F16: 남은 MG (￦) | G16: 차감 후 MG (￦) | H16: 자급 금액 (￦) | I16: Unit | J16: 정산현황
B17: 2020.12 | C17: 2065.47 | D17: 2762380 | E17: 3000000 | F17: 3000000 | G17: 237620 | H17: 0 | I17: KRW | J17: -
B18: 2021.01 | C18: 1434.2 | D18: 1930103 | E18: 3000000 | F18: =G17 -> 237620 | G18: 0 | H18: =D18-F18 -> 1692483 | I18: KRW | J18: 2021.02 정산
B19: 2021.02 | C19: 1175.73 | D19: 1588893 | E19: 3000000 | F19: 0 | G19: 0 | H19: 1588893 | I19: KRW | J19: 2021.03 정산
B20: 2021.03 | C20: 1287.42 | D20: 1727331 | E20: 3000000 | F20: 0 | G20: 0 | H20: 1727331 | I20: KRW | J20: 2021.04 정산
B21: 2021.04 | C21: 901.01 | D21: 1230419 | E21: 3000000 | F21: 0 | G21: 0 | H21: =D21 -> 1230419 | I21: KRW | J21: 2021.05 정산
B22: 2021.05 | C22: 1024.9 | D22: 1386884 | E22: 3000000 | F22: 0 | G22: 0 | H22: =D22 -> 1386884 | I22: KRW | J22: 2021.06 정산
B23: 2021.06 | C23: 961 | D23: 1308507 | E23: 3000000 | F23: 0 | G23: 0 | H23: =D23 -> 1308507 | I23: KRW | J23: 2021.07 정산
B24: 2021.07 | C24: 1025.5 | D24: 1395008 | E24: 3000000 | F24: 0 | G24: 0 | H24: 1395008 | I24: KRW | J24: 2021.08 정산
B25: 2021.08 | C25: 1265.36 | D25: 1750461 | E25: 3000000 | F25: 0 | G25: 0 | H25: 1750461 | I25: KRW | J25: 2021.09 정산
B26: 2021.09 | C26: 1103.21 | D26: 1520433 | E26: 3000000 | F26: 0 | G26: 0 | H26: 1520433 | I26: KRW | J26: 2021.10 정산
B27: 2021.10 | C27: 926.86 | D27: 1251150 | E27: 3000000 | F27: 0 | G27: 0 | H27: 1251150 | I27: KRW | J27: 2021.11 정산
B28: 2021.11 | C28: 986.28 | D28: 1314100 | E28: 3000000 | F28: 0 | G28: 0 | H28: 1314100 | I28: KRW | J28: 2021.12 정산
B29: 2021.12 | C29: 1398817 | D29: 3000000 | E29: 7000000 | F29: 4000000 | G29: 2601183 | I29: KRW | J29: 2022.01정산
B31: 작품명 | C31: 미정 (회귀의 전설)
B32: MG | C32: 5000000 | D32: KRW | E32: 2021.11 SW정산
B33: = SW 매출 * 85% = 컨헤라 정산대상액으로 인식
B34: 런칭일 | C34: 미정
B35: 매출월 | C35: CP RS (€) | D35: CP RS (￦) | E35: 전체 MG (￦) | F35: 남은 MG (￦) | G35: 차감 후 MG (￦) | H35: 자급 금액 (￦) | I35: Unit | J35: 정산현황

Sheet 델리툰(독)SW 01월
B2: 당월 정산 대상 | C2: (과세)
B3: 델리툰(독) 2022년 | C3: 1 | D3: 월 정산 금액 (단위: KRW)
B4: 구분 | C4: 정산대상액 | D4: 비고
B5: RS(21.12) | C5: =H22 -> 472861
B7: 합계 | C7: =SUM(C5:C6) -> 472861
B8: *2021년 3월 매출분(스토리위즈 4월 매출적용분)부터 과세
B10: 상세 *매출월 발생월 기준 / 타이틀 MG, RS 월별 정산 (M+2)
B11: 작품명 | C11: 미정 (마왕의 딸로 태어났습니다)
B12: MG | C12: 2500000 | D12: KRW | E12: 2020.12 SW정산
B13: 런칭일 | C13: 2021.05.09
B14: 매출월 | C14: CP RS (€) | D14: CP RS (￦) | E14: 전체 MG (￦) | F14: 남은 MG (￦) | G14: 차감 후 MG (￦) | H14: 자급 금액 (￦) | I14: Unit | J14: 정산현황
B15: 2021.05 | C15: 674.1 | D15: 912185 | E15: 2500000 | F15: 2500000 | G15: =F15-D15 -> 1587815 | H15: 0 | I15: KRW | J15: -
B16: 2021.06 | C16: 536.04 | D16: 729877 | E16: 2500000 | F16: 1587815 | G16: 857938 | H16: 0 | I16: KRW | J16: -
B17: 2021.07 | C17: 432.99 | D17: 589005 | E17: 2500000 | F17: 857938 | G17: 268933 | H17: 0 | I17: KRW | J17: -
B18: 2021.08 | C18: 684.88 | D18: 947442 | E18: 2500000 | F18: 268933 | G18: =F18-D18 -> -678509 | H18: 678509 | I18: KRW | J18: 2021.09 정산
B19: 2021.09 | C19: 589.46 | D19: 812388 | E19: 2500000 | F19: 0 | G19: 0 | H19: 812388 | I19: KRW | J19: 2021.10 정산
B20: 2021.10 | C20: 496.43 | D20: 670121 | E20: 2500000 | F20: 0 | G20: 0 | H20: 670121 | I20: KRW | J20: 2021.11 정산
B21: 2021.11 | C21: 405.51 | D21: 540293 | E21: 2500000 | F21: 0 | G21: 0 | H21: 540293 | I21: KRW | J21: 2021.12 정산
B22: 2021.12 | C22: 347.37 | D22: 472861 | E22: 2500000 | F22: 0 | G22: 0 | H22: 472861 | I22: KRW | J22: 2022.01 정산
B25: 작품명 | C25: 미정 (회귀의 전설)
B26: MG | C26: 3000000 | D26: KRW | E26: 2021.11 SW 정산
B27: = SW 매출 * 85% = 컨헤라 정산대상액으로 인식
B28: 런칭일 | C28: 미정
B29: 매출월 | C29: CP RS (€) | D29: CP RS (￦) | E29: 전체 MG (￦) | F29: 남은 MG (￦) | G29: 차감 후 MG (￦) | H29: 자급 금액 (￦) | I29: Unit | J29: 정산현황

Sheet 카카페(인니)SW 01월
B2: 당월 정산 대상 | D2: (과세)
B3: 카카페인니 2022년 | C3: 1 | D3: 월 정산 금액 (단위: KRW)
B4: 구분 | C4: 정산대상액 | D4: 비고
B5: RS(2021.1) | C5: =L25 -> 244488 | D5: vat 별도
B6: 합계 | C6: =SUM(C5) -> 244488
B7: *과세
B9: 상세 *매출월 발생월 기준 / 타이틀 MG / RS 월별 정산 (M+3)
B10: 작품명 | C10: Aku Lahir Sebagai Anak Raja Ibis (마왕의 딸로 태어났습니다)
B11: MG | C11: 6000000 | D11: KRW | E11: 2021.02 SW정산
B12: 런칭일 | C12: 2021.01.07
B13: 정산서 주기 | C13: 매출월(M)기준 M+2월 10일 내
B14: 매출월(정산입수) | C14: 플래폼거래액 (IDR) | D14: 환율 (IDR) | E14: 플래폼거래액 (원) | F14: 결제수수료 (원) | G14: page RS% | H14: page 매출액 (원) | I14: CP RS% | J14: 당월연동비 (MG+RS) | K14: 당월인식 MG | L14: 당월초과 RS | M14: 비고(잔여MG) | N14: 정산현황
B15: 2021.01(2021.03) | C15: 1.5775946e+08 | D15: 0.0783 | E15: 12352566 | F15: 3705769.7 | G15: 0.5 | H15: 4323398 | I15: 0.8 | J15: 3458718 | K15: 3458718 | L15: 0 | M15: =C11-K15 -> 2541282 | N15: -
B16: 2021.02(2021.04) | C16: 76836557 | D16: 0.0793 | E16: 6093139 | F16: 1827941.7 | G16: 0.5 | H16: 2132599 | I16: 0.8 | J16: 1706079 | K16: 1706079 | M16: =M15-K16 -> 835203 | N16: -
B17: 2021.03(2021.05) | C17: 86974830 | D17: 0.0786 | E17: 6836222 | F17: 2050866 | G17: 0.5 | H17: 2392678 | I17: 0.8 | J17: 1914142 | K17: 835203 | L17: 1078939 | N17: 2021.05 정산
B18: 2021.04(2021.06) | C18: 57607559 | D18: 0.077 | E18: 4435782 | F18: 1330734.6 | G18: 0.5 | H18: 1552524 | I18: 0.8 | J18: 1242019 | K18: 0 | L18: 1242019 | N18: 2021.06 정산
B19: 2021.05(2021.07) | C19: 53342150 | D19: 0.0785 | E19: 4187359 | F19: 1256208 | G19: 0.5 | H19: 1465576 | I19: 0.8 | J19: 1172460 | K19: 0 | L19: 1172460 | N19: 2021.07 정산
B20: 2021.06(2021.08) | C20: 44723318 | D20: 0.0783 | E20: 3501835.8 | F20: 1050550.7 | G20: 0.5 | H20: 1225643 | I20: 0.8 | J20: 980514 | K20: 0 | L20: 980514 | N20: 2021.08 정산
B21: 2021.07(2021.09) | C21: 62816006 | D21: 0.0789 | E21: 3501835.8 | F21: 1486854.9 | G21: 0.5 | H21: 1734664 | I21: 0.8 | J21: 1387731 | K21: 0 | L21: 1387731 | N21: 2021.09 정산
B22: 2021.08(2021.10) | C22: 42831348 | D22: 0.0806 | E22: 3452206.6 | F22: 1035662 | G22: 0.5 | H22: 1208272 | I22: 0.8 | J22: 966617 | K22: 0 | L22: 966617 | N22: 2021.10 정산
B23: 2021.09(2021.11) | C23: 34779614 | D23: 0.0821 | E23: 2855406.3 | F23: 856621.9 | G23: 0.5 | H23: 999392 | I23: 0.8 | J23: 799513 | L23: 799513 | N23: 2021.11 정산
B24: 2021.10(2021.12) | C24: 23910433 | D24: 0.0835 | E24: 1996521.2 | F24: 598956.35 | G24: 0.5 | H24: 1397564.8 | I24: 0.8 | J24: 559025 | L24: 559025 | N24: 2021.12 정산
B25: 2021.11(2022.01) | C25: 10520150 | D25: 0.083 | E25: 873172.48 | F25: 261951.74 | G25: 0.5 | H25: 305610 | I25: 0.8 | J25: 244488 | L25: 244488 | N25: 2022.1 정산

Sheet 카카페_회귀(타파스)SW 01월
B2: 당월 정산 대상 | D2: (과세)
B3: 카카페인니 2022년 | C3: 1 | D3: 월 정산 금액 (단위: KRW)
B4: 구분 | C4: 정산대상액 | D4: 비고
B5: MG | C5: =C11*85% -> 8500000 | D5: vat 별도
B6: 합계 | C6: =SUM(C5) -> 8500000
B7: -총 매출의 85%를 판권제휴 SW 매출로 인식/ 해당 매출의 30% 컨헤라 정산(70% 투자회수)
B9: 상세 *매출월 발생월 기준 / 타이틀 MG / RS 월별 정산
B10: 작품명 | C10: <회귀의 전설>
B11: MG | C11: 10000000 | D11: KRW | E11: 2022.01 SW정산
B12: 런칭일 | C12: 미정
B13: 매출월(정산입수) | C13: 플래폼거래액 (IDR) | D13: 환율 (IDR) | E13: 플래폼거래액 (원) | F13: 결제수수료 (원) | G13: page RS% | H13: page 매출액 (원) | I13: CP RS% | J13: 당월연동비 (MG+RS) | K13: 당월인식 MG | L13: 당월초과 RS | M13: 비고(잔여MG) | N13: 정산현황

Sheet 코믹툰(베트남)SW 01월
B2: 당월 정산 대상 | C2: (면세)
B3: 코믹툰 2022년 | C3: 1 | D3: 월 정산 금액 (단위: KRW)
B4: 구분 | C4: 정산대상액 | D4: 비고
B5: MG 차감 중 | C5: 0
B6: 합계 | C6: =SUM(C5) -> 0
B7: * 과세
B9: 상세 *매출월 발생월 기준 / 타이틀 MG, RS 월별 정산 (M+2)
B10: 작품명 | C10: 미정 (마왕의 딸로 태어났습니다)
B11: MG | C11: 2000000 | D11: KRW | E11: 2021.04 SW정산
B12: 런칭일 | C12: 2021.08
B14: 판매월/정산월 | C14: 제목 (Korean) | D14: 판매 건수 | E14: 판매 코인 | F14: 판매 금액 (VND) | G14: 총매출 (VND) | H14: 순매출 (VND) | I14: MG (원) | J14: 수익분배기준 (RS) | K14: 수익분배율(RS) | L14: 정산 금액 (VND) | M14: 정산 금액 (KRW) | N14: 잔여MG
B15: 21년 8월/21년 9월 | C15: 마왕의 딸로 태어났습니다 | D15: 1981 | E15: 5943 | F15: 5943000 | G15: 5943000 | H15: 2912070 | I15: 0 | J15: 순매출 | K15: 0.5 | L15: 1456035 | M15: 73803.753 | N15: =C11-M15 -> 1926196.2
B16: 21년 9월/21년 10월 | C16: 마왕의 딸로 태어났습니다 | D16: 1477 | E16: 4431 | F16: 4431000 | G16: 4431000 | H16: 2171190 | I16: 0 | J16: 순매출 | K16: 0.5 | L16: 1085595 | M16: 54863.403 | N16: 1871332.8
B17: 21년 10월/21년 11월 | C17: 마왕의 딸로 태어났습니다 | D17: 1480 | E17: 4440 | F17: 4440000 | G17: 4440000 | H17: 2175600 | J17: 순매출 | K17: 0.5 | L17: 1087800 | M17: 55676.645 | N17: 1815656.2
B18: 21년 11월/21년 12월 | C18: 마왕의 딸로 태어났습니다 | D18: 501 | E18: 1503 | F18: 1503000 | G18: 1503000 | H18: 736470 | J18: 순매출 | K18: 0.5 | L18: 368235 | M18: 18847.297 | N18: 1796808.9
B19: 21년 12월/22년 1월 | C19: 마왕의 딸로 태어났습니다 | D19: 1712 | E19: 5136 | F19: 5136000 | G19: 5136000 | H19: 2516640 | J19: 순매출 | K19: 0.5 | L19: 1258320 | M19: 64431.396 | N19: 1732377.5
B20: 21년 11월(추가)/22년 1월 | C20: 마왕의 딸로 태어났습니다 | D20: 622 | E20: 1866 | F20: 1866000 | G20: 1866000 | H20: 914340 | J20: 순매출 | K20: 0.5 | L20: 457170 | M20: 23399.239 | N20: 1708978.3
B23: 상세 *매출월 발생월 기준 / 타이틀 MG, RS 월별 정산 (M+2)
B24: 작품명 | C24: 미정 (옹주의 호위무사)
B25: MG | C25: 1000000 | D25: KRW | E25: 2021.04 SW정산
B26: 런칭일 | C26: 2021.06
B27: 판매월/정산월 | C27: 제목 (Korean) | D27: 판매 건수 | E27: 판매 코인 | F27: 판매 금액 (VND) | G27: 총매출 (VND) | H27: 순매출 (VND) | I27: MG (원) | J27: 수익분배기준 (RS) | K27: 수익분배율(RS) | L27: 정산 금액 (VND) | M27: 정산 금액 (KRW) | N27: 잔여MG
B28: 21년 6월/21년 7월 | C28: 옹주의 호위무사 | D28: 420 | E28: 1260 | F28: 1260000 | G28: 1260000 | H28: =G28*0.49 -> 617400 | I28: 0 | J28: 순매출 | K28: 0.5 | L28: =IF(J28="순매출",ROUND(H28*K28,0),IF(J28="매출액",ROUND(G28*K28,0),"")) -> 308700 | M28: =ROUND(L28/23250*1153.5,0) -> 15316 | N28: =C25-M28 -> 984684
B29: 21년 7월/21년 8월 | C29: 옹주의 호위무사 | D29: 45 | E29: 135 | F29: 135000 | G29: 135000 | H29: 66150 | J29: 순매출 | K29: 0.5 | L29: 33075 | M29: 1683.6242 | N29: =N28-M29 -> 983000.38
B30: 21년 8월/21년 9월 | C30: 옹주의 호위무사 | D30: 61 | E30: 183 | F30: 183000 | G30: 183000 | H30: 89670 | I30: 0 | J30: 순매출 | K30: 0.5 | L30: 44835 | M30: 2272.6042 | N30: =N29-M30 -> 980727.77
B31: 21년 9월/21년 10월 | C31: 옹주의 호위무사 | D31: 73 | E31: 219 | F31: 219000 | G31: 219000 | H31: 107310 | I31: 0 | J31: 순매출 | K31: 0.5 | L31: 53655 | M31: 2711.5968 | N31: =N30-M31 -> 978016.17
B32: 21년 10월/21년 11월 | C32: 옹주의 호위무사 | D32: 68 | E32: 204 | F32: 204000 | G32: 204000 | H32: 99960 | J32: 순매출 | K32: 0.5 | L32: 49980 | M32: 2558.1161 | N32: 975458.06
B33: 21년 11월/21년 12월 | C33: 옹주의 호위무사 | D33: 57 | E33: 171 | F33: 171000 | G33: 171000 | H33: 83790 | J33: 순매출 | K33: 0.5 | L33: 41895 | M33: 2144.3032 | N33: 973313.76
B34: 21년 12월/22년 1월 | C34: 옹주의 호위무사 | D34: 342 | E34: 1026 | F34: 1026000 | G34: 1026000 | H34: 502740 | J34: 순매출 | K34: 0.5 | L34: 251370 | M34: 12871.225 | N34: 960442.53
B35: 21년 11월(추가)/22년 1월 | C35: 옹주의 호위무사 | D35: -17 | E35: -51 | F35: -51000 | G35: -51000 | H35: -24990 | J35: 순매출 | K35: 0.5 | L35: -12495 | M35: -639.52903 | N35: 961082.06

Sheet 라라툰(글로벌)SW 01월
B2: 당월 정산 대상 | C2: (면세)
B3: 라라툰 2022년 | C3: 1 | D3: 월 정산 금액 (단위: KRW)
B4: 구분 | C4: 정산대상액 | D4: 비고
B5: N | D5: 부가세 별도
B6: 합계 | C6: =SUM(C5) -> 0
B7: * 과세
B9: 상세 *매출월 발생월 기준 / 타이틀 MG, RS 월별 정산 (M+2)
B10: 작품명 | C10: 미정 (옹주의 호위무사)
B11: MG | C11: 1000000 | D11: KRW | E11: 2021.07 SW정산
B12: 런칭일 | C12: 미정

Sheet 네이버 11월
A1: 이용권 포함 컨텐츠별 매출 통계
A3: 컨텐츠 | B3: 컨텐츠No | C3: 공급자코드 | D3: CP명 | E3: 작가명 | F3: 출판사 | G3: 나이제한 | H3: 서비스일 | I3: 대여권 | R3: 소장권 | AA3: 쿠키로 대여 | AD3: 쿠키로 구매 | AG3: i쿠키로 대여 | AJ3: i쿠키로 구매 | AM3: i쿠키 수수료 | AN3: 자동충전 쿠키로 대여 | AQ3: 자동충전 쿠키로 구매 | AT3: 합계
I4: 건수 | J4: 비정산 | K4: 무료이용권 | L4: 유상쿠키 | M4: 무상쿠키 | N4: 유상i쿠키 | O4: 무상i쿠키 | P4: 유상자동충전쿠키 | Q4: 무상자동충전쿠키 | R4: 건수 | S4: 비정산 | T4: 무료이용권 | U4: 유상쿠키 | V4: 무상쿠키 | W4: 유상i쿠키 | X4: 무상i쿠키 | Y4: 유상자동충전쿠키 | Z4: 무상자동충전쿠키 | AA4: 건수 | AB4: 유상 | AC4: 무상 | AD4: 건수 | AE4: 유상 | AF4: 무상 | AG4: 건수 | AH4: 유상 | AI4: 무상 | AJ4: 건수 | AK4: 유상 | AL4: 무상 | AN4: 건수 | AO4: 유상 | AP4: 무상 | AQ4: 건수 | AR4: 유상 | AS4: 무상
A5: 1부 5처 ~내가 인기 있는 이유~ | B5: 321933 | D5: 컨텐츠 헤라_만화 | E5: 무라오 미오 | F5: 서울비주얼웍스(컨텐츠헤라제공) | G5: 19세 이상 이용가능 | H5: 2018.09.06 | I5: 0 | J5: 0 | K5: 0 | L5: 0 | M5: 0 | N5: 0 | O5: 0 | P5: 0 | Q5: 0 | R5: 0 | S5: 0 | T5: 0 | U5: 0 | V5: 0 | W5: 0 | X5: 0 | Y5: 0 | Z5: 0 | AA5: 1 | AB5: 200 | AC5: 0 | AD5: 0 | AE5: 0 | AF5: 0 | AG5: 0 | AH5: 0 | AI5: 0 | AJ5: 0 | AK5: 0 | AL5: 0 | AM5: 0 | AN5: 0 | AO5: 0 | AP5: 0 | AQ5: 0 | AR5: 0 | AS5: 0 | AT5: 200
A6: CROSS and CRIME (크로스 앤드 크라임) | B6: 321835 | D6: 컨텐츠 헤라_만화 | E6: 하츠키 쿄 | F6: 서울비주얼웍스(컨텐츠헤라제공) | G6: 19세 이상 이용가능 | H6: 2018.11.21 | I6: 0 | J6: 0 | K6: 0 | L6: 0 | M6: 0 | N6: 0 | O6: 0 | P6: 0 | Q6: 0 | R6: 0 | S6: 0 | T6: 0 | U6: 0 | V6: 0 | W6: 0 | X6: 0 | Y6: 0 | Z6: 0 | AA6: 12 | AB6: 2400 | AC6: 0 | AD6: 0 | AE6: 0 | AF6: 0 | AG6: 0 | AH6: 0 | AI6: 0 | AJ6: 0 | AK6: 0 | AL6: 0 | AM6: 0 | AN6: 0 | AO6: 0 | AP6: 0 | AQ6: 0 | AR6: 0 | AS6: 0 | AT6: 2400
A7: CROSS and CRIME (크로스 앤드 크라임) | B7: 321835 | D7: 컨텐츠 헤라_만화 | E7: 하츠키 쿄 | F7: 서울비주얼웍스(컨텐츠헤라제공) | G7: 19세 이상 이용가능 | H7: 2018.11.21 | I7: 0 | J7: 0 | K7: 0 | L7: 0 | M7: 0 | N7: 0 | O7: 0 | P7: 0 | Q7: 0 | R7: 0 | S7: 0 | T7: 0 | U7: 0 | V7: 0 | W7: 0 | X7: 0 | Y7: 0 | Z7: 0 | AA7: 12 | AB7: 2400 | AC7: 0 | AD7: 0 | AE7: 0 | AF7: 0 | AG7: 0 | AH7: 0 | AI7: 0 | AJ7: 0 | AK7: 0 | AL7: 0 | AM7: 0 | AN7: 0 | AO7: 0 | AP7: 0 | AQ7: 0 | AR7: 0 | AS7: 0 | AT7: 2400
AT8: =SUM(AT5:AT7) -> 5000

Sheet 엠유_11월
A1: 매출없음

Sheet 미스터블루_11월
A1: 1. 컨텐츠헤라 월별 매출 상세내역
A2: 일 자 | B2: 작품명 | C2: 작가명 | D2: 코드 | E2: 매출구분 | AJ2: 소 계
E3: 정액 | H3: 종량 | AJ3: 매출액 | AK3: 정산액
H4: 블루머니 + A.앱머니 | T4: I.앱머니 | AF4: 계
H5: 권별 대여 | K5: 권별 소장 | N5: 전권 대여 | Q5: 전권 소장 | T5: 권별 대여 | W5: 권별 소장 | Z5: 전권 대여 | AC5: 전권 소장
E6: 건수 | F6: 매출액 | G6: 정산액 | H6: 건수 | I6: 이용권(화)수 | J6: 매출액 | K6: 건수 | L6: 이용권(화)수 | M6: 매출액 | N6: 건수 | O6: 이용권(화)수 | P6: 매출액 | Q6: 건수 | R6: 이용권(화)수 | S6: 매출액 | T6: 건수 | U6: 이용권(화)수 | V6: 매출액 | W6: 건수 | X6: 이용권(화)수 | Y6: 매출액 | Z6: 건수 | AA6: 이용권(화)수 | AB6: 매출액 | AC6: 건수 | AD6: 이용권(화)수 | AE6: 매출액 | AF6: 건수 | AG6: 이용권(화)수 | AH6: 매출액 | AI6: 정산액
A7: 2021-11-01 ~ 2021-11-30 | B7: 1부 5처 ~내가 인기 있는 이유~ | C7: 무라오 미오(Mio Murao) | D7: conhera_0003 | E7: 0 | F7: 0 | G7: 0 | H7: 1 | I7: 1 | J7: 200 | K7: 0 | L7: 0 | M7: 0 | N7: 0 | O7: 0 | P7: 0 | Q7: 0 | R7: 0 | S7: 0 | T7: 0 | U7: 0 | V7: 0 | W7: 0 | X7: 0 | Y7: 0 | Z7: 0 | AA7: 0 | AB7: 0 | AC7: 0 | AD7: 0 | AE7: 0 | AF7: 1 | AG7: 1 | AH7: 200 | AI7: 120 | AJ7: 200 | AK7: 120
A8: 2021-11-01 ~ 2021-11-30 | B8: 연애활동 | C8: 무라오 미오(Mio Murao) | D8: conhera_0001 | E8: 0 | F8: 0 | G8: 0 | H8: 1 | I8: 1 | J8: 200 | K8: 0 | L8: 0 | M8: 0 | N8: 0 | O8: 0 | P8: 0 | Q8: 0 | R8: 0 | S8: 0 | T8: 0 | U8: 0 | V8: 0 | W8: 0 | X8: 0 | Y8: 0 | Z8: 0 | AA8: 0 | AB8: 0 | AC8: 0 | AD8: 0 | AE8: 0 | AF8: 1 | AG8: 1 | AH8: 200 | AI8: 120 | AJ8: 200 | AK8: 120
AJ9: =SUM(AJ6:AJ8) -> 400 | AK9: =SUM(AK6:AK8) -> 240

Sheet 원스토어_11월
A1: 파트너명 | B1: 파트너ID | C1: 사업자구분 | D1: 구매요청POC | E1: 채널상품ID | F1: 채널상품명 | G1: 상품명 | H1: 회차 | I1: 상품ID | J1: 2차정산여부 | K1: 카테고리 | L1: 출판사 | M1: 글작가 | N1: 그림작가 | O1: 타입 | P1: 판매건수 | Q1: 취소건수 | R1: 정액제 정산대상액 | S1: 판매 | U1: 취소 | W1: 합계 | X1: 결제수단 | AA1: 서비스이용료 | AD1: 정산지급액 | AE1: 정산유형
S2: 건수 | T2: 금액 | U2: 건수 | V2: 금액 | X2: 고객결제 | Y2: 고객결제(현금영수증) | Z2: 쿠폰/포인트등 | AA2: 고객결제 서비스이용료 | AB2: 쿠폰/포인트등 | AC2: 차감
A3: (주)컨텐츠헤라 | B3: dclb_ch | C3: 원스토어㈜ | D3: OSB_AOS_ONESTORE | E3: H038861556 | F3: 1부 5처 ~내가 인기 있는 이유~ | G3: 1부 5처 ~내가 인기 있는 이유~ [단행본] 1권 | H3: 1 | I3: H035193416 | J3: 2차 | K3: 만화 | L3: 컨텐츠헤라 | M3: 무라오 미오 | N3: 무라오 미오 | O3: 단행 | P3: 1 | Q3: 0 | R3: 0 | S3: 1 | T3: 1000 | U3: 0 | V3: 0 | W3: 1000 | X3: 1000 | Y3: 0 | Z3: 0 | AA3: 300 | AB3: 0 | AC3: 0 | AD3: 700 | AE3: 정규
W4: =SUM(W3) -> 1000 | AD4: =SUM(AD3) -> 700

Sheet 봄툰_11월
N1: 매출없음

Sheet 리디_11월
A1: 판매처 | B1: 시리즈 ID | C1: 도서 ID | D1: 제목 | E1: 권/화수 | F1: 저자 | G1: 역자 | H1: 그림 | I1: 출판사 | J1: 시리즈명 | K1: 전자책정가 | L1: 단권판매액 | M1: 단권판매권 | N1: 단권무료권 | O1: 대여액 | P1: 대여유료권( ~ 2020-04 대여권) | Q1: 대여무료권 | R1: 자유다운금액 | S1: 자유다운권 | T1: 세트판매액 | U1: 세트판매권 | V1: 세트대여액 | W1: 세트대여권 | X1: 취소단권판매액 | Y1: 취소단권판매권 | Z1: 취소대여액 | AA1: 취소대여권 | AB1: 취소자유다운액 | AC1: 취소자유다운권 | AD1: 취소세트판매액 | AE1: 취소세트판매권 | AF1: 취소세트대여액 | AG1: 취소세트대여권 | AH1: 판매액 | AI1: 판매권 | AJ1: 취소액 | AK1: 취소권 | AL1: 일반 판매액 | AM1: 일반 취소액 | AN1: 앱마켓 정산대상액 | AO1: 앱마켓 수수료 | AP1: 앱마켓 취소액 | AQ1: 정산액
A2: 전체 | B2: 1471003057 | C2: 1471003057 | D2: [e북]1부 5처 ~내가 인기 있는 이유~ 1권 | E2: 1 | F2: 무라오 미오 | I2: 서울비주얼웍스(컨텐츠헤라제공) | J2: [e북]1부 5처 ~내가 인기 있는 이유~ | K2: 2000 | L2: 0 | M2: 0 | N2: 0 | O2: 1000 | P2: 1 | Q2: 0 | R2: 0 | S2: 0 | T2: 0 | U2: 0 | V2: 0 | W2: 0 | X2: 0 | Y2: 0 | Z2: 0 | AA2: 0 | AB2: 0 | AC2: 0 | AD2: 0 | AE2: 0 | AF2: 0 | AG2: 0 | AH2: 1000 | AI2: 1 | AJ2: 0 | AK2: 0 | AL2: 1000 | AM2: 0 | AN2: 0 | AO2: 0 | AP2: 0 | AQ2: 700
A3: 전체 | B3: 1471002771 | C3: 1471002771 | D3: 1부 5처 ~내가 인기 있는 이유~ 1화 | E3: 1 | F3: 무라오 미오 | I3: 서울비주얼웍스(컨텐츠헤라제공) | J3: 1부 5처 ~내가 인기 있는 이유~ | K3: 500 | L3: 0 | M3: 0 | N3: 0 | O3: 0 | P3: 0 | Q3: 13 | R3: 0 | S3: 0 | T3: 0 | U3: 0 | V3: 0 | W3: 0 | X3: 0 | Y3: 0 | Z3: 0 | AA3: 0 | AB3: 0 | AC3: 0 | AD3: 0 | AE3: 0 | AF3: 0 | AG3: 0 | AH3: 0 | AI3: 13 | AJ3: 0 | AK3: 0 | AL3: 0 | AM3: 0 | AN3: 0 | AO3: 0 | AP3: 0 | AQ3: 0
A4: 전체 | B4: 1471002771 | C4: 1471002772 | D4: 1부 5처 ~내가 인기 있는 이유~ 2화 | E4: 2 | F4: 무라오 미오 | I4: 서울비주얼웍스(컨텐츠헤라제공) | J4: 1부 5처 ~내가 인기 있는 이유~ | K4: 500 | L4: 0 | M4: 0 | N4: 0 | O4: 0 | P4: 0 | Q4: 9 | R4: 0 | S4: 0 | T4: 0 | U4: 0 | V4: 0 | W4: 0 | X4: 0 | Y4: 0 | Z4: 0 | AA4: 0 | AB4: 0 | AC4: 0 | AD4: 0 | AE4: 0 | AF4: 0 | AG4: 0 | AH4: 0 | AI4: 9 | AJ4: 0 | AK4: 0 | AL4: 0 | AM4: 0 | AN4: 0 | AO4: 0 | AP4: 0 | AQ4: 0
A5: 전체 | B5: 1471002753 | C5: 1471002753 | D5: 연애활동 1화 | E5: 1 | F5: 무라오 미오 | I5: 서울비주얼웍스(컨텐츠헤라제공) | J5: 연애활동 | K5: 500 | L5: 0 | M5: 0 | N5: 0 | O5: 0 | P5: 0 | Q5: 1 | R5: 0 | S5: 0 | T5: 0 | U5: 0 | V5: 0 | W5: 0 | X5: 0 | Y5: 0 | Z5: 0 | AA5: 0 | AB5: 0 | AC5: 0 | AD5: 0 | AE5: 0 | AF5: 0 | AG5: 0 | AH5: 0 | AI5: 1 | AJ5: 0 | AK5: 0 | AL5: 0 | AM5: 0 | AN5: 0 | AO5: 0 | AP5: 0 | AQ5: 0
A6: 전체 | B6: 1471002783 | C6: 1471002784 | D6: 제노스 (Xenos) 2화 | E6: 2 | F6: 무라오 미오 | I6: 서울비주얼웍스(컨텐츠헤라제공) | J6: 제노스 (Xenos) | K6: 500 | L6: 0 | M6: 0 | N6: 0 | O6: 0 | P6: 0 | Q6: 1 | R6: 0 | S6: 0 | T6: 0 | U6: 0 | V6: 0 | W6: 0 | X6: 0 | Y6: 0 | Z6: 0 | AA6: 0 | AB6: 0 | AC6: 0 | AD6: 0 | AE6: 0 | AF6: 0 | AG6: 0 | AH6: 0 | AI6: 1 | AJ6: 0 | AK6: 0 | AL6: 0 | AM6: 0 | AN6: 0 | AO6: 0 | AP6: 0 | AQ6: 0
A7: 전체 | B7: 1471002939 | C7: 1471002939 | D7: 제노스2 (Xenos2) 1화 | E7: 1 | F7: 무라오 미오 | I7: 서울비주얼웍스(컨텐츠헤라제공) | J7: 제노스2 (Xenos2) | K7: 500 | L7: 0 | M7: 0 | N7: 0 | O7: 0 | P7: 0 | Q7: 19 | R7: 0 | S7: 0 | T7: 0 | U7: 0 | V7: 0 | W7: 0 | X7: 0 | Y7: 0 | Z7: 0 | AA7: 0 | AB7: 0 | AC7: 0 | AD7: 0 | AE7: 0 | AF7: 0 | AG7: 0 | AH7: 0 | AI7: 19 | AJ7: 0 | AK7: 0 | AL7: 0 | AM7: 0 | AN7: 0 | AO7: 0 | AP7: 0 | AQ7: 0
A8: 전체 | B8: 1471002939 | C8: 1471002940 | D8: 제노스2 (Xenos2) 2화 | E8: 2 | F8: 무라오 미오 | I8: 서울비주얼웍스(컨텐츠헤라제공) | J8: 제노스2 (Xenos2) | K8: 500 | L8: 0 | M8: 0 | N8: 0 | O8: 0 | P8: 0 | Q8: 15 | R8: 0 | S8: 0 | T8: 0 | U8: 0 | V8: 0 | W8: 0 | X8: 0 | Y8: 0 | Z8: 0 | AA8: 0 | AB8: 0 | AC8: 0 | AD8: 0 | AE8: 0 | AF8: 0 | AG8: 0 | AH8: 0 | AI8: 15 | AJ8: 0 | AK8: 0 | AL8: 0 | AM8: 0 | AN8: 0 | AO8: 0 | AP8: 0 | AQ8: 0
A9: 전체 | B9: 1471003045 | C9: 1471003045 | D9: [e북]CROSS and CRIME (크로스 앤드 크라임) 1권 | E9: 1 | F9: 하츠키 쿄 | I9: 서울비주얼웍스(컨텐츠헤라제공) | J9: [e북]CROSS and CRIME (크로스 앤드 크라임) | K9: 2000 | L9: 0 | M9: 0 | N9: 0 | O9: 0 | P9: 0 | Q9: 2 | R9: 0 | S9: 0 | T9: 0 | U9: 0 | V9: 0 | W9: 0 | X9: 0 | Y9: 0 | Z9: 0 | AA9: 0 | AB9: 0 | AC9: 0 | AD9: 0 | AE9: 0 | AF9: 0 | AG9: 0 | AH9: 0 | AI9: 2 | AJ9: 0 | AK9: 0 | AL9: 0 | AM9: 0 | AN9: 0 | AO9: 0 | AP9: 0 | AQ9: 0
A10: 전체 | B10: 1471002762 | C10: 1471002764 | D10: CROSS and CRIME (크로스 앤드 크라임) 3화 | E10: 3 | F10: 하츠키 쿄 | I10: 서울비주얼웍스(컨텐츠헤라제공) | J10: CROSS and CRIME (크로스 앤드 크라임) | K10: 500 | L10: 0 | M10: 0 | N10: 0 | O10: 0 | P10: 0 | Q10: 4 | R10: 0 | S10: 0 | T10: 0 | U10: 0 | V10: 0 | W10: 0 | X10: 0 | Y10: 0 | Z10: 0 | AA10: 0 | AB10: 0 | AC10: 0 | AD10: 0 | AE10: 0 | AF10: 0 | AG10: 0 | AH10: 0 | AI10: 4 | AJ10: 0 | AK10: 0 | AL10: 0 | AM10: 0 | AN10: 0 | AO10: 0 | AP10: 0 | AQ10: 0
A11: 전체 | B11: 1471002762 | C11: 1471002762 | D11: CROSS and CRIME (크로스 앤드 크라임) 1화 | E11: 1 | F11: 하츠키 쿄 | I11: 서울비주얼웍스(컨텐츠헤라제공) | J11: CROSS and CRIME (크로스 앤드 크라임) | K11: 500 | L11: 0 | M11: 0 | N11: 0 | O11: 0 | P11: 0 | Q11: 6 | R11: 0 | S11: 0 | T11: 0 | U11: 0 | V11: 0 | W11: 0 | X11: 0 | Y11: 0 | Z11: 0 | AA11: 0 | AB11: 0 | AC11: 0 | AD11: 0 | AE11: 0 | AF11: 0 | AG11: 0 | AH11: 0 | AI11: 6 | AJ11: 0 | AK11: 0 | AL11: 0 | AM11: 0 | AN11: 0 | AO11: 0 | AP11: 0 | AQ11: 0
A12: 전체 | B12: 1471002762 | C12: 1471002763 | D12: CROSS and CRIME (크로스 앤드 크라임) 2화 | E12: 2 | F12: 하츠키 쿄 | I12: 서울비주얼웍스(컨텐츠헤라제공) | J12: CROSS and CRIME (크로스 앤드 크라임) | K12: 500 | L12: 0 | M12: 0 | N12: 0 | O12: 0 | P12: 0 | Q12: 5 | R12: 0 | S12: 0 | T12: 0 | U12: 0 | V12: 0 | W12: 0 | X12: 0 | Y12: 0 | Z12: 0 | AA12: 0 | AB12: 0 | AC12: 0 | AD12: 0 | AE12: 0 | AF12: 0 | AG12: 0 | AH12: 0 | AI12: 5 | AJ12: 0 | AK12: 0 | AL12: 0 | AM12: 0 | AN12: 0 | AO12: 0 | AP12: 0 | AQ12: 0
A13: 전체 | B13: 1471002820 | C13: 1471002820 | D13: 그 남자의 최면술 1화 | E13: 1 | F13: 효군 | I13: 서울비주얼웍스(컨텐츠헤라제공) | J13: 그 남자의 최면술 | K13: 500 | L13: 0 | M13: 0 | N13: 0 | O13: 0 | P13: 0 | Q13: 1 | R13: 0 | S13: 0 | T13: 0 | U13: 0 | V13: 0 | W13: 0 | X13: 0 | Y13: 0 | Z13: 0 | AA13: 0 | AB13: 0 | AC13: 0 | AD13: 0 | AE13: 0 | AF13: 0 | AG13: 0 | AH13: 0 | AI13: 1 | AJ13: 0 | AK13: 0 | AL13: 0 | AM13: 0 | AN13: 0 | AO13: 0 | AP13: 0 | AQ13: 0
L14: =SUM(L2:L13) -> 0 | O14: =SUM(O2:O13) -> 1000 | AQ14: =SUM(AQ2:AQ13) -> 700

Sheet 카카오페이지_11월
K1: 매출없음

Sheet 레진_11월
A1: 매출없음

Sheet 알라딘_11월
A1: 판매/취소일시 | B1: ItemId | C1: 제목 | D1: 판매형태 | E1: 정가 | F1: 판매가 | G1: 정산액 | H1: 원주문일시 | I1: 저자명 | J1: 출판사명 | K1: 정산처명 | L1: ISBN | M1: CID
A2: 44504.476 | B2: 177589007 | C2: [고화질] 지구의 방과후 (단행본) 01 | D2: 판매 | E2: 2000 | F2: 2000 | G2: 1400 | I2: 요시토미 아키히토 | J2: 서울비주얼웍스(컨텐츠헤라제공) | K2: 컨텐츠헤라(만화) | L2: =T("9791188676835") -> 9791188676835
A3: 44521.862 | B3: 177589001 | C3: [고화질] 제노스 (Xenos) (단행본) 03 | D3: 대여 | E3: 1000 | F3: 1000 | G3: 700 | I3: 무라오 미오 | J3: 서울비주얼웍스(컨텐츠헤라제공) | K3: 컨텐츠헤라(만화) | L3: =T("9791188676958") -> 9791188676958
A4: 44522.477 | B4: 177589002 | C4: [고화질] 제노스 (Xenos) (단행본) 04 (완결) | D4: 대여 | E4: 1000 | F4: 1000 | G4: 700 | I4: 무라오 미오 | J4: 서울비주얼웍스(컨텐츠헤라제공) | K4: 컨텐츠헤라(만화) | L4: =T("9791188676965") -> 9791188676965
F5: =SUM(F2:F4) -> 4000 | G5: =SUM(G2:G4) -> 2800
