Workbook

Sheet 종합
A1: 델리툰 (프)
A2: 기본정보
A3: RS: 순매출의 40% 매출월: M 정산서 전달: M+1월 20일 내 (CMS로 확인) 실제 정산(계산서 발행): M+2M 진행 기타: 과세사업자
A5: 매출내역
A6: 상세 *매출월 발생월 기준 / 타이틀 MG, RS 월별 정산 (M+2)
A7: 작품명 | B7: BAISER EN COULISSES (백스테이지 키스신) | H7: BAISER EN COULISSES Les aventures de la fille du Roi Démon (마왕의 딸로 태어났습니다) | N7: Le Retour de la Légende (회귀의 전설)
A8: 런칭일 | B8: 2020.11.26 | H8: 2020.12.15 | N8: 2022.04.22
A9: MG | B9: 2500000 | D9: MG 정산 | E9: 2020.06 SW매출인식 / 7월 입금 | H9: 3000000 | J9: MG 정산 | K9: 2020.07 SW매출인식 / 8월 입금 | N9: 5000000 | P9: MG 정산 | Q9: 2021.10 SW매출인식 / 10월 입금
A10: 구분 | B10: CP RS (￦) | C10: 전체 MG (￦) | D10: 남은 MG (￦) | E10: 차감 후 MG (￦) | F10: 지급 금액 (￦) | G10: 정산현황 | H10: CP RS (￦) | I10: 전체 MG (￦) | J10: 남은 MG (￦) | K10: 차감 후 MG (￦) | L10: 지급 금액 (￦) | M10: 정산현황 | N10: CP RS (￦) | O10: 전체 MG (￦) | P10: 남은 MG (￦) | Q10: 차감 후 MG (￦) | R10: 지급 금액 (￦) | S10: 정산현황
A11: 2020.11 | B11: ='월별 정산서'!E4 -> 464842 | C11: ='월별 정산서'!F4 -> 2500000 | D11: ='월별 정산서'!G4 -> 2500000 | E11: =D11-B11 -> 2035158 | F11: 0 | G11: N | H11: 0 | I11: =H111 -> 0 | J11: 0 | K11: 0 | L11: 0 | M11: 0
A12: 2020.12 | B12: ='월별 정산서'!E10 -> 390296 | C12: =C11 -> 2500000 | D12: =E11 -> 2035158 | E12: =D12-B12 -> 1644862 | F12: 0 | G12: N | H12: ='월별 정산서'!E9 -> 2762380 | I12: =H9 -> 3000000 | J12: =I12 -> 3000000 | K12: =J12-H12 -> 237620 | L12: 0 | M12: N
A13: 2021.01 | B13: ='월별 정산서'!E16 -> 272976 | C13: =C12 -> 2500000 | D13: ='월별 정산서'!G16 -> 1644862 | E13: =D13-B13 -> 1371886 | F13: 0 | G13: N | H13: ='월별 정산서'!E15 -> 1930103 | I13: =I12 -> 3000000 | J13: =K12 -> 237620 | K13: 0 | L13: =H13-J13 -> 1692483 | M13: 2021.02 계산서발행
A14: 2021.02 | B14: ='월별 정산서'!E22 -> 279242 | C14: =B9 -> 2500000 | D14: ='월별 정산서'!G22 -> 1371886 | E14: ='월별 정산서'!H22 -> 1092644 | F14: 0 | G14: N | H14: ='월별 정산서'!E21 -> 1588893 | I14: =H9 -> 3000000 | J14: ='월별 정산서'!G21 -> 0 | K14: 0 | L14: ='월별 정산서'!I21 -> 1588893 | M14: 2021.03 계산서 발행
A15: 2021.03 | B15: ='월별 정산서'!E28 -> 269226 | C15: ='월별 정산서'!F28 -> 2500000 | D15: ='월별 정산서'!G28 -> 1092644 | E15: ='월별 정산서'!H28 -> 823418 | F15: 0 | G15: N | H15: ='월별 정산서'!E27 -> 1727331 | I15: =H9 -> 3000000 | J15: =K14 -> 0 | K15: =J15 -> 0 | L15: =H15 -> 1727331 | M15: 2021.04 계산서 발행
A16: 2021.04 | B16: ='월별 정산서'!E34 -> 280972 | C16: ='월별 정산서'!F34 -> 2500000 | D16: ='월별 정산서'!G34 -> 823418 | E16: ='월별 정산서'!H34 -> 542446 | F16: 0 | G16: N | H16: ='월별 정산서'!E33 -> 1230419 | I16: ='월별 정산서'!F33 -> 3000000 | J16: ='월별 정산서'!G33 -> 0 | K16: 0 | L16: =H16 -> 1230419 | M16: 2021.05 계산서 발행
A17: 2021.05 | B17: ='월별 정산서'!F42 -> 252072 | C17: =C16 -> 2500000 | D17: =E16 -> 542446 | E17: ='월별 정산서'!I42 -> 290374 | F17: 0 | G17: N | H17: ='월별 정산서'!F40 -> 1386884 | I17: =I16 -> 3000000 | J17: =K16 -> 0 | K17: 0 | L17: =H17 -> 1386884 | M17: 2021.06 계산서 발행
A18: 2021.06 | B18: ='월별 정산서'!F50 -> 520666 | C18: =B9 -> 2500000 | D18: =E17 -> 290374 | E18: 0 | F18: =B18-D18 -> 230292 | G18: 2021.07 계산서 발행 | H18: ='월별 정산서'!F48 -> 1308507 | I18: =H9 -> 3000000 | J18: =K17 -> 0 | K18: 0 | L18: =H18 -> 1308507 | M18: 2021.07 계산서 발행
A19: 2021.07 | B19: ='월별 정산서'!F58 -> 227010 | C19: =B9 -> 2500000 | D19: =E18 -> 0 | E19: =D19 -> 0 | F19: =B19 -> 227010 | G19: 2021.08 계산서 발행 | H19: ='월별 정산서'!F56 -> 1395008 | I19: =H9 -> 3000000 | J19: =K18 -> 0 | K19: =J19 -> 0 | L19: =H19 -> 1395008 | M19: 2021.08 계산서 발행
A20: 2021.08 | B20: ='월별 정산서'!I64 -> 281862 | C20: 2500000 | D20: 0 | E20: 0 | F20: ='월별 정산서'!I64 -> 281862 | G20: 2021.09 계산서 발행 | H20: ='월별 정산서'!I63 -> 1750461 | I20: 3000000 | J20: 0 | K20: 0 | L20: ='월별 정산서'!I63 -> 1750461 | M20: 2021.09 계산서 발행
A21: 2021.09 | B21: ='월별 정산서'!F72 -> 190397 | C21: ='월별 정산서'!G72 -> 2500000 | F21: ='월별 정산서'!J72 -> 190397 | G21: 2021.10 계산서 발행 | H21: ='월별 정산서'!F70 -> 1520433 | I21: ='월별 정산서'!G70 -> 3000000 | L21: ='월별 정산서'!J70 -> 1520433 | M21: 2021.10 계산서 발행
A22: 2021.10 | B22: ='월별 정산서'!F78 -> 38404 | C22: =C21 -> 2500000 | F22: =B22 -> 38404 | G22: 2021.11 계산서 발행 | H22: ='월별 정산서'!F77 -> 1251150 | I22: =I21 -> 3000000 | L22: =H22 -> 1251150 | M22: 2021.11 계산서 발행
A23: 2021.11 | B23: ='월별 정산서'!E84 -> 13684 | C23: =C22 -> 2500000 | F23: =B23 -> 13684 | G23: 2021.12 계산서 발행 | H23: ='월별 정산서'!E83 -> 1314100 | I23: =I22 -> 3000000 | L23: =H23 -> 1314100 | M23: 2021.12 계산서 발행
A24: 2021.12 | B24: ='월별 정산서'!E90 -> 41096 | C24: =C23 -> 2500000 | F24: =B24 -> 41096 | G24: 2022.01 계산서 발행 | H24: ='월별 정산서'!E89 -> 1398817 | I24: =I23 -> 3000000 | J24: ='월별 정산서'!G89 -> 4000000 | K24: =J24-H24 -> 2601183 | L24: 0 | M24: N
A25: 2022.01 | B25: 41925 | C25: 2500000 | F25: 41925 | G25: 2022.02 계산서 발행 | H25: 1035146 | I25: =I24 -> 3000000 | J25: ='월별 정산서'!G90 -> 0 | K25: =K24-H25 -> 1566037 | L25: 0 | M25: N
A26: 2022.02 | B26: 21843 | C26: 2500000 | D26: 0 | E26: 0 | F26: 21843 | G26: 2022.03 계산서 발행 | H26: 1073294 | I26: 3000000 | J26: 1566037 | K26: 492743 | L26: 0 | M26: N
A27: 2022.03 | B27: 184680 | C27: 2500000 | D27: 0 | E27: 0 | F27: 184680 | G27: 2022.04 계산서 발행 | H27: 947982 | I27: 3000000 | J27: 492743 | L27: ='월별 정산서'!I107 -> 455239 | M27: 2022.04 계산서 발행
A28: 2022.04 | B28: ='월별 정산서'!E115 -> 38552 | C28: ='월별 정산서'!F115 -> 2500000 | D28: ='월별 정산서'!G115 -> 0 | E28: ='월별 정산서'!H115 -> 0 | F28: ='월별 정산서'!I115 -> 38552 | G28: 2022.05 계산서 발행 | H28: ='월별 정산서'!E113 -> 831309 | I28: ='월별 정산서'!F113 -> 3000000 | J28: ='월별 정산서'!G113 -> 0 | K28: ='월별 정산서'!H113 -> 0 | L28: ='월별 정산서'!I113 -> 831309 | M28: 2022.05 계산서 발행 | N28: ='월별 정산서'!E114 -> 443991 | O28: ='월별 정산서'!F114 -> 5000000 | P28: ='월별 정산서'!G114 -> 5000000 | Q28: ='월별 정산서'!H114 -> 4556009 | R28: ='월별 정산서'!I114 -> 0 | S28: N
A29: 2022.05 | B29: ='월별 정산서'!E122 -> 34101 | C29: ='월별 정산서'!F122 -> 2500000 | F29: ='월별 정산서'!I122 -> 34101 | G29: 2022.06 계산서 발행 | H29: ='월별 정산서'!E120 -> 1056078 | I29: ='월별 정산서'!F120 -> 3000000 | L29: ='월별 정산서'!I120 -> 1056078 | M29: 2022.06 계산서 발행 | N29: ='월별 정산서'!E121 -> 285886 | O29: ='월별 정산서'!F121 -> 5000000 | P29: ='월별 정산서'!G121 -> 4556009 | Q29: ='월별 정산서'!H121 -> 4270123 | R29: ='월별 정산서'!I121 -> 0 | S29: N

Sheet 월별 정산서
B1: 월별 매출
B2: 2020년 11월
B3: cid | C3: title | D3: CP RS (€) | E3: CP RS (￦) | F3: 전체 MG (￦) | G3: 남은 MG (￦) | H3: 차감 후 MG (￦) | I3: 자급 금액 (￦) | J3: Unit
B4: 328 | C4: Baiser en coulisses | D4: 350.84 | E4: 464842 | F4: 2500000 | G4: 2500000 | H4: 2035158 | I4: 0 | J4: KRW
B5: Sum | D5: 350.84 | E5: 464842 | I5: 0
B7: 2020년 12월
B8: cid | C8: title | D8: CP RS (€) | E8: CP RS (￦) | F8: 전체 MG (￦) | G8: 남은 MG (￦) | H8: 차감 후 MG (￦) | I8: 자급 금액 (￦) | J8: Unit
B9: 349 | C9: Les aventures de la fille du Roi Démon | D9: 2065.47 | E9: 2762380 | F9: 3000000 | G9: 3000000 | H9: 237620 | I9: 0 | J9: KRW
B10: 328 | C10: Baiser en coulisses | D10: 291.83 | E10: 390296 | F10: 2500000 | G10: 2035158 | H10: 1644862 | I10: 0 | J10: KRW
B11: Sum | D11: 2357.3 | E11: 3152676 | I11: 0
B13: 2021년 01월
B14: ='월별 정산서'!E22\ -> #NAME? | C14: title | D14: CP RS (€) | E14: CP RS (￦) | F14: 전체 MG (￦) | G14: 남은 MG (￦) | H14: 차감 후 MG (￦) | I14: 자급 금액 (￦) | J14: Unit
B15: 349 | C15: Les aventures de la fille du Roi Démon | D15: 1434.2 | E15: 1930103 | F15: 3000000 | G15: 237620 | H15: 0 | I15: 1692483 | J15: KRW
B16: 328 | C16: Baiser en coulisses | D16: 202.84 | E16: 272976 | F16: 2500000 | G16: 1644862 | H16: 1371886 | I16: 0 | J16: KRW
B17: Sum | D17: 1637.04 | E17: 2203079 | I17: 1692483
B19: 2021년 02월
B20: cid | C20: title | D20: CP RS (€) | E20: CP RS (￦) | F20: 전체 MG (￦) | G20: 남은 MG (￦) | H20: 차감 후 MG (￦) | I20: 자급 금액 (￦) | J20: Unit
B21: 349 | C21: Les aventures de la fille du Roi Démon | D21: 1175.73 | E21: 1588893 | F21: 3000000 | G21: 0 | H21: 0 | I21: 1588893 | J21: KRW
B22: 328 | C22: Baiser en coulisses | D22: 206.63 | E22: 279242 | F22: 2500000 | G22: 1371886 | H22: 1092644 | I22: 0 | J22: KRW
B23: Sum | D23: 1382.36 | E23: 1868135 | I23: 1588893
B25: 2021년 03월
B26: cid | C26: title | D26: CP RS (€) | E26: CP RS (￦) | F26: 전체 MG (￦) | G26: 남은 MG (￦) | H26: 차감 후 MG (￦) | I26: 자급 금액 (￦) | J26: Unit
B27: 349 | C27: Les aventures de la fille du Roi Démon | D27: 1287.42 | E27: 1727331 | F27: 3000000 | G27: 0 | H27: 0 | I27: =E27 -> 1727331 | J27: KRW
B28: 328 | C28: Baiser en coulisses | D28: 200.66 | E28: 269226 | F28: 2500000 | G28: =H22 -> 1092644 | H28: =G28-E28 -> 823418 | I28: 0 | J28: KRW
B29: Sum | D29: =SUM(D27:D28) -> 1488.08 | E29: =SUM(E27:E28) -> 1996557 | I29: =SUM(I27:I28) -> 1727331
B31: 2021년 04월
B32: cid | C32: title | D32: CP RS (€) | E32: CP RS (￦) | F32: 전체 MG (￦) | G32: 남은 MG (￦) | H32: 차감 후 MG (￦) | I32: 자급 금액 (￦) | J32: Unit
B33: 349 | C33: Les aventures de la fille du Roi Démon | D33: 901.01 | E33: 1230419 | F33: 3000000 | G33: 0 | H33: 0 | I33: 1230419 | J33: KRW
B34: 328 | C34: Baiser en coulisses | D34: 205.75 | E34: 280972 | F34: 2500000 | G34: 823418 | H34: 542446 | I34: 0 | J34: KRW
B35: Sum | D35: 1106.76 | E35: 1511391 | I35: 1230419
B37: 2021년 05월
B38: cid | C38: title | D38: Service | E38: CP RS (€) | F38: CP RS (￦) | G38: 전체 MG (￦) | H38: 남은 MG (￦) | I38: 차감 후 MG (￦) | J38: 자급 금액 (￦) | K38: Unit
B39: 349 | C39: Les aventures de la fille du Roi Démon | D39: delitoonFR | E39: 1024.9
D40: CID sum | E40: 1024.9 | F40: 1386884 | G40: 3000000 | H40: 0 | I40: 0 | J40: 1386884 | K40: KRW
B41: 328 | C41: Baiser en coulisses | D41: delitoonFR | E41: 186.28
D42: CID sum | E42: 186.28 | F42: 252072 | G42: 2500000 | H42: 542446 | I42: 290374 | J42: 0 | K42: KRW
B43: Sum | E43: 1211.18 | F43: 1638956 | J43: 1386884
B45: 2021년 06월
B46: cid | C46: title | D46: Service | E46: CP RS (€) | F46: CP RS (￦) | G46: 전체 MG (￦) | H46: 남은 MG (￦) | I46: 차감 후 MG (￦) | J46: 자급 금액 (￦) | K46: Unit
B47: 349 | C47: Les aventures de la fille du Roi Démon | D47: delitoonFR | E47: 961
...
