Workbook

Sheet 종합
A1: 카카오페이지 글로벌(인도네시아)
A2: 기본정보
A3: 매출월: M 정산서 전달: M+2월 10일 내 실제 정산(세금계산서 발행): M+2월 1~15일 입금일: M+3월 말일 기타: 세금계산서 발행 (면세사업자X) RS: 카카오페이지 순매출의 80%
A5: 매출내역
A6: 작품명 | B6: Aku Lahir Sebagai Anak Raja Iblis (마왕의 딸로 태어났습니다)
A7: 런칭일 | B7: 2021.01.07 | G7: MG | H7: 6000000
A8: 구분(판매월) | B8: 계산서발행 | C8: 플래폼거래액 (IDR) | D8: 환율 (IDR) | E8: 플래폼거래액 (원) | F8: 결제수수료 (원) | G8: page RS% | H8: page 매출액 (원) | I8: CP RS% | J8: 당월연동비 (MG+RS) | K8: 당월인식 MG | L8: 당월초과 RS
A9: 2021.01 | B9: X | C9: 1.5775946e+08 | D9: 0.0783 | E9: 12352566 | F9: 3705769.7 | G9: 0.5 | H9: 4323398 | I9: 0.8 | J9: 3458718 | K9: 3458718 | L9: 0
A10: 2021.02 | B10: X | C10: 76836557 | D10: 0.0793 | E10: 6093139 | F10: 1827941.7 | G10: 0.5 | H10: 2132599 | I10: 0.8 | J10: 1706079 | K10: 1706079 | L10: 0
A11: 2021.03 | B11: X | C11: ='월별 매출(마딸,공주)'!K8 -> 86974830 | D11: ='월별 매출(마딸,공주)'!L8 -> 0.0786 | E11: ='월별 매출(마딸,공주)'!M8 -> 6836221.6 | F11: ='월별 매출(마딸,공주)'!O8 -> 2050866.5 | G11: 0.5 | H11: ='월별 매출(마딸,공주)'!R8 -> 2392678 | I11: 0.8 | J11: ='월별 매출(마딸,공주)'!V8 -> 1914142 | K11: ='월별 매출(마딸,공주)'!Z8 -> 835203 | L11: ='월별 매출(마딸,공주)'!AB8 -> 1078939
A12: 2021.04 | B12: O | C12: ='월별 매출(마딸,공주)'!K9 -> 57607559 | D12: ='월별 매출(마딸,공주)'!L9 -> 0.077 | E12: ='월별 매출(마딸,공주)'!M9 -> 4435782 | F12: ='월별 매출(마딸,공주)'!O9 -> 1330734.6 | G12: 0.5 | H12: ='월별 매출(마딸,공주)'!R9 -> 1552524 | I12: 0.8 | J12: ='월별 매출(마딸,공주)'!V9 -> 1242019 | K12: ='월별 매출(마딸,공주)'!Z9 -> 0 | L12: =J12 -> 1242019
A13: 2021.05 | B13: O | C13: 53342150 | D13: 0.0785 | E13: 4187358.8 | F13: 1256207.6 | G13: 0.5 | H13: 1465576 | I13: 0.8 | J13: 1172460 | K13: 0 | L13: 1172460
A14: 2021.06 | B14: O | C14: 44723318 | D14: 0.0783 | E14: 3501835.8 | F14: 1050550.7 | G14: 0.5 | H14: 1225643 | I14: 0.8 | J14: 980514 | K14: 0 | L14: 980514 | N14: 980514 | O14: 10473932 | P14: 0
A15: 2021.07 | B15: O | C15: 62816006 | D15: 0.0789 | E15: 4956182.9 | F15: 1486854.9 | G15: 0.5 | H15: 1734664 | I15: 0.8 | J15: 1387731 | K15: 0 | L15: 1387731 | N15: 980514 | O15: 10473932 | P15: 0
A16: 2021.08 | B16: O | C16: 42831348 | D16: 0.0806 | E16: 3452206.6 | F16: 1035662 | G16: 0.5 | H16: 1208272 | I16: 0.8 | J16: 966617 | K16: 0 | L16: 966617 | N16: 980514 | O16: 10473932 | P16: 0
A17: 2021.09 | B17: O | C17: 34779614 | D17: 0.0821 | E17: 2855406.3 | F17: 856621.9 | G17: 0.5 | H17: 999392 | I17: 0.8 | J17: 799513 | K17: 0 | L17: 799513 | N17: 980514 | O17: 10473932 | P17: 0
A18: 2021.10 | B18: O | C18: 23910433 | D18: 0.0835 | E18: 1996521.2 | F18: 598956.35 | G18: 0.5 | H18: 698782 | I18: 0.8 | J18: 559025 | K18: 0 | L18: 559025
A19: 2021.11 | B19: O | C19: 10520150 | D19: 0.083 | E19: 873172.48 | F19: 261951.74 | G19: 0.5 | H19: 305610 | I19: 0.8 | J19: 244488 | K19: 0 | L19: 244488
A20: 2021.12 | B20: O | C20: 8024294.4 | D20: 0.0826 | E20: 662806.72 | F20: 198842.02 | G20: 0.5 | H20: 231982 | I20: 0.8 | J20: 185585 | K20: 0 | L20: 185585
A21: 2022.01 | B21: O | C21: 5681448 | D21: 0.0833 | E21: 473264.62 | F21: 141979.39 | G21: 0.5 | H21: 165643 | I21: 0.8 | J21: 132514 | K21: 0 | L21: 132514
A22: 2022.02 | B22: O | C22: 6036930 | D22: 0.0835 | E22: 504083.65 | F22: 151225.1 | G22: 0.5 | H22: 176429 | I22: 0.8 | J22: 141143 | L22: 141143
A23: 2022.03 | B23: O | C23: 5162404.8 | D23: 0.0851 | E23: 439320.65 | F23: 131796.19 | G23: 0.5 | H23: 153762 | I23: 0.8 | J23: 123009 | K23: 0 | L23: 123009
A25: 매출내역
A26: 작품명 | B26: How to Raise the Devil's Child (마왕의 아이를 키우는 법)
A27: 구분(판매월) | B27: 계산서발행 | C27: 플래폼거래액 (IDR) | D27: 환율 (IDR) | E27: 플래폼거래액 (원) | F27: 결제수수료 (원) | G27: page RS% | H27: page 매출액 (원) | I27: CP RS% | J27: 당월연동비 (MG+RS) | K27: 당월인식 MG | L27: 당월초과 RS
A28: 2021.07 | B28: O | C28: 2308545.6 | D28: 0.0789 | E28: 182144.25 | F28: 54643.274 | G28: 0.5 | H28: 63750 | I28: 0.8 | J28: 51000 | K28: - | L28: 51000
A29: 2021.08 | B29: O | C29: 1653456 | D29: 0.0806 | E29: 133268.55 | F29: 39980.566 | G29: 0.5 | H29: 46644 | I29: 0.8 | J29: 37315 | K29: - | L29: 37315
A30: 2021.09 | B30: O | C30: 877332 | D30: 0.0821 | E30: 72028.957 | F30: 21608.687 | G30: 0.5 | H30: 25210 | I30: 0.8 | J30: 20168 | K30: - | L30: 20168
A31: 2021.10 | B31: O | C31: 724842 | D31: 0.0835 | E31: 60524.307 | F31: 18157.292 | G31: 0.5 | H31: 21184 | I31: 0.8 | J31: 16947 | K31: 0 | L31: 16947
A32: 2021.11 | B32: O | C32: 406848 | D32: 0.083 | E32: 33768.384 | F32: 10130.515 | G32: 0.5 | H32: 11819 | I32: 0.8 | J32: 9455 | K32: 0 | L32: 9455
A33: 2021.12 | B33: O | C33: 339561.6 | D33: 0.0826 | E33: 28047.788 | F33: 8414.3364 | G33: 0.5 | H33: 9817 | I33: 0.8 | J33: 7853 | K33: 0 | L33: 7853
A34: 2022.01 | B34: O | C34: 335124 | D34: 0.0833 | E34: 27915.829 | F34: 8374.7488 | G34: 0.5 | H34: 9771 | I34: 0.8 | J34: 7816 | K34: 0 | L34: 7816
A35: 2022.02 | B35: O | C35: 317898 | D35: 0.0835 | E35: 26544.483 | F35: 7963.3449 | G35: 0.5 | H35: 9291 | I35: 0.8 | J35: 7432 | K35: 0 | L35: 7432
A36: 2022.03 | B36: O | C36: 364795.2 | D36: 0.0851 | E36: 31044.072 | F36: 9313.2215 | G36: 0.5 | H36: 10865 | I36: 0.8 | J36: 8692 | K36: 0 | L36: 8692
A38: 작품명 | B38: Pertarungan Para Putri (공주전쟁)
A39: 런칭일 | B39: 2021.08.18 | G39: MG | H39: 3000000
A40: 구분(판매월) | B40: 계산서발행 | C40: 플래폼거래액 (IDR) | D40: 환율 (IDR) | E40: 플래폼거래액 (원) | F40: 결제수수료 (원) | G40: page RS% | H40: page 매출액 (원) | I40: CP RS% | J40: 당월연동비 (MG+RS) | K40: 당월인식 MG | L40: 당월초과 RS
A41: 2021.08 | B41: X | C41: 54212326 | D41: 0.0806 | E41: 4369513.5 | F41: 1310854 | G41: 0.35 | H41: 1529330 | I41: 1 | J41: 1529330 | K41: 1529330 | L41: 0
A42: 2021.09 | B42: X | C42: 8887709.6 | D42: 0.0821 | E42: 729680.96 | F42: 218904.29 | G42: 0.35 | H42: 255388 | I42: 1 | J42: 255388 | K42: 255388 | L42: 0
A43: 2021.10 | B43: X | C43: 5337591 | D43: 0.0835 | E43: 445688.85 | F43: 133706.65 | G43: 0.35 | H43: 155991 | I43: 1 | J43: 155991 | K43: 155991
...

Sheet 월별 매출(마딸,공주)
A1: 월별 매출 정산내역
D3: TOTAL | K3: =SUBTOTAL(9,M6:M9857) -> 59924090 | M3: =SUBTOTAL(9,O6:O9857) -> 17977227 | O3: =SUBTOTAL(9,Q6:Q9857) -> 9.95 | P3: =SUBTOTAL(9,R6:R9857) -> 20973431 | R3: =SUBTOTAL(9,T6:T9857) -> 19 | V3: =SUBTOTAL(9,X6:X9857) -> 9315663 | Z3: =SUBTOTAL(9,AB6:AB9857) -> 83573508 | AA3: =SUBTOTAL(9,AC6:AC9857) -> 0
A5: NO | B5: 월 | C5: 카테고리 | D5: 작품명(인도네시아) | E5: 작품명 | F5: 오픈일 | G5: 구분 | H5: 유형 | I5: 거래처명 | J5: 필명 | K5: 플래폼거래액 (단위 IDR) | L5: 환율 | M5: 플래폼거래액 (단위 원) | N5: 결제 수수료 | O5: 결제수수료 (단위 원) | P5: 플래폼_순거래액 (단위 원) | Q5: KP% | R5: PAGE 매출액 (단위 원) | S5: 연동비MG (미오픈 제외) | T5: CP_RS_T% | U5: CP_RS% | V5: 당월연동비 (MG+RS) | W5: 누적연동비 | X5: 전월잔여_MG | Y5: 당월잔여_MG | Z5: 당월인식 MG | AA5: 당월초과 RS | AB5: 누적초과_RS | AC5: 비고
A6: 1 | B6: 44227 | C6: 만화 | D6: 마왕의 딸로 태어났습니다 (Aku Lahir Sebagai Anak Raja Iblis) | E6: 마왕의 딸로 태어났습니다 | F6: 44203 | G6: CP | H6: 사업자 | I6: 스토리위즈 | J6: 은민, 여울 | K6: 1.5775946e+08 | L6: 0.0783 | M6: 12352566 | N6: 0.3 | O6: 3705769.7 | P6: 8646796 | Q6: 0.5 | R6: 4323398 | S6: 6000000 | T6: 0.8 | U6: 0.8 | V6: 3458718 | W6: 3458718 | X6: 0 | Y6: 2541282 | Z6: 3458718 | AA6: 0 | AB6: 0
A7: 2 | B7: 44255 | C7: 만화 | D7: 마왕의 딸로 태어났습니다 (Aku Lahir Sebagai Anak Raja Iblis) | E7: 마왕의 딸로 태어났습니다 | F7: 44203 | G7: CP | H7: 사업자 | I7: 스토리위즈 | J7: 은민, 여울 | K7: 76836557 | L7: 0.0793 | M7: 6093139 | N7: 0.3 | O7: 1827941.7 | P7: 4265197.3 | Q7: 0.5 | R7: 2132599 | S7: 6000000 | T7: 0.8 | U7: 0.8 | V7: 1706079 | W7: 5164797 | X7: 2541282 | Y7: 835203 | Z7: 1706079 | AA7: 0 | AB7: 0
A8: 3 | B8: 44286 | C8: 만화 | D8: 마왕의 딸로 태어났습니다 (Aku Lahir Sebagai Anak Raja Iblis) | E8: 마왕의 딸로 태어났습니다 | F8: 44203 | G8: CP | H8: 사업자 | I8: 스토리위즈 | J8: 은민, 여울 | K8: 86974830 | L8: 0.0786 | M8: 6836221.6 | N8: 0.3 | O8: 2050866.5 | P8: 4785355.1 | Q8: 0.5 | R8: 2392678 | S8: 6000000 | T8: 0.8 | U8: 0.8 | V8: 1914142 | W8: 7078939 | X8: 835203 | Y8: 0 | Z8: 835203 | AA8: 1078939 | AB8: 1078939
A9: 4 | B9: 44316 | C9: 만화 | D9: 마왕의 딸로 태어났습니다 (Aku Lahir Sebagai Anak Raja Iblis) | E9: 마왕의 딸로 태어났습니다 | F9: 44203 | G9: CP | H9: 사업자 | I9: 스토리위즈 | J9: 은민, 여울 | K9: 57607559 | L9: 0.077 | M9: 4435782 | N9: 0.3 | O9: 1330734.6 | P9: 3105047.4 | Q9: 0.5 | R9: 1552524 | S9: 6000000 | T9: 0.8 | U9: 0.8 | V9: 1242019 | W9: 8320958 | X9: 0 | Y9: 0 | Z9: 0 | AA9: 1242019 | AB9: 2320958
A10: 5 | B10: 44347 | C10: 만화 | D10: 마왕의 딸로 태어났습니다 (Aku Lahir Sebagai Anak Raja Iblis) | E10: 마왕의 딸로 태어났습니다 | F10: 44203 | G10: CP | H10: 사업자 | I10: 스토리위즈 | J10: 은민, 여울 | K10: 53342150 | L10: 0.0785 | M10: 4187358.8 | N10: 0.3 | O10: 1256207.6 | P10: 2931151.2 | Q10: 0.5 | R10: 1465576 | S10: 6000000 | T10: 0.8 | U10: 0.8 | V10: 1172460 | W10: 9493418 | X10: 0 | Y10: 0 | Z10: 0 | AA10: 1172460 | AB10: 3493418
A11: 6 | B11: 44377 | C11: 만화 | D11: 마왕의 딸로 태어났습니다 (Aku Lahir Sebagai Anak Raja Iblis) | E11: 마왕의 딸로 태어났습니다 | F11: 44203 | G11: CP | H11: 사업자 | I11: 스토리위즈 | J11: 은민, 여울 | K11: 44723318 | L11: 0.0783 | M11: 3501835.8 | N11: 0.3 | O11: 1050550.7 | P11: 2451285.1 | Q11: 0.5 | R11: 1225643 | S11: 6000000 | T11: 0.8 | U11: 0.8 | V11: 980514 | W11: 10473932 | X11: 0 | Y11: 0 | Z11: 0 | AA11: 980514 | AB11: 4473932
A12: 7 | B12: 44408 | C12: 만화 | D12: 마왕의 딸로 태어났습니다 (Aku Lahir Sebagai Anak Raja Iblis) | E12: 마왕의 딸로 태어났습니다 | F12: 44203 | G12: CP | H12: 사업자 | I12: 스토리위즈 | J12: 은민, 여울 | K12: 62816006 | L12: 0.0789 | M12: 4956182.9 | N12: 0.3 | O12: 1486854.9 | P12: 3469328 | Q12: 0.5 | R12: 1734664 | S12: 6000000 | T12: 0.8 | U12: 0.8 | V12: 1387731 | W12: 11861663 | X12: 0 | Y12: 0 | Z12: 0 | AA12: 1387731 | AB12: 5861663
A13: 8 | B13: 44439 | C13: 만화 | D13: 마왕의 딸로 태어났습니다 (Aku Lahir Sebagai Anak Raja Iblis) | E13: 마왕의 딸로 태어났습니다 | F13: 44203 | G13: CP | H13: 사업자 | I13: 스토리위즈 | J13: 은민, 여울 | K13: 42831348 | L13: 0.0806 | M13: 3452206.6 | N13: 0.3 | O13: 1035662 | P13: 2416544.7 | Q13: 0.5 | R13: 1208272 | S13: 6000000 | T13: 0.8 | U13: 0.8 | V13: 966617 | W13: 12828280 | X13: 0 | Y13: 0 | Z13: 0 | AA13: 966617 | AB13: 6828280
A14: 9 | B14: 44469 | C14: 만화 | D14: 마왕의 딸로 태어났습니다 (Aku Lahir Sebagai Anak Raja Iblis) | E14: 마왕의 딸로 태어났습니다 | F14: 44203 | G14: CP | H14: 사업자 | I14: 스토리위즈 | J14: 은민, 여울 | K14: 34779614 | L14: 0.0821 | M14: 2855406.3 | N14: 0.3 | O14: 856621.9 | P14: 1998784.4 | Q14: 0.5 | R14: 999392 | S14: 6000000 | T14: 0.8 | U14: 0.8 | V14: 799513 | W14: 13627793 | X14: 0 | Y14: 0 | Z14: 0 | AA14: 799513 | AB14: 7627793
A15: 10 | B15: 44500 | C15: 만화 | D15: 마왕의 딸로 태어났습니다 (Aku Lahir Sebagai Anak Raja Iblis) | E15: 마왕의 딸로 태어났습니다 | F15: 44203 | G15: CP | H15: 사업자 | I15: 스토리위즈 | J15: 은민, 여울 | K15: 23910433 | L15: 0.0835 | M15: 1996521.2 | N15: 0.3 | O15: 598956.35 | P15: 1397564.8 | Q15: 0.5 | R15: 698782 | S15: 6000000 | T15: 0.8 | U15: 0.8 | V15: 559025 | W15: 14186818 | X15: 0 | Y15: 0 | Z15: 0 | AA15: 559025 | AB15: 8186818
A16: 11 | B16: 44530 | C16: 만화 | D16: 마왕의 딸로 태어났습니다 (Aku Lahir Sebagai Anak Raja Iblis) | E16: 마왕의 딸로 태어났습니다 | F16: 44203 | G16: CP | H16: 사업자 | I16: 스토리위즈 | J16: 은민, 여울 | K16: 10520150 | L16: 0.083 | M16: 873172.48 | N16: 0.3 | O16: 261951.74 | P16: 611220.74 | Q16: 0.5 | R16: 305610 | S16: 6000000 | T16: 0.8 | U16: 0.8 | V16: 244488 | W16: 14431306 | X16: 0 | Y16: 0 | Z16: 0 | AA16: 244488 | AB16: 8431306
A17: 3 | B17: 44561 | C17: 만화 | D17: 마왕의 딸로 태어났습니다 (Aku Lahir Sebagai Anak Raja Iblis) | E17: 마왕의 딸로 태어났습니다 | F17: 44203 | G17: CP | H17: 사업자 | I17: 스토리위즈 | J17: 은민, 여울 | K17: 8024294.4 | L17: 0.0826 | M17: 662806.72 | N17: 0.3 | O17: 198842.02 | P17: 463964.7 | Q17: 0.5 | R17: 231982 | S17: 6000000 | T17: 0.8 | U17: 0.8 | V17: 185585 | W17: 14616891 | X17: 0 | Y17: 0 | Z17: 0 | AA17: 185585 | AB17: 8616891
B18: 44592 | C18: 만화 | D18: 마왕의 딸로 태어났습니다 (Aku Lahir Sebagai Anak Raja Iblis) | E18: 마왕의 딸로 태어났습니다 | F18: 44203 | G18: CP | H18: 사업자 | I18: 스토리위즈 | J18: 은민, 여울 | K18: 5681448 | L18: 0.0833 | M18: 473264.62 | N18: 0.3 | O18: 141979.39 | P18: 331285.23 | Q18: 0.5 | R18: 165643 | S18: 6000000 | T18: 0.8 | U18: 0.8 | V18: 132514 | W18: 14749405 | X18: 0 | Y18: 0 | Z18: 0 | AA18: 132514 | AB18: 8749405
A19: 3 | B19: 44620 | C19: 만화 | D19: 마왕의 딸로 태어났습니다 (Aku Lahir Sebagai Anak Raja Iblis) | E19: 마왕의 딸로 태어났습니다 | F19: 44203 | G19: CP | H19: 사업자 | I19: 스토리위즈 | J19: 은민, 여울 | K19: 6036930 | L19: 0.0835 | M19: 504083.65 | N19: 0.3 | O19: 151225.1 | P19: 352858.56 | Q19: 0.5 | R19: 176429 | S19: 6000000 | T19: 0.8 | U19: 0.8 | V19: 141143 | W19: 14890548 | X19: 0 | Y19: 0 | Z19: 0 | AA19: 141143 | AB19: 8890548
A20: 3 | B20: 44651 | C20: 만화 | D20: 마왕의 딸로 태어났습니다 (Aku Lahir Sebagai Anak Raja Iblis) | E20: 마왕의 딸로 태어났습니다 | F20: 44203 | G20: CP | H20: 사업자 | I20: 스토리위즈 | J20: 은민, 여울 | K20: 5162404.8 | L20: 0.0851 | M20: 439320.65 | N20: 0.3 | O20: 131796.19 | P20: 307524.45 | Q20: 0.5 | R20: 153762 | S20: 6000000 | T20: 0.8 | U20: 0.8 | V20: 123009 | W20: 15013557 | X20: 0 | Y20: 0 | Z20: 0 | AA20: 123009 | AB20: 9013557
A22: NO | B22: 월 | C22: 카테고리 | D22: 작품명(인도네시아) | E22: 작품명 | F22: 오픈일 | G22: 구분 | H22: 유형 | I22: 거래처명 | J22: 필명 | K22: 플래폼거래액 (단위 IDR) | L22: 환율 | M22: 플래폼거래액 (단위 원) | N22: 결제 수수료 | O22: 결제수수료 (단위 원) | P22: 플래폼_순거래액 (단위 원) | Q22: KP% | R22: PAGE 매출액 (단위 원) | S22: 연동비MG (미오픈 제외) | T22: CP_RS_T% | U22: CP_RS% | V22: 당월연동비 (MG+RS) | W22: 누적연동비 | X22: 전월잔여_MG | Y22: 당월잔여_MG | Z22: 당월인식 MG | AA22: 당월초과 RS | AB22: 누적초과_RS | AC22: 비고
A23: 1 | B23: 44439 | C23: 만화 | D23: 공주전쟁 (Pertarungan Para Putri) | E23: 공주전쟁 | F23: 44426 | G23: CP | H23: 사업자 | I23: 스토리위즈 | J23: HujingxLuojie | K23: 54212326 | L23: 0.0806 | M23: 4369513.5 | N23: 0.3 | O23: 1310854 | P23: 3058659.4 | Q23: 0.35 | R23: 1529330 | S23: 3000000 | T23: 1 | U23: 1 | V23: 1529330 | W23: 1529330 | X23: 0 | Y23: 1470670 | Z23: 1529330 | AA23: 0 | AB23: 0
A24: 1 | B24: 44469 | C24: 만화 | D24: 공주전쟁 (Pertarungan Para Putri) | E24: 공주전쟁 | F24: 44426 | G24: CP | H24: 사업자 | I24: 스토리위즈 | J24: HujingxLuojie | K24: 8887709.6 | L24: 0.0821 | M24: 729680.96 | N24: 0.3 | O24: 218904.29 | P24: 510776.67 | Q24: 0.35 | R24: 255388 | S24: 3000000 | T24: 1 | U24: 1 | V24: 255388 | W24: 1784718 | X24: 1470670 | Y24: 1215282 | Z24: 255388 | AA24: 0 | AB24: 0
A25: 1 | B25: 44500 | C25: 만화 | D25: 공주전쟁 (Pertarungan Para Putri) | E25: 공주전쟁 | F25: 44426 | G25: CP | H25: 사업자 | I25: 스토리위즈 | J25: HujingxLuojie | K25: 5337591 | L25: 0.0835 | M25: 445688.85 | N25: 0.3 | O25: 133706.65 | P25: 311982.19 | Q25: 0.35 | R25: 155991 | S25: 3000000 | T25: 1 | U25: 1 | V25: 155991 | W25: 1940709 | X25: 1215282 | Y25: 1059291 | Z25: 155991 | AA25: 0 | AB25: 0
A26: 1 | B26: 44561 | C26: 만화 | D26: 공주전쟁 (Pertarungan Para Putri) | E26: 공주전쟁 | F26: 44426 | G26: CP | H26: 사업자 | I26: 스토리위즈 | J26: HujingxLuojie | K26: 2878971.2 | L26: 0.0826 | M26: 237803.02 | N26: 0.3 | O26: 71340.906 | P26: 166462.11 | Q26: 0.35 | R26: 83231 | S26: 3000000 | T26: 1 | U26: 1 | V26: 83231 | W26: 2159547 | X26: 923684 | Y26: 840453 | Z26: 83231 | AA26: 0 | AB26: 0
B27: 44592 | C27: 만화 | D27: 공주전쟁 (Pertarungan Para Putri) | E27: 공주전쟁 | F27: 44426 | G27: CP | H27: 사업자 | I27: 스토리위즈 | J27: HujingxLuojie | K27: 2484720 | L27: 0.0833 | M27: 206977.18 | N27: 0.3 | O27: 62093.153 | P27: 144884.02 | Q27: 0.35 | R27: 72442 | S27: 3000000 | T27: 1 | U27: 1 | V27: 72442 | W27: 2231989 | X27: 840453 | Y27: 768011 | Z27: 72442 | AA27: 0 | AB27: 0
B28: 44620 | C28: 만화 | D28: 공주전쟁 (Pertarungan Para Putri) | E28: 공주전쟁 | F28: 44426 | G28: CP | H28: 사업자 | I28: 스토리위즈 | J28: HujingxLuojie | K28: 1605933 | L28: 0.0835 | M28: 134095.41 | N28: 0.3 | O28: 40228.622 | P28: 93866.784 | Q28: 0.35 | R28: 46933 | S28: 3000000 | T28: 1 | U28: 1 | V28: 46933 | W28: 2278922 | X28: 768011 | Y28: 721078 | Z28: 46933 | AA28: 0 | AB28: 0
A29: 1 | B29: 44651 | C29: 만화 | D29: 공주전쟁 (Pertarungan Para Putri) | E29: 공주전쟁 | F29: 44426 | G29: CP | H29: 사업자 | I29: 스토리위즈 | J29: HujingxLuojie | K29: 2120602.4 | L29: 0.0851 | M29: 180463.26 | N29: 0.3 | O29: 54138.979 | P29: 126324.28 | Q29: 0.35 | R29: 63162 | S29: 3000000 | T29: 1 | U29: 1 | V29: 63162 | W29: 2342084 | X29: 721078 | Y29: 657916 | Z29: 63162 | AA29: 0 | AB29: 0

Sheet 월별 매출(구KT)
A1: 월별 매출 정산내역
D3: TOTAL | K3: =SUBTOTAL(9,M6:M9851) -> 697504.31 | M3: =SUBTOTAL(9,O6:O9851) -> 209251.29 | O3: =SUBTOTAL(9,Q6:Q9851) -> 9 | P3: =SUBTOTAL(9,R6:R9851) -> 244127 | R3: =SUBTOTAL(9,T6:T9851) -> 14.4 | V3: =SUBTOTAL(9,X6:X9851) -> 24939579 | Z3: =SUBTOTAL(9,AB6:AB9851) -> 2040928 | AA3: =SUBTOTAL(9,AC6:AC9851) -> 0
A5: NO | B5: 월 | C5: 카테고리 | D5: 작품명(인도네시아) | E5: 작품명 | F5: 오픈일 | G5: 구분 | H5: 유형 | I5: 거래처명 | J5: 필명 | K5: 플래폼거래액 (단위 IDR) | L5: 환율 | M5: 플래폼거래액 (단위 원) | N5: 결제 수수료 | O5: 결제수수료 (단위 원) | P5: 플래폼_순거래액 (단위 원) | Q5: KP% | R5: PAGE 매출액 (단위 원) | S5: 연동비MG (미오픈 제외) | T5: CP_RS_T% | U5: CP_RS% | V5: 당월연동비 (MG+RS) | W5: 누적연동비 | X5: 전월잔여_MG | Y5: 당월잔여_MG | Z5: 당월인식 MG | AA5: 당월초과 RS | AB5: 누적초과_RS | AC5: 비고
A6: 1 | B6: 44439 | C6: 만화 | D6: 마왕의 아이를 키우는 법 (How to Raise the Devil's Child) | E6: 마왕의 아이를 키우는 방법 (7월분) | F6: 43886 | G6: CP | H6: 사업자 | I6: 케이티 | J6: 이어원,최누리 | K6: 2308545.6 | L6: 0.0789 | M6: 182144.25 | N6: 0.3 | O6: 54643.274 | P6: 127500.97 | Q6: 0.5 | R6: 63750 | S6: 4000000 | T6: 0.8 | U6: 0.8 | V6: 51000 | W6: 4152651 | X6: 0 | Y6: 0 | Z6: 0 | AA6: 51000 | AB6: 152651 | AC6: 작품 이관으로 케이티 7월분 매출 추가
A7: 2 | B7: 44439 | C7: 만화 | D7: 마왕의 아이를 키우는 법 (How to Raise the Devil's Child) | E7: 마왕의 아이를 키우는 방법 | F7: 43886 | G7: CP | H7: 사업자 | I7: 스토리위즈 | J7: 이어원,최누리 | K7: 1653456 | L7: 0.0806 | M7: 133268.55 | N7: 0.3 | O7: 39980.566 | P7: 93287.988 | Q7: 0.5 | R7: 46644 | S7: 4000000 | T7: 0.8 | U7: 0.8 | V7: 37315 | W7: 4189966 | X7: 0 | Y7: 0 | Z7: 0 | AA7: 37315 | AB7: 189966 | AC7: 작품 이관 (케이티 → 스토리위즈)
A8: 3 | B8: 44469 | C8: 만화 | D8: 마왕의 아이를 키우는 법 (How to Raise the Devil's Child) | E8: 마왕의 아이를 키우는 방법 | F8: 43886 | G8: CP | H8: 사업자 | I8: 스토리위즈 | J8: 이어원,최누리 | K8: 877332 | L8: 0.0821 | M8: 72028.957 | N8: 0.3 | O8: 21608.687 | P8: 50420.27 | Q8: 0.5 | R8: 25210 | S8: 4000000 | T8: 0.8 | U8: 0.8 | V8: 20168 | W8: 4210134 | X8: 0 | Y8: 0 | Z8: 0 | AA8: 20168 | AB8: 210134
A9: 4 | B9: 44500 | C9: 만화 | D9: 마왕의 아이를 키우는 법 (How to Raise the Devil's Child) | E9: 마왕의 아이를 키우는 방법 | F9: 43886 | G9: CP | H9: 사업자 | I9: 스토리위즈 | J9: 이어원,최누리 | K9: 724842 | L9: 0.0835 | M9: 60524.307 | N9: 0.3 | O9: 18157.292 | P9: 42367.015 | Q9: 0.5 | R9: 21184 | S9: 4000000 | T9: 0.8 | U9: 0.8 | V9: 16947 | W9: 4227081 | X9: 0 | Y9: 0 | Z9: 0 | AA9: 16947 | AB9: 227081
A10: 5 | B10: 44501 | C10: 만화 | D10: 마왕의 아이를 키우는 법 (How to Raise the Devil's Child) | E10: 마왕의 아이를 키우는 방법 | F10: 43886 | G10: CP | H10: 사업자 | I10: 스토리위즈 | J10: 이어원,최누리 | K10: 406848 | L10: 0.083 | M10: 33768.384 | N10: 0.3 | O10: 10130.515 | P10: 23637.869 | Q10: 0.5 | R10: 11819 | S10: 4000000 | T10: 0.8 | U10: 0.8 | V10: 9455 | W10: 4236536 | X10: 0 | Y10: 0 | Z10: 0 | AA10: 9455 | AB10: 236536
A11: 1 | B11: 44561 | C11: 만화 | D11: 마왕의 아이를 키우는 법 (How to Raise the Devil's Child) | E11: 마왕의 아이를 키우는 방법 | F11: 43886 | G11: CP | H11: 사업자 | I11: 스토리위즈 | J11: 이어원,최누리 | K11: 339561.6 | L11: 0.0826 | M11: 28047.788 | N11: 0.3 | O11: 8414.3364 | P11: 19633.452 | Q11: 0.5 | R11: 9817 | S11: 4000000 | T11: 0.8 | U11: 0.8 | V11: 7853 | W11: 4244389 | X11: 0 | Y11: 0 | Z11: 0 | AA11: 7853 | AB11: 244389
B12: 44592 | C12: 만화 | D12: 마왕의 아이를 키우는 법 (How to Raise the Devil's Child) | E12: 마왕의 아이를 키우는 방법 | F12: 43886 | G12: CP | H12: 사업자 | I12: 스토리위즈 | J12: 이어원,최누리 | K12: 335124 | L12: 0.0833 | M12: 27915.829 | N12: 0.3 | O12: 8374.7488 | P12: 19541.08 | Q12: 0.5 | R12: 9771 | S12: 4000000 | T12: 0.8 | U12: 0.8 | V12: 7816 | W12: 4252205 | X12: 0 | Y12: 0 | Z12: 0 | AA12: 7816 | AB12: 252205
A13: 1 | B13: 44620 | C13: 만화 | D13: 마왕의 아이를 키우는 법 (How to Raise the Devil's Child) | E13: 마왕의 아이를 키우는 방법 | F13: 43886 | G13: CP | H13: 사업자 | I13: 스토리위즈 | J13: 이어원,최누리 | K13: 317898 | L13: 0.0835 | M13: 26544.483 | N13: 0.3 | O13: 7963.3449 | P13: 18581.138 | Q13: 0.5 | R13: 9291 | S13: 4000000 | T13: 0.8 | U13: 0.8 | V13: 7432 | W13: 4259637 | X13: 0 | Y13: 0 | Z13: 0 | AA13: 7432 | AB13: 259637
A14: 1 | B14: 44651 | C14: 만화 | D14: 마왕의 아이를 키우는 법 (How to Raise the Devil's Child) | E14: 마왕의 아이를 키우는 방법 | F14: 43886 | G14: CP | H14: 사업자 | I14: 스토리위즈 | J14: 이어원,최누리 | K14: 364795.2 | L14: 0.0851 | M14: 31044.072 | N14: 0.3 | O14: 9313.2215 | P14: 21730.85 | Q14: 0.5 | R14: 10865 | S14: 4000000 | T14: 0.8 | U14: 0.8 | V14: 8692 | W14: 4268329 | X14: 0 | Y14: 0 | Z14: 0 | AA14: 8692 | AB14: 268329
A16: 월별 매출 정산내역
D18: TOTAL | K18: =SUBTOTAL(9,M21:M9863) -> 102217.69 | M18: =SUBTOTAL(9,O21:O9863) -> 30665.306 | O18: =SUBTOTAL(9,Q21:Q9863) -> 4.5 | P18: =SUBTOTAL(9,R21:R9863) -> 35776 | R18: =SUBTOTAL(9,T21:T9863) -> 7.2 | V18: =SUBTOTAL(9,X21:X9863) -> 24939579 | Z18: =SUBTOTAL(9,AB21:AB9863) -> 0 | AA18: =SUBTOTAL(9,AC21:AC9863) -> 0
A20: NO | B20: 월 | C20: 카테고리 | D20: 작품명(인도네시아) | E20: 작품명 | F20: 오픈일 | G20: 구분 | H20: 유형 | I20: 거래처명 | J20: 필명 | K20: 플래폼거래액 (단위 IDR) | L20: 환율 | M20: 플래폼거래액 (단위 원) | N20: 결제 수수료 | O20: 결제수수료 (단위 원) | P20: 플래폼_순거래액 (단위 원) | Q20: KP% | R20: PAGE 매출액 (단위 원) | S20: 연동비MG (미오픈 제외) | T20: CP_RS_T% | U20: CP_RS% | V20: 당월연동비 (MG+RS) | W20: 누적연동비 | X20: 전월잔여_MG | Y20: 당월잔여_MG | Z20: 당월인식 MG | AA20: 당월초과 RS | AB20: 누적초과_RS | AC20: 비고
A21: 1 | B21: 44439 | C21: 만화 | D21: not alone (Not Alone) | E21: Not Alone (7월분) | F21: 44073 | G21: CP | H21: 사업자 | I21: 케이티 | J21: fee1 | K21: 246513.6 | L21: 0.0789 | M21: 19449.923 | N21: 0.3 | O21: 5834.9769 | P21: 13614.946 | Q21: 0.5 | R21: 6807 | S21: 3000000 | T21: 0.8 | U21: 0.8 | V21: 5445 | W21: 218004 | X21: 2787441 | Y21: 2781996 | Z21: 5445 | AA21: 0 | AB21: 0 | AC21: 작품 이관으로 케이티 7월분 매출 추가
A22: 2 | B22: 44439 | C22: 만화 | D22: not alone (Not Alone) | E22: Not Alone | F22: 44073 | G22: CP | H22: 사업자 | I22: 스토리위즈 | J22: fee1 | K22: 161616 | L22: 0.0806 | M22: 13026.25 | N22: 0.3 | O22: 3907.8749 | P22: 9118.3747 | Q22: 0.5 | R22: 4559 | S22: 3000000 | T22: 0.8 | U22: 0.8 | V22: 3647 | W22: 221651 | X22: 2781996 | Y22: 2778349 | Z22: 3647 | AA22: 0 | AB22: 0 | AC22: 작품 이관 (케이티 → 스토리위즈)
A23: 3 | B23: 44469 | C23: 만화 | D23: not alone (Not Alone) | E23: Not Alone | F23: 44073 | G23: CP | H23: 사업자 | I23: 스토리위즈 | J23: fee1 | K23: 139752 | L23: 0.0821 | M23: 11473.639 | N23: 0.3 | O23: 3442.0918 | P23: 8031.5474 | Q23: 0.5 | R23: 4016 | S23: 3000000 | T23: 0.8 | U23: 0.8 | V23: 3212 | W23: 224863 | X23: 2778349 | Y23: 2775137 | Z23: 3212 | AA23: 0 | AB23: 0
A24: 4 | B24: 44500 | C24: 만화 | D24: not alone (Not Alone) | E24: Not Alone | F24: 44073 | G24: CP | H24: 사업자 | I24: 스토리위즈 | J24: fee1 | K24: 342936 | L24: 0.0835 | M24: 28635.156 | N24: 0.3 | O24: 8590.5468 | P24: 20044.609 | Q24: 0.5 | R24: 10022 | S24: 3000000 | T24: 0.8 | U24: 0.8 | V24: 8017 | W24: 232880 | X24: 2775137 | Y24: 2767120 | Z24: 8017 | AA24: 0 | AB24: 0
A25: 5 | B25: 44530 | C25: 만화 | D25: not alone (Not Alone) | E25: Not Alone | F25: 44073 | G25: CP | H25: 사업자 | I25: 스토리위즈 | J25: fee1 | K25: 145526.4 | L25: 0.083 | M25: 12078.691 | N25: 0.3 | O25: 3623.6074 | P25: 8455.0838 | Q25: 0.5 | R25: 4228 | S25: 3000000 | T25: 0.8 | U25: 0.8 | V25: 3382 | W25: 236262 | X25: 2767120 | Y25: 2763738 | Z25: 3382 | AA25: 0 | AB25: 0
A26: 6 | B26: 44561 | C26: 만화 | D26: not alone (Not Alone) | E26: Not Alone | F26: 44073 | G26: CP | H26: 사업자 | I26: 스토리위즈 | J26: fee1 | K26: 37555.2 | L26: 0.0826 | M26: 3102.0595 | N26: 0.3 | O26: 930.61786 | P26: 2171.4417 | Q26: 0.5 | R26: 1086 | S26: 3000000 | T26: 0.8 | U26: 0.8 | V26: 868 | W26: 237130 | X26: 2763738 | Y26: 2762870 | Z26: 868 | AA26: 0 | AB26: 0
A27: 7 | B27: 44592 | C27: 만화 | D27: not alone (Not Alone) | E27: Not Alone | F27: 44073 | G27: CP | H27: 사업자 | I27: 스토리위즈 | J27: fee1 | K27: 39150 | L27: 0.0833 | M27: 3261.195 | N27: 0.3 | O27: 978.3585 | P27: 2282.8365 | Q27: 0.5 | R27: 1141 | S27: 3000000 | T27: 0.8 | U27: 0.8 | V27: 912 | W27: 238042 | X27: 2762870 | Y27: 2761958 | Z27: 912 | AA27: 0 | AB27: 0
A28: 2 | B28: 44620 | C28: 만화 | D28: not alone (Not Alone) | E28: Not Alone | F28: 44073 | G28: CP | H28: 사업자 | I28: 스토리위즈 | J28: fee1 | K28: 42282 | L28: 0.0835 | M28: 3530.547 | N28: 0.3 | O28: 1059.1641 | P28: 2471.3829 | Q28: 0.5 | R28: 1236 | S28: 3000000 | T28: 0.8 | U28: 0.8 | V28: 988 | W28: 239030 | X28: 2761958 | Y28: 2760970 | Z28: 988 | AA28: 0 | AB28: 0
A29: 2 | B29: 44651 | C29: 만화 | D29: not alone (Not Alone) | E29: Not Alone | F29: 44073 | G29: CP | H29: 사업자 | I29: 스토리위즈 | J29: fee1 | K29: 90014.4 | L29: 0.0851 | M29: 7660.2254 | N29: 0.3 | O29: 2298.0676 | P29: 5362.1578 | Q29: 0.5 | R29: 2681 | S29: 3000000 | T29: 0.8 | U29: 0.8 | V29: 2144 | W29: 241174 | X29: 2760970 | Y29: 2758826 | Z29: 2144 | AA29: 0 | AB29: 0
