Workbook

Sheet 합계
B2: ■ 만화가족 2022.10월 KT 정산서 | J2: *익익월 입금
J3: 선지급금 | K3: 512710000
B4: 사이트명 | C4: 소비자매출액 | D4: 유통사수수료 | E4: 케이티매출액 | F4: 케이티수익 | G4: 만화가족 수익 | H4: 비고 | J4: KT프로젝트수익 | K4: 125000000
B5: 카카오페이지1 | C5: =카카오페이지1!D12 -> 85300815 | D5: =카카오페이지1!E12 -> 0 | E5: =카카오페이지1!F12 -> 85300815 | F5: =카카오페이지1!G12 -> 17060163 | G5: =카카오페이지1!H12 -> 68240652 | H5: 연재고료 | J5: 월별 회수금 (케이티 수익)
B6: 카카오페이지2 | C6: =카카오페이지2!D6 -> 9965195 | D6: =카카오페이지2!E6 -> 3839383 | E6: =카카오페이지2!F6 -> 6125812 | F6: =카카오페이지2!G6 -> 1225162.4 | G6: =카카오페이지2!H6 -> 4900649.6 | H6: 유료판매 | J6: 2018. 08 | K6: 14506621 | L6: 입금
B7: 네이버웹툰1 | C7: =네이버웹툰1!D6 -> 6700000 | D7: =네이버웹툰1!E6 -> 0 | E7: =네이버웹툰1!F6 -> 6700000 | F7: =네이버웹툰1!G6 -> 1340000 | G7: =네이버웹툰1!H6 -> 5360000 | H7: 연재고료 | J7: 2018. 09 | K7: 8562269 | L7: 입금
B8: 네이버웹툰2 | C8: =네이버웹툰2!D36 -> 208670094 | D8: =네이버웹툰2!E36 -> 97259791 | E8: =네이버웹툰2!F36 -> 111410303 | F8: =네이버웹툰2!G36 -> 22282061 | G8: =네이버웹툰2!H36 -> 89128242 | H8: 유료판매 | J8: 2018. 10 | K8: 17036883 | L8: 입금
B9: 테크앤조이 | C9: =테크앤조이!D4 -> 0 | D9: =테크앤조이!E4 -> 0 | E9: =테크앤조이!F4 -> 0 | F9: =테크앤조이!G4 -> 0 | G9: =테크앤조이!H4 -> 0 | H9: 유료판매 | J9: 2018. 11 | K9: 30825944 | L9: 입금
B10: 키다리스튜디오 | C10: =키다리스튜디오!D6 -> 11957350 | D10: =키다리스튜디오!E6 -> 6307622 | E10: =키다리스튜디오!F6 -> 5649728 | F10: =키다리스튜디오!G6 -> 1129945.6 | G10: =키다리스튜디오!H6 -> 4519782.4 | H10: 유료판매 | J10: 2018. 12 | K10: 17198136 | L10: 입금
B11: 탑툰 | C11: =탑툰!D4 -> 1034633 | D11: =네이버웹툰1!E10 -> 0 | E11: =탑툰!F4 -> 1034633 | F11: =탑툰!G4 -> 206926.6 | G11: =탑툰!H4 -> 827706.4 | H11: 유료판매 | J11: 2018년 합계 | K11: =SUM(K6:K10) -> 88129853
B12: 리디 | C12: =리디!D4 -> 11017001 | D12: =리디!E4 -> 0 | E12: =리디!F4 -> 11017001 | F12: =리디!G4 -> 2203400.2 | G12: =리디!H4 -> 8813600.8 | H12: 유료판매 | J12: 2019.01 | K12: 17,908,333 | L12: 입금
B13: 합계 | C13: =SUM(C5:C12) -> 334645088 | D13: =SUM(D5:D12) -> 107406796 | E13: =SUM(E5:E12) -> 227238292 | F13: =SUM(F5:F12) -> 45447658 | G13: =SUM(G5:G12) -> 1.8179063e+08 | J13: 2019.02 | K13: 40642286 | L13: 입금
B14: ＊각 플랫폼 데이터는 시트 추가하여 작성, 합계 표로 가져와 총 정산금액 정리 | F14: =E13*0.2 -> 45447658 | G14: =E13*0.8 -> 1.8179063e+08 | J14: 2019.03 | K14: 28776392 | L14: 입금
J15: 2019.04 | K15: 17432662 | L15: 입금
J16: 2019.05 | K16: 35056871 | L16: 입금
J17: 2019.06 | K17: 33089659 | L17: 입금
B18: 구분 | D18: 금액 | J18: 2019.07 | K18: 17278906 | L18: 입금
B19: 스토리위즈 > 만화가족 계산서 발행 금액 | D19: =F13 -> 45447658 | J19: 2019.08 | K19: 24626732 | L19: 입금
J20: 2019.09 | K20: 27140688 | L20: 입금
J21: 2019.10 | K21: 29171298 | L21: 입금
J22: 2019.11 | K22: 15744187 | L22: 입금
J23: 2019.12 | K23: 18683634 | L23: 입금
J24: 2019년 합계 | K24: =SUM(K12:K23) -> 287643315
J25: 2020.01 | K25: 25963688 | L25: 입금
J26: 2020.02 | K26: 24673815 | L26: 입금 | M26: 입금 : 스토리위즈
J27: 2020.03 | K27: 24315434 | L27: 입금
J28: 2020.04 | K28: 31918486 | L28: 입금
J29: 2020.05 | K29: 27302553 | L29: 입금
J30: 2020.06 | K30: 25712668 | L30: 입금
J31: 2020.07 | K31: 29131889 | L31: 입금
J32: 2020.08 | K32: 27059690 | L32: 입금
J33: 2020.09 | K33: 34344144 | L33: 입금
J34: 2020.10 | K34: 27618375 | L34: 입금
J35: 2020.11 | K35: 18666794 | L35: 입금 | M35: 11/10초과분 18,000원 차감 후 지급
J36: 2020.12 | K36: 22399933 | L36: 입금
J37: 2020년 합계 | K37: =SUM(K25:K36) -> 319107469
J38: 2021.01 | K38: 25525201 | L38: 입금
J39: 2021.02 | K39: 23838777 | L39: 입금
J40: 2021.03 | K40: 19328258 | L40: 입금
J41: 2021.04 | K41: 20722060 | L41: 입금
...

Sheet 계정정보
B2: ■ 만화가족 유통계정정보
B4: 서비스명 | C4: 아이디 | D4: 패스워드 | E4: URL
B5: 카카오페이지 | C5: toonsfamily11 | D5: aocnf60djr! | E5: https://biz.kakaopage.com/partner/login
B6: 네이버 | C6: FRA01967 | D6: Good2seeu! | E6: https://friend.navercorp.com/login/loginForm.sec?url=%2Fview%2Fsvc%2Fmain%3FsvcId%3DCOM%26lz%3Dko_KR%26tz%3DAsia%252FSeoul%253A%252B09%253A00&c=d# | F6: 구작
C7: FRA09683 | D7: aocnf60djr! | E7: https://friend.navercorp.com/login/loginForm.sec?url=%2Fview%2Fsvc%2Fmain%3FsvcId%3DCOM%26lz%3Dko_KR%26tz%3DAsia%252FSeoul%253A%252B09%253A00&c=d# | F7: 악마와계약연애
C8: FRA07849 | D8: aocnf60djr! | E8: https://friend.navercorp.com/login/loginForm.sec?url=%2Fview%2Fsvc%2Fmain%3FsvcId%3DCOM%26lz%3Dko_KR%26tz%3DAsia%252FSeoul%253A%252B09%253A00&c=d# | F8: 반투명인간
C9: FRA08900 | D9: Epemfkdlvm8! | E9: https://friend.navercorp.com/login/loginForm.sec?url=%2Fview%2Fsvc%2Fmain%3FsvcId%3DCOM%26lz%3Dko_KR%26tz%3DAsia%252FSeoul%253A%252B09%253A00&c=d# | F9: 데드라이프
C10: FRA07850 | D10: aocnf60djr! | E10: https://friend.navercorp.com/login/loginForm.sec?url=%2Fview%2Fsvc%2Fmain%3FsvcId%3DCOM%26lz%3Dko_KR%26tz%3DAsia%252FSeoul%253A%252B09%253A00&c=d# | F10: 황금의핸드메이커
C11: FRA09684 | D11: aocnf60djr! | E11: https://friend.navercorp.com/login/loginForm.sec?url=%2Fview%2Fsvc%2Fmain%3FsvcId%3DCOM%26lz%3Dko_KR%26tz%3DAsia%252FSeoul%253A%252B09%253A00&c=d# | F11: 나를바꿔줘
C12: FRA09669 | D12: aocnf60djr! | E12: https://friend.navercorp.com/login/loginForm.sec?url=%2Fview%2Fsvc%2Fmain%3FsvcId%3DCOM%26lz%3Dko_KR%26tz%3DAsia%252FSeoul%253A%252B09%253A00&c=d# | F12: 그녀의 버킷리스트

Sheet 카카오페이지1
B2: 사이트명 | C2: 작품명 | D2: 소비자매출액 | E2: 유통사수수료 | F2: 케이티매출액 | G2: 케이티수익 | H2: 만화가족 수익 | I2: 비고
B3: 카카오페이지 | C3: 부기영화 | D3: 4000000 | E3: 0 | F3: =D3 -> 4000000 | G3: =F3*20% -> 800000 | H3: =F3*80% -> 3200000 | I3: 10월 MG (요율 : 약 60%, 카카오페이지 약관에 따름)
B4: 카카오페이지 | C4: 더익스트림 | D4: 3600000 | E4: 0 | F4: =D4 -> 3600000 | G4: =F4*20% -> 720000 | H4: =F4*80% -> 2880000 | I4: 10월 MG (요율 : 약 60%, 카카오페이지 약관에 따름)
B5: 카카오페이지 | C5: 웽 | D5: 5250000 | E5: 0 | F5: =D5 -> 5250000 | G5: =F5*20% -> 1050000 | H5: =F5*80% -> 4200000 | I5: 10월 MG (요율 : 약 60%, 카카오페이지 약관에 따름)
B6: 카카오페이지 | C6: 겁쟁이피지컬 | D6: 3400000 | E6: 0 | F6: =D6 -> 3400000 | G6: =F6*20% -> 680000 | H6: =F6*80% -> 2720000 | I6: 10월 MG (요율 : 약 60%, 카카오페이지 약관에 따름)
B7: 카카오페이지 | C7: 애착인형 | D7: 50000000 | E7: 0 | F7: =D7 -> 50000000 | G7: =F7*20% -> 10000000 | H7: =F7*80% -> 40000000 | I7: 10월 MG (요율 : 약 60%, 카카오페이지 약관에 따름)
B8: 카카오페이지 | C8: 재밌니짝사랑 | D8: 4683605 | E8: 0 | F8: =D8 -> 4683605 | G8: =F8*20% -> 936721 | H8: =F8*80% -> 3746884 | I8: 글로벌MG (요율 : 약 60%, 카카오페이지 약관에 따름)
B9: 카카오페이지 | C9: 그림자미녀 | D9: 4683605 | E9: 0 | F9: =D9 -> 4683605 | G9: =F9*20% -> 936721 | H9: =F9*80% -> 3746884 | I9: 글로벌MG (요율 : 약 60%, 카카오페이지 약관에 따름)
B10: 카카오페이지 | C10: 남자친구를조심해 | D10: 4683605 | E10: 0 | F10: =D10 -> 4683605 | G10: =F10*20% -> 936721 | H10: =F10*80% -> 3746884 | I10: 글로벌MG (요율 : 약 60%, 카카오페이지 약관에 따름)
B11: 카카오페이지 | C11: 홈파이브 | D11: 5000000 | E11: 0 | F11: =D11 -> 5000000 | G11: =F11*20% -> 1000000 | H11: =F11*80% -> 4000000 | I11: 글로벌MG (요율 : 약 60%, 카카오페이지 약관에 따름)
B12: 합계 | D12: =SUM(D3:D11) -> 85300815 | E12: =SUM(E3:E11) -> 0 | F12: =SUM(F3:F11) -> 85300815 | G12: =SUM(G3:G11) -> 17060163 | H12: =SUM(H3:H11) -> 68240652
G13: =F12*0.2 -> 17060163 | H13: =F12*0.8 -> 68240652

Sheet 카카오페이지2
B2: 사이트명 | C2: 작품명 | D2: 소비자매출액 | E2: 유통사수수료 | F2: 케이티매출액 | G2: 케이티수익 | H2: 만화가족 수익 | I2: 비고
B3: 카카오페이지 | C3: 우리집아이돌 | D3: =AG32 -> 266214 | E3: =D3-F3 -> 113494 | F3: 152720 | G3: =F3*20% -> 30544 | H3: =F3*80% -> 122176 | I3: 9월 초과수익
B4: 카카오페이지 | C4: 재밌니짝사랑 | D4: =AG21 -> 4205288 | E4: =D4-F4 -> 1852207 | F4: 2353081 | G4: =F4*20% -> 470616.2 | H4: =F4*80% -> 1882464.8 | I4: 9월 초과수익
B5: 카카오페이지 | C5: 날라리 外 | D5: 5493693 | E5: =D5-F5 -> 1873682 | F5: 3620011 | G5: =F5*20% -> 724002.2 | H5: =F5*80% -> 2896008.8 | I5: 픽코마 9월 RS
B6: 합계 | D6: =SUM(D3:D5) -> 9965195 | E6: =SUM(E3:E5) -> 3839383 | F6: =SUM(F3:F5) -> 6125812 | G6: =SUM(G3:G5) -> 1225162.4 | H6: =SUM(H3:H5) -> 4900649.6
G7: =F6*0.2 -> 1225162.4 | H7: =F6*0.8 -> 4900649.6
A10: <재밌니짝사랑> 7월
A11: 기초정보 | T11: 거래액(캐시) | AA11: 거래액(원화) | AH11: 순매출액 | AO11: 정산율(%) | AS11: 정산금액
A12: 특별/일반 | B12: 사업자명 | C12: 사업자번호 | D12: 발행자명 | E12: 계약유형 | F12: 당월신규계약여부 | G12: 계약UID | H12: 계약명 | I12: 과/면세 | J12: 콘텐츠유형 | K12: 시리즈ID | L12: 시리즈명 | M12: 판매시작일 | N12: 판매종료일 | O12: 제품코드 (발행자가 부여하는 코드) | P12: 레이블 | Q12: 작가명 | R12: ISBN(유/무) | S12: 이용권 종류 | T12: GIAP-캐시 | U12: WEB-캐시 | V12: IOS-캐시 | W12: EVENT-캐시 | X12: 유상캐시-캐시 | Y12: 무상캐시-캐시 | Z12: 총합계-캐시 | AA12: GIAP-원화 | AB12: WEB-원화 | AC12: IOS-원화 | AD12: EVENT-원화 | AE12: 유상캐시-원화 | AF12: 무상캐시-원화 | AG12: 총합계-원화 | AH12: GIAP-순매출 | AI12: WEB-순매출 | AJ12: IOS-순매출 | AK12: EVENT-순매출 | AL12: 유상캐시-순매출 | AM12: 무상캐시-순매출 | AN12: 총합계-캐시 | AO12: 안드로이드 정산률(%) | AP12: WEB 정산률(%) | AQ12: iOS 정산률(%) | AR12: 이벤트캐시 정산률(%) | AS12: 공급가액 | AT12: 세액 | AU12: 공급대가
A13: 특별 | B13: 주식회사 만화가족 | C13: 2618118972 | D13: 만화가족 | E13: 카카오페이지 웹툰 선투자 직계약 | F13: N | G13: 1222 | H13: 만화가족_재밌니,짝사랑 | I13: 과세 | J13: 만화 | K13: 50744771 | L13: 재밌니, 짝사랑 | M13: 43118 | Q13: 손길 | R13: 유 | S13: 단일 이용권 | T13: 42720 | U13: 14830 | V13: 2100 | W13: 79950 | X13: 59650 | Y13: 79950 | Z13: 139600 | AA13: 51264 | AB13: 14830 | AC13: 2520 | AD13: 79950 | AE13: 68614 | AF13: 79950 | AG13: 148564 | AH13: 46138 | AI13: 14385 | AJ13: 1764 | AK13: 71955 | AL13: 62287 | AM13: 71955 | AN13: 134242 | AO13: 70 | AP13: 70 | AQ13: 70 | AR13: 70 | AS13: 85428 | AT13: 8542 | AU13: 93970
A14: 특별 | B14: 주식회사 만화가족 | C14: 2618118972 | D14: 만화가족 | E14: 카카오페이지 웹툰 선투자 직계약 | F14: N | G14: 1222 | H14: 만화가족_재밌니,짝사랑 | I14: 과세 | J14: 만화 | K14: 50744771 | L14: 재밌니, 짝사랑 | M14: 43118 | Q14: 손길 | R14: 유 | S14: 시리즈 이용권 패키지 | T14: 69400 | U14: 43770 | V14: 800 | W14: 27630 | X14: 113970 | Y14: 27630 | Z14: 141600 | AA14: 83280 | AB14: 43770 | AC14: 960 | AD14: 27630 | AE14: 128010 | AF14: 27630 | AG14: 155640 | AH14: 74952 | AI14: 42457 | AJ14: 672 | AK14: 24867 | AL14: 118081 | AM14: 24867 | AN14: 142948 | AO14: 70 | AP14: 70 | AQ14: 70 | AR14: 70 | AS14: 90966 | AT14: 9097 | AU14: 100063
A15: 특별 | B15: 주식회사 만화가족 | C15: 2618118972 | D15: 만화가족 | E15: 카카오페이지 웹툰 선투자 직계약 | F15: N | G15: 1222 | H15: 만화가족_재밌니,짝사랑 | I15: 과세 | J15: 만화 | K15: 50744771 | L15: 재밌니, 짝사랑 | M15: 43118 | Q15: 손길 | R15: 유 | S15: 시리즈 이용권 패키지 | T15: 76880 | U15: 23920 | V15: 0 | W15: 0 | X15: 100800 | Y15: 0 | Z15: 100800 | AA15: 92256 | AB15: 23920 | AC15: 0 | AD15: 0 | AE15: 116176 | AF15: 0 | AG15: 116176 | AH15: 83030 | AI15: 23202 | AJ15: 0 | AK15: 0 | AL15: 106233 | AM15: 0 | AN15: 106233 | AO15: 70 | AP15: 70 | AQ15: 70 | AR15: 70 | AS15: 67602 | AT15: 6761 | AU15: 74363
A16: 특별 | B16: 주식회사 만화가족 | C16: 2618118972 | D16: 만화가족 | E16: 카카오페이지 웹툰 선투자 직계약 | F16: N | G16: 1222 | H16: 만화가족_재밌니,짝사랑 | I16: 과세 | J16: 만화 | K16: 50744771 | L16: 재밌니, 짝사랑 | M16: 43118 | Q16: 손길 | R16: 유 | S16: 시리즈 이용권 패키지 | T16: 162000 | U16: 18200 | V16: 31520 | W16: 15080 | X16: 211720 | Y16: 15080 | Z16: 226800 | AA16: 194400 | AB16: 18200 | AC16: 37824 | AD16: 15080 | AE16: 250424 | AF16: 15080 | AG16: 265504 | AH16: 174960 | AI16: 17654 | AJ16: 26477 | AK16: 13572 | AL16: 219091 | AM16: 13572 | AN16: 232663 | AO16: 70 | AP16: 70 | AQ16: 70 | AR16: 70 | AS16: 148058 | AT16: 14806 | AU16: 162864
A17: 특별 | B17: 주식회사 만화가족 | C17: 2618118972 | D17: 만화가족 | E17: 카카오페이지 웹툰 선투자 직계약 | F17: N | G17: 1222 | H17: 만화가족_재밌니,짝사랑 | I17: 과세 | J17: 만화 | K17: 50744771 | L17: 재밌니, 짝사랑 | M17: 43118 | Q17: 손길 | R17: 유 | S17: 단일 대여 이용권 | T17: 275050 | U17: 174510 | V17: 184810 | W17: 460630 | X17: 634370 | Y17: 460630 | Z17: 1095000 | AA17: 330060 | AB17: 174510 | AC17: 221432 | AD17: 460630 | AE17: 726002 | AF17: 460630 | AG17: 1186632 | AH17: 297054 | AI17: 169275 | AJ17: 155002 | AK17: 414567 | AL17: 621331 | AM17: 414567 | AN17: 1035898 | AO17: 70 | AP17: 70 | AQ17: 70 | AR17: 70 | AS17: 659208 | AT17: 65921 | AU17: 725129
A18: 특별 | B18: 주식회사 만화가족 | C18: 2618118972 | D18: 만화가족 | E18: 카카오페이지 웹툰 선투자 직계약 | F18: N | G18: 1222 | H18: 만화가족_재밌니,짝사랑 | I18: 과세 | J18: 만화 | K18: 50744771 | L18: 재밌니, 짝사랑 | M18: 43118 | Q18: 손길 | R18: 유 | S18: 시리즈 대여 이용권 패키지 | T18: 195340 | U18: 189860 | V18: 75370 | W18: 233230 | X18: 460570 | Y18: 233230 | Z18: 693800 | AA18: 234408 | AB18: 189860 | AC18: 90084 | AD18: 233230 | AE18: 514352 | AF18: 233230 | AG18: 747582 | AH18: 210967 | AI18: 184164 | AJ18: 63059 | AK18: 209907 | AL18: 458190 | AM18: 209907 | AN18: 668097 | AO18: 70 | AP18: 70 | AQ18: 70 | AR18: 70 | AS18: 425152 | AT18: 42516 | AU18: 467668
A19: 특별 | B19: 주식회사 만화가족 | C19: 2618118972 | D19: 만화가족 | E19: 카카오페이지 웹툰 선투자 직계약 | F19: N | G19: 1222 | H19: 만화가족_재밌니,짝사랑 | I19: 과세 | J19: 만화 | K19: 50744771 | L19: 재밌니, 짝사랑 | M19: 43118 | Q19: 손길 | R19: 유 | S19: 시리즈 대여 이용권 패키지 | T19: 108140 | U19: 136030 | V19: 56640 | W19: 119190 | X19: 300810 | Y19: 119190 | Z19: 420000 | AA19: 129768 | AB19: 136030 | AC19: 67618 | AD19: 119190 | AE19: 333416 | AF19: 119190 | AG19: 452606 | AH19: 116791 | AI19: 131949 | AJ19: 47333 | AK19: 107271 | AL19: 296073 | AM19: 107271 | AN19: 403344 | AO19: 70 | AP19: 70 | AQ19: 70 | AR19: 70 | AS19: 256674 | AT19: 25667 | AU19: 282341
A20: 특별 | B20: 주식회사 만화가족 | C20: 2618118972 | D20: 만화가족 | E20: 카카오페이지 웹툰 선투자 직계약 | F20: N | G20: 1222 | H20: 만화가족_재밌니,짝사랑 | I20: 과세 | J20: 만화 | K20: 50744771 | L20: 재밌니, 짝사랑 | M20: 43118 | Q20: 손길 | R20: 유 | S20: 시리즈 대여 이용권 패키지 | T20: 329070 | U20: 317880 | V20: 280550 | W20: 83300 | X20: 927500 | Y20: 83300 | Z20: 1010800 | AA20: 394884 | AB20: 317880 | AC20: 336520 | AD20: 83300 | AE20: 1049284 | AF20: 83300 | AG20: 1132584 | AH20: 355396 | AI20: 308344 | AJ20: 235564 | AK20: 74970 | AL20: 899303 | AM20: 74970 | AN20: 974273 | AO20: 70 | AP20: 70 | AQ20: 70 | AR20: 70 | AS20: 619993 | AT20: 61999 | AU20: 681992
AG21: =SUM(AG13:AG20) -> 4205288 | AS21: =SUM(AS13:AS20) -> 2353081
A23: <우리집아이돌> 7월
A24: 기초정보 | T24: 거래액(캐시) | AA24: 거래액(원화) | AH24: 순매출액 | AO24: 정산율(%) | AS24: 정산금액
A25: 특별/일반 | B25: 사업자명 | C25: 사업자번호 | D25: 발행자명 | E25: 계약유형 | F25: 당월신규계약여부 | G25: 계약UID | H25: 계약명 | I25: 과/면세 | J25: 콘텐츠유형 | K25: 시리즈ID | L25: 시리즈명 | M25: 판매시작일 | N25: 판매종료일 | O25: 제품코드 (발행자가 부여하는 코드) | P25: 레이블 | Q25: 작가명 | R25: ISBN(유/무) | S25: 이용권 종류 | T25: GIAP-캐시 | U25: WEB-캐시 | V25: IOS-캐시 | W25: EVENT-캐시 | X25: 유상캐시-캐시 | Y25: 무상캐시-캐시 | Z25: 총합계-캐시 | AA25: GIAP-원화 | AB25: WEB-원화 | AC25: IOS-원화 | AD25: EVENT-원화 | AE25: 유상캐시-원화 | AF25: 무상캐시-원화 | AG25: 총합계-원화 | AH25: GIAP-순매출 | AI25: WEB-순매출 | AJ25: IOS-순매출 | AK25: EVENT-순매출 | AL25: 유상캐시-순매출 | AM25: 무상캐시-순매출 | AN25: 총합계-캐시 | AO25: 안드로이드 정산률(%) | AP25: WEB 정산률(%) | AQ25: iOS 정산률(%) | AR25: 이벤트캐시 정산률(%) | AS25: 공급가액 | AT25: 세액 | AU25: 공급대가
A26: 특별 | B26: 주식회사 만화가족 | C26: 2618118972 | D26: 만화가족 | E26: 카카오페이지 웹툰 선투자 직계약 | F26: N | G26: 1246 | H26: 만화가족_우리집아이돌 | I26: 과세 | J26: 만화 | K26: 53067806 | L26: 우리집 아이돌 | M26: 43676 | Q26: 한둘,자라개 | R26: 유 | S26: 단일 이용권 | T26: 1200 | U26: 400 | V26: 0 | W26: 2800 | X26: 1600 | Y26: 2800 | Z26: 4400 | AA26: 1440 | AB26: 400 | AC26: 0 | AD26: 2800 | AE26: 1840 | AF26: 2800 | AG26: 4640 | AH26: 1296 | AI26: 388 | AJ26: 0 | AK26: 2520 | AL26: 1684 | AM26: 2520 | AN26: 4204 | AO26: 70 | AP26: 70 | AQ26: 70 | AR26: 70 | AS26: 2676 | AT26: 267 | AU26: 2943
A27: 특별 | B27: 주식회사 만화가족 | C27: 2618118972 | D27: 만화가족 | E27: 카카오페이지 웹툰 선투자 직계약 | F27: N | G27: 1246 | H27: 만화가족_우리집아이돌 | I27: 과세 | J27: 만화 | K27: 53067806 | L27: 우리집 아이돌 | M27: 43676 | Q27: 한둘,자라개 | R27: 유 | S27: 시리즈 이용권 패키지 | T27: 7200 | U27: -800 | V27: 0 | W27: 0 | X27: 6400 | Y27: 0 | Z27: 6400 | AA27: 8640 | AB27: -800 | AC27: 0 | AD27: 0 | AE27: 7840 | AF27: 0 | AG27: 7840 | AH27: 7776 | AI27: -776 | AJ27: 0 | AK27: 0 | AL27: 7000 | AM27: 0 | AN27: 7000 | AO27: 70 | AP27: 70 | AQ27: 70 | AR27: 70 | AS27: 4454 | AT27: 446 | AU27: 4900
A28: 특별 | B28: 주식회사 만화가족 | C28: 2618118972 | D28: 만화가족 | E28: 카카오페이지 웹툰 선투자 직계약 | F28: N | G28: 1246 | H28: 만화가족_우리집아이돌 | I28: 과세 | J28: 만화 | K28: 53067806 | L28: 우리집 아이돌 | M28: 43676 | Q28: 한둘,자라개 | R28: 유 | S28: 시리즈 이용권 패키지 | T28: 14400 | U28: 0 | V28: 0 | W28: 0 | X28: 14400 | Y28: 0 | Z28: 14400 | AA28: 17280 | AB28: 0 | AC28: 0 | AD28: 0 | AE28: 17280 | AF28: 0 | AG28: 17280 | AH28: 15552 | AI28: 0 | AJ28: 0 | AK28: 0 | AL28: 15552 | AM28: 0 | AN28: 15552 | AO28: 70 | AP28: 70 | AQ28: 70 | AR28: 70 | AS28: 9896 | AT28: 990 | AU28: 10886
A29: 특별 | B29: 주식회사 만화가족 | C29: 2618118972 | D29: 만화가족 | E29: 카카오페이지 웹툰 선투자 직계약 | F29: N | G29: 1246 | H29: 만화가족_우리집아이돌 | I29: 과세 | J29: 만화 | K29: 53067806 | L29: 우리집 아이돌 | M29: 43676 | Q29: 한둘,자라개 | R29: 유 | S29: 단일 대여 이용권 | T29: 29170 | U29: 29770 | V29: 18600 | W29: 41460 | X29: 77540 | Y29: 41460 | Z29: 119000 | AA29: 35004 | AB29: 29770 | AC29: 22320 | AD29: 41460 | AE29: 87094 | AF29: 41460 | AG29: 128554 | AH29: 31504 | AI29: 28877 | AJ29: 15624 | AK29: 37314 | AL29: 76005 | AM29: 37314 | AN29: 113319 | AO29: 70 | AP29: 70 | AQ29: 70 | AR29: 70 | AS29: 72112 | AT29: 7212 | AU29: 79324
A30: 특별 | B30: 주식회사 만화가족 | C30: 2618118972 | D30: 만화가족 | E30: 카카오페이지 웹툰 선투자 직계약 | F30: N | G30: 1246 | H30: 만화가족_우리집아이돌 | I30: 과세 | J30: 만화 | K30: 53067806 | L30: 우리집 아이돌 | M30: 43676 | Q30: 한둘,자라개 | R30: 유 | S30: 시리즈 대여 이용권 패키지 | T30: 16100 | U30: 8500 | V30: 0 | W30: 14200 | X30: 24600 | Y30: 14200 | Z30: 38800 | AA30: 19320 | AB30: 8500 | AC30: 0 | AD30: 14200 | AE30: 27820 | AF30: 14200 | AG30: 42020 | AH30: 17388 | AI30: 8245 | AJ30: 0 | AK30: 12780 | AL30: 25633 | AM30: 12780 | AN30: 38413 | AO30: 70 | AP30: 70 | AQ30: 70 | AR30: 70 | AS30: 24445 | AT30: 2445 | AU30: 26890
A31: 특별 | B31: 주식회사 만화가족 | C31: 2618118972 | D31: 만화가족 | E31: 카카오페이지 웹툰 선투자 직계약 | F31: N | G31: 1246 | H31: 만화가족_우리집아이돌 | I31: 과세 | J31: 만화 | K31: 53067806 | L31: 우리집 아이돌 | M31: 43676 | Q31: 한둘,자라개 | R31: 유 | S31: 시리즈 대여 이용권 패키지 | T31: 25400 | U31: 31600 | V31: 0 | W31: 3800 | X31: 57000 | Y31: 3800 | Z31: 60800 | AA31: 30480 | AB31: 31600 | AC31: 0 | AD31: 3800 | AE31: 62080 | AF31: 3800 | AG31: 65880 | AH31: 27432 | AI31: 30652 | AJ31: 0 | AK31: 3420 | AL31: 58084 | AM31: 3420 | AN31: 61504 | AO31: 70 | AP31: 70 | AQ31: 70 | AR31: 70 | AS31: 39137 | AT31: 3915 | AU31: 43052
AG32: =SUM(AG26:AG31) -> 266214 | AS32: =SUM(AS26:AS31) -> 152720
A34: <픽코마>

Sheet 네이버웹툰1
B2: 사이트명 | C2: 작품명 | D2: 소비자매출액 | E2: 유통사수수료 | F2: 케이티매출액 | G2: 케이티수익 | H2: 만화가족 수익 | I2: 비고
B3: 네이버웹툰 | C3: 견우와선녀 | D3: 2200000 | E3: 0 | F3: =D3 -> 2200000 | G3: =F3*20% -> 440000 | H3: =F3*80% -> 1760000 | I3: 9월 고료
B4: 네이버웹툰 | C4: 나를바꿔줘 | D4: 2500000 | E4: 0 | F4: =D4 -> 2500000 | G4: =F4*20% -> 500000 | H4: =F4*80% -> 2000000 | I4: 9월 고료
B5: 네이버웹툰 | C5: 네버마인드달링 | D5: 2000000 | E5: 0 | F5: =D5 -> 2000000 | G5: =F5*20% -> 400000 | H5: =F5*80% -> 1600000 | I5: 글로벌MG
B6: 합계 | D6: =SUM(D3:D5) -> 6700000 | E6: =SUM(E3:E5) -> 0 | F6: =SUM(F3:F5) -> 6700000 | G6: =SUM(G3:G5) -> 1340000 | H6: =SUM(H3:H5) -> 5360000
G7: =F6*0.2 -> 1340000 | H7: =F6*0.8 -> 5360000

Sheet 네이버웹툰2
B2: 사이트명 | C2: 작품명 | D2: 소비자매출액 | E2: 유통사수수료 | F2: 케이티매출액 | G2: 케이티수익 | H2: 만화가족 수익 | I2: 비고
B3: 네이버웹툰 | C3: 글로벌 | D3: 8964615 | E3: - | F3: =D3 -> 8964615 | G3: =F3*20% -> 1792923 | H3: =F3*80% -> 7171692 | I3: 9월 글로벌
B4: 네이버웹툰 | C4: 창작지원금_견우와선녀 | D4: 82421 | E4: - | F4: =D4 -> 82421 | G4: =F4*20% -> 16484.2 | H4: =F4*80% -> 65936.8 | I4: 9월 창작
B5: 네이버웹툰 | C5: 창작지원금_나를바꿔줘 | D5: 167889 | E5: - | F5: =D5 -> 167889 | G5: =F5*20% -> 33577.8 | H5: =F5*80% -> 134311.2 | I5: 9월 창작
B6: 네이버웹툰 | C6: 리워드비디오_데드라이프 | D6: 3921 | E6: - | F6: =D6 -> 3921 | G6: =F6*20% -> 784.2 | H6: =F6*80% -> 3136.8 | I6: 8월 리워드비디오
B7: 네이버웹툰 | C7: 리워드비디오_그녀의버킷리스트 | D7: 1167 | E7: - | F7: =D7 -> 1167 | G7: =F7*20% -> 233.4 | H7: =F7*80% -> 933.6 | I7: 8월 리워드비디오
B8: 네이버웹툰 | C8: 리워드비디오_악마와계약연애 | D8: 6107 | E8: - | F8: =D8 -> 6107 | G8: =F8*20% -> 1221.4 | H8: =F8*80% -> 4885.6 | I8: 8월 리워드비디오
B9: 네이버웹툰 | C9: 리워드비디오_데드라이프 | D9: 22666 | E9: - | F9: =D9 -> 22666 | G9: =F9*20% -> 4533.2 | H9: =F9*80% -> 18132.8 | I9: 9월 리워드비디오
B10: 네이버웹툰 | C10: 리워드비디오_그녀의버킷리스트 | D10: 23356 | E10: - | F10: =D10 -> 23356 | G10: =F10*20% -> 4671.2 | H10: =F10*80% -> 18684.8 | I10: 9월 리워드비디오
B11: 네이버웹툰 | C11: 리워드비디오_악마와계약연애 | D11: 201134 | E11: - | F11: =D11 -> 201134 | G11: =F11*20% -> 40226.8 | H11: =F11*80% -> 160907.2 | I11: 9월 리워드비디오
B12: 네이버웹툰 | C12: 데드라이프_앱 | D12: 33691553 | E12: =D12-F12 -> 15198751 | F12: 18492802 | G12: =F12*20% -> 3698560.4 | H12: =F12*80% -> 14794242 | I12: 9월
B13: 네이버웹툰 | C13: 데드라이프_웹 | D13: 194680 | E13: =D13-F13 -> 84312 | F13: 110368 | G13: =F13*20% -> 22073.6 | H13: =F13*80% -> 88294.4 | I13: 9월
B14: 네이버웹툰 | C14: 그녀의버킷리스트_앱 | D14: 162920 | E14: =D14-F14 -> 81959 | F14: 80961 | G14: =F14*20% -> 16192.2 | H14: =F14*80% -> 64768.8 | I14: 9월
B15: 네이버웹툰 | C15: 나를바꿔줘_앱 | D15: 63819111 | E15: =D15-F15 -> 32198012 | F15: 31621099 | G15: =F15*20% -> 6324219.8 | H15: =F15*80% -> 25296879 | I15: 9월
B16: 네이버웹툰 | C16: 나를바꿔줘_웹 | D16: 273980 | E16: =D16-F16 -> 135484 | F16: 138496 | G16: =F16*20% -> 27699.2 | H16: =F16*80% -> 110796.8 | I16: 9월
B17: 네이버웹툰 | C17: 악마와계약연애_앱 | D17: 3065250 | E17: =D17-F17 -> 1542289 | F17: 1522961 | G17: =F17*20% -> 304592.2 | H17: =F17*80% -> 1218368.8 | I17: 9월
B18: 네이버웹툰 | C18: 악마와계약연애_웹 | D18: 100400 | E18: =D18-F18 -> 50097 | F18: 50303 | G18: =F18*20% -> 10060.6 | H18: =F18*80% -> 40242.4 | I18: 9월
B19: 네이버웹툰 | C19: 반투명인간_앱 | D19: 24760 | E19: =D19-F19 -> 12185 | F19: 12575 | G19: =F19*20% -> 2515 | H19: =F19*80% -> 10060 | I19: 9월
B20: 네이버웹툰 | C20: 반투명인간_웹 | D20: 9240 | E20: =D20-F20 -> 4551 | F20: 4689 | G20: =F20*20% -> 937.8 | H20: =F20*80% -> 3751.2 | I20: 9월
B21: 네이버웹툰 | C21: 황금의핸드메이커_앱 | D21: 36816 | E21: =D21-F21 -> 18104 | F21: 18712 | G21: =F21*20% -> 3742.4 | H21: =F21*80% -> 14969.6 | I21: 9월
B22: 네이버웹툰 | C22: 황금의핸드메이커_웹 | D22: 1700 | E22: =D22-F22 -> 834 | F22: 866 | G22: =F22*20% -> 173.2 | H22: =F22*80% -> 692.8 | I22: 9월
B23: 네이버웹툰 | C23: 구작_앱 | D23: 614940 | E23: =D23-F23 -> 259368 | F23: 355572 | G23: =F23*20% -> 71114.4 | H23: =F23*80% -> 284457.6 | I23: 9월
... B35: 네이버웹툰 | C35: 구작_웹 | D35: 25840 | E35: =D35-F35 -> 9465 | F35: 16375 | G35: =F35*20% -> 3275 | H35: =F35*80% -> 13100 | I35: 10월
B36: 합계 | D36: =SUM(D3:D35) -> 208670094 | E36: =SUM(E3:E35) -> 97259791 | F36: =SUM(F3:F35) -> 111410303 | G36: =SUM(G3:G35) -> 22282061 | H36: =SUM(H3:H35) -> 89128242
G37: =F36*0.2 -> 22282061 | H37: =F36*0.8 -> 89128242
A40: <글로벌>
A226: <웹+앱> 10월

Sheet 테크앤조이
B2: 사이트명 | C2: 작품명 | D2: 소비자매출액 | E2: 유통사수수료 | F2: 케이티매출액 | G2: 케이티수익 | H2: 만화가족 수익 | I2: 비고
B3: 테크앤조이 | C3: 투믹스/나인픽셀즈 | E3: =D3-F3 -> 0 | G3: =F3*20% -> 0 | H3: =F3*80% -> 0 | I3: 7월 RS
B4: 합계 | D4: =SUM(D3:D3) -> 0 | E4: =SUM(E3:E3) -> 0 | F4: =SUM(F3:F3) -> 0 | G4: =SUM(G3:G3) -> 0 | H4: =SUM(H3:H3) -> 0
G5: =F4*0.2 -> 0 | H5: =F4*0.8 -> 0
A8: <정산서>
B9: 양방향서비스 22년 월 서비스분 매출정산
G11: 22년 03월 04월 서비스분(VAT별도)
B12: 구분 | C12: 총 청구금액 | D12: 현금 결제 | E12: 포인트결제 | F12: 공동 마케팅/할인/무료 포인트 공동 부담율 | G12: 포인트 정산대상금액
B13: 금액 | F13: 0.5 | G13: =E13*F13 -> 0
B15: 업체 | C15: 수수료 (KT/KTH/TECH) | D15: 만화가족
B16: 정산매출 | C16: =C13*C17 -> 0 | D16: =C13*D17 -> 0
B17: 요율 | C17: 0.6 | D17: 0.4

Sheet 키다리스튜디오
B2: 사이트명 | C2: 작품명 | D2: 소비자매출액 | E2: 유통사수수료 | F2: 케이티매출액 | G2: 케이티수익 | H2: 만화가족 수익 | I2: 비고
B3: 봄툰 | C3: 봄툰 구작연재 | D3: =SUM(Z11,H30) -> 11957350 | E3: =D3-F3 -> 6307622 | F3: 5649728 | G3: =F3*20% -> 1129945.6 | H3: =F3*80% -> 4519782.4 | I3: 9월 RS
B4: 봄툰 | C4: 봄툰 대만 | E4: =D4-F4 -> 0 | G4: =F4*20% -> 0 | H4: =F4*80% -> 0 | I4: 2022 Q3
B5: 봄툰 | C5: 봄툰 태국 | E5: =D5-F5 -> 0 | G5: =F5*20% -> 0 | H5: =F5*80% -> 0 | I5: 2022 Q3
B6: 합계 | D6: =SUM(D3:D5) -> 11957350 | E6: =SUM(E3:E5) -> 6307622 | F6: =SUM(F3:F5) -> 5649728 | G6: =SUM(G3:G5) -> 1129945.6 | H6: =SUM(H3:H5) -> 4519782.4
G7: =F6*0.2 -> 1129945.6 | H7: =F6*0.8 -> 4519782.4
A10: <정산서>
B11: 2022.09 | N11: 0 | O11: 0 | P11: 0 | Y11: 2771643 | Z11: 6201180 | AB11: 2771643 | AC11: 2771643 | AD11: 2771643 | AE11: 0 | AF11: 0
B12: No | C12: 구분 | D12: 만화idx | E12: 상태 | F12: 요일 | G12: 만화명 | H12: CP회사명 | I12: MCP | J12: 작가명 | K12: CP(정산처) | L12: 구분 | M12: 비고 | N12: 이월 차감잔액 | O12: 콘텐츠 MG | P12: 실지급 MG | Q12: 웹코인합계 | R12: 웹정산율 | S12: 웹매출액 | T12: 웹정산액 | U12: 앱코인합계 | V12: 앱정산율 | W12: 앱매출액 | X12: 앱정산액 | Y12: 정산액(웹+앱) | Z12: 총매출액 | AA12: 글/그림 | AB12: RS정산액 | AC12: RS-MG | AD12: RS지급액(MG-RS) | AE12: 차감잔액 | AF12: MG(당월 소멸)
B13: 7782 | C13: 연재 | D13: 6335 | E13: 업체MG | G13: 겨우내 | H13: 만화가족(웹툰) | J13: 사해&벌래 | K13: 만화가족 | L13: 1.과세 | Q13: 18 | R13: 45.00% | S13: 3240 | T13: 1458 | U13: 3 | V13: 35.00% | W13: 540 | X13: 189 | Y13: 1647 | Z13: 3780 | AB13: 1647 | AC13: 1647 | AD13: 1647 | AE13: - | AF13: -
B14: 165 | C14: 연재 | D14: 20105 | E14: 선독점 | F14: 화 | G14: 공유하는 집 | H14: 만화가족(웹툰) | J14: 징망츄&사앙 | K14: 만화가족 | L14: 1.과세 | Q14: 10261 | R14: 54.00% | S14: 1846980 | T14: 997369 | U14: 10487 | V14: 42.00% | W14: 1887660 | X14: 792817 | Y14: 1790186 | Z14: 3734640 | AB14: 1790186 | AC14: 1790186 | AD14: 1790186 | AE14: - | AF14: -
B15: 6023 | C15: 연재 | D15: 6932 | E15: 요일연재 | G15: 날라리(완결) | H15: 만화가족(웹툰) | J15: 손 길 | K15: 만화가족 | L15: 1.과세 | Q15: - | R15: 45.00% | S15: - | T15: - | U15: 48 | V15: 35.00% | W15: 8640 | X15: 3024 | Y15: 3024 | Z15: 8640 | AB15: 3024 | AC15: 3024 | AD15: 3024 | AE15: - | AF15: -
B16: 10231 | C16: 연재 | D16: 12145 | E16: 요일연재 | G16: 사랑이 커다래 | H16: 만화가족(웹툰) | J16: 깜귤 | K16: 만화가족 | L16: 1.과세 | Q16: - | R16: 54.00% | S16: - | T16: - | U16: - | V16: 42.00% | W16: - | X16: - | Y16: - | AB16: - | AC16: - | AD16: - | AE16: - | AF16: -
B17: 14022 | C17: 연재 | D17: 8960 | E17: 업체MG | G17: 세렌디피티 | H17: 만화가족(웹툰) | J17: 잇뚜&주요 | K17: 만화가족 | L17: 1.과세 | Q17: - | R17: 45.00% | S17: - | T17: - | U17: - | V17: 35.00% | W17: - | X17: - | Y17: - | AB17: - | AC17: - | AD17: - | AE17: - | AF17: -
B18: 7779 | C18: 연재 | D18: 5822 | E18: 요일연재 | G18: 소음(완결) | H18: 만화가족(웹툰) | J18: 어고 | K18: 만화가족 | L18: 1.과세 | Q18: 10 | R18: 45.00% | S18: 1800 | T18: 810 | U18: 10 | V18: 35.00% | W18: 1800 | X18: 630 | Y18: 1440 | Z18: 3600 | AB18: 1440 | AC18: 1440 | AD18: 1440 | AE18: - | AF18: -
B19: 13294 | C19: 연재 | D19: 5455 | E19: 요일연재 | G19: 시어머니는 츤데레(완결) | H19: 만화가족(웹툰) | J19: 온조 | K19: 만화가족 | L19: 1.과세 | Q19: - | R19: 45.00% | S19: - | T19: - | U19: - | V19: 35.00% | W19: - | X19: - | Y19: - | AB19: - | AC19: - | AD19: - | AE19: - | AF19: -
B20: 357 | C20: 연재 | D20: 12853 | E20: 업체MG | G20: 아는 사람 이야기 | H20: 만화가족(웹툰) | J20: 온우주&서랭 | K20: 만화가족 | L20: 1.과세 | Q20: 2364 | R20: 45.00% | S20: 425520 | T20: 191484 | U20: 4716 | V20: 35.00% | W20: 848880 | X20: 297108 | Y20: 488592 | Z20: 1274400 | AB20: 488592 | AC20: 488592 | AD20: 488592 | AE20: - | AF20: -
B21: 5482 | C21: 연재 | D21: 6732 | E21: 요일연재 | G21: 아임펫! 시즌 1,2,3 | H21: 만화가족(웹툰) | J21: 탐이부 | K21: 만화가족 | L21: 1.과세 | Q21: 16 | R21: 45.00% | S21: 2880 | T21: 1296 | U21: 46 | V21: 35.00% | W21: 8280 | X21: 2898 | Y21: 4194 | Z21: 11160 | AB21: 4194 | AC21: 4194 | AD21: 4194 | AE21: - | AF21: -
B22: 421 | C22: 연재 | D22: 17898 | E22: 업체MG | G22: 애증과 애정 사이 | H22: 만화가족(웹툰) | J22: 부찌 | K22: 만화가족 | L22: 1.과세 | Q22: 3084 | R22: 45.00% | S22: 555120 | T22: 249804 | U22: 1863 | V22: 35.00% | W22: 335340 | X22: 117369 | Y22: 367173 | Z22: 890460 | AB22: 367173 | AC22: 367173 | AD22: 367173 | AE22: - | AF22: -
B23: 981 | C23: 연재 | D23: 12179 | E23: 업체MG | G23: 에버그린 | H23: 만화가족(웹툰) | J23: 부찌 | K23: 만화가족 | L23: 1.과세 | Q23: 1020 | R23: 45.00% | S23: 183600 | T23: 82620 | U23: 444 | V23: 35.00% | W23: 79920 | X23: 27972 | Y23: 110592 | Z23: 263520 | AB23: 110592 | AC23: 110592 | AD23: 110592 | AE23: - | AF23: -
B24: 13276 | C24: 연재 | D24: 5392 | E24: 요일연재 | G24: 여고를 아느냐(완결) | H24: 만화가족(웹툰) | J24: 젠틀독 | K24: 만화가족 | L24: 1.과세 | Q24: - | R24: 45.00% | S24: - | T24: - | U24: - | V24: 35.00% | W24: - | X24: - | Y24: - | AB24: - | AC24: - | AD24: - | AE24: - | AF24: -
B25: 13517 | C25: 연재 | D25: 6457 | E25: 요일연재 | G25: 연애에 서툰 뱀파이어(완결) | H25: 만화가족(웹툰) | J25: 유승승 | K25: 만화가족 | L25: 1.과세 | Q25: - | R25: 45.00% | S25: - | T25: - | U25: - | V25: 35.00% | W25: - | X25: - | Y25: - | AB25: - | AC25: - | AD25: - | AE25: - | AF25: -
B26: 5691 | C26: 연재 | D26: 21065 | E26: 요일연재 | G26: 이상적인관계 | H26: 만화가족(웹툰) | J26: 얏꽁 | K26: 만화가족 | L26: 1.과세 | Q26: - | R26: 54.00% | S26: - | T26: - | U26: 27 | V26: 42.00% | W26: 4860 | X26: 2041 | Y26: 2041 | Z26: 4860 | AB26: 2041 | AC26: 2041 | AD26: 2041 | AE26: - | AF26: -
B27: 6899 | C27: 연재 | D27: 5401 | E27: 요일연재 | G27: 죽은자를 상대하는 방법(완결) | H27: 만화가족(웹툰) | J27: 곽병진 | K27: 만화가족 | L27: 1.과세 | Q27: 34 | R27: 45.00% | S27: 6120 | T27: 2754 | U27: - | V27: 35.00% | W27: - | X27: - | Y27: 2754 | Z27: 6120 | AB27: 2754 | AC27: 2754 | AD27: 2754 | AE27: - | AF27: -
B29: B2BC
H30: 5756170 | I30: 2878085
B31: 서비스사 | C31: 세금계산년월 | D31: 만화IDX | E31: 컨텐츠 | F31: CP1(정산처) | G31: 구분 | H31: 순매출 | I31: 봄툰-CP정산액
B32: 레진 | C32: 44774 | D32: 12853 | E32: 아는 사람 이야기 | F32: 만화가족 | G32: 1.과세 | H32: 5562130 | I32: 2781065
B33: 레진 | C33: 44774 | D33: 17898 | E33: 애증과 애정 사이 | F33: 만화가족 | G33: 1.과세 | H33: 136500 | I33: 68250
B34: 레진 | C34: 44774 | D34: 12179 | E34: 에버그린 | F34: 만화가족 | G34: 1.과세 | H34: 57540 | I34: 28770
B38: 대만 Boomtoon 정산
G39: 기준 환율 | H39: 43.48 | I39: 인보이스 발행일 | J39: 44742 | K39: 지급일 | L39: 2022년 8월 지급요청
B40: 2022-2Q | C40: 작품 | D40: 정산처 | E40: 구분 | F40: 글/그림 | G40: MG/잔여금(KRW) | H40: 웹순매출(NTD) | I40: 앱순매출(NTD) | J40: 순매출(KRW) | K40: RS요율 | L40: 순매출(KRW)*RS요율 | M40: MG-(순매출*RS요율) | N40: 최종 지급액(KRW)
B42: Sum | H42: =SUM(H41:H41) -> 0 | I42: =SUM(I41:I41) -> 0 | J42: =SUM(J41:J41) -> 0 | L42: =SUM(L41:L41) -> 0 | N42: =SUM(N41:N41) -> 0
B44: 태국 Boomtoon 정산
G45: 기준 환율 | H45: 36.73 | I45: 인보이스 발행일 | J45: 44742 | K45: 지급일 | L45: 2022년 8월 지급요청
B46: 2022-2Q | C46: 작품 | D46: 정산처 | E46: 구분 | F46: 글/그림 | G46: MG/잔여금(KRW) | H46: 웹순매출(THB) | I46: 앱순매출(THB) | J46: 순매출(KRW) | K46: RS요율 | L46: 순매출(KRW)*RS요율 | M46: MG-(순매출*RS요율) | N46: 최종 지급액(KRW)

Sheet 탑툰
B2: 사이트명 | C2: 작품명 | D2: 소비자매출액 | E2: 유통사수수료 | F2: 케이티매출액 | G2: 케이티수익 | H2: 만화가족 수익 | I2: 비고
B3: 탑툰 | C3: 해금 外 | D3: 1034633 | E3: 0 | F3: =D3 -> 1034633 | G3: =F3*20% -> 206926.6 | H3: =F3*80% -> 827706.4 | I3: 9월 국내/해외 RS
B4: 합계 | D4: =SUM(D3:D3) -> 1034633 | E4: =SUM(E3:E3) -> 0 | F4: =SUM(F3:F3) -> 1034633 | G4: =SUM(G3:G3) -> 206926.6 | H4: =SUM(H3:H3) -> 827706.4
G5: =F4*0.2 -> 206926.6 | H5: =F4*0.8 -> 827706.4
A8: <정산서>
A9: # | B9: 구분 | C9: 작품명 | D9: 범위 | E9: 세금 | F9: WEB 정산 | G9: APP 정산 | H9: 결제 및 기타수수료 | I9: 07월 연재 | J9: 07월 휴재 | K9: 연재/MG정산액 | L9: RS 선지급차감액 | M9: RS 조정액 | N9: RS 정산액 | O9: 총 정산액 | P9: 기타
A10: 8013 | B10: (한국) | C10: 나싸 | D10: 전체회차 | E10: 적용 | F10: 0 | G10: 0 | I10: (연재없음) | J10: (연재없음) | K10: 0 | L10: 0 | M10: 0 | N10: 0 | O10: 0
A11: 8749 | B11: (한국) | C11: 러브 앤 위시 | D11: 전체회차 | E11: 적용 | F11: 0 | G11: 0 | I11: (연재없음) | J11: (연재없음) | K11: 0 | L11: 0 | M11: 0 | N11: 0 | O11: 0
A12: 8896 | B12: (한국) | C12: 그래도 사랑해 | D12: 전체회차 | E12: 적용 | F12: 1166 | G12: 0 | I12: (연재없음) | J12: (연재없음) | K12: 0 | L12: 0 | M12: 0 | N12: 1166 | O12: 1166
A13: 8943 | B13: (한국) | C13: 루나 | D13: 전체회차 | E13: 적용 | F13: 0 | G13: 0 | I13: (연재없음) | J13: (연재없음) | K13: 0 | L13: 0 | M13: 0 | N13: 0 | O13: 0
A14: 8988 | B14: (한국) | C14: 우당탕탕 따식이 | D14: 전체회차 | E14: 적용 | F14: 0 | G14: 0 | I14: (연재없음) | J14: (연재없음) | K14: 0 | L14: 0 | M14: 0 | N14: 0 | O14: 0
A15: 8989 | B15: (한국) | C15: 시어머니는 츤데레 | D15: 전체회차 | E15: 적용 | F15: 0 | G15: 0 | I15: (연재없음) | J15: (연재없음) | K15: 0 | L15: 0 | M15: 0 | N15: 0 | O15: 0
A16: 8990 | B16: (한국) | C16: 위험한 동거 | D16: 전체회차 | E16: 적용 | F16: 0 | G16: 0 | I16: (연재없음) | J16: (연재없음) | K16: 0 | L16: 0 | M16: 0 | N16: 0 | O16: 0
A17: 8991 | B17: (한국) | C17: 프랑켄이 사는 마을 | D17: 전체회차 | E17: 적용 | F17: 0 | G17: 0 | I17: (연재없음) | J17: (연재없음) | K17: 0 | L17: 0 | M17: 0 | N17: 0 | O17: 0
A18: 8992 | B18: (한국) | C18: 죽은 자를 상대하는 방법 | D18: 전체회차 | E18: 적용 | F18: 0 | G18: 0 | I18: (연재없음) | J18: (연재없음) | K18: 0 | L18: 0 | M18: 0 | N18: 0 | O18: 0
A19: 8993 | B19: (한국) | C19: NPC | D19: 전체회차 | E19: 적용 | F19: 0 | G19: 0 | I19: (연재없음) | J19: (연재없음) | K19: 0 | L19: 0 | M19: 0 | N19: 0 | O19: 0
A20: 8995 | B20: (한국) | C20: 아임 펫! | D20: 전체회차 | E20: 적용 | F20: 0 | G20: 0 | I20: (연재없음) | J20: (연재없음) | K20: 0 | L20: 0 | M20: 0 | N20: 0 | O20: 0
A21: 9030 | B21: (한국) | C21: 당신의 아내를 접수합니다 | D21: 전체회차 | E21: 적용 | F21: 0 | G21: 0 | I21: (연재없음) | J21: (연재없음) | K21: 0 | L21: 0 | M21: 0 | N21: 0 | O21: 0
... A41: 571 | B41: (대만) | C41: 戀愛ing 그래도 사랑해 | D41: 전체회차 | E41: 적용 | F41: 0 | G41: 0 | I41: (연재없음) | J41: (연재없음) | K41: 0 | L41: 0 | M41: 0 | N41: 0 | O41: 0
A42: 616 | B42: (대만) | C42: 解禁:初始的快感 해금 : 시작되는 쾌락 | D42: 전체회차 | E42: 적용 | F42: 83130 | G42: 20140 | H42: 20654 | I42: (연재없음) | J42: (연재없음) | K42: 0 | L42: 0 | M42: 0 | N42: 82616 | O42: 82616
A43: 807 | B43: (대만) | C43: Lust Awakening 해금 : 시작되는 쾌락 - 영어 | D43: 전체회차 | E43: 적용 | F43: 0 | G43: 0 | I43: (연재없음) | J43: (연재없음) | K43: 0 | L43: 0 | M43: 0 | N43: 0 | O43: 0
A44: 833 | B44: (대만) | C44: 窺視 엿보기 | D44: 전체회차 | E44: 적용 | F44: 0 | G44: 0 | I44: (연재없음) | J44: (연재없음) | K44: 0 | L44: 0 | M44: 0 | N44: 0 | O44: 0
A45: 870 | B45: (대만) | C45: 青春:逆齡小鮮肉 청춘 : 그 몸을 삼키다 | D45: 전체회차 | E45: 적용 | F45: 2632 | G45: 0 | H45: 526 | I45: (연재없음) | J45: (연재없음) | K45: 0 | L45: 0 | M45: 0 | N45: 2106 | O45: 2106
A46: 1017 | B46: (대만) | C46: 前女友 전여친 | D46: 전체회차 | E46: 적용 | F46: 47061 | G46: 21654 | H46: 13743 | I46: (연재없음) | J46: (연재없음) | K46: 0 | L46: 0 | M46: 0 | N46: 54972 | O46: 54972
A47: 1157 | B47: (대만) | C47: 與前妻同居 전처와의 동거 | D47: 전체회차 | E47: 적용 | F47: 127401 | G47: 84934 | H47: 42467 | I47: (연재없음) | J47: (연재없음) | K47: 0 | L47: 0 | M47: 0 | N47: 169868 | O47: 169868
A48: 100104 | B48: (글로벌) | C48: LUNA 루나 | D48: 전체회차 | E48: 적용 | F48: 8208 | G48: 0 | H48: 1641 | I48: (연재없음) | J48: (연재없음) | K48: 0 | L48: 0 | M48: 0 | N48: 6567 | O48: 6567
A49: 100106 | B49: (글로벌) | C49: Nevertheless, I love you. 그래도 사랑해 | D49: 전체회차 | E49: 적용 | F49: 0 | G49: 0 | I49: (연재없음) | J49: (연재없음) | K49: 0 | L49: 0 | M49: 0 | N49: 0 | O49: 0
A50: 100136 | B50: (글로벌) | C50: Lust Awakening 해금 : 시작되는 쾌락 | D50: 전체회차 | E50: 적용 | F50: 19634 | G50: 0 | H50: 3926 | I50: (연재없음) | J50: (연재없음) | K50: 0 | L50: 0 | M50: 0 | N50: 15708 | O50: 15708
A51: 100217 | B51: (글로벌) | C51: How to Deal With the Dead 죽은자를 상대하는 방법 | D51: 전체회차 | E51: 적용 | F51: 0 | G51: 0 | I51: (연재없음) | J51: (연재없음) | K51: 0 | L51: 0 | M51: 0 | N51: 0 | O51: 0
A52: 100254 | B52: (글로벌) | C52: LOVE & WISH 러브 앤 위시 | D52: 전체회차 | E52: 적용 | F52: 0 | G52: 0 | I52: (연재없음) | J52: (연재없음) | K52: 0 | L52: 0 | M52: 0 | N52: 0 | O52: 0
A53: 100290 | B53: (글로벌) | C53: Ah! I'm your pet! 아임펫 | D53: 전체회차 | E53: 적용 | F53: 0 | G53: 0 | I53: (연재없음) | J53: (연재없음) | K53: 0 | L53: 0 | M53: 0 | N53: 0 | O53: 0
A54: 100307 | B54: (글로벌) | C54: Path of Justice 우당탕탕 따식이 | D54: 전체회차 | E54: 적용 | F54: 0 | G54: 0 | I54: (연재없음) | J54: (연재없음) | K54: 0 | L54: 0 | M54: 0 | N54: 0 | O54: 0
A55: 100308 | B55: (글로벌) | C55: The Perfect Roommate 위험한 동거 | D55: 전체회차 | E55: 적용 | F55: 0 | G55: 0 | I55: (연재없음) | J55: (연재없음) | K55: 0 | L55: 0 | M55: 0 | N55: 0 | O55: 0
A56: 100553 | B56: (글로벌) | C56: Living With My Ex-Wife 전처와의 동거 | D56: 전체회차 | E56: 적용 | F56: 90252 | G56: 0 | H56: 18050 | I56: (연재없음) | J56: (연재없음) | K56: 0 | L56: 0 | M56: 0 | N56: 72202 | O56: 72202
A57: 100594 | B57: (글로벌) | C57: Ex-girlfriend 전 여친 | D57: 전체회차 | E57: 적용 | F57: 6544 | G57: 0 | H57: 1308 | I57: (연재없음) | J57: (연재없음) | K57: 0 | L57: 0 | M57: 0 | N57: 5236 | O57: 5236
A58: 100136 | B58: (일본) | C58: 解禁 해금 : 시작되는 쾌락 | D58: 전체회차 | E58: 적용 | F58: 10466 | G58: 0 | H58: 2093 | I58: (연재없음) | J58: (연재없음) | K58: 0 | L58: 0 | M58: 0 | N58: 8373 | O58: 8373
A59: 100594 | B59: (일본) | C59: モトカノ 전 여친 | D59: 전체회차 | E59: 적용 | F59: 8715 | G59: 0 | H59: 1743 | I59: (연재없음) | J59: (연재없음) | K59: 0 | L59: 0 | M59: 0 | N59: 6972 | O59: 6972
A60: 101077 | B60: (일본) | C60: のぞき 엿보기(망가) | D60: 전체회차 | E60: 적용 | F60: 29038 | G60: 0 | H60: 5807 | I60: (연재없음) | J60: (연재없음) | K60: 0 | L60: 0 | M60: 0 | N60: 23231 | O60: 23231
A61: 101095 | B61: (일본) | C61: 偽りの青春 청춘 : 그 몸을 삼키다(망가) | D61: 전체회차 | E61: 적용 | F61: 1332 | G61: 0 | H61: 266 | I61: (연재없음) | J61: (연재없음) | K61: 0 | L61: 0 | M61: 0 | N61: 1066 | O61: 1066
A62: 101114 | B62: (일본) | C62: 解禁 해금 : 시작되는 쾌락(망가) | D62: 전체회차 | E62: 적용 | F62: 7611 | G62: 0 | H62: 1522 | I62: (연재없음) | J62: (연재없음) | K62: 0 | L62: 0 | M62: 0 | N62: 6089 | O62: 6089
...

Sheet 리디
B2: 사이트명 | C2: 작품명 | D2: 소비자매출액 | E2: 유통사수수료 | F2: 케이티매출액 | G2: 케이티수익 | H2: 만화가족 수익 | I2: 비고
B3: 리디 | C3: 대형막내 外 | D3: 11017001 | E3: 0 | F3: =D3 -> 11017001 | G3: =F3*20% -> 2203400.2 | H3: =F3*80% -> 8813600.8 | I3: 9월 RS
B4: 합계 | D4: =SUM(D3:D3) -> 11017001 | E4: =SUM(E3:E3) -> 0 | F4: =SUM(F3:F3) -> 11017001 | G4: =SUM(G3:G3) -> 2203400.2 | H4: =SUM(H3:H3) -> 8813600.8
G5: =F4*0.2 -> 2203400.2 | H5: =F4*0.8 -> 8813600.8
A8: <정산서>
A9: 시리즈명 | B9: 전자책정가 | C9: 단권판매액 | D9: 단권판매권 | E9: 단권무료권 | F9: 대여액 | G9: 대여유료권( ~ 2020-04 대여권) | H9: 대여무료권 | I9: 자유다운금액 | J9: 자유다운권 | K9: 세트판매액 | L9: 세트판매권 | M9: 세트대여액 | N9: 세트대여권 | O9: 취소단권판매액 | P9: 취소단권판매권 | Q9: 취소대여액 | R9: 취소대여권 | S9: 취소자유다운액 | T9: 취소자유다운권 | U9: 취소세트판매액 | V9: 취소세트판매권 | W9: 취소세트대여액 | X9: 취소세트대여권 | Y9: 판매액 | Z9: 판매권 | AA9: 취소액 | AB9: 취소권 | AC9: 일반 판매액 | AD9: 일반 취소액 | AE9: 앱마켓 정산대상액 | AF9: 앱마켓 수수료 | AG9: 앱마켓 취소액 | AH9: 정산액
A10: 대형막내! | B10: 400 | C10: 2800 | D10: 7 | E10: 0 | F10: 10800 | G10: 54 | H10: 0 | I10: 0 | J10: 0 | K10: 0 | L10: 0 | M10: 0 | N10: 0 | O10: 0 | P10: 0 | Q10: -400 | R10: 2 | S10: 0 | T10: 0 | U10: 0 | V10: 0 | W10: 0 | X10: 0 | Y10: 13600 | Z10: 61 | AA10: -400 | AB10: 2 | AC10: 11300 | AD10: -400 | AE10: 2758.1 | AF10: -827.43 | AG10: 0 | AH10: 8981.47
A11: 대형막내! | B11: 400 | C11: 2800 | D11: 7 | E11: 0 | F11: 11400 | G11: 57 | H11: 0 | I11: 0 | J11: 0 | K11: 0 | L11: 0 | M11: 0 | N11: 0 | O11: 0 | P11: 0 | Q11: 0 | R11: 0 | S11: 0 | T11: 0 | U11: 0 | V11: 0 | W11: 0 | X11: 0 | Y11: 14200 | Z11: 64 | AA11: 0 | AB11: 0 | AC11: 12054 | AD11: 0 | AE11: 2573.3 | AF11: -771.99 | AG11: 0 | AH11: 9698.72
A12: 대형막내! | B12: 400 | C12: 2800 | D12: 7 | E12: 0 | F12: 10800 | G12: 54 | H12: 0 | I12: 0 | J12: 0 | K12: 0 | L12: 0 | M12: 0 | N12: 0 | O12: 0 | P12: 0 | Q12: -400 | R12: 2 | S12: 0 | T12: 0 | U12: 0 | V12: 0 | W12: 0 | X12: 0 | Y12: 13600 | Z12: 61 | AA12: -400 | AB12: 2 | AC12: 11600 | AD12: -400 | AE12: 2398.1 | AF12: -719.43 | AG12: 0 | AH12: 9015.07
A13: 대형막내! | B13: 400 | C13: 2400 | D13: 6 | E13: 0 | F13: 9600 | G13: 48 | H13: 0 | I13: 0 | J13: 0 | K13: 0 | L13: 0 | M13: 0 | N13: 0 | O13: 0 | P13: 0 | Q13: -200 | R13: 1 | S13: 0 | T13: 0 | U13: 0 | V13: 0 | W13: 0 | X13: 0 | Y13: 12000 | Z13: 54 | AA13: -200 | AB13: 1 | AC13: 10000 | AD13: -200 | AE13: 2398.1 | AF13: -719.43 | AG13: 0 | AH13: 8035.07
A14: 대형막내! | B14: 400 | C14: 2400 | D14: 6 | E14: 0 | F14: 7400 | G14: 37 | H14: 0 | I14: 0 | J14: 0 | K14: 0 | L14: 0 | M14: 0 | N14: 0 | O14: 0 | P14: 0 | Q14: -200 | R14: 1 | S14: 0 | T14: 0 | U14: 0 | V14: 0 | W14: 0 | X14: 0 | Y14: 9800 | Z14: 43 | AA14: -200 | AB14: 1 | AC14: 7800 | AD14: -200 | AE14: 2398.1 | AF14: -719.43 | AG14: 0 | AH14: 6495.07
A15: 대형막내! | B15: 400 | C15: 2400 | D15: 6 | E15: 0 | F15: 6600 | G15: 33 | H15: 0 | I15: 0 | J15: 0 | K15: 0 | L15: 0 | M15: 0 | N15: 0 | O15: 0 | P15: 0 | Q15: 0 | R15: 0 | S15: 0 | T15: 0 | U15: 0 | V15: 0 | W15: 0 | X15: 0 | Y15: 9000 | Z15: 39 | AA15: 0 | AB15: 0 | AC15: 7200 | AD15: 0 | AE15: 2158.1 | AF15: -647.43 | AG15: 0 | AH15: 6097.47
A16: 대형막내! | B16: 400 | C16: 2400 | D16: 6 | E16: 0 | F16: 6600 | G16: 33 | H16: 0 | I16: 0 | J16: 0 | K16: 0 | L16: 0 | M16: 0 | N16: 0 | O16: 0 | P16: 0 | Q16: 0 | R16: 0 | S16: 0 | T16: 0 | U16: 0 | V16: 0 | W16: 0 | X16: 0 | Y16: 9000 | Z16: 39 | AA16: 0 | AB16: 0 | AC16: 7220 | AD16: 0 | AE16: 2136 | AF16: -640.8 | AG16: 0 | AH16: 6100.64
A17: 대형막내! | B17: 400 | C17: 2400 | D17: 6 | E17: 0 | F17: 5800 | G17: 29 | H17: 0 | I17: 0 | J17: 0 | K17: 0 | L17: 0 | M17: 0 | N17: 0 | O17: 0 | P17: 0 | Q17: 0 | R17: 0 | S17: 0 | T17: 0 | U17: 0 | V17: 0 | W17: 0 | X17: 0 | Y17: 8200 | Z17: 35 | AA17: 0 | AB17: 0 | AC17: 6800 | AD17: 0 | AE17: 1680 | AF17: -504 | AG17: 0 | AH17: 5583.2
A18: 대형막내! | B18: 400 | C18: 2400 | D18: 6 | E18: 0 | F18: 5400 | G18: 27 | H18: 0 | I18: 0 | J18: 0 | K18: 0 | L18: 0 | M18: 0 | N18: 0 | O18: 0 | P18: 0 | Q18: 0 | R18: 0 | S18: 0 | T18: 0 | U18: 0 | V18: 0 | W18: 0 | X18: 0 | Y18: 7800 | Z18: 33 | AA18: 0 | AB18: 0 | AC18: 6200 | AD18: 0 | AE18: 1920 | AF18: -576 | AG18: 0 | AH18: 5280.8
A19: 대형막내! | B19: 400 | C19: 2400 | D19: 6 | E19: 0 | F19: 6000 | G19: 30 | H19: 0 | I19: 0 | J19: 0 | K19: 0 | L19: 0 | M19: 0 | N19: 0 | O19: 0 | P19: 0 | Q19: 0 | R19: 0 | S19: 0 | T19: 0 | U19: 0 | V19: 0 | W19: 0 | X19: 0 | Y19: 8400 | Z19: 36 | AA19: 0 | AB19: 0 | AC19: 6800 | AD19: 0 | AE19: 1920 | AF19: -576 | AG19: 0 | AH19: 5700.8
A20: 대형막내! | B20: 0 | C20: 0 | D20: 0 | E20: 296 | F20: 0 | G20: 0 | H20: 275 | I20: 0 | J20: 0 | K20: 0 | L20: 0 | M20: 0 | N20: 0 | O20: 0 | P20: 2 | Q20: 0 | R20: 2 | S20: 0 | T20: 0 | U20: 0 | V20: 0 | W20: 0 | X20: 0 | Y20: 0 | Z20: 571 | AA20: 0 | AB20: 4 | AC20: 0 | AD20: 0 | AE20: 0 | AF20: 0 | AG20: 0 | AH20: 0
A21: 대형막내! | B21: 400 | C21: 2400 | D21: 6 | E21: 0 | F21: 6200 | G21: 31 | H21: 0 | I21: 0 | J21: 0 | K21: 0 | L21: 0 | M21: 0 | N21: 0 | O21: 0 | P21: 0 | Q21: 0 | R21: 0 | S21: 0 | T21: 0 | U21: 0 | V21: 0 | W21: 0 | X21: 0 | Y21: 8600 | Z21: 37 | AA21: 0 | AB21: 0 | AC21: 7000 | AD21: 0 | AE21: 1920 | AF21: -576 | AG21: 0 | AH21: 5840.8
... A171: 한 번 더 | B171: 0 | C171: 0 | D171: 0 | E171: 2689 | F171: 0 | G171: 0 | H171: 692 | I171: 0 | J171: 0 | K171: 0 | L171: 0 | M171: 0 | N171: 0 | O171: 0 | P171: 0 | Q171: 0 | R171: 0 | S171: 0 | T171: 0 | U171: 0 | V171: 0 | W171: 0 | X171: 0 | Y171: 0 | Z171: 3381 | AA171: 0 | AB171: 0 | AC171: 0 | AD171: 0 | AE171: 0 | AF171: 0 | AG171: 0 | AH171: 0
AH172: =SUM(AH10:AH171) -> 11017001
