Workbook

Sheet 합계(5)
A1: Earnings Date | B1: Transaction Date | C1: Id | D1: Product | E1: Type | F1: Preorder | G1: Qty | H1: Primary ISBN | I1: Imprint Name | J1: Title | K1: Author | L1: Original List Price Currency | M1: Original List Price | N1: List Price Currency | O1: List Price [tax inclusive] | P1: List Price [tax exclusive] | Q1: Country of Sale | R1: Publisher Revenue % | S1: Publisher Revenue | T1: Earnings Currency | U1: Earnings Amount | V1: 출판사 | W1: 작가 CP
A2: 22. 5. 31. | B2: 22. 5. 1. | C2: ID:3108-1093-6844-10720 | D2: Rental 24 Hours | E2: Sale | F2: None | G2: 1 | H2: 9791166300691 | I2: 스토리위즈 | J2: 회귀의 전설 2부 43권 (2부 완결) | K2: 김광수 | L2: KRW | M2: 630 | N2: KRW | O2: 630 | P2: 630 | Q2: KR | R2: 0.7 | S2: 441 | T2: KRW | U2: 441 | V2: =IF(ISERROR(VLOOKUP(K2,[1]작가별정산률!$R:$S,2,0)),"스토리위즈",VLOOKUP(K2,[1]작가별정산률!$R:$S,2,0)) -> 스토리위즈 | W2: =IF(V2="스토리위즈",VLOOKUP(K2,[1]작가별정산률!$A:$B,2,0),V2) -> 김광수
A3: 22. 5. 31. | B3: 22. 5. 1. | C3: ID:3158-0757-5717-35824 | D3: Single Purchase | E3: Sale | F3: None | G3: 1 | H3: 9791166300103 | I3: 스토리위즈 | J3: 회귀의 전설 1부 2권 | K3: 김광수 | L3: KRW | M3: 3200 | N3: KRW | O3: 3200 | P3: 3200 | Q3: KR | R3: 0.7 | S3: 2240 | T3: KRW | U3: 2240 | V3: =IF(ISERROR(VLOOKUP(K3,[1]작가별정산률!$R:$S,2,0)),"스토리위즈",VLOOKUP(K3,[1]작가별정산률!$R:$S,2,0)) -> 스토리위즈 | W3: =IF(V3="스토리위즈",VLOOKUP(K3,[1]작가별정산률!$A:$B,2,0),V3) -> 김광수
A4: 22. 5. 31. | B4: 22. 5. 1. | C4: ID:3102-2585-8968-82625 | D4: Rental 24 Hours | E4: Sale | F4: None | G4: 1 | H4: 9791166300196 | I4: 스토리위즈 | J4: 회귀의 전설 1부 10권 | K4: 김광수 | L4: KRW | M4: 630 | N4: KRW | O4: 630 | P4: 630 | Q4: KR | R4: 0.7 | S4: 441 | T4: KRW | U4: 441 | V4: =IF(ISERROR(VLOOKUP(K4,[1]작가별정산률!$R:$S,2,0)),"스토리위즈",VLOOKUP(K4,[1]작가별정산률!$R:$S,2,0)) -> 스토리위즈 | W4: =IF(V4="스토리위즈",VLOOKUP(K4,[1]작가별정산률!$A:$B,2,0),V4) -> 김광수
A5: 22. 5. 31. | B5: 22. 5. 1. | C5: ID:3121-2286-4383-79263 | D5: Rental 24 Hours | E5: Sale | F5: None | G5: 1 | H5: 9791166300462 | I5: 스토리위즈 | J5: 회귀의 전설 2부 22권 | K5: 김광수 | L5: KRW | M5: 630 | N5: KRW | O5: 630 | P5: 630 | Q5: KR | R5: 0.7 | S5: 441 | T5: KRW | U5: 441 | V5: =IF(ISERROR(VLOOKUP(K5,[1]작가별정산률!$R:$S,2,0)),"스토리위즈",VLOOKUP(K5,[1]작가별정산률!$R:$S,2,0)) -> 스토리위즈 | W5: =IF(V5="스토리위즈",VLOOKUP(K5,[1]작가별정산률!$A:$B,2,0),V5) -> 김광수
A6: 22. 5. 31. | B6: 22. 5. 1. | C6: ID:3171-0891-8179-17547 | D6: Rental 24 Hours | E6: Sale | F6: None | G6: 1 | H6: 9791166300103 | I6: 스토리위즈 | J6: 회귀의 전설 1부 2권 | K6: 김광수 | L6: KRW | M6: 630 | N6: KRW | O6: 630 | P6: 630 | Q6: KR | R6: 0.7 | S6: 441 | T6: KRW | U6: 441 | V6: =IF(ISERROR(VLOOKUP(K6,[1]작가별정산률!$R:$S,2,0)),"스토리위즈",VLOOKUP(K6,[1]작가별정산률!$R:$S,2,0)) -> 스토리위즈 | W6: =IF(V6="스토리위즈",VLOOKUP(K6,[1]작가별정산률!$A:$B,2,0),V6) -> 김광수
A7: 22. 5. 31. | B7: 22. 5. 1. | C7: ID:3160-6049-4440-27619 | D7: Rental 24 Hours | E7: Sale | F7: None | G7: 1 | H7: 9791166300271 | I7: 스토리위즈 | J7: 회귀의 전설 1부 18권 | K7: 김광수 | L7: KRW | M7: 630 | N7: KRW | O7: 630 | P7: 630 | Q7: KR | R7: 0.7 | S7: 441 | T7: KRW | U7: 441 | V7: =IF(ISERROR(VLOOKUP(K7,[1]작가별정산률!$R:$S,2,0)),"스토리위즈",VLOOKUP(K7,[1]작가별정산률!$R:$S,2,0)) -> 스토리위즈 | W7: =IF(V7="스토리위즈",VLOOKUP(K7,[1]작가별정산률!$A:$B,2,0),V7) -> 김광수
A8: 22. 5. 31. | B8: 22. 5. 1. | C8: ID:3169-9987-1767-37955 | D8: Single Purchase | E8: Sale | F8: None | G8: 1 | H8: 9791191562286 | I8: Storywiz Co., Ltd. | J8: 집착 상사 | K8: 장현미 | L8: KRW | M8: 2000 | N8: KRW | O8: 2000 | P8: 2000 | Q8: KR | R8: 0.7 | S8: 1400 | T8: KRW | U8: 1400 | V8: =IF(ISERROR(VLOOKUP(K8,[1]작가별정산률!$R:$S,2,0)),"스토리위즈",VLOOKUP(K8,[1]작가별정산률!$R:$S,2,0)) -> 밀리의 서재 | W8: =IF(V8="스토리위즈",VLOOKUP(K8,[1]작가별정산률!$A:$B,2,0),V8) -> 밀리의 서재
A9: 22. 5. 31. | B9: 22. 5. 1. | C9: ID:3171-6661-7766-39546 | D9: Rental 24 Hours | E9: Sale | F9: None | G9: 1 | H9: 9791166300264 | I9: 스토리위즈 | J9: 회귀의 전설 1부 17권 | K9: 김광수 | L9: KRW | M9: 630 | N9: KRW | O9: 630 | P9: 630 | Q9: KR | R9: 0.7 | S9: 441 | T9: KRW | U9: 441 | V9: =IF(ISERROR(VLOOKUP(K9,[1]작가별정산률!$R:$S,2,0)),"스토리위즈",VLOOKUP(K9,[1]작가별정산률!$R:$S,2,0)) -> 스토리위즈 | W9: =IF(V9="스토리위즈",VLOOKUP(K9,[1]작가별정산률!$A:$B,2,0),V9) -> 김광수
A10: 22. 5. 31. | B10: 22. 5. 1. | C10: ID:3198-8734-9492-13488 | D10: Rental 24 Hours | E10: Sale | F10: None | G10: 1 | H10: 9791166300592 | I10: 스토리위즈 | J10: 회귀의 전설 2부 35권 | K10: 김광수 | L10: KRW | M10: 630 | N10: KRW | O10: 630 | P10: 630 | Q10: KR | R10: 0.7 | S10: 441 | T10: KRW | U10: 441 | V10: =IF(ISERROR(VLOOKUP(K10,[1]작가별정산률!$R:$S,2,0)),"스토리위즈",VLOOKUP(K10,[1]작가별정산률!$R:$S,2,0)) -> 스토리위즈 | W10: =IF(V10="스토리위즈",VLOOKUP(K10,[1]작가별정산률!$A:$B,2,0),V10) -> 김광수
A11: 22. 5. 31. | B11: 22. 5. 1. | C11: ID:3198-1160-5829-08936 | D11: Rental 24 Hours | E11: Sale | F11: None | G11: 1 | H11: 9791166300509 | I11: 스토리위즈 | J11: 회귀의 전설 2부 26권 | K11: 김광수 | L11: KRW | M11: 630 | N11: KRW | O11: 630 | P11: 630 | Q11: KR | R11: 0.7 | S11: 441 | T11: KRW | U11: 441 | V11: =IF(ISERROR(VLOOKUP(K11,[1]작가별정산률!$R:$S,2,0)),"스토리위즈",VLOOKUP(K11,[1]작가별정산률!$R:$S,2,0)) -> 스토리위즈 | W11: =IF(V11="스토리위즈",VLOOKUP(K11,[1]작가별정산률!$A:$B,2,0),V11) -> 김광수
A12: 22. 5. 31. | B12: 22. 5. 1. | C12: ID:3193-0308-3877-21470 | D12: Single Purchase | E12: Sale | F12: None | G12: 1 | H12: 9791191562125 | I12: Storywiz Co., Ltd. | J12: 계약 비서 | K12: 김원경 | L12: KRW | M12: 2500 | N12: KRW | O12: 2500 | P12: 2500 | Q12: KR | R12: 0.7 | S12: 1750 | T12: KRW | U12: 1750 | V12: =IF(ISERROR(VLOOKUP(K12,[1]작가별정산률!$R:$S,2,0)),"스토리위즈",VLOOKUP(K12,[1]작가별정산률!$R:$S,2,0)) -> 밀리의 서재 | W12: =IF(V12="스토리위즈",VLOOKUP(K12,[1]작가별정산률!$A:$B,2,0),V12) -> 밀리의 서재
A13: 22. 5. 31. | B13: 22. 5. 1. | C13: ID:3169-4652-0137-87686 | D13: Rental 24 Hours | E13: Sale | F13: None | G13: 1 | H13: 9791166300615 | I13: 스토리위즈 | J13: 회귀의 전설 2부 37권 | K13: 김광수 | L13: KRW | M13: 630 | N13: KRW | O13: 630 | P13: 630 | Q13: KR | R13: 0.7 | S13: 441 | T13: KRW | U13: 441 | V13: =IF(ISERROR(VLOOKUP(K13,[1]작가별정산률!$R:$S,2,0)),"스토리위즈",VLOOKUP(K13,[1]작가별정산률!$R:$S,2,0)) -> 스토리위즈 | W13: =IF(V13="스토리위즈",VLOOKUP(K13,[1]작가별정산률!$A:$B,2,0),V13) -> 김광수
... A2181: 22. 5. 31. | B2181: 22. 5. 31. | C2181: ID:3136-5034-9038-40659 | D2181: Rental 24 Hours | E2181: Sale | F2181: None | G2181: 1 | H2181: 9791166300134 | I2181: 스토리위즈 | J2181: 회귀의 전설 1부 5권 | K2181: 김광수 | L2181: KRW | M2181: 630 | N2181: KRW | O2181: 630 | P2181: 630 | Q2181: KR | R2181: 0.7 | S2181: 441 | T2181: KRW | U2181: 441 | V2181: =IF(ISERROR(VLOOKUP(K2181,[1]작가별정산률!$R:$S,2,0)),"스토리위즈",VLOOKUP(K2181,[1]작가별정산률!$R:$S,2,0)) -> 스토리위즈 | W2181: =IF(V2181="스토리위즈",VLOOKUP(K2181,[1]작가별정산률!$A:$B,2,0),V2181) -> 김광수
U2182: =SUM(U2:U2181) -> 2081259

Sheet 김광수
A1: Earnings Date | B1: Transaction Date | C1: Id | D1: Product | E1: Type | F1: Preorder | G1: Qty | H1: Primary ISBN | I1: Imprint Name | J1: Title | K1: Author | L1: Original List Price Currency | M1: Original List Price | N1: List Price Currency | O1: List Price [tax inclusive] | P1: List Price [tax exclusive] | Q1: Country of Sale | R1: Publisher Revenue % | S1: Publisher Revenue | T1: Earnings Currency | U1: Earnings Amount | V1: 출판사 | W1: 작가 CP
A2: 22. 5. 31. | B2: 22. 5. 1. | C2: ID:3108-1093-6844-10720 | D2: Rental 24 Hours | E2: Sale | F2: None | G2: 1 | H2: 9791166300691 | I2: 스토리위즈 | J2: 회귀의 전설 2부 43권 (2부 완결) | K2: 김광수 | L2: KRW | M2: 630 | N2: KRW | O2: 630 | P2: 630 | Q2: KR | R2: 0.7 | S2: 441 | T2: KRW | U2: 441 | V2: 스토리위즈 | W2: 김광수
A3: 22. 5. 31. | B3: 22. 5. 1. | C3: ID:3158-0757-5717-35824 | D3: Single Purchase | E3: Sale | F3: None | G3: 1 | H3: 9791166300103 | I3: 스토리위즈 | J3: 회귀의 전설 1부 2권 | K3: 김광수 | L3: KRW | M3: 3200 | N3: KRW | O3: 3200 | P3: 3200 | Q3: KR | R3: 0.7 | S3: 2240 | T3: KRW | U3: 2240 | V3: 스토리위즈 | W3: 김광수
A4: 22. 5. 31. | B4: 22. 5. 1. | C4: ID:3102-2585-8968-82625 | D4: Rental 24 Hours | E4: Sale | F4: None | G4: 1 | H4: 9791166300196 | I4: 스토리위즈 | J4: 회귀의 전설 1부 10권 | K4: 김광수 | L4: KRW | M4: 630 | N4: KRW | O4: 630 | P4: 630 | Q4: KR | R4: 0.7 | S4: 441 | T4: KRW | U4: 441 | V4: 스토리위즈 | W4: 김광수
A5: 22. 5. 31. | B5: 22. 5. 1. | C5: ID:3121-2286-4383-79263 | D5: Rental 24 Hours | E5: Sale | F5: None | G5: 1 | H5: 9791166300462 | I5: 스토리위즈 | J5: 회귀의 전설 2부 22권 | K5: 김광수 | L5: KRW | M5: 630 | N5: KRW | O5: 630 | P5: 630 | Q5: KR | R5: 0.7 | S5: 441 | T5: KRW | U5: 441 | V5: 스토리위즈 | W5: 김광수
A6: 22. 5. 31. | B6: 22. 5. 1. | C6: ID:3171-0891-8179-17547 | D6: Rental 24 Hours | E6: Sale | F6: None | G6: 1 | H6: 9791166300103 | I6: 스토리위즈 | J6: 회귀의 전설 1부 2권 | K6: 김광수 | L6: KRW | M6: 630 | N6: KRW | O6: 630 | P6: 630 | Q6: KR | R6: 0.7 | S6: 441 | T6: KRW | U6: 441 | V6: 스토리위즈 | W6: 김광수
A7: 22. 5. 31. | B7: 22. 5. 1. | C7: ID:3160-6049-4440-27619 | D7: Rental 24 Hours | E7: Sale | F7: None | G7: 1 | H7: 9791166300271 | I7: 스토리위즈 | J7: 회귀의 전설 1부 18권 | K7: 김광수 | L7: KRW | M7: 630 | N7: KRW | O7: 630 | P7: 630 | Q7: KR | R7: 0.7 | S7: 441 | T7: KRW | U7: 441 | V7: 스토리위즈 | W7: 김광수
A8: 22. 5. 31. | B8: 22. 5. 1. | C8: ID:3171-6661-7766-39546 | D8: Rental 24 Hours | E8: Sale | F8: None | G8: 1 | H8: 9791166300264 | I8: 스토리위즈 | J8: 회귀의 전설 1부 17권 | K8: 김광수 | L8: KRW | M8: 630 | N8: KRW | O8: 630 | P8: 630 | Q8: KR | R8: 0.7 | S8: 441 | T8: KRW | U8: 441 | V8: 스토리위즈 | W8: 김광수
A9: 22. 5. 31. | B9: 22. 5. 1. | C9: ID:3198-8734-9492-13488 | D9: Rental 24 Hours | E9: Sale | F9: None | G9: 1 | H9: 9791166300592 | I9: 스토리위즈 | J9: 회귀의 전설 2부 35권 | K9: 김광수 | L9: KRW | M9: 630 | N9: KRW | O9: 630 | P9: 630 | Q9: KR | R9: 0.7 | S9: 441 | T9: KRW | U9: 441 | V9: 스토리위즈 | W9: 김광수
A10: 22. 5. 31. | B10: 22. 5. 1. | C10: ID:3198-1160-5829-08936 | D10: Rental 24 Hours | E10: Sale | F10: None | G10: 1 | H10: 9791166300509 | I10: 스토리위즈 | J10: 회귀의 전설 2부 26권 | K10: 김광수 | L10: KRW | M10: 630 | N10: KRW | O10: 630 | P10: 630 | Q10: KR | R10: 0.7 | S10: 441 | T10: KRW | U10: 441 | V10: 스토리위즈 | W10: 김광수
A11: 22. 5. 31. | B11: 22. 5. 1. | C11: ID:3169-4652-0137-87686 | D11: Rental 24 Hours | E11: Sale | F11: None | G11: 1 | H11: 9791166300615 | I11: 스토리위즈 | J11: 회귀의 전설 2부 37권 | K11: 김광수 | L11: KRW | M11: 630 | N11: KRW | O11: 630 | P11: 630 | Q11: KR | R11: 0.7 | S11: 441 | T11: KRW | U11: 441 | V11: 스토리위즈 | W11: 김광수
A12: 22. 5. 31. | B12: 22. 5. 1. | C12: ID:3170-5913-7960-38798 | D12: Rental 24 Hours | E12: Sale | F12: None | G12: 1 | H12: 9791166300202 | I12: 스토리위즈 | J12: 회귀의 전설 1부 11권 | K12: 김광수 | L12: KRW | M12: 630 | N12: KRW | O12: 630 | P12: 630 | Q12: KR | R12: 0.7 | S12: 441 | T12: KRW | U12: 441 | V12: 스토리위즈 | W12: 김광수
A13: 22. 5. 31. | B13: 22. 5. 1. | C13: ID:3131-1826-3654-73380 | D13: Rental 24 Hours | E13: Sale | F13: None | G13: 1 | H13: 9791166300523 | I13: 스토리위즈 | J13: 회귀의 전설 2부 28권 | K13: 김광수 | L13: KRW | M13: 630 | N13: KRW | O13: 630 | P13: 630 | Q13: KR | R13: 0.7 | S13: 441 | T13: KRW | U13: 441 | V13: 스토리위즈 | W13: 김광수
... A1061: 22. 5. 31. | B1061: 22. 5. 31. | C1061: ID:3136-5034-9038-40659 | D1061: Rental 24 Hours | E1061: Sale | F1061: None | G1061: 1 | H1061: 9791166300134 | I1061: 스토리위즈 | J1061: 회귀의 전설 1부 5권 | K1061: 김광수 | L1061: KRW | M1061: 630 | N1061: KRW | O1061: 630 | P1061: 630 | Q1061: KR | R1061: 0.7 | S1061: 441 | T1061: KRW | U1061: 441 | V1061: 스토리위즈 | W1061: 김광수

Sheet 밀리의 서재
A1: Earnings Date | B1: Transaction Date | C1: Id | D1: Product | E1: Type | F1: Preorder | G1: Qty | H1: Primary ISBN | I1: Imprint Name | J1: Title | K1: Author | L1: Original List Price Currency | M1: Original List Price | N1: List Price Currency | O1: List Price [tax inclusive] | P1: List Price [tax exclusive] | Q1: Country of Sale | R1: Publisher Revenue % | S1: Publisher Revenue | T1: Earnings Currency | U1: Earnings Amount | V1: 출판사 | W1: 작가 CP
A2: 22. 5. 31. | B2: 22. 5. 1. | C2: ID:3169-9987-1767-37955 | D2: Single Purchase | E2: Sale | F2: None | G2: 1 | H2: 9791191562286 | I2: Storywiz Co., Ltd. | J2: 집착 상사 | K2: 장현미 | L2: KRW | M2: 2000 | N2: KRW | O2: 2000 | P2: 2000 | Q2: KR | R2: 0.7 | S2: 1400 | T2: KRW | U2: 1400 | V2: 밀리의 서재 | W2: 밀리의 서재
A3: 22. 5. 31. | B3: 22. 5. 1. | C3: ID:3193-0308-3877-21470 | D3: Single Purchase | E3: Sale | F3: None | G3: 1 | H3: 9791191562125 | I3: Storywiz Co., Ltd. | J3: 계약 비서 | K3: 김원경 | L3: KRW | M3: 2500 | N3: KRW | O3: 2500 | P3: 2500 | Q3: KR | R3: 0.7 | S3: 1750 | T3: KRW | U3: 1750 | V3: 밀리의 서재 | W3: 밀리의 서재
A4: 22. 5. 31. | B4: 22. 5. 1. | C4: ID:3169-1551-7686-98511 | D4: Single Purchase | E4: Sale | F4: None | G4: 1 | H4: 9791191562125 | I4: Storywiz Co., Ltd. | J4: 계약 비서 | K4: 김원경 | L4: KRW | M4: 2500 | N4: KRW | O4: 2500 | P4: 2500 | Q4: KR | R4: 0.7 | S4: 1750 | T4: KRW | U4: 1750 | V4: 밀리의 서재 | W4: 밀리의 서재
A5: 22. 5. 31. | B5: 22. 5. 1. | C5: ID:3172-5326-7250-34225 | D5: Single Purchase | E5: Sale | F5: None | G5: 1 | H5: 9791191562101 | I5: Storywiz Co., Ltd. | J5: 연애의 시작 | K5: 차크 | L5: KRW | M5: 3000 | N5: USD | O5: 2.47 | P5: 2.47 | Q5: US | R5: 0.7 | S5: 1.73 | T5: KRW | U5: 2173 | V5: 밀리의 서재 | W5: 밀리의 서재
A6: 22. 5. 31. | B6: 22. 5. 1. | C6: ID:3107-0905-2036-63344 | D6: Single Purchase | E6: Sale | F6: None | G6: 1 | H6: 9791191562125 | I6: Storywiz Co., Ltd. | J6: 계약 비서 | K6: 김원경 | L6: KRW | M6: 2500 | N6: KRW | O6: 2500 | P6: 2500 | Q6: KR | R6: 0.7 | S6: 1750 | T6: KRW | U6: 1750 | V6: 밀리의 서재 | W6: 밀리의 서재
A7: 22. 5. 31. | B7: 22. 5. 1. | C7: ID:3116-8160-1536-38832 | D7: Single Purchase | E7: Sale | F7: None | G7: 1 | H7: 9791191562125 | I7: Storywiz Co., Ltd. | J7: 계약 비서 | K7: 김원경 | L7: KRW | M7: 2500 | N7: KRW | O7: 2500 | P7: 2500 | Q7: KR | R7: 0.7 | S7: 1750 | T7: KRW | U7: 1750 | V7: 밀리의 서재 | W7: 밀리의 서재
A8: 22. 5. 31. | B8: 22. 5. 1. | C8: ID:3178-4115-9728-56550 | D8: Single Purchase | E8: Sale | F8: None | G8: 1 | H8: 9791191562347 | I8: Storywiz Co., Ltd. | J8: 인턴사원 | K8: 트리플베리 | L8: KRW | M8: 3200 | N8: KRW | O8: 3200 | P8: 3200 | Q8: KR | R8: 0.7 | S8: 2240 | T8: KRW | U8: 2240 | V8: 밀리의 서재 | W8: 밀리의 서재
A9: 22. 5. 31. | B9: 22. 5. 1. | C9: ID:3141-9170-9771-08623 | D9: Single Purchase | E9: Sale | F9: None | G9: 1 | H9: 9791191562248 | I9: Storywiz Co., Ltd. | J9: 엑스 비서 | K9: 비향 | L9: KRW | M9: 2000 | N9: KRW | O9: 2000 | P9: 2000 | Q9: KR | R9: 0.7 | S9: 1400 | T9: KRW | U9: 1400 | V9: 밀리의 서재 | W9: 밀리의 서재
A10: 22. 5. 31. | B10: 22. 5. 1. | C10: ID:3185-1147-8851-38447 | D10: Single Purchase | E10: Sale | F10: None | G10: 1 | H10: 9791191562309 | I10: Storywiz Co., Ltd. | J10: 일교차 | K10: 해화 | L10: KRW | M10: 2500 | N10: USD | O10: 2.06 | P10: 2.06 | Q10: US | R10: 0.7 | S10: 1.44 | T10: KRW | U10: 1822 | V10: 밀리의 서재 | W10: 밀리의 서재
A11: 22. 5. 31. | B11: 22. 5. 2. | C11: ID:3170-5040-5426-47740 | D11: Single Purchase | E11: Sale | F11: None | G11: 1 | H11: 9791191562125 | I11: Storywiz Co., Ltd. | J11: 계약 비서 | K11: 김원경 | L11: KRW | M11: 2500 | N11: KRW | O11: 2500 | P11: 2500 | Q11: KR | R11: 0.7 | S11: 1750 | T11: KRW | U11: 1750 | V11: 밀리의 서재 | W11: 밀리의 서재
A12: 22. 5. 31. | B12: 22. 5. 2. | C12: ID:3142-7364-7216-85919 | D12: Single Purchase | E12: Sale | F12: None | G12: 1 | H12: 9791191562125 | I12: Storywiz Co., Ltd. | J12: 계약 비서 | K12: 김원경 | L12: KRW | M12: 2500 | N12: KRW | O12: 2500 | P12: 2500 | Q12: KR | R12: 0.7 | S12: 1750 | T12: KRW | U12: 1750 | V12: 밀리의 서재 | W12: 밀리의 서재
A13: 22. 5. 31. | B13: 22. 5. 2. | C13: ID:3184-2714-7107-00291 | D13: Single Purchase | E13: Sale | F13: None | G13: 1 | H13: 9791191562262 | I13: Storywiz Co., Ltd. | J13: 미쳐 버린 밤 | K13: 백화(百花) | L13: KRW | M13: 2000 | N13: KRW | O13: 2000 | P13: 2000 | Q13: KR | R13: 0.7 | S13: 1400 | T13: KRW | U13: 1400 | V13: 밀리의 서재 | W13: 밀리의 서재
... A336: 22. 5. 31. | B336: 22. 5. 31. | C336: ID:3121-5113-5924-16328 | D336: Single Purchase | E336: Sale | F336: None | G336: 1 | H336: 9791191562477 | I336: Storywiz Co., Ltd. | J336: 수면제 | K336: 명우 | L336: KRW | M336: 2000 | N336: KRW | O336: 2000 | P336: 2000 | Q336: KR | R336: 0.7 | S336: 1400 | T336: KRW | U336: 1400 | V336: 밀리의 서재 | W336: 밀리의 서재

Sheet 권용찬
A1: Earnings Date | B1: Transaction Date | C1: Id | D1: Product | E1: Type | F1: Preorder | G1: Qty | H1: Primary ISBN | I1: Imprint Name | J1: Title | K1: Author | L1: Original List Price Currency | M1: Original List Price | N1: List Price Currency | O1: List Price [tax inclusive] | P1: List Price [tax exclusive] | Q1: Country of Sale | R1: Publisher Revenue % | S1: Publisher Revenue | T1: Earnings Currency | U1: Earnings Amount | V1: 출판사 | W1: 작가 CP
A2: 22. 5. 31. | B2: 22. 5. 1. | C2: ID:3178-8258-6537-03263 | D2: Rental 24 Hours | E2: Sale | F2: None | G2: 1 | H2: 9791166061103 | I2: 스토리위즈 | J2: 파계 4권 | K2: 권용찬 | L2: KRW | M2: 900 | N2: KRW | O2: 900 | P2: 900 | Q2: KR | R2: 0.7 | S2: 630 | T2: KRW | U2: 630 | V2: 스토리위즈 | W2: 권용찬
A3: 22. 5. 31. | B3: 22. 5. 1. | C3: ID:3186-3129-6637-61166 | D3: Rental 24 Hours | E3: Sale | F3: None | G3: 1 | H3: 9791159283086 | I3: 스토리위즈 | J3: 신마협도 2권 | K3: 권용찬 | L3: KRW | M3: 900 | N3: KRW | O3: 900 | P3: 900 | Q3: KR | R3: 0.7 | S3: 630 | T3: KRW | U3: 630 | V3: 스토리위즈 | W3: 권용찬
A4: 22. 5. 31. | B4: 22. 5. 1. | C4: ID:3175-1589-1193-30039 | D4: Single Purchase | E4: Sale | F4: None | G4: 1 | H4: 9791197098444 | I4: 스토리위즈 | J4: 검산도해 5권 | K4: 권용찬 | L4: KRW | M4: 3200 | N4: KRW | O4: 3200 | P4: 3200 | Q4: KR | R4: 0.7 | S4: 2240 | T4: KRW | U4: 2240 | V4: 스토리위즈 | W4: 권용찬
A5: 22. 5. 31. | B5: 22. 5. 1. | C5: ID:3179-4887-4225-38645 | D5: Single Purchase | E5: Sale | F5: None | G5: 1 | H5: 9791197098451 | I5: 스토리위즈 | J5: 검산도해 6권 | K5: 권용찬 | L5: KRW | M5: 3200 | N5: KRW | O5: 3200 | P5: 3200 | Q5: KR | R5: 0.7 | S5: 2240 | T5: KRW | U5: 2240 | V5: 스토리위즈 | W5: 권용찬
A6: 22. 5. 31. | B6: 22. 5. 1. | C6: ID:3125-7770-2081-88267 | D6: Rental 24 Hours | E6: Sale | F6: None | G6: 1 | H6: 9791159285912 | I6: 스토리위즈 | J6: 상왕 진우몽 9권(완결) | K6: 권용찬 | L6: KRW | M6: 630 | N6: KRW | O6: 630 | P6: 630 | Q6: KR | R6: 0.7 | S6: 441 | T6: KRW | U6: 441 | V6: 스토리위즈 | W6: 권용찬
A7: 22. 5. 31. | B7: 22. 5. 2. | C7: ID:3186-6408-6992-02559 | D7: Single Purchase | E7: Sale | F7: None | G7: 1 | H7: 9791166064111 | I7: 스토리위즈 | J7: 용무쌍 8권 (완결) | K7: 권용찬 | L7: KRW | M7: 3200 | N7: NZD | O7: 3.8 | P7: 3.3 | Q7: NZ | R7: 0.7 | S7: 2.31 | T7: KRW | U7: 1882 | V7: 스토리위즈 | W7: 권용찬
A8: 22. 5. 31. | B8: 22. 5. 2. | C8: ID:3149-4365-9142-34962 | D8: Rental 24 Hours | E8: Sale | F8: None | G8: 1 | H8: 9791166061080 | I8: 스토리위즈 | J8: 파계 2권 | K8: 권용찬 | L8: KRW | M8: 900 | N8: KRW | O8: 900 | P8: 900 | Q8: KR | R8: 0.7 | S8: 630 | T8: KRW | U8: 630 | V8: 스토리위즈 | W8: 권용찬
A9: 22. 5. 31. | B9: 22. 5. 2. | C9: ID:3103-5079-9675-40791 | D9: Single Purchase | E9: Sale | F9: None | G9: 1 | H9: 9791197098468 | I9: 스토리위즈 | J9: 검산도해 7권 (완결) | K9: 권용찬 | L9: KRW | M9: 3200 | N9: KRW | O9: 3200 | P9: 3200 | Q9: KR | R9: 0.7 | S9: 2240 | T9: KRW | U9: 2240 | V9: 스토리위즈 | W9: 권용찬
A10: 22. 5. 31. | B10: 22. 5. 2. | C10: ID:3128-5495-9554-65048 | D10: Rental 24 Hours | E10: Sale | F10: None | G10: 1 | H10: 9791166061097 | I10: 스토리위즈 | J10: 파계 3권 | K10: 권용찬 | L10: KRW | M10: 900 | N10: KRW | O10: 900 | P10: 900 | Q10: KR | R10: 0.7 | S10: 630 | T10: KRW | U10: 630 | V10: 스토리위즈 | W10: 권용찬
A11: 22. 5. 31. | B11: 22. 5. 2. | C11: ID:3109-5542-5679-26024 | D11: Rental 24 Hours | E11: Sale | F11: None | G11: 1 | H11: 9791166064135 | I11: 스토리위즈 | J11: 용중신권 2권 | K11: 권용찬 | L11: KRW | M11: 900 | N11: KRW | O11: 900 | P11: 900 | Q11: KR | R11: 0.7 | S11: 630 | T11: KRW | U11: 630 | V11: 스토리위즈 | W11: 권용찬
A12: 22. 5. 31. | B12: 22. 5. 2. | C12: ID:3108-4154-1609-36144 | D12: Rental 24 Hours | E12: Sale | F12: None | G12: 1 | H12: 9791166064135 | I12: 스토리위즈 | J12: 용중신권 2권 | K12: 권용찬 | L12: KRW | M12: 900 | N12: KRW | O12: 900 | P12: 900 | Q12: KR | R12: 0.7 | S12: 630 | T12: KRW | U12: 630 | V12: 스토리위즈 | W12: 권용찬
A13: 22. 5. 31. | B13: 22. 5. 2. | C13: ID:3188-4023-3101-44637 | D13: Rental 24 Hours | E13: Sale | F13: None | G13: 1 | H13: 9791159283086 | I13: 스토리위즈 | J13: 신마협도 2권 | K13: 권용찬 | L13: KRW | M13: 900 | N13: KRW | O13: 900 | P13: 900 | Q13: KR | R13: 0.7 | S13: 630 | T13: KRW | U13: 630 | V13: 스토리위즈 | W13: 권용찬
... A365: 22. 5. 31. | B365: 22. 5. 31. | C365: ID:3111-8975-1881-56724 | D365: Rental 24 Hours | E365: Sale | F365: None | G365: 1 | H365: 9791166061141 | I365: 스토리위즈 | J365: 파계 8권 | K365: 권용찬 | L365: KRW | M365: 900 | N365: KRW | O365: 900 | P365: 900 | Q365: KR | R365: 0.7 | S365: 630 | T365: KRW | U365: 630 | V365: 스토리위즈 | W365: 권용찬

Sheet 예로나
A1: Earnings Date | B1: Transaction Date | C1: Id | D1: Product | E1: Type | F1: Preorder | G1: Qty | H1: Primary ISBN | I1: Imprint Name | J1: Title | K1: Author | L1: Original List Price Currency | M1: Original List Price | N1: List Price Currency | O1: List Price [tax inclusive] | P1: List Price [tax exclusive] | Q1: Country of Sale | R1: Publisher Revenue % | S1: Publisher Revenue | T1: Earnings Currency | U1: Earnings Amount | V1: 출판사 | W1: 작가 CP
A2: 22. 5. 31. | B2: 22. 5. 2. | C2: ID:3108-3129-6131-13708 | D2: Rental 24 Hours | E2: Sale | F2: None | G2: 1 | H2: 9791166064395 | I2: 스토리위즈 | J2: 기사가문 망나니는 10클래스 2권 | K2: 예로나 | L2: KRW | M2: 720 | N2: KRW | O2: 720 | P2: 720 | Q2: KR | R2: 0.7 | S2: 504 | T2: KRW | U2: 504 | V2: 스토리위즈 | W2: 예로나
A3: 22. 5. 31. | B3: 22. 5. 3. | C3: ID:3140-1441-8735-20264 | D3: Rental 24 Hours | E3: Sale | F3: None | G3: 1 | H3: 9791166064395 | I3: 스토리위즈 | J3: 기사가문 망나니는 10클래스 2권 | K3: 예로나 | L3: KRW | M3: 720 | N3: KRW | O3: 720 | P3: 720 | Q3: KR | R3: 0.7 | S3: 504 | T3: KRW | U3: 504 | V3: 스토리위즈 | W3: 예로나
A4: 22. 5. 31. | B4: 22. 5. 3. | C4: ID:3142-0350-8114-51681 | D4: Rental 24 Hours | E4: Sale | F4: None | G4: 1 | H4: 9791166064401 | I4: 스토리위즈 | J4: 기사가문 망나니는 10클래스 3권 | K4: 예로나 | L4: KRW | M4: 720 | N4: KRW | O4: 720 | P4: 720 | Q4: KR | R4: 0.7 | S4: 504 | T4: KRW | U4: 504 | V4: 스토리위즈 | W4: 예로나
A5: 22. 5. 31. | B5: 22. 5. 4. | C5: ID:3105-6603-1046-80088 | D5: Rental 24 Hours | E5: Sale | F5: None | G5: 1 | H5: 9791166064418 | I5: 스토리위즈 | J5: 기사가문 망나니는 10클래스 4권 | K5: 예로나 | L5: KRW | M5: 720 | N5: KRW | O5: 720 | P5: 720 | Q5: KR | R5: 0.7 | S5: 504 | T5: KRW | U5: 504 | V5: 스토리위즈 | W5: 예로나
A6: 22. 5. 31. | B6: 22. 5. 8. | C6: ID:3182-9328-5987-41358 | D6: Rental 24 Hours | E6: Sale | F6: None | G6: 1 | H6: 9791166064395 | I6: 스토리위즈 | J6: 기사가문 망나니는 10클래스 2권 | K6: 예로나 | L6: KRW | M6: 720 | N6: KRW | O6: 720 | P6: 720 | Q6: KR | R6: 0.7 | S6: 504 | T6: KRW | U6: 504 | V6: 스토리위즈 | W6: 예로나
A7: 22. 5. 31. | B7: 22. 5. 8. | C7: ID:3102-3707-7859-95960 | D7: Rental 24 Hours | E7: Sale | F7: None | G7: 1 | H7: 9791166064401 | I7: 스토리위즈 | J7: 기사가문 망나니는 10클래스 3권 | K7: 예로나 | L7: KRW | M7: 720 | N7: KRW | O7: 720 | P7: 720 | Q7: KR | R7: 0.7 | S7: 504 | T7: KRW | U7: 504 | V7: 스토리위즈 | W7: 예로나
A8: 22. 5. 31. | B8: 22. 5. 9. | C8: ID:3135-9661-3886-36632 | D8: Rental 24 Hours | E8: Sale | F8: None | G8: 1 | H8: 9791166064418 | I8: 스토리위즈 | J8: 기사가문 망나니는 10클래스 4권 | K8: 예로나 | L8: KRW | M8: 720 | N8: KRW | O8: 720 | P8: 720 | Q8: KR | R8: 0.7 | S8: 504 | T8: KRW | U8: 504 | V8: 스토리위즈 | W8: 예로나
A9: 22. 5. 31. | B9: 22. 5. 9. | C9: ID:3163-9997-3403-10340 | D9: Single Purchase | E9: Sale | F9: None | G9: 1 | H9: 9791166064395 | I9: 스토리위즈 | J9: 기사가문 망나니는 10클래스 2권 | K9: 예로나 | L9: KRW | M9: 3200 | N9: KRW | O9: 3200 | P9: 3200 | Q9: KR | R9: 0.7 | S9: 2240 | T9: KRW | U9: 2240 | V9: 스토리위즈 | W9: 예로나
A10: 22. 5. 31. | B10: 22. 5. 9. | C10: ID:3163-9997-3403-10340 | D10: Single Purchase | E10: Sale | F10: None | G10: 1 | H10: 9791166064401 | I10: 스토리위즈 | J10: 기사가문 망나니는 10클래스 3권 | K10: 예로나 | L10: KRW | M10: 3200 | N10: KRW | O10: 3200 | P10: 3200 | Q10: KR | R10: 0.7 | S10: 2240 | T10: KRW | U10: 2240 | V10: 스토리위즈 | W10: 예로나
A11: 22. 5. 31. | B11: 22. 5. 9. | C11: ID:3163-9997-3403-10340 | D11: Single Purchase | E11: Sale | F11: None | G11: 1 | H11: 9791166064418 | I11: 스토리위즈 | J11: 기사가문 망나니는 10클래스 4권 | K11: 예로나 | L11: KRW | M11: 3200 | N11: KRW | O11: 3200 | P11: 3200 | Q11: KR | R11: 0.7 | S11: 2240 | T11: KRW | U11: 2240 | V11: 스토리위즈 | W11: 예로나
A12: 22. 5. 31. | B12: 22. 5. 9. | C12: ID:3187-2251-7449-85213 | D12: Rental 24 Hours | E12: Sale | F12: None | G12: 1 | H12: 9791166064425 | I12: 스토리위즈 | J12: 기사가문 망나니는 10클래스 5권 | K12: 예로나 | L12: KRW | M12: 720 | N12: KRW | O12: 720 | P12: 720 | Q12: KR | R12: 0.7 | S12: 504 | T12: KRW | U12: 504 | V12: 스토리위즈 | W12: 예로나
A13: 22. 5. 31. | B13: 22. 5. 10. | C13: ID:3185-6937-3197-57208 | D13: Rental 24 Hours | E13: Sale | F13: None | G13: 1 | H13: 9791166064432 | I13: 스토리위즈 | J13: 기사가문 망나니는 10클래스 6권 | K13: 예로나 | L13: KRW | M13: 720 | N13: KRW | O13: 720 | P13: 720 | Q13: KR | R13: 0.7 | S13: 504 | T13: KRW | U13: 504 | V13: 스토리위즈 | W13: 예로나
... A36: 22. 5. 31. | B36: 22. 5. 31. | C36: ID:3176-7877-1640-82589 | D36: Rental 24 Hours | E36: Sale | F36: None | G36: 1 | H36: 9791166064401 | I36: 스토리위즈 | J36: 기사가문 망나니는 10클래스 3권 | K36: 예로나 | L36: KRW | M36: 720 | N36: KRW | O36: 720 | P36: 720 | Q36: KR | R36: 0.7 | S36: 504 | T36: KRW | U36: 504 | V36: 스토리위즈 | W36: 예로나

Sheet 독고진
A1: Earnings Date | B1: Transaction Date | C1: Id | D1: Product | E1: Type | F1: Preorder | G1: Qty | H1: Primary ISBN | I1: Imprint Name | J1: Title | K1: Author | L1: Original List Price Currency | M1: Original List Price | N1: List Price Currency | O1: List Price [tax inclusive] | P1: List Price [tax exclusive] | Q1: Country of Sale | R1: Publisher Revenue % | S1: Publisher Revenue | T1: Earnings Currency | U1: Earnings Amount | V1: 출판사 | W1: 작가 CP
A2: 22. 5. 31. | B2: 22. 5. 2. | C2: ID:3153-9908-8105-08635 | D2: Rental 24 Hours | E2: Sale | F2: None | G2: 1 | H2: 9791159282843 | I2: 스토리위즈 | J2: [완전판] 스트라이커 2권 | K2: 독고진 | L2: KRW | M2: 630 | N2: KRW | O2: 630 | P2: 630 | Q2: KR | R2: 0.7 | S2: 441 | T2: KRW | U2: 441 | V2: 스토리위즈 | W2: 독고진
A3: 22. 5. 31. | B3: 22. 5. 2. | C3: ID:3155-9447-9689-19679 | D3: Rental 24 Hours | E3: Sale | F3: None | G3: 1 | H3: 9791159282850 | I3: 스토리위즈 | J3: [완전판] 스트라이커 3권 | K3: 독고진 | L3: KRW | M3: 630 | N3: KRW | O3: 630 | P3: 630 | Q3: KR | R3: 0.7 | S3: 441 | T3: KRW | U3: 441 | V3: 스토리위즈 | W3: 독고진
A4: 22. 5. 31. | B4: 22. 5. 2. | C4: ID:3115-3159-4785-91488 | D4: Rental 24 Hours | E4: Sale | F4: None | G4: 1 | H4: 9791159282867 | I4: 스토리위즈 | J4: [완전판] 스트라이커 4권 | K4: 독고진 | L4: KRW | M4: 630 | N4: KRW | O4: 630 | P4: 630 | Q4: KR | R4: 0.7 | S4: 441 | T4: KRW | U4: 441 | V4: 스토리위즈 | W4: 독고진
A5: 22. 5. 31. | B5: 22. 5. 3. | C5: ID:3122-7439-1099-78758 | D5: Rental 24 Hours | E5: Sale | F5: None | G5: 1 | H5: 9791159282874 | I5: 스토리위즈 | J5: [완전판] 스트라이커 5권 | K5: 독고진 | L5: KRW | M5: 630 | N5: KRW | O5: 630 | P5: 630 | Q5: KR | R5: 0.7 | S5: 441 | T5: KRW | U5: 441 | V5: 스토리위즈 | W5: 독고진
A6: 22. 5. 31. | B6: 22. 5. 3. | C6: ID:3128-5290-7412-89468 | D6: Rental 24 Hours | E6: Sale | F6: None | G6: 1 | H6: 9791159282881 | I6: 스토리위즈 | J6: [완전판] 스트라이커 6권 | K6: 독고진 | L6: KRW | M6: 630 | N6: KRW | O6: 630 | P6: 630 | Q6: KR | R6: 0.7 | S6: 441 | T6: KRW | U6: 441 | V6: 스토리위즈 | W6: 독고진
A7: 22. 5. 31. | B7: 22. 5. 4. | C7: ID:3161-6469-2072-62608 | D7: Rental 24 Hours | E7: Sale | F7: None | G7: 1 | H7: 9791159282898 | I7: 스토리위즈 | J7: [완전판] 스트라이커 7권 | K7: 독고진 | L7: KRW | M7: 630 | N7: KRW | O7: 630 | P7: 630 | Q7: KR | R7: 0.7 | S7: 441 | T7: KRW | U7: 441 | V7: 스토리위즈 | W7: 독고진
A8: 22. 5. 31. | B8: 22. 5. 5. | C8: ID:3104-8834-0799-68575 | D8: Rental 24 Hours | E8: Sale | F8: None | G8: 1 | H8: 9791159282904 | I8: 스토리위즈 | J8: [완전판] 스트라이커 8권 | K8: 독고진 | L8: KRW | M8: 630 | N8: KRW | O8: 630 | P8: 630 | Q8: KR | R8: 0.7 | S8: 441 | T8: KRW | U8: 441 | V8: 스토리위즈 | W8: 독고진
A9: 22. 5. 31. | B9: 22. 5. 5. | C9: ID:3127-7347-8207-57329 | D9: Rental 24 Hours | E9: Sale | F9: None | G9: 1 | H9: 9791159282911 | I9: 스토리위즈 | J9: [완전판] 스트라이커 9권 | K9: 독고진 | L9: KRW | M9: 630 | N9: KRW | O9: 630 | P9: 630 | Q9: KR | R9: 0.7 | S9: 441 | T9: KRW | U9: 441 | V9: 스토리위즈 | W9: 독고진
A10: 22. 5. 31. | B10: 22. 5. 6. | C10: ID:3187-8636-5405-69564 | D10: Rental 24 Hours | E10: Sale | F10: None | G10: 1 | H10: 9791159282928 | I10: 스토리위즈 | J10: [완전판] 스트라이커 10권 | K10: 독고진 | L10: KRW | M10: 630 | N10: KRW | O10: 630 | P10: 630 | Q10: KR | R10: 0.7 | S10: 441 | T10: KRW | U10: 441 | V10: 스토리위즈 | W10: 독고진
A11: 22. 5. 31. | B11: 22. 5. 8. | C11: ID:3124-0370-6972-46108 | D11: Rental 24 Hours | E11: Sale | F11: None | G11: 1 | H11: 9791159282843 | I11: 스토리위즈 | J11: [완전판] 스트라이커 2권 | K11: 독고진 | L11: KRW | M11: 630 | N11: KRW | O11: 630 | P11: 630 | Q11: KR | R11: 0.7 | S11: 441 | T11: KRW | U11: 441 | V11: 스토리위즈 | W11: 독고진
A12: 22. 5. 31. | B12: 22. 5. 8. | C12: ID:3199-9359-3763-77805 | D12: Rental 24 Hours | E12: Sale | F12: None | G12: 1 | H12: 9791159282850 | I12: 스토리위즈 | J12: [완전판] 스트라이커 3권 | K12: 독고진 | L12: KRW | M12: 630 | N12: KRW | O12: 630 | P12: 630 | Q12: KR | R12: 0.7 | S12: 441 | T12: KRW | U12: 441 | V12: 스토리위즈 | W12: 독고진
A13: 22. 5. 31. | B13: 22. 5. 8. | C13: ID:3139-0450-4190-88260 | D13: Rental 24 Hours | E13: Sale | F13: None | G13: 1 | H13: 9791159282935 | I13: 스토리위즈 | J13: [완전판] 스트라이커 11권 | K13: 독고진 | L13: KRW | M13: 630 | N13: KRW | O13: 630 | P13: 630 | Q13: KR | R13: 0.7 | S13: 441 | T13: KRW | U13: 441 | V13: 스토리위즈 | W13: 독고진
... A66: 22. 5. 31. | B66: 22. 5. 28. | C66: ID:3124-9408-8689-04837 | D66: Rental 24 Hours | E66: Sale | F66: None | G66: 1 | H66: 9791159282867 | I66: 스토리위즈 | J66: [완전판] 스트라이커 4권 | K66: 독고진 | L66: KRW | M66: 630 | N66: KRW | O66: 630 | P66: 630 | Q66: KR | R66: 0.7 | S66: 441 | T66: KRW | U66: 441 | V66: 스토리위즈 | W66: 독고진

Sheet 전혁
A1: Earnings Date | B1: Transaction Date | C1: Id | D1: Product | E1: Type | F1: Preorder | G1: Qty | H1: Primary ISBN | I1: Imprint Name | J1: Title | K1: Author | L1: Original List Price Currency | M1: Original List Price | N1: List Price Currency | O1: List Price [tax inclusive] | P1: List Price [tax exclusive] | Q1: Country of Sale | R1: Publisher Revenue % | S1: Publisher Revenue | T1: Earnings Currency | U1: Earnings Amount | V1: 출판사 | W1: 작가 CP
A2: 22. 5. 31. | B2: 22. 5. 3. | C2: ID:3197-6524-6764-11097 | D2: Rental 24 Hours | E2: Sale | F2: None | G2: 1 | H2: 9791159285035 | I2: 스토리위즈 | J2: 절륜공자 10권(완결) | K2: 전혁 | L2: KRW | M2: 630 | N2: KRW | O2: 630 | P2: 630 | Q2: KR | R2: 0.7 | S2: 441 | T2: KRW | U2: 441 | V2: 스토리위즈 | W2: 전혁
A3: 22. 5. 31. | B3: 22. 5. 4. | C3: ID:3172-2077-2749-05287 | D3: Rental 24 Hours | E3: Sale | F3: None | G3: 1 | H3: 9791159284953 | I3: 스토리위즈 | J3: 절륜공자 2권 | K3: 전혁 | L3: KRW | M3: 630 | N3: KRW | O3: 630 | P3: 630 | Q3: KR | R3: 0.7 | S3: 441 | T3: KRW | U3: 441 | V3: 스토리위즈 | W3: 전혁
A4: 22. 5. 31. | B4: 22. 5. 16. | C4: ID:3145-3407-2573-19432 | D4: Rental 24 Hours | E4: Sale | F4: None | G4: 1 | H4: 9791159284953 | I4: 스토리위즈 | J4: 절륜공자 2권 | K4: 전혁 | L4: KRW | M4: 630 | N4: KRW | O4: 630 | P4: 630 | Q4: KR | R4: 0.7 | S4: 441 | T4: KRW | U4: 441 | V4: 스토리위즈 | W4: 전혁
A5: 22. 5. 31. | B5: 22. 5. 16. | C5: ID:3186-5157-6129-97851 | D5: Rental 24 Hours | E5: Sale | F5: None | G5: 1 | H5: 9791159284960 | I5: 스토리위즈 | J5: 절륜공자 3권 | K5: 전혁 | L5: KRW | M5: 630 | N5: KRW | O5: 630 | P5: 630 | Q5: KR | R5: 0.7 | S5: 441 | T5: KRW | U5: 441 | V5: 스토리위즈 | W5: 전혁
A6: 22. 5. 31. | B6: 22. 5. 16. | C6: ID:3155-1878-0053-55215 | D6: Rental 24 Hours | E6: Sale | F6: None | G6: 1 | H6: 9791159284977 | I6: 스토리위즈 | J6: 절륜공자 4권 | K6: 전혁 | L6: KRW | M6: 630 | N6: KRW | O6: 630 | P6: 630 | Q6: KR | R6: 0.7 | S6: 441 | T6: KRW | U6: 441 | V6: 스토리위즈 | W6: 전혁
A7: 22. 5. 31. | B7: 22. 5. 17. | C7: ID:3144-0785-3599-30120 | D7: Rental 24 Hours | E7: Sale | F7: None | G7: 1 | H7: 9791159284984 | I7: 스토리위즈 | J7: 절륜공자 5권 | K7: 전혁 | L7: KRW | M7: 630 | N7: KRW | O7: 630 | P7: 630 | Q7: KR | R7: 0.7 | S7: 441 | T7: KRW | U7: 441 | V7: 스토리위즈 | W7: 전혁
A8: 22. 5. 31. | B8: 22. 5. 17. | C8: ID:3106-1076-6673-31990 | D8: Rental 24 Hours | E8: Sale | F8: None | G8: 1 | H8: 9791159284991 | I8: 스토리위즈 | J8: 절륜공자 6권 | K8: 전혁 | L8: KRW | M8: 630 | N8: KRW | O8: 630 | P8: 630 | Q8: KR | R8: 0.7 | S8: 441 | T8: KRW | U8: 441 | V8: 스토리위즈 | W8: 전혁
A9: 22. 5. 31. | B9: 22. 5. 18. | C9: ID:3150-5880-2992-78875 | D9: Rental 24 Hours | E9: Sale | F9: None | G9: 1 | H9: 9791159285004 | I9: 스토리위즈 | J9: 절륜공자 7권 | K9: 전혁 | L9: KRW | M9: 630 | N9: KRW | O9: 630 | P9: 630 | Q9: KR | R9: 0.7 | S9: 441 | T9: KRW | U9: 441 | V9: 스토리위즈 | W9: 전혁
A10: 22. 5. 31. | B10: 22. 5. 18. | C10: ID:3115-7455-2043-61743 | D10: Rental 24 Hours | E10: Sale | F10: None | G10: 1 | H10: 9791159285011 | I10: 스토리위즈 | J10: 절륜공자 8권 | K10: 전혁 | L10: KRW | M10: 630 | N10: KRW | O10: 630 | P10: 630 | Q10: KR | R10: 0.7 | S10: 441 | T10: KRW | U10: 441 | V10: 스토리위즈 | W10: 전혁
A11: 22. 5. 31. | B11: 22. 5. 22. | C11: ID:3112-1448-4061-48317 | D11: Rental 24 Hours | E11: Sale | F11: None | G11: 1 | H11: 9791159284953 | I11: 스토리위즈 | J11: 절륜공자 2권 | K11: 전혁 | L11: KRW | M11: 630 | N11: KRW | O11: 630 | P11: 630 | Q11: KR | R11: 0.7 | S11: 441 | T11: KRW | U11: 441 | V11: 스토리위즈 | W11: 전혁
A12: 22. 5. 31. | B12: 22. 5. 23. | C12: ID:3102-4150-4204-29967 | D12: Rental 24 Hours | E12: Sale | F12: None | G12: 1 | H12: 9791159284960 | I12: 스토리위즈 | J12: 절륜공자 3권 | K12: 전혁 | L12: KRW | M12: 630 | N12: KRW | O12: 630 | P12: 630 | Q12: KR | R12: 0.7 | S12: 441 | T12: KRW | U12: 441 | V12: 스토리위즈 | W12: 전혁
A13: 22. 5. 31. | B13: 22. 5. 23. | C13: ID:3179-7441-9877-97964 | D13: Rental 24 Hours | E13: Sale | F13: None | G13: 1 | H13: 9791159284977 | I13: 스토리위즈 | J13: 절륜공자 4권 | K13: 전혁 | L13: KRW | M13: 630 | N13: KRW | O13: 630 | P13: 630 | Q13: KR | R13: 0.7 | S13: 441 | T13: KRW | U13: 441 | V13: 스토리위즈 | W13: 전혁
... A38: 22. 5. 31. | B38: 22. 5. 31. | C38: ID:3177-0448-6351-22984 | D38: Rental 24 Hours | E38: Sale | F38: None | G38: 1 | H38: 9791159284960 | I38: 스토리위즈 | J38: 절륜공자 3권 | K38: 전혁 | L38: KRW | M38: 630 | N38: KRW | O38: 630 | P38: 630 | Q38: KR | R38: 0.7 | S38: 441 | T38: KRW | U38: 441 | V38: 스토리위즈 | W38: 전혁

Sheet 더컴퍼니
A1: Earnings Date | B1: Transaction Date | C1: Id | D1: Product | E1: Type | F1: Preorder | G1: Qty | H1: Primary ISBN | I1: Imprint Name | J1: Title | K1: Author | L1: Original List Price Currency | M1: Original List Price | N1: List Price Currency | O1: List Price [tax inclusive] | P1: List Price [tax exclusive] | Q1: Country of Sale | R1: Publisher Revenue % | S1: Publisher Revenue | T1: Earnings Currency | U1: Earnings Amount | V1: 출판사 | W1: 작가 CP
A2: 22. 5. 31. | B2: 22. 5. 4. | C2: ID:3144-1583-6466-34086 | D2: Single Purchase | E2: Sale | F2: None | G2: 1 | H2: 9791166483233 | I2: Storywiz Co., Ltd. | J2: 집착의 맛 1권 | K2: sJessi | L2: KRW | M2: 3000 | N2: KRW | O2: 3000 | P2: 3000 | Q2: KR | R2: 0.7 | S2: 2100 | T2: KRW | U2: 2100 | V2: 더컴퍼니 | W2: 더컴퍼니
A3: 22. 5. 31. | B3: 22. 5. 4. | C3: ID:3189-4375-5705-59781 | D3: Single Purchase | E3: Sale | F3: None | G3: 1 | H3: 9791166483240 | I3: Storywiz Co., Ltd. | J3: 집착의 맛 2권 | K3: sJessi | L3: KRW | M3: 3000 | N3: KRW | O3: 3000 | P3: 3000 | Q3: KR | R3: 0.7 | S3: 2100 | T3: KRW | U3: 2100 | V3: 더컴퍼니 | W3: 더컴퍼니
A4: 22. 5. 31. | B4: 22. 5. 4. | C4: ID:3154-7941-0452-42687 | D4: Single Purchase | E4: Sale | F4: None | G4: 1 | H4: 9791166483257 | I4: Storywiz Co., Ltd. | J4: 집착의 맛 외전 (완결) | K4: sJessi | L4: KRW | M4: 300 | N4: KRW | O4: 300 | P4: 300 | Q4: KR | R4: 0.7 | S4: 210 | T4: KRW | U4: 210 | V4: 더컴퍼니 | W4: 더컴퍼니
A5: 22. 5. 31. | B5: 22. 5. 9. | C5: ID:3189-9000-2662-09178 | D5: Single Purchase | E5: Sale | F5: None | G5: 1 | H5: 9791166481871 | I5: 블러쉬 | J5: [BL] 택스 프리(TAX FREE) 1권 | K5: SISSI | L5: KRW | M5: 2800 | N5: KRW | O5: 2800 | P5: 2800 | Q5: KR | R5: 0.7 | S5: 1960 | T5: KRW | U5: 1960 | V5: 더컴퍼니 | W5: 더컴퍼니
A6: 22. 5. 31. | B6: 22. 5. 9. | C6: ID:3189-9000-2662-09178 | D6: Single Purchase | E6: Sale | F6: None | G6: 1 | H6: 9791166481888 | I6: 블러쉬 | J6: [BL] 택스 프리(TAX FREE) 2권 (완결) | K6: SISSI | L6: KRW | M6: 2800 | N6: KRW | O6: 2800 | P6: 2800 | Q6: KR | R6: 0.7 | S6: 1960 | T6: KRW | U6: 1960 | V6: 더컴퍼니 | W6: 더컴퍼니

Sheet 셔틀
A1: Earnings Date | B1: Transaction Date | C1: Id | D1: Product | E1: Type | F1: Preorder | G1: Qty | H1: Primary ISBN | I1: Imprint Name | J1: Title | K1: Author | L1: Original List Price Currency | M1: Original List Price | N1: List Price Currency | O1: List Price [tax inclusive] | P1: List Price [tax exclusive] | Q1: Country of Sale | R1: Publisher Revenue % | S1: Publisher Revenue | T1: Earnings Currency | U1: Earnings Amount | V1: 출판사 | W1: 작가 CP
A2: 22. 5. 31. | B2: 22. 5. 4. | C2: ID:3179-7694-7236-04380 | D2: Single Purchase | E2: Sale | F2: None | G2: 1 | H2: 9791189084813 | I2: Storywiz Co., Ltd. | J2: 그땐 미처(외전증보판) | K2: 셔틀 | L2: KRW | M2: 4000 | N2: KRW | O2: 4000 | P2: 4000 | Q2: KR | R2: 0.7 | S2: 2800 | T2: KRW | U2: 2800 | V2: 스토리위즈 | W2: 셔틀
A3: 22. 5. 31. | B3: 22. 5. 7. | C3: ID:3161-3147-1127-15621 | D3: Single Purchase | E3: Sale | F3: None | G3: 1 | H3: 9791189084813 | I3: Storywiz Co., Ltd. | J3: 그땐 미처(외전증보판) | K3: 셔틀 | L3: KRW | M3: 4000 | N3: KRW | O3: 4000 | P3: 4000 | Q3: KR | R3: 0.7 | S3: 2800 | T3: KRW | U3: 2800 | V3: 스토리위즈 | W3: 셔틀
A4: 22. 5. 31. | B4: 22. 5. 8. | C4: ID:3154-6605-3034-66443 | D4: Single Purchase | E4: Sale | F4: None | G4: 1 | H4: 9791189084813 | I4: Storywiz Co., Ltd. | J4: 그땐 미처(외전증보판) | K4: 셔틀 | L4: KRW | M4: 4000 | N4: KRW | O4: 4000 | P4: 4000 | Q4: KR | R4: 0.7 | S4: 2800 | T4: KRW | U4: 2800 | V4: 스토리위즈 | W4: 셔틀
A5: 22. 5. 31. | B5: 22. 5. 9. | C5: ID:3149-9510-1412-55672 | D5: Single Purchase | E5: Sale | F5: None | G5: 1 | H5: 9791189084813 | I5: Storywiz Co., Ltd. | J5: 그땐 미처(외전증보판) | K5: 셔틀 | L5: KRW | M5: 4000 | N5: KRW | O5: 4000 | P5: 4000 | Q5: KR | R5: 0.7 | S5: 2800 | T5: KRW | U5: 2800 | V5: 스토리위즈 | W5: 셔틀
A6: 22. 5. 31. | B6: 22. 5. 12. | C6: ID:3124-9181-7498-41229 | D6: Single Purchase | E6: Sale | F6: None | G6: 1 | H6: 9791189084813 | I6: Storywiz Co., Ltd. | J6: 그땐 미처(외전증보판) | K6: 셔틀 | L6: KRW | M6: 4000 | N6: KRW | O6: 4000 | P6: 4000 | Q6: KR | R6: 0.7 | S6: 2800 | T6: KRW | U6: 2800 | V6: 스토리위즈 | W6: 셔틀
A7: 22. 5. 31. | B7: 22. 5. 12. | C7: ID:3193-9938-5069-80911 | D7: Single Purchase | E7: Sale | F7: None | G7: 1 | H7: 9791189084813 | I7: Storywiz Co., Ltd. | J7: 그땐 미처(외전증보판) | K7: 셔틀 | L7: KRW | M7: 4000 | N7: KRW | O7: 4000 | P7: 4000 | Q7: KR | R7: 0.7 | S7: 2800 | T7: KRW | U7: 2800 | V7: 스토리위즈 | W7: 셔틀
A8: 22. 5. 31. | B8: 22. 5. 13. | C8: ID:3100-4328-5688-29392 | D8: Single Purchase | E8: Sale | F8: None | G8: 1 | H8: 9791189084813 | I8: Storywiz Co., Ltd. | J8: 그땐 미처(외전증보판) | K8: 셔틀 | L8: KRW | M8: 4000 | N8: KRW | O8: 4000 | P8: 4000 | Q8: KR | R8: 0.7 | S8: 2800 | T8: KRW | U8: 2800 | V8: 스토리위즈 | W8: 셔틀
A9: 22. 5. 31. | B9: 22. 5. 13. | C9: ID:3143-8381-9795-23875 | D9: Single Purchase | E9: Sale | F9: None | G9: 1 | H9: 9791189084813 | I9: Storywiz Co., Ltd. | J9: 그땐 미처(외전증보판) | K9: 셔틀 | L9: KRW | M9: 4000 | N9: KRW | O9: 4000 | P9: 4000 | Q9: KR | R9: 0.7 | S9: 2800 | T9: KRW | U9: 2800 | V9: 스토리위즈 | W9: 셔틀
A10: 22. 5. 31. | B10: 22. 5. 14. | C10: ID:3123-6058-4222-62185 | D10: Single Purchase | E10: Sale | F10: None | G10: 1 | H10: 9791189084813 | I10: Storywiz Co., Ltd. | J10: 그땐 미처(외전증보판) | K10: 셔틀 | L10: KRW | M10: 4000 | N10: KRW | O10: 4000 | P10: 4000 | Q10: KR | R10: 0.7 | S10: 2800 | T10: KRW | U10: 2800 | V10: 스토리위즈 | W10: 셔틀
A11: 22. 5. 31. | B11: 22. 5. 14. | C11: ID:3163-0147-5977-15571 | D11: Single Purchase | E11: Sale | F11: None | G11: 1 | H11: 9791189084813 | I11: Storywiz Co., Ltd. | J11: 그땐 미처(외전증보판) | K11: 셔틀 | L11: KRW | M11: 4000 | N11: AUD | O11: 4.81 | P11: 4.37 | Q11: AU | R11: 0.7 | S11: 3.06 | T11: KRW | U11: 2726 | V11: 스토리위즈 | W11: 셔틀
A12: 22. 5. 31. | B12: 22. 5. 16. | C12: ID:3173-8629-2667-59138 | D12: Single Purchase | E12: Sale | F12: None | G12: 1 | H12: 9791189084813 | I12: Storywiz Co., Ltd. | J12: 그땐 미처(외전증보판) | K12: 셔틀 | L12: KRW | M12: 4000 | N12: KRW | O12: 4000 | P12: 4000 | Q12: KR | R12: 0.7 | S12: 2800 | T12: KRW | U12: 2800 | V12: 스토리위즈 | W12: 셔틀
A13: 22. 5. 31. | B13: 22. 5. 17. | C13: ID:3127-0397-2854-01888 | D13: Single Purchase | E13: Sale | F13: None | G13: 1 | H13: 9791189084813 | I13: Storywiz Co., Ltd. | J13: 그땐 미처(외전증보판) | K13: 셔틀 | L13: KRW | M13: 4000 | N13: KRW | O13: 4000 | P13: 4000 | Q13: KR | R13: 0.7 | S13: 2800 | T13: KRW | U13: 2800 | V13: 스토리위즈 | W13: 셔틀
... A55: 22. 5. 31. | B55: 22. 5. 31. | C55: ID:3149-0557-1350-08700 | D55: Single Purchase | E55: Sale | F55: None | G55: 1 | H55: 9791164372188 | I55: Storywiz Co., Ltd. | J55: 욕망에 눈뜨다 외전 | K55: 셔틀 | L55: KRW | M55: 300 | N55: KRW | O55: 300 | P55: 300 | Q55: KR | R55: 0.7 | S55: 210 | T55: KRW | U55: 210 | V55: 스토리위즈 | W55: 셔틀

Sheet 이동열
A1: Earnings Date | B1: Transaction Date | C1: Id | D1: Product | E1: Type | F1: Preorder | G1: Qty | H1: Primary ISBN | I1: Imprint Name | J1: Title | K1: Author | L1: Original List Price Currency | M1: Original List Price | N1: List Price Currency | O1: List Price [tax inclusive] | P1: List Price [tax exclusive] | Q1: Country of Sale | R1: Publisher Revenue % | S1: Publisher Revenue | T1: Earnings Currency | U1: Earnings Amount | V1: 출판사 | W1: 작가 CP
A2: 22. 5. 31. | B2: 22. 5. 6. | C2: ID:3108-8755-1430-40870 | D2: Single Purchase | E2: Sale | F2: None | G2: 1 | H2: 9791159289583 | I2: 스토리위즈 | J2: 나 혼자만 일일 보상 2권 | K2: 이동열 | L2: KRW | M2: 3200 | N2: USD | O2: 2.64 | P2: 2.64 | Q2: US | R2: 0.7 | S2: 1.85 | T2: KRW | U2: 2354 | V2: 스토리위즈 | W2: 이동열
A3: 22. 5. 31. | B3: 22. 5. 7. | C3: ID:3113-9240-4074-24596 | D3: Single Purchase | E3: Sale | F3: None | G3: 1 | H3: 9791159289590 | I3: 스토리위즈 | J3: 나 혼자만 일일 보상 3권 | K3: 이동열 | L3: KRW | M3: 3200 | N3: USD | O3: 2.64 | P3: 2.64 | Q3: US | R3: 0.7 | S3: 1.85 | T3: KRW | U3: 2354 | V3: 스토리위즈 | W3: 이동열
A4: 22. 5. 31. | B4: 22. 5. 7. | C4: ID:3160-2762-8461-66452 | D4: Single Purchase | E4: Sale | F4: None | G4: 1 | H4: 9791159289606 | I4: 스토리위즈 | J4: 나 혼자만 일일 보상 4권 | K4: 이동열 | L4: KRW | M4: 3200 | N4: USD | O4: 2.64 | P4: 2.64 | Q4: US | R4: 0.7 | S4: 1.85 | T4: KRW | U4: 2354 | V4: 스토리위즈 | W4: 이동열
A5: 22. 5. 31. | B5: 22. 5. 9. | C5: ID:3129-0914-0122-05869 | D5: Single Purchase | E5: Sale | F5: None | G5: 1 | H5: 9791159289583 | I5: 스토리위즈 | J5: 나 혼자만 일일 보상 2권 | K5: 이동열 | L5: KRW | M5: 3200 | N5: KRW | O5: 3200 | P5: 3200 | Q5: KR | R5: 0.7 | S5: 2240 | T5: KRW | U5: 2240 | V5: 스토리위즈 | W5: 이동열
A6: 22. 5. 31. | B6: 22. 5. 9. | C6: ID:3182-3284-5879-59382 | D6: Single Purchase | E6: Sale | F6: None | G6: 1 | H6: 9791159289583 | I6: 스토리위즈 | J6: 나 혼자만 일일 보상 2권 | K6: 이동열 | L6: KRW | M6: 3200 | N6: KRW | O6: 3200 | P6: 3200 | Q6: KR | R6: 0.7 | S6: 2240 | T6: KRW | U6: 2240 | V6: 스토리위즈 | W6: 이동열
A7: 22. 5. 31. | B7: 22. 5. 11. | C7: ID:3101-5442-8315-46623 | D7: Single Purchase | E7: Sale | F7: None | G7: 1 | H7: 9791159289583 | I7: 스토리위즈 | J7: 나 혼자만 일일 보상 2권 | K7: 이동열 | L7: KRW | M7: 3200 | N7: KRW | O7: 3200 | P7: 3200 | Q7: KR | R7: 0.7 | S7: 2240 | T7: KRW | U7: 2240 | V7: 스토리위즈 | W7: 이동열
A8: 22. 5. 31. | B8: 22. 5. 12. | C8: ID:3140-3036-6164-25914 | D8: Single Purchase | E8: Sale | F8: None | G8: 1 | H8: 9791159289590 | I8: 스토리위즈 | J8: 나 혼자만 일일 보상 3권 | K8: 이동열 | L8: KRW | M8: 3200 | N8: KRW | O8: 3200 | P8: 3200 | Q8: KR | R8: 0.7 | S8: 2240 | T8: KRW | U8: 2240 | V8: 스토리위즈 | W8: 이동열
A9: 22. 5. 31. | B9: 22. 5. 12. | C9: ID:3174-4995-9092-53593 | D9: Single Purchase | E9: Sale | F9: None | G9: 1 | H9: 9791159289606 | I9: 스토리위즈 | J9: 나 혼자만 일일 보상 4권 | K9: 이동열 | L9: KRW | M9: 3200 | N9: KRW | O9: 3200 | P9: 3200 | Q9: KR | R9: 0.7 | S9: 2240 | T9: KRW | U9: 2240 | V9: 스토리위즈 | W9: 이동열
A10: 22. 5. 31. | B10: 22. 5. 12. | C10: ID:3129-7360-4931-35544 | D10: Single Purchase | E10: Sale | F10: None | G10: 1 | H10: 9791159289613 | I10: 스토리위즈 | J10: 나 혼자만 일일 보상 5권 | K10: 이동열 | L10: KRW | M10: 3200 | N10: KRW | O10: 3200 | P10: 3200 | Q10: KR | R10: 0.7 | S10: 2240 | T10: KRW | U10: 2240 | V10: 스토리위즈 | W10: 이동열
A11: 22. 5. 31. | B11: 22. 5. 12. | C11: ID:3130-0518-4709-73729 | D11: Single Purchase | E11: Sale | F11: None | G11: 1 | H11: 9791159289620 | I11: 스토리위즈 | J11: 나 혼자만 일일 보상 6권 | K11: 이동열 | L11: KRW | M11: 3200 | N11: KRW | O11: 3200 | P11: 3200 | Q11: KR | R11: 0.7 | S11: 2240 | T11: KRW | U11: 2240 | V11: 스토리위즈 | W11: 이동열
A12: 22. 5. 31. | B12: 22. 5. 13. | C12: ID:3191-7350-2685-80731 | D12: Single Purchase | E12: Sale | F12: None | G12: 1 | H12: 9791159289637 | I12: 스토리위즈 | J12: 나 혼자만 일일 보상 7권 | K12: 이동열 | L12: KRW | M12: 3200 | N12: KRW | O12: 3200 | P12: 3200 | Q12: KR | R12: 0.7 | S12: 2240 | T12: KRW | U12: 2240 | V12: 스토리위즈 | W12: 이동열
A13: 22. 5. 31. | B13: 22. 5. 13. | C13: ID:3139-1239-8554-22537 | D13: Single Purchase | E13: Sale | F13: None | G13: 1 | H13: 9791159289644 | I13: 스토리위즈 | J13: 나 혼자만 일일 보상 8권 | K13: 이동열 | L13: KRW | M13: 3200 | N13: KRW | O13: 3200 | P13: 3200 | Q13: KR | R13: 0.7 | S13: 2240 | T13: KRW | U13: 2240 | V13: 스토리위즈 | W13: 이동열
... A35: 22. 5. 31. | B35: 22. 5. 30. | C35: ID:3148-9058-3837-05358 | D35: Single Purchase | E35: Sale | F35: None | G35: 1 | H35: 9791159289583 | I35: 스토리위즈 | J35: 나 혼자만 일일 보상 2권 | K35: 이동열 | L35: KRW | M35: 3200 | N35: AUD | O35: 3.5 | P35: 3.18 | Q35: AU | R35: 0.7 | S35: 2.23 | T35: KRW | U35: 1982 | V35: 스토리위즈 | W35: 이동열

Sheet 온서
A1: Earnings Date | B1: Transaction Date | C1: Id | D1: Product | E1: Type | F1: Preorder | G1: Qty | H1: Primary ISBN | I1: Imprint Name | J1: Title | K1: Author | L1: Original List Price Currency | M1: Original List Price | N1: List Price Currency | O1: List Price [tax inclusive] | P1: List Price [tax exclusive] | Q1: Country of Sale | R1: Publisher Revenue % | S1: Publisher Revenue | T1: Earnings Currency | U1: Earnings Amount | V1: 출판사 | W1: 작가 CP
A2: 22. 5. 31. | B2: 22. 5. 7. | C2: ID:3190-9709-2676-73129 | D2: Single Purchase | E2: Sale | F2: None | G2: 1 | H2: 9791137600430 | I2: Storywiz Co., Ltd. | J2: 임신부터 할까요 2권(완결) | K2: 온서 | L2: KRW | M2: 2400 | N2: KRW | O2: 2400 | P2: 2400 | Q2: KR | R2: 0.7 | S2: 1680 | T2: KRW | U2: 1680 | V2: 스토리위즈 | W2: 온서
A3: 22. 5. 31. | B3: 22. 5. 14. | C3: ID:3148-9855-4363-50992 | D3: Single Purchase | E3: Sale | F3: None | G3: 1 | H3: 9791137600423 | I3: Storywiz Co., Ltd. | J3: 임신부터 할까요? 1권 | K3: 온서 | L3: KRW | M3: 2400 | N3: KRW | O3: 2400 | P3: 2400 | Q3: KR | R3: 0.7 | S3: 1680 | T3: KRW | U3: 1680 | V3: 스토리위즈 | W3: 온서
A4: 22. 5. 31. | B4: 22. 5. 14. | C4: ID:3127-0110-3983-65067 | D4: Single Purchase | E4: Sale | F4: None | G4: 1 | H4: 9791137600430 | I4: Storywiz Co., Ltd. | J4: 임신부터 할까요 2권(완결) | K4: 온서 | L4: KRW | M4: 2400 | N4: KRW | O4: 2400 | P4: 2400 | Q4: KR | R4: 0.7 | S4: 1680 | T4: KRW | U4: 1680 | V4: 스토리위즈 | W4: 온서

Sheet 스내치
A1: Earnings Date | B1: Transaction Date | C1: Id | D1: Product | E1: Type | F1: Preorder | G1: Qty | H1: Primary ISBN | I1: Imprint Name | J1: Title | K1: Author | L1: Original List Price Currency | M1: Original List Price | N1: List Price Currency | O1: List Price [tax inclusive] | P1: List Price [tax exclusive] | Q1: Country of Sale | R1: Publisher Revenue % | S1: Publisher Revenue | T1: Earnings Currency | U1: Earnings Amount | V1: 출판사 | W1: 작가 CP
A2: 22. 5. 31. | B2: 22. 5. 9. | C2: ID:3124-0569-0894-21851 | D2: Single Purchase | E2: Sale | F2: None | G2: 1 | H2: 9791189084257 | I2: Storywiz Co., Ltd. | J2: 나만의 스타(외전증보판) | K2: 스내치 | L2: KRW | M2: 3600 | N2: KRW | O2: 3600 | P2: 3600 | Q2: KR | R2: 0.7 | S2: 2520 | T2: KRW | U2: 2520 | V2: 스토리위즈 | W2: 스내치
A3: 22. 5. 31. | B3: 22. 5. 12. | C3: ID:3199-0113-8057-89601 | D3: Single Purchase | E3: Sale | F3: None | G3: 1 | H3: 9791189084257 | I3: Storywiz Co., Ltd. | J3: 나만의 스타(외전증보판) | K3: 스내치 | L3: KRW | M3: 3600 | N3: KRW | O3: 3600 | P3: 3600 | Q3: KR | R3: 0.7 | S3: 2520 | T3: KRW | U3: 2520 | V3: 스토리위즈 | W3: 스내치
A4: 22. 5. 31. | B4: 22. 5. 12. | C4: ID:3183-0541-2568-81109 | D4: Single Purchase | E4: Sale | F4: None | G4: 1 | H4: 9791189084578 | I4: Storywiz Co., Ltd. | J4: 주님 (외전증보판) | K4: 스내치 | L4: KRW | M4: 3800 | N4: KRW | O4: 3800 | P4: 3800 | Q4: KR | R4: 0.7 | S4: 2660 | T4: KRW | U4: 2660 | V4: 스토리위즈 | W4: 스내치
A5: 22. 5. 31. | B5: 22. 5. 12. | C5: ID:3129-2264-1499-62278 | D5: Single Purchase | E5: Sale | F5: None | G5: 1 | H5: 9791189084004 | I5: Storywiz Co., Ltd. | J5: 황설 (외전증보판) | K5: 스내치 | L5: KRW | M5: 3600 | N5: KRW | O5: 3600 | P5: 3600 | Q5: KR | R5: 0.7 | S5: 2520 | T5: KRW | U5: 2520 | V5: 스토리위즈 | W5: 스내치
A6: 22. 5. 31. | B6: 22. 5. 19. | C6: ID:3164-0490-8220-31648 | D6: Single Purchase | E6: Sale | F6: None | G6: 1 | H6: 9791189084004 | I6: Storywiz Co., Ltd. | J6: 황설 (외전증보판) | K6: 스내치 | L6: KRW | M6: 3600 | N6: KRW | O6: 3600 | P6: 3600 | Q6: KR | R6: 0.7 | S6: 2520 | T6: KRW | U6: 2520 | V6: 스토리위즈 | W6: 스내치

Sheet 라비니안느
A1: Earnings Date | B1: Transaction Date | C1: Id | D1: Product | E1: Type | F1: Preorder | G1: Qty | H1: Primary ISBN | I1: Imprint Name | J1: Title | K1: Author | L1: Original List Price Currency | M1: Original List Price | N1: List Price Currency | O1: List Price [tax inclusive] | P1: List Price [tax exclusive] | Q1: Country of Sale | R1: Publisher Revenue % | S1: Publisher Revenue | T1: Earnings Currency | U1: Earnings Amount | V1: 출판사 | W1: 작가 CP
A2: 22. 5. 31. | B2: 22. 5. 10. | C2: ID:3166-5057-2518-82395 | D2: Single Purchase | E2: Sale | F2: None | G2: 1 | H2: 9791189627324 | I2: Storywiz Co., Ltd. | J2: [BL] 욕망하다 1권 | K2: 라비니안느 | L2: KRW | M2: 3100 | N2: AUD | O2: 3.73 | P2: 3.39 | Q2: AU | R2: 0.7 | S2: 2.37 | T2: KRW | U2: 2099 | V2: 스토리위즈 | W2: 라비니안느
A3: 22. 5. 31. | B3: 22. 5. 10. | C3: ID:3148-0360-0616-86604 | D3: Single Purchase | E3: Sale | F3: None | G3: 1 | H3: 9791189627331 | I3: Storywiz Co., Ltd. | J3: [BL] 욕망하다 2권 | K3: 라비니안느 | L3: KRW | M3: 3300 | N3: AUD | O3: 3.97 | P3: 3.61 | Q3: AU | R3: 0.7 | S3: 2.53 | T3: KRW | U3: 2241 | V3: 스토리위즈 | W3: 라비니안느

Sheet 모리미
A1: Earnings Date | B1: Transaction Date | C1: Id | D1: Product | E1: Type | F1: Preorder | G1: Qty | H1: Primary ISBN | I1: Imprint Name | J1: Title | K1: Author | L1: Original List Price Currency | M1: Original List Price | N1: List Price Currency | O1: List Price [tax inclusive] | P1: List Price [tax exclusive] | Q1: Country of Sale | R1: Publisher Revenue % | S1: Publisher Revenue | T1: Earnings Currency | U1: Earnings Amount | V1: 출판사 | W1: 작가 CP
A2: 22. 5. 31. | B2: 22. 5. 10. | C2: ID:3135-6931-8160-30746 | D2: Single Purchase | E2: Sale | F2: None | G2: 1 | H2: 9791189627072 | I2: Storywiz Co., Ltd. | J2: [BL] 이 비서 다리 좀 치워 1권 | K2: 모리미 | L2: KRW | M2: 2200 | N2: KRW | O2: 2200 | P2: 2200 | Q2: KR | R2: 0.7 | S2: 1540 | T2: KRW | U2: 1540 | V2: 스토리위즈 | W2: 모리미
A3: 22. 5. 31. | B3: 22. 5. 11. | C3: ID:3129-5009-6738-58790 | D3: Single Purchase | E3: Sale | F3: None | G3: 1 | H3: 9791189627089 | I3: Storywiz Co., Ltd. | J3: [BL] 이 비서 다리 좀 치워 2권 | K3: 모리미 | L3: KRW | M3: 2200 | N3: KRW | O3: 2200 | P3: 2200 | Q3: KR | R3: 0.7 | S3: 1540 | T3: KRW | U3: 1540 | V3: 스토리위즈 | W3: 모리미
A4: 22. 5. 31. | B4: 22. 5. 17. | C4: ID:3166-2034-3988-37704 | D4: Single Purchase | E4: Sale | F4: None | G4: 1 | H4: 9791189627843 | I4: Storywiz Co., Ltd. | J4: [BL] 야쿠자가 사랑을 한다면 (개정판) 2권 | K4: 모리미 | L4: KRW | M4: 3200 | N4: KRW | O4: 3200 | P4: 3200 | Q4: KR | R4: 0.7 | S4: 2240 | T4: KRW | U4: 2240 | V4: 스토리위즈 | W4: 모리미
A5: 22. 5. 31. | B5: 22. 5. 18. | C5: ID:3100-5947-4482-81529 | D5: Single Purchase | E5: Sale | F5: None | G5: 1 | H5: 9791164370085 | I5: Storywiz Co., Ltd. | J5: [BL] 야쿠자가 사랑을 한다면 (개정판) 외전 | K5: 모리미 | L5: KRW | M5: 400 | N5: USD | O5: 0.33 | P5: 0.33 | Q5: US | R5: 0.7 | S5: 0.23 | T5: KRW | U5: 291 | V5: 스토리위즈 | W5: 모리미
A6: 22. 5. 31. | B6: 22. 5. 21. | C6: ID:3170-5855-9249-62265 | D6: Single Purchase | E6: Sale | F6: None | G6: 1 | H6: 9791189627072 | I6: Storywiz Co., Ltd. | J6: [BL] 이 비서 다리 좀 치워 1권 | K6: 모리미 | L6: KRW | M6: 2200 | N6: KRW | O6: 2200 | P6: 2200 | Q6: KR | R6: 0.7 | S6: 1540 | T6: KRW | U6: 1540 | V6: 스토리위즈 | W6: 모리미
A7: 22. 5. 31. | B7: 22. 5. 21. | C7: ID:3103-1954-7253-12785 | D7: Single Purchase | E7: Sale | F7: None | G7: 1 | H7: 9791189627874 | I7: Storywiz Co., Ltd. | J7: [BL] 정혼자 1권 | K7: 모리미 | L7: KRW | M7: 2800 | N7: KRW | O7: 2800 | P7: 2800 | Q7: KR | R7: 0.7 | S7: 1960 | T7: KRW | U7: 1960 | V7: 스토리위즈 | W7: 모리미
A8: 22. 5. 31. | B8: 22. 5. 22. | C8: ID:3177-0075-5065-70072 | D8: Single Purchase | E8: Sale | F8: None | G8: 1 | H8: 9791189627072 | I8: Storywiz Co., Ltd. | J8: [BL] 이 비서 다리 좀 치워 1권 | K8: 모리미 | L8: KRW | M8: 2200 | N8: KRW | O8: 2200 | P8: 2200 | Q8: KR | R8: 0.7 | S8: 1540 | T8: KRW | U8: 1540 | V8: 스토리위즈 | W8: 모리미
A9: 22. 5. 31. | B9: 22. 5. 22. | C9: ID:3169-8773-8356-94821 | D9: Single Purchase | E9: Sale | F9: None | G9: 1 | H9: 9791189627089 | I9: Storywiz Co., Ltd. | J9: [BL] 이 비서 다리 좀 치워 2권 | K9: 모리미 | L9: KRW | M9: 2200 | N9: KRW | O9: 2200 | P9: 2200 | Q9: KR | R9: 0.7 | S9: 1540 | T9: KRW | U9: 1540 | V9: 스토리위즈 | W9: 모리미
A10: 22. 5. 31. | B10: 22. 5. 23. | C10: ID:3171-5876-4095-15621 | D10: Single Purchase | E10: Sale | F10: None | G10: 1 | H10: 9791189627881 | I10: Storywiz Co., Ltd. | J10: [BL] 정혼자 2권 | K10: 모리미 | L10: KRW | M10: 2800 | N10: KRW | O10: 2800 | P10: 2800 | Q10: KR | R10: 0.7 | S10: 1960 | T10: KRW | U10: 1960 | V10: 스토리위즈 | W10: 모리미
A11: 22. 5. 31. | B11: 22. 5. 24. | C11: ID:3168-9354-2824-49415 | D11: Single Purchase | E11: Sale | F11: None | G11: 1 | H11: 9791189627379 | I11: Storywiz Co., Ltd. | J11: [BL] 이 비서 다리 좀 치워 외전 | K11: 모리미 | L11: KRW | M11: 300 | N11: USD | O11: 0.25 | P11: 0.25 | Q11: PA | R11: 0.7 | S11: 0.17 | T11: KRW | U11: 215 | V11: 스토리위즈 | W11: 모리미
A12: 22. 5. 31. | B12: 22. 5. 24. | C12: ID:3156-4302-2498-90551 | D12: Single Purchase | E12: Sale | F12: None | G12: 1 | H12: 9791164370504 | I12: Storywiz Co., Ltd. | J12: [BL] Only you 외전 | K12: 모리미 | L12: KRW | M12: 300 | N12: USD | O12: 0.25 | P12: 0.25 | Q12: PA | R12: 0.7 | S12: 0.17 | T12: KRW | U12: 215 | V12: 스토리위즈 | W12: 모리미
A13: 22. 5. 31. | B13: 22. 5. 24. | C13: ID:3133-4477-8282-33097 | D13: Single Purchase | E13: Sale | F13: None | G13: 1 | H13: 9791164370177 | I13: Storywiz Co., Ltd. | J13: [BL] Only you 1권 | K13: 모리미 | L13: KRW | M13: 2500 | N13: KRW | O13: 2500 | P13: 2500 | Q13: KR | R13: 0.7 | S13: 1750 | T13: KRW | U13: 1750 | V13: 스토리위즈 | W13: 모리미
... A45: 22. 5. 31. | B45: 22. 5. 31. | C45: ID:3162-7236-1519-99535 | D45: Single Purchase | E45: Sale | F45: None | G45: 1 | H45: 9791164370498 | I45: Storywiz Co., Ltd. | J45: [BL] 골 때리는 사랑 2권 | K45: 모리미 | L45: KRW | M45: 2800 | N45: KRW | O45: 2800 | P45: 2800 | Q45: KR | R45: 0.7 | S45: 1960 | T45: KRW | U45: 1960 | V45: 스토리위즈 | W45: 모리미

Sheet 진문
A1: Earnings Date | B1: Transaction Date | C1: Id | D1: Product | E1: Type | F1: Preorder | G1: Qty | H1: Primary ISBN | I1: Imprint Name | J1: Title | K1: Author | L1: Original List Price Currency | M1: Original List Price | N1: List Price Currency | O1: List Price [tax inclusive] | P1: List Price [tax exclusive] | Q1: Country of Sale | R1: Publisher Revenue % | S1: Publisher Revenue | T1: Earnings Currency | U1: Earnings Amount | V1: 출판사 | W1: 작가 CP
A2: 22. 5. 31. | B2: 22. 5. 11. | C2: ID:3126-2282-7325-97337 | D2: Rental 24 Hours | E2: Sale | F2: None | G2: 1 | H2: 9791190937320 | I2: 스토리위즈 | J2: 드래곤은 나 혼자 잡는다 2권 | K2: 진문 | L2: KRW | M2: 630 | N2: KRW | O2: 630 | P2: 630 | Q2: KR | R2: 0.7 | S2: 441 | T2: KRW | U2: 441 | V2: 스토리위즈 | W2: 진문
A3: 22. 5. 31. | B3: 22. 5. 12. | C3: ID:3114-2293-9874-75530 | D3: Rental 24 Hours | E3: Sale | F3: None | G3: 1 | H3: 9791190937320 | I3: 스토리위즈 | J3: 드래곤은 나 혼자 잡는다 2권 | K3: 진문 | L3: KRW | M3: 630 | N3: KRW | O3: 630 | P3: 630 | Q3: KR | R3: 0.7 | S3: 441 | T3: KRW | U3: 441 | V3: 스토리위즈 | W3: 진문
A4: 22. 5. 31. | B4: 22. 5. 13. | C4: ID:3193-7572-8518-10469 | D4: Single Purchase | E4: Sale | F4: None | G4: 1 | H4: 9791166068065 | I4: Storywiz Co., Ltd. | J4: 리얼 머니 2권 | K4: 진문 | L4: KRW | M4: 3200 | N4: KRW | O4: 3200 | P4: 3200 | Q4: KR | R4: 0.7 | S4: 2240 | T4: KRW | U4: 2240 | V4: 스토리위즈 | W4: 진문
A5: 22. 5. 31. | B5: 22. 5. 13. | C5: ID:3128-8809-9649-85964 | D5: Single Purchase | E5: Sale | F5: None | G5: 1 | H5: 9791166068102 | I5: Storywiz Co., Ltd. | J5: 리얼 머니 3권 | K5: 진문 | L5: KRW | M5: 3200 | N5: KRW | O5: 3200 | P5: 3200 | Q5: KR | R5: 0.7 | S5: 2240 | T5: KRW | U5: 2240 | V5: 스토리위즈 | W5: 진문
A6: 22. 5. 31. | B6: 22. 5. 13. | C6: ID:3119-7952-4579-91542 | D6: Rental 24 Hours | E6: Sale | F6: None | G6: 1 | H6: 9791190937337 | I6: 스토리위즈 | J6: 드래곤은 나 혼자 잡는다 3권 | K6: 진문 | L6: KRW | M6: 630 | N6: KRW | O6: 630 | P6: 630 | Q6: KR | R6: 0.7 | S6: 441 | T6: KRW | U6: 441 | V6: 스토리위즈 | W6: 진문
A7: 22. 5. 31. | B7: 22. 5. 13. | C7: ID:3124-8297-4568-64426 | D7: Rental 24 Hours | E7: Sale | F7: None | G7: 1 | H7: 9791190937344 | I7: 스토리위즈 | J7: 드래곤은 나 혼자 잡는다 4권 | K7: 진문 | L7: KRW | M7: 630 | N7: KRW | O7: 630 | P7: 630 | Q7: KR | R7: 0.7 | S7: 441 | T7: KRW | U7: 441 | V7: 스토리위즈 | W7: 진문
A8: 22. 5. 31. | B8: 22. 5. 28. | C8: ID:3130-1988-2933-07265 | D8: Rental 24 Hours | E8: Sale | F8: None | G8: 1 | H8: 9791190937320 | I8: 스토리위즈 | J8: 드래곤은 나 혼자 잡는다 2권 | K8: 진문 | L8: KRW | M8: 630 | N8: KRW | O8: 630 | P8: 630 | Q8: KR | R8: 0.7 | S8: 441 | T8: KRW | U8: 441 | V8: 스토리위즈 | W8: 진문

Sheet 차홍주
A1: Earnings Date | B1: Transaction Date | C1: Id | D1: Product | E1: Type | F1: Preorder | G1: Qty | H1: Primary ISBN | I1: Imprint Name | J1: Title | K1: Author | L1: Original List Price Currency | M1: Original List Price | N1: List Price Currency | O1: List Price [tax inclusive] | P1: List Price [tax exclusive] | Q1: Country of Sale | R1: Publisher Revenue % | S1: Publisher Revenue | T1: Earnings Currency | U1: Earnings Amount | V1: 출판사 | W1: 작가 CP
A2: 22. 5. 31. | B2: 22. 5. 11. | C2: ID:3119-8224-3167-53691 | D2: Single Purchase | E2: Sale | F2: None | G2: 1 | H2: 9791164370689 | I2: Storywiz Co., Ltd. | J2: 사랑을 놓치고 2권 | K2: 차홍주 | L2: KRW | M2: 3000 | N2: KRW | O2: 3000 | P2: 3000 | Q2: KR | R2: 0.7 | S2: 2100 | T2: KRW | U2: 2100 | V2: 스토리위즈 | W2: 차홍주
A3: 22. 5. 31. | B3: 22. 5. 15. | C3: ID:3143-0185-9756-58935 | D3: Single Purchase | E3: Sale | F3: None | G3: 1 | H3: 9791164370689 | I3: Storywiz Co., Ltd. | J3: 사랑을 놓치고 2권 | K3: 차홍주 | L3: KRW | M3: 3000 | N3: KRW | O3: 3000 | P3: 3000 | Q3: KR | R3: 0.7 | S3: 2100 | T3: KRW | U3: 2100 | V3: 스토리위즈 | W3: 차홍주
A4: 22. 5. 31. | B4: 22. 5. 19. | C4: ID:3109-8821-3242-48249 | D4: Single Purchase | E4: Sale | F4: None | G4: 1 | H4: 9791164370986 | I4: Storywiz Co., Ltd. | J4: 사랑을 놓치고 외전 | K4: 차홍주 | L4: KRW | M4: 500 | N4: KRW | O4: 500 | P4: 500 | Q4: KR | R4: 0.7 | S4: 350 | T4: KRW | U4: 350 | V4: 스토리위즈 | W4: 차홍주
A5: 22. 5. 31. | B5: 22. 5. 19. | C5: ID:3179-4293-7698-37143 | D5: Single Purchase | E5: Sale | F5: None | G5: 1 | H5: 9791164370672 | I5: Storywiz Co., Ltd. | J5: 사랑을 놓치고 1권 | K5: 차홍주 | L5: KRW | M5: 3000 | N5: KRW | O5: 3000 | P5: 3000 | Q5: KR | R5: 0.7 | S5: 2100 | T5: KRW | U5: 2100 | V5: 스토리위즈 | W5: 차홍주
A6: 22. 5. 31. | B6: 22. 5. 20. | C6: ID:3173-0106-7604-22430 | D6: Single Purchase | E6: Sale | F6: None | G6: 1 | H6: 9791164370689 | I6: Storywiz Co., Ltd. | J6: 사랑을 놓치고 2권 | K6: 차홍주 | L6: KRW | M6: 3000 | N6: KRW | O6: 3000 | P6: 3000 | Q6: KR | R6: 0.7 | S6: 2100 | T6: KRW | U6: 2100 | V6: 스토리위즈 | W6: 차홍주
A7: 22. 5. 31. | B7: 22. 5. 20. | C7: ID:3163-3292-1286-55073 | D7: Single Purchase | E7: Sale | F7: None | G7: 1 | H7: 9791164370986 | I7: Storywiz Co., Ltd. | J7: 사랑을 놓치고 외전 | K7: 차홍주 | L7: KRW | M7: 500 | N7: KRW | O7: 500 | P7: 500 | Q7: KR | R7: 0.7 | S7: 350 | T7: KRW | U7: 350 | V7: 스토리위즈 | W7: 차홍주
A8: 22. 5. 31. | B8: 22. 5. 27. | C8: ID:3118-7190-8697-56567 | D8: Single Purchase | E8: Sale | F8: None | G8: 1 | H8: 9791164370986 | I8: Storywiz Co., Ltd. | J8: 사랑을 놓치고 외전 | K8: 차홍주 | L8: KRW | M8: 500 | N8: KRW | O8: 500 | P8: 500 | Q8: KR | R8: 0.7 | S8: 350 | T8: KRW | U8: 350 | V8: 스토리위즈 | W8: 차홍주

Sheet 청빙
A1: Earnings Date | B1: Transaction Date | C1: Id | D1: Product | E1: Type | F1: Preorder | G1: Qty | H1: Primary ISBN | I1: Imprint Name | J1: Title | K1: Author | L1: Original List Price Currency | M1: Original List Price | N1: List Price Currency | O1: List Price [tax inclusive] | P1: List Price [tax exclusive] | Q1: Country of Sale | R1: Publisher Revenue % | S1: Publisher Revenue | T1: Earnings Currency | U1: Earnings Amount | V1: 출판사 | W1: 작가 CP
A2: 22. 5. 31. | B2: 22. 5. 11. | C2: ID:3181-3981-5039-96912 | D2: Single Purchase | E2: Sale | F2: None | G2: 1 | H2: 9791166065781 | I2: 스토리위즈 | J2: 삼국지 호접몽전 1부 2권 | K2: 청빙 | L2: KRW | M2: 3200 | N2: USD | O2: 2.64 | P2: 2.64 | Q2: US | R2: 0.7 | S2: 1.85 | T2: KRW | U2: 2383 | V2: 스토리위즈 | W2: 청빙
