Workbook

Sheet 합계 (5)
A1: 제목 | B1: 저자 | C1: 출판권자 | D1: 판매처 | E1: 판매유형 | F1: 부수 | G1: 정가 | H1: 판매액 | I1: 할인 | J1: 수수료 | K1: 정산대상금액 | L1: 정산액 | M1: 출판사 | N1: 작가 CP
A2: 21세기 대마법사 2 | B2: 김광수 | C2: 스토리위즈 | D2: B2C | E2: 대여제 | H2: 900 | J2: 0 | K2: 900 | L2: 630 | M2: =IF(ISERROR(VLOOKUP(B2,[1]작가별정산률!$R:$S,2,0)),"스토리위즈",VLOOKUP(B2,[1]작가별정산률!$R:$S,2,0)) -> 스토리위즈 | N2: =IF(M2="스토리위즈",VLOOKUP(B2,[1]작가별정산률!$A:$B,2,0),M2) -> 김광수
A3: 21세기 대마법사 3 | B3: 김광수 | C3: 스토리위즈 | D3: B2C | E3: 대여제 | H3: 900 | J3: 0 | K3: 900 | L3: 630 | M3: =IF(ISERROR(VLOOKUP(B3,[1]작가별정산률!$R:$S,2,0)),"스토리위즈",VLOOKUP(B3,[1]작가별정산률!$R:$S,2,0)) -> 스토리위즈 | N3: =IF(M3="스토리위즈",VLOOKUP(B3,[1]작가별정산률!$A:$B,2,0),M3) -> 김광수
A4: 21세기 대마법사 4 | B4: 김광수 | C4: 스토리위즈 | D4: B2C | E4: 대여제 | H4: 900 | J4: 0 | K4: 900 | L4: 630 | M4: =IF(ISERROR(VLOOKUP(B4,[1]작가별정산률!$R:$S,2,0)),"스토리위즈",VLOOKUP(B4,[1]작가별정산률!$R:$S,2,0)) -> 스토리위즈 | N4: =IF(M4="스토리위즈",VLOOKUP(B4,[1]작가별정산률!$A:$B,2,0),M4) -> 김광수
A5: 21세기 대마법사 5 | B5: 김광수 | C5: 스토리위즈 | D5: B2C | E5: 대여제 | H5: 900 | J5: 0 | K5: 900 | L5: 630 | M5: =IF(ISERROR(VLOOKUP(B5,[1]작가별정산률!$R:$S,2,0)),"스토리위즈",VLOOKUP(B5,[1]작가별정산률!$R:$S,2,0)) -> 스토리위즈 | N5: =IF(M5="스토리위즈",VLOOKUP(B5,[1]작가별정산률!$A:$B,2,0),M5) -> 김광수
A6: 21세기 대마법사 6 | B6: 김광수 | C6: 스토리위즈 | D6: B2C | E6: 대여제 | H6: 900 | J6: 0 | K6: 900 | L6: 630 | M6: =IF(ISERROR(VLOOKUP(B6,[1]작가별정산률!$R:$S,2,0)),"스토리위즈",VLOOKUP(B6,[1]작가별정산률!$R:$S,2,0)) -> 스토리위즈 | N6: =IF(M6="스토리위즈",VLOOKUP(B6,[1]작가별정산률!$A:$B,2,0),M6) -> 김광수
A7: 21세기 대마법사 7 | B7: 김광수 | C7: 스토리위즈 | D7: B2C | E7: 대여제 | H7: 900 | J7: 0 | K7: 900 | L7: 630 | M7: =IF(ISERROR(VLOOKUP(B7,[1]작가별정산률!$R:$S,2,0)),"스토리위즈",VLOOKUP(B7,[1]작가별정산률!$R:$S,2,0)) -> 스토리위즈 | N7: =IF(M7="스토리위즈",VLOOKUP(B7,[1]작가별정산률!$A:$B,2,0),M7) -> 김광수
A8: 21세기 대마법사 8 | B8: 김광수 | C8: 스토리위즈 | D8: B2C | E8: 대여제 | H8: 900 | J8: 0 | K8: 900 | L8: 630 | M8: =IF(ISERROR(VLOOKUP(B8,[1]작가별정산률!$R:$S,2,0)),"스토리위즈",VLOOKUP(B8,[1]작가별정산률!$R:$S,2,0)) -> 스토리위즈 | N8: =IF(M8="스토리위즈",VLOOKUP(B8,[1]작가별정산률!$A:$B,2,0),M8) -> 김광수
A9: 21세기 대마법사 9 | B9: 김광수 | C9: 스토리위즈 | D9: B2C | E9: 대여제 | H9: 900 | J9: 0 | K9: 900 | L9: 630 | M9: =IF(ISERROR(VLOOKUP(B9,[1]작가별정산률!$R:$S,2,0)),"스토리위즈",VLOOKUP(B9,[1]작가별정산률!$R:$S,2,0)) -> 스토리위즈 | N9: =IF(M9="스토리위즈",VLOOKUP(B9,[1]작가별정산률!$A:$B,2,0),M9) -> 김광수
A10: 21세기 대마법사 10 | B10: 김광수 | C10: 스토리위즈 | D10: B2C | E10: 대여제 | H10: 900 | J10: 0 | K10: 900 | L10: 630 | M10: =IF(ISERROR(VLOOKUP(B10,[1]작가별정산률!$R:$S,2,0)),"스토리위즈",VLOOKUP(B10,[1]작가별정산률!$R:$S,2,0)) -> 스토리위즈 | N10: =IF(M10="스토리위즈",VLOOKUP(B10,[1]작가별정산률!$A:$B,2,0),M10) -> 김광수
A11: 21세기 대마법사 11 | B11: 김광수 | C11: 스토리위즈 | D11: B2C | E11: 대여제 | H11: 900 | J11: 0 | K11: 900 | L11: 630 | M11: =IF(ISERROR(VLOOKUP(B11,[1]작가별정산률!$R:$S,2,0)),"스토리위즈",VLOOKUP(B11,[1]작가별정산률!$R:$S,2,0)) -> 스토리위즈 | N11: =IF(M11="스토리위즈",VLOOKUP(B11,[1]작가별정산률!$A:$B,2,0),M11) -> 김광수
A12: 21세기 대마법사 12 | B12: 김광수 | C12: 스토리위즈 | D12: B2C | E12: 대여제 | H12: 900 | J12: 0 | K12: 900 | L12: 630 | M12: =IF(ISERROR(VLOOKUP(B12,[1]작가별정산률!$R:$S,2,0)),"스토리위즈",VLOOKUP(B12,[1]작가별정산률!$R:$S,2,0)) -> 스토리위즈 | N12: =IF(M12="스토리위즈",VLOOKUP(B12,[1]작가별정산률!$A:$B,2,0),M12) -> 김광수
A13: 21세기 대마법사 13 | B13: 김광수 | C13: 스토리위즈 | D13: B2C | E13: 대여제 | H13: 900 | J13: 0 | K13: 900 | L13: 630 | M13: =IF(ISERROR(VLOOKUP(B13,[1]작가별정산률!$R:$S,2,0)),"스토리위즈",VLOOKUP(B13,[1]작가별정산률!$R:$S,2,0)) -> 스토리위즈 | N13: =IF(M13="스토리위즈",VLOOKUP(B13,[1]작가별정산률!$A:$B,2,0),M13) -> 김광수
... A18: 21세기 대마법사 18 (완결) | B18: 김광수 | C18: 스토리위즈 | D18: B2C | E18: 대여제 | H18: 900 | J18: 0 | K18: 900 | L18: 630 | M18: =IF(ISERROR(VLOOKUP(B18,[1]작가별정산률!$R:$S,2,0)),"스토리위즈",VLOOKUP(B18,[1]작가별정산률!$R:$S,2,0)) -> 스토리위즈 | N18: =IF(M18="스토리위즈",VLOOKUP(B18,[1]작가별정산률!$A:$B,2,0),M18) -> 김광수
A19: 갓 오브 블랙필드 14 | B19: 무장 | C19: 스토리위즈 | D19: B2C | E19: 단권 | F19: 1 | G19: 3200 | H19: 3200 | I19: 0 | J19: 0 | K19: 3200 | L19: 2240 | M19: =IF(ISERROR(VLOOKUP(B19,[1]작가별정산률!$R:$S,2,0)),"스토리위즈",VLOOKUP(B19,[1]작가별정산률!$R:$S,2,0)) -> 스토리위즈 | N19: =IF(M19="스토리위즈",VLOOKUP(B19,[1]작가별정산률!$A:$B,2,0),M19) -> 무장
A20: 갓 오브 블랙필드 2 | B20: 무장 | C20: 스토리위즈 | D20: B2C | E20: 단권 | F20: 1 | G20: 3200 | H20: 3200 | I20: 0 | J20: 0 | K20: 3200 | L20: 2240 | M20: =IF(ISERROR(VLOOKUP(B20,[1]작가별정산률!$R:$S,2,0)),"스토리위즈",VLOOKUP(B20,[1]작가별정산률!$R:$S,2,0)) -> 스토리위즈 | N20: =IF(M20="스토리위즈",VLOOKUP(B20,[1]작가별정산률!$A:$B,2,0),M20) -> 무장
A21: 갓 오브 블랙필드 20 | B21: 무장 | C21: 스토리위즈 | D21: B2C | E21: 단권 | F21: 1 | G21: 3200 | H21: 3200 | I21: 0 | J21: 0 | K21: 3200 | L21: 2240 | M21: =IF(ISERROR(VLOOKUP(B21,[1]작가별정산률!$R:$S,2,0)),"스토리위즈",VLOOKUP(B21,[1]작가별정산률!$R:$S,2,0)) -> 스토리위즈 | N21: =IF(M21="스토리위즈",VLOOKUP(B21,[1]작가별정산률!$A:$B,2,0),M21) -> 무장
A22: 갓 오브 블랙필드 21 | B22: 무장 | C22: 스토리위즈 | D22: B2C | E22: 단권 | F22: 1 | G22: 3200 | H22: 3200 | I22: 0 | J22: 0 | K22: 3200 | L22: 2240 | M22: =IF(ISERROR(VLOOKUP(B22,[1]작가별정산률!$R:$S,2,0)),"스토리위즈",VLOOKUP(B22,[1]작가별정산률!$R:$S,2,0)) -> 스토리위즈 | N22: =IF(M22="스토리위즈",VLOOKUP(B22,[1]작가별정산률!$A:$B,2,0),M22) -> 무장
A23: 갓 오브 블랙필드 22 | B23: 무장 | C23: 스토리위즈 | D23: B2C | E23: 단권 | F23: 1 | G23: 3200 | H23: 3200 | I23: 0 | J23: 0 | K23: 3200 | L23: 2240 | M23: =IF(ISERROR(VLOOKUP(B23,[1]작가별정산률!$R:$S,2,0)),"스토리위즈",VLOOKUP(B23,[1]작가별정산률!$R:$S,2,0)) -> 스토리위즈 | N23: =IF(M23="스토리위즈",VLOOKUP(B23,[1]작가별정산률!$A:$B,2,0),M23) -> 무장
A24: 갓 오브 블랙필드 23 | B24: 무장 | C24: 스토리위즈 | D24: B2C | E24: 단권 | F24: 1 | G24: 3200 | H24: 3200 | I24: 0 | J24: 0 | K24: 3200 | L24: 2240 | M24: =IF(ISERROR(VLOOKUP(B24,[1]작가별정산률!$R:$S,2,0)),"스토리위즈",VLOOKUP(B24,[1]작가별정산률!$R:$S,2,0)) -> 스토리위즈 | N24: =IF(M24="스토리위즈",VLOOKUP(B24,[1]작가별정산률!$A:$B,2,0),M24) -> 무장
A25: 갓 오브 블랙필드 24 | B25: 무장 | C25: 스토리위즈 | D25: B2C | E25: 단권 | F25: 1 | G25: 3200 | H25: 3200 | I25: 0 | J25: 0 | K25: 3200 | L25: 2240 | M25: =IF(ISERROR(VLOOKUP(B25,[1]작가별정산률!$R:$S,2,0)),"스토리위즈",VLOOKUP(B25,[1]작가별정산률!$R:$S,2,0)) -> 스토리위즈 | N25: =IF(M25="스토리위즈",VLOOKUP(B25,[1]작가별정산률!$A:$B,2,0),M25) -> 무장
A26: 갓 오브 블랙필드 3 | B26: 무장 | C26: 스토리위즈 | D26: B2C | E26: 단권 | F26: 2 | G26: 3200 | H26: 6400 | I26: 0 | J26: 0 | K26: 6400 | L26: 4480 | M26: =IF(ISERROR(VLOOKUP(B26,[1]작가별정산률!$R:$S,2,0)),"스토리위즈",VLOOKUP(B26,[1]작가별정산률!$R:$S,2,0)) -> 스토리위즈 | N26: =IF(M26="스토리위즈",VLOOKUP(B26,[1]작가별정산률!$A:$B,2,0),M26) -> 무장
A27: 갓 오브 블랙필드 4 | B27: 무장 | C27: 스토리위즈 | D27: B2C | E27: 단권 | F27: 2 | G27: 3200 | H27: 6400 | I27: 0 | J27: 0 | K27: 6400 | L27: 4480 | M27: =IF(ISERROR(VLOOKUP(B27,[1]작가별정산률!$R:$S,2,0)),"스토리위즈",VLOOKUP(B27,[1]작가별정산률!$R:$S,2,0)) -> 스토리위즈 | N27: =IF(M27="스토리위즈",VLOOKUP(B27,[1]작가별정산률!$A:$B,2,0),M27) -> 무장
A28: 갓 오브 블랙필드 5 | B28: 무장 | C28: 스토리위즈 | D28: B2C | E28: 단권 | F28: 1 | G28: 3200 | H28: 3200 | I28: 0 | J28: 0 | K28: 3200 | L28: 2240 | M28: =IF(ISERROR(VLOOKUP(B28,[1]작가별정산률!$R:$S,2,0)),"스토리위즈",VLOOKUP(B28,[1]작가별정산률!$R:$S,2,0)) -> 스토리위즈 | N28: =IF(M28="스토리위즈",VLOOKUP(B28,[1]작가별정산률!$A:$B,2,0),M28) -> 무장
A29: 갓 오브 블랙필드 6 | B29: 무장 | C29: 스토리위즈 | D29: B2C | E29: 단권 | F29: 1 | G29: 3200 | H29: 3200 | I29: 0 | J29: 0 | K29: 3200 | L29: 2240 | M29: =IF(ISERROR(VLOOKUP(B29,[1]작가별정산률!$R:$S,2,0)),"스토리위즈",VLOOKUP(B29,[1]작가별정산률!$R:$S,2,0)) -> 스토리위즈 | N29: =IF(M29="스토리위즈",VLOOKUP(B29,[1]작가별정산률!$A:$B,2,0),M29) -> 무장
A30: 갓 오브 블랙필드 7 | B30: 무장 | C30: 스토리위즈 | D30: B2C | E30: 단권 | F30: 1 | G30: 3200 | H30: 3200 | I30: 0 | J30: 0 | K30: 3200 | L30: 2240 | M30: =IF(ISERROR(VLOOKUP(B30,[1]작가별정산률!$R:$S,2,0)),"스토리위즈",VLOOKUP(B30,[1]작가별정산률!$R:$S,2,0)) -> 스토리위즈 | N30: =IF(M30="스토리위즈",VLOOKUP(B30,[1]작가별정산률!$A:$B,2,0),M30) -> 무장
... A68: [시리즈]로드 오브 머니 9 | B68: 무장 | C68: 스토리위즈 | D68: B2C | E68: 단권 | F68: 1 | G68: 3200 | H68: 3200 | I68: 0 | J68: 0 | K68: 3200 | L68: 2240 | M68: =IF(ISERROR(VLOOKUP(B68,[1]작가별정산률!$R:$S,2,0)),"스토리위즈",VLOOKUP(B68,[1]작가별정산률!$R:$S,2,0)) -> 스토리위즈 | N68: =IF(M68="스토리위즈",VLOOKUP(B68,[1]작가별정산률!$A:$B,2,0),M68) -> 무장
A69: 마스터 K 2 | B69: 김광수 | C69: 스토리위즈 | D69: B2C | E69: 대여제 | H69: 900 | J69: 0 | K69: 900 | L69: 630 | M69: =IF(ISERROR(VLOOKUP(B69,[1]작가별정산률!$R:$S,2,0)),"스토리위즈",VLOOKUP(B69,[1]작가별정산률!$R:$S,2,0)) -> 스토리위즈 | N69: =IF(M69="스토리위즈",VLOOKUP(B69,[1]작가별정산률!$A:$B,2,0),M69) -> 김광수
A70: [시리즈]마왕 데이몬 2 | B70: 김정률 | C70: 스토리위즈 | D70: B2C | E70: 단권 | F70: 1 | G70: 3200 | H70: 3200 | I70: 0 | J70: 0 | K70: 3200 | L70: 2240 | M70: =IF(ISERROR(VLOOKUP(B70,[1]작가별정산률!$R:$S,2,0)),"스토리위즈",VLOOKUP(B70,[1]작가별정산률!$R:$S,2,0)) -> 스토리위즈 | N70: =IF(M70="스토리위즈",VLOOKUP(B70,[1]작가별정산률!$A:$B,2,0),M70) -> 김정률
A71: [시리즈]마왕 데이몬 3 | B71: 김정률 | C71: 스토리위즈 | D71: B2C | E71: 단권 | F71: 1 | G71: 3200 | H71: 3200 | I71: 0 | J71: 0 | K71: 3200 | L71: 2240 | M71: =IF(ISERROR(VLOOKUP(B71,[1]작가별정산률!$R:$S,2,0)),"스토리위즈",VLOOKUP(B71,[1]작가별정산률!$R:$S,2,0)) -> 스토리위즈 | N71: =IF(M71="스토리위즈",VLOOKUP(B71,[1]작가별정산률!$A:$B,2,0),M71) -> 김정률
A72: [시리즈]마왕 데이몬 4 | B72: 김정률 | C72: 스토리위즈 | D72: B2C | E72: 단권 | F72: 1 | G72: 3200 | H72: 3200 | I72: 0 | J72: 0 | K72: 3200 | L72: 2240 | M72: =IF(ISERROR(VLOOKUP(B72,[1]작가별정산률!$R:$S,2,0)),"스토리위즈",VLOOKUP(B72,[1]작가별정산률!$R:$S,2,0)) -> 스토리위즈 | N72: =IF(M72="스토리위즈",VLOOKUP(B72,[1]작가별정산률!$A:$B,2,0),M72) -> 김정률
A73: [시리즈]마왕 데이몬 5 | B73: 김정률 | C73: 스토리위즈 | D73: B2C | E73: 단권 | F73: 1 | G73: 3200 | H73: 3200 | I73: 0 | J73: 0 | K73: 3200 | L73: 2240 | M73: =IF(ISERROR(VLOOKUP(B73,[1]작가별정산률!$R:$S,2,0)),"스토리위즈",VLOOKUP(B73,[1]작가별정산률!$R:$S,2,0)) -> 스토리위즈 | N73: =IF(M73="스토리위즈",VLOOKUP(B73,[1]작가별정산률!$A:$B,2,0),M73) -> 김정률
A74: [시리즈]마왕 데이몬 6 | B74: 김정률 | C74: 스토리위즈 | D74: B2C | E74: 단권 | F74: 1 | G74: 3200 | H74: 3200 | I74: 0 | J74: 0 | K74: 3200 | L74: 2240 | M74: =IF(ISERROR(VLOOKUP(B74,[1]작가별정산률!$R:$S,2,0)),"스토리위즈",VLOOKUP(B74,[1]작가별정산률!$R:$S,2,0)) -> 스토리위즈 | N74: =IF(M74="스토리위즈",VLOOKUP(B74,[1]작가별정산률!$A:$B,2,0),M74) -> 김정률
A75: [시리즈]마왕 데이몬 7 | B75: 김정률 | C75: 스토리위즈 | D75: B2C | E75: 단권 | F75: 1 | G75: 3200 | H75: 3200 | I75: 0 | J75: 0 | K75: 3200 | L75: 2240 | M75: =IF(ISERROR(VLOOKUP(B75,[1]작가별정산률!$R:$S,2,0)),"스토리위즈",VLOOKUP(B75,[1]작가별정산률!$R:$S,2,0)) -> 스토리위즈 | N75: =IF(M75="스토리위즈",VLOOKUP(B75,[1]작가별정산률!$A:$B,2,0),M75) -> 김정률
A76: [시리즈]마왕 데이몬 8 | B76: 김정률 | C76: 스토리위즈 | D76: B2C | E76: 단권 | F76: 1 | G76: 3200 | H76: 3200 | I76: 0 | J76: 0 | K76: 3200 | L76: 2240 | M76: =IF(ISERROR(VLOOKUP(B76,[1]작가별정산률!$R:$S,2,0)),"스토리위즈",VLOOKUP(B76,[1]작가별정산률!$R:$S,2,0)) -> 스토리위즈 | N76: =IF(M76="스토리위즈",VLOOKUP(B76,[1]작가별정산률!$A:$B,2,0),M76) -> 김정률
A77: [시리즈]마왕 데이몬 9 | B77: 김정률 | C77: 스토리위즈 | D77: B2C | E77: 단권 | F77: 1 | G77: 3200 | H77: 3200 | I77: 0 | J77: 0 | K77: 3200 | L77: 2240 | M77: =IF(ISERROR(VLOOKUP(B77,[1]작가별정산률!$R:$S,2,0)),"스토리위즈",VLOOKUP(B77,[1]작가별정산률!$R:$S,2,0)) -> 스토리위즈 | N77: =IF(M77="스토리위즈",VLOOKUP(B77,[1]작가별정산률!$A:$B,2,0),M77) -> 김정률
A78: [시리즈]마왕 데이몬 10 | B78: 김정률 | C78: 스토리위즈 | D78: B2C | E78: 단권 | F78: 1 | G78: 3200 | H78: 3200 | I78: 0 | J78: 0 | K78: 3200 | L78: 2240 | M78: =IF(ISERROR(VLOOKUP(B78,[1]작가별정산률!$R:$S,2,0)),"스토리위즈",VLOOKUP(B78,[1]작가별정산률!$R:$S,2,0)) -> 스토리위즈 | N78: =IF(M78="스토리위즈",VLOOKUP(B78,[1]작가별정산률!$A:$B,2,0),M78) -> 김정률
A79: [시리즈]마왕 데이몬 11 | B79: 김정률 | C79: 스토리위즈 | D79: B2C | E79: 단권 | F79: 1 | G79: 3200 | H79: 3200 | I79: 0 | J79: 0 | K79: 3200 | L79: 2240 | M79: =IF(ISERROR(VLOOKUP(B79,[1]작가별정산률!$R:$S,2,0)),"스토리위즈",VLOOKUP(B79,[1]작가별정산률!$R:$S,2,0)) -> 스토리위즈 | N79: =IF(M79="스토리위즈",VLOOKUP(B79,[1]작가별정산률!$A:$B,2,0),M79) -> 김정률
A80: [시리즈]마왕 데이몬 12 (완결) | B80: 김정률 | C80: 스토리위즈 | D80: B2C | E80: 단권 | F80: 1 | G80: 3200 | H80: 3200 | I80: 0 | J80: 0 | K80: 3200 | L80: 2240 | M80: =IF(ISERROR(VLOOKUP(B80,[1]작가별정산률!$R:$S,2,0)),"스토리위즈",VLOOKUP(B80,[1]작가별정산률!$R:$S,2,0)) -> 스토리위즈 | N80: =IF(M80="스토리위즈",VLOOKUP(B80,[1]작가별정산률!$A:$B,2,0),M80) -> 김정률
A81: 망작 리메이커 2 | B81: 덕킹 | C81: 스토리위즈 | D81: B2B | E81: 백석대학교 | F81: 1 | G81: 3200 | H81: 3200 | I81: 0 | J81: 0 | K81: 3200 | L81: 1600 | M81: =IF(ISERROR(VLOOKUP(B81,[1]작가별정산률!$R:$S,2,0)),"스토리위즈",VLOOKUP(B81,[1]작가별정산률!$R:$S,2,0)) -> 스토리위즈 | N81: =IF(M81="스토리위즈",VLOOKUP(B81,[1]작가별정산률!$A:$B,2,0),M81) -> 덕킹
...

Sheet 김광수
A1: 제목 | B1: 저자 | C1: 출판권자 | D1: 판매처 | E1: 판매유형 | F1: 부수 | G1: 정가 | H1: 판매액 | I1: 할인 | J1: 수수료 | K1: 정산대상금액 | L1: 정산액 | M1: 출판사 | N1: 작가 CP
A2: 21세기 대마법사 2 | B2: 김광수 | C2: 스토리위즈 | D2: B2C | E2: 대여제 | H2: 900 | J2: 0 | K2: 900 | L2: 630 | M2: 스토리위즈 | N2: 김광수
A3: 21세기 대마법사 3 | B3: 김광수 | C3: 스토리위즈 | D3: B2C | E3: 대여제 | H3: 900 | J3: 0 | K3: 900 | L3: 630 | M3: 스토리위즈 | N3: 김광수
A4: 21세기 대마법사 4 | B4: 김광수 | C4: 스토리위즈 | D4: B2C | E4: 대여제 | H4: 900 | J4: 0 | K4: 900 | L4: 630 | M4: 스토리위즈 | N4: 김광수
A5: 21세기 대마법사 5 | B5: 김광수 | C5: 스토리위즈 | D5: B2C | E5: 대여제 | H5: 900 | J5: 0 | K5: 900 | L5: 630 | M5: 스토리위즈 | N5: 김광수
A6: 21세기 대마법사 6 | B6: 김광수 | C6: 스토리위즈 | D6: B2C | E6: 대여제 | H6: 900 | J6: 0 | K6: 900 | L6: 630 | M6: 스토리위즈 | N6: 김광수
A7: 21세기 대마법사 7 | B7: 김광수 | C7: 스토리위즈 | D7: B2C | E7: 대여제 | H7: 900 | J7: 0 | K7: 900 | L7: 630 | M7: 스토리위즈 | N7: 김광수
A8: 21세기 대마법사 8 | B8: 김광수 | C8: 스토리위즈 | D8: B2C | E8: 대여제 | H8: 900 | J8: 0 | K8: 900 | L8: 630 | M8: 스토리위즈 | N8: 김광수
A9: 21세기 대마법사 9 | B9: 김광수 | C9: 스토리위즈 | D9: B2C | E9: 대여제 | H9: 900 | J9: 0 | K9: 900 | L9: 630 | M9: 스토리위즈 | N9: 김광수
A10: 21세기 대마법사 10 | B10: 김광수 | C10: 스토리위즈 | D10: B2C | E10: 대여제 | H10: 900 | J10: 0 | K10: 900 | L10: 630 | M10: 스토리위즈 | N10: 김광수
A11: 21세기 대마법사 11 | B11: 김광수 | C11: 스토리위즈 | D11: B2C | E11: 대여제 | H11: 900 | J11: 0 | K11: 900 | L11: 630 | M11: 스토리위즈 | N11: 김광수
A12: 21세기 대마법사 12 | B12: 김광수 | C12: 스토리위즈 | D12: B2C | E12: 대여제 | H12: 900 | J12: 0 | K12: 900 | L12: 630 | M12: 스토리위즈 | N12: 김광수
A13: 21세기 대마법사 13 | B13: 김광수 | C13: 스토리위즈 | D13: B2C | E13: 대여제 | H13: 900 | J13: 0 | K13: 900 | L13: 630 | M13: 스토리위즈 | N13: 김광수
... A27: [시리즈]프리나이트 9 (완결) | B27: 김광수 | C27: 스토리위즈 | D27: B2C | E27: 대여제 | H27: 900 | J27: 0 | K27: 900 | L27: 630 | M27: 스토리위즈 | N27: 김광수
A28: 회귀의 전설 | B28: 김광수 | C28: 스토리위즈 | D28: B2C | E28: 프리미엄 | F28: 1696 | G28: 100 | H28: 169600 | I28: 0 | J28: 0 | K28: 169600 | L28: 118720 | M28: 스토리위즈 | N28: 김광수
A29: 회귀의 전설 2부 22 | B29: 김광수 | C29: 스토리위즈 | D29: B2B | E29: 제천시립도서관 | F29: 2 | G29: 3200 | H29: 6400 | I29: 0 | J29: 0 | K29: 6400 | L29: 3200 | M29: 스토리위즈 | N29: 김광수
A30: 회귀의 전설 2부 23 | B30: 김광수 | C30: 스토리위즈 | D30: B2B | E30: 제천시립도서관 | F30: 2 | G30: 3200 | H30: 6400 | I30: 0 | J30: 0 | K30: 6400 | L30: 3200 | M30: 스토리위즈 | N30: 김광수
A31: 회귀의 전설 2부 24 | B31: 김광수 | C31: 스토리위즈 | D31: B2B | E31: 제천시립도서관 | F31: 2 | G31: 3200 | H31: 6400 | I31: 0 | J31: 0 | K31: 6400 | L31: 3200 | M31: 스토리위즈 | N31: 김광수
A32: 회귀의 전설 2부 25 | B32: 김광수 | C32: 스토리위즈 | D32: B2B | E32: 제천시립도서관 | F32: 2 | G32: 3200 | H32: 6400 | I32: 0 | J32: 0 | K32: 6400 | L32: 3200 | M32: 스토리위즈 | N32: 김광수
A33: 회귀의 전설 2부 26 | B33: 김광수 | C33: 스토리위즈 | D33: B2B | E33: 제천시립도서관 | F33: 2 | G33: 3200 | H33: 6400 | I33: 0 | J33: 0 | K33: 6400 | L33: 3200 | M33: 스토리위즈 | N33: 김광수
A34: 회귀의 전설 2부 27 | B34: 김광수 | C34: 스토리위즈 | D34: B2B | E34: 제천시립도서관 | F34: 2 | G34: 3200 | H34: 6400 | I34: 0 | J34: 0 | K34: 6400 | L34: 3200 | M34: 스토리위즈 | N34: 김광수
A35: 회귀의 전설 2부 28 | B35: 김광수 | C35: 스토리위즈 | D35: B2B | E35: 제천시립도서관 | F35: 2 | G35: 3200 | H35: 6400 | I35: 0 | J35: 0 | K35: 6400 | L35: 3200 | M35: 스토리위즈 | N35: 김광수
A36: 회귀의 전설 2부 29 | B36: 김광수 | C36: 스토리위즈 | D36: B2B | E36: 제천시립도서관 | F36: 2 | G36: 3200 | H36: 6400 | I36: 0 | J36: 0 | K36: 6400 | L36: 3200 | M36: 스토리위즈 | N36: 김광수
A37: 회귀의 전설 2부 30 | B37: 김광수 | C37: 스토리위즈 | D37: B2B | E37: 제천시립도서관 | F37: 2 | G37: 3200 | H37: 6400 | I37: 0 | J37: 0 | K37: 6400 | L37: 3200 | M37: 스토리위즈 | N37: 김광수
A38: 회귀의 전설 2부 31 | B38: 김광수 | C38: 스토리위즈 | D38: B2B | E38: 제천시립도서관 | F38: 2 | G38: 3200 | H38: 6400 | I38: 0 | J38: 0 | K38: 6400 | L38: 3200 | M38: 스토리위즈 | N38: 김광수
A39: 회귀의 전설 2부 32 | B39: 김광수 | C39: 스토리위즈 | D39: B2B | E39: 제천시립도서관 | F39: 2 | G39: 3200 | H39: 6400 | I39: 0 | J39: 0 | K39: 6400 | L39: 3200 | M39: 스토리위즈 | N39: 김광수
... A50: 회귀의 전설 2부 43 (2부 완결) | B50: 김광수 | C50: 스토리위즈 | D50: B2B | E50: 제천시립도서관 | F50: 2 | G50: 3200 | H50: 6400 | I50: 0 | J50: 0 | K50: 6400 | L50: 3200 | M50: 스토리위즈 | N50: 김광수

Sheet 무장
A1: 제목 | B1: 저자 | C1: 출판권자 | D1: 판매처 | E1: 판매유형 | F1: 부수 | G1: 정가 | H1: 판매액 | I1: 할인 | J1: 수수료 | K1: 정산대상금액 | L1: 정산액 | M1: 출판사 | N1: 작가 CP
A2: 갓 오브 블랙필드 14 | B2: 무장 | C2: 스토리위즈 | D2: B2C | E2: 단권 | F2: 1 | G2: 3200 | H2: 3200 | I2: 0 | J2: 0 | K2: 3200 | L2: 2240 | M2: 스토리위즈 | N2: 무장
A3: 갓 오브 블랙필드 2 | B3: 무장 | C3: 스토리위즈 | D3: B2C | E3: 단권 | F3: 1 | G3: 3200 | H3: 3200 | I3: 0 | J3: 0 | K3: 3200 | L3: 2240 | M3: 스토리위즈 | N3: 무장
A4: 갓 오브 블랙필드 20 | B4: 무장 | C4: 스토리위즈 | D4: B2C | E4: 단권 | F4: 1 | G4: 3200 | H4: 3200 | I4: 0 | J4: 0 | K4: 3200 | L4: 2240 | M4: 스토리위즈 | N4: 무장
A5: 갓 오브 블랙필드 21 | B5: 무장 | C5: 스토리위즈 | D5: B2C | E5: 단권 | F5: 1 | G5: 3200 | H5: 3200 | I5: 0 | J5: 0 | K5: 3200 | L5: 2240 | M5: 스토리위즈 | N5: 무장
A6: 갓 오브 블랙필드 22 | B6: 무장 | C6: 스토리위즈 | D6: B2C | E6: 단권 | F6: 1 | G6: 3200 | H6: 3200 | I6: 0 | J6: 0 | K6: 3200 | L6: 2240 | M6: 스토리위즈 | N6: 무장
A7: 갓 오브 블랙필드 23 | B7: 무장 | C7: 스토리위즈 | D7: B2C | E7: 단권 | F7: 1 | G7: 3200 | H7: 3200 | I7: 0 | J7: 0 | K7: 3200 | L7: 2240 | M7: 스토리위즈 | N7: 무장
A8: 갓 오브 블랙필드 24 | B8: 무장 | C8: 스토리위즈 | D8: B2C | E8: 단권 | F8: 1 | G8: 3200 | H8: 3200 | I8: 0 | J8: 0 | K8: 3200 | L8: 2240 | M8: 스토리위즈 | N8: 무장
A9: 갓 오브 블랙필드 3 | B9: 무장 | C9: 스토리위즈 | D9: B2C | E9: 단권 | F9: 2 | G9: 3200 | H9: 6400 | I9: 0 | J9: 0 | K9: 6400 | L9: 4480 | M9: 스토리위즈 | N9: 무장
A10: 갓 오브 블랙필드 4 | B10: 무장 | C10: 스토리위즈 | D10: B2C | E10: 단권 | F10: 2 | G10: 3200 | H10: 6400 | I10: 0 | J10: 0 | K10: 6400 | L10: 4480 | M10: 스토리위즈 | N10: 무장
A11: 갓 오브 블랙필드 5 | B11: 무장 | C11: 스토리위즈 | D11: B2C | E11: 단권 | F11: 1 | G11: 3200 | H11: 3200 | I11: 0 | J11: 0 | K11: 3200 | L11: 2240 | M11: 스토리위즈 | N11: 무장
A12: 갓 오브 블랙필드 6 | B12: 무장 | C12: 스토리위즈 | D12: B2C | E12: 단권 | F12: 1 | G12: 3200 | H12: 3200 | I12: 0 | J12: 0 | K12: 3200 | L12: 2240 | M12: 스토리위즈 | N12: 무장
A13: 갓 오브 블랙필드 7 | B13: 무장 | C13: 스토리위즈 | D13: B2C | E13: 단권 | F13: 1 | G13: 3200 | H13: 3200 | I13: 0 | J13: 0 | K13: 3200 | L13: 2240 | M13: 스토리위즈 | N13: 무장
... A66: 형사의 게임 | B66: 무장 | C66: 스토리위즈 | D66: B2C | E66: 프리미엄 | F66: 490 | G66: 100 | H66: 49000 | I66: 0 | J66: 0 | K66: 49000 | L66: 34300 | M66: 스토리위즈 | N66: 무장
A67: 형사의 게임 10 | B67: 무장 | C67: 스토리위즈 | D67: B2C | E67: 대여제 | H67: 1800 | J67: 0 | K67: 1800 | L67: 1260 | M67: 스토리위즈 | N67: 무장
A68: 형사의 게임 11 | B68: 무장 | C68: 스토리위즈 | D68: B2C | E68: 대여제 | H68: 1800 | J68: 0 | K68: 1800 | L68: 1260 | M68: 스토리위즈 | N68: 무장
A69: 형사의 게임 12 (완결) | B69: 무장 | C69: 스토리위즈 | D69: B2C | E69: 대여제 | H69: 1800 | J69: 0 | K69: 1800 | L69: 1260 | M69: 스토리위즈 | N69: 무장
A70: 형사의 게임 2 | B70: 무장 | C70: 스토리위즈 | D70: B2C | E70: 대여제 | H70: 1800 | J70: 0 | K70: 1800 | L70: 1260 | M70: 스토리위즈 | N70: 무장
A71: 형사의 게임 3 | B71: 무장 | C71: 스토리위즈 | D71: B2C | E71: 대여제 | H71: 1800 | J71: 0 | K71: 1800 | L71: 1260 | M71: 스토리위즈 | N71: 무장
A72: 형사의 게임 4 | B72: 무장 | C72: 스토리위즈 | D72: B2C | E72: 대여제 | H72: 1800 | J72: 0 | K72: 1800 | L72: 1260 | M72: 스토리위즈 | N72: 무장
A73: 형사의 게임 5 | B73: 무장 | C73: 스토리위즈 | D73: B2C | E73: 대여제 | H73: 1800 | J73: 0 | K73: 1800 | L73: 1260 | M73: 스토리위즈 | N73: 무장
A74: 형사의 게임 6 | B74: 무장 | C74: 스토리위즈 | D74: B2C | E74: 대여제 | H74: 1800 | J74: 0 | K74: 1800 | L74: 1260 | M74: 스토리위즈 | N74: 무장
A75: 형사의 게임 7 | B75: 무장 | C75: 스토리위즈 | D75: B2C | E75: 대여제 | H75: 1800 | J75: 0 | K75: 1800 | L75: 1260 | M75: 스토리위즈 | N75: 무장
A76: 형사의 게임 8 | B76: 무장 | C76: 스토리위즈 | D76: B2C | E76: 대여제 | H76: 900 | J76: 0 | K76: 900 | L76: 630 | M76: 스토리위즈 | N76: 무장
A77: 형사의 게임 9 | B77: 무장 | C77: 스토리위즈 | D77: B2C | E77: 대여제 | H77: 1800 | J77: 0 | K77: 1800 | L77: 1260 | M77: 스토리위즈 | N77: 무장
A78: 화산검제 (2부) 1 | B78: 무장 | C78: 스토리위즈 | D78: B2C | E78: 단권 | F78: 1 | G78: 3200 | H78: 3200 | I78: 0 | J78: 0 | K78: 3200 | L78: 2240 | M78: 스토리위즈 | N78: 무장
A79: 화산검제 (2부) 2 | B79: 무장 | C79: 스토리위즈 | D79: B2C | E79: 단권 | F79: 1 | G79: 3200 | H79: 3200 | I79: 0 | J79: 0 | K79: 3200 | L79: 2240 | M79: 스토리위즈 | N79: 무장
A80: 화산검제 (2부) 3 | B80: 무장 | C80: 스토리위즈 | D80: B2C | E80: 단권 | F80: 1 | G80: 3200 | H80: 3200 | I80: 0 | J80: 0 | K80: 3200 | L80: 2240 | M80: 스토리위즈 | N80: 무장
A81: 화산검제 (2부) 4 | B81: 무장 | C81: 스토리위즈 | D81: B2C | E81: 단권 | F81: 1 | G81: 3200 | H81: 3200 | I81: 0 | J81: 0 | K81: 3200 | L81: 2240 | M81: 스토리위즈 | N81: 무장
A82: 화산검제 (2부) 5 (완결) | B82: 무장 | C82: 스토리위즈 | D82: B2C | E82: 단권 | F82: 1 | G82: 3200 | H82: 3200 | I82: 0 | J82: 0 | K82: 3200 | L82: 2240 | M82: 스토리위즈 | N82: 무장

Sheet 권용찬
A1: 제목 | B1: 저자 | C1: 출판권자 | D1: 판매처 | E1: 판매유형 | F1: 부수 | G1: 정가 | H1: 판매액 | I1: 할인 | J1: 수수료 | K1: 정산대상금액 | L1: 정산액 | M1: 출판사 | N1: 작가 CP
A2: 검산도해 2 | B2: 권용찬 | C2: 스토리위즈 | D2: B2C | E2: 단권 | F2: 1 | G2: 3200 | H2: 3200 | I2: 0 | J2: 0 | K2: 3200 | L2: 2240 | M2: 스토리위즈 | N2: 권용찬
A3: 신마협도 10 | B3: 권용찬 | C3: 스토리위즈 | D3: B2C | E3: 대여제 | H3: 900 | J3: 0 | K3: 900 | L3: 630 | M3: 스토리위즈 | N3: 권용찬
A4: 신마협도 11 | B4: 권용찬 | C4: 스토리위즈 | D4: B2C | E4: 대여제 | H4: 900 | J4: 0 | K4: 900 | L4: 630 | M4: 스토리위즈 | N4: 권용찬
A5: 신마협도 12 (완결) | B5: 권용찬 | C5: 스토리위즈 | D5: B2C | E5: 대여제 | H5: 900 | J5: 0 | K5: 900 | L5: 630 | M5: 스토리위즈 | N5: 권용찬
A6: 신마협도 2 | B6: 권용찬 | C6: 스토리위즈 | D6: B2C | E6: 대여제 | H6: 2700 | J6: 0 | K6: 2700 | L6: 1890 | M6: 스토리위즈 | N6: 권용찬
A7: 신마협도 3 | B7: 권용찬 | C7: 스토리위즈 | D7: B2C | E7: 대여제 | H7: 1800 | J7: 0 | K7: 1800 | L7: 1260 | M7: 스토리위즈 | N7: 권용찬
A8: 신마협도 4 | B8: 권용찬 | C8: 스토리위즈 | D8: B2C | E8: 대여제 | H8: 1800 | J8: 0 | K8: 1800 | L8: 1260 | M8: 스토리위즈 | N8: 권용찬
A9: 신마협도 5 | B9: 권용찬 | C9: 스토리위즈 | D9: B2C | E9: 대여제 | H9: 1800 | J9: 0 | K9: 1800 | L9: 1260 | M9: 스토리위즈 | N9: 권용찬
A10: 신마협도 6 | B10: 권용찬 | C10: 스토리위즈 | D10: B2C | E10: 대여제 | H10: 900 | J10: 0 | K10: 900 | L10: 630 | M10: 스토리위즈 | N10: 권용찬
A11: 신마협도 7 | B11: 권용찬 | C11: 스토리위즈 | D11: B2C | E11: 대여제 | H11: 900 | J11: 0 | K11: 900 | L11: 630 | M11: 스토리위즈 | N11: 권용찬
A12: 신마협도 8 | B12: 권용찬 | C12: 스토리위즈 | D12: B2C | E12: 대여제 | H12: 900 | J12: 0 | K12: 900 | L12: 630 | M12: 스토리위즈 | N12: 권용찬
A13: 신마협도 9 | B13: 권용찬 | C13: 스토리위즈 | D13: B2C | E13: 대여제 | H13: 900 | J13: 0 | K13: 900 | L13: 630 | M13: 스토리위즈 | N13: 권용찬
A14: 용무쌍 2 | B14: 권용찬 | C14: 스토리위즈 | D14: B2C | E14: 대여제 | H14: 2700 | J14: 0 | K14: 2700 | L14: 1890 | M14: 스토리위즈 | N14: 권용찬
... A23: 용중신권 7 (완결) | B23: 권용찬 | C23: 스토리위즈 | D23: B2C | E23: 대여제 | H23: 900 | J23: 0 | K23: 900 | L23: 630 | M23: 스토리위즈 | N23: 권용찬

Sheet 예로나
A1: 제목 | B1: 저자 | C1: 출판권자 | D1: 판매처 | E1: 판매유형 | F1: 부수 | G1: 정가 | H1: 판매액 | I1: 할인 | J1: 수수료 | K1: 정산대상금액 | L1: 정산액 | M1: 출판사 | N1: 작가 CP
A2: 기사가문 망나니는 10클래스 | B2: 예로나 | C2: 스토리위즈 | D2: B2C | E2: 프리미엄 | F2: 7 | G2: 100 | H2: 700 | I2: 0 | J2: 0 | K2: 700 | L2: 490 | M2: 스토리위즈 | N2: 예로나

Sheet 단팥크림빵7
A1: 제목 | B1: 저자 | C1: 출판권자 | D1: 판매처 | E1: 판매유형 | F1: 부수 | G1: 정가 | H1: 판매액 | I1: 할인 | J1: 수수료 | K1: 정산대상금액 | L1: 정산액 | M1: 출판사 | N1: 작가 CP
A2: 낚싯대 하나로 세계최강 2 | B2: 단팥크림빵7 | C2: 스토리위즈 | D2: B2B | E2: 마산대학교 | F2: 1 | G2: 3200 | H2: 3200 | I2: 0 | J2: 0 | K2: 3200 | L2: 1600 | M2: 스토리위즈 | N2: 단팥크림빵7
A3: 낚싯대 하나로 세계최강 2 | B3: 단팥크림빵7 | C3: 스토리위즈 | D3: B2B | E3: 경남정보대학교 | F3: 1 | G3: 3200 | H3: 3200 | I3: 0 | J3: 0 | K3: 3200 | L3: 1600 | M3: 스토리위즈 | N3: 단팥크림빵7
A4: 낚싯대 하나로 세계최강 3 | B4: 단팥크림빵7 | C4: 스토리위즈 | D4: B2B | E4: 마산대학교 | F4: 1 | G4: 3200 | H4: 3200 | I4: 0 | J4: 0 | K4: 3200 | L4: 1600 | M4: 스토리위즈 | N4: 단팥크림빵7
A5: 낚싯대 하나로 세계최강 3 | B5: 단팥크림빵7 | C5: 스토리위즈 | D5: B2B | E5: 경남정보대학교 | F5: 1 | G5: 3200 | H5: 3200 | I5: 0 | J5: 0 | K5: 3200 | L5: 1600 | M5: 스토리위즈 | N5: 단팥크림빵7
A6: 낚싯대 하나로 세계최강 4 | B6: 단팥크림빵7 | C6: 스토리위즈 | D6: B2B | E6: 경남정보대학교 | F6: 1 | G6: 3200 | H6: 3200 | I6: 0 | J6: 0 | K6: 3200 | L6: 1600 | M6: 스토리위즈 | N6: 단팥크림빵7
A7: 낚싯대 하나로 세계최강 4 | B7: 단팥크림빵7 | C7: 스토리위즈 | D7: B2B | E7: 마산대학교 | F7: 1 | G7: 3200 | H7: 3200 | I7: 0 | J7: 0 | K7: 3200 | L7: 1600 | M7: 스토리위즈 | N7: 단팥크림빵7
A8: 낚싯대 하나로 세계최강 5 | B8: 단팥크림빵7 | C8: 스토리위즈 | D8: B2B | E8: 마산대학교 | F8: 1 | G8: 3200 | H8: 3200 | I8: 0 | J8: 0 | K8: 3200 | L8: 1600 | M8: 스토리위즈 | N8: 단팥크림빵7
A9: 낚싯대 하나로 세계최강 5 | B9: 단팥크림빵7 | C9: 스토리위즈 | D9: B2B | E9: 경남정보대학교 | F9: 1 | G9: 3200 | H9: 3200 | I9: 0 | J9: 0 | K9: 3200 | L9: 1600 | M9: 스토리위즈 | N9: 단팥크림빵7
A10: 낚싯대 하나로 세계최강 6 (완결) | B10: 단팥크림빵7 | C10: 스토리위즈 | D10: B2B | E10: 경남정보대학교 | F10: 1 | G10: 3200 | H10: 3200 | I10: 0 | J10: 0 | K10: 3200 | L10: 1600 | M10: 스토리위즈 | N10: 단팥크림빵7
A11: 낚싯대 하나로 세계최강 6 (완결) | B11: 단팥크림빵7 | C11: 스토리위즈 | D11: B2B | E11: 마산대학교 | F11: 1 | G11: 3200 | H11: 3200 | I11: 0 | J11: 0 | K11: 3200 | L11: 1600 | M11: 스토리위즈 | N11: 단팥크림빵7

Sheet 김정률
A1: 제목 | B1: 저자 | C1: 출판권자 | D1: 판매처 | E1: 판매유형 | F1: 부수 | G1: 정가 | H1: 판매액 | I1: 할인 | J1: 수수료 | K1: 정산대상금액 | L1: 정산액 | M1: 출판사 | N1: 작가 CP
A2: 다크메이지 3부 - 마왕 데이몬 | B2: 김정률 | C2: 스토리위즈 | D2: B2C | E2: 프리미엄 | F2: 14 | G2: 100 | H2: 1400 | I2: 0 | J2: 0 | K2: 1400 | L2: 980 | M2: 스토리위즈 | N2: 김정률
A3: [시리즈]마왕 데이몬 2 | B3: 김정률 | C3: 스토리위즈 | D3: B2C | E3: 단권 | F3: 1 | G3: 3200 | H3: 3200 | I3: 0 | J3: 0 | K3: 3200 | L3: 2240 | M3: 스토리위즈 | N3: 김정률
A4: [시리즈]마왕 데이몬 3 | B4: 김정률 | C4: 스토리위즈 | D4: B2C | E4: 단권 | F4: 1 | G4: 3200 | H4: 3200 | I4: 0 | J4: 0 | K4: 3200 | L4: 2240 | M4: 스토리위즈 | N4: 김정률
A5: [시리즈]마왕 데이몬 4 | B5: 김정률 | C5: 스토리위즈 | D5: B2C | E5: 단권 | F5: 1 | G5: 3200 | H5: 3200 | I5: 0 | J5: 0 | K5: 3200 | L5: 2240 | M5: 스토리위즈 | N5: 김정률
A6: [시리즈]마왕 데이몬 5 | B6: 김정률 | C6: 스토리위즈 | D6: B2C | E6: 단권 | F6: 1 | G6: 3200 | H6: 3200 | I6: 0 | J6: 0 | K6: 3200 | L6: 2240 | M6: 스토리위즈 | N6: 김정률
A7: [시리즈]마왕 데이몬 6 | B7: 김정률 | C7: 스토리위즈 | D7: B2C | E7: 단권 | F7: 1 | G7: 3200 | H7: 3200 | I7: 0 | J7: 0 | K7: 3200 | L7: 2240 | M7: 스토리위즈 | N7: 김정률
A8: [시리즈]마왕 데이몬 7 | B8: 김정률 | C8: 스토리위즈 | D8: B2C | E8: 단권 | F8: 1 | G8: 3200 | H8: 3200 | I8: 0 | J8: 0 | K8: 3200 | L8: 2240 | M8: 스토리위즈 | N8: 김정률
A9: [시리즈]마왕 데이몬 8 | B9: 김정률 | C9: 스토리위즈 | D9: B2C | E9: 단권 | F9: 1 | G9: 3200 | H9: 3200 | I9: 0 | J9: 0 | K9: 3200 | L9: 2240 | M9: 스토리위즈 | N9: 김정률
A10: [시리즈]마왕 데이몬 9 | B10: 김정률 | C10: 스토리위즈 | D10: B2C | E10: 단권 | F10: 1 | G10: 3200 | H10: 3200 | I10: 0 | J10: 0 | K10: 3200 | L10: 2240 | M10: 스토리위즈 | N10: 김정률
A11: [시리즈]마왕 데이몬 10 | B11: 김정률 | C11: 스토리위즈 | D11: B2C | E11: 단권 | F11: 1 | G11: 3200 | H11: 3200 | I11: 0 | J11: 0 | K11: 3200 | L11: 2240 | M11: 스토리위즈 | N11: 김정률
A12: [시리즈]마왕 데이몬 11 | B12: 김정률 | C12: 스토리위즈 | D12: B2C | E12: 단권 | F12: 1 | G12: 3200 | H12: 3200 | I12: 0 | J12: 0 | K12: 3200 | L12: 2240 | M12: 스토리위즈 | N12: 김정률
A13: [시리즈]마왕 데이몬 12 (완결) | B13: 김정률 | C13: 스토리위즈 | D13: B2C | E13: 단권 | F13: 1 | G13: 3200 | H13: 3200 | I13: 0 | J13: 0 | K13: 3200 | L13: 2240 | M13: 스토리위즈 | N13: 김정률
A14: 소드 엠페러 2 | B14: 김정률 | C14: 스토리위즈 | D14: B2C | E14: 단권 | F14: 1 | G14: 3200 | H14: 3200 | I14: 0 | J14: 0 | K14: 3200 | L14: 2240 | M14: 스토리위즈 | N14: 김정률
A15: 소드 엠페러 2 | B15: 김정률 | C15: 스토리위즈 | D15: B2C | E15: 대여제 | H15: 3600 | J15: 0 | K15: 3600 | L15: 2520 | M15: 스토리위즈 | N15: 김정률
A16: [시리즈]소드 엠페러 2 | B16: 김정률 | C16: 스토리위즈 | D16: B2C | E16: 대여제 | H16: 3690 | J16: 0 | K16: 3690 | L16: 2583 | M16: 스토리위즈 | N16: 김정률
A17: 소드 엠페러 3 | B17: 김정률 | C17: 스토리위즈 | D17: B2C | E17: 대여제 | H17: 1800 | J17: 0 | K17: 1800 | L17: 1260 | M17: 스토리위즈 | N17: 김정률
A18: [시리즈]소드 엠페러 3 | B18: 김정률 | C18: 스토리위즈 | D18: B2C | E18: 대여제 | H18: 3690 | J18: 0 | K18: 3690 | L18: 2583 | M18: 스토리위즈 | N18: 김정률
A19: [시리즈]소드 엠페러 4 | B19: 김정률 | C19: 스토리위즈 | D19: B2C | E19: 대여제 | H19: 3690 | J19: 0 | K19: 3690 | L19: 2583 | M19: 스토리위즈 | N19: 김정률
A20: [시리즈]소드 엠페러 5 | B20: 김정률 | C20: 스토리위즈 | D20: B2C | E20: 대여제 | H20: 3690 | J20: 0 | K20: 3690 | L20: 2583 | M20: 스토리위즈 | N20: 김정률
A21: [시리즈]소드 엠페러 6 | B21: 김정률 | C21: 스토리위즈 | D21: B2C | E21: 대여제 | H21: 3690 | J21: 0 | K21: 3690 | L21: 2583 | M21: 스토리위즈 | N21: 김정률
A22: [시리즈]소드 엠페러 7 | B22: 김정률 | C22: 스토리위즈 | D22: B2C | E22: 대여제 | H22: 3690 | J22: 0 | K22: 3690 | L22: 2583 | M22: 스토리위즈 | N22: 김정률
A23: [시리즈]소드 엠페러 8 | B23: 김정률 | C23: 스토리위즈 | D23: B2C | E23: 대여제 | H23: 3690 | J23: 0 | K23: 3690 | L23: 2583 | M23: 스토리위즈 | N23: 김정률
A24: [시리즈]소드 엠페러 9 | B24: 김정률 | C24: 스토리위즈 | D24: B2C | E24: 대여제 | H24: 3690 | J24: 0 | K24: 3690 | L24: 2583 | M24: 스토리위즈 | N24: 김정률
A25: [시리즈]소드 엠페러 10 | B25: 김정률 | C25: 스토리위즈 | D25: B2C | E25: 대여제 | H25: 3690 | J25: 0 | K25: 3690 | L25: 2583 | M25: 스토리위즈 | N25: 김정률
A26: [시리즈]소드 엠페러 11 | B26: 김정률 | C26: 스토리위즈 | D26: B2C | E26: 대여제 | H26: 3690 | J26: 0 | K26: 3690 | L26: 2583 | M26: 스토리위즈 | N26: 김정률
... A40: 스피릿 소드 (완전판) 8 (완결) | B40: 김정률 | C40: 스토리위즈 | D40: B2C | E40: 대여제 | H40: 700 | J40: 0 | K40: 700 | L40: 490 | M40: 스토리위즈 | N40: 김정률
A41: 스피릿소드 | B41: 김정률 | C41: 스토리위즈 | D41: B2C | E41: 프리미엄 | F41: 5 | G41: 100 | H41: 500 | I41: 0 | J41: 0 | K41: 500 | L41: 350 | M41: 스토리위즈 | N41: 김정률
A42: 아나크레온 10 | B42: 김정률 | C42: 스토리위즈 | D42: B2C | E42: 대여제 | H42: 900 | J42: 0 | K42: 900 | L42: 630 | M42: 스토리위즈 | N42: 김정률
A43: [시리즈]아나크레온 10 | B43: 김정률 | C43: 스토리위즈 | D43: B2C | E43: 대여제 | H43: 900 | J43: 0 | K43: 900 | L43: 630 | M43: 스토리위즈 | N43: 김정률
A44: 아나크레온 11 | B44: 김정률 | C44: 스토리위즈 | D44: B2C | E44: 대여제 | H44: 900 | J44: 0 | K44: 900 | L44: 630 | M44: 스토리위즈 | N44: 김정률
A45: [시리즈]아나크레온 11 | B45: 김정률 | C45: 스토리위즈 | D45: B2C | E45: 대여제 | H45: 900 | J45: 0 | K45: 900 | L45: 630 | M45: 스토리위즈 | N45: 김정률
A46: 아나크레온 12 | B46: 김정률 | C46: 스토리위즈 | D46: B2C | E46: 대여제 | H46: 900 | J46: 0 | K46: 900 | L46: 630 | M46: 스토리위즈 | N46: 김정률
A47: [시리즈]아나크레온 12 | B47: 김정률 | C47: 스토리위즈 | D47: B2C | E47: 대여제 | H47: 900 | J47: 0 | K47: 900 | L47: 630 | M47: 스토리위즈 | N47: 김정률
A48: 아나크레온 13 | B48: 김정률 | C48: 스토리위즈 | D48: B2C | E48: 대여제 | H48: 900 | J48: 0 | K48: 900 | L48: 630 | M48: 스토리위즈 | N48: 김정률
A49: [시리즈]아나크레온 13 | B49: 김정률 | C49: 스토리위즈 | D49: B2C | E49: 대여제 | H49: 900 | J49: 0 | K49: 900 | L49: 630 | M49: 스토리위즈 | N49: 김정률
A50: 아나크레온 14 | B50: 김정률 | C50: 스토리위즈 | D50: B2C | E50: 대여제 | H50: 900 | J50: 0 | K50: 900 | L50: 630 | M50: 스토리위즈 | N50: 김정률
A51: [시리즈]아나크레온 14 | B51: 김정률 | C51: 스토리위즈 | D51: B2C | E51: 대여제 | H51: 900 | J51: 0 | K51: 900 | L51: 630 | M51: 스토리위즈 | N51: 김정률
A52: 아나크레온 15 | B52: 김정률 | C52: 스토리위즈 | D52: B2C | E52: 대여제 | H52: 900 | J52: 0 | K52: 900 | L52: 630 | M52: 스토리위즈 | N52: 김정률
A53: [시리즈]아나크레온 15 | B53: 김정률 | C53: 스토리위즈 | D53: B2C | E53: 대여제 | H53: 900 | J53: 0 | K53: 900 | L53: 630 | M53: 스토리위즈 | N53: 김정률
...

Sheet 전혁
A1: 제목 | B1: 저자 | C1: 출판권자 | D1: 판매처 | E1: 판매유형 | F1: 부수 | G1: 정가 | H1: 판매액 | I1: 할인 | J1: 수수료 | K1: 정산대상금액 | L1: 정산액 | M1: 출판사 | N1: 작가 CP
A2: 레이드 만물상점 | B2: 전혁 | C2: 스토리위즈 | D2: B2C | E2: 프리미엄 | F2: 3 | G2: 100 | H2: 300 | I2: 0 | J2: 0 | K2: 300 | L2: 210 | M2: 스토리위즈 | N2: 전혁
A3: [시리즈]절대비만 2 | B3: 전혁 | C3: 스토리위즈 | D3: B2C | E3: 대여제 | H3: 900 | J3: 0 | K3: 900 | L3: 630 | M3: 스토리위즈 | N3: 전혁
A4: [시리즈]절대비만 3 | B4: 전혁 | C4: 스토리위즈 | D4: B2C | E4: 대여제 | H4: 900 | J4: 0 | K4: 900 | L4: 630 | M4: 스토리위즈 | N4: 전혁
A5: [시리즈]절대비만 4 | B5: 전혁 | C5: 스토리위즈 | D5: B2C | E5: 대여제 | H5: 900 | J5: 0 | K5: 900 | L5: 630 | M5: 스토리위즈 | N5: 전혁
A6: [시리즈]절대비만 5 | B6: 전혁 | C6: 스토리위즈 | D6: B2C | E6: 대여제 | H6: 900 | J6: 0 | K6: 900 | L6: 630 | M6: 스토리위즈 | N6: 전혁
A7: [시리즈]절대비만 6 | B7: 전혁 | C7: 스토리위즈 | D7: B2C | E7: 대여제 | H7: 900 | J7: 0 | K7: 900 | L7: 630 | M7: 스토리위즈 | N7: 전혁
A8: [시리즈]절대비만 7 | B8: 전혁 | C8: 스토리위즈 | D8: B2C | E8: 대여제 | H8: 900 | J8: 0 | K8: 900 | L8: 630 | M8: 스토리위즈 | N8: 전혁
A9: [시리즈]절대비만 8 (완결) | B9: 전혁 | C9: 스토리위즈 | D9: B2C | E9: 대여제 | H9: 900 | J9: 0 | K9: 900 | L9: 630 | M9: 스토리위즈 | N9: 전혁
A10: 절륜공자 10 (완결) | B10: 전혁 | C10: 스토리위즈 | D10: B2C | E10: 대여제 | H10: 900 | J10: 0 | K10: 900 | L10: 630 | M10: 스토리위즈 | N10: 전혁
A11: 절륜공자 2 | B11: 전혁 | C11: 스토리위즈 | D11: B2C | E11: 대여제 | H11: 1800 | J11: 0 | K11: 1800 | L11: 1260 | M11: 스토리위즈 | N11: 전혁
A12: 절륜공자 3 | B12: 전혁 | C12: 스토리위즈 | D12: B2C | E12: 대여제 | H12: 1800 | J12: 0 | K12: 1800 | L12: 1260 | M12: 스토리위즈 | N12: 전혁
A13: 절륜공자 4 | B13: 전혁 | C13: 스토리위즈 | D13: B2C | E13: 대여제 | H13: 1800 | J13: 0 | K13: 1800 | L13: 1260 | M13: 스토리위즈 | N13: 전혁
A14: 절륜공자 5 | B14: 전혁 | C14: 스토리위즈 | D14: B2C | E14: 대여제 | H14: 1800 | J14: 0 | K14: 1800 | L14: 1260 | M14: 스토리위즈 | N14: 전혁
... A18: 절륜공자 9 | B18: 전혁 | C18: 스토리위즈 | D18: B2C | E18: 대여제 | H18: 900 | J18: 0 | K18: 900 | L18: 630 | M18: 스토리위즈 | N18: 전혁

Sheet 덕킹
A1: 제목 | B1: 저자 | C1: 출판권자 | D1: 판매처 | E1: 판매유형 | F1: 부수 | G1: 정가 | H1: 판매액 | I1: 할인 | J1: 수수료 | K1: 정산대상금액 | L1: 정산액 | M1: 출판사 | N1: 작가 CP
A2: 망작 리메이커 2 | B2: 덕킹 | C2: 스토리위즈 | D2: B2B | E2: 백석대학교 | F2: 1 | G2: 3200 | H2: 3200 | I2: 0 | J2: 0 | K2: 3200 | L2: 1600 | M2: 스토리위즈 | N2: 덕킹
A3: 망작 리메이커 3 | B3: 덕킹 | C3: 스토리위즈 | D3: B2B | E3: 백석대학교 | F3: 1 | G3: 3200 | H3: 3200 | I3: 0 | J3: 0 | K3: 3200 | L3: 1600 | M3: 스토리위즈 | N3: 덕킹
A4: 망작 리메이커 4 | B4: 덕킹 | C4: 스토리위즈 | D4: B2B | E4: 백석대학교 | F4: 1 | G4: 3200 | H4: 3200 | I4: 0 | J4: 0 | K4: 3200 | L4: 1600 | M4: 스토리위즈 | N4: 덕킹
A5: 망작 리메이커 5 | B5: 덕킹 | C5: 스토리위즈 | D5: B2B | E5: 백석대학교 | F5: 1 | G5: 3200 | H5: 3200 | I5: 0 | J5: 0 | K5: 3200 | L5: 1600 | M5: 스토리위즈 | N5: 덕킹
A6: 망작 리메이커 6 | B6: 덕킹 | C6: 스토리위즈 | D6: B2B | E6: 백석대학교 | F6: 1 | G6: 3200 | H6: 3200 | I6: 0 | J6: 0 | K6: 3200 | L6: 1600 | M6: 스토리위즈 | N6: 덕킹
A7: 망작 리메이커 7 | B7: 덕킹 | C7: 스토리위즈 | D7: B2B | E7: 백석대학교 | F7: 1 | G7: 3200 | H7: 3200 | I7: 0 | J7: 0 | K7: 3200 | L7: 1600 | M7: 스토리위즈 | N7: 덕킹
A8: 망작 리메이커 8 | B8: 덕킹 | C8: 스토리위즈 | D8: B2B | E8: 백석대학교 | F8: 1 | G8: 3200 | H8: 3200 | I8: 0 | J8: 0 | K8: 3200 | L8: 1600 | M8: 스토리위즈 | N8: 덕킹
A9: 망작 리메이커 9 (완결) | B9: 덕킹 | C9: 스토리위즈 | D9: B2B | E9: 백석대학교 | F9: 1 | G9: 3200 | H9: 3200 | I9: 0 | J9: 0 | K9: 3200 | L9: 1600 | M9: 스토리위즈 | N9: 덕킹

Sheet 독고진
A1: 제목 | B1: 저자 | C1: 출판권자 | D1: 판매처 | E1: 판매유형 | F1: 부수 | G1: 정가 | H1: 판매액 | I1: 할인 | J1: 수수료 | K1: 정산대상금액 | L1: 정산액 | M1: 출판사 | N1: 작가 CP
A2: 소천무쌍 10 | B2: 가람검 | C2: 스토리위즈 | D2: B2C | E2: 대여제 | H2: 1800 | J2: 0 | K2: 1800 | L2: 1260 | M2: 스토리위즈 | N2: 독고진
A3: 소천무쌍 11 | B3: 가람검 | C3: 스토리위즈 | D3: B2C | E3: 대여제 | H3: 1800 | J3: 0 | K3: 1800 | L3: 1260 | M3: 스토리위즈 | N3: 독고진
A4: 소천무쌍 12 (완결) | B4: 가람검 | C4: 스토리위즈 | D4: B2C | E4: 대여제 | H4: 1800 | J4: 0 | K4: 1800 | L4: 1260 | M4: 스토리위즈 | N4: 독고진
A5: 소천무쌍 2 | B5: 가람검 | C5: 스토리위즈 | D5: B2C | E5: 대여제 | H5: 500 | J5: 0 | K5: 500 | L5: 350 | M5: 스토리위즈 | N5: 독고진
A6: 소천무쌍 2 | B6: 가람검 | C6: 스토리위즈 | D6: B2C | E6: 대여제 | H6: 1800 | J6: 0 | K6: 1800 | L6: 1260 | M6: 스토리위즈 | N6: 독고진
A7: 소천무쌍 3 | B7: 가람검 | C7: 스토리위즈 | D7: B2C | E7: 대여제 | H7: 500 | J7: 0 | K7: 500 | L7: 350 | M7: 스토리위즈 | N7: 독고진
A8: 소천무쌍 3 | B8: 가람검 | C8: 스토리위즈 | D8: B2C | E8: 대여제 | H8: 1800 | J8: 0 | K8: 1800 | L8: 1260 | M8: 스토리위즈 | N8: 독고진
A9: 소천무쌍 4 | B9: 가람검 | C9: 스토리위즈 | D9: B2C | E9: 대여제 | H9: 500 | J9: 0 | K9: 500 | L9: 350 | M9: 스토리위즈 | N9: 독고진
A10: 소천무쌍 4 | B10: 가람검 | C10: 스토리위즈 | D10: B2C | E10: 대여제 | H10: 1800 | J10: 0 | K10: 1800 | L10: 1260 | M10: 스토리위즈 | N10: 독고진
A11: 소천무쌍 5 | B11: 가람검 | C11: 스토리위즈 | D11: B2C | E11: 대여제 | H11: 500 | J11: 0 | K11: 500 | L11: 350 | M11: 스토리위즈 | N11: 독고진
A12: 소천무쌍 5 | B12: 가람검 | C12: 스토리위즈 | D12: B2C | E12: 대여제 | H12: 900 | J12: 0 | K12: 900 | L12: 630 | M12: 스토리위즈 | N12: 독고진
A13: 소천무쌍 6 | B13: 가람검 | C13: 스토리위즈 | D13: B2C | E13: 대여제 | H13: 500 | J13: 0 | K13: 500 | L13: 350 | M13: 스토리위즈 | N13: 독고진
... A19: 소천무쌍 9 | B19: 가람검 | C19: 스토리위즈 | D19: B2C | E19: 대여제 | H19: 1800 | J19: 0 | K19: 1800 | L19: 1260 | M19: 스토리위즈 | N19: 독고진
A20: 스트라이커 | B20: 독고진 | C20: 스토리위즈 | D20: B2C | E20: 프리미엄 | F20: 22 | G20: 100 | H20: 2200 | I20: 0 | J20: 0 | K20: 2200 | L20: 1540 | M20: 스토리위즈 | N20: 독고진

Sheet 왕십리글쟁이
A1: 제목 | B1: 저자 | C1: 출판권자 | D1: 판매처 | E1: 판매유형 | F1: 부수 | G1: 정가 | H1: 판매액 | I1: 할인 | J1: 수수료 | K1: 정산대상금액 | L1: 정산액 | M1: 출판사 | N1: 작가 CP
A2: 슈퍼스타의 비밀어플 2 | B2: 왕십리글쟁이 | C2: 스토리위즈 | D2: B2B | E2: 경남정보대학교 | F2: 1 | G2: 3200 | H2: 3200 | I2: 0 | J2: 0 | K2: 3200 | L2: 1600 | M2: 스토리위즈 | N2: 왕십리글쟁이
A3: 슈퍼스타의 비밀어플 3 | B3: 왕십리글쟁이 | C3: 스토리위즈 | D3: B2B | E3: 경남정보대학교 | F3: 1 | G3: 3200 | H3: 3200 | I3: 0 | J3: 0 | K3: 3200 | L3: 1600 | M3: 스토리위즈 | N3: 왕십리글쟁이
A4: 슈퍼스타의 비밀어플 4 | B4: 왕십리글쟁이 | C4: 스토리위즈 | D4: B2B | E4: 경남정보대학교 | F4: 1 | G4: 3200 | H4: 3200 | I4: 0 | J4: 0 | K4: 3200 | L4: 1600 | M4: 스토리위즈 | N4: 왕십리글쟁이
A5: 슈퍼스타의 비밀어플 5 | B5: 왕십리글쟁이 | C5: 스토리위즈 | D5: B2B | E5: 경남정보대학교 | F5: 1 | G5: 3200 | H5: 3200 | I5: 0 | J5: 0 | K5: 3200 | L5: 1600 | M5: 스토리위즈 | N5: 왕십리글쟁이
A6: 슈퍼스타의 비밀어플 6 (완결) | B6: 왕십리글쟁이 | C6: 스토리위즈 | D6: B2B | E6: 경남정보대학교 | F6: 1 | G6: 3200 | H6: 3200 | I6: 0 | J6: 0 | K6: 3200 | L6: 1600 | M6: 스토리위즈 | N6: 왕십리글쟁이

Sheet 갓띵작
A1: 제목 | B1: 저자 | C1: 출판권자 | D1: 판매처 | E1: 판매유형 | F1: 부수 | G1: 정가 | H1: 판매액 | I1: 할인 | J1: 수수료 | K1: 정산대상금액 | L1: 정산액 | M1: 출판사 | N1: 작가 CP
A2: 신들의 알바나라 | B2: 갓띵작 | C2: 스토리위즈 | D2: B2C | E2: 프리미엄 | F2: 176 | G2: 100 | H2: 17600 | I2: 0 | J2: 0 | K2: 17600 | L2: 12320 | M2: 스토리위즈 | N2: 갓띵작

Sheet 바나바다
A1: 제목 | B1: 저자 | C1: 출판권자 | D1: 판매처 | E1: 판매유형 | F1: 부수 | G1: 정가 | H1: 판매액 | I1: 할인 | J1: 수수료 | K1: 정산대상금액 | L1: 정산액 | M1: 출판사 | N1: 작가 CP
A2: 위대한 가문의 망나니가 되다 | B2: 바나바다 | C2: 스토리위즈 | D2: B2C | E2: 프리미엄 | F2: 267 | G2: 100 | H2: 26700 | I2: 0 | J2: 0 | K2: 26700 | L2: 18690 | M2: 스토리위즈 | N2: 바나바다

Sheet 서강후
A1: 제목 | B1: 저자 | C1: 출판권자 | D1: 판매처 | E1: 판매유형 | F1: 부수 | G1: 정가 | H1: 판매액 | I1: 할인 | J1: 수수료 | K1: 정산대상금액 | L1: 정산액 | M1: 출판사 | N1: 작가 CP
A2: 칵테일로 레벨업 2 | B2: 서강후 | C2: 스토리위즈 | D2: B2C | E2: 대여제 | H2: 3600 | J2: 0 | K2: 3600 | L2: 2520 | M2: 스토리위즈 | N2: 서강후
A3: 칵테일로 레벨업 3 | B3: 서강후 | C3: 스토리위즈 | D3: B2C | E3: 대여제 | H3: 900 | J3: 0 | K3: 900 | L3: 630 | M3: 스토리위즈 | N3: 서강후
A4: 칵테일로 레벨업 4 | B4: 서강후 | C4: 스토리위즈 | D4: B2C | E4: 대여제 | H4: 900 | J4: 0 | K4: 900 | L4: 630 | M4: 스토리위즈 | N4: 서강후

Sheet 구공
A1: 제목 | B1: 저자 | C1: 출판권자 | D1: 판매처 | E1: 판매유형 | F1: 부수 | G1: 정가 | H1: 판매액 | I1: 할인 | J1: 수수료 | K1: 정산대상금액 | L1: 정산액 | M1: 출판사 | N1: 작가 CP
A2: 회귀자의 슬기로운 복수생활 | B2: 구공 | C2: 스토리위즈 | D2: B2C | E2: 프리미엄 | F2: 573 | G2: 100 | H2: 57300 | I2: 0 | J2: 0 | K2: 57300 | L2: 40110 | M2: 스토리위즈 | N2: 구공

Sheet 구유
A1: 제목 | B1: 저자 | C1: 출판권자 | D1: 판매처 | E1: 판매유형 | F1: 부수 | G1: 정가 | H1: 판매액 | I1: 할인 | J1: 수수료 | K1: 정산대상금액 | L1: 정산액 | M1: 출판사 | N1: 작가 CP
A2: SSS급 마왕의 귀환 2 | B2: 구유 | C2: 스토리위즈 | D2: B2C | E2: 단권 | F2: 1 | G2: 3200 | H2: 3200 | I2: 0 | J2: 0 | K2: 3200 | L2: 2240 | M2: 스토리위즈 | N2: 구유

Sheet 제외
A1: 제목 | B1: 저자 | C1: 출판권자 | D1: 판매처 | E1: 판매유형 | F1: 부수 | G1: 정가 | H1: 판매액 | I1: 할인 | J1: 수수료 | K1: 정산대상금액 | L1: 정산액 | M1: 출판사 | N1: 작가 CP
A2: [시리즈]2위의 역습 | B2: 羽宸?(Uchenhu), 林?瑜(Lin Peiyu) | C2: 도서출판 태랑 | D2: B2C | E2: 단권 | F2: 13 | G2: 3200 | H2: 37440 | I2: 4160 | J2: 0 | K2: 37440 | L2: 26208 | M2: 스토리위즈 | N2: 제외
A3: [시리즈]영원한 1위 | B3: 羽宸?(Uchenhu), 林?瑜(Lin Peiyu) | C3: 도서출판 태랑 | D3: B2C | E3: 단권 | F3: 8 | G3: 3000 | H3: 22200 | I3: 1800 | J3: 0 | K3: 22200 | L3: 15540 | M3: 스토리위즈 | N3: 제외

Sheet 모리미
A1: 제목 | B1: 저자 | C1: 출판권자 | D1: 판매처 | E1: 판매유형 | F1: 부수 | G1: 정가 | H1: 판매액 | I1: 할인 | J1: 수수료 | K1: 정산대상금액 | L1: 정산액 | M1: 출판사 | N1: 작가 CP
A2: [시리즈]골 때리는 사랑 (외전증보판) (외전) | B2: 모리미 | C2: 도서출판 태랑 | D2: B2C | E2: 단권 | F2: 1 | G2: 500 | H2: 500 | I2: 0 | J2: 0 | K2: 500 | L2: 350 | M2: 스토리위즈 | N2: 모리미
A3: 골 때리는 사랑 (외전증보판) 1 | B3: 모리미 | C3: 도서출판 태랑 | D3: B2C | E3: 단권 | F3: 1 | G3: 2800 | H3: 2800 | I3: 0 | J3: 0 | K3: 2800 | L3: 1960 | M3: 스토리위즈 | N3: 모리미
A4: [시리즈]골 때리는 사랑 (외전증보판) 1 | B4: 모리미 | C4: 도서출판 태랑 | D4: B2C | E4: 단권 | F4: 1 | G4: 2800 | H4: 2800 | I4: 0 | J4: 0 | K4: 2800 | L4: 1960 | M4: 스토리위즈 | N4: 모리미
A5: [시리즈]골 때리는 사랑 (외전증보판) 2 (완결) | B5: 모리미 | C5: 도서출판 태랑 | D5: B2C | E5: 단권 | F5: 1 | G5: 2800 | H5: 2800 | I5: 0 | J5: 0 | K5: 2800 | L5: 1960 | M5: 스토리위즈 | N5: 모리미
A6: [시리즈]선택된 남자 (외전) | B6: 모리미 | C6: 도서출판 태랑 | D6: B2C | E6: 단권 | F6: 2 | G6: 300 | H6: 600 | I6: 0 | J6: 0 | K6: 600 | L6: 420 | M6: 스토리위즈 | N6: 모리미
A7: [시리즈]선택된 남자 1 | B7: 모리미 | C7: 도서출판 태랑 | D7: B2C | E7: 단권 | F7: 2 | G7: 2400 | H7: 4800 | I7: 0 | J7: 0 | K7: 4800 | L7: 3360 | M7: 스토리위즈 | N7: 모리미
A8: [시리즈]선택된 남자 2 (완결) | B8: 모리미 | C8: 도서출판 태랑 | D8: B2C | E8: 단권 | F8: 2 | G8: 2400 | H8: 4800 | I8: 0 | J8: 0 | K8: 4800 | L8: 3360 | M8: 스토리위즈 | N8: 모리미
A9: 야쿠자가 사랑을 한다면 (개정판) (외전) | B9: 모리미 | C9: 도서출판 태랑 | D9: B2C | E9: 단권 | F9: 1 | G9: 400 | H9: 400 | I9: 0 | J9: 0 | K9: 400 | L9: 280 | M9: 스토리위즈 | N9: 모리미
A10: [시리즈]야쿠자가 사랑을 한다면 (개정판) (외전) | B10: 모리미 | C10: 도서출판 태랑 | D10: B2C | E10: 단권 | F10: 1 | G10: 400 | H10: 400 | I10: 0 | J10: 0 | K10: 400 | L10: 280 | M10: 스토리위즈 | N10: 모리미
A11: [시리즈]야쿠자가 사랑을 한다면 (개정판) 1 | B11: 모리미 | C11: 도서출판 태랑 | D11: B2C | E11: 단권 | F11: 1 | G11: 3200 | H11: 3200 | I11: 0 | J11: 0 | K11: 3200 | L11: 2240 | M11: 스토리위즈 | N11: 모리미
A12: 야쿠자가 사랑을 한다면 (개정판) 2 (완결) | B12: 모리미 | C12: 도서출판 태랑 | D12: B2C | E12: 단권 | F12: 1 | G12: 3200 | H12: 3200 | I12: 0 | J12: 0 | K12: 3200 | L12: 2240 | M12: 스토리위즈 | N12: 모리미
A13: [시리즈]야쿠자가 사랑을 한다면 (개정판) 2 (완결) | B13: 모리미 | C13: 도서출판 태랑 | D13: B2C | E13: 단권 | F13: 1 | G13: 3200 | H13: 3200 | I13: 0 | J13: 0 | K13: 3200 | L13: 2240 | M13: 스토리위즈 | N13: 모리미
... A17: [시리즈]야쿠자가 사랑을 한다면 2 (개정판) 2 (완결) | B17: 모리미 | C17: 도서출판 태랑 | D17: B2C | E17: 단권 | F17: 1 | G17: 3000 | H17: 3000 | I17: 0 | J17: 0 | K17: 3000 | L17: 2100 | M17: 스토리위즈 | N17: 모리미

Sheet 주이서
A1: 제목 | B1: 저자 | C1: 출판권자 | D1: 판매처 | E1: 판매유형 | F1: 부수 | G1: 정가 | H1: 판매액 | I1: 할인 | J1: 수수료 | K1: 정산대상금액 | L1: 정산액 | M1: 출판사 | N1: 작가 CP
A2: 그 알파 내 오메가 만들기 | B2: 주이서 | C2: 도서출판 태랑 | D2: B2C | E2: 단권 | F2: 1 | G2: 4400 | H2: 4400 | I2: 0 | J2: 0 | K2: 4400 | L2: 3080 | M2: 스토리위즈 | N2: 주이서
A3: 그 알파 내 오메가 만들기 (외전) | B3: 주이서 | C3: 도서출판 태랑 | D3: B2C | E3: 단권 | F3: 1 | G3: 500 | H3: 500 | I3: 0 | J3: 0 | K3: 500 | L3: 350 | M3: 스토리위즈 | N3: 주이서

Sheet 차홍주
A1: 제목 | B1: 저자 | C1: 출판권자 | D1: 판매처 | E1: 판매유형 | F1: 부수 | G1: 정가 | H1: 판매액 | I1: 할인 | J1: 수수료 | K1: 정산대상금액 | L1: 정산액 | M1: 출판사 | N1: 작가 CP
A2: [시리즈]기어이 사랑 (외전) | B2: 차홍주 | C2: 도서출판 태랑 | D2: B2C | E2: 단권 | F2: 1 | G2: 300 | H2: 300 | I2: 0 | J2: 0 | K2: 300 | L2: 210 | M2: 스토리위즈 | N2: 차홍주
A3: [시리즈]기어이 사랑 1 | B3: 차홍주 | C3: 도서출판 태랑 | D3: B2C | E3: 단권 | F3: 1 | G3: 3200 | H3: 3200 | I3: 0 | J3: 0 | K3: 3200 | L3: 2240 | M3: 스토리위즈 | N3: 차홍주
A4: [시리즈]기어이 사랑 2 (완결) | B4: 차홍주 | C4: 도서출판 태랑 | D4: B2C | E4: 단권 | F4: 1 | G4: 3200 | H4: 3200 | I4: 0 | J4: 0 | K4: 3200 | L4: 2240 | M4: 스토리위즈 | N4: 차홍주
A5: 사랑도 없이 결혼 (외전) | B5: 차홍주 | C5: 도서출판 태랑 | D5: B2C | E5: 단권 | F5: 1 | G5: 1000 | H5: 1000 | I5: 0 | J5: 0 | K5: 1000 | L5: 700 | M5: 스토리위즈 | N5: 차홍주
A6: 사랑도 없이 결혼 1 | B6: 차홍주 | C6: 도서출판 태랑 | D6: B2C | E6: 단권 | F6: 1 | G6: 3500 | H6: 3500 | I6: 0 | J6: 0 | K6: 3500 | L6: 2450 | M6: 스토리위즈 | N6: 차홍주
A7: 사랑도 없이 결혼 2 (완결) | B7: 차홍주 | C7: 도서출판 태랑 | D7: B2C | E7: 단권 | F7: 1 | G7: 3500 | H7: 3500 | I7: 0 | J7: 0 | K7: 3500 | L7: 2450 | M7: 스토리위즈 | N7: 차홍주
A8: [시리즈]충동적인 결혼 (외전증보판) | B8: 차홍주 | C8: 도서출판 태랑 | D8: B2C | E8: 단권 | F8: 1 | G8: 3900 | H8: 3900 | I8: 0 | J8: 0 | K8: 3900 | L8: 2730 | M8: 스토리위즈 | N8: 차홍주

Sheet 진숙
A1: 제목 | B1: 저자 | C1: 출판권자 | D1: 판매처 | E1: 판매유형 | F1: 부수 | G1: 정가 | H1: 판매액 | I1: 할인 | J1: 수수료 | K1: 정산대상금액 | L1: 정산액 | M1: 출판사 | N1: 작가 CP
A2: 나쁜 이혼 (외전) | B2: 진숙 | C2: 도서출판 태랑 | D2: B2C | E2: 단권 | F2: 1 | G2: 1100 | H2: 1100 | I2: 0 | J2: 0 | K2: 1100 | L2: 770 | M2: 스토리위즈 | N2: 진숙

Sheet 밈스
A1: 제목 | B1: 저자 | C1: 출판권자 | D1: 판매처 | E1: 판매유형 | F1: 부수 | G1: 정가 | H1: 판매액 | I1: 할인 | J1: 수수료 | K1: 정산대상금액 | L1: 정산액 | M1: 출판사 | N1: 작가 CP
A2: 내 남자 길들이기 (외전) | B2: 밈스 | C2: 도서출판 태랑 | D2: B2C | E2: 단권 | F2: 1 | G2: 1000 | H2: 1000 | I2: 0 | J2: 0 | K2: 1000 | L2: 700 | M2: 스토리위즈 | N2: 밈스
A3: [시리즈]내 남자 길들이기 (외전) | B3: 밈스 | C3: 도서출판 태랑 | D3: B2C | E3: 단권 | F3: 1 | G3: 1000 | H3: 1000 | I3: 0 | J3: 0 | K3: 1000 | L3: 700 | M3: 스토리위즈 | N3: 밈스
A4: 내 남자 길들이기 1 | B4: 밈스 | C4: 도서출판 태랑 | D4: B2C | E4: 단권 | F4: 1 | G4: 3800 | H4: 3800 | I4: 0 | J4: 0 | K4: 3800 | L4: 2660 | M4: 스토리위즈 | N4: 밈스
A5: [시리즈]내 남자 길들이기 1 | B5: 밈스 | C5: 도서출판 태랑 | D5: B2C | E5: 단권 | F5: 1 | G5: 3800 | H5: 3800 | I5: 0 | J5: 0 | K5: 3800 | L5: 2660 | M5: 스토리위즈 | N5: 밈스
A6: 내 남자 길들이기 2 (완결) | B6: 밈스 | C6: 도서출판 태랑 | D6: B2C | E6: 단권 | F6: 1 | G6: 3800 | H6: 3800 | I6: 0 | J6: 0 | K6: 3800 | L6: 2660 | M6: 스토리위즈 | N6: 밈스
A7: [시리즈]내 남자 길들이기 2 (완결) | B7: 밈스 | C7: 도서출판 태랑 | D7: B2C | E7: 단권 | F7: 1 | G7: 3800 | H7: 3800 | I7: 0 | J7: 0 | K7: 3800 | L7: 2660 | M7: 스토리위즈 | N7: 밈스

Sheet 윈델
A1: 제목 | B1: 저자 | C1: 출판권자 | D1: 판매처 | E1: 판매유형 | F1: 부수 | G1: 정가 | H1: 판매액 | I1: 할인 | J1: 수수료 | K1: 정산대상금액 | L1: 정산액 | M1: 출판사 | N1: 작가 CP
A2: 돌아온 막내 영애님을 조심하세요 (외전) | B2: 윈델 | C2: 스토리위즈 | D2: B2C | E2: 단권 | F2: 1 | G2: 1500 | H2: 1500 | I2: 0 | J2: 0 | K2: 1500 | L2: 1050 | M2: 스토리위즈 | N2: 윈델
A3: [시리즈]돌아온 막내 영애님을 조심하세요 (외전) | B3: 윈델 | C3: 스토리위즈 | D3: B2C | E3: 단권 | F3: 1 | G3: 1500 | H3: 1500 | I3: 0 | J3: 0 | K3: 1500 | L3: 1050 | M3: 스토리위즈 | N3: 윈델
A4: 돌아온 막내 영애님을 조심하세요 1 | B4: 윈델 | C4: 스토리위즈 | D4: B2C | E4: 단권 | F4: 1 | G4: 3500 | H4: 3500 | I4: 0 | J4: 0 | K4: 3500 | L4: 2450 | M4: 스토리위즈 | N4: 윈델
A5: [시리즈]돌아온 막내 영애님을 조심하세요 1 | B5: 윈델 | C5: 스토리위즈 | D5: B2C | E5: 단권 | F5: 1 | G5: 3500 | H5: 3500 | I5: 0 | J5: 0 | K5: 3500 | L5: 2450 | M5: 스토리위즈 | N5: 윈델
A6: 돌아온 막내 영애님을 조심하세요 2 | B6: 윈델 | C6: 스토리위즈 | D6: B2C | E6: 단권 | F6: 1 | G6: 3500 | H6: 3500 | I6: 0 | J6: 0 | K6: 3500 | L6: 2450 | M6: 스토리위즈 | N6: 윈델
A7: [시리즈]돌아온 막내 영애님을 조심하세요 2 | B7: 윈델 | C7: 스토리위즈 | D7: B2C | E7: 단권 | F7: 1 | G7: 3500 | H7: 3500 | I7: 0 | J7: 0 | K7: 3500 | L7: 2450 | M7: 스토리위즈 | N7: 윈델
A8: 돌아온 막내 영애님을 조심하세요 3 | B8: 윈델 | C8: 스토리위즈 | D8: B2C | E8: 단권 | F8: 1 | G8: 3500 | H8: 3500 | I8: 0 | J8: 0 | K8: 3500 | L8: 2450 | M8: 스토리위즈 | N8: 윈델
A9: [시리즈]돌아온 막내 영애님을 조심하세요 3 | B9: 윈델 | C9: 스토리위즈 | D9: B2C | E9: 단권 | F9: 1 | G9: 3500 | H9: 3500 | I9: 0 | J9: 0 | K9: 3500 | L9: 2450 | M9: 스토리위즈 | N9: 윈델
A10: 돌아온 막내 영애님을 조심하세요 4 | B10: 윈델 | C10: 스토리위즈 | D10: B2C | E10: 단권 | F10: 1 | G10: 3500 | H10: 3500 | I10: 0 | J10: 0 | K10: 3500 | L10: 2450 | M10: 스토리위즈 | N10: 윈델
A11: [시리즈]돌아온 막내 영애님을 조심하세요 4 | B11: 윈델 | C11: 스토리위즈 | D11: B2C | E11: 단권 | F11: 1 | G11: 3500 | H11: 3500 | I11: 0 | J11: 0 | K11: 3500 | L11: 2450 | M11: 스토리위즈 | N11: 윈델
A12: 돌아온 막내 영애님을 조심하세요 5 | B12: 윈델 | C12: 스토리위즈 | D12: B2C | E12: 단권 | F12: 1 | G12: 3500 | H12: 3500 | I12: 0 | J12: 0 | K12: 3500 | L12: 2450 | M12: 스토리위즈 | N12: 윈델
A13: [시리즈]돌아온 막내 영애님을 조심하세요 5 | B13: 윈델 | C13: 스토리위즈 | D13: B2C | E13: 단권 | F13: 1 | G13: 3500 | H13: 3500 | I13: 0 | J13: 0 | K13: 3500 | L13: 2450 | M13: 스토리위즈 | N13: 윈델
... A15: [시리즈]돌아온 막내 영애님을 조심하세요 6 (완결) | B15: 윈델 | C15: 스토리위즈 | D15: B2C | E15: 단권 | F15: 1 | G15: 3500 | H15: 3500 | I15: 0 | J15: 0 | K15: 3500 | L15: 2450 | M15: 스토리위즈 | N15: 윈델

Sheet 스내치
A1: 제목 | B1: 저자 | C1: 출판권자 | D1: 판매처 | E1: 판매유형 | F1: 부수 | G1: 정가 | H1: 판매액 | I1: 할인 | J1: 수수료 | K1: 정산대상금액 | L1: 정산액 | M1: 출판사 | N1: 작가 CP
A2: [시리즈]매혹적인 상사 (외전) | B2: 스내치 | C2: 도서출판 태랑 | D2: B2C | E2: 단권 | F2: 1 | G2: 1000 | H2: 1000 | I2: 0 | J2: 0 | K2: 1000 | L2: 700 | M2: 스토리위즈 | N2: 스내치
A3: [시리즈]매혹적인 상사 1 | B3: 스내치 | C3: 도서출판 태랑 | D3: B2C | E3: 단권 | F3: 1 | G3: 3800 | H3: 3800 | I3: 0 | J3: 0 | K3: 3800 | L3: 2660 | M3: 스토리위즈 | N3: 스내치
A4: [시리즈]매혹적인 상사 2 (완결) | B4: 스내치 | C4: 도서출판 태랑 | D4: B2C | E4: 단권 | F4: 1 | G4: 3800 | H4: 3800 | I4: 0 | J4: 0 | K4: 3800 | L4: 2660 | M4: 스토리위즈 | N4: 스내치

Sheet 블랙커피
A1: 제목 | B1: 저자 | C1: 출판권자 | D1: 판매처 | E1: 판매유형 | F1: 부수 | G1: 정가 | H1: 판매액 | I1: 할인 | J1: 수수료 | K1: 정산대상금액 | L1: 정산액 | M1: 출판사 | N1: 작가 CP
A2: [시리즈]사냥 꿈 (개정판) | B2: 블랙커피 | C2: 도서출판 태랑 | D2: B2C | E2: 단권 | F2: 5 | G2: 3800 | H2: 19000 | I2: 0 | J2: 0 | K2: 19000 | L2: 13300 | M2: 스토리위즈 | N2: 블랙커피
A3: [시리즈]사랑, 흘러간다 (외전) | B3: 블랙커피 | C3: 도서출판 태랑 | D3: B2C | E3: 단권 | F3: 5 | G3: 300 | H3: 1500 | I3: 0 | J3: 0 | K3: 1500 | L3: 1050 | M3: 스토리위즈 | N3: 블랙커피
A4: [시리즈]사랑, 흘러간다 1 | B4: 블랙커피 | C4: 도서출판 태랑 | D4: B2C | E4: 단권 | F4: 5 | G4: 2500 | H4: 12500 | I4: 0 | J4: 0 | K4: 12500 | L4: 8750 | M4: 스토리위즈 | N4: 블랙커피
A5: 사랑, 흘러간다 2 (완결) | B5: 블랙커피 | C5: 도서출판 태랑 | D5: B2C | E5: 단권 | F5: 1 | G5: 2500 | H5: 2500 | I5: 0 | J5: 0 | K5: 2500 | L5: 1750 | M5: 스토리위즈 | N5: 블랙커피
A6: [시리즈]사랑, 흘러간다 2 (완결) | B6: 블랙커피 | C6: 도서출판 태랑 | D6: B2C | E6: 단권 | F6: 5 | G6: 2500 | H6: 12500 | I6: 0 | J6: 0 | K6: 12500 | L6: 8750 | M6: 스토리위즈 | N6: 블랙커피
A7: 스타의 연애 (외전증보 개정판) 1 | B7: 블랙커피 | C7: 도서출판 태랑 | D7: B2C | E7: 단권 | F7: 1 | G7: 4000 | H7: 4000 | I7: 0 | J7: 0 | K7: 4000 | L7: 2800 | M7: 스토리위즈 | N7: 블랙커피
A8: [시리즈]스타의 연애 (외전증보 개정판) 1 | B8: 블랙커피 | C8: 도서출판 태랑 | D8: B2C | E8: 단권 | F8: 1 | G8: 4000 | H8: 4000 | I8: 0 | J8: 0 | K8: 4000 | L8: 2800 | M8: 스토리위즈 | N8: 블랙커피
A9: 스타의 연애 (외전증보 개정판) 2 (완결) | B9: 블랙커피 | C9: 도서출판 태랑 | D9: B2C | E9: 단권 | F9: 1 | G9: 4000 | H9: 4000 | I9: 0 | J9: 0 | K9: 4000 | L9: 2800 | M9: 스토리위즈 | N9: 블랙커피
A10: [시리즈]스타의 연애 (외전증보 개정판) 2 (완결) | B10: 블랙커피 | C10: 도서출판 태랑 | D10: B2C | E10: 단권 | F10: 1 | G10: 4000 | H10: 4000 | I10: 0 | J10: 0 | K10: 4000 | L10: 2800 | M10: 스토리위즈 | N10: 블랙커피
A11: [시리즈]트리거 | B11: 블랙커피 | C11: 도서출판 태랑 | D11: B2C | E11: 단권 | F11: 4 | G11: 4000 | H11: 16000 | I11: 0 | J11: 0 | K11: 16000 | L11: 11200 | M11: 스토리위즈 | N11: 블랙커피
A12: 트리거 (외전) | B12: 블랙커피 | C12: 도서출판 태랑 | D12: B2C | E12: 단권 | F12: 1 | G12: 600 | H12: 600 | I12: 0 | J12: 0 | K12: 600 | L12: 420 | M12: 스토리위즈 | N12: 블랙커피
A13: [시리즈]트리거 (외전) | B13: 블랙커피 | C13: 도서출판 태랑 | D13: B2C | E13: 단권 | F13: 4 | G13: 600 | H13: 2400 | I13: 0 | J13: 0 | K13: 2400 | L13: 1680 | M13: 스토리위즈 | N13: 블랙커피

Sheet 아슈크림
A1: 제목 | B1: 저자 | C1: 출판권자 | D1: 판매처 | E1: 판매유형 | F1: 부수 | G1: 정가 | H1: 판매액 | I1: 할인 | J1: 수수료 | K1: 정산대상금액 | L1: 정산액 | M1: 출판사 | N1: 작가 CP
A2: 어쩌다 계약 아내 (외전) | B2: 아슈크림 | C2: 도서출판 태랑 | D2: B2C | E2: 단권 | F2: 10 | G2: 2200 | H2: 22000 | I2: 0 | J2: 0 | K2: 22000 | L2: 15400 | M2: 스토리위즈 | N2: 아슈크림
A3: [시리즈]어쩌다 계약 아내 (외전) | B3: 아슈크림 | C3: 도서출판 태랑 | D3: B2C | E3: 단권 | F3: 22 | G3: 2200 | H3: 48400 | I3: 0 | J3: 0 | K3: 48400 | L3: 33880 | M3: 스토리위즈 | N3: 아슈크림
A4: 어쩌다 계약 아내 1 | B4: 아슈크림 | C4: 도서출판 태랑 | D4: B2C | E4: 단권 | F4: 18 | G4: 2800 | H4: 50400 | I4: 0 | J4: 0 | K4: 50400 | L4: 35280 | M4: 스토리위즈 | N4: 아슈크림
A5: [시리즈]어쩌다 계약 아내 1 | B5: 아슈크림 | C5: 도서출판 태랑 | D5: B2C | E5: 단권 | F5: 22 | G5: 2800 | H5: 61600 | I5: 0 | J5: 0 | K5: 61600 | L5: 43120 | M5: 스토리위즈 | N5: 아슈크림
A6: 어쩌다 계약 아내 2 | B6: 아슈크림 | C6: 도서출판 태랑 | D6: B2C | E6: 단권 | F6: 12 | G6: 2800 | H6: 33600 | I6: 0 | J6: 0 | K6: 33600 | L6: 23520 | M6: 스토리위즈 | N6: 아슈크림
A7: [시리즈]어쩌다 계약 아내 2 | B7: 아슈크림 | C7: 도서출판 태랑 | D7: B2C | E7: 단권 | F7: 22 | G7: 2800 | H7: 61600 | I7: 0 | J7: 0 | K7: 61600 | L7: 43120 | M7: 스토리위즈 | N7: 아슈크림
A8: 어쩌다 계약 아내 3 (완결) | B8: 아슈크림 | C8: 도서출판 태랑 | D8: B2C | E8: 단권 | F8: 9 | G8: 2800 | H8: 25200 | I8: 0 | J8: 0 | K8: 25200 | L8: 17640 | M8: 스토리위즈 | N8: 아슈크림
A9: [시리즈]어쩌다 계약 아내 3 (완결) | B9: 아슈크림 | C9: 도서출판 태랑 | D9: B2C | E9: 단권 | F9: 22 | G9: 2800 | H9: 61600 | I9: 0 | J9: 0 | K9: 61600 | L9: 43120 | M9: 스토리위즈 | N9: 아슈크림

Sheet 꽃잠
A1: 제목 | B1: 저자 | C1: 출판권자 | D1: 판매처 | E1: 판매유형 | F1: 부수 | G1: 정가 | H1: 판매액 | I1: 할인 | J1: 수수료 | K1: 정산대상금액 | L1: 정산액 | M1: 출판사 | N1: 작가 CP
A2: [시리즈]완벽한 타인과 (외전증보판) | B2: 꽃잠 | C2: 도서출판 태랑 | D2: B2C | E2: 단권 | F2: 1 | G2: 4600 | H2: 4600 | I2: 0 | J2: 0 | K2: 4600 | L2: 3220 | M2: 스토리위즈 | N2: 꽃잠
A3: [시리즈]흔적 (외전) | B3: 꽃잠 | C3: 도서출판 태랑 | D3: B2C | E3: 단권 | F3: 1 | G3: 600 | H3: 600 | I3: 0 | J3: 0 | K3: 600 | L3: 420 | M3: 스토리위즈 | N3: 꽃잠
A4: [시리즈]흔적 1 | B4: 꽃잠 | C4: 도서출판 태랑 | D4: B2C | E4: 단권 | F4: 1 | G4: 3300 | H4: 3300 | I4: 0 | J4: 0 | K4: 3300 | L4: 2310 | M4: 스토리위즈 | N4: 꽃잠
A5: [시리즈]흔적 2 (완결) | B5: 꽃잠 | C5: 도서출판 태랑 | D5: B2C | E5: 단권 | F5: 1 | G5: 3300 | H5: 3300 | I5: 0 | J5: 0 | K5: 3300 | L5: 2310 | M5: 스토리위즈 | N5: 꽃잠

Sheet 문스톤
A1: 제목 | B1: 저자 | C1: 출판권자 | D1: 판매처 | E1: 판매유형 | F1: 부수 | G1: 정가 | H1: 판매액 | I1: 할인 | J1: 수수료 | K1: 정산대상금액 | L1: 정산액 | M1: 출판사 | N1: 작가 CP
A2: [시리즈]중독 (외전증보판) | B2: 문스톤 | C2: 도서출판 태랑 | D2: B2C | E2: 단권 | F2: 1 | G2: 4300 | H2: 4300 | I2: 0 | J2: 0 | K2: 4300 | L2: 3010 | M2: 스토리위즈 | N2: 문스톤

Sheet 세상
A1: 제목 | B1: 저자 | C1: 출판권자 | D1: 판매처 | E1: 판매유형 | F1: 부수 | G1: 정가 | H1: 판매액 | I1: 할인 | J1: 수수료 | K1: 정산대상금액 | L1: 정산액 | M1: 출판사 | N1: 작가 CP
A2: 컬러 러쉬 (외전증보판) 1 | B2: 세상 | C2: 스토리위즈 | D2: B2C | E2: 단권 | F2: 1 | G2: 2800 | H2: 2800 | I2: 0 | J2: 0 | K2: 2800 | L2: 1960 | M2: 스토리위즈 | N2: 세상

Sheet 더컴퍼니
A1: 제목 | B1: 저자 | C1: 출판권자 | D1: 판매처 | E1: 판매유형 | F1: 부수 | G1: 정가 | H1: 판매액 | I1: 할인 | J1: 수수료 | K1: 정산대상금액 | L1: 정산액 | M1: 출판사 | N1: 작가 CP
A2: 그 순간, 별이 빛났다 (외전) | B2: 성실 | C2: 블러쉬 | D2: B2C | E2: 단권 | F2: 3 | G2: 700 | H2: 2100 | I2: 0 | J2: 0 | K2: 2100 | L2: 1470 | M2: 더컴퍼니 | N2: 더컴퍼니
A3: 그 순간, 별이 빛났다 1 | B3: 성실 | C3: 블러쉬 | D3: B2C | E3: 단권 | F3: 1 | G3: 3500 | H3: 3500 | I3: 0 | J3: 0 | K3: 3500 | L3: 2450 | M3: 더컴퍼니 | N3: 더컴퍼니
A4: 그 순간, 별이 빛났다 2 | B4: 성실 | C4: 블러쉬 | D4: B2C | E4: 단권 | F4: 1 | G4: 3500 | H4: 3500 | I4: 0 | J4: 0 | K4: 3500 | L4: 2450 | M4: 더컴퍼니 | N4: 더컴퍼니
A5: 그 순간, 별이 빛났다 3 (완결) | B5: 성실 | C5: 블러쉬 | D5: B2C | E5: 단권 | F5: 2 | G5: 3500 | H5: 7000 | I5: 0 | J5: 0 | K5: 7000 | L5: 4900 | M5: 더컴퍼니 | N5: 더컴퍼니
A6: [시리즈]그을린 신기루 | B6: 녹치 | C6: 블러쉬 | D6: B2C | E6: 단권 | F6: 1 | G6: 3300 | H6: 3300 | I6: 0 | J6: 0 | K6: 3300 | L6: 2310 | M6: 더컴퍼니 | N6: 더컴퍼니
A7: 그저, 닿지 않을 너에게 3 (완결) | B7: 뚜여사 | C7: 블러쉬 | D7: B2C | E7: 단권 | F7: 1 | G7: 3500 | H7: 3500 | I7: 0 | J7: 0 | K7: 3500 | L7: 2450 | M7: 더컴퍼니 | N7: 더컴퍼니
A8: 금의 해, 새의 눈 | B8: 등나무밑소공자 | C8: 블러쉬 | D8: B2C | E8: 프리미엄 | F8: 137 | G8: 100 | H8: 13700 | I8: 0 | J8: 0 | K8: 13700 | L8: 9590 | M8: 더컴퍼니 | N8: 더컴퍼니
A9: [시리즈]납치범과 도련님 | B9: 이락 | C9: 블러쉬 | D9: B2C | E9: 단권 | F9: 1 | G9: 3200 | H9: 3200 | I9: 0 | J9: 0 | K9: 3200 | L9: 2240 | M9: 더컴퍼니 | N9: 더컴퍼니
A10: 너드 공략집 | B10: 이다겸 | C10: 블러쉬 | D10: B2C | E10: 프리미엄 | F10: 98 | G10: 100 | H10: 9800 | I10: 0 | J10: 0 | K10: 9800 | L10: 6860 | M10: 더컴퍼니 | N10: 더컴퍼니
A11: [시리즈]너드 공략집 1 | B11: 이다겸 | C11: 블러쉬 | D11: B2C | E11: 단권 | F11: 2 | G11: 3200 | H11: 6400 | I11: 0 | J11: 0 | K11: 6400 | L11: 4480 | M11: 더컴퍼니 | N11: 더컴퍼니
A12: [시리즈]너드 공략집 2 | B12: 이다겸 | C12: 블러쉬 | D12: B2C | E12: 단권 | F12: 2 | G12: 3200 | H12: 6400 | I12: 0 | J12: 0 | K12: 6400 | L12: 4480 | M12: 더컴퍼니 | N12: 더컴퍼니
A13: [시리즈]너드 공략집 3 (완결) | B13: 이다겸 | C13: 블러쉬 | D13: B2C | E13: 단권 | F13: 2 | G13: 3200 | H13: 6400 | I13: 0 | J13: 0 | K13: 6400 | L13: 4480 | M13: 더컴퍼니 | N13: 더컴퍼니
... A48: [시리즈]홍염의 덫 6 (완결) | B48: 무슈슈 | C48: 블러쉬 | D48: B2C | E48: 단권 | F48: 1 | G48: 3300 | H48: 3300 | I48: 0 | J48: 0 | K48: 3300 | L48: 2310 | M48: 더컴퍼니 | N48: 더컴퍼니

Sheet 밀리의 서재
A1: 제목 | B1: 저자 | C1: 출판권자 | D1: 판매처 | E1: 판매유형 | F1: 부수 | G1: 정가 | H1: 판매액 | I1: 할인 | J1: 수수료 | K1: 정산대상금액 | L1: 정산액 | M1: 출판사 | N1: 작가 CP
A2: [시리즈]깊은 밤 너의 고백이 | B2: 이새인 | C2: 밀리오리지널 | D2: B2C | E2: 단권 | F2: 18 | G2: 2000 | H2: 36000 | I2: 0 | J2: 0 | K2: 36000 | L2: 25200 | M2: 밀리의 서재 | N2: 밀리의 서재
A3: [시리즈]낯선 밤에 마주친 | B3: 춈춈 | C3: 밀리오리지널 | D3: B2C | E3: 단권 | F3: 8 | G3: 2000 | H3: 16000 | I3: 0 | J3: 0 | K3: 16000 | L3: 11200 | M3: 밀리의 서재 | N3: 밀리의 서재
A4: [시리즈]너는 싱그러운 여름처럼 | B4: 박지영 | C4: 밀리오리지널 | D4: B2C | E4: 단권 | F4: 1 | G4: 2000 | H4: 2000 | I4: 0 | J4: 0 | K4: 2000 | L4: 1400 | M4: 밀리의 서재 | N4: 밀리의 서재
A5: [시리즈]너만 보면 두근두근 | B5: 정경하 | C5: 밀리오리지널 | D5: B2C | E5: 단권 | F5: 7 | G5: 2500 | H5: 17500 | I5: 0 | J5: 0 | K5: 17500 | L5: 12250 | M5: 밀리의 서재 | N5: 밀리의 서재
A6: [시리즈]너와 나의 절정 | B6: 공호 | C6: 밀리오리지널 | D6: B2C | E6: 단권 | F6: 4 | G6: 2500 | H6: 10000 | I6: 0 | J6: 0 | K6: 10000 | L6: 7000 | M6: 밀리의 서재 | N6: 밀리의 서재
A7: [시리즈]미드나잇 썸머 (Midnight Summer) | B7: 적랑 | C7: 밀리오리지널 | D7: B2C | E7: 단권 | F7: 1 | G7: 2500 | H7: 2500 | I7: 0 | J7: 0 | K7: 2500 | L7: 1750 | M7: 밀리의 서재 | N7: 밀리의 서재
A8: [시리즈]미쳐 버린 밤 | B8: 백화(百花) | C8: 밀리오리지널 | D8: B2C | E8: 단권 | F8: 2 | G8: 2000 | H8: 4000 | I8: 0 | J8: 0 | K8: 4000 | L8: 2800 | M8: 밀리의 서재 | N8: 밀리의 서재
A9: [시리즈]봄, 어리 이야기 | B9: 신윤희(에드가) | C9: 밀리오리지널 | D9: B2C | E9: 단권 | F9: 2 | G9: 2500 | H9: 5000 | I9: 0 | J9: 0 | K9: 5000 | L9: 3500 | M9: 밀리의 서재 | N9: 밀리의 서재
A10: [시리즈]불꽃 | B10: 김혜연 | C10: 밀리오리지널 | D10: B2C | E10: 단권 | F10: 4 | G10: 3000 | H10: 12000 | I10: 0 | J10: 0 | K10: 12000 | L10: 8400 | M10: 밀리의 서재 | N10: 밀리의 서재
A11: [시리즈]붉은 정자 : 살라댕 | B11: 라벤더블루 | C11: 밀리오리지널 | D11: B2C | E11: 단권 | F11: 3 | G11: 2500 | H11: 7500 | I11: 0 | J11: 0 | K11: 7500 | L11: 5250 | M11: 밀리의 서재 | N11: 밀리의 서재
A12: [시리즈]브레이크 어웨이 (Break Away) | B12: 서정윤 | C12: 밀리오리지널 | D12: B2C | E12: 단권 | F12: 14 | G12: 2500 | H12: 35000 | I12: 0 | J12: 0 | K12: 35000 | L12: 24500 | M12: 밀리의 서재 | N12: 밀리의 서재
A13: [시리즈]사내 연애의 끝 | B13: 라벤더블루 | C13: 밀리오리지널 | D13: B2C | E13: 단권 | F13: 31 | G13: 2500 | H13: 77500 | I13: 0 | J13: 0 | K13: 77500 | L13: 54250 | M13: 밀리의 서재 | N13: 밀리의 서재
... A33: [시리즈]황궁의 밤 | B33: 현진서 | C33: 밀리오리지널 | D33: B2C | E33: 단권 | F33: 1 | G33: 3500 | H33: 3500 | I33: 0 | J33: 0 | K33: 3500 | L33: 2450 | M33: 밀리의 서재 | N33: 밀리의 서재
