Workbook
Name AFFMST: [1]AFFMST!$A$1:$E$42
Name coin_domestic_total_no_tax: [2]コイン内訳!$K$17
Name coin_oversea_total: [2]コイン内訳!$L$17
Name coin_report_rs_ratio: '[2]コイン報告書_foreign CP'!$P$27
Name direct_apple_domestic_total_no_tax: [2]内訳_公式決済!$D$10
Name direct_apple_oversea_total: [2]内訳_公式決済!$E$10
Name direct_google_domestic_total_no_tax: [2]内訳_公式決済!$G$10
Name direct_google_oversea_total: [2]内訳_公式決済!$H$10
Name direct_item: '[2]コイン報告書_foreign CP'!#REF!
Name direct_item: '[2]コイン報告書_foreign CP'!#REF!
Name direct_items: '[2]コイン報告書_foreign CP'!#REF!
Name direct_items: '[2]コイン報告書_foreign CP'!#REF!
Name direct_report_rs_ratio: '[2]コイン報告書_foreign CP'!$P$32
Name direct_report_ym: '[2]コイン報告書_foreign CP'!#REF!
Name direct_report_ym: '[2]コイン報告書_foreign CP'!#REF!
Name withholdingtaxrate: '[2]コイン報告書_foreign CP'!$W$36
Name ws_items: '[2]コイン報告書_foreign CP'!#REF!
Name ws_items: '[2]コイン報告書_foreign CP'!#REF!
Name ws_report_rs_ratio: '[2]コイン報告書_foreign CP'!#REF!
Name ws_report_rs_ratio: '[2]コイン報告書_foreign CP'!#REF!
Name ws_report_rs_ratio1: '[2]コイン報告書_foreign CP'!#REF!
Name ws_report_rs_ratio1: '[2]コイン報告書_foreign CP'!#REF!
Name ws_report_rs_ratio2: '[2]コイン報告書_foreign CP'!#REF!
Name ws_report_rs_ratio2: '[2]コイン報告書_foreign CP'!#REF!
Name ws_report_ym: '[2]コイン報告書_foreign CP'!#REF!
Name ws_report_ym: '[2]コイン報告書_foreign CP'!#REF!
Name ㄹㄹ: '[2]コイン報告書_foreign CP'!#REF!
Name ㄹㄹ: '[2]コイン報告書_foreign CP'!#REF!
Name ㅇ: '[2]コイン報告書_foreign CP'!#REF!
Name ㅇ: '[2]コイン報告書_foreign CP'!#REF!
Name ㅇㅇ: '[2]コイン報告書_foreign CP'!#REF!
Name ㅇㅇ: '[2]コイン報告書_foreign CP'!#REF!
Name ㅇㅇㅇㅇㅇㅇㅇ: '[2]コイン報告書_foreign CP'!#REF!
Name 타이틀명: [3]hidden!$A$2:$A$120
Name 테스트: '[2]コイン報告書_foreign CP'!#REF!

Sheet 합계04
A1: 4월 | B1: 플랫폼별 매출 내역
B2: 유통처 | C2: 스토리위즈 매출액 | D2: 작가 정산액
B3: 구글북스 | C3: 41859 | D3: =C3*60% -> 25115.4
B4: 네이버APP | C4: 213492 | D4: =C4*60% -> 128095.2
B5: 네이버PC1 | C5: 25211 | D5: =C5*60% -> 15126.6
B6: 리디북스1 | C6: 104650 | D6: =C6*60% -> 62790
B7: 무툰 | C7: =무툰04!O5 -> 630 | D7: =C7*60% -> 378
B8: 문피아 | C8: 26208 | D8: =C8*60% -> 15724.8
B9: 버프툰 | C9: 3290 | D9: =C9*60% -> 1974
B10: 북큐브 | C10: 36840 | D10: =C10*60% -> 22104
B11: 예스이십사 | C11: -73920 | D11: =C11*60% -> -44352
B12: 원스토어 | C12: 88200 | D12: =C12*60% -> 52920
B13: 조아라 | C13: 16920 | D13: =C13*60% -> 10152
B14: 톡소다 | C14: 70 | D14: =C14*60% -> 42
B15: 알라딘 | C15: =알라딘04!G3 -> 26880 | D15: =C15*60% -> 16128
B16: 블라이스 | C16: =블라이스04!V5 -> 105910 | D16: =C16*60% -> 63546
B17: 네이버APP(장유진) | C17: =네이버APP04_장유진!AW6 -> 148527.33 | D17: =C17*60% -> 89116.398
B18: 리디북스1(장유진) | C18: =리디북스04_장유진!AP38 -> 9450 | D18: =C18*60% -> 5670
B19: 무툰(장유진) | C19: =무툰04_장유진!O5 -> 910 | D19: =C19*60% -> 546
B20: 문피아(장유진) | C20: =문피아04_장유진!M4 -> 5418 | D20: =C20*60% -> 3250.8
B21: 미스터블루(장유진) | C21: =미스터블루04_장유진!AJ4 -> 4536 | D21: =C21*60% -> 2721.6
B22: 카카오(장유진) | C22: =카카오04_장유진!AP5 -> 5600 | D22: =C22*60% -> 3360
B23: 합계 | C23: =SUM(C3:C22) -> 790681.33 | D23: =ROUND(SUM(D3:D22),0) -> 474409
B25: 카카오 선MG 차감 내역 | D25: 2차 (21.12월 정산)
B26: 당월 차감 MG | D26: =MG차감내역04!C18 -> 474409
B27: 잔여 MG | D27: =MG차감내역04!D18 -> 31465609
B28: * 월별 상세 내역은 카카오 시트 확인

Sheet MG차감내역04
B2: 구분 | D2: 금액
B3: 선MG | D3: 50000000
B4: 보증보험료 | D4: 2542500
B5: 총 합계 | D5: =D3+D4 -> 52542500
B7: 대상월 | C7: 스토리위즈 매출액 | D7: 잔여 선MG
B8: 44349 | C8: 1339391 | D8: =D5-C8 -> 51203109
B9: 44378 | C9: 1267013 | D9: =D8-C9 -> 49936096
B10: 44409 | C10: 1696410 | D10: =D9-C10 -> 48239686
B11: 44440 | C11: 527385 | D11: =D10-C11 -> 47712301
B12: 44470 | C12: 388214 | D12: =D11-C12 -> 47324087
B13: 44501 | C13: 718576 | D13: =D12-C13 -> 46605511
B14: 44531 | C14: 12447502 | D14: =D13-C14 -> 34158009
B15: 44562 | C15: 928377 | D15: =D14-C15 -> 33229632
B16: 44593 | C16: 600504 | D16: 32629128
B17: 44621 | C17: 689110 | D17: =D16-C17 -> 31940018
B18: 44652 | C18: 474409 | D18: =D17-C18 -> 31465609

Sheet 카카오04_청빙
A1: 특별/일반 | B1: 사업자명 | C1: 사업자번호 | D1: 발행자명 | E1: 계약UID | F1: 계약유형 | G1: 계약(과/면세) | H1: 당월신규계약여부 | I1: 카테고리 | J1: 시리즈ID | K1: 시리즈명 | L1: 발행자가 부여하는 코드 | M1: 레이블 | N1: 작가명 | O1: ISBN(유/무) | P1: CP정산율_안드로이드/이벤트캐시 | Q1: CP정산율_iOS | R1: 이용권 종류 | S1: 이용권 금액 | T1: 캐시_합계 | U1: 캐시_CPP | V1: 캐시_CPI | W1: 캐시_CP1 | X1: 캐시_CP2 | Y1: 캐시_CP3 | Z1: 캐시_CP7 | AA1: 캐시_CP8 | AB1: 캐시_CP9 | AC1: 캐시_이벤트캐시 | AD1: 원화_합계 | AE1: 원화_CPP | AF1: 원화_CPI | AG1: 원화_CP1 | AH1: 원화_CP2 | AI1: 원화_CP3 | AJ1: 원화_CP7 | AK1: 원화_CP8 | AL1: 원화_CP9 | AM1: 원화_이벤트캐시 | AN1: 공급가액 | AO1: 부가세 | AP1: 공급대가
A2: 특별계약 | B2: 주식회사 스토리위즈 | C2: 3828601768 | D2: 스토리위즈 | E2: 1941 | F2: 선투자 | G2: 면세 | H2: N | I2: 소설 | J2: 51936303 | K2: 호접몽전 | N2: 청빙 | O2: Y | P2: 0.55 | Q2: 0.55 | R2: 단일 이용권 | S2: 100 | T2: 119000 | U2: 20850 | V2: 0 | W2: 0 | X2: 0 | Y2: 0 | Z2: 0 | AA2: 0 | AB2: 0 | AC2: 98150 | AD2: 119000 | AE2: 20850 | AF2: 0 | AG2: 0 | AH2: 0 | AI2: 0 | AJ2: 0 | AK2: 0 | AL2: 0 | AM2: 98150 | AN2: 65450 | AO2: 0 | AP2: 65450
A3: 특별계약 | B3: 주식회사 스토리위즈 | C3: 3828601768 | D3: 스토리위즈 | E3: 1941 | F3: 선투자 | G3: 면세 | H3: N | I3: 소설 | J3: 51936303 | K3: 호접몽전 | N3: 청빙 | O3: Y | P3: 0.55 | Q3: 0.55 | R3: 시리즈 이용권 패키지 | S3: 2400 | T3: 33500 | U3: 23600 | V3: 0 | W3: 0 | X3: 0 | Y3: 0 | Z3: 0 | AA3: 0 | AB3: 0 | AC3: 9900 | AD3: 33500 | AE3: 23600 | AF3: 0 | AG3: 0 | AH3: 0 | AI3: 0 | AJ3: 0 | AK3: 0 | AL3: 0 | AM3: 9900 | AN3: 18425 | AO3: 0 | AP3: 18425
A4: 특별계약 | B4: 주식회사 스토리위즈 | C4: 3828601768 | D4: 스토리위즈 | E4: 1941 | F4: 선투자 | G4: 면세 | H4: N | I4: 소설 | J4: 51936303 | K4: 호접몽전 | N4: 청빙 | O4: Y | P4: 0.55 | Q4: 0.55 | R4: 시리즈 이용권 패키지 | S4: 9200 | T4: 64400 | U4: 64400 | V4: 0 | W4: 0 | X4: 0 | Y4: 0 | Z4: 0 | AA4: 0 | AB4: 0 | AC4: 0 | AD4: 64400 | AE4: 64400 | AF4: 0 | AG4: 0 | AH4: 0 | AI4: 0 | AJ4: 0 | AK4: 0 | AL4: 0 | AM4: 0 | AN4: 35420 | AO4: 0 | AP4: 35420
A5: 특별계약 | B5: 주식회사 스토리위즈 | C5: 3828601768 | D5: 스토리위즈 | E5: 1941 | F5: 선투자 | G5: 면세 | H5: N | I5: 소설 | J5: 51936303 | K5: 호접몽전 | N5: 청빙 | O5: Y | P5: 0.55 | Q5: 0.55 | R5: 시리즈 이용권 패키지 | S5: 18000 | T5: 54000 | U5: 54000 | V5: 0 | W5: 0 | X5: 0 | Y5: 0 | Z5: 0 | AA5: 0 | AB5: 0 | AC5: 0 | AD5: 54000 | AE5: 54000 | AF5: 0 | AG5: 0 | AH5: 0 | AI5: 0 | AJ5: 0 | AK5: 0 | AL5: 0 | AM5: 0 | AN5: 29700 | AO5: 0 | AP5: 29700
A6: 특별계약 | B6: 주식회사 스토리위즈 | C6: 3828601768 | D6: 스토리위즈 | E6: 1941 | F6: 선투자 | G6: 면세 | H6: N | I6: 소설 | J6: 54212515 | K6: 라스트 서바이버 : 진화로 살아남아라! | N6: 청빙 | O6: Y | P6: 0.55 | Q6: 0.55 | R6: 단일 이용권 | S6: 100 | T6: 27000 | U6: 13700 | V6: 0 | W6: 0 | X6: 0 | Y6: 0 | Z6: 0 | AA6: 0 | AB6: 0 | AC6: 13300 | AD6: 27000 | AE6: 13700 | AF6: 0 | AG6: 0 | AH6: 0 | AI6: 0 | AJ6: 0 | AK6: 0 | AL6: 0 | AM6: 13300 | AN6: 14850 | AO6: 0 | AP6: 14850
A7: 특별계약 | B7: 주식회사 스토리위즈 | C7: 3828601768 | D7: 스토리위즈 | E7: 1941 | F7: 선투자 | G7: 면세 | H7: N | I7: 소설 | J7: 54212515 | K7: 라스트 서바이버 : 진화로 살아남아라! | N7: 청빙 | O7: Y | P7: 0.55 | Q7: 0.55 | R7: 시리즈 이용권 패키지 | S7: 2400 | T7: 79200 | U7: 75100 | V7: 0 | W7: 0 | X7: 0 | Y7: 0 | Z7: 0 | AA7: 0 | AB7: 0 | AC7: 4100 | AD7: 79200 | AE7: 75100 | AF7: 0 | AG7: 0 | AH7: 0 | AI7: 0 | AJ7: 0 | AK7: 0 | AL7: 0 | AM7: 4100 | AN7: 43560 | AO7: 0 | AP7: 43560
A8: 특별계약 | B8: 주식회사 스토리위즈 | C8: 3828601768 | D8: 스토리위즈 | E8: 1941 | F8: 선투자 | G8: 면세 | H8: N | I8: 소설 | J8: 54212515 | K8: 라스트 서바이버 : 진화로 살아남아라! | N8: 청빙 | O8: Y | P8: 0.55 | Q8: 0.55 | R8: 시리즈 이용권 패키지 | S8: 9200 | T8: 9200 | U8: 9200 | V8: 0 | W8: 0 | X8: 0 | Y8: 0 | Z8: 0 | AA8: 0 | AB8: 0 | AC8: 0 | AD8: 9200 | AE8: 9200 | AF8: 0 | AG8: 0 | AH8: 0 | AI8: 0 | AJ8: 0 | AK8: 0 | AL8: 0 | AM8: 0 | AN8: 5060 | AO8: 0 | AP8: 5060
A9: 특별계약 | B9: 주식회사 스토리위즈 | C9: 3828601768 | D9: 스토리위즈 | E9: 1941 | F9: 선투자 | G9: 면세 | H9: N | I9: 소설 | J9: 54212515 | K9: 라스트 서바이버 : 진화로 살아남아라! | N9: 청빙 | O9: Y | P9: 0.55 | Q9: 0.55 | R9: 시리즈 이용권 패키지 | S9: 18000 | T9: 70600 | U9: 70600 | V9: 0 | W9: 0 | X9: 0 | Y9: 0 | Z9: 0 | AA9: 0 | AB9: 0 | AC9: 0 | AD9: 70600 | AE9: 70600 | AF9: 0 | AG9: 0 | AH9: 0 | AI9: 0 | AJ9: 0 | AK9: 0 | AL9: 0 | AM9: 0 | AN9: 38830 | AO9: 0 | AP9: 38830
A10: 특별계약 | B10: 주식회사 스토리위즈 | C10: 3828601768 | D10: 스토리위즈 | E10: 1941 | F10: 선투자 | G10: 면세 | H10: N | I10: 소설 | J10: 56380069 | K10: 문답무용 - 삼국지 유비의 모사가 되었다 | N10: 청빙 | O10: Y | P10: 0.55 | Q10: 0.55 | R10: 단일 이용권 | S10: 100 | T10: 700 | U10: -200 | V10: 0 | W10: 0 | X10: 0 | Y10: 0 | Z10: 0 | AA10: 0 | AB10: 0 | AC10: 900 | AD10: 700 | AE10: -200 | AF10: 0 | AG10: 0 | AH10: 0 | AI10: 0 | AJ10: 0 | AK10: 0 | AL10: 0 | AM10: 900 | AN10: 385 | AO10: 0 | AP10: 385
A11: 특별계약 | B11: 주식회사 스토리위즈 | C11: 3828601768 | D11: 스토리위즈 | E11: 1941 | F11: 선투자 | G11: 면세 | H11: N | I11: 소설 | J11: 56380069 | K11: 문답무용 - 삼국지 유비의 모사가 되었다 | N11: 청빙 | O11: Y | P11: 0.55 | Q11: 0.55 | R11: 시리즈 이용권 패키지 | S11: 2400 | T11: 7200 | U11: 2400 | V11: 0 | W11: 0 | X11: 0 | Y11: 0 | Z11: 0 | AA11: 0 | AB11: 0 | AC11: 4800 | AD11: 7200 | AE11: 2400 | AF11: 0 | AG11: 0 | AH11: 0 | AI11: 0 | AJ11: 0 | AK11: 0 | AL11: 0 | AM11: 4800 | AN11: 3960 | AO11: 0 | AP11: 3960
A12: 특별계약 | B12: 주식회사 스토리위즈 | C12: 3828601768 | D12: 스토리위즈 | E12: 1941 | F12: 선투자 | G12: 면세 | H12: N | I12: 소설 | J12: 56380069 | K12: 문답무용 - 삼국지 유비의 모사가 되었다 | N12: 청빙 | O12: Y | P12: 0.55 | Q12: 0.55 | R12: 시리즈 이용권 패키지 | S12: 9200 | T12: 1100 | U12: 1100 | V12: 0 | W12: 0 | X12: 0 | Y12: 0 | Z12: 0 | AA12: 0 | AB12: 0 | AC12: 0 | AD12: 1100 | AE12: 1100 | AF12: 0 | AG12: 0 | AH12: 0 | AI12: 0 | AJ12: 0 | AK12: 0 | AL12: 0 | AM12: 0 | AN12: 605 | AO12: 0 | AP12: 605
A13: 특별계약 | B13: 주식회사 스토리위즈 | C13: 3828601768 | D13: 스토리위즈 | E13: 1941 | F13: 선투자 | G13: 면세 | H13: N | I13: 소설 | J13: 56380069 | K13: 문답무용 - 삼국지 유비의 모사가 되었다 | N13: 청빙 | O13: Y | P13: 0.55 | Q13: 0.55 | R13: 시리즈 이용권 패키지 | S13: 18000 | T13: 6200 | U13: 6200 | V13: 0 | W13: 0 | X13: 0 | Y13: 0 | Z13: 0 | AA13: 0 | AB13: 0 | AC13: 0 | AD13: 6200 | AE13: 6200 | AF13: 0 | AG13: 0 | AH13: 0 | AI13: 0 | AJ13: 0 | AK13: 0 | AL13: 0 | AM13: 0 | AN13: 3410 | AO13: 0 | AP13: 3410
AP14: =SUM(AP2:AP13) -> 259655
A16: ㅇ MG차감 내역
A17: 유통년월 | B17: 선MG | C17: KT 매출 | D17: MG 잔여
A18: 201912 | B18: 50000000 | C18: 616705 | D18: 49383295
A19: 202001 | C19: 702488 | D19: 48680807
A20: 202002 | C20: 631686 | D20: 48049121
A21: 202003 | C21: 569830 | D21: 47479291
A22: 202004 | C22: 19193902 | D22: 28285389
A23: 202005 | C23: 5406095 | D23: 22879294
A24: 202006 | C24: 2614141 | D24: 20265153
A25: 202007 | C25: 3800817 | D25: 16464336
A26: 202008 | C26: 2432478 | D26: 14031858
A27: 202009 | C27: 1712223 | D27: 12319635
A28: 202010 | C28: 4755890 | D28: 7563745
A29: 202011 | C29: 1758007 | D29: 5805738
A30: 202012 | C30: 562936 | D30: 5242802
... A36: 202106 | C36: 442222 | D36: 1844847
A37: 202107 | C37: 321530 | D37: =D36-C37 -> 1523317
A38: 202108 | C38: 300806 | D38: =D37-C38 -> 1222511
A39: 202109 | C39: 188639 | D39: =D38-C39 -> 1033872
A40: 202110 | C40: 325666 | D40: =D39-C40 -> 708206
A41: 202111 | C41: 295037 | D41: =D40-C41 -> 413169
A42: 202112 | B42: 20000000 | C42: 353299 | D42: =D41-C42+B42 -> 20059870
A43: 202201 | C43: 246202 | D43: =D42-C43 -> 19813668
A44: 202202 | C44: 173976 | D44: =D43-C44 -> 19639692
A45: 202203 | C45: 279606 | D45: =D44-C45 -> 19360086
A46: 202204 | C46: =AP14 -> 259655 | D46: =D45-C46 -> 19100431
...

Sheet 구글북스04
A1: Earnings Date | B1: Transaction Date | C1: Id | D1: Product | E1: Type | F1: Preorder | G1: Qty | H1: Primary ISBN | I1: Imprint Name | J1: Title | K1: Author | L1: Original List Price Currency | M1: Original List Price | N1: List Price Currency | O1: List Price [tax inclusive] | P1: List Price [tax exclusive] | Q1: Country of Sale | R1: Publisher Revenue % | S1: Publisher Revenue | T1: Earnings Currency | U1: Earnings Amount | V1: 출판사
A2: 22. 4. 30. | B2: 22. 4. 8. | C2: ID:3197-4753-5954-10105 | D2: Single Purchase | E2: Sale | F2: None | G2: 1 | H2: 9791137600553 | I2: 스토리위즈 | J2: 라스트 서바이버 : 진화로 살아남아라! 2권 | K2: 청빙 | L2: KRW | M2: 3200 | N2: USD | O2: 2.64 | P2: 2.64 | Q2: US | R2: 0.7 | S2: 1.85 | T2: KRW | U2: 2266 | V2: 스토리위즈
A3: 22. 4. 30. | B3: 22. 4. 8. | C3: ID:3197-4753-5954-10105 | D3: Single Purchase | E3: Sale | F3: None | G3: 1 | H3: 9791137600560 | I3: 스토리위즈 | J3: 라스트 서바이버 : 진화로 살아남아라! 3권 | K3: 청빙 | L3: KRW | M3: 3200 | N3: USD | O3: 2.64 | P3: 2.64 | Q3: US | R3: 0.7 | S3: 1.85 | T3: KRW | U3: 2266 | V3: 스토리위즈
A4: 22. 4. 30. | B4: 22. 4. 8. | C4: ID:3197-4753-5954-10105 | D4: Single Purchase | E4: Sale | F4: None | G4: 1 | H4: 9791137600577 | I4: 스토리위즈 | J4: 라스트 서바이버 : 진화로 살아남아라! 4권 | K4: 청빙 | L4: KRW | M4: 3200 | N4: USD | O4: 2.64 | P4: 2.64 | Q4: US | R4: 0.7 | S4: 1.85 | T4: KRW | U4: 2266 | V4: 스토리위즈
A5: 22. 4. 30. | B5: 22. 4. 11. | C5: ID:3143-6459-0754-52287 | D5: Single Purchase | E5: Sale | F5: None | G5: 1 | H5: 9791137600584 | I5: 스토리위즈 | J5: 라스트 서바이버 : 진화로 살아남아라! 5권 | K5: 청빙 | L5: KRW | M5: 3200 | N5: USD | O5: 2.64 | P5: 2.64 | Q5: US | R5: 0.7 | S5: 1.85 | T5: KRW | U5: 2282 | V5: 스토리위즈
A6: 22. 4. 30. | B6: 22. 4. 11. | C6: ID:3143-6459-0754-52287 | D6: Single Purchase | E6: Sale | F6: None | G6: 1 | H6: 9791137600591 | I6: 스토리위즈 | J6: 라스트 서바이버 : 진화로 살아남아라! 6권 | K6: 청빙 | L6: KRW | M6: 3200 | N6: USD | O6: 2.64 | P6: 2.64 | Q6: US | R6: 0.7 | S6: 1.85 | T6: KRW | U6: 2282 | V6: 스토리위즈
A7: 22. 4. 30. | B7: 22. 4. 11. | C7: ID:3143-6459-0754-52287 | D7: Single Purchase | E7: Sale | F7: None | G7: 1 | H7: 9791137600607 | I7: 스토리위즈 | J7: 라스트 서바이버 : 진화로 살아남아라! 7권 | K7: 청빙 | L7: KRW | M7: 3200 | N7: USD | O7: 2.64 | P7: 2.64 | Q7: US | R7: 0.7 | S7: 1.85 | T7: KRW | U7: 2282 | V7: 스토리위즈
A8: 22. 4. 30. | B8: 22. 4. 20. | C8: ID:3126-6365-7008-62621 | D8: Single Purchase | E8: Sale | F8: None | G8: 1 | H8: 9791166065897 | I8: 스토리위즈 | J8: 삼국지 호접몽전 1부 13권 | K8: 청빙 | L8: KRW | M8: 3200 | N8: AUD | O8: 3.5 | P8: 3.18 | Q8: AU | R8: 0.7 | S8: 2.23 | T8: KRW | U8: 2049 | V8: 스토리위즈
A9: 22. 4. 30. | B9: 22. 4. 21. | C9: ID:3178-4407-3113-46557 | D9: Single Purchase | E9: Sale | F9: None | G9: 1 | H9: 9791166065958 | I9: 스토리위즈 | J9: 삼국지 호접몽전 2부 5권 | K9: 청빙 | L9: KRW | M9: 3200 | N9: AUD | O9: 3.5 | P9: 3.18 | Q9: AU | R9: 0.7 | S9: 2.23 | T9: KRW | U9: 2036 | V9: 스토리위즈
A10: 22. 4. 30. | B10: 22. 4. 21. | C10: ID:3132-3069-4122-76281 | D10: Single Purchase | E10: Sale | F10: None | G10: 1 | H10: 9791166065903 | I10: 스토리위즈 | J10: 삼국지 호접몽전 1부 14권 | K10: 청빙 | L10: KRW | M10: 3200 | N10: AUD | O10: 3.5 | P10: 3.18 | Q10: AU | R10: 0.7 | S10: 2.23 | T10: KRW | U10: 2036 | V10: 스토리위즈
A11: 22. 4. 30. | B11: 22. 4. 21. | C11: ID:3107-8220-7095-32050 | D11: Single Purchase | E11: Sale | F11: None | G11: 1 | H11: 9791166065910 | I11: 스토리위즈 | J11: 삼국지 호접몽전 2부 1권 | K11: 청빙 | L11: KRW | M11: 3200 | N11: AUD | O11: 3.5 | P11: 3.18 | Q11: AU | R11: 0.7 | S11: 2.23 | T11: KRW | U11: 2039 | V11: 스토리위즈
A12: 22. 4. 30. | B12: 22. 4. 22. | C12: ID:3144-3908-4148-34104 | D12: Single Purchase | E12: Sale | F12: None | G12: 1 | H12: 9791166065927 | I12: 스토리위즈 | J12: 삼국지 호접몽전 2부 2권 | K12: 청빙 | L12: KRW | M12: 3200 | N12: AUD | O12: 3.5 | P12: 3.18 | Q12: AU | R12: 0.7 | S12: 2.23 | T12: KRW | U12: 2021 | V12: 스토리위즈
A13: 22. 4. 30. | B13: 22. 4. 22. | C13: ID:3191-3815-0438-23567 | D13: Single Purchase | E13: Sale | F13: None | G13: 1 | H13: 9791166065934 | I13: 스토리위즈 | J13: 삼국지 호접몽전 2부 3권 | K13: 청빙 | L13: KRW | M13: 3200 | N13: AUD | O13: 3.5 | P13: 3.18 | Q13: AU | R13: 0.7 | S13: 2.23 | T13: KRW | U13: 2019 | V13: 스토리위즈
... A21: 22. 4. 30. | B21: 22. 4. 26. | C21: ID:3196-1968-5562-34468 | D21: Single Purchase | E21: Sale | F21: None | G21: 1 | H21: 9791166066023 | I21: 스토리위즈 | J21: 삼국지 호접몽전 3부 2권 | K21: 청빙 | L21: KRW | M21: 3200 | N21: AUD | O21: 3.5 | P21: 3.18 | Q21: AU | R21: 0.7 | S21: 2.23 | T21: KRW | U21: 2011 | V21: 스토리위즈

Sheet 네이버APP04
A1: 구분 | B1: 4 | C1: 컨텐츠No | D1: 공급자코드 | E1: CP명 | F1: 작가명 | G1: 출판사 | H1: 나이제한 | I1: 서비스일 | J1: 건수 | K1: 비정산 | L1: 무료이용권 | M1: 유상쿠키 | N1: 무상쿠키 | O1: 유상i쿠키 | P1: 무상i쿠키 | Q1: 유상자동충전쿠키 | R1: 무상자동충전쿠키 | S1: 건수 | T1: 비정산 | U1: 무료이용권 | V1: 유상쿠키 | W1: 무상쿠키 | X1: 유상i쿠키 | Y1: 무상i쿠키 | Z1: 유상자동충전쿠키 | AA1: 무상자동충전쿠키 | AB1: 건수 | AC1: 유상 | AD1: 무상 | AE1: 건수 | AF1: 유상 | AG1: 무상 | AH1: 건수 | AI1: 유상 | AJ1: 무상 | AK1: 건수 | AL1: 유상 | AM1: 무상 | AN1: i쿠키 수수료 | AO1: 건수 | AP1: 유상 | AQ1: 무상 | AR1: 건수 | AS1: 유상 | AT1: 무상 | AU1: 합계 | AV1: 순매출(합계-수수료) | AW1: SW매출
A2: 시리즈(APP) | B2: 문답무용 - 삼국지 유비의 모사가 되었다 | C2: 425289 | E2: 스토리위즈_1 | F2: 청빙 | G2: 스토리위즈 | H2: 전체이용가 | I2: 2021.02.24 | J2: 0 | K2: 0 | L2: 0 | M2: 0 | N2: 0 | O2: 0 | P2: 0 | Q2: 0 | R2: 0 | S2: 0 | T2: 0 | U2: 0 | V2: 0 | W2: 0 | X2: 0 | Y2: 0 | Z2: 0 | AA2: 0 | AB2: 0 | AC2: 0 | AD2: 0 | AE2: 0 | AF2: 0 | AG2: 0 | AH2: 0 | AI2: 0 | AJ2: 0 | AK2: 0 | AL2: 0 | AM2: 0 | AN2: 0 | AO2: 0 | AP2: 0 | AQ2: 0 | AR2: 0 | AS2: 0 | AT2: 0 | AU2: 106600 | AV2: 106600 | AW2: 74620
A3: 시리즈(APP) | B3: 삼국지 호접몽전 [단행본] | C3: 395179 | E3: 스토리위즈_1 | F3: 청빙 | G3: 스토리위즈 | H3: 전체이용가 | I3: 2020.05.05 | J3: 0 | K3: 0 | L3: 0 | M3: 0 | N3: 0 | O3: 0 | P3: 0 | Q3: 0 | R3: 0 | S3: 0 | T3: 0 | U3: 0 | V3: 0 | W3: 0 | X3: 0 | Y3: 0 | Z3: 0 | AA3: 0 | AB3: 0 | AC3: 0 | AD3: 0 | AE3: 0 | AF3: 0 | AG3: 0 | AH3: 0 | AI3: 0 | AJ3: 0 | AK3: 0 | AL3: 0 | AM3: 0 | AN3: 0 | AO3: 0 | AP3: 0 | AQ3: 0 | AR3: 0 | AS3: 0 | AT3: 0 | AU3: 73600 | AV3: 73600 | AW3: 51520
A4: 시리즈(APP) | B4: 라스트 서바이버 : 진화로 살아남아라! | C4: 428319 | E4: 스토리위즈_1 | F4: 청빙 | G4: 스토리위즈 | H4: 전체이용가 | I4: 2021.03.26 | J4: 0 | K4: 0 | L4: 0 | M4: 0 | N4: 0 | O4: 0 | P4: 0 | Q4: 0 | R4: 0 | S4: 0 | T4: 0 | U4: 0 | V4: 0 | W4: 0 | X4: 0 | Y4: 0 | Z4: 0 | AA4: 0 | AB4: 0 | AC4: 0 | AD4: 0 | AE4: 0 | AF4: 0 | AG4: 0 | AH4: 0 | AI4: 0 | AJ4: 0 | AK4: 0 | AL4: 0 | AM4: 0 | AN4: 0 | AO4: 0 | AP4: 0 | AQ4: 0 | AR4: 0 | AS4: 0 | AT4: 0 | AU4: 31200 | AV4: 31200 | AW4: 21840
A5: 시리즈(APP) | B5: 문답무용 - 삼국지 유비의 모사가 되었다 [단행본] | C5: 431511 | E5: 스토리위즈_1 | F5: 청빙 | G5: 스토리위즈 | H5: 전체이용가 | I5: 2021.05.20 | J5: 0 | K5: 0 | L5: 0 | M5: 0 | N5: 0 | O5: 0 | P5: 0 | Q5: 0 | R5: 0 | S5: 0 | T5: 0 | U5: 0 | V5: 0 | W5: 0 | X5: 0 | Y5: 0 | Z5: 0 | AA5: 0 | AB5: 0 | AC5: 0 | AD5: 0 | AE5: 0 | AF5: 0 | AG5: 0 | AH5: 0 | AI5: 0 | AJ5: 0 | AK5: 0 | AL5: 0 | AM5: 0 | AN5: 0 | AO5: 0 | AP5: 0 | AQ5: 0 | AR5: 0 | AS5: 0 | AT5: 0 | AU5: 22400 | AV5: 22400 | AW5: 15680
A6: 완전판APP | B6: 문답무용 - 삼국지 유비의 모사가 되었다 | C6: 425289 | E6: 스토리위즈_1 | F6: 청빙 | G6: 스토리위즈 | H6: 전체이용가 | I6: 2021.02.24 | J6: 0 | K6: 0 | L6: 0 | M6: 0 | N6: 0 | O6: 0 | P6: 0 | Q6: 0 | R6: 0 | S6: 0 | T6: 0 | U6: 0 | V6: 0 | W6: 0 | X6: 0 | Y6: 0 | Z6: 0 | AA6: 0 | AB6: 0 | AC6: 0 | AD6: 0 | AE6: 0 | AF6: 0 | AG6: 0 | AH6: 0 | AI6: 0 | AJ6: 0 | AK6: 0 | AL6: 0 | AM6: 0 | AN6: 0 | AO6: 0 | AP6: 0 | AQ6: 0 | AR6: 0 | AS6: 0 | AT6: 0 | AU6: 3300 | AV6: 3300 | AW6: 2310
A7: 시리즈(IOS) | B7: 삼국지 호접몽전 [단행본] | C7: 395179 | E7: 스토리위즈_1 | F7: 청빙 | G7: 스토리위즈 | H7: 전체이용가 | I7: 2020.05.05 | J7: 0 | K7: 0 | L7: 0 | M7: 0 | N7: 0 | O7: 0 | P7: 0 | Q7: 0 | R7: 0 | S7: 0 | T7: 0 | U7: 0 | V7: 0 | W7: 0 | X7: 0 | Y7: 0 | Z7: 0 | AA7: 0 | AB7: 0 | AC7: 0 | AD7: 0 | AE7: 0 | AF7: 0 | AG7: 0 | AH7: 0 | AI7: 0 | AJ7: 0 | AK7: 0 | AL7: 0 | AM7: 0 | AN7: 14652 | AO7: 0 | AP7: 0 | AQ7: 0 | AR7: 0 | AS7: 0 | AT7: 0 | AU7: 81740 | AV7: 67088 | AW7: 46961.6
A8: 시리즈(IOS) | B8: 라스트 서바이버 : 진화로 살아남아라! | C8: 428319 | E8: 스토리위즈_1 | F8: 청빙 | G8: 스토리위즈 | H8: 전체이용가 | I8: 2021.03.26 | J8: 0 | K8: 0 | L8: 0 | M8: 0 | N8: 0 | O8: 0 | P8: 0 | Q8: 0 | R8: 0 | S8: 0 | T8: 0 | U8: 0 | V8: 0 | W8: 0 | X8: 0 | Y8: 0 | Z8: 0 | AA8: 0 | AB8: 0 | AC8: 0 | AD8: 0 | AE8: 0 | AF8: 0 | AG8: 0 | AH8: 0 | AI8: 0 | AJ8: 0 | AK8: 0 | AL8: 0 | AM8: 0 | AN8: 0 | AO8: 0 | AP8: 0 | AQ8: 0 | AR8: 0 | AS8: 0 | AT8: 0 | AU8: 800 | AV8: 800 | AW8: 560

Sheet 네이버PC04
A1: 구분 | B1: 컨텐츠 | C1: 컨텐츠No | D1: 공급자코드 | E1: CP명 | F1: 작가명 | G1: 출판사 | H1: 나이제한 | I1: 서비스일 | J1: 건수 | K1: 비정산 | L1: 무료이용권 | M1: 유상쿠키 | N1: 무상쿠키 | O1: 유상i쿠키 | P1: 무상i쿠키 | Q1: 유상자동충전쿠키 | R1: 무상자동충전쿠키 | S1: 건수 | T1: 비정산 | U1: 무료이용권 | V1: 유상쿠키 | W1: 무상쿠키 | X1: 유상i쿠키 | Y1: 무상i쿠키 | Z1: 유상자동충전쿠키 | AA1: 무상자동충전쿠키 | AB1: 건수 | AC1: 유상 | AD1: 무상 | AE1: 건수 | AF1: 유상 | AG1: 무상 | AH1: 건수 | AI1: 유상 | AJ1: 무상 | AK1: 건수 | AL1: 유상 | AM1: 무상 | AN1: i쿠키 수수료 | AO1: 건수 | AP1: 유상 | AQ1: 무상 | AR1: 건수 | AS1: 유상 | AT1: 무상 | AU1: 합계 | AV1: 순매출(합계-수수료) | AW1: SW매출
A2: N스토어(PC) | B2: 삼국지 호접몽전 [단행본] | C2: 395179 | E2: 스토리위즈_1 | F2: 청빙 | G2: 스토리위즈 | H2: 전체이용가 | I2: 2020.05.05 | J2: 0 | K2: 0 | L2: 0 | M2: 0 | N2: 0 | O2: 0 | P2: 0 | Q2: 0 | R2: 0 | S2: 0 | T2: 0 | U2: 0 | V2: 0 | W2: 0 | X2: 0 | Y2: 0 | Z2: 0 | AA2: 0 | AB2: 0 | AC2: 0 | AD2: 0 | AE2: 0 | AF2: 0 | AG2: 0 | AH2: 0 | AI2: 0 | AJ2: 0 | AK2: 0 | AL2: 0 | AM2: 0 | AN2: 0 | AO2: 0 | AP2: 0 | AQ2: 0 | AR2: 0 | AS2: 0 | AT2: 0 | AU2: 3200 | AV2: 3200 | AW2: 2240
A3: PC뷰어(PC) | B3: 삼국지 호접몽전 [단행본] | C3: 395179 | E3: 스토리위즈_1 | F3: 청빙 | G3: 스토리위즈 | H3: 전체이용가 | I3: 2020.05.05 | J3: 0 | K3: 0 | L3: 0 | M3: 0 | N3: 0 | O3: 0 | P3: 0 | Q3: 0 | R3: 0 | S3: 0 | T3: 0 | U3: 0 | V3: 0 | W3: 0 | X3: 0 | Y3: 0 | Z3: 0 | AA3: 0 | AB3: 0 | AC3: 0 | AD3: 0 | AE3: 0 | AF3: 0 | AG3: 0 | AH3: 0 | AI3: 0 | AJ3: 0 | AK3: 0 | AL3: 0 | AM3: 0 | AN3: 5364 | AO3: 0 | AP3: 0 | AQ3: 0 | AR3: 0 | AS3: 0 | AT3: 0 | AU3: 34980 | AV3: 29616 | AW3: 20731.2
A4: PC뷰어(PC) | B4: 문답무용 - 삼국지 유비의 모사가 되었다 [단행본] | C4: 431511 | E4: 스토리위즈_1 | F4: 청빙 | G4: 스토리위즈 | H4: 전체이용가 | I4: 2021.05.20 | J4: 0 | K4: 0 | L4: 0 | M4: 0 | N4: 0 | O4: 0 | P4: 0 | Q4: 0 | R4: 0 | S4: 0 | T4: 0 | U4: 0 | V4: 0 | W4: 0 | X4: 0 | Y4: 0 | Z4: 0 | AA4: 0 | AB4: 0 | AC4: 0 | AD4: 0 | AE4: 0 | AF4: 0 | AG4: 0 | AH4: 0 | AI4: 0 | AJ4: 0 | AK4: 0 | AL4: 0 | AM4: 0 | AN4: 0 | AO4: 0 | AP4: 0 | AQ4: 0 | AR4: 0 | AS4: 0 | AT4: 0 | AU4: 3200 | AV4: 3200 | AW4: 2240

Sheet 리디북스04
A1: 시리즈 ID | B1: 도서 ID | C1: 제목 | D1: 권/화수 | E1: 저자 | F1: 역자 | G1: 그림 | H1: 출판사 | I1: 시리즈명 | J1: 전자책정가 | K1: 단권판매액 | L1: 단권판매권 | M1: 단권무료권 | N1: 대여액 | O1: 대여유료권( ~ 2020-04 대여권) | P1: 대여무료권 | Q1: 자유다운금액 | R1: 자유다운권 | S1: 세트판매액 | T1: 세트판매권 | U1: 세트대여액 | V1: 세트대여권 | W1: 취소단권판매액 | X1: 취소단권판매권 | Y1: 취소대여액 | Z1: 취소대여권 | AA1: 취소자유다운액 | AB1: 취소자유다운권 | AC1: 취소세트판매액 | AD1: 취소세트판매권 | AE1: 취소세트대여액 | AF1: 취소세트대여권 | AG1: 판매액 | AH1: 판매권 | AI1: 취소액 | AJ1: 취소권 | AK1: 일반 판매액 | AL1: 일반 취소액 | AM1: 앱마켓 정산대상액 | AN1: 앱마켓 수수료(30%) | AO1: 앱마켓 취소액 | AP1: 정산액 | AQ1: 종이책ISBN10 | AR1: 종이책ISBN13 | AS1: 전자책ISBN10 | AT1: 전자책ISBN13 | AU1: CP 관리 ID | AV1: 카테고리1 | AW1: 카테고리2
A2: 2313007047 | B2: 2313007052 | C2: [e북]삼국지 호접몽전 1부 6권 | D2: 6 | E2: 청빙 | H2: 스토리위즈 | I2: [e북]삼국지 호접몽전 | J2: 3200 | K2: 6400 | L2: 2 | M2: 0 | N2: 0 | O2: 0 | P2: 0 | Q2: 0 | R2: 0 | S2: 0 | T2: 0 | U2: 0 | V2: 0 | W2: 0 | X2: 0 | Y2: 0 | Z2: 0 | AA2: 0 | AB2: 0 | AC2: 0 | AD2: 0 | AE2: 0 | AF2: 0 | AG2: 6400 | AH2: 2 | AI2: 0 | AJ2: 0 | AK2: 6400 | AL2: 0 | AM2: 0 | AN2: 0 | AO2: 0 | AP2: 4480 | AT2: 9791159289262 | AV2: 판타지 e북 > 퓨전 판타지
A3: 2313007047 | B3: 2313007056 | C3: [e북]삼국지 호접몽전 1부 10권 | D3: 10 | E3: 청빙 | H3: 스토리위즈 | I3: [e북]삼국지 호접몽전 | J3: 3200 | K3: 6400 | L3: 2 | M3: 0 | N3: 0 | O3: 0 | P3: 0 | Q3: 0 | R3: 0 | S3: 0 | T3: 0 | U3: 0 | V3: 0 | W3: 0 | X3: 0 | Y3: 0 | Z3: 0 | AA3: 0 | AB3: 0 | AC3: 0 | AD3: 0 | AE3: 0 | AF3: 0 | AG3: 6400 | AH3: 2 | AI3: 0 | AJ3: 0 | AK3: 6400 | AL3: 0 | AM3: 0 | AN3: 0 | AO3: 0 | AP3: 4480 | AT3: 9791159289309 | AV3: 판타지 e북 > 퓨전 판타지
A4: 2313007047 | B4: 2313007057 | C4: [e북]삼국지 호접몽전 1부 11권 | D4: 11 | E4: 청빙 | H4: 스토리위즈 | I4: [e북]삼국지 호접몽전 | J4: 3200 | K4: 6400 | L4: 2 | M4: 0 | N4: 0 | O4: 0 | P4: 0 | Q4: 0 | R4: 0 | S4: 0 | T4: 0 | U4: 0 | V4: 0 | W4: 0 | X4: 0 | Y4: 0 | Z4: 0 | AA4: 0 | AB4: 0 | AC4: 0 | AD4: 0 | AE4: 0 | AF4: 0 | AG4: 6400 | AH4: 2 | AI4: 0 | AJ4: 0 | AK4: 6400 | AL4: 0 | AM4: 0 | AN4: 0 | AO4: 0 | AP4: 4480 | AT4: 9791159289316 | AV4: 판타지 e북 > 퓨전 판타지
A5: 2313007047 | B5: 2313007058 | C5: [e북]삼국지 호접몽전 1부 12권 | D5: 12 | E5: 청빙 | H5: 스토리위즈 | I5: [e북]삼국지 호접몽전 | J5: 3200 | K5: 6400 | L5: 2 | M5: 0 | N5: 0 | O5: 0 | P5: 0 | Q5: 0 | R5: 0 | S5: 0 | T5: 0 | U5: 0 | V5: 0 | W5: 0 | X5: 0 | Y5: 0 | Z5: 0 | AA5: 0 | AB5: 0 | AC5: 0 | AD5: 0 | AE5: 0 | AF5: 0 | AG5: 6400 | AH5: 2 | AI5: 0 | AJ5: 0 | AK5: 6400 | AL5: 0 | AM5: 0 | AN5: 0 | AO5: 0 | AP5: 4480 | AT5: 9791159289323 | AV5: 판타지 e북 > 퓨전 판타지
A6: 2313007047 | B6: 2313007059 | C6: [e북]삼국지 호접몽전 1부 13권 | D6: 13 | E6: 청빙 | H6: 스토리위즈 | I6: [e북]삼국지 호접몽전 | J6: 3200 | K6: 6400 | L6: 2 | M6: 0 | N6: 0 | O6: 0 | P6: 0 | Q6: 0 | R6: 0 | S6: 0 | T6: 0 | U6: 0 | V6: 0 | W6: 0 | X6: 0 | Y6: 0 | Z6: 0 | AA6: 0 | AB6: 0 | AC6: 0 | AD6: 0 | AE6: 0 | AF6: 0 | AG6: 6400 | AH6: 2 | AI6: 0 | AJ6: 0 | AK6: 6400 | AL6: 0 | AM6: 0 | AN6: 0 | AO6: 0 | AP6: 4480 | AT6: 9791159289330 | AV6: 판타지 e북 > 퓨전 판타지
A7: 2313007047 | B7: 2313007060 | C7: [e북]삼국지 호접몽전 1부 14권 | D7: 14 | E7: 청빙 | H7: 스토리위즈 | I7: [e북]삼국지 호접몽전 | J7: 3200 | K7: 6400 | L7: 2 | M7: 0 | N7: 0 | O7: 0 | P7: 0 | Q7: 0 | R7: 0 | S7: 0 | T7: 0 | U7: 0 | V7: 0 | W7: 0 | X7: 0 | Y7: 0 | Z7: 0 | AA7: 0 | AB7: 0 | AC7: 0 | AD7: 0 | AE7: 0 | AF7: 0 | AG7: 6400 | AH7: 2 | AI7: 0 | AJ7: 0 | AK7: 6400 | AL7: 0 | AM7: 0 | AN7: 0 | AO7: 0 | AP7: 4480 | AT7: 9791159289347 | AV7: 판타지 e북 > 퓨전 판타지
A8: 2313011372 | B8: 2313011374 | C8: [e북]라스트 서바이버 : 진화로 살아남아라! 3권 | D8: 3 | E8: 청빙 | H8: 스토리위즈 | I8: [e북]라스트 서바이버 : 진화로 살아남아라! | J8: 3200 | K8: 6400 | L8: 2 | M8: 0 | N8: 0 | O8: 0 | P8: 0 | Q8: 0 | R8: 0 | S8: 0 | T8: 0 | U8: 0 | V8: 0 | W8: 0 | X8: 0 | Y8: 0 | Z8: 0 | AA8: 0 | AB8: 0 | AC8: 0 | AD8: 0 | AE8: 0 | AF8: 0 | AG8: 6400 | AH8: 2 | AI8: 0 | AJ8: 0 | AK8: 6400 | AL8: 0 | AM8: 0 | AN8: 0 | AO8: 0 | AP8: 4480 | AT8: 9791137600560 | AV8: 판타지 e북 > 퓨전 판타지
A9: 2313011386 | B9: 2313011387 | C9: [e북]문답무용 - 삼국지 유비의 모사가 되었다 2권 | D9: 2 | E9: 청빙 | H9: 스토리위즈 | I9: [e북]문답무용 - 삼국지 유비의 모사가 되었다 | J9: 3200 | K9: 6400 | L9: 2 | M9: 0 | N9: 0 | O9: 0 | P9: 0 | Q9: 0 | R9: 0 | S9: 0 | T9: 0 | U9: 0 | V9: 0 | W9: 0 | X9: 0 | Y9: 0 | Z9: 0 | AA9: 0 | AB9: 0 | AC9: 0 | AD9: 0 | AE9: 0 | AF9: 0 | AG9: 6400 | AH9: 2 | AI9: 0 | AJ9: 0 | AK9: 6400 | AL9: 0 | AM9: 0 | AN9: 0 | AO9: 0 | AP9: 4480 | AT9: 9791166069949 | AV9: 판타지 e북 > 퓨전 판타지
A10: 2313007047 | B10: 2313007048 | C10: [e북]삼국지 호접몽전 1부 2권 | D10: 2 | E10: 청빙 | H10: 스토리위즈 | I10: [e북]삼국지 호접몽전 | J10: 3200 | K10: 3200 | L10: 1 | M10: 0 | N10: 0 | O10: 0 | P10: 0 | Q10: 0 | R10: 0 | S10: 0 | T10: 0 | U10: 0 | V10: 0 | W10: 0 | X10: 0 | Y10: 0 | Z10: 0 | AA10: 0 | AB10: 0 | AC10: 0 | AD10: 0 | AE10: 0 | AF10: 0 | AG10: 3200 | AH10: 1 | AI10: 0 | AJ10: 0 | AK10: 3200 | AL10: 0 | AM10: 0 | AN10: 0 | AO10: 0 | AP10: 2240 | AT10: 9791159289224 | AV10: 판타지 e북 > 퓨전 판타지
A11: 2313007047 | B11: 2313007049 | C11: [e북]삼국지 호접몽전 1부 3권 | D11: 3 | E11: 청빙 | H11: 스토리위즈 | I11: [e북]삼국지 호접몽전 | J11: 3200 | K11: 3200 | L11: 1 | M11: 0 | N11: 0 | O11: 0 | P11: 0 | Q11: 0 | R11: 0 | S11: 0 | T11: 0 | U11: 0 | V11: 0 | W11: 0 | X11: 0 | Y11: 0 | Z11: 0 | AA11: 0 | AB11: 0 | AC11: 0 | AD11: 0 | AE11: 0 | AF11: 0 | AG11: 3200 | AH11: 1 | AI11: 0 | AJ11: 0 | AK11: 3200 | AL11: 0 | AM11: 0 | AN11: 0 | AO11: 0 | AP11: 2240 | AT11: 9791159289231 | AV11: 판타지 e북 > 퓨전 판타지
A12: 2313007047 | B12: 2313007050 | C12: [e북]삼국지 호접몽전 1부 4권 | D12: 4 | E12: 청빙 | H12: 스토리위즈 | I12: [e북]삼국지 호접몽전 | J12: 3200 | K12: 3200 | L12: 1 | M12: 0 | N12: 0 | O12: 0 | P12: 0 | Q12: 0 | R12: 0 | S12: 0 | T12: 0 | U12: 0 | V12: 0 | W12: 0 | X12: 0 | Y12: 0 | Z12: 0 | AA12: 0 | AB12: 0 | AC12: 0 | AD12: 0 | AE12: 0 | AF12: 0 | AG12: 3200 | AH12: 1 | AI12: 0 | AJ12: 0 | AK12: 3200 | AL12: 0 | AM12: 0 | AN12: 0 | AO12: 0 | AP12: 2240 | AT12: 9791159289248 | AV12: 판타지 e북 > 퓨전 판타지
A13: 2313007047 | B13: 2313007051 | C13: [e북]삼국지 호접몽전 1부 5권 | D13: 5 | E13: 청빙 | H13: 스토리위즈 | I13: [e북]삼국지 호접몽전 | J13: 3200 | K13: 3200 | L13: 1 | M13: 0 | N13: 0 | O13: 0 | P13: 0 | Q13: 0 | R13: 0 | S13: 0 | T13: 0 | U13: 0 | V13: 0 | W13: 0 | X13: 0 | Y13: 0 | Z13: 0 | AA13: 0 | AB13: 0 | AC13: 0 | AD13: 0 | AE13: 0 | AF13: 0 | AG13: 3200 | AH13: 1 | AI13: 0 | AJ13: 0 | AK13: 3200 | AL13: 0 | AM13: 0 | AN13: 0 | AO13: 0 | AP13: 2240 | AT13: 9791159289255 | AV13: 판타지 e북 > 퓨전 판타지
... A290: 2313011386 | B290: 2313011386 | C290: [e북]문답무용 - 삼국지 유비의 모사가 되었다 1권 | D290: 1 | E290: 청빙 | H290: 스토리위즈 | I290: [e북]문답무용 - 삼국지 유비의 모사가 되었다 | J290: 0 | K290: 0 | L290: 0 | M290: 5 | N290: 0 | O290: 0 | P290: 0 | Q290: 0 | R290: 0 | S290: 0 | T290: 0 | U290: 0 | V290: 0 | W290: 0 | X290: 0 | Y290: 0 | Z290: 0 | AA290: 0 | AB290: 0 | AC290: 0 | AD290: 0 | AE290: 0 | AF290: 0 | AG290: 0 | AH290: 5 | AI290: 0 | AJ290: 0 | AK290: 0 | AL290: 0 | AM290: 0 | AN290: 0 | AO290: 0 | AP290: 0 | AT290: 9791166069932 | AV290: 판타지 e북 > 퓨전 판타지

Sheet 무툰04
A1: NO | B1: 작가 | C1: 타이틀 | D1: 플랫폼 | E1: 코인 | F1: 금액 | G1: 코인 | H1: 금액 | I1: 코인 | J1: 금액 | K1: 결제 | L1: 이벤트 | M1: 수수료공제액 | N1: 정산비율 | O1: 정산액
A2: 52 | B2: 청빙 | C2: 삼국지 호접몽전 | D2: M | E2: 0 | F2: 0 | G2: 0 | H2: 0 | I2: 0 | J2: 0 | K2: 0 | L2: 0 | M2: 0 | O2: 0
A3: 52 | B3: 청빙 | C3: 삼국지 호접몽전 | D3: W | E3: 9 | F3: 900 | G3: 9 | H3: 900 | I3: 9 | J3: 900 | K3: 0 | L3: 0 | M3: 900 | O3: 630
A4: 52 | B4: 청빙 | C4: 삼국지 호접몽전 | D4: A | E4: 0 | F4: 0 | G4: 0 | H4: 0 | I4: 0 | J4: 0 | K4: 0 | L4: 0 | M4: 0 | O4: 0
O5: =SUM(O2:O4) -> 630

Sheet 문피아04
A1: 날짜 | B1: 구분 | C1: 작가 | D1: 계정 | E1: 작품코드 | F1: 작품 | G1: 구매 | H1: 구매취소 | I1: 대여 | J1: 대여취소 | K1: 총매출 | L1: IOS매출 | M1: 정산
A2: 2022.03 | B2: 문피아 | C2: 청빙 | D2: kt_0601 | E2: 270858 | F2: 라스트 서바이버 : 진화로 살아남아라! [D] | G2: 13 | H2: 0 | I2: 0 | J2: 0 | K2: 41600 | L2: 0 | M2: 26208

Sheet 버프툰04
A1: 작품번호 | B1: 작품명 | C1: 작가명 | D1: 연동계정명 | E1: 주문상태 | F1: 주문유형 | G1: 주문건수 | H1: 합계금액 | I1: 작품기간할인 | J1: 일괄구매할인 | K1: 모아무이용권 | L1: 이용권 | M1: 유료코인 | N1: 이벤트코인 | O1: 보너스코인 | P1: AOS유료코인 | Q1: AOS이벤트코인 | R1: AOS보너스코인 | S1: IOS유료코인 | T1: IOS이벤트코인 | U1: IOS보너스코인 | V1: 정산금액
A2: 1007668 | B2: 라스트 서바이버 : 진화로 살아남아라! | C2: 청빙 | D2: 스토리위즈 | E2: 주문완료 | F2: 대여 | G2: 47 | H2: 4700 | I2: - | J2: - | K2: 4700 | L2: - | M2: - | N2: - | O2: - | P2: - | Q2: - | R2: - | S2: - | T2: - | U2: - | V2: 3290

Sheet 북큐브04
A1: 제목 | B1: 저자 | C1: 출판권자 | D1: 판매처 | E1: 판매유형 | F1: 부수 | G1: 정가 | H1: 판매액 | I1: 할인 | J1: 수수료 | K1: 정산대상금액 | L1: 정산액
A2: 라스트 서바이버 : 진화로 살아남아라! 10 | B2: 청빙 | C2: 스토리위즈 | D2: B2B | E2: 제주관광대학교 | F2: 1 | G2: 3200 | H2: 3200 | I2: 0 | J2: 0 | K2: 3200 | L2: 1600
A3: 라스트 서바이버 : 진화로 살아남아라! 11 | B3: 청빙 | C3: 스토리위즈 | D3: B2B | E3: 제주관광대학교 | F3: 1 | G3: 3200 | H3: 3200 | I3: 0 | J3: 0 | K3: 3200 | L3: 1600
A4: 라스트 서바이버 : 진화로 살아남아라! 12 | B4: 청빙 | C4: 스토리위즈 | D4: B2B | E4: 제주관광대학교 | F4: 1 | G4: 3200 | H4: 3200 | I4: 0 | J4: 0 | K4: 3200 | L4: 1600
A5: 라스트 서바이버 : 진화로 살아남아라! 13 (완결) | B5: 청빙 | C5: 스토리위즈 | D5: B2B | E5: 제주관광대학교 | F5: 1 | G5: 3200 | H5: 3200 | I5: 0 | J5: 0 | K5: 3200 | L5: 1600
A6: 라스트 서바이버 : 진화로 살아남아라! 2 | B6: 청빙 | C6: 스토리위즈 | D6: B2B | E6: 제주관광대학교 | F6: 1 | G6: 3200 | H6: 3200 | I6: 0 | J6: 0 | K6: 3200 | L6: 1600
A7: 라스트 서바이버 : 진화로 살아남아라! 3 | B7: 청빙 | C7: 스토리위즈 | D7: B2B | E7: 제주관광대학교 | F7: 1 | G7: 3200 | H7: 3200 | I7: 0 | J7: 0 | K7: 3200 | L7: 1600
A8: 라스트 서바이버 : 진화로 살아남아라! 4 | B8: 청빙 | C8: 스토리위즈 | D8: B2B | E8: 제주관광대학교 | F8: 1 | G8: 3200 | H8: 3200 | I8: 0 | J8: 0 | K8: 3200 | L8: 1600
A9: 라스트 서바이버 : 진화로 살아남아라! 5 | B9: 청빙 | C9: 스토리위즈 | D9: B2B | E9: 제주관광대학교 | F9: 1 | G9: 3200 | H9: 3200 | I9: 0 | J9: 0 | K9: 3200 | L9: 1600
A10: 라스트 서바이버 : 진화로 살아남아라! 6 | B10: 청빙 | C10: 스토리위즈 | D10: B2B | E10: 제주관광대학교 | F10: 1 | G10: 3200 | H10: 3200 | I10: 0 | J10: 0 | K10: 3200 | L10: 1600
A11: 라스트 서바이버 : 진화로 살아남아라! 7 | B11: 청빙 | C11: 스토리위즈 | D11: B2B | E11: 제주관광대학교 | F11: 1 | G11: 3200 | H11: 3200 | I11: 0 | J11: 0 | K11: 3200 | L11: 1600
A12: 라스트 서바이버 : 진화로 살아남아라! 8 | B12: 청빙 | C12: 스토리위즈 | D12: B2B | E12: 제주관광대학교 | F12: 1 | G12: 3200 | H12: 3200 | I12: 0 | J12: 0 | K12: 3200 | L12: 1600
A13: 라스트 서바이버 : 진화로 살아남아라! 9 | B13: 청빙 | C13: 스토리위즈 | D13: B2B | E13: 제주관광대학교 | F13: 1 | G13: 3200 | H13: 3200 | I13: 0 | J13: 0 | K13: 3200 | L13: 1600
... A15: 문답무용 - 삼국지 유비의 모사가 되었다 2 | B15: 청빙 | C15: 스토리위즈 | D15: B2C | E15: 단권 | F15: 1 | G15: 3200 | H15: 3200 | I15: 0 | J15: 0 | K15: 3200 | L15: 2240

Sheet 예스이십사04
A1: No | B1: 도서명 | C1: 출판사 | D1: 출판사판매가 | E1: 판매서점 | F1: 서점판매가 | G1: 서점환불가 | H1: 원가율 | I1: 출판사정산액 | J1: 이벤트구분 | K1: 판매구분 | L1: 이벤트판매가 | M1: 저자명 | N1: 출판사 | O1: ePubID | P1: 세트코드 | Q1: 종이책ISBN | R1: 전자책ISBN | S1: 판매일 | T1: 환불일
A2: 805 | B2: 삼국지 호접몽전 1부 01권 | C2: 스토리위즈 | D2: 0 | E2: YES24 | F2: 0 | G2: 0 | H2: 70 | I2: 0 | J2: 일반 | K2: 구매 | L2: 0 | M2: 청빙 | N2: 스토리위즈 | O2: 1186278 | P2: 0 | Q2: 0 | R2: 9791159289217 | S2: 2022-04-23 00:38:29.437
A3: 806 | B3: 삼국지 호접몽전 1부 02권 | C3: 스토리위즈 | D3: 3200 | E3: YES24 | F3: 3200 | G3: 0 | H3: 70 | I3: 2240 | J3: 일반 | K3: 구매 | L3: 0 | M3: 청빙 | N3: 스토리위즈 | O3: 1186279 | P3: 0 | Q3: 0 | R3: 9791159289224 | S3: 2022-04-23 00:38:29.437
A4: 807 | B4: 삼국지 호접몽전 1부 03권 | C4: 스토리위즈 | D4: 3200 | E4: YES24 | F4: 3200 | G4: 0 | H4: 70 | I4: 2240 | J4: 일반 | K4: 구매 | L4: 0 | M4: 청빙 | N4: 스토리위즈 | O4: 1186280 | P4: 0 | Q4: 0 | R4: 9791159289231 | S4: 2022-04-23 00:38:29.437
A5: 808 | B5: 삼국지 호접몽전 1부 04권 | C5: 스토리위즈 | D5: 3200 | E5: YES24 | F5: 3200 | G5: 0 | H5: 70 | I5: 2240 | J5: 일반 | K5: 구매 | L5: 0 | M5: 청빙 | N5: 스토리위즈 | O5: 1186281 | P5: 0 | Q5: 0 | R5: 9791159289248 | S5: 2022-04-23 00:38:29.437
A6: 809 | B6: 삼국지 호접몽전 1부 05권 | C6: 스토리위즈 | D6: 3200 | E6: YES24 | F6: 3200 | G6: 0 | H6: 70 | I6: 2240 | J6: 일반 | K6: 구매 | L6: 0 | M6: 청빙 | N6: 스토리위즈 | O6: 1186282 | P6: 0 | Q6: 0 | R6: 9791159289255 | S6: 2022-04-23 00:38:29.437
A7: 810 | B7: 삼국지 호접몽전 1부 06권 | C7: 스토리위즈 | D7: 3200 | E7: YES24 | F7: 3200 | G7: 0 | H7: 70 | I7: 2240 | J7: 일반 | K7: 구매 | L7: 0 | M7: 청빙 | N7: 스토리위즈 | O7: 1186283 | P7: 0 | Q7: 0 | R7: 9791159289262 | S7: 2022-04-23 00:38:29.437
A8: 811 | B8: 삼국지 호접몽전 1부 07권 | C8: 스토리위즈 | D8: 3200 | E8: YES24 | F8: 3200 | G8: 0 | H8: 70 | I8: 2240 | J8: 일반 | K8: 구매 | L8: 0 | M8: 청빙 | N8: 스토리위즈 | O8: 1186284 | P8: 0 | Q8: 0 | R8: 9791159289279 | S8: 2022-04-23 00:38:29.437
A9: 812 | B9: 삼국지 호접몽전 1부 08권 | C9: 스토리위즈 | D9: 3200 | E9: YES24 | F9: 3200 | G9: 0 | H9: 70 | I9: 2240 | J9: 일반 | K9: 구매 | L9: 0 | M9: 청빙 | N9: 스토리위즈 | O9: 1186285 | P9: 0 | Q9: 0 | R9: 9791159289286 | S9: 2022-04-23 00:38:29.437
A10: 813 | B10: 삼국지 호접몽전 1부 09권 | C10: 스토리위즈 | D10: 3200 | E10: YES24 | F10: 3200 | G10: 0 | H10: 70 | I10: 2240 | J10: 일반 | K10: 구매 | L10: 0 | M10: 청빙 | N10: 스토리위즈 | O10: 1186286 | P10: 0 | Q10: 0 | R10: 9791159289293 | S10: 2022-04-23 00:38:29.437
A11: 814 | B11: 삼국지 호접몽전 1부 10권 | C11: 스토리위즈 | D11: 3200 | E11: YES24 | F11: 3200 | G11: 0 | H11: 70 | I11: 2240 | J11: 일반 | K11: 구매 | L11: 0 | M11: 청빙 | N11: 스토리위즈 | O11: 1186287 | P11: 0 | Q11: 0 | R11: 9791159289309 | S11: 2022-04-23 00:38:29.437
A12: 815 | B12: 삼국지 호접몽전 1부 11권 | C12: 스토리위즈 | D12: 3200 | E12: YES24 | F12: 3200 | G12: 0 | H12: 70 | I12: 2240 | J12: 일반 | K12: 구매 | L12: 0 | M12: 청빙 | N12: 스토리위즈 | O12: 1186288 | P12: 0 | Q12: 0 | R12: 9791159289316 | S12: 2022-04-23 00:38:29.437
A13: 816 | B13: 삼국지 호접몽전 1부 12권 | C13: 스토리위즈 | D13: 3200 | E13: YES24 | F13: 3200 | G13: 0 | H13: 70 | I13: 2240 | J13: 일반 | K13: 구매 | L13: 0 | M13: 청빙 | N13: 스토리위즈 | O13: 1186289 | P13: 0 | Q13: 0 | R13: 9791159289323 | S13: 2022-04-23 00:38:29.437
... A36: 1578 | B36: 라스트 서바이버 : 진화로 살아남아라! 01권 | C36: 스토리위즈 | D36: 0 | E36: YES24 | F36: 0 | G36: 0 | H36: 70 | I36: 0 | J36: 일반 | K36: 구매 | L36: 0 | M36: 청빙 | N36: 스토리위즈 | O36: 1285414 | P36: 0 | Q36: 0 | R36: 9791137600546 | S36: 2022-04-12 02:47:47.133
A37: 2274 | B37: [세트] 삼국지 호접몽전 (총34권/완결) | C37: 스토리위즈 | D37: 105600 | E37: YES24 | F37: 0 | G37: 105600 | H37: 70 | I37: -73920 | J37: 세트 일반 | K37: 구매 | L37: 0 | M37: 청빙 | N37: 스토리위즈 | O37: 0 | P37: 45672 | S37: 2022-03-31 23:04:29.977 | T37: 2022-04-01 05:07:37.593
A38: 2275 | B38: [세트] 삼국지 호접몽전 (총34권/완결) | C38: 스토리위즈 | D38: 105600 | E38: YES24 | F38: 0 | G38: 105600 | H38: 70 | I38: -73920 | J38: 세트 일반 | K38: 구매 | L38: 0 | M38: 청빙 | N38: 스토리위즈 | O38: 0 | P38: 45672 | S38: 2022-03-31 22:56:10.71 | T38: 2022-04-01 05:05:50.087

Sheet 원스토어04
A1: 파트너명 | B1: 파트너ID | C1: 사업자구분 | D1: 채널상품ID | E1: 채널상품명 | F1: 상품명 | G1: 회차 | H1: 상품ID | I1: 2차정산여부 | J1: 카테고리 | K1: 출판사 | L1: 글작가 | M1: 그림작가 | N1: 타입 | O1: 판매건수 | P1: 취소건수 | Q1: 정액제 정산대상액 | R1: 판매_건수 | S1: 판매_금액 | T1: 취소_건수 | U1: 취소_금액 | V1: 합계 | W1: 결제수단_고객결제 | X1: 결제수단_고객결제(현금영수증) | Y1: 결제수단_쿠폰/포인트등 | Z1: 서비스이용료_고객결제서비스이용료 | AA1: 서비스이용료_쿠폰/포인트 등 | AB1: 서비스이용료_차감 | AC1: 정산지급액 | AD1: 정산유형
A2: 주식회사 스토리위즈 | B2: storywiz1 | C2: 원스토어㈜ | D2: H038934564 | E2: 호접몽전 | F2: 호접몽전 1부 10권 | G2: 10 | H2: H038934733 | I2: 2차 | J2: eBook | K2: 스토리위즈 | L2: 청빙 | N2: 단행 | O2: 1 | P2: 0 | Q2: 0 | R2: 1 | S2: 3200 | T2: 0 | U2: 0 | V2: 3200 | W2: 3200 | X2: 0 | Y2: 0 | Z2: 960 | AA2: 0 | AB2: 0 | AC2: 2240 | AD2: 정규
A3: 주식회사 스토리위즈 | B3: storywiz1 | C3: 원스토어㈜ | D3: H038934564 | E3: 호접몽전 | F3: 호접몽전 1부 11권 | G3: 11 | H3: H038934732 | I3: 2차 | J3: eBook | K3: 스토리위즈 | L3: 청빙 | N3: 단행 | O3: 1 | P3: 0 | Q3: 0 | R3: 1 | S3: 3200 | T3: 0 | U3: 0 | V3: 3200 | W3: 3200 | X3: 0 | Y3: 0 | Z3: 960 | AA3: 0 | AB3: 0 | AC3: 2240 | AD3: 정규
A4: 주식회사 스토리위즈 | B4: storywiz1 | C4: 원스토어㈜ | D4: H038934564 | E4: 호접몽전 | F4: 호접몽전 1부 12권 | G4: 12 | H4: H038934731 | I4: 2차 | J4: eBook | K4: 스토리위즈 | L4: 청빙 | N4: 단행 | O4: 1 | P4: 0 | Q4: 0 | R4: 1 | S4: 3200 | T4: 0 | U4: 0 | V4: 3200 | W4: 3200 | X4: 0 | Y4: 0 | Z4: 960 | AA4: 0 | AB4: 0 | AC4: 2240 | AD4: 정규
A5: 주식회사 스토리위즈 | B5: storywiz1 | C5: 원스토어㈜ | D5: H038934564 | E5: 호접몽전 | F5: 호접몽전 1부 13권 | G5: 13 | H5: H038934730 | I5: 2차 | J5: eBook | K5: 스토리위즈 | L5: 청빙 | N5: 단행 | O5: 1 | P5: 0 | Q5: 0 | R5: 1 | S5: 3200 | T5: 0 | U5: 0 | V5: 3200 | W5: 3200 | X5: 0 | Y5: 0 | Z5: 960 | AA5: 0 | AB5: 0 | AC5: 2240 | AD5: 정규
A6: 주식회사 스토리위즈 | B6: storywiz1 | C6: 원스토어㈜ | D6: H038934564 | E6: 호접몽전 | F6: 호접몽전 1부 14권 | G6: 14 | H6: H038934729 | I6: 2차 | J6: eBook | K6: 스토리위즈 | L6: 청빙 | N6: 단행 | O6: 1 | P6: 0 | Q6: 0 | R6: 1 | S6: 3200 | T6: 0 | U6: 0 | V6: 3200 | W6: 3200 | X6: 0 | Y6: 0 | Z6: 960 | AA6: 0 | AB6: 0 | AC6: 2240 | AD6: 정규
A7: 주식회사 스토리위즈 | B7: storywiz1 | C7: 원스토어㈜ | D7: H038934564 | E7: 호접몽전 | F7: 호접몽전 1부 2권 | G7: 2 | H7: H038934741 | I7: 2차 | J7: eBook | K7: 스토리위즈 | L7: 청빙 | N7: 단행 | O7: 1 | P7: 0 | Q7: 0 | R7: 1 | S7: 3200 | T7: 0 | U7: 0 | V7: 3200 | W7: 3200 | X7: 0 | Y7: 0 | Z7: 960 | AA7: 0 | AB7: 0 | AC7: 2240 | AD7: 정규
A8: 주식회사 스토리위즈 | B8: storywiz1 | C8: 원스토어㈜ | D8: H038934564 | E8: 호접몽전 | F8: 호접몽전 1부 3권 | G8: 3 | H8: H038934740 | I8: 2차 | J8: eBook | K8: 스토리위즈 | L8: 청빙 | N8: 단행 | O8: 1 | P8: 0 | Q8: 0 | R8: 1 | S8: 3200 | T8: 0 | U8: 0 | V8: 3200 | W8: 3200 | X8: 0 | Y8: 0 | Z8: 960 | AA8: 0 | AB8: 0 | AC8: 2240 | AD8: 정규
A9: 주식회사 스토리위즈 | B9: storywiz1 | C9: 원스토어㈜ | D9: H038934564 | E9: 호접몽전 | F9: 호접몽전 1부 6권 | G9: 6 | H9: H038934737 | I9: 2차 | J9: eBook | K9: 스토리위즈 | L9: 청빙 | N9: 단행 | O9: 1 | P9: 0 | Q9: 0 | R9: 1 | S9: 3200 | T9: 0 | U9: 0 | V9: 3200 | W9: 0 | X9: 0 | Y9: 3200 | Z9: 0 | AA9: 960 | AB9: 0 | AC9: 2240 | AD9: 정규
A10: 주식회사 스토리위즈 | B10: storywiz1 | C10: 원스토어㈜ | D10: H038934564 | E10: 호접몽전 | F10: 호접몽전 2부 10권 | G10: 24 | H10: H038934719 | I10: 2차 | J10: eBook | K10: 스토리위즈 | L10: 청빙 | N10: 단행 | O10: 1 | P10: 0 | Q10: 0 | R10: 1 | S10: 3200 | T10: 0 | U10: 0 | V10: 3200 | W10: 3040 | X10: 0 | Y10: 160 | Z10: 912 | AA10: 48 | AB10: 0 | AC10: 2240 | AD10: 정규
A11: 주식회사 스토리위즈 | B11: storywiz1 | C11: 원스토어㈜ | D11: H038934564 | E11: 호접몽전 | F11: 호접몽전 2부 1권 | G11: 15 | H11: H038934728 | I11: 2차 | J11: eBook | K11: 스토리위즈 | L11: 청빙 | N11: 단행 | O11: 1 | P11: 0 | Q11: 0 | R11: 1 | S11: 3200 | T11: 0 | U11: 0 | V11: 3200 | W11: 3200 | X11: 0 | Y11: 0 | Z11: 960 | AA11: 0 | AB11: 0 | AC11: 2240 | AD11: 정규
A12: 주식회사 스토리위즈 | B12: storywiz1 | C12: 원스토어㈜ | D12: H038934564 | E12: 호접몽전 | F12: 호접몽전 2부 2권 | G12: 16 | H12: H038934727 | I12: 2차 | J12: eBook | K12: 스토리위즈 | L12: 청빙 | N12: 단행 | O12: 1 | P12: 0 | Q12: 0 | R12: 1 | S12: 3200 | T12: 0 | U12: 0 | V12: 3200 | W12: 3200 | X12: 0 | Y12: 0 | Z12: 960 | AA12: 0 | AB12: 0 | AC12: 2240 | AD12: 정규
A13: 주식회사 스토리위즈 | B13: storywiz1 | C13: 원스토어㈜ | D13: H038934564 | E13: 호접몽전 | F13: 호접몽전 2부 3권 | G13: 17 | H13: H038934726 | I13: 2차 | J13: eBook | K13: 스토리위즈 | L13: 청빙 | N13: 단행 | O13: 1 | P13: 0 | Q13: 0 | R13: 1 | S13: 3200 | T13: 0 | U13: 0 | V13: 3200 | W13: 3200 | X13: 0 | Y13: 0 | Z13: 960 | AA13: 0 | AB13: 0 | AC13: 2240 | AD13: 정규
... A114: 주식회사 스토리위즈 | B114: storywiz1 | C114: 원스토어㈜ | D114: H040585192 | E114: 문답무용 - 삼국지 유비의 모사가 되었다 | F114: 문답무용 - 삼국지 유비의 모사가 되었다 9권 | G114: 9 | H114: H040585198 | I114: 2차 | J114: eBook | K114: 스토리위즈 | L114: 청빙 | N114: 단행 | O114: 1 | P114: 0 | Q114: 0 | R114: 1 | S114: 3200 | T114: 0 | U114: 0 | V114: 3200 | W114: 3000 | X114: 0 | Y114: 200 | Z114: 900 | AA114: 60 | AB114: 0 | AC114: 2240 | AD114: 정규

Sheet 조아라04
A1: 작품명 | B1: 작품코드 | C1: 작가명 | D1: 단가 | E1: 판매건수 | F1: 비율 | G1: 정산금액 | H1: 출판사명
A2: 호접몽전 | B2: 1438404 | C2: 청빙 | D2: 100 | E2: 30 | F2: 0.6 | G2: 1800
A3: 문답무용 - 삼국지 유비의 모사가 되었다 | B3: 1533756 | C3: 청빙 | D3: 100 | E3: 252 | F3: 0.6 | G3: 15120

Sheet 톡소다04
A1: 상품구분 | B1: 대분류 | C1: 중분류 | D1: 바코드 | E1: 상품명 | F1: 판매채널 | G1: 저자 | H1: 회차수 | I1: 공급사 | J1: 구분 | K1: 정가 | L1: 판매가 | M1: 정산대상 기준 판매금액 | N1: 수량 | O1: 총판매금액 | P1: 정산대상 기준 총 판매금액 | Q1: 정산율 | R1: 정산금액 | S1: 출판사
A2: 웹소설 | B2: 판타지 | C2: 퓨전 | D2: 76M2012152412 | E2: 삼국지 호접몽전 | F2: ANDROID | G2: 청빙 | H2: 812 | I2: 스토리위즈(주) | J2: 소장 판매 | K2: 100 | L2: 100 | M2: 100 | N2: 1 | O2: 100 | P2: 100 | Q2: 70 | R2: 70 | S2: 스토리위즈

Sheet 알라딘04
A1: 판매/취소일시 | B1: ItemId | C1: 제목 | D1: 판매형태 | E1: 정가 | F1: 판매가 | G1: 정산액 | H1: 원주문일시 | I1: 저자명 | J1: 출판사명 | K1: 정산처명 | L1: ISBN
A2: 44655.494 | B2: 273042791 | C2: [세트] 라스트 서바이버 : 진화로 살아남아라! (총13권/완결) | D2: 판매 | E2: 38400 | F2: 38400 | G2: 26880 | I2: 최영진(청빙) | J2: 스토리위즈 | K2: 스토리위즈 | L2: 9791137601000
G3: =SUM(G2) -> 26880

Sheet 블라이스04
A1: 판매월 | B1: 정산월 | C1: 작품명 | D1: 출판사 | E1: 작품NO | F1: CP명 | G1: CP순번 | H1: 닉네임 | I1: 필명 | J1: 판매액 | P1: 수수료(결제 대행 수수료 + 블라이스 운영 수수료) | V1: 정산금액
J2: 전체 | K2: PC웹/모바일웹 | L2: 구글플레이 | M2: 애플앱스토어 | N2: 원스토어 | O2: 블라이스증정 | P2: 전체 | Q2: PC웹/모바일웹 | R2: 구글플레이 | S2: 애플앱스토어 | T2: 원스토어 | U2: 블라이스증정
A3: 2022.04 | B3: 2022.05 | C3: 문답무용 - 삼국지 유비의 모사가 되었다 | D3: 스토리위즈 | E3: 38539 | F3: 케이티블라이스 | G3: 129981 | H3: 케이티블라이스 | I3: 청빙 | J3: 145900 | K3: 75100 | L3: 13900 | M3: 0 | N3: 0 | O3: 56900 | P3: 145900 | Q3: 75100 | R3: 13900 | S3: 0 | T3: 0 | U3: 56900 | V3: 102130
A4: 2022.04 | B4: 2022.05 | C4: 호접몽전 | D4: 스토리위즈 | E4: 16486 | F4: 케이티 | G4: 100569 | H4: 케이티 | I4: 청빙 | J4: 5400 | K4: 0 | L4: 0 | M4: 0 | N4: 0 | O4: 5400 | P4: 5400 | Q4: 0 | R4: 0 | S4: 0 | T4: 0 | U4: 5400 | V4: 3780
V5: =SUM(V3:V4) -> 105910

Sheet 네이버APP04_장유진
A1: 구분 | B1: 컨텐츠 | C1: 컨텐츠No | D1: 공급자코드 | E1: CP명 | F1: 작가명 | G1: 출판사 | H1: 나이제한 | I1: 서비스일 | J1: 건수 | K1: 비정산 | L1: 무료이용권 | M1: 유상쿠키 | N1: 무상쿠키 | O1: 유상i쿠키 | P1: 무상i쿠키 | Q1: 유상자동충전쿠키 | R1: 무상자동충전쿠키 | S1: 건수 | T1: 비정산 | U1: 무료이용권 | V1: 유상쿠키 | W1: 무상쿠키 | X1: 유상i쿠키 | Y1: 무상i쿠키 | Z1: 유상자동충전쿠키 | AA1: 무상자동충전쿠키 | AB1: 건수 | AC1: 유상 | AD1: 무상 | AE1: 건수 | AF1: 유상 | AG1: 무상 | AH1: 건수 | AI1: 유상 | AJ1: 무상 | AK1: 건수 | AL1: 유상 | AM1: 무상 | AN1: i쿠키 수수료 | AO1: 건수 | AP1: 유상 | AQ1: 무상 | AR1: 건수 | AS1: 유상 | AT1: 무상 | AU1: 합계 | AV1: 순매출(합계-수수료) | AW1: SW매출
A2: 시리즈(APP) | B2: 절대자의 귀환 | C2: 422032 | E2: 스토리위즈_1 | F2: 장유진 | G2: 스토리위즈 | H2: 12세 이상 이용가능 | I2: 2021.01.19 | J2: 0 | K2: 0 | L2: 0 | M2: 0 | N2: 0 | O2: 0 | P2: 0 | Q2: 0 | R2: 0 | S2: 0 | T2: 0 | U2: 0 | V2: 0 | W2: 0 | X2: 0 | Y2: 0 | Z2: 0 | AA2: 0 | AB2: 0 | AC2: 0 | AD2: 0 | AE2: 0 | AF2: 0 | AG2: 0 | AH2: 0 | AI2: 0 | AJ2: 0 | AK2: 0 | AL2: 0 | AM2: 0 | AN2: 0 | AO2: 0 | AP2: 0 | AQ2: 0 | AR2: 0 | AS2: 0 | AT2: 0 | AU2: 168300 | AV2: 168300 | AW2: 117810
A3: 시리즈(APP) | B3: 절대자의 귀환 [단행본] | C3: 430085 | E3: 스토리위즈_1 | F3: 장유진 | G3: 스토리위즈 | H3: 12세 이상 이용가능 | I3: 2021.04.15 | J3: 0 | K3: 0 | L3: 0 | M3: 0 | N3: 0 | O3: 0 | P3: 0 | Q3: 0 | R3: 0 | S3: 0 | T3: 0 | U3: 0 | V3: 0 | W3: 0 | X3: 0 | Y3: 0 | Z3: 0 | AA3: 0 | AB3: 0 | AC3: 0 | AD3: 0 | AE3: 0 | AF3: 0 | AG3: 0 | AH3: 0 | AI3: 0 | AJ3: 0 | AK3: 0 | AL3: 0 | AM3: 0 | AN3: 0 | AO3: 0 | AP3: 0 | AQ3: 0 | AR3: 0 | AS3: 0 | AT3: 0 | AU3: 9600 | AV3: 9600 | AW3: 6720
A4: 완전판APP | B4: 절대자의 귀환 | C4: 422032 | E4: 스토리위즈_1 | F4: 장유진 | G4: 스토리위즈 | H4: 12세 이상 이용가능 | I4: 2021.01.19 | J4: 0 | K4: 0 | L4: 0 | M4: 0 | N4: 0 | O4: 0 | P4: 0 | Q4: 0 | R4: 0 | S4: 0 | T4: 0 | U4: 0 | V4: 0 | W4: 0 | X4: 0 | Y4: 0 | Z4: 0 | AA4: 0 | AB4: 0 | AC4: 0 | AD4: 0 | AE4: 0 | AF4: 0 | AG4: 0 | AH4: 0 | AI4: 0 | AJ4: 0 | AK4: 0 | AL4: 0 | AM4: 0 | AN4: 0 | AO4: 0 | AP4: 0 | AQ4: 0 | AR4: 0 | AS4: 0 | AT4: 0 | AU4: 17500 | AV4: 17500 | AW4: 12250
A5: 시리즈(IOS) | B5: 절대자의 귀환 | C5: 422032 | E5: 스토리위즈_1 | F5: 장유진 | G5: 스토리위즈 | H5: 12세 이상 이용가능 | I5: 2021.01.19 | J5: 0 | K5: 0 | L5: 0 | M5: 0 | N5: 0 | O5: 0 | P5: 0 | Q5: 0 | R5: 0 | S5: 0 | T5: 0 | U5: 0 | V5: 0 | W5: 0 | X5: 0 | Y5: 0 | Z5: 0 | AA5: 0 | AB5: 0 | AC5: 0 | AD5: 0 | AE5: 0 | AF5: 0 | AG5: 0 | AH5: 0 | AI5: 0 | AJ5: 0 | AK5: 0 | AL5: 0 | AM5: 0 | AN5: 35.1 | AO5: 0 | AP5: 0 | AQ5: 0 | AR5: 0 | AS5: 0 | AT5: 0 | AU5: 16817 | AV5: 16781.9 | AW5: 11747.33
AW6: =SUM(AW2:AW5) -> 148527.33

Sheet 리디북스04_장유진
A1: 시리즈 ID | B1: 도서 ID | C1: 제목 | D1: 권/화수 | E1: 저자 | F1: 역자 | G1: 그림 | H1: 출판사 | I1: 시리즈명 | J1: 전자책정가 | K1: 단권판매액 | L1: 단권판매권 | M1: 단권무료권 | N1: 대여액 | O1: 대여유료권( ~ 2020-04 대여권) | P1: 대여무료권 | Q1: 자유다운금액 | R1: 자유다운권 | S1: 세트판매액 | T1: 세트판매권 | U1: 세트대여액 | V1: 세트대여권 | W1: 취소단권판매액 | X1: 취소단권판매권 | Y1: 취소대여액 | Z1: 취소대여권 | AA1: 취소자유다운액 | AB1: 취소자유다운권 | AC1: 취소세트판매액 | AD1: 취소세트판매권 | AE1: 취소세트대여액 | AF1: 취소세트대여권 | AG1: 판매액 | AH1: 판매권 | AI1: 취소액 | AJ1: 취소권 | AK1: 일반 판매액 | AL1: 일반 취소액 | AM1: 앱마켓 정산대상액 | AN1: 앱마켓 수수료(30%) | AO1: 앱마켓 취소액 | AP1: 정산액 | AQ1: 종이책ISBN10 | AR1: 종이책ISBN13 | AS1: 전자책ISBN10 | AT1: 전자책ISBN13 | AU1: CP 관리 ID | AV1: 카테고리1 | AW1: 카테고리2
A2: 2313010576 | B2: 2313010577 | C2: [e북]절대자의 귀환 2권 | D2: 2 | E2: 장유진 | H2: 스토리위즈 | I2: [e북]절대자의 귀환 | J2: 3200 | K2: 6400 | L2: 2 | M2: 0 | N2: 0 | O2: 0 | P2: 0 | Q2: 0 | R2: 0 | S2: 0 | T2: 0 | U2: 0 | V2: 0 | W2: 0 | X2: 0 | Y2: 0 | Z2: 0 | AA2: 0 | AB2: 0 | AC2: 0 | AD2: 0 | AE2: 0 | AF2: 0 | AG2: 6400 | AH2: 2 | AI2: 0 | AJ2: 0 | AK2: 6400 | AL2: 0 | AM2: 0 | AN2: 0 | AO2: 0 | AP2: 4480 | AT2: 9791166069772 | AV2: 판타지 e북 > 퓨전 판타지
A3: 2313010576 | B3: 2313010578 | C3: [e북]절대자의 귀환 3권 | D3: 3 | E3: 장유진 | H3: 스토리위즈 | I3: [e북]절대자의 귀환 | J3: 3200 | K3: 3200 | L3: 1 | M3: 0 | N3: 0 | O3: 0 | P3: 0 | Q3: 0 | R3: 0 | S3: 0 | T3: 0 | U3: 0 | V3: 0 | W3: 0 | X3: 0 | Y3: 0 | Z3: 0 | AA3: 0 | AB3: 0 | AC3: 0 | AD3: 0 | AE3: 0 | AF3: 0 | AG3: 3200 | AH3: 1 | AI3: 0 | AJ3: 0 | AK3: 3200 | AL3: 0 | AM3: 0 | AN3: 0 | AO3: 0 | AP3: 2240 | AT3: 9791166069789 | AV3: 판타지 e북 > 퓨전 판타지
A4: 2313010576 | B4: 2313010579 | C4: [e북]절대자의 귀환 4권 | D4: 4 | E4: 장유진 | H4: 스토리위즈 | I4: [e북]절대자의 귀환 | J4: 3200 | K4: 3200 | L4: 1 | M4: 0 | N4: 0 | O4: 0 | P4: 0 | Q4: 0 | R4: 0 | S4: 0 | T4: 0 | U4: 0 | V4: 0 | W4: 0 | X4: 0 | Y4: 0 | Z4: 0 | AA4: 0 | AB4: 0 | AC4: 0 | AD4: 0 | AE4: 0 | AF4: 0 | AG4: 3200 | AH4: 1 | AI4: 0 | AJ4: 0 | AK4: 3200 | AL4: 0 | AM4: 0 | AN4: 0 | AO4: 0 | AP4: 2240 | AT4: 9791166069796 | AV4: 판타지 e북 > 퓨전 판타지
A5: 2313010364 | B5: 2313010389 | C5: 절대자의 귀환 26화 | D5: 26 | E5: 장유진 | H5: 스토리위즈 | I5: 절대자의 귀환 | J5: 100 | K5: 100 | L5: 1 | M5: 0 | N5: 0 | O5: 0 | P5: 0 | Q5: 0 | R5: 0 | S5: 0 | T5: 0 | U5: 0 | V5: 0 | W5: 0 | X5: 0 | Y5: 0 | Z5: 0 | AA5: 0 | AB5: 0 | AC5: 0 | AD5: 0 | AE5: 0 | AF5: 0 | AG5: 100 | AH5: 1 | AI5: 0 | AJ5: 0 | AK5: 100 | AL5: 0 | AM5: 0 | AN5: 0 | AO5: 0 | AP5: 70 | AT5: 9791166069154 | AV5: 판타지 웹소설 > 퓨전 판타지
A6: 2313010364 | B6: 2313010390 | C6: 절대자의 귀환 27화 | D6: 27 | E6: 장유진 | H6: 스토리위즈 | I6: 절대자의 귀환 | J6: 100 | K6: 100 | L6: 1 | M6: 0 | N6: 0 | O6: 0 | P6: 0 | Q6: 0 | R6: 0 | S6: 0 | T6: 0 | U6: 0 | V6: 0 | W6: 0 | X6: 0 | Y6: 0 | Z6: 0 | AA6: 0 | AB6: 0 | AC6: 0 | AD6: 0 | AE6: 0 | AF6: 0 | AG6: 100 | AH6: 1 | AI6: 0 | AJ6: 0 | AK6: 100 | AL6: 0 | AM6: 0 | AN6: 0 | AO6: 0 | AP6: 70 | AT6: 9791166069154 | AV6: 판타지 웹소설 > 퓨전 판타지
A7: 2313010364 | B7: 2313010391 | C7: 절대자의 귀환 28화 | D7: 28 | E7: 장유진 | H7: 스토리위즈 | I7: 절대자의 귀환 | J7: 100 | K7: 100 | L7: 1 | M7: 0 | N7: 0 | O7: 0 | P7: 0 | Q7: 0 | R7: 0 | S7: 0 | T7: 0 | U7: 0 | V7: 0 | W7: 0 | X7: 0 | Y7: 0 | Z7: 0 | AA7: 0 | AB7: 0 | AC7: 0 | AD7: 0 | AE7: 0 | AF7: 0 | AG7: 100 | AH7: 1 | AI7: 0 | AJ7: 0 | AK7: 100 | AL7: 0 | AM7: 0 | AN7: 0 | AO7: 0 | AP7: 70 | AT7: 9791166069154 | AV7: 판타지 웹소설 > 퓨전 판타지
A8: 2313010364 | B8: 2313010392 | C8: 절대자의 귀환 29화 | D8: 29 | E8: 장유진 | H8: 스토리위즈 | I8: 절대자의 귀환 | J8: 100 | K8: 100 | L8: 1 | M8: 0 | N8: 0 | O8: 0 | P8: 0 | Q8: 0 | R8: 0 | S8: 0 | T8: 0 | U8: 0 | V8: 0 | W8: 0 | X8: 0 | Y8: 0 | Z8: 0 | AA8: 0 | AB8: 0 | AC8: 0 | AD8: 0 | AE8: 0 | AF8: 0 | AG8: 100 | AH8: 1 | AI8: 0 | AJ8: 0 | AK8: 100 | AL8: 0 | AM8: 0 | AN8: 0 | AO8: 0 | AP8: 70 | AT8: 9791166069154 | AV8: 판타지 웹소설 > 퓨전 판타지
A9: 2313010364 | B9: 2313010393 | C9: 절대자의 귀환 30화 | D9: 30 | E9: 장유진 | H9: 스토리위즈 | I9: 절대자의 귀환 | J9: 100 | K9: 100 | L9: 1 | M9: 0 | N9: 0 | O9: 0 | P9: 0 | Q9: 0 | R9: 0 | S9: 0 | T9: 0 | U9: 0 | V9: 0 | W9: 0 | X9: 0 | Y9: 0 | Z9: 0 | AA9: 0 | AB9: 0 | AC9: 0 | AD9: 0 | AE9: 0 | AF9: 0 | AG9: 100 | AH9: 1 | AI9: 0 | AJ9: 0 | AK9: 100 | AL9: 0 | AM9: 0 | AN9: 0 | AO9: 0 | AP9: 70 | AT9: 9791166069154 | AV9: 판타지 웹소설 > 퓨전 판타지
A10: 2313010364 | B10: 2313010394 | C10: 절대자의 귀환 31화 | D10: 31 | E10: 장유진 | H10: 스토리위즈 | I10: 절대자의 귀환 | J10: 100 | K10: 100 | L10: 1 | M10: 0 | N10: 0 | O10: 0 | P10: 0 | Q10: 0 | R10: 0 | S10: 0 | T10: 0 | U10: 0 | V10: 0 | W10: 0 | X10: 0 | Y10: 0 | Z10: 0 | AA10: 0 | AB10: 0 | AC10: 0 | AD10: 0 | AE10: 0 | AF10: 0 | AG10: 100 | AH10: 1 | AI10: 0 | AJ10: 0 | AK10: 100 | AL10: 0 | AM10: 0 | AN10: 0 | AO10: 0 | AP10: 70 | AT10: 9791166069154 | AV10: 판타지 웹소설 > 퓨전 판타지
A11: 2313010364 | B11: 2313010395 | C11: 절대자의 귀환 32화 | D11: 32 | E11: 장유진 | H11: 스토리위즈 | I11: 절대자의 귀환 | J11: 100 | K11: 100 | L11: 1 | M11: 0 | N11: 0 | O11: 0 | P11: 0 | Q11: 0 | R11: 0 | S11: 0 | T11: 0 | U11: 0 | V11: 0 | W11: 0 | X11: 0 | Y11: 0 | Z11: 0 | AA11: 0 | AB11: 0 | AC11: 0 | AD11: 0 | AE11: 0 | AF11: 0 | AG11: 100 | AH11: 1 | AI11: 0 | AJ11: 0 | AK11: 100 | AL11: 0 | AM11: 0 | AN11: 0 | AO11: 0 | AP11: 70 | AT11: 9791166069154 | AV11: 판타지 웹소설 > 퓨전 판타지
A12: 2313010364 | B12: 2313010364 | C12: 절대자의 귀환 1화 | D12: 1 | E12: 장유진 | H12: 스토리위즈 | I12: 절대자의 귀환 | J12: 0 | K12: 0 | L12: 0 | M12: 6 | N12: 0 | O12: 0 | P12: 0 | Q12: 0 | R12: 0 | S12: 0 | T12: 0 | U12: 0 | V12: 0 | W12: 0 | X12: 0 | Y12: 0 | Z12: 0 | AA12: 0 | AB12: 0 | AC12: 0 | AD12: 0 | AE12: 0 | AF12: 0 | AG12: 0 | AH12: 6 | AI12: 0 | AJ12: 0 | AK12: 0 | AL12: 0 | AM12: 0 | AN12: 0 | AO12: 0 | AP12: 0 | AT12: 9791166069154 | AV12: 판타지 웹소설 > 퓨전 판타지
A13: 2313010364 | B13: 2313010365 | C13: 절대자의 귀환 2화 | D13: 2 | E13: 장유진 | H13: 스토리위즈 | I13: 절대자의 귀환 | J13: 0 | K13: 0 | L13: 0 | M13: 5 | N13: 0 | O13: 0 | P13: 0 | Q13: 0 | R13: 0 | S13: 0 | T13: 0 | U13: 0 | V13: 0 | W13: 0 | X13: 0 | Y13: 0 | Z13: 0 | AA13: 0 | AB13: 0 | AC13: 0 | AD13: 0 | AE13: 0 | AF13: 0 | AG13: 0 | AH13: 5 | AI13: 0 | AJ13: 0 | AK13: 0 | AL13: 0 | AM13: 0 | AN13: 0 | AO13: 0 | AP13: 0 | AT13: 9791166069154 | AV13: 판타지 웹소설 > 퓨전 판타지
... A37: 2313010576 | B37: 2313010576 | C37: [e북]절대자의 귀환 1권 | D37: 1 | E37: 장유진 | H37: 스토리위즈 | I37: [e북]절대자의 귀환 | J37: 0 | K37: 0 | L37: 0 | M37: 5 | N37: 0 | O37: 0 | P37: 0 | Q37: 0 | R37: 0 | S37: 0 | T37: 0 | U37: 0 | V37: 0 | W37: 0 | X37: 0 | Y37: 0 | Z37: 0 | AA37: 0 | AB37: 0 | AC37: 0 | AD37: 0 | AE37: 0 | AF37: 0 | AG37: 0 | AH37: 5 | AI37: 0 | AJ37: 0 | AK37: 0 | AL37: 0 | AM37: 0 | AN37: 0 | AO37: 0 | AP37: 0 | AT37: 9791166069765 | AV37: 판타지 e북 > 퓨전 판타지
AP38: =SUM(AP2:AP37) -> 9450

Sheet 무툰04_장유진
A1: NO | B1: 작가 | C1: 타이틀 | D1: 플랫폼 | E1: 코인 | F1: 금액 | G1: 코인 | H1: 금액 | I1: 코인 | J1: 금액 | K1: 결제 | L1: 이벤트 | M1: 수수료공제액 | N1: 정산비율 | O1: 정산액
A2: 49 | B2: 장유진 | C2: 절대자의 귀환 | D2: M | E2: 0 | F2: 0 | G2: 0 | H2: 0 | I2: 0 | J2: 0 | K2: 0 | L2: 0 | M2: 0 | O2: 0
A3: 49 | B3: 장유진 | C3: 절대자의 귀환 | D3: W | E3: 0 | F3: 0 | G3: 0 | H3: 0 | I3: 0 | J3: 0 | K3: 0 | L3: 0 | M3: 0 | O3: 0
A4: 49 | B4: 장유진 | C4: 절대자의 귀환 | D4: A | E4: 13 | F4: 1300 | G4: 13 | H4: 1300 | I4: 13 | J4: 1300 | K4: 0 | L4: 0 | M4: 1300 | O4: 910
O5: =SUM(O2:O4) -> 910

Sheet 문피아04_장유진
A1: 날짜 | B1: 구분 | C1: 작가 | D1: 계정 | E1: 작품코드 | F1: 작품 | G1: 구매 | H1: 구매취소 | I1: 대여 | J1: 대여취소 | K1: 총매출 | L1: IOS매출 | M1: 정산
A2: 2022.03 | B2: 문피아 | C2: 장유진 | D2: kt_0601 | E2: 259015 | F2: 절대자의 귀환 [D] | G2: 2 | H2: 0 | I2: 0 | J2: 0 | K2: 6400 | L2: 0 | M2: 4032
A3: 2022.03 | B3: 문피아 | C3: 장유진 | D3: kt_0601 | E3: 252421 | F3: 절대자의 귀환 [장유진 작가 - 퓨전판타지 소설] | G3: 22 | H3: 0 | I3: 0 | J3: 0 | K3: 2200 | L3: 0 | M3: 1386
M4: =SUM(M2:M3) -> 5418

Sheet 미스터블루04_장유진
A1: 작품명 | B1: 작가명 | C1: 코드 | D1: 정액_건수 | E1: 정액_매출액 | F1: 정액_정산액 | G1: 블루머니_권별대여_건수 | H1: 블루머니_권별대여_이용권(화) 수 | I1: 블루머니_권별대여_매출액 | J1: 블루머니_권별소장_건수 | K1: 블루머니_권별소장_이용권(화) 수 | L1: 블루머니_권별소장_매출액 | M1: 블루머니_전권대여_건수 | N1: 블루머니_전권대여_이용권(화) 수 | O1: 블루머니_전권대여_매출액 | P1: 블루머니_전권소장_건수 | Q1: 블루머니_전권소장_이용권(화) 수 | R1: 블루머니_전권소장_매출액 | S1: A.앱머니_권별대여_건수 | T1: A.앱머니_권별대여_이용권(화) 수 | U1: A.앱머니_권별대여_매출액 | V1: A.앱머니_권별소장_건수 | W1: A.앱머니_권별소장_이용권(화) 수 | X1: A.앱머니_권별소장_매출액 | Y1: A.앱머니_전권대여_건수 | Z1: A.앱머니_전권대여_이용권(화) 수 | AA1: A.앱머니_전권대여_매출액 | AB1: A.앱머니_전권소장_건수 | AC1: A.앱머니_전권소장_이용권(화) 수 | AD1: A.앱머니_전권소장_매출액 | AE1: 계_건수 | AF1: 계_이용권(화)수 | AG1: 계_매출액 | AH1: 계_정산액 | AI1: 매출액 | AJ1: 정산액
A2: 절대자의 귀환 | B2: 장유진 | D2: 0 | E2: 0 | F2: 0 | G2: 0 | H2: 0 | I2: 0 | J2: 1 | K2: 1 | L2: 3200 | M2: 0 | N2: 0 | O2: 0 | P2: 0 | Q2: 0 | R2: 0 | S2: 0 | T2: 0 | U2: 0 | V2: 0 | W2: 0 | X2: 0 | Y2: 0 | Z2: 0 | AA2: 0 | AB2: 0 | AC2: 0 | AD2: 0 | AE2: 1 | AF2: 1 | AG2: 3200 | AH2: 2016 | AI2: 3200 | AJ2: 2016
A3: 절대자의 귀환 (연재) | B3: 장유진 | D3: 0 | E3: 0 | F3: 0 | G3: 0 | H3: 0 | I3: 0 | J3: 40 | K3: 40 | L3: 4000 | M3: 0 | N3: 0 | O3: 0 | P3: 0 | Q3: 0 | R3: 0 | S3: 0 | T3: 0 | U3: 0 | V3: 0 | W3: 0 | X3: 0 | Y3: 0 | Z3: 0 | AA3: 0 | AB3: 0 | AC3: 0 | AD3: 0 | AE3: 40 | AF3: 40 | AG3: 4000 | AH3: 2520 | AI3: 4000 | AJ3: 2520
AJ4: =SUM(AJ2:AJ3) -> 4536

Sheet 카카오04_장유진
A1: 특별/일반 | B1: 사업자명 | C1: 사업자번호 | D1: 발행자명 | E1: 계약UID | F1: 계약유형 | G1: 계약(과/면세) | H1: 당월신규계약여부 | I1: 카테고리 | J1: 시리즈ID | K1: 시리즈명 | L1: 발행자가 부여하는 코드 | M1: 레이블 | N1: 작가명 | O1: ISBN(유/무) | P1: CP정산율_안드로이드/이벤트캐시 | Q1: CP정산율_iOS | R1: 이용권 종류 | S1: 이용권 금액 | T1: 캐시_합계 | U1: 캐시_CPP | V1: 캐시_CPI | W1: 캐시_CP1 | X1: 캐시_CP2 | Y1: 캐시_CP3 | Z1: 캐시_CP7 | AA1: 캐시_CP8 | AB1: 캐시_CP9 | AC1: 캐시_이벤트캐시 | AD1: 원화_합계 | AE1: 원화_CPP | AF1: 원화_CPI | AG1: 원화_CP1 | AH1: 원화_CP2 | AI1: 원화_CP3 | AJ1: 원화_CP7 | AK1: 원화_CP8 | AL1: 원화_CP9 | AM1: 원화_이벤트캐시 | AN1: 공급가액 | AO1: 부가세 | AP1: 공급대가
A2: 일반계약 | B2: 주식회사 스토리위즈 | C2: 3828601768 | D2: 스토리위즈 | G2: 면세 | H2: N | I2: 소설 | J2: 56372121 | K2: 절대자의 귀환 | N2: 장유진 | O2: Y | P2: 0.7 | Q2: 0.6 | R2: 단일 이용권 | S2: 100 | T2: 2100 | U2: 300 | V2: 0 | W2: 0 | X2: 0 | Y2: 0 | Z2: 0 | AA2: 0 | AB2: 0 | AC2: 1800 | AD2: 2100 | AE2: 300 | AF2: 0 | AG2: 0 | AH2: 0 | AI2: 0 | AJ2: 0 | AK2: 0 | AL2: 0 | AM2: 1800 | AN2: 1470 | AO2: 0 | AP2: 1470
A3: 일반계약 | B3: 주식회사 스토리위즈 | C3: 3828601768 | D3: 스토리위즈 | G3: 면세 | H3: N | I3: 소설 | J3: 56372121 | K3: 절대자의 귀환 | N3: 장유진 | O3: Y | P3: 0.7 | Q3: 0.6 | R3: 시리즈 이용권 패키지 | S3: 2400 | T3: 4800 | U3: 0 | V3: 0 | W3: 0 | X3: 0 | Y3: 0 | Z3: 0 | AA3: 0 | AB3: 0 | AC3: 4800 | AD3: 4800 | AE3: 0 | AF3: 0 | AG3: 0 | AH3: 0 | AI3: 0 | AJ3: 0 | AK3: 0 | AL3: 0 | AM3: 4800 | AN3: 3360 | AO3: 0 | AP3: 3360
A4: 일반계약 | B4: 주식회사 스토리위즈 | C4: 3828601768 | D4: 스토리위즈 | G4: 면세 | H4: N | I4: 소설 | J4: 56372121 | K4: 절대자의 귀환 | N4: 장유진 | O4: Y | P4: 0.7 | Q4: 0.6 | R4: 시리즈 이용권 패키지 | S4: 13500 | T4: 1100 | U4: 1100 | V4: 0 | W4: 0 | X4: 0 | Y4: 0 | Z4: 0 | AA4: 0 | AB4: 0 | AC4: 0 | AD4: 1100 | AE4: 1100 | AF4: 0 | AG4: 0 | AH4: 0 | AI4: 0 | AJ4: 0 | AK4: 0 | AL4: 0 | AM4: 0 | AN4: 770 | AO4: 0 | AP4: 770
AP5: =SUM(AP2:AP4) -> 5600
