Workbook
Name AFFMST: [1]AFFMST!$A$1:$E$42
Name coin_domestic_total_no_tax: [2]コイン内訳!$K$17
Name coin_oversea_total: [2]コイン内訳!$L$17
Name coin_report_rs_ratio: '[2]コイン報告書_foreign CP'!$P$27
Name direct_apple_domestic_total_no_tax: [2]内訳_公式決済!$D$10
Name direct_apple_oversea_total: [2]内訳_公式決済!$E$10
Name direct_google_domestic_total_no_tax: [2]内訳_公式決済!$G$10
Name direct_google_oversea_total: [2]内訳_公式決済!$H$10
Name direct_item: '[2]コイン報告書_foreign CP'!#REF!
Name direct_item: '[2]コイン報告書_foreign CP'!#REF!
Name direct_items: '[2]コイン報告書_foreign CP'!#REF!
Name direct_items: '[2]コイン報告書_foreign CP'!#REF!
Name direct_report_rs_ratio: '[2]コイン報告書_foreign CP'!$P$32
Name direct_report_ym: '[2]コイン報告書_foreign CP'!#REF!
Name direct_report_ym: '[2]コイン報告書_foreign CP'!#REF!
Name withholdingtaxrate: '[2]コイン報告書_foreign CP'!$W$36
Name ws_items: '[2]コイン報告書_foreign CP'!#REF!
Name ws_items: '[2]コイン報告書_foreign CP'!#REF!
Name ws_report_rs_ratio: '[2]コイン報告書_foreign CP'!#REF!
Name ws_report_rs_ratio: '[2]コイン報告書_foreign CP'!#REF!
Name ws_report_rs_ratio1: '[2]コイン報告書_foreign CP'!#REF!
Name ws_report_rs_ratio1: '[2]コイン報告書_foreign CP'!#REF!
Name ws_report_rs_ratio2: '[2]コイン報告書_foreign CP'!#REF!
Name ws_report_rs_ratio2: '[2]コイン報告書_foreign CP'!#REF!
Name ws_report_ym: '[2]コイン報告書_foreign CP'!#REF!
Name ws_report_ym: '[2]コイン報告書_foreign CP'!#REF!
Name ㄹㄹ: '[2]コイン報告書_foreign CP'!#REF!
Name ㄹㄹ: '[2]コイン報告書_foreign CP'!#REF!
Name ㅇ: '[2]コイン報告書_foreign CP'!#REF!
Name ㅇ: '[2]コイン報告書_foreign CP'!#REF!
Name ㅇㅇ: '[2]コイン報告書_foreign CP'!#REF!
Name ㅇㅇ: '[2]コイン報告書_foreign CP'!#REF!
Name ㅇㅇㅇㅇㅇㅇㅇ: '[2]コイン報告書_foreign CP'!#REF!
Name 타이틀명: [3]hidden!$A$2:$A$120
Name 테스트: '[2]コイン報告書_foreign CP'!#REF!

Sheet 합계
A1: 04월 | B1: 플랫폼별 매출내역
B2: 유통처 | C2: 스토리위즈 매출액 | D2: 작가 정산액
B3: 교보문고 | C3: 31777
B4: 구글북스 | C4: 40320
B5: 네이버APP | C5: 303131
B6: 네이버PC | C6: 1610
B7: 리디북스 | C7: 81697
B8: 무툰 | C8: =무툰04!O5 -> 2240
B9: 문피아 | C9: 32256
B10: 미스터블루 | C10: =미스터블루04!AJ4 -> 158035.5
B11: 스낵북 | C11: =스낵북04!F3 -> 0
B12: 원스토어 | C12: 483280
B13: 조아라 | C13: 18480
B14: 코미코 | C14: 16499
B15: 톡소다 | C15: 15610
B16: 하이북 | C16: 490
B17: 한아름 | C17: 14112
B18: 카카오 | C18: =카카오04!AP19 -> 750850
B19: 합계 | C19: =SUM(C3:C18) -> 1950387.5 | D19: =ROUND(SUM(D3:D17),0) -> 0

Sheet MG차감내역04
B2: 구분 | D2: 금액
B3: 선MG | D3: 100000000
B4: 보증보험료 | D4: 3390000
B5: 합계 | D5: 103390000
B7: 대상월 | C7: 차감액 | D7: 잔여 선MG
B8: 44287 | C8: 4630973.7 | D8: =D5-C8 -> 98759026
B9: 44317 | C9: 7141839.4 | D9: =D8-C9 -> 91617187
B10: 44348 | C10: 3158668.2 | D10: =D9-C10 -> 88458519
B11: 44378 | C11: 1944171.7 | D11: =D10-C11 -> 86514347
B12: 44409 | C12: 5592019.1 | D12: =D11-C12 -> 80922328
B13: 44440 | C13: 4194383.9 | D13: =D12-C13 -> 76727944
B14: 44470 | C14: 3744837.8 | D14: =D13-C14 -> 72983106
B15: 44501 | C15: 2146611 | D15: =D14-C15 -> 70836495
B16: 44531 | C16: 1978371.5 | D16: =D15-C16 -> 68858124
B17: 44562 | C17: 1692101.8 | D17: =D16-C17 -> 67166022
B18: 44593 | C18: 12269957 | D18: =D17-C18 -> 54896065
B19: 44621 | C19: =[4]합계03!C18 -> 3596683.7 | D19: =D18-C19 -> 51299381
B20: 44652 | C20: =합계!C19 -> 1950387.5 | D20: =D19-C20 -> 49348994

Sheet 교보문고04
A1: 판매구분 | B1: 판매형태 | C1: 상품 | D1: 대분류 | E1: 도서바코드 | F1: ISBN | G1: EPUB ISBN | H1: PDF ISBN | I1: 상품명 | J1: 회차명 | K1: 저자명 | L1: 정가 | M1: 판매가 | N1: 판매량 | O1: 다운로드수 | P1: 정산대상판매가 | Q1: 정산대상판매총액 | R1: 지불액 | S1: 정산율(%) | T1: 출판사
A2: B2C | B2: 대여 | C2: eBook | D2: 장르소설>판타지 | E2: 480D191034910 | F2: D191034910 | I2: 나 혼자만 일일 보상 | J2: 5권 | K2: 이동열 | L2: 630 | M2: 630 | N2: 6 | O2: 0 | P2: 630 | Q2: 3,780 | R2: 2646 | S2: 70 | T2: 스토리위즈
A3: B2C | B3: 대여 | C3: eBook | D3: 장르소설>판타지 | E3: 480D191034930 | F3: D191034930 | I3: 나 혼자만 일일 보상 | J3: 7권 | K3: 이동열 | L3: 900 | M3: 630 | N3: 1 | O3: 0 | P3: 630 | Q3: 630 | R3: 441 | S3: 70 | T3: 스토리위즈
A4: B2C | B4: 대여 | C4: eBook | D4: 장르소설>판타지 | E4: 480D191034860 | F4: D191034860 | I4: 나 혼자만 일일 보상 | J4: 3권 | K4: 이동열 | L4: 900 | M4: 630 | N4: 2 | O4: 0 | P4: 630 | Q4: 1,260 | R4: 882 | S4: 70 | T4: 스토리위즈
A5: B2C | B5: 대여 | C5: eBook | D5: 장르소설>판타지 | E5: 480D191034830 | F5: D191034830 | I5: 나 혼자만 일일 보상 | J5: 2권 | K5: 이동열 | L5: 900 | M5: 630 | N5: 3 | O5: 0 | P5: 630 | Q5: 1,890 | R5: 1323 | S5: 70 | T5: 스토리위즈
A6: B2C | B6: 대여 | C6: eBook | D6: 장르소설>판타지 | E6: 480D191034830 | F6: D191034830 | I6: 나 혼자만 일일 보상 | J6: 2권 | K6: 이동열 | L6: 630 | M6: 630 | N6: 7 | O6: 0 | P6: 630 | Q6: 4,410 | R6: 3087 | S6: 70 | T6: 스토리위즈
A7: B2C | B7: 대여 | C7: eBook | D7: 장르소설>판타지 | E7: 480D191034920 | F7: D191034920 | I7: 나 혼자만 일일 보상 | J7: 6권 | K7: 이동열 | L7: 900 | M7: 630 | N7: 2 | O7: 0 | P7: 630 | Q7: 1,260 | R7: 882 | S7: 70 | T7: 스토리위즈
A8: B2C | B8: 대여 | C8: eBook | D8: 장르소설>판타지 | E8: 480D191034920 | F8: D191034920 | I8: 나 혼자만 일일 보상 | J8: 6권 | K8: 이동열 | L8: 630 | M8: 630 | N8: 6 | O8: 0 | P8: 630 | Q8: 3,780 | R8: 2646 | S8: 70 | T8: 스토리위즈
A9: B2C | B9: 대여 | C9: eBook | D9: 장르소설>판타지 | E9: 480D191034890 | F9: D191034890 | I9: 나 혼자만 일일 보상 | J9: 4권 | K9: 이동열 | L9: 900 | M9: 630 | N9: 2 | O9: 0 | P9: 630 | Q9: 1,260 | R9: 882 | S9: 70 | T9: 스토리위즈
A10: B2C | B10: 대여 | C10: eBook | D10: 장르소설>판타지 | E10: 480D191034890 | F10: D191034890 | I10: 나 혼자만 일일 보상 | J10: 4권 | K10: 이동열 | L10: 630 | M10: 630 | N10: 6 | O10: 0 | P10: 630 | Q10: 3,780 | R10: 2646 | S10: 70 | T10: 스토리위즈
A11: B2C | B11: 대여 | C11: eBook | D11: 장르소설>판타지 | E11: 480D191034860 | F11: D191034860 | I11: 나 혼자만 일일 보상 | J11: 3권 | K11: 이동열 | L11: 630 | M11: 630 | N11: 6 | O11: 0 | P11: 630 | Q11: 3,780 | R11: 2646 | S11: 70 | T11: 스토리위즈
A12: B2C | B12: 대여 | C12: eBook | D12: 장르소설>판타지 | E12: 480D191034930 | F12: D191034930 | I12: 나 혼자만 일일 보상 | J12: 7권 | K12: 이동열 | L12: 630 | M12: 630 | N12: 6 | O12: 0 | P12: 630 | Q12: 3,780 | R12: 2646 | S12: 70 | T12: 스토리위즈
A13: B2C | B13: 대여 | C13: eBook | D13: 장르소설>판타지 | E13: 480D191034940 | F13: D191034940 | I13: 나 혼자만 일일 보상 | J13: 8권 | K13: 이동열 | L13: 630 | M13: 630 | N13: 5 | O13: 0 | P13: 630 | Q13: 3,150 | R13: 2205 | S13: 70 | T13: 스토리위즈
... A25: B2BC | B25: 대여 | C25: eBook | D25: 장르소설>판타지 | E25: 26M0000044184 | F25: D191034940 | I25: 나 혼자만 일일 보상 | J25: 8권 | K25: 이동열 | L25: 630 | M25: 630 | N25: 1 | O25: 0 | P25: 630 | Q25: 630 | R25: 315 | S25: 50 | T25: 스토리위즈
A26: B2C | B26: 단권 | C26: eBook | D26: 장르소설>판타지 | E26: 480D191034960 | F26: D191034960 | I26: 나 혼자만 일일 보상. 외전 | K26: 이동열 | L26: 630 | M26: 630 | N26: 1 | O26: 0 | P26: 630 | Q26: 630 | R26: 441 | S26: 70 | T26: 스토리위즈
A27: B2C | B27: 단권 | C27: eBook | D27: 장르소설>판타지 | E27: 480D191034960 | F27: D191034960 | I27: 나 혼자만 일일 보상. 외전 | K27: 이동열 | L27: 900 | M27: 630 | N27: 1 | O27: 0 | P27: 630 | Q27: 630 | R27: 441 | S27: 70 | T27: 스토리위즈
A28: B2BC | B28: 대여 | C28: eBook | D28: 장르소설>판타지 | E28: 26M0000044183 | F28: D191034960 | I28: 나 혼자만 일일 보상. 외전 | K28: 이동열 | L28: 630 | M28: 630 | N28: 1 | O28: 0 | P28: 630 | Q28: 630 | R28: 315 | S28: 50 | T28: 스토리위즈
A29: B2BC | B29: 단권 | C29: eBook | D29: 장르소설>판타지 | E29: 480D191034960 | F29: D191034960 | G29: 9791159289668 | I29: 나 혼자만 일일 보상. 외전 | K29: 이동열 | L29: 3,200 | M29: 3,200 | N29: 1 | O29: 0 | P29: 3,200 | Q29: 3,200 | R29: 1600 | S29: 50 | T29: 스토리위즈

Sheet 구글북스04
A1: Earnings Date | B1: Transaction Date | C1: Id | D1: Product | E1: Type | F1: Preorder | G1: Qty | H1: Primary ISBN | I1: Imprint Name | J1: Title | K1: Author | L1: Original List Price Currency | M1: Original List Price | N1: List Price Currency | O1: List Price [tax inclusive] | P1: List Price [tax exclusive] | Q1: Country of Sale | R1: Publisher Revenue % | S1: Publisher Revenue | T1: Earnings Currency | U1: Earnings Amount | V1: 출판사
A2: 22. 4. 30. | B2: 22. 4. 9. | C2: ID:3102-4960-4649-22133 | D2: Single Purchase | E2: Sale | F2: None | G2: 1 | H2: 9791159289606 | I2: 스토리위즈 | J2: 나 혼자만 일일 보상 4권 | K2: 이동열 | L2: KRW | M2: 3200 | N2: KRW | O2: 3200 | P2: 3200 | Q2: KR | R2: 0.7 | S2: 2240 | T2: KRW | U2: 2240 | V2: 스토리위즈
A3: 22. 4. 30. | B3: 22. 4. 9. | C3: ID:3140-0397-7859-05490 | D3: Single Purchase | E3: Sale | F3: None | G3: 1 | H3: 9791159289583 | I3: 스토리위즈 | J3: 나 혼자만 일일 보상 2권 | K3: 이동열 | L3: KRW | M3: 3200 | N3: KRW | O3: 3200 | P3: 3200 | Q3: KR | R3: 0.7 | S3: 2240 | T3: KRW | U3: 2240 | V3: 스토리위즈
A4: 22. 4. 30. | B4: 22. 4. 9. | C4: ID:3162-0189-9003-62621 | D4: Single Purchase | E4: Sale | F4: None | G4: 1 | H4: 9791159289583 | I4: 스토리위즈 | J4: 나 혼자만 일일 보상 2권 | K4: 이동열 | L4: KRW | M4: 3200 | N4: KRW | O4: 3200 | P4: 3200 | Q4: KR | R4: 0.7 | S4: 2240 | T4: KRW | U4: 2240 | V4: 스토리위즈
A5: 22. 4. 30. | B5: 22. 4. 10. | C5: ID:3173-9367-6810-92105 | D5: Single Purchase | E5: Sale | F5: None | G5: 1 | H5: 9791159289590 | I5: 스토리위즈 | J5: 나 혼자만 일일 보상 3권 | K5: 이동열 | L5: KRW | M5: 3200 | N5: KRW | O5: 3200 | P5: 3200 | Q5: KR | R5: 0.7 | S5: 2240 | T5: KRW | U5: 2240 | V5: 스토리위즈
A6: 22. 4. 30. | B6: 22. 4. 10. | C6: ID:3149-2319-3973-78267 | D6: Single Purchase | E6: Sale | F6: None | G6: 1 | H6: 9791159289606 | I6: 스토리위즈 | J6: 나 혼자만 일일 보상 4권 | K6: 이동열 | L6: KRW | M6: 3200 | N6: KRW | O6: 3200 | P6: 3200 | Q6: KR | R6: 0.7 | S6: 2240 | T6: KRW | U6: 2240 | V6: 스토리위즈
A7: 22. 4. 30. | B7: 22. 4. 16. | C7: ID:3177-4156-7163-70165 | D7: Single Purchase | E7: Sale | F7: None | G7: 1 | H7: 9791159286575 | I7: 스토리위즈 | J7: 던전 공략 LIVE 2권 | K7: 이동열 | L7: KRW | M7: 3200 | N7: KRW | O7: 3200 | P7: 3200 | Q7: KR | R7: 0.7 | S7: 2240 | T7: KRW | U7: 2240 | V7: 스토리위즈
A8: 22. 4. 30. | B8: 22. 4. 18. | C8: ID:3106-1566-7012-88886 | D8: Single Purchase | E8: Sale | F8: None | G8: 1 | H8: 9791159289583 | I8: 스토리위즈 | J8: 나 혼자만 일일 보상 2권 | K8: 이동열 | L8: KRW | M8: 3200 | N8: KRW | O8: 3200 | P8: 3200 | Q8: KR | R8: 0.7 | S8: 2240 | T8: KRW | U8: 2240 | V8: 스토리위즈
A9: 22. 4. 30. | B9: 22. 4. 24. | C9: ID:3183-8734-3936-59438 | D9: Single Purchase | E9: Sale | F9: None | G9: 1 | H9: 9791159289583 | I9: 스토리위즈 | J9: 나 혼자만 일일 보상 2권 | K9: 이동열 | L9: KRW | M9: 3200 | N9: KRW | O9: 3200 | P9: 3200 | Q9: KR | R9: 0.7 | S9: 2240 | T9: KRW | U9: 2240 | V9: 스토리위즈
A10: 22. 4. 30. | B10: 22. 4. 27. | C10: ID:3112-4653-4107-50044 | D10: Single Purchase | E10: Sale | F10: None | G10: 1 | H10: 9791159289590 | I10: 스토리위즈 | J10: 나 혼자만 일일 보상 3권 | K10: 이동열 | L10: KRW | M10: 3200 | N10: KRW | O10: 3200 | P10: 3200 | Q10: KR | R10: 0.7 | S10: 2240 | T10: KRW | U10: 2240 | V10: 스토리위즈
A11: 22. 4. 30. | B11: 22. 4. 27. | C11: ID:3117-5796-6654-83819 | D11: Single Purchase | E11: Sale | F11: None | G11: 1 | H11: 9791159289606 | I11: 스토리위즈 | J11: 나 혼자만 일일 보상 4권 | K11: 이동열 | L11: KRW | M11: 3200 | N11: KRW | O11: 3200 | P11: 3200 | Q11: KR | R11: 0.7 | S11: 2240 | T11: KRW | U11: 2240 | V11: 스토리위즈
A12: 22. 4. 30. | B12: 22. 4. 27. | C12: ID:3116-0130-5126-79210 | D12: Single Purchase | E12: Sale | F12: None | G12: 1 | H12: 9791159289613 | I12: 스토리위즈 | J12: 나 혼자만 일일 보상 5권 | K12: 이동열 | L12: KRW | M12: 3200 | N12: KRW | O12: 3200 | P12: 3200 | Q12: KR | R12: 0.7 | S12: 2240 | T12: KRW | U12: 2240 | V12: 스토리위즈
A13: 22. 4. 30. | B13: 22. 4. 27. | C13: ID:3116-2558-4850-19567 | D13: Single Purchase | E13: Sale | F13: None | G13: 1 | H13: 9791159289620 | I13: 스토리위즈 | J13: 나 혼자만 일일 보상 6권 | K13: 이동열 | L13: KRW | M13: 3200 | N13: KRW | O13: 3200 | P13: 3200 | Q13: KR | R13: 0.7 | S13: 2240 | T13: KRW | U13: 2240 | V13: 스토리위즈
... A19: 22. 4. 30. | B19: 22. 4. 28. | C19: ID:3138-0382-9593-64874 | D19: Single Purchase | E19: Sale | F19: None | G19: 1 | H19: 9791159289606 | I19: 스토리위즈 | J19: 나 혼자만 일일 보상 4권 | K19: 이동열 | L19: KRW | M19: 3200 | N19: KRW | O19: 3200 | P19: 3200 | Q19: KR | R19: 0.7 | S19: 2240 | T19: KRW | U19: 2240 | V19: 스토리위즈

Sheet 네이버APP04
A1: 구분 | B1: 컨텐츠 | C1: 컨텐츠No | D1: 공급자코드 | E1: CP명 | F1: 작가명 | G1: 출판사 | H1: 나이제한 | I1: 서비스일 | J1: 건수 | K1: 비정산 | L1: 무료이용권 | M1: 유상쿠키 | N1: 무상쿠키 | O1: 유상i쿠키 | P1: 무상i쿠키 | Q1: 유상자동충전쿠키 | R1: 무상자동충전쿠키 | S1: 건수 | T1: 비정산 | U1: 무료이용권 | V1: 유상쿠키 | W1: 무상쿠키 | X1: 유상i쿠키 | Y1: 무상i쿠키 | Z1: 유상자동충전쿠키 | AA1: 무상자동충전쿠키 | AB1: 건수 | AC1: 유상 | AD1: 무상 | AE1: 건수 | AF1: 유상 | AG1: 무상 | AH1: 건수 | AI1: 유상 | AJ1: 무상 | AK1: 건수 | AL1: 유상 | AM1: 무상 | AN1: i쿠키 수수료 | AO1: 건수 | AP1: 유상 | AQ1: 무상 | AR1: 건수 | AS1: 유상 | AT1: 무상 | AU1: 합계 | AV1: 순매출(합계-수수료) | AW1: SW매출
A2: 시리즈(APP) | B2: BJ소드마스터 [독점] | C2: 387417 | E2: 스토리위즈_1 | F2: 이동열 | G2: 스토리위즈 | H2: 전체이용가 | I2: 2020.07.24 | J2: 0 | K2: 75 | L2: 0 | M2: 0 | N2: 0 | O2: 0 | P2: 0 | Q2: 0 | R2: 0 | S2: 0 | T2: 75 | U2: 0 | V2: 0 | W2: 0 | X2: 0 | Y2: 0 | Z2: 0 | AA2: 0 | AB2: 0 | AC2: 0 | AD2: 0 | AE2: 0 | AF2: 0 | AG2: 0 | AH2: 0 | AI2: 0 | AJ2: 0 | AK2: 0 | AL2: 0 | AM2: 0 | AN2: 0 | AO2: 0 | AP2: 0 | AQ2: 0 | AR2: 0 | AS2: 0 | AT2: 0 | AU2: 150900 | AV2: 150900 | AW2: 105630
A3: 시리즈(APP) | B3: 말빨 | C3: 388999 | E3: 스토리위즈_1 | F3: 이동열 | G3: 스토리위즈 | H3: 전체이용가 | I3: 2020.02.12 | J3: 0 | K3: 40 | L3: 0 | M3: 0 | N3: 0 | O3: 0 | P3: 0 | Q3: 0 | R3: 0 | S3: 0 | T3: 40 | U3: 0 | V3: 0 | W3: 0 | X3: 0 | Y3: 0 | Z3: 0 | AA3: 0 | AB3: 0 | AC3: 0 | AD3: 0 | AE3: 0 | AF3: 0 | AG3: 0 | AH3: 0 | AI3: 0 | AJ3: 0 | AK3: 0 | AL3: 0 | AM3: 0 | AN3: 0 | AO3: 0 | AP3: 0 | AQ3: 0 | AR3: 0 | AS3: 0 | AT3: 0 | AU3: 100300 | AV3: 100300 | AW3: 70210
A4: 시리즈(APP) | B4: 나 혼자만 일일 보상 | C4: 316658 | E4: 스토리위즈_1 | F4: 이동열 | G4: 스토리위즈 | H4: 전체이용가 | I4: 2018.12.20 | J4: 0 | K4: 0 | L4: 0 | M4: 0 | N4: 0 | O4: 0 | P4: 0 | Q4: 0 | R4: 0 | S4: 0 | T4: 0 | U4: 0 | V4: 0 | W4: 0 | X4: 0 | Y4: 0 | Z4: 0 | AA4: 0 | AB4: 0 | AC4: 0 | AD4: 0 | AE4: 0 | AF4: 0 | AG4: 0 | AH4: 0 | AI4: 0 | AJ4: 0 | AK4: 0 | AL4: 0 | AM4: 0 | AN4: 0 | AO4: 0 | AP4: 0 | AQ4: 0 | AR4: 0 | AS4: 0 | AT4: 0 | AU4: 77100 | AV4: 77100 | AW4: 53970
A5: 시리즈(APP) | B5: 나 혼자만 일일 보상 [단행본] | C5: 391329 | E5: 스토리위즈_1 | F5: 이동열 | G5: 스토리위즈 | H5: 전체이용가 | I5: 2020.03.05 | J5: 0 | K5: 0 | L5: 0 | M5: 0 | N5: 0 | O5: 0 | P5: 0 | Q5: 0 | R5: 0 | S5: 0 | T5: 0 | U5: 0 | V5: 0 | W5: 0 | X5: 0 | Y5: 0 | Z5: 0 | AA5: 0 | AB5: 0 | AC5: 0 | AD5: 0 | AE5: 0 | AF5: 0 | AG5: 0 | AH5: 0 | AI5: 0 | AJ5: 0 | AK5: 0 | AL5: 0 | AM5: 0 | AN5: 0 | AO5: 0 | AP5: 0 | AQ5: 0 | AR5: 0 | AS5: 0 | AT5: 0 | AU5: 6400 | AV5: 6400 | AW5: 4480
A6: 시리즈(APP) | B6: 던전 공략 LIVE [단행본] | C6: 304651 | E6: 스토리위즈_1 | F6: 이동열 | G6: 스토리위즈 | H6: 전체이용가 | I6: 2018.02.21 | J6: 0 | K6: 0 | L6: 0 | M6: 0 | N6: 0 | O6: 0 | P6: 0 | Q6: 0 | R6: 0 | S6: 0 | T6: 0 | U6: 0 | V6: 0 | W6: 0 | X6: 0 | Y6: 0 | Z6: 0 | AA6: 0 | AB6: 0 | AC6: 900 | AD6: 200 | AE6: 0 | AF6: 900 | AG6: 200 | AH6: 0 | AI6: 900 | AJ6: 200 | AK6: 0 | AL6: 900 | AM6: 200 | AN6: 0 | AO6: 0 | AP6: 900 | AQ6: 200 | AR6: 0 | AS6: 900 | AT6: 200 | AU6: 3600 | AV6: 3600 | AW6: 2520
A7: 시리즈(APP) | B7: 던전 공략 LIVE | C7: 251205 | E7: 스토리위즈_1 | F7: 이동열 | G7: 스토리위즈 | H7: 전체이용가 | I7: 2018.06.20 | J7: 0 | K7: 0 | L7: 0 | M7: 0 | N7: 0 | O7: 0 | P7: 0 | Q7: 0 | R7: 0 | S7: 0 | T7: 0 | U7: 0 | V7: 0 | W7: 0 | X7: 0 | Y7: 0 | Z7: 0 | AA7: 0 | AB7: 0 | AC7: 0 | AD7: 0 | AE7: 0 | AF7: 0 | AG7: 0 | AH7: 0 | AI7: 0 | AJ7: 0 | AK7: 0 | AL7: 0 | AM7: 0 | AN7: 0 | AO7: 0 | AP7: 0 | AQ7: 0 | AR7: 0 | AS7: 0 | AT7: 0 | AU7: 100 | AV7: 100 | AW7: 70
A8: 완전판APP | B8: 나 혼자만 일일 보상 | C8: 316658 | E8: 스토리위즈_1 | F8: 이동열 | G8: 스토리위즈 | H8: 전체이용가 | I8: 2018.12.20 | J8: 0 | K8: 0 | L8: 0 | M8: 0 | N8: 0 | O8: 0 | P8: 0 | Q8: 0 | R8: 0 | S8: 0 | T8: 0 | U8: 0 | V8: 0 | W8: 0 | X8: 0 | Y8: 0 | Z8: 0 | AA8: 0 | AB8: 0 | AC8: 0 | AD8: 0 | AE8: 0 | AF8: 0 | AG8: 0 | AH8: 0 | AI8: 0 | AJ8: 0 | AK8: 0 | AL8: 0 | AM8: 0 | AN8: 0 | AO8: 0 | AP8: 0 | AQ8: 0 | AR8: 0 | AS8: 0 | AT8: 0 | AU8: 33900 | AV8: 33900 | AW8: 23730
A9: 완전판APP | B9: BJ소드마스터 [독점] | C9: 387417 | E9: 스토리위즈_1 | F9: 이동열 | G9: 스토리위즈 | H9: 전체이용가 | I9: 2020.07.24 | J9: 0 | K9: 27 | L9: 0 | M9: 0 | N9: 0 | O9: 0 | P9: 0 | Q9: 0 | R9: 0 | S9: 0 | T9: 27 | U9: 0 | V9: 0 | W9: 0 | X9: 0 | Y9: 0 | Z9: 0 | AA9: 0 | AB9: 0 | AC9: 0 | AD9: 0 | AE9: 0 | AF9: 0 | AG9: 0 | AH9: 0 | AI9: 0 | AJ9: 0 | AK9: 0 | AL9: 0 | AM9: 0 | AN9: 0 | AO9: 0 | AP9: 0 | AQ9: 0 | AR9: 0 | AS9: 0 | AT9: 0 | AU9: 12300 | AV9: 12300 | AW9: 8610
A10: 완전판APP | B10: 말빨 | C10: 388999 | E10: 스토리위즈_1 | F10: 이동열 | G10: 스토리위즈 | H10: 전체이용가 | I10: 2020.02.12 | J10: 0 | K10: 1 | L10: 0 | M10: 0 | N10: 0 | O10: 0 | P10: 0 | Q10: 0 | R10: 0 | S10: 0 | T10: 1 | U10: 0 | V10: 0 | W10: 0 | X10: 0 | Y10: 0 | Z10: 0 | AA10: 0 | AB10: 0 | AC10: 0 | AD10: 0 | AE10: 0 | AF10: 0 | AG10: 0 | AH10: 0 | AI10: 0 | AJ10: 0 | AK10: 0 | AL10: 0 | AM10: 0 | AN10: 0 | AO10: 0 | AP10: 0 | AQ10: 0 | AR10: 0 | AS10: 0 | AT10: 0 | AU10: 8000 | AV10: 8000 | AW10: 5600
A11: 시리즈(IOS) | B11: BJ소드마스터 [독점] | C11: 387417 | E11: 스토리위즈_1 | F11: 이동열 | G11: 스토리위즈 | H11: 전체이용가 | I11: 2020.07.24 | J11: 0 | K11: 3 | L11: 0 | M11: 0 | N11: 0 | O11: 0 | P11: 0 | Q11: 0 | R11: 0 | S11: 0 | T11: 3 | U11: 0 | V11: 0 | W11: 0 | X11: 0 | Y11: 0 | Z11: 0 | AA11: 0 | AB11: 0 | AC11: 0 | AD11: 0 | AE11: 0 | AF11: 0 | AG11: 0 | AH11: 0 | AI11: 0 | AJ11: 0 | AK11: 0 | AL11: 0 | AM11: 0 | AN11: 4176 | AO11: 0 | AP11: 0 | AQ11: 0 | AR11: 0 | AS11: 0 | AT11: 0 | AU11: 40520 | AV11: 36344 | AW11: 25440.8
A12: 시리즈(IOS) | B12: 나 혼자만 일일 보상 | C12: 316658 | E12: 스토리위즈_1 | F12: 이동열 | G12: 스토리위즈 | H12: 전체이용가 | I12: 2018.12.20 | J12: 0 | K12: 0 | L12: 0 | M12: 0 | N12: 0 | O12: 0 | P12: 0 | Q12: 0 | R12: 0 | S12: 0 | T12: 0 | U12: 0 | V12: 0 | W12: 0 | X12: 0 | Y12: 0 | Z12: 0 | AA12: 0 | AB12: 0 | AC12: 0 | AD12: 0 | AE12: 0 | AF12: 0 | AG12: 0 | AH12: 0 | AI12: 0 | AJ12: 0 | AK12: 0 | AL12: 0 | AM12: 0 | AN12: 0 | AO12: 0 | AP12: 0 | AQ12: 0 | AR12: 0 | AS12: 0 | AT12: 0 | AU12: 4000 | AV12: 4000 | AW12: 2800
A13: 시리즈(IOS) | B13: 말빨 | C13: 388999 | E13: 스토리위즈_1 | F13: 이동열 | G13: 스토리위즈 | H13: 전체이용가 | I13: 2020.02.12 | J13: 0 | K13: 0 | L13: 0 | M13: 0 | N13: 0 | O13: 0 | P13: 0 | Q13: 0 | R13: 0 | S13: 0 | T13: 0 | U13: 0 | V13: 0 | W13: 0 | X13: 0 | Y13: 0 | Z13: 0 | AA13: 0 | AB13: 0 | AC13: 0 | AD13: 0 | AE13: 0 | AF13: 0 | AG13: 0 | AH13: 0 | AI13: 0 | AJ13: 0 | AK13: 0 | AL13: 0 | AM13: 0 | AN13: 0 | AO13: 0 | AP13: 0 | AQ13: 0 | AR13: 0 | AS13: 0 | AT13: 0 | AU13: 100 | AV13: 100 | AW13: 70

Sheet 네이버PC04
A1: 구분 | B1: 컨텐츠 | C1: 컨텐츠No | D1: 공급자코드 | E1: CP명 | F1: 작가명 | G1: 출판사 | H1: 나이제한 | I1: 서비스일 | J1: 건수 | K1: 비정산 | L1: 무료이용권 | M1: 유상쿠키 | N1: 무상쿠키 | O1: 유상i쿠키 | P1: 무상i쿠키 | Q1: 유상자동충전쿠키 | R1: 무상자동충전쿠키 | S1: 건수 | T1: 비정산 | U1: 무료이용권 | V1: 유상쿠키 | W1: 무상쿠키 | X1: 유상i쿠키 | Y1: 무상i쿠키 | Z1: 유상자동충전쿠키 | AA1: 무상자동충전쿠키 | AB1: 건수 | AC1: 유상 | AD1: 무상 | AE1: 건수 | AF1: 유상 | AG1: 무상 | AH1: 건수 | AI1: 유상 | AJ1: 무상 | AK1: 건수 | AL1: 유상 | AM1: 무상 | AN1: i쿠키 수수료 | AO1: 건수 | AP1: 유상 | AQ1: 무상 | AR1: 건수 | AS1: 유상 | AT1: 무상 | AU1: 합계 | AV1: 순매출(합계-수수료) | AW1: SW매출
A2: N스토어(PC) | B2: BJ소드마스터 [독점] | C2: 387417 | E2: 스토리위즈_1 | F2: 이동열 | G2: 스토리위즈 | H2: 전체이용가 | I2: 2020.07.24 | J2: 0 | K2: 0 | L2: 0 | M2: 0 | N2: 0 | O2: 0 | P2: 0 | Q2: 0 | R2: 0 | S2: 0 | T2: 0 | U2: 0 | V2: 0 | W2: 0 | X2: 0 | Y2: 0 | Z2: 0 | AA2: 0 | AB2: 0 | AC2: 0 | AD2: 0 | AE2: 0 | AF2: 0 | AG2: 0 | AH2: 0 | AI2: 0 | AJ2: 0 | AK2: 0 | AL2: 0 | AM2: 0 | AN2: 0 | AO2: 0 | AP2: 0 | AQ2: 0 | AR2: 0 | AS2: 0 | AT2: 0 | AU2: 200 | AV2: 200 | AW2: 140
A3: PC뷰어(PC) | B3: BJ소드마스터 [독점] | C3: 387417 | E3: 스토리위즈_1 | F3: 이동열 | G3: 스토리위즈 | H3: 전체이용가 | I3: 2020.07.24 | J3: 0 | K3: 0 | L3: 0 | M3: 0 | N3: 0 | O3: 0 | P3: 0 | Q3: 0 | R3: 0 | S3: 0 | T3: 0 | U3: 0 | V3: 0 | W3: 0 | X3: 0 | Y3: 0 | Z3: 0 | AA3: 0 | AB3: 0 | AC3: 0 | AD3: 0 | AE3: 0 | AF3: 0 | AG3: 0 | AH3: 0 | AI3: 0 | AJ3: 0 | AK3: 0 | AL3: 0 | AM3: 0 | AN3: 0 | AO3: 0 | AP3: 0 | AQ3: 0 | AR3: 0 | AS3: 0 | AT3: 0 | AU3: 2100 | AV3: 2100 | AW3: 1470

Sheet 리디북스03
A1: 시리즈 ID | B1: 도서 ID | C1: 제목 | D1: 권/화수 | E1: 저자 | F1: 역자 | G1: 그림 | H1: 출판사 | I1: 시리즈명 | J1: 전자책정가 | K1: 단권판매액 | L1: 단권판매권 | M1: 단권무료권 | N1: 대여액 | O1: 대여유료권( ~ 2020-04 대여권) | P1: 대여무료권 | Q1: 자유다운금액 | R1: 자유다운권 | S1: 세트판매액 | T1: 세트판매권 | U1: 세트대여액 | V1: 세트대여권 | W1: 취소단권판매액 | X1: 취소단권판매권 | Y1: 취소대여액 | Z1: 취소대여권 | AA1: 취소자유다운액 | AB1: 취소자유다운권 | AC1: 취소세트판매액 | AD1: 취소세트판매권 | AE1: 취소세트대여액 | AF1: 취소세트대여권 | AG1: 판매액 | AH1: 판매권 | AI1: 취소액 | AJ1: 취소권 | AK1: 일반 판매액 | AL1: 일반 취소액 | AM1: 앱마켓 정산대상액 | AN1: 앱마켓 수수료(30%) | AO1: 앱마켓 취소액 | AP1: 정산액 | AQ1: 종이책ISBN10 | AR1: 종이책ISBN13 | AS1: 전자책ISBN10 | AT1: 전자책ISBN13 | AU1: CP 관리 ID | AV1: 카테고리1 | AW1: 카테고리2
A2: 2313005704 | B2: 2313005705 | C2: [e북]나 혼자만 일일 보상 2권 | D2: 2 | E2: 이동열 | H2: 스토리위즈 | I2: [e북]나 혼자만 일일 보상 | J2: 3200 | K2: 9600 | L2: 3 | M2: 0 | N2: 0 | O2: 0 | P2: 0 | Q2: 0 | R2: 0 | S2: 0 | T2: 0 | U2: 0 | V2: 0 | W2: 0 | X2: 0 | Y2: 0 | Z2: 0 | AA2: 0 | AB2: 0 | AC2: 0 | AD2: 0 | AE2: 0 | AF2: 0 | AG2: 9600 | AH2: 3 | AI2: 0 | AJ2: 0 | AK2: 9600 | AL2: 0 | AM2: 0 | AN2: 0 | AO2: 0 | AP2: 6720 | AT2: 9791159289583 | AV2: 판타지 e북 > 퓨전 판타지
A3: 2313005704 | B3: 2313005706 | C3: [e북]나 혼자만 일일 보상 3권 | D3: 3 | E3: 이동열 | H3: 스토리위즈 | I3: [e북]나 혼자만 일일 보상 | J3: 3200 | K3: 3200 | L3: 1 | M3: 0 | N3: 0 | O3: 0 | P3: 0 | Q3: 0 | R3: 0 | S3: 0 | T3: 0 | U3: 0 | V3: 0 | W3: 0 | X3: 0 | Y3: 0 | Z3: 0 | AA3: 0 | AB3: 0 | AC3: 0 | AD3: 0 | AE3: 0 | AF3: 0 | AG3: 3200 | AH3: 1 | AI3: 0 | AJ3: 0 | AK3: 3200 | AL3: 0 | AM3: 0 | AN3: 0 | AO3: 0 | AP3: 2240 | AT3: 9791159289590 | AV3: 판타지 e북 > 퓨전 판타지
A4: 2313005704 | B4: 2313005707 | C4: [e북]나 혼자만 일일 보상 4권 | D4: 4 | E4: 이동열 | H4: 스토리위즈 | I4: [e북]나 혼자만 일일 보상 | J4: 3200 | K4: 3200 | L4: 1 | M4: 0 | N4: 0 | O4: 0 | P4: 0 | Q4: 0 | R4: 0 | S4: 0 | T4: 0 | U4: 0 | V4: 0 | W4: 0 | X4: 0 | Y4: 0 | Z4: 0 | AA4: 0 | AB4: 0 | AC4: 0 | AD4: 0 | AE4: 0 | AF4: 0 | AG4: 3200 | AH4: 1 | AI4: 0 | AJ4: 0 | AK4: 3200 | AL4: 0 | AM4: 0 | AN4: 0 | AO4: 0 | AP4: 2240 | AT4: 9791159289606 | AV4: 판타지 e북 > 퓨전 판타지
A5: 2313005704 | B5: 2313005708 | C5: [e북]나 혼자만 일일 보상 5권 | D5: 5 | E5: 이동열 | H5: 스토리위즈 | I5: [e북]나 혼자만 일일 보상 | J5: 3200 | K5: 3200 | L5: 1 | M5: 0 | N5: 0 | O5: 0 | P5: 0 | Q5: 0 | R5: 0 | S5: 0 | T5: 0 | U5: 0 | V5: 0 | W5: 0 | X5: 0 | Y5: 0 | Z5: 0 | AA5: 0 | AB5: 0 | AC5: 0 | AD5: 0 | AE5: 0 | AF5: 0 | AG5: 3200 | AH5: 1 | AI5: 0 | AJ5: 0 | AK5: 3200 | AL5: 0 | AM5: 0 | AN5: 0 | AO5: 0 | AP5: 2240 | AT5: 9791159289613 | AV5: 판타지 e북 > 퓨전 판타지
A6: 2313005704 | B6: 2313005709 | C6: [e북]나 혼자만 일일 보상 6권 | D6: 6 | E6: 이동열 | H6: 스토리위즈 | I6: [e북]나 혼자만 일일 보상 | J6: 3200 | K6: 3200 | L6: 1 | M6: 0 | N6: 0 | O6: 0 | P6: 0 | Q6: 0 | R6: 0 | S6: 0 | T6: 0 | U6: 0 | V6: 0 | W6: 0 | X6: 0 | Y6: 0 | Z6: 0 | AA6: 0 | AB6: 0 | AC6: 0 | AD6: 0 | AE6: 0 | AF6: 0 | AG6: 3200 | AH6: 1 | AI6: 0 | AJ6: 0 | AK6: 3200 | AL6: 0 | AM6: 0 | AN6: 0 | AO6: 0 | AP6: 2240 | AT6: 9791159289620 | AV6: 판타지 e북 > 퓨전 판타지
A7: 2313005704 | B7: 2313005710 | C7: [e북]나 혼자만 일일 보상 7권 | D7: 7 | E7: 이동열 | H7: 스토리위즈 | I7: [e북]나 혼자만 일일 보상 | J7: 3200 | K7: 3200 | L7: 1 | M7: 0 | N7: 0 | O7: 0 | P7: 0 | Q7: 0 | R7: 0 | S7: 0 | T7: 0 | U7: 0 | V7: 0 | W7: 0 | X7: 0 | Y7: 0 | Z7: 0 | AA7: 0 | AB7: 0 | AC7: 0 | AD7: 0 | AE7: 0 | AF7: 0 | AG7: 3200 | AH7: 1 | AI7: 0 | AJ7: 0 | AK7: 3200 | AL7: 0 | AM7: 0 | AN7: 0 | AO7: 0 | AP7: 2240 | AT7: 9791159289637 | AV7: 판타지 e북 > 퓨전 판타지
A8: 2313005704 | B8: 2313005711 | C8: [e북]나 혼자만 일일 보상 8권 | D8: 8 | E8: 이동열 | H8: 스토리위즈 | I8: [e북]나 혼자만 일일 보상 | J8: 3200 | K8: 3200 | L8: 1 | M8: 0 | N8: 0 | O8: 0 | P8: 0 | Q8: 0 | R8: 0 | S8: 0 | T8: 0 | U8: 0 | V8: 0 | W8: 0 | X8: 0 | Y8: 0 | Z8: 0 | AA8: 0 | AB8: 0 | AC8: 0 | AD8: 0 | AE8: 0 | AF8: 0 | AG8: 3200 | AH8: 1 | AI8: 0 | AJ8: 0 | AK8: 3200 | AL8: 0 | AM8: 0 | AN8: 0 | AO8: 0 | AP8: 2240 | AT8: 9791159289644 | AV8: 판타지 e북 > 퓨전 판타지
A9: 2313005704 | B9: 2313005712 | C9: [e북]나 혼자만 일일 보상 9권 | D9: 9 | E9: 이동열 | H9: 스토리위즈 | I9: [e북]나 혼자만 일일 보상 | J9: 3200 | K9: 3200 | L9: 1 | M9: 0 | N9: 0 | O9: 0 | P9: 0 | Q9: 0 | R9: 0 | S9: 0 | T9: 0 | U9: 0 | V9: 0 | W9: 0 | X9: 0 | Y9: 0 | Z9: 0 | AA9: 0 | AB9: 0 | AC9: 0 | AD9: 0 | AE9: 0 | AF9: 0 | AG9: 3200 | AH9: 1 | AI9: 0 | AJ9: 0 | AK9: 3200 | AL9: 0 | AM9: 0 | AN9: 0 | AO9: 0 | AP9: 2240 | AT9: 9791159289651 | AV9: 판타지 e북 > 퓨전 판타지
A10: 2313005704 | B10: 2313005713 | C10: [e북]나 혼자만 일일 보상 (외전) (완결) | D10: 10 | E10: 이동열 | H10: 스토리위즈 | I10: [e북]나 혼자만 일일 보상 | J10: 3200 | K10: 3200 | L10: 1 | M10: 0 | N10: 0 | O10: 0 | P10: 0 | Q10: 0 | R10: 0 | S10: 0 | T10: 0 | U10: 0 | V10: 0 | W10: 0 | X10: 0 | Y10: 0 | Z10: 0 | AA10: 0 | AB10: 0 | AC10: 0 | AD10: 0 | AE10: 0 | AF10: 0 | AG10: 3200 | AH10: 1 | AI10: 0 | AJ10: 0 | AK10: 3200 | AL10: 0 | AM10: 0 | AN10: 0 | AO10: 0 | AP10: 2240 | AT10: 9791159289668 | AV10: 판타지 e북 > 퓨전 판타지
A11: 2313009409 | B11: 2313009410 | C11: [e북]말빨 2권 | D11: 2 | E11: 이동열 | H11: 스토리위즈 | I11: [e북]말빨 | J11: 3200 | K11: 3200 | L11: 1 | M11: 0 | N11: 3420 | O11: 5 | P11: 0 | Q11: 0 | R11: 0 | S11: 0 | T11: 0 | U11: 0 | V11: 0 | W11: 0 | X11: 0 | Y11: 0 | Z11: 0 | AA11: 0 | AB11: 0 | AC11: 0 | AD11: 0 | AE11: 0 | AF11: 0 | AG11: 6620 | AH11: 6 | AI11: 0 | AJ11: 0 | AK11: 6620 | AL11: 0 | AM11: 0 | AN11: 0 | AO11: 0 | AP11: 4634 | AR11: 0000000000000 | AT11: 9791165311766 | AV11: 판타지 e북 > 게임 판타지
A12: 2313009409 | B12: 2313009411 | C12: [e북]말빨 3권 | D12: 3 | E12: 이동열 | H12: 스토리위즈 | I12: [e북]말빨 | J12: 3200 | K12: 3200 | L12: 1 | M12: 0 | N12: 2520 | O12: 4 | P12: 0 | Q12: 0 | R12: 0 | S12: 0 | T12: 0 | U12: 0 | V12: 0 | W12: 0 | X12: 0 | Y12: 0 | Z12: 0 | AA12: 0 | AB12: 0 | AC12: 0 | AD12: 0 | AE12: 0 | AF12: 0 | AG12: 5720 | AH12: 5 | AI12: 0 | AJ12: 0 | AK12: 5720 | AL12: 0 | AM12: 0 | AN12: 0 | AO12: 0 | AP12: 4004 | AR12: 0000000000000 | AT12: 9791165311773 | AV12: 판타지 e북 > 게임 판타지
A13: 2313009409 | B13: 2313009412 | C13: [e북]말빨 4권 | D13: 4 | E13: 이동열 | H13: 스토리위즈 | I13: [e북]말빨 | J13: 3200 | K13: 3200 | L13: 1 | M13: 0 | N13: 2520 | O13: 4 | P13: 0 | Q13: 0 | R13: 0 | S13: 0 | T13: 0 | U13: 0 | V13: 0 | W13: 0 | X13: 0 | Y13: 0 | Z13: 0 | AA13: 0 | AB13: 0 | AC13: 0 | AD13: 0 | AE13: 0 | AF13: 0 | AG13: 5720 | AH13: 5 | AI13: 0 | AJ13: 0 | AK13: 5720 | AL13: 0 | AM13: 0 | AN13: 0 | AO13: 0 | AP13: 4004 | AR13: 0000000000000 | AT13: 9791165311780 | AV13: 판타지 e북 > 게임 판타지
A14: 2313009409 | B14: 2313009413 | C14: [e북]말빨 5권 | D14: 5 | E14: 이동열 | H14: 스토리위즈 | I14: [e북]말빨 | J14: 3200 | K14: 3200 | L14: 1 | M14: 0 | N14: 2520 | O14: 4 | P14: 0 | Q14: 0 | R14: 0 | S14: 0 | T14: 0 | U14: 0 | V14: 0 | W14: 0 | X14: 0 | Y14: 0 | Z14: 0 | AA14: 0 | AB14: 0 | AC14: 0 | AD14: 0 | AE14: 0 | AF14: 0 | AG14: 5720 | AH14: 5 | AI14: 0 | AJ14: 0 | AK14: 5720 | AL14: 0 | AM14: 0 | AN14: 0 | AO14: 0 | AP14: 4004 | AR14: 0000000000000 | AT14: 9791165311797 | AV14: 판타지 e북 > 게임 판타지
A15: 2313009409 | B15: 2313009414 | C15: [e북]말빨 6권 | D15: 6 | E15: 이동열 | H15: 스토리위즈 | I15: [e북]말빨 | J15: 3200 | K15: 3200 | L15: 1 | M15: 0 | N15: 2520 | O15: 4 | P15: 0 | Q15: 0 | R15: 0 | S15: 0 | T15: 0 | U15: 0 | V15: 0 | W15: 0 | X15: 0 | Y15: 0 | Z15: 0 | AA15: 0 | AB15: 0 | AC15: 0 | AD15: 0 | AE15: 0 | AF15: 0 | AG15: 5720 | AH15: 5 | AI15: 0 | AJ15: 0 | AK15: 5720 | AL15: 0 | AM15: 0 | AN15: 0 | AO15: 0 | AP15: 4004 | AR15: 0000000000000 | AT15: 9791165311803 | AV15: 판타지 e북 > 게임 판타지
A16: 2313009409 | B16: 2313009415 | C16: [e북]말빨 7권 | D16: 7 | E16: 이동열 | H16: 스토리위즈 | I16: [e북]말빨 | J16: 3200 | K16: 3200 | L16: 1 | M16: 0 | N16: 2520 | O16: 4 | P16: 0 | Q16: 0 | R16: 0 | S16: 0 | T16: 0 | U16: 0 | V16: 0 | W16: 0 | X16: 0 | Y16: 0 | Z16: 0 | AA16: 0 | AB16: 0 | AC16: 0 | AD16: 0 | AE16: 0 | AF16: 0 | AG16: 5720 | AH16: 5 | AI16: 0 | AJ16: 0 | AK16: 5720 | AL16: 0 | AM16: 0 | AN16: 0 | AO16: 0 | AP16: 4004 | AR16: 0000000000000 | AT16: 9791165311810 | AV16: 판타지 e북 > 게임 판타지
A17: 2313009409 | B17: 2313009416 | C17: [e북]말빨 8권 | D17: 8 | E17: 이동열 | H17: 스토리위즈 | I17: [e북]말빨 | J17: 3200 | K17: 3200 | L17: 1 | M17: 0 | N17: 2520 | O17: 4 | P17: 0 | Q17: 0 | R17: 0 | S17: 0 | T17: 0 | U17: 0 | V17: 0 | W17: 0 | X17: 0 | Y17: 0 | Z17: 0 | AA17: 0 | AB17: 0 | AC17: 0 | AD17: 0 | AE17: 0 | AF17: 0 | AG17: 5720 | AH17: 5 | AI17: 0 | AJ17: 0 | AK17: 5720 | AL17: 0 | AM17: 0 | AN17: 0 | AO17: 0 | AP17: 4004 | AR17: 0000000000000 | AT17: 9791165311827 | AV17: 판타지 e북 > 게임 판타지
A18: 2313009409 | B18: 2313009417 | C18: [e북]말빨 9권 (완결) | D18: 9 | E18: 이동열 | H18: 스토리위즈 | I18: [e북]말빨 | J18: 3200 | K18: 3200 | L18: 1 | M18: 0 | N18: 2520 | O18: 4 | P18: 0 | Q18: 0 | R18: 0 | S18: 0 | T18: 0 | U18: 0 | V18: 0 | W18: 0 | X18: 0 | Y18: 0 | Z18: 0 | AA18: 0 | AB18: 0 | AC18: 0 | AD18: 0 | AE18: 0 | AF18: 0 | AG18: 5720 | AH18: 5 | AI18: 0 | AJ18: 0 | AK18: 5720 | AL18: 0 | AM18: 0 | AN18: 0 | AO18: 0 | AP18: 4004 | AR18: 0000000000000 | AT18: 9791165311834 | AV18: 판타지 e북 > 게임 판타지
A19: 2313000001 | B19: 2313000016 | C19: 던전 공략 LIVE 16화 | D19: 16 | E19: 이동열 | H19: 스토리위즈 | I19: 던전 공략 LIVE | J19: 100 | K19: 100 | L19: 1 | M19: 0 | N19: 0 | O19: 0 | P19: 0 | Q19: 0 | R19: 0 | S19: 0 | T19: 0 | U19: 0 | V19: 0 | W19: 0 | X19: 0 | Y19: 0 | Z19: 0 | AA19: 0 | AB19: 0 | AC19: 0 | AD19: 0 | AE19: 0 | AF19: 0 | AG19: 100 | AH19: 1 | AI19: 0 | AJ19: 0 | AK19: 100 | AL19: 0 | AM19: 0 | AN19: 0 | AO19: 0 | AP19: 70 | AT19: 9791159283307 | AU19: 10281429451 | AV19: 판타지 웹소설 > 현대 판타지
A20: 2313000001 | B20: 2313000017 | C20: 던전 공략 LIVE 17화 | D20: 17 | E20: 이동열 | H20: 스토리위즈 | I20: 던전 공략 LIVE | J20: 100 | K20: 100 | L20: 1 | M20: 0 | N20: 0 | O20: 0 | P20: 0 | Q20: 0 | R20: 0 | S20: 0 | T20: 0 | U20: 0 | V20: 0 | W20: 0 | X20: 0 | Y20: 0 | Z20: 0 | AA20: 0 | AB20: 0 | AC20: 0 | AD20: 0 | AE20: 0 | AF20: 0 | AG20: 100 | AH20: 1 | AI20: 0 | AJ20: 0 | AK20: 100 | AL20: 0 | AM20: 0 | AN20: 0 | AO20: 0 | AP20: 70 | AT20: 9791159283307 | AU20: 10281429451 | AV20: 판타지 웹소설 > 현대 판타지
A21: 2313000001 | B21: 2313000018 | C21: 던전 공략 LIVE 18화 | D21: 18 | E21: 이동열 | H21: 스토리위즈 | I21: 던전 공략 LIVE | J21: 100 | K21: 100 | L21: 1 | M21: 0 | N21: 0 | O21: 0 | P21: 0 | Q21: 0 | R21: 0 | S21: 0 | T21: 0 | U21: 0 | V21: 0 | W21: 0 | X21: 0 | Y21: 0 | Z21: 0 | AA21: 0 | AB21: 0 | AC21: 0 | AD21: 0 | AE21: 0 | AF21: 0 | AG21: 100 | AH21: 1 | AI21: 0 | AJ21: 0 | AK21: 100 | AL21: 0 | AM21: 0 | AN21: 0 | AO21: 0 | AP21: 70 | AT21: 9791159283307 | AU21: 10281429451 | AV21: 판타지 웹소설 > 현대 판타지
A22: 2313000001 | B22: 2313000019 | C22: 던전 공략 LIVE 19화 | D22: 19 | E22: 이동열 | H22: 스토리위즈 | I22: 던전 공략 LIVE | J22: 100 | K22: 100 | L22: 1 | M22: 0 | N22: 0 | O22: 0 | P22: 0 | Q22: 0 | R22: 0 | S22: 0 | T22: 0 | U22: 0 | V22: 0 | W22: 0 | X22: 0 | Y22: 0 | Z22: 0 | AA22: 0 | AB22: 0 | AC22: 0 | AD22: 0 | AE22: 0 | AF22: 0 | AG22: 100 | AH22: 1 | AI22: 0 | AJ22: 0 | AK22: 100 | AL22: 0 | AM22: 0 | AN22: 0 | AO22: 0 | AP22: 70 | AT22: 9791159283307 | AU22: 10281429451 | AV22: 판타지 웹소설 > 현대 판타지
A23: 2313000001 | B23: 2313000020 | C23: 던전 공략 LIVE 20화 | D23: 20 | E23: 이동열 | H23: 스토리위즈 | I23: 던전 공략 LIVE | J23: 100 | K23: 100 | L23: 1 | M23: 0 | N23: 0 | O23: 0 | P23: 0 | Q23: 0 | R23: 0 | S23: 0 | T23: 0 | U23: 0 | V23: 0 | W23: 0 | X23: 0 | Y23: 0 | Z23: 0 | AA23: 0 | AB23: 0 | AC23: 0 | AD23: 0 | AE23: 0 | AF23: 0 | AG23: 100 | AH23: 1 | AI23: 0 | AJ23: 0 | AK23: 100 | AL23: 0 | AM23: 0 | AN23: 0 | AO23: 0 | AP23: 70 | AT23: 9791159283307 | AU23: 10281429451 | AV23: 판타지 웹소설 > 현대 판타지
A24: 2313000001 | B24: 2313000021 | C24: 던전 공략 LIVE 21화 | D24: 21 | E24: 이동열 | H24: 스토리위즈 | I24: 던전 공략 LIVE | J24: 100 | K24: 100 | L24: 1 | M24: 0 | N24: 0 | O24: 0 | P24: 0 | Q24: 0 | R24: 0 | S24: 0 | T24: 0 | U24: 0 | V24: 0 | W24: 0 | X24: 0 | Y24: 0 | Z24: 0 | AA24: 0 | AB24: 0 | AC24: 0 | AD24: 0 | AE24: 0 | AF24: 0 | AG24: 100 | AH24: 1 | AI24: 0 | AJ24: 0 | AK24: 100 | AL24: 0 | AM24: 0 | AN24: 0 | AO24: 0 | AP24: 70 | AT24: 9791159283307 | AU24: 10281429451 | AV24: 판타지 웹소설 > 현대 판타지
A25: 2313000001 | B25: 2313000022 | C25: 던전 공략 LIVE 22화 | D25: 22 | E25: 이동열 | H25: 스토리위즈 | I25: 던전 공략 LIVE | J25: 100 | K25: 100 | L25: 1 | M25: 0 | N25: 0 | O25: 0 | P25: 0 | Q25: 0 | R25: 0 | S25: 0 | T25: 0 | U25: 0 | V25: 0 | W25: 0 | X25: 0 | Y25: 0 | Z25: 0 | AA25: 0 | AB25: 0 | AC25: 0 | AD25: 0 | AE25: 0 | AF25: 0 | AG25: 100 | AH25: 1 | AI25: 0 | AJ25: 0 | AK25: 100 | AL25: 0 | AM25: 0 | AN25: 0 | AO25: 0 | AP25: 70 | AT25: 9791159283307 | AU25: 10281429451 | AV25: 판타지 웹소설 > 현대 판타지
A26: 2313000001 | B26: 2313000023 | C26: 던전 공략 LIVE 23화 | D26: 23 | E26: 이동열 | H26: 스토리위즈 | I26: 던전 공략 LIVE | J26: 100 | K26: 100 | L26: 1 | M26: 0 | N26: 0 | O26: 0 | P26: 0 | Q26: 0 | R26: 0 | S26: 0 | T26: 0 | U26: 0 | V26: 0 | W26: 0 | X26: 0 | Y26: 0 | Z26: 0 | AA26: 0 | AB26: 0 | AC26: 0 | AD26: 0 | AE26: 0 | AF26: 0 | AG26: 100 | AH26: 1 | AI26: 0 | AJ26: 0 | AK26: 100 | AL26: 0 | AM26: 0 | AN26: 0 | AO26: 0 | AP26: 70 | AT26: 9791159283307 | AU26: 10281429451 | AV26: 판타지 웹소설 > 현대 판타지
A27: 2313000001 | B27: 2313000024 | C27: 던전 공략 LIVE 24화 | D27: 24 | E27: 이동열 | H27: 스토리위즈 | I27: 던전 공략 LIVE | J27: 100 | K27: 100 | L27: 1 | M27: 0 | N27: 0 | O27: 0 | P27: 0 | Q27: 0 | R27: 0 | S27: 0 | T27: 0 | U27: 0 | V27: 0 | W27: 0 | X27: 0 | Y27: 0 | Z27: 0 | AA27: 0 | AB27: 0 | AC27: 0 | AD27: 0 | AE27: 0 | AF27: 0 | AG27: 100 | AH27: 1 | AI27: 0 | AJ27: 0 | AK27: 100 | AL27: 0 | AM27: 0 | AN27: 0 | AO27: 0 | AP27: 70 | AT27: 9791159283307 | AU27: 10281429451 | AV27: 판타지 웹소설 > 현대 판타지
A28: 2313000001 | B28: 2313000025 | C28: 던전 공략 LIVE 25화 | D28: 25 | E28: 이동열 | H28: 스토리위즈 | I28: 던전 공략 LIVE | J28: 100 | K28: 100 | L28: 1 | M28: 0 | N28: 0 | O28: 0 | P28: 0 | Q28: 0 | R28: 0 | S28: 0 | T28: 0 | U28: 0 | V28: 0 | W28: 0 | X28: 0 | Y28: 0 | Z28: 0 | AA28: 0 | AB28: 0 | AC28: 0 | AD28: 0 | AE28: 0 | AF28: 0 | AG28: 100 | AH28: 1 | AI28: 0 | AJ28: 0 | AK28: 100 | AL28: 0 | AM28: 0 | AN28: 0 | AO28: 0 | AP28: 70 | AT28: 9791159283307 | AU28: 10281429451 | AV28: 판타지 웹소설 > 현대 판타지
A29: 2313000001 | B29: 2313000026 | C29: 던전 공략 LIVE 26화 | D29: 26 | E29: 이동열 | H29: 스토리위즈 | I29: 던전 공략 LIVE | J29: 100 | K29: 100 | L29: 1 | M29: 0 | N29: 0 | O29: 0 | P29: 0 | Q29: 0 | R29: 0 | S29: 0 | T29: 0 | U29: 0 | V29: 0 | W29: 0 | X29: 0 | Y29: 0 | Z29: 0 | AA29: 0 | AB29: 0 | AC29: 0 | AD29: 0 | AE29: 0 | AF29: 0 | AG29: 100 | AH29: 1 | AI29: 0 | AJ29: 0 | AK29: 100 | AL29: 0 | AM29: 0 | AN29: 0 | AO29: 0 | AP29: 70 | AT29: 9791159283307 | AU29: 10281429451 | AV29: 판타지 웹소설 > 현대 판타지
A30: 2313000001 | B30: 2313000027 | C30: 던전 공략 LIVE 27화 | D30: 27 | E30: 이동열 | H30: 스토리위즈 | I30: 던전 공략 LIVE | J30: 100 | K30: 100 | L30: 1 | M30: 0 | N30: 0 | O30: 0 | P30: 0 | Q30: 0 | R30: 0 | S30: 0 | T30: 0 | U30: 0 | V30: 0 | W30: 0 | X30: 0 | Y30: 0 | Z30: 0 | AA30: 0 | AB30: 0 | AC30: 0 | AD30: 0 | AE30: 0 | AF30: 0 | AG30: 100 | AH30: 1 | AI30: 0 | AJ30: 0 | AK30: 100 | AL30: 0 | AM30: 0 | AN30: 0 | AO30: 0 | AP30: 70 | AT30: 9791159283307 | AU30: 10281429451 | AV30: 판타지 웹소설 > 현대 판타지
... A37: 2313000001 | B37: 2313000034 | C37: 던전 공략 LIVE 34화 | D37: 34 | E37: 이동열 | H37: 스토리위즈 | I37: 던전 공략 LIVE | J37: 100 | K37: 100 | L37: 1 | M37: 0 | N37: 0 | O37: 0 | P37: 0 | Q37: 0 | R37: 0 | S37: 0 | T37: 0 | U37: 0 | V37: 0 | W37: 0 | X37: 0 | Y37: 0 | Z37: 0 | AA37: 0 | AB37: 0 | AC37: 0 | AD37: 0 | AE37: 0 | AF37: 0 | AG37: 100 | AH37: 1 | AI37: 0 | AJ37: 0 | AK37: 100 | AL37: 0 | AM37: 0 | AN37: 0 | AO37: 0 | AP37: 70 | AT37: 9791159283307 | AU37: 10281429451 | AV37: 판타지 웹소설 > 현대 판타지
A38: 2313008438 | B38: 2313008530 | C38: 말빨 93화 | D38: 93 | E38: 이동열 | H38: 스토리위즈 | I38: 말빨 | J38: 100 | K38: 100 | L38: 1 | M38: 0 | N38: 0 | O38: 0 | P38: 0 | Q38: 0 | R38: 0 | S38: 0 | T38: 0 | U38: 0 | V38: 0 | W38: 0 | X38: 0 | Y38: 0 | Z38: 0 | AA38: 0 | AB38: 0 | AC38: 0 | AD38: 0 | AE38: 0 | AF38: 0 | AG38: 100 | AH38: 1 | AI38: 0 | AJ38: 0 | AK38: 100 | AL38: 0 | AM38: 0 | AN38: 0 | AO38: 0 | AP38: 70 | AT38: 9791165310820 | AV38: 판타지 웹소설 > 퓨전 판타지
A39: 2313008438 | B39: 2313008531 | C39: 말빨 94화 | D39: 94 | E39: 이동열 | H39: 스토리위즈 | I39: 말빨 | J39: 100 | K39: 100 | L39: 1 | M39: 0 | N39: 0 | O39: 0 | P39: 0 | Q39: 0 | R39: 0 | S39: 0 | T39: 0 | U39: 0 | V39: 0 | W39: 0 | X39: 0 | Y39: 0 | Z39: 0 | AA39: 0 | AB39: 0 | AC39: 0 | AD39: 0 | AE39: 0 | AF39: 0 | AG39: 100 | AH39: 1 | AI39: 0 | AJ39: 0 | AK39: 100 | AL39: 0 | AM39: 0 | AN39: 0 | AO39: 0 | AP39: 70 | AT39: 9791165310820 | AV39: 판타지 웹소설 > 퓨전 판타지
A40: 2313008438 | B40: 2313008544 | C40: 말빨 107화 | D40: 107 | E40: 이동열 | H40: 스토리위즈 | I40: 말빨 | J40: 100 | K40: 100 | L40: 1 | M40: 0 | N40: 0 | O40: 0 | P40: 0 | Q40: 0 | R40: 0 | S40: 0 | T40: 0 | U40: 0 | V40: 0 | W40: 0 | X40: 0 | Y40: 0 | Z40: 0 | AA40: 0 | AB40: 0 | AC40: 0 | AD40: 0 | AE40: 0 | AF40: 0 | AG40: 100 | AH40: 1 | AI40: 0 | AJ40: 0 | AK40: 100 | AL40: 0 | AM40: 0 | AN40: 0 | AO40: 0 | AP40: 70 | AT40: 9791165310820 | AV40: 판타지 웹소설 > 퓨전 판타지
A41: 2313008438 | B41: 2313008546 | C41: 말빨 109화 | D41: 109 | E41: 이동열 | H41: 스토리위즈 | I41: 말빨 | J41: 100 | K41: 100 | L41: 1 | M41: 0 | N41: 0 | O41: 0 | P41: 0 | Q41: 0 | R41: 0 | S41: 0 | T41: 0 | U41: 0 | V41: 0 | W41: 0 | X41: 0 | Y41: 0 | Z41: 0 | AA41: 0 | AB41: 0 | AC41: 0 | AD41: 0 | AE41: 0 | AF41: 0 | AG41: 100 | AH41: 1 | AI41: 0 | AJ41: 0 | AK41: 100 | AL41: 0 | AM41: 0 | AN41: 0 | AO41: 0 | AP41: 70 | AT41: 9791165310820 | AV41: 판타지 웹소설 > 퓨전 판타지
A42: 2313008438 | B42: 2313008547 | C42: 말빨 110화 | D42: 110 | E42: 이동열 | H42: 스토리위즈 | I42: 말빨 | J42: 100 | K42: 100 | L42: 1 | M42: 0 | N42: 0 | O42: 0 | P42: 0 | Q42: 0 | R42: 0 | S42: 0 | T42: 0 | U42: 0 | V42: 0 | W42: 0 | X42: 0 | Y42: 0 | Z42: 0 | AA42: 0 | AB42: 0 | AC42: 0 | AD42: 0 | AE42: 0 | AF42: 0 | AG42: 100 | AH42: 1 | AI42: 0 | AJ42: 0 | AK42: 100 | AL42: 0 | AM42: 0 | AN42: 0 | AO42: 0 | AP42: 70 | AT42: 9791165310820 | AV42: 판타지 웹소설 > 퓨전 판타지
A43: 2313008438 | B43: 2313008642 | C43: 말빨 205화 | D43: 205 | E43: 이동열 | H43: 스토리위즈 | I43: 말빨 | J43: 100 | K43: 100 | L43: 1 | M43: 0 | N43: 0 | O43: 0 | P43: 0 | Q43: 0 | R43: 0 | S43: 0 | T43: 0 | U43: 0 | V43: 0 | W43: 0 | X43: 0 | Y43: 0 | Z43: 0 | AA43: 0 | AB43: 0 | AC43: 0 | AD43: 0 | AE43: 0 | AF43: 0 | AG43: 100 | AH43: 1 | AI43: 0 | AJ43: 0 | AK43: 100 | AL43: 0 | AM43: 0 | AN43: 0 | AO43: 0 | AP43: 70 | AT43: 9791165310820 | AV43: 판타지 웹소설 > 퓨전 판타지
A44: 2313000001 | B44: 2313000001 | C44: 던전 공략 LIVE 1화 | D44: 1 | E44: 이동열 | H44: 스토리위즈 | I44: 던전 공략 LIVE | J44: 0 | K44: 0 | L44: 0 | M44: 2 | N44: 0 | O44: 0 | P44: 0 | Q44: 0 | R44: 0 | S44: 0 | T44: 0 | U44: 0 | V44: 0 | W44: 0 | X44: 0 | Y44: 0 | Z44: 0 | AA44: 0 | AB44: 0 | AC44: 0 | AD44: 0 | AE44: 0 | AF44: 0 | AG44: 0 | AH44: 2 | AI44: 0 | AJ44: 0 | AK44: 0 | AL44: 0 | AM44: 0 | AN44: 0 | AO44: 0 | AP44: 0 | AT44: 9791159283307 | AU44: 10281429451 | AV44: 판타지 웹소설 > 현대 판타지
A45: 2313000001 | B45: 2313000002 | C45: 던전 공략 LIVE 2화 | D45: 2 | E45: 이동열 | H45: 스토리위즈 | I45: 던전 공략 LIVE | J45: 0 | K45: 0 | L45: 0 | M45: 2 | N45: 0 | O45: 0 | P45: 0 | Q45: 0 | R45: 0 | S45: 0 | T45: 0 | U45: 0 | V45: 0 | W45: 0 | X45: 0 | Y45: 0 | Z45: 0 | AA45: 0 | AB45: 0 | AC45: 0 | AD45: 0 | AE45: 0 | AF45: 0 | AG45: 0 | AH45: 2 | AI45: 0 | AJ45: 0 | AK45: 0 | AL45: 0 | AM45: 0 | AN45: 0 | AO45: 0 | AP45: 0 | AT45: 9791159283307 | AU45: 10281429451 | AV45: 판타지 웹소설 > 현대 판타지
A46: 2313000001 | B46: 2313000003 | C46: 던전 공략 LIVE 3화 | D46: 3 | E46: 이동열 | H46: 스토리위즈 | I46: 던전 공략 LIVE | J46: 0 | K46: 0 | L46: 0 | M46: 2 | N46: 0 | O46: 0 | P46: 0 | Q46: 0 | R46: 0 | S46: 0 | T46: 0 | U46: 0 | V46: 0 | W46: 0 | X46: 0 | Y46: 0 | Z46: 0 | AA46: 0 | AB46: 0 | AC46: 0 | AD46: 0 | AE46: 0 | AF46: 0 | AG46: 0 | AH46: 2 | AI46: 0 | AJ46: 0 | AK46: 0 | AL46: 0 | AM46: 0 | AN46: 0 | AO46: 0 | AP46: 0 | AT46: 9791159283307 | AU46: 10281429451 | AV46: 판타지 웹소설 > 현대 판타지
...

Sheet 무툰04
A1: NO | B1: 작가 | C1: 타이틀 | D1: 플랫폼 | E1: 코인 | F1: 금액 | G1: 코인 | H1: 금액 | I1: 코인 | J1: 금액 | K1: 결제 | L1: 이벤트 | M1: 수수료공제액 | N1: 정산비율 | O1: 정산액
A2: 46 | B2: 이동열 | C2: 나 혼자만 일일 보상 | D2: M | E2: 0 | F2: 0 | G2: 0 | H2: 0 | I2: 0 | J2: 0 | K2: 0 | L2: 0 | M2: 0 | O2: 0
A3: 46 | B3: 이동열 | C3: 나 혼자만 일일 보상 | D3: W | E3: 0 | F3: 0 | G3: 0 | H3: 0 | I3: 0 | J3: 0 | K3: 0 | L3: 0 | M3: 0 | O3: 0
A4: 46 | B4: 이동열 | C4: 나 혼자만 일일 보상 | D4: A | E4: 32 | F4: 3200 | G4: 32 | H4: 3200 | I4: 32 | J4: 3200 | K4: 0 | L4: 0 | M4: 3200 | O4: 2240
O5: =SUM(O2:O4) -> 2240

Sheet 문피아03
A1: 날짜 | B1: 구분 | C1: 작가 | D1: 계정 | E1: 작품코드 | F1: 작품 | G1: 구매 | H1: 구매취소 | I1: 대여 | J1: 대여취소 | K1: 총매출 | L1: IOS매출 | M1: 정산
A2: 2022.03 | B2: 문피아 | C2: 이동열 | D2: kt_0601 | E2: 246133 | F2: 나 혼자만 일일 보상 [D] | G2: 16 | H2: 0 | I2: 0 | J2: 0 | K2: 51200 | L2: 0 | M2: 32256

Sheet 미스터블루04
A1: 작품명 | B1: 작가명 | C1: 코드 | D1: 정액_건수 | E1: 정액_매출액 | F1: 정액_정산액 | G1: 블루머니_권별대여_건수 | H1: 블루머니_권별대여_이용권(화) 수 | I1: 블루머니_권별대여_매출액 | J1: 블루머니_권별소장_건수 | K1: 블루머니_권별소장_이용권(화) 수 | L1: 블루머니_권별소장_매출액 | M1: 블루머니_전권대여_건수 | N1: 블루머니_전권대여_이용권(화) 수 | O1: 블루머니_전권대여_매출액 | P1: 블루머니_전권소장_건수 | Q1: 블루머니_전권소장_이용권(화) 수 | R1: 블루머니_전권소장_매출액 | S1: A.앱머니_권별대여_건수 | T1: A.앱머니_권별대여_이용권(화) 수 | U1: A.앱머니_권별대여_매출액 | V1: A.앱머니_권별소장_건수 | W1: A.앱머니_권별소장_이용권(화) 수 | X1: A.앱머니_권별소장_매출액 | Y1: A.앱머니_전권대여_건수 | Z1: A.앱머니_전권대여_이용권(화) 수 | AA1: A.앱머니_전권대여_매출액 | AB1: A.앱머니_전권소장_건수 | AC1: A.앱머니_전권소장_이용권(화) 수 | AD1: A.앱머니_전권소장_매출액 | AE1: 계_건수 | AF1: 계_이용권(화)수 | AG1: 계_매출액 | AH1: 계_정산액 | AI1: 매출액 | AJ1: 정산액
A2: 나 혼자만 일일 보상 | B2: 이동열 | C2: ktn03_0022 | D2: 0 | E2: 0 | F2: 0 | G2: 94 | H2: 94 | I2: 84600 | J2: 4 | K2: 4 | L2: 12800 | M2: 25 | N2: 225 | O2: 141750 | P2: 0 | Q2: 0 | R2: 0 | S2: 0 | T2: 0 | U2: 0 | V2: 0 | W2: 0 | X2: 0 | Y2: 0 | Z2: 0 | AA2: 0 | AB2: 0 | AC2: 0 | AD2: 0 | AE2: 123 | AF2: 323 | AG2: 239150 | AH2: 150664.5 | AI2: 239150 | AJ2: 150664.5
A3: 말빨 | B3: 이동열 | D3: 0 | E3: 0 | F3: 0 | G3: 13 | H3: 13 | I3: 11700 | J3: 0 | K3: 0 | L3: 0 | M3: 0 | N3: 0 | O3: 0 | P3: 0 | Q3: 0 | R3: 0 | S3: 0 | T3: 0 | U3: 0 | V3: 0 | W3: 0 | X3: 0 | Y3: 0 | Z3: 0 | AA3: 0 | AB3: 0 | AC3: 0 | AD3: 0 | AE3: 13 | AF3: 13 | AG3: 11700 | AH3: 7371 | AI3: 11700 | AJ3: 7371
AJ4: =SUM(AJ2:AJ3) -> 158035.5

Sheet 스낵북04
A1: 작품ID | B1: 작품명 | C1: 필자명 | D1: 정산비율 | E1: 판매(원) | F1: 정산(원) | G1: 출판사
A2: 13757 | B2: 던전 공략 LIVE | C2: 이동열 | D2: 70 | E2: 0 | F2: 0 | G2: 스토리위즈
F3: =SUM(F2) -> 0

Sheet 원스토어03
A1: 파트너명 | B1: 파트너ID | C1: 사업자구분 | D1: 채널상품ID | E1: 채널상품명 | F1: 상품명 | G1: 회차 | H1: 상품ID | I1: 2차정산여부 | J1: 카테고리 | K1: 출판사 | L1: 글작가 | M1: 그림작가 | N1: 타입 | O1: 판매건수 | P1: 취소건수 | Q1: 정액제 정산대상액 | R1: 판매_건수 | S1: 판매_금액 | T1: 취소_건수 | U1: 취소_금액 | V1: 합계 | W1: 결제수단_고객결제 | X1: 결제수단_고객결제(현금영수증) | Y1: 결제수단_쿠폰/포인트등 | Z1: 서비스이용료_고객결제서비스이용료 | AA1: 서비스이용료_쿠폰/포인트 등 | AB1: 서비스이용료_차감 | AC1: 정산지급액 | AD1: 정산유형
A2: 주식회사 스토리위즈 | B2: storywiz1 | C2: 원스토어㈜ | D2: H035795481 | E2: 나 혼자만 일일 보상 | F2: [연재] 나 혼자만 일일 보상 100회 | G2: 100 | H2: H035795787 | I2: 2차 | J2: eBook | K2: 스토리위즈 | L2: 이동열 | N2: 연재 | O2: 1 | P2: 0 | Q2: 0 | R2: 1 | S2: 100 | T2: 0 | U2: 0 | V2: 100 | W2: 100 | X2: 0 | Y2: 0 | Z2: 30 | AA2: 0 | AB2: 0 | AC2: 70 | AD2: 정규
A3: 주식회사 스토리위즈 | B3: storywiz1 | C3: 원스토어㈜ | D3: H035795481 | E3: 나 혼자만 일일 보상 | F3: [연재] 나 혼자만 일일 보상 101회 | G3: 101 | H3: H035795786 | I3: 2차 | J3: eBook | K3: 스토리위즈 | L3: 이동열 | N3: 연재 | O3: 1 | P3: 0 | Q3: 0 | R3: 1 | S3: 100 | T3: 0 | U3: 0 | V3: 100 | W3: 100 | X3: 0 | Y3: 0 | Z3: 30 | AA3: 0 | AB3: 0 | AC3: 70 | AD3: 정규
A4: 주식회사 스토리위즈 | B4: storywiz1 | C4: 원스토어㈜ | D4: H035795481 | E4: 나 혼자만 일일 보상 | F4: [연재] 나 혼자만 일일 보상 102회 | G4: 102 | H4: H035795785 | I4: 2차 | J4: eBook | K4: 스토리위즈 | L4: 이동열 | N4: 연재 | O4: 1 | P4: 0 | Q4: 0 | R4: 1 | S4: 100 | T4: 0 | U4: 0 | V4: 100 | W4: 100 | X4: 0 | Y4: 0 | Z4: 30 | AA4: 0 | AB4: 0 | AC4: 70 | AD4: 정규
A5: 주식회사 스토리위즈 | B5: storywiz1 | C5: 원스토어㈜ | D5: H035795481 | E5: 나 혼자만 일일 보상 | F5: [연재] 나 혼자만 일일 보상 103회 | G5: 103 | H5: H035795784 | I5: 2차 | J5: eBook | K5: 스토리위즈 | L5: 이동열 | N5: 연재 | O5: 1 | P5: 0 | Q5: 0 | R5: 1 | S5: 100 | T5: 0 | U5: 0 | V5: 100 | W5: 100 | X5: 0 | Y5: 0 | Z5: 30 | AA5: 0 | AB5: 0 | AC5: 70 | AD5: 정규
A6: 주식회사 스토리위즈 | B6: storywiz1 | C6: 원스토어㈜ | D6: H035795481 | E6: 나 혼자만 일일 보상 | F6: [연재] 나 혼자만 일일 보상 104회 | G6: 104 | H6: H035795783 | I6: 2차 | J6: eBook | K6: 스토리위즈 | L6: 이동열 | N6: 연재 | O6: 1 | P6: 0 | Q6: 0 | R6: 1 | S6: 100 | T6: 0 | U6: 0 | V6: 100 | W6: 100 | X6: 0 | Y6: 0 | Z6: 30 | AA6: 0 | AB6: 0 | AC6: 70 | AD6: 정규
A7: 주식회사 스토리위즈 | B7: storywiz1 | C7: 원스토어㈜ | D7: H035795481 | E7: 나 혼자만 일일 보상 | F7: [연재] 나 혼자만 일일 보상 105회 | G7: 105 | H7: H035795782 | I7: 2차 | J7: eBook | K7: 스토리위즈 | L7: 이동열 | N7: 연재 | O7: 1 | P7: 0 | Q7: 0 | R7: 1 | S7: 100 | T7: 0 | U7: 0 | V7: 100 | W7: 100 | X7: 0 | Y7: 0 | Z7: 30 | AA7: 0 | AB7: 0 | AC7: 70 | AD7: 정규
A8: 주식회사 스토리위즈 | B8: storywiz1 | C8: 원스토어㈜ | D8: H035795481 | E8: 나 혼자만 일일 보상 | F8: [연재] 나 혼자만 일일 보상 106회 | G8: 106 | H8: H035795781 | I8: 2차 | J8: eBook | K8: 스토리위즈 | L8: 이동열 | N8: 연재 | O8: 1 | P8: 0 | Q8: 0 | R8: 1 | S8: 100 | T8: 0 | U8: 0 | V8: 100 | W8: 100 | X8: 0 | Y8: 0 | Z8: 30 | AA8: 0 | AB8: 0 | AC8: 70 | AD8: 정규
A9: 주식회사 스토리위즈 | B9: storywiz1 | C9: 원스토어㈜ | D9: H035795481 | E9: 나 혼자만 일일 보상 | F9: [연재] 나 혼자만 일일 보상 107회 | G9: 107 | H9: H035795780 | I9: 2차 | J9: eBook | K9: 스토리위즈 | L9: 이동열 | N9: 연재 | O9: 1 | P9: 0 | Q9: 0 | R9: 1 | S9: 100 | T9: 0 | U9: 0 | V9: 100 | W9: 100 | X9: 0 | Y9: 0 | Z9: 30 | AA9: 0 | AB9: 0 | AC9: 70 | AD9: 정규
A10: 주식회사 스토리위즈 | B10: storywiz1 | C10: 원스토어㈜ | D10: H035795481 | E10: 나 혼자만 일일 보상 | F10: [연재] 나 혼자만 일일 보상 108회 | G10: 108 | H10: H035795779 | I10: 2차 | J10: eBook | K10: 스토리위즈 | L10: 이동열 | N10: 연재 | O10: 1 | P10: 0 | Q10: 0 | R10: 1 | S10: 100 | T10: 0 | U10: 0 | V10: 100 | W10: 100 | X10: 0 | Y10: 0 | Z10: 30 | AA10: 0 | AB10: 0 | AC10: 70 | AD10: 정규
A11: 주식회사 스토리위즈 | B11: storywiz1 | C11: 원스토어㈜ | D11: H035795481 | E11: 나 혼자만 일일 보상 | F11: [연재] 나 혼자만 일일 보상 109회 | G11: 109 | H11: H035795778 | I11: 2차 | J11: eBook | K11: 스토리위즈 | L11: 이동열 | N11: 연재 | O11: 1 | P11: 0 | Q11: 0 | R11: 1 | S11: 100 | T11: 0 | U11: 0 | V11: 100 | W11: 100 | X11: 0 | Y11: 0 | Z11: 30 | AA11: 0 | AB11: 0 | AC11: 70 | AD11: 정규
A12: 주식회사 스토리위즈 | B12: storywiz1 | C12: 원스토어㈜ | D12: H035795481 | E12: 나 혼자만 일일 보상 | F12: [연재] 나 혼자만 일일 보상 110회 | G12: 110 | H12: H035795777 | I12: 2차 | J12: eBook | K12: 스토리위즈 | L12: 이동열 | N12: 연재 | O12: 1 | P12: 0 | Q12: 0 | R12: 1 | S12: 100 | T12: 0 | U12: 0 | V12: 100 | W12: 100 | X12: 0 | Y12: 0 | Z12: 30 | AA12: 0 | AB12: 0 | AC12: 70 | AD12: 정규
A13: 주식회사 스토리위즈 | B13: storywiz1 | C13: 원스토어㈜ | D13: H035795481 | E13: 나 혼자만 일일 보상 | F13: [연재] 나 혼자만 일일 보상 111회 | G13: 111 | H13: H035795776 | I13: 2차 | J13: eBook | K13: 스토리위즈 | L13: 이동열 | N13: 연재 | O13: 1 | P13: 0 | Q13: 0 | R13: 1 | S13: 100 | T13: 0 | U13: 0 | V13: 100 | W13: 100 | X13: 0 | Y13: 0 | Z13: 30 | AA13: 0 | AB13: 0 | AC13: 70 | AD13: 정규
... A233: 주식회사 스토리위즈 | B233: storywiz1 | C233: 원스토어㈜ | D233: H038820214 | E233: 나 혼자만 일일 보상 | F233: 나 혼자만 일일 보상 외전 (완결) | G233: 10 | H233: H040597612 | I233: 2차 | J233: eBook | K233: 스토리위즈 | L233: 이동열 | N233: 단행 | O233: 25 | P233: 0 | Q233: 0 | R233: 25 | S233: 22500 | T233: 0 | U233: 0 | V233: 22500 | W233: 20450 | X233: 0 | Y233: 2050 | Z233: 6135 | AA233: 615 | AB233: 0 | AC233: 15750 | AD233: 정규

Sheet 조아라04
A1: 작품명 | B1: 작품코드 | C1: 작가명 | D1: 단가 | E1: 판매건수 | F1: 비율 | G1: 정산금액 | H1: 출판사명
A2: 던전 공략 LIVE | B2: 1197084 | C2: 이동열 | D2: 100 | E2: 84 | F2: 0.6 | G2: 5040
A3: 나 혼자만 일일 보상 | B3: 1430791 | C3: 이동열 | D3: 100 | E3: 224 | F3: 0.6 | G3: 13440

Sheet 코미코04
A1: 플랫폼 | B1: 마스터작품명 | C1: 언어 | D1: 작품명 | E1: 작가 | F1: 출판사 | G1: 결제유형 | H1: 사용 | I1: 취소 | J1: 무료사용 | K1: 무료취소 | L1: 사용 | M1: 취소 | N1: 무료사용 | O1: 무료취소 | Q1: (A)코인매출액 | R1: (B)마켓수수료율 | S1: (C)분배전매출[(A)×(1-B)] | T1: (D)RS율 | U1: 배분금액[(C)×(D)] | V1: (A')코인매출액 | W1: (B')마켓수수료율 | X1: (C')분배전매출[(A')×(1-B')] | Y1: (D')RS율 | Z1: (E')배분금액[(C')×(D')] | AA1: 코인매출 | AB1: 배분금액
A2: 한국코미코 | B2: 나 혼자만 일일 보상 [완] | C2: Korean | D2: 나 혼자만 일일 보상 [완] | E2: 이동열 | G2: 일반결제 | H2: 0 | I2: 0 | J2: 0 | K2: 0 | L2: 0 | M2: 0 | N2: 0 | O2: 0 | Q2: 18900 | R2: 0 | S2: 18900 | T2: 0.7 | U2: 13230 | V2: 0 | W2: 0 | X2: 0 | Y2: 0.7 | Z2: 0 | AA2: 18900 | AB2: 13230
A3: 한국코미코 | B3: 나 혼자만 일일 보상 [완] | C3: Korean | D3: 나 혼자만 일일 보상 [완] | E3: 이동열 | G3: Google | H3: 0 | I3: 0 | J3: 0 | K3: 0 | L3: 0 | M3: 0 | N3: 0 | O3: 0 | Q3: 1600 | R3: 0.3 | S3: 1120 | T3: 0.7 | U3: 784 | V3: 500 | W3: 0.3 | X3: 350 | Y3: 0.7 | Z3: 245 | AA3: 2100 | AB3: 1029
A4: 한국코미코 | B4: 나 혼자만 일일 보상 [완] | C4: Korean | D4: 나 혼자만 일일 보상 [완] | E4: 이동열 | G4: OneStore | H4: 0 | I4: 0 | J4: 0 | K4: 0 | L4: 0 | M4: 0 | N4: 0 | O4: 0 | Q4: 3200 | R4: 0 | S4: 3200 | T4: 0.7 | U4: 2240 | V4: 0 | W4: 0 | X4: 0 | Y4: 0.7 | Z4: 0 | AA4: 3200 | AB4: 2240

Sheet 톡소다04
A1: 상품구분 | B1: 대분류 | C1: 중분류 | D1: 바코드 | E1: 상품명 | F1: 판매채널 | G1: 저자 | H1: 회차수 | I1: 공급사 | J1: 구분 | K1: 정가 | L1: 판매가 | M1: 정산대상 기준 판매금액 | N1: 수량 | O1: 총판매금액 | P1: 정산대상 기준 총 판매금액 | Q1: 정산율 | R1: 정산금액 | S1: 출판사
A2: 웹소설 | B2: 판타지 | C2: 현대 | D2: 76M2009149149 | E2: 나 혼자만 일일 보상 | F2: ANDROID | G2: 이동열 | H2: 249 | I2: 스토리위즈(주) | J2: 대여 판매 | K2: 100 | L2: 100 | M2: 21600 | N2: 216 | O2: 21600 | P2: 21600 | Q2: 70 | R2: 15120 | S2: 스토리위즈
A3: 웹소설 | B3: 판타지 | C3: 현대 | D3: 76M2009149149 | E3: 나 혼자만 일일 보상 | F3: ANDROID | G3: 이동열 | H3: 249 | I3: 스토리위즈(주) | J3: 소장 판매 | K3: 100 | L3: 100 | M3: 700 | N3: 7 | O3: 700 | P3: 700 | Q3: 70 | R3: 490 | S3: 스토리위즈

Sheet 하이북04
A1: 작품명 | B1: 작가명 | C1: 출판사 | D1: 정산일 | E1: 정산주기 | F1: 조회수(구매) | G1: 판매금액(구매) | H1: 정산금액(구매) | I1: 조회수(대여) | J1: 판매금액(대여) | K1: 정산금액(대여) | L1: 조회수 | M1: 판매금액 | N1: 정산금액
A2: 나 혼자만 일일 보상 | B2: 이동열 | C2: 스토리위즈 | D2: 월정산 | E2: 확인중 | F2: 7 | G2: 700 | H2: 490 | I2: 0 | J2: 0 | K2: 0 | L2: 7 | M2: 700 | N2: 490

Sheet 한아름04
A1: NO | B1: 업체명 | C1: 구분 | D1: 출판사 | E1: 작가명 | F1: 속성 | G1: 작품명 | H1: 권수 | I1: 권당 | J1: 판매 | K1: 금액 | L1: 정산금
B2: 스토리위즈 | C2: 소설 | D2: 스토리위즈 | E2: 이동열 | F2: 구매 | G2: 나 혼자만 일일 보상 | H2: 2 | I2: 2240 | J2: 1 | K2: 2240 | L2: 1568
B3: 스토리위즈 | C3: 소설 | D3: 스토리위즈 | E3: 이동열 | F3: 구매 | G3: 나 혼자만 일일 보상 | H3: 3 | I3: 2240 | J3: 1 | K3: 2240 | L3: 1568
B4: 스토리위즈 | C4: 소설 | D4: 스토리위즈 | E4: 이동열 | F4: 구매 | G4: 나 혼자만 일일 보상 | H4: 4 | I4: 2240 | J4: 1 | K4: 2240 | L4: 1568
B5: 스토리위즈 | C5: 소설 | D5: 스토리위즈 | E5: 이동열 | F5: 구매 | G5: 나 혼자만 일일 보상 | H5: 5 | I5: 2240 | J5: 1 | K5: 2240 | L5: 1568
B6: 스토리위즈 | C6: 소설 | D6: 스토리위즈 | E6: 이동열 | F6: 구매 | G6: 나 혼자만 일일 보상 | H6: 6 | I6: 2240 | J6: 1 | K6: 2240 | L6: 1568
B7: 스토리위즈 | C7: 소설 | D7: 스토리위즈 | E7: 이동열 | F7: 구매 | G7: 나 혼자만 일일 보상 | H7: 7 | I7: 2240 | J7: 1 | K7: 2240 | L7: 1568
B8: 스토리위즈 | C8: 소설 | D8: 스토리위즈 | E8: 이동열 | F8: 구매 | G8: 나 혼자만 일일 보상 | H8: 8 | I8: 2240 | J8: 1 | K8: 2240 | L8: 1568
B9: 스토리위즈 | C9: 소설 | D9: 스토리위즈 | E9: 이동열 | F9: 구매 | G9: 나 혼자만 일일 보상 | H9: 9 | I9: 2240 | J9: 1 | K9: 2240 | L9: 1568
B10: 스토리위즈 | C10: 소설 | D10: 스토리위즈 | E10: 이동열 | F10: 구매 | G10: 나 혼자만 일일 보상 | H10: 10 | I10: 2240 | J10: 1 | K10: 2240 | L10: 1568

Sheet 카카오04
A1: 특별/일반 | B1: 사업자명 | C1: 사업자번호 | D1: 발행자명 | E1: 계약UID | F1: 계약유형 | G1: 계약(과/면세) | H1: 당월신규계약여부 | I1: 카테고리 | J1: 시리즈ID | K1: 시리즈명 | L1: 발행자가 부여하는 코드 | M1: 레이블 | N1: 작가명 | O1: ISBN(유/무) | P1: CP정산율_안드로이드/이벤트캐시 | Q1: CP정산율_iOS | R1: 이용권 종류 | S1: 이용권 금액 | T1: 캐시_합계 | U1: 캐시_CPP | V1: 캐시_CPI | W1: 캐시_CP1 | X1: 캐시_CP2 | Y1: 캐시_CP3 | Z1: 캐시_CP7 | AA1: 캐시_CP8 | AB1: 캐시_CP9 | AC1: 캐시_이벤트캐시 | AD1: 원화_합계 | AE1: 원화_CPP | AF1: 원화_CPI | AG1: 원화_CP1 | AH1: 원화_CP2 | AI1: 원화_CP3 | AJ1: 원화_CP7 | AK1: 원화_CP8 | AL1: 원화_CP9 | AM1: 원화_이벤트캐시 | AN1: 공급가액 | AO1: 부가세 | AP1: 공급대가
A2: 특별계약 | B2: 주식회사 스토리위즈 | C2: 3828601768 | D2: 스토리위즈 | E2: 1942 | F2: 선투자 | G2: 면세 | H2: N | I2: 소설 | J2: 49989820 | K2: 던전 공략 LIVE | N2: 이동열 | O2: Y | P2: 0.55 | Q2: 0.55 | R2: 단일 이용권 | S2: 100 | T2: 7900 | U2: 700 | V2: 0 | W2: 0 | X2: 0 | Y2: 0 | Z2: 0 | AA2: 0 | AB2: 0 | AC2: 7200 | AD2: 7900 | AE2: 700 | AF2: 0 | AG2: 0 | AH2: 0 | AI2: 0 | AJ2: 0 | AK2: 0 | AL2: 0 | AM2: 7200 | AN2: 4345 | AO2: 0 | AP2: 4345
A3: 특별계약 | B3: 주식회사 스토리위즈 | C3: 3828601768 | D3: 스토리위즈 | E3: 1942 | F3: 선투자 | G3: 면세 | H3: N | I3: 소설 | J3: 49989820 | K3: 던전 공략 LIVE | N3: 이동열 | O3: Y | P3: 0.55 | Q3: 0.55 | R3: 시리즈 이용권 패키지 | S3: 2400 | T3: 5700 | U3: 3300 | V3: 0 | W3: 0 | X3: 0 | Y3: 0 | Z3: 0 | AA3: 0 | AB3: 0 | AC3: 2400 | AD3: 5700 | AE3: 3300 | AF3: 0 | AG3: 0 | AH3: 0 | AI3: 0 | AJ3: 0 | AK3: 0 | AL3: 0 | AM3: 2400 | AN3: 3135 | AO3: 0 | AP3: 3135
A4: 특별계약 | B4: 주식회사 스토리위즈 | C4: 3828601768 | D4: 스토리위즈 | E4: 1942 | F4: 선투자 | G4: 면세 | H4: N | I4: 소설 | J4: 49989820 | K4: 던전 공략 LIVE | N4: 이동열 | O4: Y | P4: 0.55 | Q4: 0.55 | R4: 시리즈 이용권 패키지 | S4: 9000 | T4: -3200 | U4: -3200 | V4: 0 | W4: 0 | X4: 0 | Y4: 0 | Z4: 0 | AA4: 0 | AB4: 0 | AC4: 0 | AD4: -3200 | AE4: -3200 | AF4: 0 | AG4: 0 | AH4: 0 | AI4: 0 | AJ4: 0 | AK4: 0 | AL4: 0 | AM4: 0 | AN4: -1760 | AO4: 0 | AP4: -1760
A5: 특별계약 | B5: 주식회사 스토리위즈 | C5: 3828601768 | D5: 스토리위즈 | E5: 1942 | F5: 선투자 | G5: 면세 | H5: N | I5: 소설 | J5: 49989820 | K5: 던전 공략 LIVE | N5: 이동열 | O5: Y | P5: 0.55 | Q5: 0.55 | R5: 시리즈 이용권 패키지 | S5: 13500 | T5: 13500 | U5: 13500 | V5: 0 | W5: 0 | X5: 0 | Y5: 0 | Z5: 0 | AA5: 0 | AB5: 0 | AC5: 0 | AD5: 13500 | AE5: 13500 | AF5: 0 | AG5: 0 | AH5: 0 | AI5: 0 | AJ5: 0 | AK5: 0 | AL5: 0 | AM5: 0 | AN5: 7425 | AO5: 0 | AP5: 7425
A6: 특별계약 | B6: 주식회사 스토리위즈 | C6: 3828601768 | D6: 스토리위즈 | E6: 1942 | F6: 선투자 | G6: 면세 | H6: N | I6: 소설 | J6: 51584299 | K6: 나 혼자만 일일 보상 | N6: 이동열 | O6: Y | P6: 0.55 | Q6: 0.55 | R6: 단일 이용권 | S6: 100 | T6: 25000 | U6: 8600 | V6: 0 | W6: 0 | X6: 0 | Y6: 0 | Z6: 100 | AA6: 0 | AB6: 0 | AC6: 16300 | AD6: 25010 | AE6: 8600 | AF6: 0 | AG6: 0 | AH6: 0 | AI6: 0 | AJ6: 110 | AK6: 0 | AL6: 0 | AM6: 16300 | AN6: 13756 | AO6: 0 | AP6: 13756
A7: 특별계약 | B7: 주식회사 스토리위즈 | C7: 3828601768 | D7: 스토리위즈 | E7: 1942 | F7: 선투자 | G7: 면세 | H7: N | I7: 소설 | J7: 51584299 | K7: 나 혼자만 일일 보상 | N7: 이동열 | O7: Y | P7: 0.55 | Q7: 0.55 | R7: 시리즈 이용권 패키지 | S7: 2400 | T7: 43000 | U7: 37800 | V7: 0 | W7: 0 | X7: 0 | Y7: 0 | Z7: 0 | AA7: 0 | AB7: 0 | AC7: 5200 | AD7: 43000 | AE7: 37800 | AF7: 0 | AG7: 0 | AH7: 0 | AI7: 0 | AJ7: 0 | AK7: 0 | AL7: 0 | AM7: 5200 | AN7: 23650 | AO7: 0 | AP7: 23650
A8: 특별계약 | B8: 주식회사 스토리위즈 | C8: 3828601768 | D8: 스토리위즈 | E8: 1942 | F8: 선투자 | G8: 면세 | H8: N | I8: 소설 | J8: 51584299 | K8: 나 혼자만 일일 보상 | N8: 이동열 | O8: Y | P8: 0.55 | Q8: 0.55 | R8: 시리즈 이용권 패키지 | S8: 9200 | T8: 78500 | U8: 71000 | V8: 0 | W8: 0 | X8: 0 | Y8: 0 | Z8: 0 | AA8: 0 | AB8: 0 | AC8: 7500 | AD8: 78500 | AE8: 71000 | AF8: 0 | AG8: 0 | AH8: 0 | AI8: 0 | AJ8: 0 | AK8: 0 | AL8: 0 | AM8: 7500 | AN8: 43175 | AO8: 0 | AP8: 43175
A9: 특별계약 | B9: 주식회사 스토리위즈 | C9: 3828601768 | D9: 스토리위즈 | E9: 1942 | F9: 선투자 | G9: 면세 | H9: N | I9: 소설 | J9: 51584299 | K9: 나 혼자만 일일 보상 | N9: 이동열 | O9: Y | P9: 0.55 | Q9: 0.55 | R9: 시리즈 이용권 패키지 | S9: 18000 | T9: 45800 | U9: 42000 | V9: 0 | W9: 0 | X9: 0 | Y9: 0 | Z9: 0 | AA9: 0 | AB9: 0 | AC9: 3800 | AD9: 45800 | AE9: 42000 | AF9: 0 | AG9: 0 | AH9: 0 | AI9: 0 | AJ9: 0 | AK9: 0 | AL9: 0 | AM9: 3800 | AN9: 25190 | AO9: 0 | AP9: 25190
A10: 특별계약 | B10: 주식회사 스토리위즈 | C10: 3828601768 | D10: 스토리위즈 | E10: 1942 | F10: 선투자 | G10: 면세 | H10: N | I10: 소설 | J10: 52963521 | K10: 말빨 | N10: 이동열 | O10: Y | P10: 0.55 | Q10: 0.55 | R10: 단일 이용권 | S10: 100 | T10: 17000 | U10: 6500 | V10: 0 | W10: 0 | X10: 0 | Y10: 0 | Z10: 0 | AA10: 0 | AB10: 0 | AC10: 10500 | AD10: 17000 | AE10: 6500 | AF10: 0 | AG10: 0 | AH10: 0 | AI10: 0 | AJ10: 0 | AK10: 0 | AL10: 0 | AM10: 10500 | AN10: 9350 | AO10: 0 | AP10: 9350
A11: 특별계약 | B11: 주식회사 스토리위즈 | C11: 3828601768 | D11: 스토리위즈 | E11: 1942 | F11: 선투자 | G11: 면세 | H11: N | I11: 소설 | J11: 52963521 | K11: 말빨 | N11: 이동열 | O11: Y | P11: 0.55 | Q11: 0.55 | R11: 시리즈 이용권 패키지 | S11: 2400 | T11: 29300 | U11: 18800 | V11: 0 | W11: 0 | X11: 0 | Y11: 6600 | Z11: 0 | AA11: 0 | AB11: 0 | AC11: 3900 | AD11: 30620 | AE11: 18800 | AF11: 0 | AG11: 0 | AH11: 0 | AI11: 7920 | AJ11: 0 | AK11: 0 | AL11: 0 | AM11: 3900 | AN11: 16841 | AO11: 0 | AP11: 16841
A12: 특별계약 | B12: 주식회사 스토리위즈 | C12: 3828601768 | D12: 스토리위즈 | E12: 1942 | F12: 선투자 | G12: 면세 | H12: N | I12: 소설 | J12: 52963521 | K12: 말빨 | N12: 이동열 | O12: Y | P12: 0.55 | Q12: 0.55 | R12: 시리즈 이용권 패키지 | S12: 9200 | T12: 46000 | U12: 46000 | V12: 0 | W12: 0 | X12: 0 | Y12: 0 | Z12: 0 | AA12: 0 | AB12: 0 | AC12: 0 | AD12: 46000 | AE12: 46000 | AF12: 0 | AG12: 0 | AH12: 0 | AI12: 0 | AJ12: 0 | AK12: 0 | AL12: 0 | AM12: 0 | AN12: 25300 | AO12: 0 | AP12: 25300
A13: 특별계약 | B13: 주식회사 스토리위즈 | C13: 3828601768 | D13: 스토리위즈 | E13: 1942 | F13: 선투자 | G13: 면세 | H13: N | I13: 소설 | J13: 56766083 | K13: 던전 공략 LIVE [단행본] | N13: 이동열 | O13: Y | P13: 0.55 | Q13: 0.55 | R13: 단일 대여 이용권 | S13: 900 | T13: 2700 | U13: 2700 | V13: 0 | W13: 0 | X13: 0 | Y13: 0 | Z13: 0 | AA13: 0 | AB13: 0 | AC13: 0 | AD13: 2700 | AE13: 2700 | AF13: 0 | AG13: 0 | AH13: 0 | AI13: 0 | AJ13: 0 | AK13: 0 | AL13: 0 | AM13: 0 | AN13: 1485 | AO13: 0 | AP13: 1485
... A18: 특별계약 | B18: 주식회사 스토리위즈 | C18: 3828601768 | D18: 스토리위즈 | E18: 1942 | F18: 선투자 | G18: 면세 | H18: N | I18: 소설 | J18: 58669835 | K18: 마법 아카데미의 육체파 천재 | N18: 이동열 | O18: Y | P18: 0.55 | Q18: 0.55 | R18: 시리즈 이용권 패키지 | S18: 9200 | T18: 327500 | U18: 300600 | V18: 0 | W18: 0 | X18: 0 | Y18: 0 | Z18: 9200 | AA18: 0 | AB18: 0 | AC18: 17700 | AD18: 328420 | AE18: 300600 | AF18: 0 | AG18: 0 | AH18: 0 | AI18: 0 | AJ18: 10120 | AK18: 0 | AL18: 0 | AM18: 17700 | AN18: 180631 | AO18: 0 | AP18: 180631
AP19: =SUM(AP2:AP18) -> 750850
