Workbook

Sheet 종합
A1: 델리툰 (독)
A2: 기본정보
A3: RS: 순매출의 40% 매출월: M 정산서 전달: M+1월 20일 내 (CMS로 확인) 실제 정산(계산서 발행): M+2M 진행 기타: 과세사업자
A5: 매출내역
A6: 상세 *매출월 발생월 기준 / 타이틀 MG, RS 월별 정산 (M+2)
A7: 작품명 | B7: Küsse hinter den Kulissen (백스테이지 키스신) | H7: Tochter des Teufels (마왕의 딸로 태어났습니다)
A8: 런칭일 | B8: 2021.05.03 | H8: 2021.05.09
A9: MG | B9: 1500000 | D9: MG 정산 | E9: 2020.12 SW매출인식 / 2021.01 입금 | H9: 2500000 | J9: MG 정산 | K9: 2020.12 SW매출인식 / 2021.01 입금
A10: 구분 | B10: CP RS (￦) | C10: 전체 MG (￦) | D10: 남은 MG (￦) | E10: 차감 후 MG (￦) | F10: 지급 금액 (￦) | G10: 정산현황 | H10: CP RS (￦) | I10: 전체 MG (￦) | J10: 남은 MG (￦) | K10: 차감 후 MG (￦) | L10: 지급 금액 (￦) | M10: 정산현황
A11: 2021.05 | B11: ='월별 정산서'!D6 -> 198635 | C11: =B9 -> 1500000 | D11: 1500000 | E11: =D11-B11 -> 1301365 | F11: 0 | G11: N | H11: ='월별 정산서'!D5 -> 912185 | I11: =H9 -> 2500000 | J11: 2500000 | K11: =J11-H11 -> 1587815 | L11: 0 | M11: N
A12: 2021.06 | B12: ='월별 정산서'!D12 -> 146046 | C12: 1500000 | D12: =E11 -> 1301365 | E12: =D12-B12 -> 1155319 | F12: 0 | G12: N | H12: ='월별 정산서'!D11 -> 729877 | I12: 2500000 | J12: =K11 -> 1587815 | K12: =J12-H12 -> 857938 | L12: 0 | M12: N
A13: 2021.07 | B13: 128768 | C13: 1500000 | D13: =E12 -> 1155319 | E13: =D13-B13 -> 1026551 | F13: 0 | G13: N | H13: ='월별 정산서'!D16 -> 589005 | I13: 2500000 | J13: =K12 -> 857938 | K13: =J13-H13 -> 268933 | L13: 0 | M13: N
A14: 2021.08 | B14: 127657 | C14: 1500000 | D14: =E13 -> 1026551 | E14: =D14-B14 -> 898894 | F14: 0 | G14: N | H14: ='월별 정산서'!D22 -> 947442 | I14: 2500000 | J14: =K13 -> 268933 | K14: 0 | L14: 678509 | M14: 2021.09 계산서 발행
A15: 2021.09 | B15: ='월별 정산서'!D29 -> 198018 | C15: ='월별 정산서'!E29 -> 1500000 | D15: =E14 -> 898894 | E15: =D15-B15 -> 700876 | F15: 0 | G15: N | H15: ='월별 정산서'!D28 -> 812388 | I15: ='월별 정산서'!E28 -> 2500000 | J15: ='월별 정산서'!F28 -> 0 | K15: 0 | L15: =H15 -> 812388 | M15: 2021.10 계산서 발행
A16: 2021.10 | B16: ='월별 정산서'!D35 -> 156276 | C16: ='월별 정산서'!E35 -> 1500000 | D16: =E15 -> 700876 | E16: =D16-B16 -> 544600 | F16: 0 | G16: N | H16: ='월별 정산서'!D34 -> 670121 | I16: ='월별 정산서'!E34 -> 2500000 | J16: 0 | K16: 0 | L16: =H16 -> 670121 | M16: 2021.11 계산서 발행
A17: 2021.11 | B17: ='월별 정산서'!D41 -> 73734 | C17: =C16 -> 1500000 | D17: =E16 -> 544600 | E17: =D17-B17 -> 470866 | F17: 0 | G17: N | H17: ='월별 정산서'!D40 -> 540293 | I17: =I16 -> 2500000 | J17: 0 | K17: 0 | L17: =H17 -> 540293 | M17: 2021.12 계산서 발행
A18: 2021.12 | B18: ='월별 정산서'!D47 -> 109350 | C18: =C17 -> 1500000 | D18: =E17 -> 470866 | E18: =D18-B18 -> 361516 | F18: 0 | G18: N | H18: ='월별 정산서'!D46 -> 472861 | I18: =I17 -> 2500000 | J18: 0 | K18: 0 | L18: =H18 -> 472861 | M18: 2022.01 계산서 발행
A19: 2022.01 | B19: 100445 | C19: =C18 -> 1500000 | D19: 361516 | E19: 261071 | G19: N | H19: 515623 | I19: 2500000 | J19: 0 | K19: 0 | L19: 515623 | M19: 2022.02 계산서 발행
A20: 2022.02 | B20: 82956 | C20: 1500000 | D20: 261071 | E20: 178115 | F20: 0 | G20: N | H20: 750990 | I20: 2500000 | J20: 0 | K20: 0 | L20: 750990 | M20: 2022.03 계산서 발행
A21: 2022.03 | B21: ='월별 정산서'!D65 -> 24105 | C21: ='월별 정산서'!E65 -> 1500000 | D21: ='월별 정산서'!F65 -> 178115 | E21: ='월별 정산서'!G65 -> 154010 | F21: 0 | G21: N | H21: ='월별 정산서'!D64 -> 715197 | I21: ='월별 정산서'!E64 -> 2500000 | J21: 0 | K21: 0 | L21: ='월별 정산서'!H64 -> 715197 | M21: 2022.04 계산서 발행
A22: 2022.04 | B22: ='월별 정산서'!D71 -> 61907 | C22: ='월별 정산서'!E71 -> 1500000 | D22: ='월별 정산서'!F71 -> 154010 | E22: ='월별 정산서'!G71 -> 92103 | F22: 0 | G22: N | H22: ='월별 정산서'!D70 -> 715440 | I22: ='월별 정산서'!E70 -> 2500000 | L22: ='월별 정산서'!H70 -> 715440 | M22: 2022.05 계산서 발행

Sheet 월별 정산서
B1: 월별 매출
B3: 2021년 05월
A4: cid | B4: title | C4: CP RS (€) | D4: CP RS (￦) | E4: 전체 MG (￦) | F4: 남은 MG (￦) | G4: 차감 후 MG (￦) | H4: 자급 금액 (￦) | I4: Unit
A5: 10083 | B5: Tochter des Teufels | C5: 674.1 | D5: 912185 | E5: 2500000 | F5: 2500000 | G5: 1587815 | H5: 0 | I5: KRW
A6: 10082 | B6: Küsse hinter den Kulissen | C6: 146.79 | D6: 198635 | E6: 1500000 | F6: 1500000 | G6: 1301365 | H6: 0 | I6: KRW
A7: Sum | C7: 820.89 | D7: 1110820 | H7: 0
B9: 2021년 06월
A10: cid | B10: title | C10: CP RS (€) | D10: CP RS (￦) | E10: 전체 MG (￦) | F10: 남은 MG (￦) | G10: 차감 후 MG (￦) | H10: 자급 금액 (￦) | I10: Unit
A11: 10083 | B11: Tochter des Teufels | C11: 536.04 | D11: 729877 | E11: 2500000 | F11: 1587815 | G11: 857938 | H11: 0 | I11: KRW
A12: 10082 | B12: Küsse hinter den Kulissen | C12: 107.26 | D12: 146046 | E12: 1500000 | F12: 1301365 | G12: 1155319 | H12: 0 | I12: KRW
B14: 2021년 07월
A15: cid | B15: title | C15: CP RS (€) | D15: CP RS (￦) | E15: 전체 MG (￦) | F15: 남은 MG (￦) | G15: 차감 후 MG (￦) | H15: 자급 금액 (￦) | I15: Unit
A16: 10083 | B16: Tochter des Teufels | C16: 432.99 | D16: 589005 | E16: 2500000 | F16: 857938 | G16: =F16-D16 -> 268933 | H16: 0 | I16: KRW
A17: 10082 | B17: Küsse hinter den Kulissen | C17: 94.66 | D17: 128768 | E17: 1500000 | F17: 1155319 | G17: =F17-D17 -> 1026551 | H17: 0 | I17: KRW
A18: Sum | C18: 527.65 | D18: 717773
B20: 2021년 08월
A21: cid | B21: title | C21: CP RS (€) | D21: CP RS (￦) | E21: 전체 MG (￦) | F21: 남은 MG (￦) | G21: 차감 후 MG (￦) | H21: 자급 금액 (￦) | I21: Unit
A22: 10083 | B22: Tochter des Teufels | C22: 684.88 | D22: 947442 | E22: 2500000 | F22: 268933 | G22: =F22-D22 -> -678509 | H22: 678509 | I22: KRW
A23: 10082 | B23: Küsse hinter den Kulissen | C23: 92.28 | D23: 127657 | E23: 1500000 | F23: 1026551 | G23: =F23-D23 -> 898894 | H23: 0 | I23: KRW
A24: Sum | C24: 527.65 | D24: 717773
B26: 2021년 09월
A27: cid | B27: title | C27: CP RS (€) | D27: CP RS (￦) | E27: 전체 MG (￦) | F27: 남은 MG (￦) | G27: 차감 후 MG (￦) | H27: 자급 금액 (￦) | I27: Unit
A28: 10083 | B28: Tochter des Teufels | C28: 589.46 | D28: 812388 | E28: 2500000 | F28: 0 | G28: 0 | H28: 812388 | I28: KRW
A29: 10082 | B29: Küsse hinter den Kulissen | C29: 143.68 | D29: 198018 | E29: 1500000 | F29: 898894 | G29: 700876 | H29: 0 | I29: KRW
A30: Sum | C30: 527.65 | D30: 717773
B32: 2021년 10월
A33: cid | B33: title | C33: CP RS (€) | D33: CP RS (￦) | E33: 전체 MG (￦) | F33: 남은 MG (￦) | G33: 차감 후 MG (￦) | H33: 자급 금액 (￦) | I33: Unit
A34: 10083 | B34: Tochter des Teufels | C34: 496.43 | D34: 670121 | E34: 2500000 | F34: 0 | G34: 0 | H34: 670121 | I34: KRW
A35: 10082 | B35: Küsse hinter den Kulissen | C35: 115.77 | D35: 156276 | E35: 1500000 | F35: 700876 | G35: 544600 | H35: 0 | I35: KRW
A36: Sum | C36: 612.2 | D36: 826397 | H36: 670121
B38: 2021년 11월
A39: cid | B39: title | C39: CP RS (€) | D39: CP RS (￦) | E39: 전체 MG (￦) | F39: 남은 MG (￦) | G39: 차감 후 MG (￦) | H39: 자급 금액 (￦) | I39: Unit
A40: 10083 | B40: Tochter des Teufels | C40: 405.51 | D40: 540293 | E40: 2500000 | F40: 0 | G40: 0 | H40: 540293 | I40: KRW
A41: 10082 | B41: Küsse hinter den Kulissen | C41: 55.34 | D41: 73734 | E41: 1500000 | F41: 544600 | G41: 470866 | H41: 0 | I41: KRW
A42: Sum | C42: 460.85 | D42: 614027 | H42: 540293
B44: 2021년 12월
A45: cid | B45: title | C45: CP RS (€) | D45: CP RS (￦) | E45: 전체 MG (￦) | F45: 남은 MG (￦) | G45: 차감 후 MG (￦) | H45: 자급 금액 (￦) | I45: Unit
A46: 10083 | B46: Tochter des Teufels | C46: 347.37 | D46: 472861 | E46: 2500000 | F46: 0 | G46: 0 | H46: 472861 | I46: KRW
A47: 10082 | B47: Küsse hinter den Kulissen | C47: 80.33 | D47: 109350 | E47: 1500000 | F47: 470866 | G47: 361516 | H47: 0 | I47: KRW
A48: Sum | C48: 427.7 | D48: 582211 | H48: 472861
...
